Workbook
Name company: CaseData!$J$3
Name lstCountries: CaseData!$D$10:$D$17
Name lstCurrencies: CaseData!$B$47:$B$52
Name lstStoreCurrencies: CaseData!$E$10:$E$17
Name lstStores: CaseData!$C$10:$C$17
Name periods: CaseData!$J$5
Name start_date: CaseData!$J$4
Name topic: "CFM Topic: " & CaseData!$J$6

Sheet Cover
E15: =company -> Fashion Boutique
E16: {=topic} -> CFM Topic: Revenue

Sheet Notes
A1: =company -> Fashion Boutique
A2: {=topic} -> CFM Topic: Revenue
A3: NOTES
A5: GENERAL NOTES
E7: - keeping arrays of similar size throughout the model pays off
E8: - need more practice with da formulas for Time sheet
A10: COMPOUNDED INFLATION
E12: • bug in original Price!J8: IF(rate="n.a.",1, 1*(1+rate)) only applies the current year's rate once, so each year resets to 1 instead of compounding
E13: • correct logic (per CaseSolution): inflation index = product of (1 + rate) for every year from start through the current year
E14: • key insight: the column axis is SEQUENTIAL (year j depends on year j-1), not independent — so BYROW / BYCOL / MAP don't work, because they require scalar returns and treat elements in isolation
E15: • SCAN is the right primitive: SCAN(1, rates_row, LAMBDA(s,c, s*(1+c))) carries the accumulator forward along one dimension
E16: • to spill the full grid (currencies × years), wrap SCAN in MAKEARRAY: each (i,j) call re-runs SCAN over row i and picks element j
E17: • MAKEARRAY(rows, cols, LAMBDA(i,j, ...)): Excel calls the LAMBDA once per output cell, passing in row index i and column index j
E18: • final formula in CaseData!I86 spills 6×5 grid; lookup against currency/year happens at the consumer (e.g. Price!J8), not inside the grid formula
A21: PRICE FORMULA
E23: - unified operating flag. Very useful.
E26: - calculation of the unit price at each store
E35: - calculation of the discount, XLOOKUP
E41: - calculation of the compounded inflation
E43: - this is the most important formula

Sheet Revenue
A1: =company -> Fashion Boutique
A2: {=topic} -> CFM Topic: Revenue | J2: {=EDATE( start_date, _xlfn.SEQUENCE( 1, periods, 0, 1 ) )} -> 44562 | K2: 44593 | L2: 44621 | M2: 44652 | N2: 44682 | O2: 44713 | P2: 44743 | Q2: 44774 | R2: 44805 | S2: 44835 | T2: 44866 | U2: 44896 | V2: 44927 | W2: 44958 | X2: 44986 | Y2: 45017 | Z2: 45047 | AA2: 45078 | AB2: 45108 | AC2: 45139 | AD2: 45170 | AE2: 45200 | AF2: 45231 | AG2: 45261 | AH2: 45292 | AI2: 45323 | AJ2: 45352 | AK2: 45383 | AL2: 45413 | AM2: 45444 | AN2: 45474 | AO2: 45505 | AP2: 45536 | AQ2: 45566 | AR2: 45597 | AS2: 45627 | AT2: 45658 | AU2: 45689 | AV2: 45717 | AW2: 45748 | AX2: 45778 | AY2: 45809 | AZ2: 45839 | BA2: 45870 | BB2: 45901 | BC2: 45931 | BD2: 45962 | BE2: 45992 | BF2: 46023 | BG2: 46054 | BH2: 46082 | BI2: 46113 | BJ2: 46143 | BK2: 46174 | BL2: 46204 | BM2: 46235 | BN2: 46266 | BO2: 46296 | BP2: 46327 | BQ2: 46357
A3: REVENUE SCHEDULE | F3: Constant | G3: Unit | H3: Total | J3: {=EOMONTH( start_date, _xlfn.SEQUENCE( 1, periods, 0, 1 ) )} -> 44592 | K3: 44620 | L3: 44651 | M3: 44681 | N3: 44712 | O3: 44742 | P3: 44773 | Q3: 44804 | R3: 44834 | S3: 44865 | T3: 44895 | U3: 44926 | V3: 44957 | W3: 44985 | X3: 45016 | Y3: 45046 | Z3: 45077 | AA3: 45107 | AB3: 45138 | AC3: 45169 | AD3: 45199 | AE3: 45230 | AF3: 45260 | AG3: 45291 | AH3: 45322 | AI3: 45351 | AJ3: 45382 | AK3: 45412 | AL3: 45443 | AM3: 45473 | AN3: 45504 | AO3: 45535 | AP3: 45565 | AQ3: 45596 | AR3: 45626 | AS3: 45657 | AT3: 45688 | AU3: 45716 | AV3: 45747 | AW3: 45777 | AX3: 45808 | AY3: 45838 | AZ3: 45869 | BA3: 45900 | BB3: 45930 | BC3: 45961 | BD3: 45991 | BE3: 46022 | BF3: 46053 | BG3: 46081 | BH3: 46112 | BI3: 46142 | BJ3: 46173 | BK3: 46203 | BL3: 46234 | BM3: 46265 | BN3: 46295 | BO3: 46326 | BP3: 46356 | BQ3: 46387
A5: MONTHLY REVENUE
D7: i Total sales | G7: EUR | H7: {=_xlfn.LET( _xlpm.anchor,$J7, _xlpm.block, OFFSET( _xlpm.anchor, 0, 0, 1, periods ), _xlfn.BYROW( _xlpm.block, _xlfn.LAMBDA(_xlpm.row, SUM( _xlpm.row ) ) ) )} -> 83483876 | J7: {=_xlfn.LET( _xlpm.operating_flag,_xlfn.ANCHORARRAY( Time!$J18), _xlpm.w_units_anchor, Volume!$J8, _xlpm.w_units_sold, OFFSET( _xlpm.w_units_anchor, 0, 0, COUNTA( lstStores ), periods ), _xlpm.w_price_anchor, Price!$J40, _xlpm.w_price, OFFSET( _xlpm.w_price_anchor, 0, 0, COUNTA( lstStores ), periods ), _xlpm.w_revenue, _xlfn.BYCOL( _xlpm.w_units_sold * _xlpm.w_price, _xlfn.LAMBDA(_xlpm.column, SUM( _xlpm.column ) ) ), _xlpm.m_units_anchor, Volume!$J18, _xlpm.m_units_sold, OFFSET( _xlpm.m_units_anchor, 0, 0, COUNTA( lstStores ), periods ), _xlpm.m_price_anchor, Price!$J50, _xlpm.m_price, OFFSET( _xlpm.m_price_anchor, 0, 0, COUNTA( lstStores ), periods ), _xlpm.m_revenue, _xlfn.BYCOL( _xlpm.m_units_sold * _xlpm.m_price, _xlfn.LAMBDA(_xlpm.column, SUM( _xlpm.column ) ) ), _xlpm.a_units_anchor, Volume!$J45, _xlpm.a_units_sold, OFFSET( _xlpm.a_units_anchor, 0, 0, COUNTA( lstStores ), periods ), _xlpm.a_price_anchor, Price!$J60, _xlpm.a_price, OFFSET( _xlpm.a_price_anchor, 0, 0, COUNTA( lstStores ), periods ), _xlpm.a_revenue, _xlfn.BYCOL( _xlpm.a_units_sold * _xlpm.a_price, _xlfn.LAMBDA(_xlpm.column, SUM( _xlpm.column ) ) ), _xlfn.BYCOL( _xlfn.VSTACK(_xlpm.w_revenue, _xlpm.m_revenue, _xlpm.a_revenue ), _xlfn.LAMBDA(_xlpm.column, SUM( _xlpm.column ) ) ) )} -> 1003953.5 | K7: 669302.33 | L7: 669302.33 | M7: 726423.54 | N7: 730817.48 | O7: 735211.42 | P7: 1109408 | Q7: 743999.3 | R7: 748393.23 | S7: 851486.84 | T7: 863473.06 | U7: 1050551.1 | V7: 1344002.3 | W7: 908179.02 | X7: 920356.51 | Y7: 1107453.9 | Z7: 1128946.8 | AA7: 1150439.7 | AB7: 1755995.5 | AC7: 1193425.5 | AD7: 1214918.3 | AE7: 1322979.7 | AF7: 1344030.9 | AG7: 1638098.6 | AH7: 2054153.6 | AI7: 1411576.4 | AJ7: 1432543.1 | AK7: 1439768.8 | AL7: 1446994.5 | AM7: 1454220.2 | AN7: 2151120.7 | AO7: 1468671.7 | AP7: 1475897.4 | AQ7: 1475897.4 | AR7: 1475897.4 | AS7: 1771076.8 | AT7: 2197355.4 | AU7: 1494010.4 | AV7: 1494010.4 | AW7: 1494010.4 | AX7: 1494010.4 | AY7: 1494010.4 | AZ7: 2197355.4 | BA7: 1494010.4 | BB7: 1494010.4 | BC7: 1494010.4 | BD7: 1494010.4 | BE7: 1792812.5 | BF7: 2222814.3 | BG7: 1511339.6 | BH7: 1511339.6 | BI7: 1511339.6 | BJ7: 1511339.6 | BK7: 1511339.6 | BL7: 2222814.3 | BM7: 1511339.6 | BN7: 1511339.6 | BO7: 1511339.6 | BP7: 1511339.6 | BQ7: 1813607.5
D9: ii. Total sales split by category
E10: Women's | G10: EUR | H10: {=_xlfn.LET( _xlpm.anchor,$J10, _xlpm.block, OFFSET( _xlpm.anchor, 0, 0, COUNTA( $E$10:$E$12 ) + 1, periods ), _xlfn.BYROW( _xlpm.block, _xlfn.LAMBDA(_xlpm.row, SUM( _xlpm.row ) ) ) )} -> 44332304 | J10: {=_xlfn.LET( _xlpm.operating_flag,_xlfn.ANCHORARRAY( Time!$J18), _xlpm.w_units_anchor, Volume!$J8, _xlpm.w_units_sold, OFFSET( _xlpm.w_units_anchor, 0, 0, COUNTA( lstStores ), periods ), _xlpm.w_price_anchor, Price!$J40, _xlpm.w_price, OFFSET( _xlpm.w_price_anchor, 0, 0, COUNTA( lstStores ), periods ), _xlpm.w_revenue, _xlfn.BYCOL( _xlpm.w_units_sold * _xlpm.w_price, _xlfn.LAMBDA(_xlpm.column, SUM( _xlpm.column ) ) ), _xlpm.m_units_anchor, Volume!$J18, _xlpm.m_units_sold, OFFSET( _xlpm.m_units_anchor, 0, 0, COUNTA( lstStores ), periods ), _xlpm.m_price_anchor, Price!$J50, _xlpm.m_price, OFFSET( _xlpm.m_price_anchor, 0, 0, COUNTA( lstStores ), periods ), _xlpm.m_revenue, _xlfn.BYCOL( _xlpm.m_units_sold * _xlpm.m_price, _xlfn.LAMBDA(_xlpm.column, SUM( _xlpm.column ) ) ), _xlpm.a_units_anchor, Volume!$J45, _xlpm.a_units_sold, OFFSET( _xlpm.a_units_anchor, 0, 0, COUNTA( lstStores ), periods ), _xlpm.a_price_anchor, Price!$J60, _xlpm.a_price, OFFSET( _xlpm.a_price_anchor, 0, 0, COUNTA( lstStores ), periods ), _xlpm.a_revenue, _xlfn.BYCOL( _xlpm.a_units_sold * _xlpm.a_price, _xlfn.LAMBDA(_xlpm.column, SUM( _xlpm.column ) ) ), _xlfn.VSTACK(_xlpm.w_revenue, _xlpm.m_revenue, _xlpm.a_revenue ) )} -> 539040.7 | K10: 359360.47 | L10: 359360.47 | M10: 385089.63 | N10: 387068.8 | O10: 389047.97 | P10: 586540.7 | Q10: 393006.3 | R10: 394985.47 | S10: 442770 | T10: 448272.66 | U10: 544530.38 | V10: 695154.87 | W10: 469026.76 | X10: 474616.94 | Y10: 587153.06 | Z10: 599105.07 | AA10: 611057.08 | AB10: 934513.63 | AC10: 634961.09 | AD10: 646913.1 | AE10: 700022.87 | AF10: 711845.48 | AG10: 868401.7 | AH10: 1106429.6 | AI10: 749394.31 | AJ10: 761168.9 | AK10: 764597.57 | AL10: 768026.24 | AM10: 771454.9 | AN10: 1162325.4 | AO10: 778312.24 | AP10: 781740.91 | AQ10: 781740.91 | AR10: 781740.91 | AS10: 938089.1 | AT10: 1187410.8 | AU10: 791607.18 | AV10: 791607.18 | AW10: 791607.18 | AX10: 791607.18 | AY10: 791607.18 | AZ10: 1187410.8 | BA10: 791607.18 | BB10: 791607.18 | BC10: 791607.18 | BD10: 791607.18 | BE10: 949928.61 | BF10: 1201843.6 | BG10: 801229.06 | BH10: 801229.06 | BI10: 801229.06 | BJ10: 801229.06 | BK10: 801229.06 | BL10: 1201843.6 | BM10: 801229.06 | BN10: 801229.06 | BO10: 801229.06 | BP10: 801229.06 | BQ10: 961474.87
E11: Men's | G11: EUR | H11: 28625015 | J11: 337360.47 | K11: 224906.98 | L11: 224906.98 | M11: 248912.66 | N11: 250759.25 | O11: 252605.84 | P11: 381678.65 | Q11: 256299.02 | R11: 258145.61 | S11: 293982.7 | T11: 298443.94 | U11: 363486.22 | V11: 465871.89 | W11: 315115.28 | X11: 319649.3 | Y11: 375224.87 | Z11: 381945.3 | AA11: 388665.73 | AB11: 593079.23 | AC11: 402106.58 | AD11: 408827.01 | AE11: 451341.97 | AF11: 458370.44 | AG11: 558478.69 | AH11: 710995.96 | AI11: 480997.99 | AJ11: 487998.68 | AK11: 490945.64 | AL11: 493892.59 | AM11: 496839.55 | AN11: 749679.76 | AO11: 502733.46 | AP11: 505680.42 | AQ11: 505680.42 | AR11: 505680.42 | AS11: 606816.5 | AT11: 767387.98 | AU11: 511591.99 | AV11: 511591.99 | AW11: 511591.99 | AX11: 511591.99 | AY11: 511591.99 | AZ11: 767387.98 | BA11: 511591.99 | BB11: 511591.99 | BC11: 511591.99 | BD11: 511591.99 | BE11: 613910.39 | BF11: 775442.61 | BG11: 516961.74 | BH11: 516961.74 | BI11: 516961.74 | BJ11: 516961.74 | BK11: 516961.74 | BL11: 775442.61 | BM11: 516961.74 | BN11: 516961.74 | BO11: 516961.74 | BP11: 516961.74 | BQ11: 620354.09
E12: Accessories | G12: EUR | H12: 10526557 | J12: 127552.33 | K12: 85034.884 | L12: 85034.884 | M12: 92421.247 | N12: 92989.429 | O12: 93557.611 | P12: 141188.69 | Q12: 94693.975 | R12: 95262.156 | S12: 114734.14 | T12: 116756.46 | U12: 142534.54 | V12: 182975.54 | W12: 124036.98 | X12: 126090.27 | Y12: 145076.02 | Z12: 147896.46 | AA12: 150716.9 | AB12: 228402.66 | AC12: 156357.78 | AD12: 159178.23 | AE12: 171614.86 | AF12: 173815.01 | AG12: 211218.19 | AH12: 236728.11 | AI12: 181184.15 | AJ12: 183375.54 | AK12: 184225.62 | AL12: 185075.7 | AM12: 185925.79 | AN12: 239115.62 | AO12: 187625.95 | AP12: 188476.04 | AQ12: 188476.04 | AR12: 188476.04 | AS12: 226171.24 | AT12: 242556.67 | AU12: 190811.25 | AV12: 190811.25 | AW12: 190811.25 | AX12: 190811.25 | AY12: 190811.25 | AZ12: 242556.67 | BA12: 190811.25 | BB12: 190811.25 | BC12: 190811.25 | BD12: 190811.25 | BE12: 228973.5 | BF12: 245528.09 | BG12: 193148.76 | BH12: 193148.76 | BI12: 193148.76 | BJ12: 193148.76 | BK12: 193148.76 | BL12: 245528.09 | BM12: 193148.76 | BN12: 193148.76 | BO12: 193148.76 | BP12: 193148.76 | BQ12: 231778.51
E13: Total sales split by category | G13: EUR | H13: 83483876 | J13: {=_xlfn.LET( _xlpm.anchor, $J10, _xlpm.block, OFFSET( _xlpm.anchor, 0, 0, COUNTA( $E$10:$E$12 ), periods ), _xlfn.BYCOL( _xlpm.block, _xlfn.LAMBDA(_xlpm.column, SUM( _xlpm.column ) ) ) )} -> 1003953.5 | K13: 669302.33 | L13: 669302.33 | M13: 726423.54 | N13: 730817.48 | O13: 735211.42 | P13: 1109408 | Q13: 743999.3 | R13: 748393.23 | S13: 851486.84 | T13: 863473.06 | U13: 1050551.1 | V13: 1344002.3 | W13: 908179.02 | X13: 920356.51 | Y13: 1107453.9 | Z13: 1128946.8 | AA13: 1150439.7 | AB13: 1755995.5 | AC13: 1193425.5 | AD13: 1214918.3 | AE13: 1322979.7 | AF13: 1344030.9 | AG13: 1638098.6 | AH13: 2054153.6 | AI13: 1411576.4 | AJ13: 1432543.1 | AK13: 1439768.8 | AL13: 1446994.5 | AM13: 1454220.2 | AN13: 2151120.7 | AO13: 1468671.7 | AP13: 1475897.4 | AQ13: 1475897.4 | AR13: 1475897.4 | AS13: 1771076.8 | AT13: 2197355.4 | AU13: 1494010.4 | AV13: 1494010.4 | AW13: 1494010.4 | AX13: 1494010.4 | AY13: 1494010.4 | AZ13: 2197355.4 | BA13: 1494010.4 | BB13: 1494010.4 | BC13: 1494010.4 | BD13: 1494010.4 | BE13: 1792812.5 | BF13: 2222814.3 | BG13: 1511339.6 | BH13: 1511339.6 | BI13: 1511339.6 | BJ13: 1511339.6 | BK13: 1511339.6 | BL13: 2222814.3 | BM13: 1511339.6 | BN13: 1511339.6 | BO13: 1511339.6 | BP13: 1511339.6 | BQ13: 1813607.5
D15: iii. Total sales split by country
E16: {=lstCountries} -> France | G16: EUR | H16: {=_xlfn.LET( _xlpm.anchor,$J16, _xlpm.block, OFFSET( _xlpm.anchor, 0, 0, COUNTA( lstCountries ) + 1, periods ), _xlfn.BYROW( _xlpm.block, _xlfn.LAMBDA(_xlpm.row, SUM( _xlpm.row ) ) ) )} -> 13159056 | J16: {=_xlfn.LET( _xlpm.operating_flag,_xlfn.ANCHORARRAY( Time!$J18), _xlpm.w_units_anchor, Volume!$J8, _xlpm.w_units_sold, OFFSET( _xlpm.w_units_anchor, 0, 0, COUNTA( lstStores ), periods ), _xlpm.w_price_anchor, Price!$J40, _xlpm.w_price, OFFSET( _xlpm.w_price_anchor, 0, 0, COUNTA( lstStores ), periods ), _xlpm.m_units_anchor, Volume!$J18, _xlpm.m_units_sold, OFFSET( _xlpm.m_units_anchor, 0, 0, COUNTA( lstStores ), periods ), _xlpm.m_price_anchor, Price!$J50, _xlpm.m_price, OFFSET( _xlpm.m_price_anchor, 0, 0, COUNTA( lstStores ), periods ), _xlpm.a_units_anchor, Volume!$J45, _xlpm.a_units_sold, OFFSET( _xlpm.a_units_anchor, 0, 0, COUNTA( lstStores ), periods ), _xlpm.a_price_anchor, Price!$J60, _xlpm.a_price, OFFSET( _xlpm.a_price_anchor, 0, 0, COUNTA( lstStores ), periods ), _xlpm.operating_flag * ( (_xlpm.w_units_sold * _xlpm.w_price ) + (_xlpm.m_units_sold * _xlpm.m_price ) + (_xlpm.a_units_sold * _xlpm.a_price ) ) )} -> 295500 | K16: 197000 | L16: 197000 | M16: 197000 | N16: 197000 | O16: 197000 | P16: 295500 | Q16: 197000 | R16: 197000 | S16: 197000 | T16: 197000 | U16: 236400 | V16: 296977.5 | W16: 197985 | X16: 197985 | Y16: 197985 | Z16: 197985 | AA16: 197985 | AB16: 296491.61 | AC16: 197985 | AD16: 197985 | AE16: 197985 | AF16: 197985 | AG16: 237582 | AH16: 291472.73 | AI16: 198974.92 | AJ16: 198974.92 | AK16: 198974.92 | AL16: 198974.92 | AM16: 198974.92 | AN16: 289805.34 | AO16: 198974.92 | AP16: 198974.92 | AQ16: 198974.92 | AR16: 198974.92 | AS16: 238769.91 | AT16: 292343.69 | AU16: 200964.67 | AV16: 200964.67 | AW16: 200964.67 | AX16: 200964.67 | AY16: 200964.67 | AZ16: 292343.69 | BA16: 200964.67 | BB16: 200964.67 | BC16: 200964.67 | BD16: 200964.67 | BE16: 241157.61 | BF16: 299652.28 | BG16: 205988.79 | BH16: 205988.79 | BI16: 205988.79 | BJ16: 205988.79 | BK16: 205988.79 | BL16: 299652.28 | BM16: 205988.79 | BN16: 205988.79 | BO16: 205988.79 | BP16: 205988.79 | BQ16: 247186.55
E17: Italy | G17: EUR | H17: 15428200 | J17: 345750 | K17: 230500 | L17: 230500 | M17: 230500 | N17: 230500 | O17: 230500 | P17: 345750 | Q17: 230500 | R17: 230500 | S17: 230500 | T17: 230500 | U17: 276600 | V17: 347478.75 | W17: 231652.5 | X17: 231652.5 | Y17: 231652.5 | Z17: 231652.5 | AA17: 231652.5 | AB17: 347198.43 | AC17: 231652.5 | AD17: 231652.5 | AE17: 231652.5 | AF17: 231652.5 | AG17: 277983 | AH17: 345183.65 | AI17: 232810.76 | AJ17: 232810.76 | AK17: 232810.76 | AL17: 232810.76 | AM17: 232810.76 | AN17: 344221.69 | AO17: 232810.76 | AP17: 232810.76 | AQ17: 232810.76 | AR17: 232810.76 | AS17: 279372.91 | AT17: 347456.39 | AU17: 235138.87 | AV17: 235138.87 | AW17: 235138.87 | AX17: 235138.87 | AY17: 235138.87 | AZ17: 347456.39 | BA17: 235138.87 | BB17: 235138.87 | BC17: 235138.87 | BD17: 235138.87 | BE17: 282166.64 | BF17: 356142.8 | BG17: 241017.34 | BH17: 241017.34 | BI17: 241017.34 | BJ17: 241017.34 | BK17: 241017.34 | BL17: 356142.8 | BM17: 241017.34 | BN17: 241017.34 | BO17: 241017.34 | BP17: 241017.34 | BQ17: 289220.81
E18: Spain | G18: EUR | H18: 8035722.3 | J18: 180000 | K18: 120000 | L18: 120000 | M18: 120000 | N18: 120000 | O18: 120000 | P18: 180000 | Q18: 120000 | R18: 120000 | S18: 120000 | T18: 120000 | U18: 144000 | V18: 180900 | W18: 120600 | X18: 120600 | Y18: 120600 | Z18: 120600 | AA18: 120600 | AB18: 180787.87 | AC18: 120600 | AD18: 120600 | AE18: 120600 | AF18: 120600 | AG18: 144720 | AH18: 180191.5 | AI18: 121203 | AJ18: 121203 | AK18: 121203 | AL18: 121203 | AM18: 121203 | AN18: 179806.72 | AO18: 121203 | AP18: 121203 | AQ18: 121203 | AR18: 121203 | AS18: 145443.6 | AT18: 181521.78 | AU18: 122415.03 | AV18: 122415.03 | AW18: 122415.03 | AX18: 122415.03 | AY18: 122415.03 | AZ18: 181521.78 | BA18: 122415.03 | BB18: 122415.03 | BC18: 122415.03 | BD18: 122415.03 | BE18: 146898.04 | BF18: 186059.82 | BG18: 125475.41 | BH18: 125475.41 | BI18: 125475.41 | BJ18: 125475.41 | BK18: 125475.41 | BL18: 186059.82 | BM18: 125475.41 | BN18: 125475.41 | BO18: 125475.41 | BP18: 125475.41 | BQ18: 150570.49
E19: UK | G19: EUR | H19: 8122540.2 | J19: 182703.49 | K19: 121802.33 | L19: 121802.33 | M19: 121802.33 | N19: 121802.33 | O19: 121802.33 | P19: 182703.49 | Q19: 121802.33 | R19: 121802.33 | S19: 121802.33 | T19: 121802.33 | U19: 146162.79 | V19: 186021.55 | W19: 124014.37 | X19: 124014.37 | Y19: 124014.37 | Z19: 124014.37 | AA19: 124014.37 | AB19: 185838.09 | AC19: 124014.37 | AD19: 124014.37 | AE19: 124014.37 | AF19: 124014.37 | AG19: 148817.24 | AH19: 183124.67 | AI19: 123831.16 | AJ19: 123831.16 | AK19: 123831.16 | AL19: 123831.16 | AM19: 123831.16 | AN19: 182499.17 | AO19: 123831.16 | AP19: 123831.16 | AQ19: 123831.16 | AR19: 123831.16 | AS19: 148597.4 | AT19: 182119.69 | AU19: 123664.2 | AV19: 123664.2 | AW19: 123664.2 | AX19: 123664.2 | AY19: 123664.2 | AZ19: 182119.69 | BA19: 123664.2 | BB19: 123664.2 | BC19: 123664.2 | BD19: 123664.2 | BE19: 148397.04 | BF19: 181897.09 | BG19: 123513.06 | BH19: 123513.06 | BI19: 123513.06 | BJ19: 123513.06 | BK19: 123513.06 | BL19: 181897.09 | BM19: 123513.06 | BN19: 123513.06 | BO19: 123513.06 | BP19: 123513.06 | BQ19: 148215.67
E20: US | G20: EUR | H20: 6473259.2 | J20: 0 | K20: 0 | L20: 0 | M20: 57121.212 | N20: 61515.152 | O20: 65909.091 | P20: 105454.55 | Q20: 74696.97 | R20: 79090.909 | S20: 83484.848 | T20: 87878.788 | U20: 110727.27 | V20: 148004.5 | W20: 103154.65 | X20: 107639.64 | Y20: 107639.64 | Z20: 107639.64 | AA20: 107639.64 | AB20: 161286.91 | AC20: 107639.64 | AD20: 107639.64 | AE20: 107639.64 | AF20: 107639.64 | AG20: 129167.57 | AH20: 160721.5 | AI20: 108812.14 | AJ20: 108812.14 | AK20: 108812.14 | AL20: 108812.14 | AM20: 108812.14 | AN20: 160125.9 | AO20: 108812.14 | AP20: 108812.14 | AQ20: 108812.14 | AR20: 108812.14 | AS20: 130574.57 | AT20: 163340.25 | AU20: 111084.68 | AV20: 111084.68 | AW20: 111084.68 | AX20: 111084.68 | AY20: 111084.68 | AZ20: 163340.25 | BA20: 111084.68 | BB20: 111084.68 | BC20: 111084.68 | BD20: 111084.68 | BE20: 133301.62 | BF20: 162716.98 | BG20: 110660.8 | BH20: 110660.8 | BI20: 110660.8 | BJ20: 110660.8 | BK20: 110660.8 | BL20: 162716.98 | BM20: 110660.8 | BN20: 110660.8 | BO20: 110660.8 | BP20: 110660.8 | BQ20: 132792.96
E21: Canada | G21: EUR | H21: 9946468.4 | J21: 0 | K21: 0 | L21: 0 | M21: 0 | N21: 0 | O21: 0 | P21: 0 | Q21: 0 | R21: 0 | S21: 98699.664 | T21: 106291.95 | U21: 136661.07 | V21: 184620 | W21: 130772.5 | X21: 138465 | Y21: 146157.5 | Z21: 153850 | AA21: 161542.5 | AB21: 253450.68 | AC21: 176927.5 | AD21: 184620 | AE21: 184620 | AF21: 184620 | AG21: 221544 | AH21: 274240.46 | AI21: 187065.3 | AJ21: 187065.3 | AK21: 187065.3 | AL21: 187065.3 | AM21: 187065.3 | AN21: 272723.87 | AO21: 187065.3 | AP21: 187065.3 | AQ21: 187065.3 | AR21: 187065.3 | AS21: 224478.36 | AT21: 277373.03 | AU21: 190480.47 | AV21: 190480.47 | AW21: 190480.47 | AX21: 190480.47 | AY21: 190480.47 | AZ21: 277373.03 | BA21: 190480.47 | BB21: 190480.47 | BC21: 190480.47 | BD21: 190480.47 | BE21: 228576.56 | BF21: 281071.33 | BG21: 193020.21 | BH21: 193020.21 | BI21: 193020.21 | BJ21: 193020.21 | BK21: 193020.21 | BL21: 281071.33 | BM21: 193020.21 | BN21: 193020.21 | BO21: 193020.21 | BP21: 193020.21 | BQ21: 231624.25
E22: Switzerland | G22: EUR | H22: 15446099 | J22: 0 | K22: 0 | L22: 0 | M22: 0 | N22: 0 | O22: 0 | P22: 0 | Q22: 0 | R22: 0 | S22: 0 | T22: 0 | U22: 0 | V22: 0 | W22: 0 | X22: 0 | Y22: 179404.94 | Z22: 193205.32 | AA22: 207005.7 | AB22: 330941.92 | AC22: 234606.45 | AD22: 248406.83 | AE22: 262207.21 | AF22: 276007.59 | AG22: 347769.57 | AH22: 448215.6 | AI22: 316042.11 | AJ22: 329783.07 | AK22: 329783.07 | AL22: 329783.07 | AM22: 329783.07 | AN22: 487599.83 | AO22: 329783.07 | AP22: 329783.07 | AQ22: 329783.07 | AR22: 329783.07 | AS22: 395739.69 | AT22: 497323.2 | AU22: 336560.27 | AV22: 336560.27 | AW22: 336560.27 | AX22: 336560.27 | AY22: 336560.27 | AZ22: 497323.2 | BA22: 336560.27 | BB22: 336560.27 | BC22: 336560.27 | BD22: 336560.27 | BE22: 403872.32 | BF22: 500194.11 | BG22: 338503.14 | BH22: 338503.14 | BI22: 338503.14 | BJ22: 338503.14 | BK22: 338503.14 | BL22: 500194.11 | BM22: 338503.14 | BN22: 338503.14 | BO22: 338503.14 | BP22: 338503.14 | BQ22: 406203.76
E23: Russia | G23: EUR | H23: 6872532.3 | J23: 0 | K23: 0 | L23: 0 | M23: 0 | N23: 0 | O23: 0 | P23: 0 | Q23: 0 | R23: 0 | S23: 0 | T23: 0 | U23: 0 | V23: 0 | W23: 0 | X23: 0 | Y23: 0 | Z23: 0 | AA23: 0 | AB23: 0 | AC23: 0 | AD23: 0 | AE23: 94260.98 | AF23: 101511.82 | AG23: 130515.2 | AH23: 171003.54 | AI23: 122837.04 | AJ23: 130062.75 | AK23: 137288.46 | AL23: 144514.17 | AM23: 151739.88 | AN23: 234338.23 | AO23: 166191.29 | AP23: 173417 | AQ23: 173417 | AR23: 173417 | AS23: 208100.4 | AT23: 255877.41 | AU23: 173702.23 | AV23: 173702.23 | AW23: 173702.23 | AX23: 173702.23 | AY23: 173702.23 | AZ23: 255877.41 | BA23: 173702.23 | BB23: 173702.23 | BC23: 173702.23 | BD23: 173702.23 | BE23: 208442.67 | BF23: 255079.87 | BG23: 173160.82 | BH23: 173160.82 | BI23: 173160.82 | BJ23: 173160.82 | BK23: 173160.82 | BL23: 255079.87 | BM23: 173160.82 | BN23: 173160.82 | BO23: 173160.82 | BP23: 173160.82 | BQ23: 207792.98
E24: Total sales split by country | G24: EUR | H24: 83483876 | J24: {=_xlfn.LET( _xlpm.anchor, $J16, _xlpm.block, OFFSET( _xlpm.anchor, 0, 0, COUNTA( lstCountries ), periods ), _xlfn.BYCOL( _xlpm.block, _xlfn.LAMBDA(_xlpm.column, SUM( _xlpm.column ) ) ) )} -> 1003953.5 | K24: 669302.33 | L24: 669302.33 | M24: 726423.54 | N24: 730817.48 | O24: 735211.42 | P24: 1109408 | Q24: 743999.3 | R24: 748393.23 | S24: 851486.84 | T24: 863473.06 | U24: 1050551.1 | V24: 1344002.3 | W24: 908179.02 | X24: 920356.51 | Y24: 1107453.9 | Z24: 1128946.8 | AA24: 1150439.7 | AB24: 1755995.5 | AC24: 1193425.5 | AD24: 1214918.3 | AE24: 1322979.7 | AF24: 1344030.9 | AG24: 1638098.6 | AH24: 2054153.6 | AI24: 1411576.4 | AJ24: 1432543.1 | AK24: 1439768.8 | AL24: 1446994.5 | AM24: 1454220.2 | AN24: 2151120.7 | AO24: 1468671.7 | AP24: 1475897.4 | AQ24: 1475897.4 | AR24: 1475897.4 | AS24: 1771076.8 | AT24: 2197355.4 | AU24: 1494010.4 | AV24: 1494010.4 | AW24: 1494010.4 | AX24: 1494010.4 | AY24: 1494010.4 | AZ24: 2197355.4 | BA24: 1494010.4 | BB24: 1494010.4 | BC24: 1494010.4 | BD24: 1494010.4 | BE24: 1792812.5 | BF24: 2222814.3 | BG24: 1511339.6 | BH24: 1511339.6 | BI24: 1511339.6 | BJ24: 1511339.6 | BK24: 1511339.6 | BL24: 2222814.3 | BM24: 1511339.6 | BN24: 1511339.6 | BO24: 1511339.6 | BP24: 1511339.6 | BQ24: 1813607.5
A26: ANNUAL REVENUE
J28: {=_xlfn.ANCHORARRAY(Time!$J$13)} -> 2022 | K28: 2023 | L28: 2024 | M28: 2025 | N28: 2026
D30: i Total sales | G30: EUR | H30: {=_xlfn.LET( _xlpm.anchor,$J30, _xlpm.block, OFFSET( _xlpm.anchor, 0, 0, 1, periods ), _xlfn.BYROW( _xlpm.block, _xlfn.LAMBDA(_xlpm.row, SUM( _xlpm.row ) ) ) )} -> 83483876 | J30: {=MMULT(_xlfn.ANCHORARRAY( J7), --(TRANSPOSE(_xlfn.ANCHORARRAY( Time!J12) ) =_xlfn.ANCHORARRAY( Revenue!J28) ) )} -> 9902322.2 | K30: 15028827 | L30: 19057818 | M30: 19633617 | N30: 19861292
D32: ii. Total sales split by category
E33: Women's | G33: EUR | H33: {=_xlfn.LET( _xlpm.anchor,$J33, _xlpm.block, OFFSET( _xlpm.anchor, 0, 0, COUNTA( $E$10:$E$12 ) + 1, periods ), _xlfn.BYROW( _xlpm.block, _xlfn.LAMBDA(_xlpm.row, SUM( _xlpm.row ) ) ) )} -> 44332304 | J33: {=MMULT(_xlfn.ANCHORARRAY( J10), --( TRANSPOSE(_xlfn.ANCHORARRAY( Time!J12) ) =_xlfn.ANCHORARRAY( Revenue!J28) ) )} -> 5229073.5 | K33: 7932771.6 | L33: 10145021 | M33: 10449215 | N33: 10576224
E34: Men's | G34: EUR | H34: 28625015 | J34: 3391488.3 | K34: 5118676.3 | L34: 6537941.4 | M34: 6753014.2 | N34: 6823894.9
E35: Accessories | G35: EUR | H35: 10526557 | J35: 1281760.3 | K35: 1977378.9 | L35: 2374855.8 | M35: 2431388.1 | N35: 2461173.5
E36: Total sales split by category | G36: EUR | H36: 83483876 | J36: {=_xlfn.LET( _xlpm.anchor, $J33, _xlpm.block, OFFSET( _xlpm.anchor, 0, 0, COUNTA( $E$33:$E$35 ), COUNTA(_xlfn.ANCHORARRAY( J28) ) ), _xlfn.BYCOL( _xlpm.block, _xlfn.LAMBDA(_xlpm.column, SUM( _xlpm.column ) ) ) )} -> 9902322.2 | K36: 15028827 | L36: 19057818 | M36: 19633617 | N36: 19861292
D38: iii. Total sales split by country
E40: {=lstCountries} -> France | G40: EUR | H40: {=_xlfn.LET( _xlpm.anchor,$J40, _xlpm.block, OFFSET( _xlpm.anchor, 0, 0, COUNTA( lstCountries ) + 1, periods ), _xlfn.BYROW( _xlpm.block, _xlfn.LAMBDA(_xlpm.row, SUM( _xlpm.row ) ) ) )} -> 13159056 | J40: {=MMULT(_xlfn.ANCHORARRAY( J16), --(TRANSPOSE(_xlfn.ANCHORARRAY( Time!J12) ) =_xlfn.ANCHORARRAY( Revenue!J28) ) )} -> 2600400 | K40: 2612916.1 | L40: 2610822.3 | M40: 2634527.1 | N40: 2700390.2
E41: Italy | G41: EUR | H41: 15428200 | J41: 3042600 | K41: 3057532.7 | L41: 3064075.1 | M41: 3093329.3 | N41: 3170662.5
E42: Spain | G42: EUR | H42: 8035722.3 | J42: 1584000 | K42: 1591807.9 | L42: 1596268.8 | M42: 1611676.9 | N42: 1651968.8
E43: UK | G43: EUR | H43: 8122540.2 | J43: 1607790.7 | K43: 1636806.2 | L43: 1628701.7 | M43: 1625614.2 | N43: 1623627.4
E44: US | G44: EUR | H44: 6473259.2 | J44: 725878.79 | K44: 1402730.8 | L44: 1430731.3 | M44: 1459744.2 | N44: 1454174.2
E45: Canada | G45: EUR | H45: 9946468.4 | J45: 341652.68 | K45: 2121189.7 | L45: 2455030.4 | M45: 2497646.9 | N45: 2530948.8
E46: Switzerland | G46: EUR | H46: 15446099 | J46: 0 | K46: 2279555.5 | L46: 4285861.8 | M46: 4427561.1 | N46: 4453120.2
E47: Russia | G47: EUR | H47: 6872532.3 | J47: 0 | K47: 326288.01 | L47: 1986326.7 | M47: 2283517.5 | N47: 2276400.1
E48: Total sales split by country | G48: EUR | H48: 83483876 | J48: {=_xlfn.LET( _xlpm.anchor, $J40, _xlpm.block, OFFSET( _xlpm.anchor, 0, 0, COUNTA( lstCountries ), COUNTA(_xlfn.ANCHORARRAY( J28) ) ), _xlfn.BYCOL( _xlpm.block, _xlfn.LAMBDA(_xlpm.column, SUM( _xlpm.column ) ) ) )} -> 9902322.2 | K48: 15028827 | L48: 19057818 | M48: 19633617 | N48: 19861292
A50: End of schedule

Sheet Price
A1: =company -> Fashion Boutique
A2: {=topic} -> CFM Topic: Revenue | J2: {=EDATE( start_date, _xlfn.SEQUENCE( 1, periods, 0, 1 ) )} -> 44562 | K2: 44593 | L2: 44621 | M2: 44652 | N2: 44682 | O2: 44713 | P2: 44743 | Q2: 44774 | R2: 44805 | S2: 44835 | T2: 44866 | U2: 44896 | V2: 44927 | W2: 44958 | X2: 44986 | Y2: 45017 | Z2: 45047 | AA2: 45078 | AB2: 45108 | AC2: 45139 | AD2: 45170 | AE2: 45200 | AF2: 45231 | AG2: 45261 | AH2: 45292 | AI2: 45323 | AJ2: 45352 | AK2: 45383 | AL2: 45413 | AM2: 45444 | AN2: 45474 | AO2: 45505 | AP2: 45536 | AQ2: 45566 | AR2: 45597 | AS2: 45627 | AT2: 45658 | AU2: 45689 | AV2: 45717 | AW2: 45748 | AX2: 45778 | AY2: 45809 | AZ2: 45839 | BA2: 45870 | BB2: 45901 | BC2: 45931 | BD2: 45962 | BE2: 45992 | BF2: 46023 | BG2: 46054 | BH2: 46082 | BI2: 46113 | BJ2: 46143 | BK2: 46174 | BL2: 46204 | BM2: 46235 | BN2: 46266 | BO2: 46296 | BP2: 46327 | BQ2: 46357
A3: PRICE SCHEDULE | F3: Constant | G3: Unit | H3: Total | J3: {=EOMONTH( start_date, _xlfn.SEQUENCE( 1, periods, 0, 1 ) )} -> 44592 | K3: 44620 | L3: 44651 | M3: 44681 | N3: 44712 | O3: 44742 | P3: 44773 | Q3: 44804 | R3: 44834 | S3: 44865 | T3: 44895 | U3: 44926 | V3: 44957 | W3: 44985 | X3: 45016 | Y3: 45046 | Z3: 45077 | AA3: 45107 | AB3: 45138 | AC3: 45169 | AD3: 45199 | AE3: 45230 | AF3: 45260 | AG3: 45291 | AH3: 45322 | AI3: 45351 | AJ3: 45382 | AK3: 45412 | AL3: 45443 | AM3: 45473 | AN3: 45504 | AO3: 45535 | AP3: 45565 | AQ3: 45596 | AR3: 45626 | AS3: 45657 | AT3: 45688 | AU3: 45716 | AV3: 45747 | AW3: 45777 | AX3: 45808 | AY3: 45838 | AZ3: 45869 | BA3: 45900 | BB3: 45930 | BC3: 45961 | BD3: 45991 | BE3: 46022 | BF3: 46053 | BG3: 46081 | BH3: 46112 | BI3: 46142 | BJ3: 46173 | BK3: 46203 | BL3: 46234 | BM3: 46265 | BN3: 46295 | BO3: 46326 | BP3: 46356 | BQ3: 46387
A5: SECTION 4, 5 AND 7: AVERAGE LOCAL CURRENCY PRICE ADJUSTED FOR SEASONALITY AND INFLATION
D7: Women's
E8: {=lstStores} -> Paris | G8: {=INDEX( CaseData!$C$9:$E$17, MATCH(_xlfn.ANCHORARRAY( Price!E8), CaseData!$C$9:$C$17, 0 ), 3 )} -> EUR | J8: {=_xlfn.LET( _xlpm.operating_flag,_xlfn.ANCHORARRAY( Time!$J$18), _xlpm.unit_prices_table, CaseData!$B$46:$E$52, _xlpm.currency_row, CaseData!$B$46:$B$52, _xlpm.apparel_column, CaseData!$B$46:$E$46, _xlpm.current_apparel, Price!$D7, _xlpm.store_currency,_xlfn.ANCHORARRAY( Price!$G8), _xlpm.unit_price_at_store, INDEX( _xlpm.unit_prices_table, _xlfn.XMATCH( _xlpm.store_currency, _xlpm.currency_row, 0, 1 ), _xlfn.XMATCH( _xlpm.current_apparel, _xlpm.apparel_column, 0, 1 ) ), _xlpm.discount_month, CaseData!$C$58:$C$69, _xlpm.discount_percentage, CaseData!$E$58:$E$69, _xlpm.current_month,_xlfn.ANCHORARRAY( Time!J$11), _xlpm.discount, 1 - _xlfn.XLOOKUP( _xlpm.current_month, _xlpm.discount_month, _xlpm.discount_percentage, 0, 0, 1 ), _xlpm.current_year, YEAR(_xlfn.ANCHORARRAY( Time!J$9) ), _xlpm.clean_rates, IF( CaseData!$C$86:$G$91 = "n.a.", 0, CaseData!$C$86:$G$91), _xlpm.compounded_rates, _xlfn.MAKEARRAY( ROWS( _xlpm.clean_rates ), COLUMNS( _xlpm.clean_rates ), _xlfn.LAMBDA(_xlpm.i,_xlpm.j, INDEX( _xlfn.SCAN( 1, INDEX( _xlpm.clean_rates, _xlpm.i, 0 ), _xlfn.LAMBDA(_xlpm.s,_xlpm.c, _xlpm.s * ( 1 + _xlpm.c ) ) ), _xlpm.j ) ) ), _xlpm.inflation_rows, CaseData!$B$86:$B$91, _xlpm.inflation_columns, CaseData!$B$85:$G$85, _xlpm.inflation_table, _xlfn.VSTACK( _xlpm.inflation_columns, _xlfn.HSTACK( _xlpm.inflation_rows, _xlpm.compounded_rates ) ), _xlpm.inflation, INDEX( _xlpm.inflation_table, _xlfn.XMATCH( _xlpm.store_currency, _xlpm.inflation_rows, 0 ) + 1, _xlfn.XMATCH( _xlpm.current_year, _xlpm.inflation_columns, 0 ) ), _xlpm.operating_flag * _xlpm.unit_price_at_store * _xlpm.discount * _xlpm.inflation)} -> 300 | K8: 500 | L8: 500 | M8: 500 | N8: 500 | O8: 500 | P8: 300 | Q8: 500 | R8: 500 | S8: 500 | T8: 500 | U8: 400 | V8: 301.5 | W8: 502.5 | X8: 502.5 | Y8: 502.5 | Z8: 502.5 | AA8: 502.5 | AB8: 301.5 | AC8: 502.5 | AD8: 502.5 | AE8: 502.5 | AF8: 502.5 | AG8: 402 | AH8: 303.0075 | AI8: 505.0125 | AJ8: 505.0125 | AK8: 505.0125 | AL8: 505.0125 | AM8: 505.0125 | AN8: 303.0075 | AO8: 505.0125 | AP8: 505.0125 | AQ8: 505.0125 | AR8: 505.0125 | AS8: 404.01 | AT8: 306.03757 | AU8: 510.06262 | AV8: 510.06262 | AW8: 510.06262 | AX8: 510.06262 | AY8: 510.06262 | AZ8: 306.03757 | BA8: 510.06262 | BB8: 510.06262 | BC8: 510.06262 | BD8: 510.06262 | BE8: 408.0501 | BF8: 313.68851 | BG8: 522.81419 | BH8: 522.81419 | BI8: 522.81419 | BJ8: 522.81419 | BK8: 522.81419 | BL8: 313.68851 | BM8: 522.81419 | BN8: 522.81419 | BO8: 522.81419 | BP8: 522.81419 | BQ8: 418.25135
E9: Milano | G9: EUR | J9: 300 | K9: 500 | L9: 500 | M9: 500 | N9: 500 | O9: 500 | P9: 300 | Q9: 500 | R9: 500 | S9: 500 | T9: 500 | U9: 400 | V9: 301.5 | W9: 502.5 | X9: 502.5 | Y9: 502.5 | Z9: 502.5 | AA9: 502.5 | AB9: 301.5 | AC9: 502.5 | AD9: 502.5 | AE9: 502.5 | AF9: 502.5 | AG9: 402 | AH9: 303.0075 | AI9: 505.0125 | AJ9: 505.0125 | AK9: 505.0125 | AL9: 505.0125 | AM9: 505.0125 | AN9: 303.0075 | AO9: 505.0125 | AP9: 505.0125 | AQ9: 505.0125 | AR9: 505.0125 | AS9: 404.01 | AT9: 306.03757 | AU9: 510.06262 | AV9: 510.06262 | AW9: 510.06262 | AX9: 510.06262 | AY9: 510.06262 | AZ9: 306.03757 | BA9: 510.06262 | BB9: 510.06262 | BC9: 510.06262 | BD9: 510.06262 | BE9: 408.0501 | BF9: 313.68851 | BG9: 522.81419 | BH9: 522.81419 | BI9: 522.81419 | BJ9: 522.81419 | BK9: 522.81419 | BL9: 313.68851 | BM9: 522.81419 | BN9: 522.81419 | BO9: 522.81419 | BP9: 522.81419 | BQ9: 418.25135
E10: Madrid | G10: EUR | J10: 300 | K10: 500 | L10: 500 | M10: 500 | N10: 500 | O10: 500 | P10: 300 | Q10: 500 | R10: 500 | S10: 500 | T10: 500 | U10: 400 | V10: 301.5 | W10: 502.5 | X10: 502.5 | Y10: 502.5 | Z10: 502.5 | AA10: 502.5 | AB10: 301.5 | AC10: 502.5 | AD10: 502.5 | AE10: 502.5 | AF10: 502.5 | AG10: 402 | AH10: 303.0075 | AI10: 505.0125 | AJ10: 505.0125 | AK10: 505.0125 | AL10: 505.0125 | AM10: 505.0125 | AN10: 303.0075 | AO10: 505.0125 | AP10: 505.0125 | AQ10: 505.0125 | AR10: 505.0125 | AS10: 404.01 | AT10: 306.03757 | AU10: 510.06262 | AV10: 510.06262 | AW10: 510.06262 | AX10: 510.06262 | AY10: 510.06262 | AZ10: 306.03757 | BA10: 510.06262 | BB10: 510.06262 | BC10: 510.06262 | BD10: 510.06262 | BE10: 408.0501 | BF10: 313.68851 | BG10: 522.81419 | BH10: 522.81419 | BI10: 522.81419 | BJ10: 522.81419 | BK10: 522.81419 | BL10: 313.68851 | BM10: 522.81419 | BN10: 522.81419 | BO10: 522.81419 | BP10: 522.81419 | BQ10: 418.25135
E11: London | G11: GBP | J11: 255 | K11: 425 | L11: 425 | M11: 425 | N11: 425 | O11: 425 | P11: 255 | Q11: 425 | R11: 425 | S11: 425 | T11: 425 | U11: 340 | V11: 262.65 | W11: 437.75 | X11: 437.75 | Y11: 437.75 | Z11: 437.75 | AA11: 437.75 | AB11: 262.65 | AC11: 437.75 | AD11: 437.75 | AE11: 437.75 | AF11: 437.75 | AG11: 350.2 | AH11: 265.2765 | AI11: 442.1275 | AJ11: 442.1275 | AK11: 442.1275 | AL11: 442.1275 | AM11: 442.1275 | AN11: 265.2765 | AO11: 442.1275 | AP11: 442.1275 | AQ11: 442.1275 | AR11: 442.1275 | AS11: 353.702 | AT11: 267.92926 | AU11: 446.54877 | AV11: 446.54877 | AW11: 446.54877 | AX11: 446.54877 | AY11: 446.54877 | AZ11: 267.92926 | BA11: 446.54877 | BB11: 446.54877 | BC11: 446.54877 | BD11: 446.54877 | BE11: 357.23902 | BF11: 270.60856 | BG11: 451.01426 | BH11: 451.01426 | BI11: 451.01426 | BJ11: 451.01426 | BK11: 451.01426 | BL11: 270.60856 | BM11: 451.01426 | BN11: 451.01426 | BO11: 451.01426 | BP11: 451.01426 | BQ11: 360.81141
E12: New York | G12: USD | J12: 0 | K12: 0 | L12: 0 | M12: 475 | N12: 475 | O12: 475 | P12: 285 | Q12: 475 | R12: 475 | S12: 475 | T12: 475 | U12: 380 | V12: 293.55 | W12: 489.25 | X12: 489.25 | Y12: 489.25 | Z12: 489.25 | AA12: 489.25 | AB12: 293.55 | AC12: 489.25 | AD12: 489.25 | AE12: 489.25 | AF12: 489.25 | AG12: 391.4 | AH12: 299.421 | AI12: 499.035 | AJ12: 499.035 | AK12: 499.035 | AL12: 499.035 | AM12: 499.035 | AN12: 299.421 | AO12: 499.035 | AP12: 499.035 | AQ12: 499.035 | AR12: 499.035 | AS12: 399.228 | AT12: 308.40363 | AU12: 514.00605 | AV12: 514.00605 | AW12: 514.00605 | AX12: 514.00605 | AY12: 514.00605 | AZ12: 308.40363 | BA12: 514.00605 | BB12: 514.00605 | BC12: 514.00605 | BD12: 514.00605 | BE12: 411.20484 | BF12: 309.94565 | BG12: 516.57608 | BH12: 516.57608 | BI12: 516.57608 | BJ12: 516.57608 | BK12: 516.57608 | BL12: 309.94565 | BM12: 516.57608 | BN12: 516.57608 | BO12: 516.57608 | BP12: 516.57608 | BQ12: 413.26086
E13: Montreal | G13: CAD | J13: 0 | K13: 0 | L13: 0 | M13: 0 | N13: 0 | O13: 0 | P13: 0 | Q13: 0 | R13: 0 | S13: 700 | T13: 700 | U13: 560 | V13: 428.4 | W13: 714 | X13: 714 | Y13: 714 | Z13: 714 | AA13: 714 | AB13: 428.4 | AC13: 714 | AD13: 714 | AE13: 714 | AF13: 714 | AG13: 571.2 | AH13: 436.968 | AI13: 728.28 | AJ13: 728.28 | AK13: 728.28 | AL13: 728.28 | AM13: 728.28 | AN13: 436.968 | AO13: 728.28 | AP13: 728.28 | AQ13: 728.28 | AR13: 728.28 | AS13: 582.624 | AT13: 447.8922 | AU13: 746.487 | AV13: 746.487 | AW13: 746.487 | AX13: 746.487 | AY13: 746.487 | AZ13: 447.8922 | BA13: 746.487 | BB13: 746.487 | BC13: 746.487 | BD13: 746.487 | BE13: 597.1896 | BF13: 456.85004 | BG13: 761.41674 | BH13: 761.41674 | BI13: 761.41674 | BJ13: 761.41674 | BK13: 761.41674 | BL13: 456.85004 | BM13: 761.41674 | BN13: 761.41674 | BO13: 761.41674 | BP13: 761.41674 | BQ13: 609.13339
E14: Zurich | G14: CHF | J14: 0 | K14: 0 | L14: 0 | M14: 0 | N14: 0 | O14: 0 | P14: 0 | Q14: 0 | R14: 0 | S14: 0 | T14: 0 | U14: 0 | V14: 0 | W14: 0 | X14: 0 | Y14: 768.75 | Z14: 768.75 | AA14: 768.75 | AB14: 461.25 | AC14: 768.75 | AD14: 768.75 | AE14: 768.75 | AF14: 768.75 | AG14: 615 | AH14: 463.55625 | AI14: 772.59375 | AJ14: 772.59375 | AK14: 772.59375 | AL14: 772.59375 | AM14: 772.59375 | AN14: 463.55625 | AO14: 772.59375 | AP14: 772.59375 | AQ14: 772.59375 | AR14: 772.59375 | AS14: 618.075 | AT14: 477.46294 | AU14: 795.77156 | AV14: 795.77156 | AW14: 795.77156 | AX14: 795.77156 | AY14: 795.77156 | AZ14: 477.46294 | BA14: 795.77156 | BB14: 795.77156 | BC14: 795.77156 | BD14: 795.77156 | BE14: 636.61725 | BF14: 484.62488 | BG14: 807.70814 | BH14: 807.70814 | BI14: 807.70814 | BJ14: 807.70814 | BK14: 807.70814 | BL14: 484.62488 | BM14: 807.70814 | BN14: 807.70814 | BO14: 807.70814 | BP14: 807.70814 | BQ14: 646.16651
E15: Moscow | G15: RUB | J15: 0 | K15: 0 | L15: 0 | M15: 0 | N15: 0 | O15: 0 | P15: 0 | Q15: 0 | R15: 0 | S15: 0 | T15: 0 | U15: 0 | V15: 0 | W15: 0 | X15: 0 | Y15: 0 | Z15: 0 | AA15: 0 | AB15: 0 | AC15: 0 | AD15: 0 | AE15: 55550 | AF15: 55550 | AG15: 44440 | AH15: 33663.3 | AI15: 56105.5 | AJ15: 56105.5 | AK15: 56105.5 | AL15: 56105.5 | AM15: 56105.5 | AN15: 33663.3 | AO15: 56105.5 | AP15: 56105.5 | AQ15: 56105.5 | AR15: 56105.5 | AS15: 44884.4 | AT15: 34168.249 | AU15: 56947.082 | AV15: 56947.082 | AW15: 56947.082 | AX15: 56947.082 | AY15: 56947.082 | AZ15: 34168.249 | BA15: 56947.082 | BB15: 56947.082 | BC15: 56947.082 | BD15: 56947.082 | BE15: 45557.666 | BF15: 34509.932 | BG15: 57516.553 | BH15: 57516.553 | BI15: 57516.553 | BJ15: 57516.553 | BK15: 57516.553 | BL15: 34509.932 | BM15: 57516.553 | BN15: 57516.553 | BO15: 57516.553 | BP15: 57516.553 | BQ15: 46013.243
D17: Men's
E18: {=lstStores} -> Paris | G18: {=INDEX( CaseData!$C$9:$E$17, MATCH(_xlfn.ANCHORARRAY( Price!E18), CaseData!$C$9:$C$17, 0 ), 3 )} -> EUR | J18: {=_xlfn.LET( _xlpm.operating_flag,_xlfn.ANCHORARRAY( Time!$J$18), _xlpm.unit_prices_table, CaseData!$B$46:$E$52, _xlpm.currency_row, CaseData!$B$46:$B$52, _xlpm.apparel_column, CaseData!$B$46:$E$46, _xlpm.current_apparel, Price!$D17, _xlpm.store_currency,_xlfn.ANCHORARRAY( Price!$G18), _xlpm.unit_price_at_store, INDEX( _xlpm.unit_prices_table, _xlfn.XMATCH( _xlpm.store_currency, _xlpm.currency_row, 0, 1 ), _xlfn.XMATCH( _xlpm.current_apparel, _xlpm.apparel_column, 0, 1 ) ), _xlpm.discount_month, CaseData!$C$58:$C$69, _xlpm.discount_percentage, CaseData!$E$58:$E$69, _xlpm.current_month,_xlfn.ANCHORARRAY( Time!J$11), _xlpm.discount, 1 - _xlfn.XLOOKUP( _xlpm.current_month, _xlpm.discount_month, _xlpm.discount_percentage, 0, 0, 1 ), _xlpm.current_year, YEAR(_xlfn.ANCHORARRAY( Time!J$9) ), _xlpm.clean_rates, IF( CaseData!$C$86:$G$91 = "n.a.", 0, CaseData!$C$86:$G$91), _xlpm.compounded_rates, _xlfn.MAKEARRAY( ROWS( _xlpm.clean_rates ), COLUMNS( _xlpm.clean_rates ), _xlfn.LAMBDA(_xlpm.i,_xlpm.j, INDEX( _xlfn.SCAN( 1, INDEX( _xlpm.clean_rates, _xlpm.i, 0 ), _xlfn.LAMBDA(_xlpm.s,_xlpm.c, _xlpm.s * ( 1 + _xlpm.c ) ) ), _xlpm.j ) ) ), _xlpm.inflation_rows, CaseData!$B$86:$B$91, _xlpm.inflation_columns, CaseData!$B$85:$G$85, _xlpm.inflation_table, _xlfn.VSTACK( _xlpm.inflation_columns, _xlfn.HSTACK( _xlpm.inflation_rows, _xlpm.compounded_rates ) ), _xlpm.inflation, INDEX( _xlpm.inflation_table, _xlfn.XMATCH( _xlpm.store_currency, _xlpm.inflation_rows, 0 ) + 1, _xlfn.XMATCH( _xlpm.current_year, _xlpm.inflation_columns, 0 ) ), _xlpm.operating_flag * _xlpm.unit_price_at_store * _xlpm.discount * _xlpm.inflation)} -> 240 | K18: 400 | L18: 400 | M18: 400 | N18: 400 | O18: 400 | P18: 240 | Q18: 400 | R18: 400 | S18: 400 | T18: 400 | U18: 320 | V18: 241.2 | W18: 402 | X18: 402 | Y18: 402 | Z18: 402 | AA18: 402 | AB18: 241.2 | AC18: 402 | AD18: 402 | AE18: 402 | AF18: 402 | AG18: 321.6 | AH18: 242.406 | AI18: 404.01 | AJ18: 404.01 | AK18: 404.01 | AL18: 404.01 | AM18: 404.01 | AN18: 242.406 | AO18: 404.01 | AP18: 404.01 | AQ18: 404.01 | AR18: 404.01 | AS18: 323.208 | AT18: 244.83006 | AU18: 408.0501 | AV18: 408.0501 | AW18: 408.0501 | AX18: 408.0501 | AY18: 408.0501 | AZ18: 244.83006 | BA18: 408.0501 | BB18: 408.0501 | BC18: 408.0501 | BD18: 408.0501 | BE18: 326.44008 | BF18: 250.95081 | BG18: 418.25135 | BH18: 418.25135 | BI18: 418.25135 | BJ18: 418.25135 | BK18: 418.25135 | BL18: 250.95081 | BM18: 418.25135 | BN18: 418.25135 | BO18: 418.25135 | BP18: 418.25135 | BQ18: 334.60108
E19: Milano | G19: EUR | J19: 240 | K19: 400 | L19: 400 | M19: 400 | N19: 400 | O19: 400 | P19: 240 | Q19: 400 | R19: 400 | S19: 400 | T19: 400 | U19: 320 | V19: 241.2 | W19: 402 | X19: 402 | Y19: 402 | Z19: 402 | AA19: 402 | AB19: 241.2 | AC19: 402 | AD19: 402 | AE19: 402 | AF19: 402 | AG19: 321.6 | AH19: 242.406 | AI19: 404.01 | AJ19: 404.01 | AK19: 404.01 | AL19: 404.01 | AM19: 404.01 | AN19: 242.406 | AO19: 404.01 | AP19: 404.01 | AQ19: 404.01 | AR19: 404.01 | AS19: 323.208 | AT19: 244.83006 | AU19: 408.0501 | AV19: 408.0501 | AW19: 408.0501 | AX19: 408.0501 | AY19: 408.0501 | AZ19: 244.83006 | BA19: 408.0501 | BB19: 408.0501 | BC19: 408.0501 | BD19: 408.0501 | BE19: 326.44008 | BF19: 250.95081 | BG19: 418.25135 | BH19: 418.25135 | BI19: 418.25135 | BJ19: 418.25135 | BK19: 418.25135 | BL19: 250.95081 | BM19: 418.25135 | BN19: 418.25135 | BO19: 418.25135 | BP19: 418.25135 | BQ19: 334.60108
E20: Madrid | G20: EUR | J20: 240 | K20: 400 | L20: 400 | M20: 400 | N20: 400 | O20: 400 | P20: 240 | Q20: 400 | R20: 400 | S20: 400 | T20: 400 | U20: 320 | V20: 241.2 | W20: 402 | X20: 402 | Y20: 402 | Z20: 402 | AA20: 402 | AB20: 241.2 | AC20: 402 | AD20: 402 | AE20: 402 | AF20: 402 | AG20: 321.6 | AH20: 242.406 | AI20: 404.01 | AJ20: 404.01 | AK20: 404.01 | AL20: 404.01 | AM20: 404.01 | AN20: 242.406 | AO20: 404.01 | AP20: 404.01 | AQ20: 404.01 | AR20: 404.01 | AS20: 323.208 | AT20: 244.83006 | AU20: 408.0501 | AV20: 408.0501 | AW20: 408.0501 | AX20: 408.0501 | AY20: 408.0501 | AZ20: 244.83006 | BA20: 408.0501 | BB20: 408.0501 | BC20: 408.0501 | BD20: 408.0501 | BE20: 326.44008 | BF20: 250.95081 | BG20: 418.25135 | BH20: 418.25135 | BI20: 418.25135 | BJ20: 418.25135 | BK20: 418.25135 | BL20: 250.95081 | BM20: 418.25135 | BN20: 418.25135 | BO20: 418.25135 | BP20: 418.25135 | BQ20: 334.60108
E21: London | G21: GBP | J21: 210 | K21: 350 | L21: 350 | M21: 350 | N21: 350 | O21: 350 | P21: 210 | Q21: 350 | R21: 350 | S21: 350 | T21: 350 | U21: 280 | V21: 216.3 | W21: 360.5 | X21: 360.5 | Y21: 360.5 | Z21: 360.5 | AA21: 360.5 | AB21: 216.3 | AC21: 360.5 | AD21: 360.5 | AE21: 360.5 | AF21: 360.5 | AG21: 288.4 | AH21: 218.463 | AI21: 364.105 | AJ21: 364.105 | AK21: 364.105 | AL21: 364.105 | AM21: 364.105 | AN21: 218.463 | AO21: 364.105 | AP21: 364.105 | AQ21: 364.105 | AR21: 364.105 | AS21: 291.284 | AT21: 220.64763 | AU21: 367.74605 | AV21: 367.74605 | AW21: 367.74605 | AX21: 367.74605 | AY21: 367.74605 | AZ21: 220.64763 | BA21: 367.74605 | BB21: 367.74605 | BC21: 367.74605 | BD21: 367.74605 | BE21: 294.19684 | BF21: 222.85411 | BG21: 371.42351 | BH21: 371.42351 | BI21: 371.42351 | BJ21: 371.42351 | BK21: 371.42351 | BL21: 222.85411 | BM21: 371.42351 | BN21: 371.42351 | BO21: 371.42351 | BP21: 371.42351 | BQ21: 297.13881
E22: New York | G22: USD | J22: 0 | K22: 0 | L22: 0 | M22: 375 | N22: 375 | O22: 375 | P22: 225 | Q22: 375 | R22: 375 | S22: 375 | T22: 375 | U22: 300 | V22: 231.75 | W22: 386.25 | X22: 386.25 | Y22: 386.25 | Z22: 386.25 | AA22: 386.25 | AB22: 231.75 | AC22: 386.25 | AD22: 386.25 | AE22: 386.25 | AF22: 386.25 | AG22: 309 | AH22: 236.385 | AI22: 393.975 | AJ22: 393.975 | AK22: 393.975 | AL22: 393.975 | AM22: 393.975 | AN22: 236.385 | AO22: 393.975 | AP22: 393.975 | AQ22: 393.975 | AR22: 393.975 | AS22: 315.18 | AT22: 243.47655 | AU22: 405.79425 | AV22: 405.79425 | AW22: 405.79425 | AX22: 405.79425 | AY22: 405.79425 | AZ22: 243.47655 | BA22: 405.79425 | BB22: 405.79425 | BC22: 405.79425 | BD22: 405.79425 | BE22: 324.6354 | BF22: 244.69393 | BG22: 407.82322 | BH22: 407.82322 | BI22: 407.82322 | BJ22: 407.82322 | BK22: 407.82322 | BL22: 244.69393 | BM22: 407.82322 | BN22: 407.82322 | BO22: 407.82322 | BP22: 407.82322 | BQ22: 326.25858
E23: Montreal | G23: CAD | J23: 0 | K23: 0 | L23: 0 | M23: 0 | N23: 0 | O23: 0 | P23: 0 | Q23: 0 | R23: 0 | S23: 550 | T23: 550 | U23: 440 | V23: 336.6 | W23: 561 | X23: 561 | Y23: 561 | Z23: 561 | AA23: 561 | AB23: 336.6 | AC23: 561 | AD23: 561 | AE23: 561 | AF23: 561 | AG23: 448.8 | AH23: 343.332 | AI23: 572.22 | AJ23: 572.22 | AK23: 572.22 | AL23: 572.22 | AM23: 572.22 | AN23: 343.332 | AO23: 572.22 | AP23: 572.22 | AQ23: 572.22 | AR23: 572.22 | AS23: 457.776 | AT23: 351.9153 | AU23: 586.5255 | AV23: 586.5255 | AW23: 586.5255 | AX23: 586.5255 | AY23: 586.5255 | AZ23: 351.9153 | BA23: 586.5255 | BB23: 586.5255 | BC23: 586.5255 | BD23: 586.5255 | BE23: 469.2204 | BF23: 358.95361 | BG23: 598.25601 | BH23: 598.25601 | BI23: 598.25601 | BJ23: 598.25601 | BK23: 598.25601 | BL23: 358.95361 | BM23: 598.25601 | BN23: 598.25601 | BO23: 598.25601 | BP23: 598.25601 | BQ23: 478.60481
E24: Zurich | G24: CHF | J24: 0 | K24: 0 | L24: 0 | M24: 0 | N24: 0 | O24: 0 | P24: 0 | Q24: 0 | R24: 0 | S24: 0 | T24: 0 | U24: 0 | V24: 0 | W24: 0 | X24: 0 | Y24: 615 | Z24: 615 | AA24: 615 | AB24: 369 | AC24: 615 | AD24: 615 | AE24: 615 | AF24: 615 | AG24: 492 | AH24: 370.845 | AI24: 618.075 | AJ24: 618.075 | AK24: 618.075 | AL24: 618.075 | AM24: 618.075 | AN24: 370.845 | AO24: 618.075 | AP24: 618.075 | AQ24: 618.075 | AR24: 618.075 | AS24: 494.46 | AT24: 381.97035 | AU24: 636.61725 | AV24: 636.61725 | AW24: 636.61725 | AX24: 636.61725 | AY24: 636.61725 | AZ24: 381.97035 | BA24: 636.61725 | BB24: 636.61725 | BC24: 636.61725 | BD24: 636.61725 | BE24: 509.2938 | BF24: 387.69991 | BG24: 646.16651 | BH24: 646.16651 | BI24: 646.16651 | BJ24: 646.16651 | BK24: 646.16651 | BL24: 387.69991 | BM24: 646.16651 | BN24: 646.16651 | BO24: 646.16651 | BP24: 646.16651 | BQ24: 516.93321
E25: Moscow | G25: RUB | J25: 0 | K25: 0 | L25: 0 | M25: 0 | N25: 0 | O25: 0 | P25: 0 | Q25: 0 | R25: 0 | S25: 0 | T25: 0 | U25: 0 | V25: 0 | W25: 0 | X25: 0 | Y25: 0 | Z25: 0 | AA25: 0 | AB25: 0 | AC25: 0 | AD25: 0 | AE25: 40400 | AF25: 40400 | AG25: 32320 | AH25: 24482.4 | AI25: 40804 | AJ25: 40804 | AK25: 40804 | AL25: 40804 | AM25: 40804 | AN25: 24482.4 | AO25: 40804 | AP25: 40804 | AQ25: 40804 | AR25: 40804 | AS25: 32643.2 | AT25: 24849.636 | AU25: 41416.06 | AV25: 41416.06 | AW25: 41416.06 | AX25: 41416.06 | AY25: 41416.06 | AZ25: 24849.636 | BA25: 41416.06 | BB25: 41416.06 | BC25: 41416.06 | BD25: 41416.06 | BE25: 33132.848 | BF25: 25098.132 | BG25: 41830.221 | BH25: 41830.221 | BI25: 41830.221 | BJ25: 41830.221 | BK25: 41830.221 | BL25: 25098.132 | BM25: 41830.221 | BN25: 41830.221 | BO25: 41830.221 | BP25: 41830.221 | BQ25: 33464.176
D27: Accessories
E28: {=lstStores} -> Paris | G28: {=INDEX( CaseData!$C$9:$E$17, MATCH(_xlfn.ANCHORARRAY( Price!E28), CaseData!$C$9:$C$17, 0 ), 3 )} -> EUR | J28: {=_xlfn.LET( _xlpm.operating_flag,_xlfn.ANCHORARRAY( Time!$J$18), _xlpm.unit_prices_table, CaseData!$B$46:$E$52, _xlpm.currency_row, CaseData!$B$46:$B$52, _xlpm.apparel_column, CaseData!$B$46:$E$46, _xlpm.current_apparel, Price!$D27, _xlpm.store_currency,_xlfn.ANCHORARRAY( Price!$G28), _xlpm.unit_price_at_store, INDEX( _xlpm.unit_prices_table, _xlfn.XMATCH( _xlpm.store_currency, _xlpm.currency_row, 0, 1 ), _xlfn.XMATCH( _xlpm.current_apparel, _xlpm.apparel_column, 0, 1 ) ), _xlpm.discount_month, CaseData!$C$58:$C$69, _xlpm.discount_percentage, CaseData!$E$58:$E$69, _xlpm.current_month,_xlfn.ANCHORARRAY( Time!J$11), _xlpm.discount, 1 - _xlfn.XLOOKUP( _xlpm.current_month, _xlpm.discount_month, _xlpm.discount_percentage, 0, 0, 1 ), _xlpm.current_year, YEAR(_xlfn.ANCHORARRAY( Time!J$9) ), _xlpm.clean_rates, IF( CaseData!$C$86:$G$91 = "n.a.", 0, CaseData!$C$86:$G$91), _xlpm.compounded_rates, _xlfn.MAKEARRAY( ROWS( _xlpm.clean_rates ), COLUMNS( _xlpm.clean_rates ), _xlfn.LAMBDA(_xlpm.i,_xlpm.j, INDEX( _xlfn.SCAN( 1, INDEX( _xlpm.clean_rates, _xlpm.i, 0 ), _xlfn.LAMBDA(_xlpm.s,_xlpm.c, _xlpm.s * ( 1 + _xlpm.c ) ) ), _xlpm.j ) ) ), _xlpm.inflation_rows, CaseData!$B$86:$B$91, _xlpm.inflation_columns, CaseData!$B$85:$G$85, _xlpm.inflation_table, _xlfn.VSTACK( _xlpm.inflation_columns, _xlfn.HSTACK( _xlpm.inflation_rows, _xlpm.compounded_rates ) ), _xlpm.inflation, INDEX( _xlpm.inflation_table, _xlfn.XMATCH( _xlpm.store_currency, _xlpm.inflation_rows, 0 ) + 1, _xlfn.XMATCH( _xlpm.current_year, _xlpm.inflation_columns, 0 ) ), _xlpm.operating_flag * _xlpm.unit_price_at_store * _xlpm.discount * _xlpm.inflation)} -> 90 | K28: 150 | L28: 150 | M28: 150 | N28: 150 | O28: 150 | P28: 90 | Q28: 150 | R28: 150 | S28: 150 | T28: 150 | U28: 120 | V28: 90.45 | W28: 150.75 | X28: 150.75 | Y28: 150.75 | Z28: 150.75 | AA28: 150.75 | AB28: 90.45 | AC28: 150.75 | AD28: 150.75 | AE28: 150.75 | AF28: 150.75 | AG28: 120.6 | AH28: 90.90225 | AI28: 151.50375 | AJ28: 151.50375 | AK28: 151.50375 | AL28: 151.50375 | AM28: 151.50375 | AN28: 90.90225 | AO28: 151.50375 | AP28: 151.50375 | AQ28: 151.50375 | AR28: 151.50375 | AS28: 121.203 | AT28: 91.811272 | AU28: 153.01879 | AV28: 153.01879 | AW28: 153.01879 | AX28: 153.01879 | AY28: 153.01879 | AZ28: 91.811272 | BA28: 153.01879 | BB28: 153.01879 | BC28: 153.01879 | BD28: 153.01879 | BE28: 122.41503 | BF28: 94.106554 | BG28: 156.84426 | BH28: 156.84426 | BI28: 156.84426 | BJ28: 156.84426 | BK28: 156.84426 | BL28: 94.106554 | BM28: 156.84426 | BN28: 156.84426 | BO28: 156.84426 | BP28: 156.84426 | BQ28: 125.47541
E29: Milano | G29: EUR | J29: 90 | K29: 150 | L29: 150 | M29: 150 | N29: 150 | O29: 150 | P29: 90 | Q29: 150 | R29: 150 | S29: 150 | T29: 150 | U29: 120 | V29: 90.45 | W29: 150.75 | X29: 150.75 | Y29: 150.75 | Z29: 150.75 | AA29: 150.75 | AB29: 90.45 | AC29: 150.75 | AD29: 150.75 | AE29: 150.75 | AF29: 150.75 | AG29: 120.6 | AH29: 90.90225 | AI29: 151.50375 | AJ29: 151.50375 | AK29: 151.50375 | AL29: 151.50375 | AM29: 151.50375 | AN29: 90.90225 | AO29: 151.50375 | AP29: 151.50375 | AQ29: 151.50375 | AR29: 151.50375 | AS29: 121.203 | AT29: 91.811272 | AU29: 153.01879 | AV29: 153.01879 | AW29: 153.01879 | AX29: 153.01879 | AY29: 153.01879 | AZ29: 91.811272 | BA29: 153.01879 | BB29: 153.01879 | BC29: 153.01879 | BD29: 153.01879 | BE29: 122.41503 | BF29: 94.106554 | BG29: 156.84426 | BH29: 156.84426 | BI29: 156.84426 | BJ29: 156.84426 | BK29: 156.84426 | BL29: 94.106554 | BM29: 156.84426 | BN29: 156.84426 | BO29: 156.84426 | BP29: 156.84426 | BQ29: 125.47541
E30: Madrid | G30: EUR | J30: 90 | K30: 150 | L30: 150 | M30: 150 | N30: 150 | O30: 150 | P30: 90 | Q30: 150 | R30: 150 | S30: 150 | T30: 150 | U30: 120 | V30: 90.45 | W30: 150.75 | X30: 150.75 | Y30: 150.75 | Z30: 150.75 | AA30: 150.75 | AB30: 90.45 | AC30: 150.75 | AD30: 150.75 | AE30: 150.75 | AF30: 150.75 | AG30: 120.6 | AH30: 90.90225 | AI30: 151.50375 | AJ30: 151.50375 | AK30: 151.50375 | AL30: 151.50375 | AM30: 151.50375 | AN30: 90.90225 | AO30: 151.50375 | AP30: 151.50375 | AQ30: 151.50375 | AR30: 151.50375 | AS30: 121.203 | AT30: 91.811272 | AU30: 153.01879 | AV30: 153.01879 | AW30: 153.01879 | AX30: 153.01879 | AY30: 153.01879 | AZ30: 91.811272 | BA30: 153.01879 | BB30: 153.01879 | BC30: 153.01879 | BD30: 153.01879 | BE30: 122.41503 | BF30: 94.106554 | BG30: 156.84426 | BH30: 156.84426 | BI30: 156.84426 | BJ30: 156.84426 | BK30: 156.84426 | BL30: 94.106554 | BM30: 156.84426 | BN30: 156.84426 | BO30: 156.84426 | BP30: 156.84426 | BQ30: 125.47541
E31: London | G31: GBP | J31: 75 | K31: 125 | L31: 125 | M31: 125 | N31: 125 | O31: 125 | P31: 75 | Q31: 125 | R31: 125 | S31: 125 | T31: 125 | U31: 100 | V31: 77.25 | W31: 128.75 | X31: 128.75 | Y31: 128.75 | Z31: 128.75 | AA31: 128.75 | AB31: 77.25 | AC31: 128.75 | AD31: 128.75 | AE31: 128.75 | AF31: 128.75 | AG31: 103 | AH31: 78.0225 | AI31: 130.0375 | AJ31: 130.0375 | AK31: 130.0375 | AL31: 130.0375 | AM31: 130.0375 | AN31: 78.0225 | AO31: 130.0375 | AP31: 130.0375 | AQ31: 130.0375 | AR31: 130.0375 | AS31: 104.03 | AT31: 78.802725 | AU31: 131.33787 | AV31: 131.33787 | AW31: 131.33787 | AX31: 131.33787 | AY31: 131.33787 | AZ31: 78.802725 | BA31: 131.33787 | BB31: 131.33787 | BC31: 131.33787 | BD31: 131.33787 | BE31: 105.0703 | BF31: 79.590752 | BG31: 132.65125 | BH31: 132.65125 | BI31: 132.65125 | BJ31: 132.65125 | BK31: 132.65125 | BL31: 79.590752 | BM31: 132.65125 | BN31: 132.65125 | BO31: 132.65125 | BP31: 132.65125 | BQ31: 106.121
E32: New York | G32: USD | J32: 0 | K32: 0 | L32: 0 | M32: 150 | N32: 150 | O32: 150 | P32: 90 | Q32: 150 | R32: 150 | S32: 150 | T32: 150 | U32: 120 | V32: 92.7 | W32: 154.5 | X32: 154.5 | Y32: 154.5 | Z32: 154.5 | AA32: 154.5 | AB32: 92.7 | AC32: 154.5 | AD32: 154.5 | AE32: 154.5 | AF32: 154.5 | AG32: 123.6 | AH32: 94.554 | AI32: 157.59 | AJ32: 157.59 | AK32: 157.59 | AL32: 157.59 | AM32: 157.59 | AN32: 94.554 | AO32: 157.59 | AP32: 157.59 | AQ32: 157.59 | AR32: 157.59 | AS32: 126.072 | AT32: 97.39062 | AU32: 162.3177 | AV32: 162.3177 | AW32: 162.3177 | AX32: 162.3177 | AY32: 162.3177 | AZ32: 97.39062 | BA32: 162.3177 | BB32: 162.3177 | BC32: 162.3177 | BD32: 162.3177 | BE32: 129.85416 | BF32: 97.877573 | BG32: 163.12929 | BH32: 163.12929 | BI32: 163.12929 | BJ32: 163.12929 | BK32: 163.12929 | BL32: 97.877573 | BM32: 163.12929 | BN32: 163.12929 | BO32: 163.12929 | BP32: 163.12929 | BQ32: 130.50343
E33: Montreal | G33: CAD | J33: 0 | K33: 0 | L33: 0 | M33: 0 | N33: 0 | O33: 0 | P33: 0 | Q33: 0 | R33: 0 | S33: 200 | T33: 200 | U33: 160 | V33: 122.4 | W33: 204 | X33: 204 | Y33: 204 | Z33: 204 | AA33: 204 | AB33: 122.4 | AC33: 204 | AD33: 204 | AE33: 204 | AF33: 204 | AG33: 163.2 | AH33: 124.848 | AI33: 208.08 | AJ33: 208.08 | AK33: 208.08 | AL33: 208.08 | AM33: 208.08 | AN33: 124.848 | AO33: 208.08 | AP33: 208.08 | AQ33: 208.08 | AR33: 208.08 | AS33: 166.464 | AT33: 127.9692 | AU33: 213.282 | AV33: 213.282 | AW33: 213.282 | AX33: 213.282 | AY33: 213.282 | AZ33: 127.9692 | BA33: 213.282 | BB33: 213.282 | BC33: 213.282 | BD33: 213.282 | BE33: 170.6256 | BF33: 130.52858 | BG33: 217.54764 | BH33: 217.54764 | BI33: 217.54764 | BJ33: 217.54764 | BK33: 217.54764 | BL33: 130.52858 | BM33: 217.54764 | BN33: 217.54764 | BO33: 217.54764 | BP33: 217.54764 | BQ33: 174.03811
E34: Zurich | G34: CHF | J34: 0 | K34: 0 | L34: 0 | M34: 0 | N34: 0 | O34: 0 | P34: 0 | Q34: 0 | R34: 0 | S34: 0 | T34: 0 | U34: 0 | V34: 0 | W34: 0 | X34: 0 | Y34: 230.625 | Z34: 230.625 | AA34: 230.625 | AB34: 138.375 | AC34: 230.625 | AD34: 230.625 | AE34: 230.625 | AF34: 230.625 | AG34: 184.5 | AH34: 139.06687 | AI34: 231.77812 | AJ34: 231.77812 | AK34: 231.77812 | AL34: 231.77812 | AM34: 231.77812 | AN34: 139.06687 | AO34: 231.77812 | AP34: 231.77812 | AQ34: 231.77812 | AR34: 231.77812 | AS34: 185.4225 | AT34: 143.23888 | AU34: 238.73147 | AV34: 238.73147 | AW34: 238.73147 | AX34: 238.73147 | AY34: 238.73147 | AZ34: 143.23888 | BA34: 238.73147 | BB34: 238.73147 | BC34: 238.73147 | BD34: 238.73147 | BE34: 190.98517 | BF34: 145.38746 | BG34: 242.31244 | BH34: 242.31244 | BI34: 242.31244 | BJ34: 242.31244 | BK34: 242.31244 | BL34: 145.38746 | BM34: 242.31244 | BN34: 242.31244 | BO34: 242.31244 | BP34: 242.31244 | BQ34: 193.84995
E35: Moscow | G35: RUB | J35: 0 | K35: 0 | L35: 0 | M35: 0 | N35: 0 | O35: 0 | P35: 0 | Q35: 0 | R35: 0 | S35: 0 | T35: 0 | U35: 0 | V35: 0 | W35: 0 | X35: 0 | Y35: 0 | Z35: 0 | AA35: 0 | AB35: 0 | AC35: 0 | AD35: 0 | AE35: 15150 | AF35: 15150 | AG35: 12120 | AH35: 9180.9 | AI35: 15301.5 | AJ35: 15301.5 | AK35: 15301.5 | AL35: 15301.5 | AM35: 15301.5 | AN35: 9180.9 | AO35: 15301.5 | AP35: 15301.5 | AQ35: 15301.5 | AR35: 15301.5 | AS35: 12241.2 | AT35: 9318.6135 | AU35: 15531.022 | AV35: 15531.022 | AW35: 15531.022 | AX35: 15531.022 | AY35: 15531.022 | AZ35: 9318.6135 | BA35: 15531.022 | BB35: 15531.022 | BC35: 15531.022 | BD35: 15531.022 | BE35: 12424.818 | BF35: 9411.7996 | BG35: 15686.333 | BH35: 15686.333 | BI35: 15686.333 | BJ35: 15686.333 | BK35: 15686.333 | BL35: 9411.7996 | BM35: 15686.333 | BN35: 15686.333 | BO35: 15686.333 | BP35: 15686.333 | BQ35: 12549.066
A37: SECTION 6: AVERAGE PRICE IN CONSOLIDATION CURRENCY
D39: Women's
E40: {=lstStores} -> Paris | F40: {=INDEX( CaseData!$C$9:$E$17, MATCH(_xlfn.ANCHORARRAY( Price!E40), CaseData!$C$9:$C$17, 0 ), 3 )} -> EUR | G40: EUR | J40: {=_xlfn.LET( _xlpm.operating_flag,_xlfn.ANCHORARRAY( Time!J$18), _xlpm.fx_table, CaseData!$B$74:$G$80, _xlpm.fx_row, CaseData!$B$74:$B$80, _xlpm.fx_column, CaseData!$B$74:$G$74, _xlpm.store_currency,_xlfn.ANCHORARRAY( Price!$F40), _xlpm.current_year, YEAR(_xlfn.ANCHORARRAY( Time!J$9) ), _xlpm.fx_rate, INDEX( _xlpm.fx_table, _xlfn.XMATCH( _xlpm.store_currency, _xlpm.fx_row, 0, 1 ), _xlfn.XMATCH( _xlpm.current_year, _xlpm.fx_column, 0, 1 ) ), _xlpm.anchor,_xlfn.ANCHORARRAY( Price!$J8), _xlpm.block, OFFSET( _xlpm.anchor, 0, 0, COUNTA( _xlpm.store_currency ), periods ), _xlpm.block / _xlpm.fx_rate )} -> 300 | K40: 500 | L40: 500 | M40: 500 | N40: 500 | O40: 500 | P40: 300 | Q40: 500 | R40: 500 | S40: 500 | T40: 500 | U40: 400 | V40: 301.5 | W40: 502.5 | X40: 502.5 | Y40: 502.5 | Z40: 502.5 | AA40: 502.5 | AB40: 301.5 | AC40: 502.5 | AD40: 502.5 | AE40: 502.5 | AF40: 502.5 | AG40: 402 | AH40: 303.0075 | AI40: 505.0125 | AJ40: 505.0125 | AK40: 505.0125 | AL40: 505.0125 | AM40: 505.0125 | AN40: 303.0075 | AO40: 505.0125 | AP40: 505.0125 | AQ40: 505.0125 | AR40: 505.0125 | AS40: 404.01 | AT40: 306.03757 | AU40: 510.06262 | AV40: 510.06262 | AW40: 510.06262 | AX40: 510.06262 | AY40: 510.06262 | AZ40: 306.03757 | BA40: 510.06262 | BB40: 510.06262 | BC40: 510.06262 | BD40: 510.06262 | BE40: 408.0501 | BF40: 313.68851 | BG40: 522.81419 | BH40: 522.81419 | BI40: 522.81419 | BJ40: 522.81419 | BK40: 522.81419 | BL40: 313.68851 | BM40: 522.81419 | BN40: 522.81419 | BO40: 522.81419 | BP40: 522.81419 | BQ40: 418.25135
E41: Milano | F41: EUR | G41: EUR | J41: 300 | K41: 500 | L41: 500 | M41: 500 | N41: 500 | O41: 500 | P41: 300 | Q41: 500 | R41: 500 | S41: 500 | T41: 500 | U41: 400 | V41: 301.5 | W41: 502.5 | X41: 502.5 | Y41: 502.5 | Z41: 502.5 | AA41: 502.5 | AB41: 301.5 | AC41: 502.5 | AD41: 502.5 | AE41: 502.5 | AF41: 502.5 | AG41: 402 | AH41: 303.0075 | AI41: 505.0125 | AJ41: 505.0125 | AK41: 505.0125 | AL41: 505.0125 | AM41: 505.0125 | AN41: 303.0075 | AO41: 505.0125 | AP41: 505.0125 | AQ41: 505.0125 | AR41: 505.0125 | AS41: 404.01 | AT41: 306.03757 | AU41: 510.06262 | AV41: 510.06262 | AW41: 510.06262 | AX41: 510.06262 | AY41: 510.06262 | AZ41: 306.03757 | BA41: 510.06262 | BB41: 510.06262 | BC41: 510.06262 | BD41: 510.06262 | BE41: 408.0501 | BF41: 313.68851 | BG41: 522.81419 | BH41: 522.81419 | BI41: 522.81419 | BJ41: 522.81419 | BK41: 522.81419 | BL41: 313.68851 | BM41: 522.81419 | BN41: 522.81419 | BO41: 522.81419 | BP41: 522.81419 | BQ41: 418.25135
E42: Madrid | F42: EUR | G42: EUR | J42: 300 | K42: 500 | L42: 500 | M42: 500 | N42: 500 | O42: 500 | P42: 300 | Q42: 500 | R42: 500 | S42: 500 | T42: 500 | U42: 400 | V42: 301.5 | W42: 502.5 | X42: 502.5 | Y42: 502.5 | Z42: 502.5 | AA42: 502.5 | AB42: 301.5 | AC42: 502.5 | AD42: 502.5 | AE42: 502.5 | AF42: 502.5 | AG42: 402 | AH42: 303.0075 | AI42: 505.0125 | AJ42: 505.0125 | AK42: 505.0125 | AL42: 505.0125 | AM42: 505.0125 | AN42: 303.0075 | AO42: 505.0125 | AP42: 505.0125 | AQ42: 505.0125 | AR42: 505.0125 | AS42: 404.01 | AT42: 306.03757 | AU42: 510.06262 | AV42: 510.06262 | AW42: 510.06262 | AX42: 510.06262 | AY42: 510.06262 | AZ42: 306.03757 | BA42: 510.06262 | BB42: 510.06262 | BC42: 510.06262 | BD42: 510.06262 | BE42: 408.0501 | BF42: 313.68851 | BG42: 522.81419 | BH42: 522.81419 | BI42: 522.81419 | BJ42: 522.81419 | BK42: 522.81419 | BL42: 313.68851 | BM42: 522.81419 | BN42: 522.81419 | BO42: 522.81419 | BP42: 522.81419 | BQ42: 418.25135
