Workbook
Name company: CaseData!$B$2
Name ModelStartDate: CaseData!$H$8
Name periods: CaseData!$H$9
Name production: Time!$F$28:$F$30
Name production_selector: Time!$F$31
Name subscription: Time!$F$33:$F$35
Name subscription_selector: Time!$F$36
Name topic: "CFM Topic: " & CaseData!$Q$2

Sheet Cover
E15: =company -> Domestique Rides Inc.
E16: {=topic} -> CFM Topic: Revenue

Sheet Executive Summary
A1: =company -> Domestique Rides Inc. | F1: Scenario selectors
A2: {=topic} -> CFM Topic: Revenue | F2: Production | G2: Subscription | J2: {=_xlfn.ANCHORARRAY(Time!J2)} -> 44197 | K2: 44562 | L2: 44927 | M2: 45292 | N2: 45658
A3: EXECUTIVE SUMMARY | J3: {=_xlfn.ANCHORARRAY(Time!J3)} -> 44561 | K3: 44926 | L3: 45291 | M3: 45657 | N3: 46022
B5: a) 5-year revenue forecast
E7: Alp revenue | G7: EUR | H7: {=_xlfn.BYROW(_xlfn.ANCHORARRAY( J7), _xleta.SUM )} -> 23095192 | J7: {=OFFSET( Production!$J$38, 0, 0, COUNTA( Production!E38:$E$40 ), periods )} -> 4202400 | K7: 4415041.4 | L7: 4638442.5 | M7: 4870944.7 | N7: 4968363.6
E8: Pyrenées revenue | G8: EUR | H8: 13936922 | J8: 0 | K8: 2812500 | L8: 3248437.5 | M8: 3751945.3 | N8: 4124039.1
E9: Production revenue | G9: EUR | H9: 37032114 | J9: 4202400 | K9: 7227541.4 | L9: 7886880 | M9: 8622890 | N9: 9092402.7
E11: Client #1 | G11: EUR | H11: {=_xlfn.BYROW(J11:N13, _xleta.SUM )} -> 353989.07 | J11: {=_xlfn.BYCOL(_xlfn.ANCHORARRAY(Subscription!J28), _xlfn.LAMBDA(_xlpm.col, SUMIFS(_xlpm.col, Subscription!$E$28:$E$33, 'Executive Summary'!$E11)))} -> 57738.25 | K11: 63620.334 | L11: 70115.97 | M11: 77295.846 | N11: 85218.67
E12: Client #2 | G12: EUR | H12: 809851.33 | J12: {=_xlfn.BYCOL(_xlfn.ANCHORARRAY(Subscription!J28), _xlfn.LAMBDA(_xlpm.col, SUMIFS(_xlpm.col, Subscription!$E$28:$E$33, 'Executive Summary'!$E12)))} -> 132092.77 | K12: 145549.73 | L12: 160410.35 | M12: 176836.37 | N12: 194962.1
E13: Subscription revenue | G13: EUR | H13: 1163840.4 | J13: {=_xlfn.ANCHORARRAY( Subscription!J34)} -> 189831.02 | K13: 209170.06 | L13: 230526.32 | M13: 254132.22 | N13: 280180.77
E15: Total revenue | G15: EUR | H15: {=_xlfn.BYROW(J15:N15, _xleta.SUM )} -> 38195955 | J15: =J9 + J13 -> 4392231 | K15: =K9 + K13 -> 7436711.5 | L15: =L9 + L13 -> 8117406.4 | M15: =M9 + M13 -> 8877022.3 | N15: =N9 + N13 -> 9372583.4
B17: b) Revenue and volume executive summary
E19: =E7 -> Alp revenue | G19: =G7 -> EUR | H19: =H7 -> 23095192 | I19: =I7 -> 0 | J19: =J7 -> 4202400 | K19: =K7 -> 4415041.4 | L19: =L7 -> 4638442.5 | M19: =M7 -> 4870944.7 | N19: =N7 -> 4968363.6
E20: =Production!E11 -> Forecasted unit sales - Alp | G20: =Production!G11 -> units | H20: =Production!H11 -> 4346.9016 | I20: =Production!I11 -> 0 | J20: =Production!J11 -> 824 | K20: =Production!K11 -> 848.72 | L20: =Production!L11 -> 874.1816 | M20: =Production!M11 -> 900 | N20: =Production!N11 -> 900
E22: =E8 -> Pyrenées revenue | G22: =G8 -> EUR | H22: =H8 -> 13936922 | I22: =I8 -> 0 | J22: =J8 -> 0 | K22: =K8 -> 2812500 | L22: =L8 -> 3248437.5 | M22: =M8 -> 3751945.3 | N22: =N8 -> 4124039.1
E23: =Production!E27 -> Forecasted unit sales - Pyrenées | G23: =Production!G27 -> units | H23: =Production!H27 -> 1716.25 | I23: =Production!I27 -> 0 | J23: =Production!J27 -> 0 | K23: =Production!K27 -> 375 | L23: =Production!L27 -> 412.5 | M23: =Production!M27 -> 453.75 | N23: =Production!N27 -> 475
E25: =E11 -> Client #1 | G25: =G11 -> EUR | H25: =H11 -> 353989.07 | I25: =I11 -> 0 | J25: =J11 -> 57738.25 | K25: =K11 -> 63620.334 | L25: =L11 -> 70115.97 | M25: =M11 -> 77295.846 | N25: =N11 -> 85218.67
E26: Forecasted subscriptions | G26: units | H26: {=_xlfn.BYROW(_xlfn.ANCHORARRAY( $J$26), _xleta.SUM )} -> 2769.3445 | J26: {=_xlfn.BYCOL(_xlfn.ANCHORARRAY(Subscription!$J$8), _xlfn.LAMBDA(_xlpm.col, SUMIFS(_xlpm.col, Subscription!$E$8:$E$13, 'Executive Summary'!$E25)))} -> 483.75 | K26: 520.03125 | L26: 556.43344 | M26: 589.81944 | N26: 619.31042
E28: =E12 -> Client #2 | G28: =G12 -> EUR | H28: =H12 -> 809851.33 | I28: =I12 -> 0 | J28: =J12 -> 132092.77 | K28: =K12 -> 145549.73 | L28: =L12 -> 160410.35 | M28: =M12 -> 176836.37 | N28: =N12 -> 194962.1
E29: Forecasted subscriptions | G29: units | H29: {=_xlfn.BYROW(_xlfn.ANCHORARRAY( $J$29), _xleta.SUM )} -> 5378.6825 | J29: {=_xlfn.BYCOL(_xlfn.ANCHORARRAY(Subscription!$J$8), _xlfn.LAMBDA(_xlpm.col, SUMIFS(_xlpm.col, Subscription!$E$8:$E$13, 'Executive Summary'!$E28)))} -> 939.55 | K29: 1010.0163 | L29: 1080.7174 | M29: 1145.5604 | N29: 1202.8385
B31: c) Key metrics
D33: i. Percentage of total 2024 revenue derived from production revenue if Pyrenées is started in 2022
E35: Total revenue in 2024 | G35: EUR | J35: 9058551
E36: Production revenue if Pyrenées is launched in 2022 | G36: EUR | J36: 8804418.8
E37: Percentage of revenue derived from production | G37: EUR | J37: 0.9719456
D39: ii. How many subscriptions has Client #1 in 2025 and what is their average price
E41: Numer of subscribers at the end of 2025 | G41: units | J41: 619.31042
E42: Average price in client's local currency | G42: LC | J42: 553.86891
D44: iii. What is the impact to Total Revenue of a 10% increase in the fx rate of Client #1 and Pyrenée launch in 2023
E46: =CaseData!C$58 -> FX fluctuation | F46: =CaseData!D$58 -> 0 | G46: =CaseData!E$58 -> %
E48: {=_xlfn.LET( _xlpm.clients, _xlfn._xlws.FILTER( CaseData!$N$8:$N$1331, CaseData!$N$8:$N$1331 = "Client #1"), _xlpm.prices_local, _xlfn._xlws.FILTER( CaseData!$P$8:$P$1331, CaseData!$N$8:$N$1331 = "Client #1"), _xlpm.fx_EUR, _xlfn._xlws.FILTER( CaseData!$Q$8:$Q$1331, CaseData!$N$8:$N$1331 = "Client #1"), _xlpm.fx_fluctuation, CaseData!$D$58, _xlpm.fx_rate_applied, _xlpm.fx_EUR * (1 + _xlpm.fx_fluctuation ), _xlpm.prices_EUR, _xlpm.prices_local / _xlpm.fx_rate_applied, _xlpm.pricing_table, _xlfn._xlws.SORT( _xlfn.UNIQUE( _xlfn.HSTACK( _xlpm.clients, _xlpm.prices_local, _xlpm.prices_EUR, _xlpm.fx_rate_applied ) ),{1,2},{1,-1}), _xlfn.VSTACK( _xlfn.HSTACK( "Client", "Price (Local)", "Price (EUR)", "FX rate applied" ), _xlfn.HSTACK( _xlpm.pricing_table ) ) )} -> Client | F48: Price (Local) | G48: Price (EUR) | H48: FX rate applied
E49: Client #1 | F49: 150 | G49: 120 | H49: 1.25 | J49: {=_xlfn.LET( _xlpm.operating_flag,_xlfn.ANCHORARRAY( Time!$J$24), _xlpm.price_2020, _xlfn.DROP(INDEX(_xlfn.ANCHORARRAY( E48),,3), 1), _xlpm.current_year,_xlfn.ANCHORARRAY(Time!$J$14), _xlpm.current_scenario, INDEX( subscription, subscription_selector ), _xlpm.growth_rates, CaseData!$G$62:$K$64, _xlpm.compounded_rates, _xlfn.MAKEARRAY( ROWS( _xlpm.growth_rates ), COLUMNS( _xlpm.growth_rates ), _xlfn.LAMBDA(_xlpm.i,_xlpm.j, INDEX( _xlfn.SCAN( 1, INDEX( _xlpm.growth_rates, _xlpm.i, 0 ), _xlfn.LAMBDA(_xlpm.s,_xlpm.c, _xlpm.s * ( 1 + _xlpm.c ) ) ), _xlpm.j ) ) ), _xlpm.compounded_rows, CaseData!$C$62:$C$64, _xlpm.compounded_columns, CaseData!$F$59:$K$59, _xlpm.compounded_table, _xlfn.VSTACK( _xlpm.compounded_columns, _xlfn.HSTACK( _xlpm.compounded_rows, _xlpm.compounded_rates ) ), _xlpm.compounded_growth, INDEX( _xlpm.compounded_table, _xlfn.XMATCH( _xlpm.current_scenario, _xlpm.compounded_rows, 0, 1 ) + 1, _xlfn.XMATCH( _xlpm.current_year, _xlpm.compounded_columns, 0, 1 ) ), _xlpm.operating_flag * _xlpm.price_2020 * _xlpm.compounded_growth )} -> 123 | K49: 126.075 | L49: 129.85725 | M49: 135.05154 | N49: 141.80412
E50: Client #1 | F50: 140 | G50: 112 | H50: 1.25 | J50: 114.8 | K50: 117.67 | L50: 121.2001 | M50: 126.0481 | N50: 132.35051
E52: Client #1 | G52: units | J52: {=Subscription!J8:N9} -> 268.75 | K52: 288.90625 | L52: 309.12969 | M52: 327.67747 | N52: 344.06134
J53: 215 | K53: 231.125 | L53: 247.30375 | M53: 262.14198 | N53: 275.24907
E55: Revenue from Pyrenée launch in 2023 | G55: EUR | H55: 10333406 | J55: 0 | K55: 0 | L55: 2812500 | M55: 3403125 | N55: 4117781.3
E56: Revenue from Client #1 subjected to fx fluctuation | G56: EUR | H56: {=_xlfn.BYROW(_xlfn.ANCHORARRAY(J56), _xleta.SUM )} -> 353989.07 | J56: {=_xlfn.LET( _xlpm.price_anchor, $J$49, _xlpm.price_block, OFFSET( _xlpm.price_anchor, 0, 0, 2, periods ), _xlpm.volume_anchor, $J$52, _xlpm.volume_block, OFFSET( _xlpm.volume_anchor, 0, 0, 2, periods ), _xlfn.BYCOL( _xlpm.price_block * _xlpm.volume_block, _xleta.SUM ) )} -> 57738.25 | K56: 63620.334 | L56: 70115.97 | M56: 77295.846 | N56: 85218.67
E57: Revenue from Alp production | F57: =F7 -> 0 | G57: =G7 -> EUR | H57: =H7 -> 23095192 | I57: =I7 -> 0 | J57: =J7 -> 4202400 | K57: =K7 -> 4415041.4 | L57: =L7 -> 4638442.5 | M57: =M7 -> 4870944.7 | N57: =N7 -> 4968363.6
E58: Revenue from Client #2 | F58: =F$12 -> 0 | G58: =G$12 -> EUR | H58: =H$12 -> 809851.33 | I58: =I$12 -> 0 | J58: =J$12 -> 132092.77 | K58: =K$12 -> 145549.73 | L58: =L$12 -> 160410.35 | M58: =M$12 -> 176836.37 | N58: =N$12 -> 194962.1
E59: Total revenue | G59: EUR | H59: {=_xlfn.BYROW(_xlfn.ANCHORARRAY( J59), _xleta.SUM)} -> 24259033 | J59: {=_xlfn.BYCOL(_xlfn.ANCHORARRAY( J56) :_xlfn.ANCHORARRAY( N58), _xleta.SUM)} -> 4392231 | K59: 4624211.5 | L59: 4868968.9 | M59: 5125076.9 | N59: 5248544.4
...

Sheet Subscription
A1: =company -> Domestique Rides Inc.
A2: {=topic} -> CFM Topic: Revenue | J2: {=_xlfn.ANCHORARRAY(Time!J2)} -> 44197 | K2: 44562 | L2: 44927 | M2: 45292 | N2: 45658
A3: SUBSCRIPTION SCHEDULE | F3: Constant | G3: Unit | J3: {=_xlfn.ANCHORARRAY(Time!J3)} -> 44561 | K3: 44926 | L3: 45291 | M3: 45657 | N3: 46022
A5: Subscriptions
E7: {=_xlfn.LET( _xlpm.clients, CaseData!$N$8:$N$1331, _xlpm.prices_local, CaseData!$P$8:$P$1331, _xlpm.fx_EUR, CaseData!$Q$8:$Q$1331, _xlpm.prices_EUR, _xlpm.prices_local / _xlpm.fx_EUR, _xlpm.pricing_table, _xlfn._xlws.SORT( _xlfn.UNIQUE( _xlfn.HSTACK( _xlpm.clients, _xlpm.prices_local, _xlpm.prices_EUR )),{1,2},{1,-1}), _xlpm.cu, INDEX( _xlpm.pricing_table,,1), _xlpm.pu, INDEX( _xlpm.pricing_table,,2), _xlpm.pe, INDEX( _xlpm.pricing_table,,3), _xlpm.cnt, _xlfn.MAP( _xlpm.cu, _xlpm.pu, _xlfn.LAMBDA(_xlpm.x,_xlpm.y, SUMPRODUCT( (_xlpm.x = _xlpm.clients) * (_xlpm.y = _xlpm.prices_local) ) ) ), _xlpm.tot, _xlfn.MAP( _xlpm.cu, _xlpm.pe, _xlfn.LAMBDA(_xlpm.x,_xlpm.y, SUMPRODUCT( (_xlpm.x = _xlpm.clients) * (_xlpm.y = _xlpm.prices_EUR) * _xlpm.prices_EUR ))), _xlfn.VSTACK( _xlfn.HSTACK("Clients", "Price (Local) ", "Number of Subscriptions in 2020"), _xlfn.HSTACK(_xlpm.cu, _xlpm.pu, _xlpm.cnt) ) )} -> Clients | F7: Price (Local) | G7: Number of Subscriptions in 2020
E8: Client #1 | F8: 150 | G8: 250 | H8: units | J8: {=_xlfn.LET( _xlpm.operating_flag,_xlfn.ANCHORARRAY( Time!$J$24), _xlpm.subscription_2020, _xlfn.DROP(INDEX(_xlfn.ANCHORARRAY( E7),,3), 1), _xlpm.current_year,_xlfn.ANCHORARRAY(Time!$J$14), _xlpm.current_scenario, INDEX( subscription, subscription_selector ), _xlpm.growth_rates, CaseData!$G$67:$K$69, _xlpm.compounded_rates, _xlfn.MAKEARRAY( ROWS( _xlpm.growth_rates ), COLUMNS( _xlpm.growth_rates ), _xlfn.LAMBDA(_xlpm.i,_xlpm.j, INDEX( _xlfn.SCAN( 1, INDEX( _xlpm.growth_rates, _xlpm.i, 0 ), _xlfn.LAMBDA(_xlpm.s,_xlpm.c, _xlpm.s * ( 1 + _xlpm.c ) ) ), _xlpm.j ) ) ), _xlpm.compounded_rows, CaseData!$C$67:$C$69, _xlpm.compounded_columns, CaseData!$F$59:$K$59, _xlpm.compounded_table, _xlfn.VSTACK( _xlpm.compounded_columns, _xlfn.HSTACK( _xlpm.compounded_rows, _xlpm.compounded_rates ) ), _xlpm.compounded_growth, INDEX( _xlpm.compounded_table, _xlfn.XMATCH( _xlpm.current_scenario, _xlpm.compounded_rows, 0, 1 ) + 1, _xlfn.XMATCH( _xlpm.current_year, _xlpm.compounded_columns, 0, 1 ) ), _xlpm.operating_flag * _xlpm.subscription_2020 * _xlpm.compounded_growth )} -> 268.75 | K8: 288.90625 | L8: 309.12969 | M8: 327.67747 | N8: 344.06134
E9: Client #1 | F9: 140 | G9: 200 | H9: units | J9: 215 | K9: 231.125 | L9: 247.30375 | M9: 262.14198 | N9: 275.24907
E10: Client #2 | F10: 150 | G10: 250 | H10: units | J10: 268.75 | K10: 288.90625 | L10: 309.12969 | M10: 327.67747 | N10: 344.06134
E11: Client #2 | F11: 140 | G11: 250 | H11: units | J11: 268.75 | K11: 288.90625 | L11: 309.12969 | M11: 327.67747 | N11: 344.06134
E12: Client #2 | F12: 130 | G12: 250 | H12: units | J12: 268.75 | K12: 288.90625 | L12: 309.12969 | M12: 327.67747 | N12: 344.06134
E13: Client #2 | F13: 120 | G13: 124 | H13: units | J13: 133.3 | K13: 143.2975 | L13: 153.32832 | M13: 162.52802 | N13: 170.65443
A15: Price
E17: {=_xlfn.LET( _xlpm.clients, CaseData!$N$8:$N$1331, _xlpm.prices_local, CaseData!$P$8:$P$1331, _xlpm.fx_EUR, CaseData!$Q$8:$Q$1331, _xlpm.prices_EUR, _xlpm.prices_local / _xlpm.fx_EUR, _xlpm.pricing_table, _xlfn._xlws.SORT( _xlfn.UNIQUE( _xlfn.HSTACK( _xlpm.clients, _xlpm.prices_local, _xlpm.prices_EUR )),{1,2},{1,-1}), _xlpm.cu, INDEX( _xlpm.pricing_table,,1), _xlpm.pu, INDEX( _xlpm.pricing_table,,2), _xlpm.pe, INDEX( _xlpm.pricing_table,,3), _xlpm.cnt, _xlfn.MAP( _xlpm.cu, _xlpm.pu, _xlfn.LAMBDA(_xlpm.x,_xlpm.y, SUMPRODUCT( (_xlpm.x = _xlpm.clients) * (_xlpm.y = _xlpm.prices_local) ) ) ), _xlpm.tot, _xlfn.MAP( _xlpm.cu, _xlpm.pe, _xlfn.LAMBDA(_xlpm.x,_xlpm.y, SUMPRODUCT( (_xlpm.x = _xlpm.clients) * (_xlpm.y = _xlpm.prices_EUR) * _xlpm.prices_EUR ))), _xlfn.VSTACK( _xlfn.HSTACK("Clients", "Price (EUR)", "Number of Subscriptions in 2020"), _xlfn.HSTACK(_xlpm.cu, _xlpm.pe, _xlpm.cnt) ) )} -> Clients | F17: Price (EUR) | G17: Number of Subscriptions in 2020
E18: Client #1 | F18: 120 | G18: 250 | H18: EUR | J18: {=_xlfn.LET( _xlpm.operating_flag,_xlfn.ANCHORARRAY( Time!$J$24), _xlpm.price_2020, _xlfn.DROP(INDEX(_xlfn.ANCHORARRAY( E17),,2), 1), _xlpm.current_year,_xlfn.ANCHORARRAY(Time!$J$14), _xlpm.current_scenario, INDEX( subscription, subscription_selector ), _xlpm.growth_rates, CaseData!$G$62:$K$64, _xlpm.compounded_rates, _xlfn.MAKEARRAY( ROWS( _xlpm.growth_rates ), COLUMNS( _xlpm.growth_rates ), _xlfn.LAMBDA(_xlpm.i,_xlpm.j, INDEX( _xlfn.SCAN( 1, INDEX( _xlpm.growth_rates, _xlpm.i, 0 ), _xlfn.LAMBDA(_xlpm.s,_xlpm.c, _xlpm.s * ( 1 + _xlpm.c ) ) ), _xlpm.j ) ) ), _xlpm.compounded_rows, CaseData!$C$62:$C$64, _xlpm.compounded_columns, CaseData!$F$59:$K$59, _xlpm.compounded_table, _xlfn.VSTACK( _xlpm.compounded_columns, _xlfn.HSTACK( _xlpm.compounded_rows, _xlpm.compounded_rates ) ), _xlpm.compounded_growth, INDEX( _xlpm.compounded_table, _xlfn.XMATCH( _xlpm.current_scenario, _xlpm.compounded_rows, 0, 1 ) + 1, _xlfn.XMATCH( _xlpm.current_year, _xlpm.compounded_columns, 0, 1 ) ), _xlpm.operating_flag * _xlpm.price_2020 * _xlpm.compounded_growth )} -> 123 | K18: 126.075 | L18: 129.85725 | M18: 135.05154 | N18: 141.80412
E19: Client #1 | F19: 112 | G19: 200 | H19: EUR | J19: 114.8 | K19: 117.67 | L19: 121.2001 | M19: 126.0481 | N19: 132.35051
E20: Client #2 | F20: 150 | G20: 250 | H20: EUR | J20: 153.75 | K20: 157.59375 | L20: 162.32156 | M20: 168.81442 | N20: 177.25515
E21: Client #2 | F21: 140 | G21: 250 | H21: EUR | J21: 143.5 | K21: 147.0875 | L21: 151.50012 | M21: 157.56013 | N21: 165.43814
E22: Client #2 | F22: 130 | G22: 250 | H22: EUR | J22: 133.25 | K22: 136.58125 | L22: 140.67869 | M22: 146.30584 | N22: 153.62113
E23: Client #2 | F23: 120 | G23: 124 | H23: EUR | J23: 123 | K23: 126.075 | L23: 129.85725 | M23: 135.05154 | N23: 141.80412
A25: Subscription revenue
E27: {=_xlfn.LET( _xlpm.clients, CaseData!$N$8:$N$1331, _xlpm.prices_local, CaseData!$P$8:$P$1331, _xlpm.fx_EUR, CaseData!$Q$8:$Q$1331, _xlpm.prices_EUR, _xlpm.prices_local / _xlpm.fx_EUR, _xlpm.pricing_table, _xlfn._xlws.SORT( _xlfn.UNIQUE( _xlfn.HSTACK( _xlpm.clients, _xlpm.prices_local, _xlpm.prices_EUR )),{1,2},{1,-1}), _xlpm.cu, INDEX( _xlpm.pricing_table,,1), _xlpm.pu, INDEX( _xlpm.pricing_table,,2), _xlpm.pe, INDEX( _xlpm.pricing_table,,3), _xlpm.cnt, _xlfn.MAP( _xlpm.cu, _xlpm.pu, _xlfn.LAMBDA(_xlpm.x,_xlpm.y, SUMPRODUCT( (_xlpm.x = _xlpm.clients) * (_xlpm.y = _xlpm.prices_local) ) ) ), _xlpm.tot, _xlfn.MAP( _xlpm.cu, _xlpm.pe, _xlfn.LAMBDA(_xlpm.x,_xlpm.y, SUMPRODUCT( (_xlpm.x = _xlpm.clients) * (_xlpm.y = _xlpm.prices_EUR) * _xlpm.prices_EUR ))), _xlfn.VSTACK( _xlfn.HSTACK("Clients", "Price (EUR) ", "Number of Subscriptions in 2020", "Total"), _xlfn.HSTACK(_xlpm.cu, _xlpm.pe, _xlpm.cnt, _xlpm.tot), _xlfn.HSTACK("Subscription Revenue", "", "", SUM(_xlpm.tot)) ) )} -> Clients | F27: Price (EUR) | G27: Number of Subscriptions in 2020 | H27: Total
E28: Client #1 | F28: 120 | G28: 250 | H28: 30000 | J28: {=_xlfn.ANCHORARRAY( J8) *_xlfn.ANCHORARRAY( J18)} -> 33056.25 | K28: 36423.855 | L28: 40142.731 | M28: 44253.347 | N28: 48789.315
E29: Client #1 | F29: 112 | G29: 200 | H29: 22400 | J29: 24682 | K29: 27196.479 | L29: 29973.239 | M29: 33042.499 | N29: 36429.355
E30: Client #2 | F30: 150 | G30: 250 | H30: 37500 | J30: 41320.312 | K30: 45529.819 | L30: 50178.414 | M30: 55316.683 | N30: 60986.644
E31: Client #2 | F31: 140 | G31: 250 | H31: 35000 | J31: 38565.625 | K31: 42494.498 | L31: 46833.186 | M31: 51628.905 | N31: 56920.867
E32: Client #2 | F32: 130 | G32: 250 | H32: 32500 | J32: 35810.938 | K32: 39459.177 | L32: 43487.959 | M32: 47941.126 | N32: 52855.091
E33: Client #2 | F33: 120 | G33: 124 | H33: 14880 | J33: 16395.9 | K33: 18066.232 | L33: 19910.795 | M33: 21949.66 | N33: 24199.5
E34: Subscription Revenue | H34: 172280 | J34: {=_xlfn.BYCOL(_xlfn.ANCHORARRAY( J28), _xleta.SUM )} -> 189831.02 | K34: 209170.06 | L34: 230526.32 | M34: 254132.22 | N34: 280180.77
A36: End of schedule

Sheet Production
A1: =company -> Domestique Rides Inc.
A2: {=topic} -> CFM Topic: Revenue | J2: {=_xlfn.ANCHORARRAY(Time!J2)} -> 44197 | K2: 44562 | L2: 44927 | M2: 45292 | N2: 45658
A3: PRODUCTION SCHEDULE | F3: Constant | G3: Unit | H3: Total | J3: {=_xlfn.ANCHORARRAY(Time!J3)} -> 44561 | K3: 44926 | L3: 45291 | M3: 45657 | N3: 46022
A5: Alp
B7: Units produced
E8: Alp unit sales - unconstrained by capacity | G8: units | H8: {=_xlfn.BYROW(_xlfn.ANCHORARRAY( J8), _xleta.SUM )} -> 4374.7279 | J8: {=_xlfn.LET( _xlpm.operating_flag,_xlfn.ANCHORARRAY( Time!J18), _xlpm.unit_sales_2020, CaseData!$D$19, _xlpm.current_year,_xlfn.ANCHORARRAY(Time!$J$14), _xlpm.current_scenario, INDEX( production, production_selector ), _xlpm.growth_rates, CaseData!$G$31:$K$33, _xlpm.compounded_rates, _xlfn.MAKEARRAY( ROWS( _xlpm.growth_rates ), COLUMNS( _xlpm.growth_rates ), _xlfn.LAMBDA(_xlpm.i,_xlpm.j, INDEX( _xlfn.SCAN( 1, INDEX( _xlpm.growth_rates, _xlpm.i, 0 ), _xlfn.LAMBDA(_xlpm.s,_xlpm.c, _xlpm.s * ( 1 + _xlpm.c ) ) ), _xlpm.j ) ) ), _xlpm.compounded_rows, CaseData!$C$26:$C$28, _xlpm.compounded_columns, CaseData!$F$23:$K$23, _xlpm.compounded_table, _xlfn.VSTACK( _xlpm.compounded_columns, _xlfn.HSTACK( _xlpm.compounded_rows, _xlpm.compounded_rates ) ), _xlpm.compounded_growth, INDEX( _xlpm.compounded_table, _xlfn.XMATCH( _xlpm.current_scenario, _xlpm.compounded_rows, 0, 1 ) + 1, _xlfn.XMATCH( _xlpm.current_year, _xlpm.compounded_columns, 0, 1 ) ), _xlpm.operating_flag * _xlpm.unit_sales_2020 * _xlpm.compounded_growth )} -> 824 | K8: 848.72 | L8: 874.1816 | M8: 900.40705 | N8: 927.41926
E10: =CaseData!C$21 -> Maximum capacity - Alp | F10: =CaseData!D$21 -> 900 | G10: =CaseData!E$21 -> units
E11: Forecasted unit sales - Alp | G11: units | H11: {=_xlfn.BYROW(_xlfn.ANCHORARRAY( J11), _xleta.SUM )} -> 4346.9016 | J11: {=_xlfn.LET( _xlpm.max_capacity, CaseData!$D$21, _xlfn.BYCOL(_xlfn.ANCHORARRAY( Production!J8), _xlfn.LAMBDA(_xlpm.d, MIN( _xlpm.max_capacity, _xlpm.d ) ) ) )} -> 824 | K11: 848.72 | L11: 874.1816 | M11: 900 | N11: 900
B13: Unit price
E14: =CaseData!C$20 -> Unit price in 2020 - Alp | F14: =CaseData!D$20 -> 5000 | G14: =CaseData!E$20 -> EUR / unit
E15: Forecasted unit price - Alp | G15: EUR / unit | J15: {=_xlfn.LET( _xlpm.operating_flag,_xlfn.ANCHORARRAY( Time!$J$18), _xlpm.unit_price, CaseData!$D$20, _xlpm.current_year,_xlfn.ANCHORARRAY(Time!$J$14), _xlpm.current_scenario, INDEX( production, production_selector ), _xlpm.growth_rates, CaseData!$G$26:$K$28, _xlpm.compounded_rates, _xlfn.MAKEARRAY( ROWS( _xlpm.growth_rates ), COLUMNS( _xlpm.growth_rates ), _xlfn.LAMBDA(_xlpm.i,_xlpm.j, INDEX( _xlfn.SCAN( 1, INDEX( _xlpm.growth_rates, _xlpm.i, 0 ), _xlfn.LAMBDA(_xlpm.s,_xlpm.c, _xlpm.s * ( 1 + _xlpm.c ) ) ), _xlpm.j ) ) ), _xlpm.compounded_rows, CaseData!$C$26:$C$28, _xlpm.compounded_columns, CaseData!$F$23:$K$23, _xlpm.compounded_table, _xlfn.VSTACK( _xlpm.compounded_columns, _xlfn.HSTACK( _xlpm.compounded_rows, _xlpm.compounded_rates ) ), _xlpm.compounded_growth, INDEX( _xlpm.compounded_table, _xlfn.XMATCH( _xlpm.current_scenario, _xlpm.compounded_rows, 0, 1 ) + 1, _xlfn.XMATCH( _xlpm.current_year, _xlpm.compounded_columns, 0, 1 ) ), _xlpm.operating_flag * _xlpm.unit_price * _xlpm.compounded_growth)} -> 5100 | K15: 5202 | L15: 5306.04 | M15: 5412.1608 | N15: 5520.404
B17: Revenue
E18: Alp revenue | G18: EUR | H18: {=_xlfn.BYROW(_xlfn.ANCHORARRAY( J18), _xleta.SUM )} -> 23095192 | J18: {=_xlfn.ANCHORARRAY( $J$11) *_xlfn.ANCHORARRAY( $J$15)} -> 4202400 | K18: 4415041.4 | L18: 4638442.5 | M18: 4870944.7 | N18: 4968363.6
A20: Pyrenées
B22: Units produced
E23: =CaseData!C$41 -> Start of production - Pyrenees | F23: =YEAR( CaseData!D$41 ) -> 2022 | G23: =CaseData!E$41 -> date
E24: Pyrenées unit sales - unconstrained by capacity | G24: units | H24: {=_xlfn.BYROW(_xlfn.ANCHORARRAY( J24), _xleta.SUM )} -> 1740.375 | J24: {=_xlfn.LET( _xlpm.operating_flag,_xlfn.ANCHORARRAY( Time!$J$21), _xlpm.first_year_unit_sales, CaseData!$D$38, _xlpm.start_of_production_date, YEAR( CaseData!$D$41 ), _xlpm.current_year,_xlfn.ANCHORARRAY(Time!$J$14), _xlpm.current_scenario, INDEX( production, production_selector ), _xlpm.growth_rates, IF( CaseData!$G$42:$K$42 <= _xlpm.start_of_production_date, 0, CaseData!$G$50:$K$52 ), _xlpm.compounded_rates, _xlfn.MAKEARRAY( ROWS( _xlpm.growth_rates ), COLUMNS( _xlpm.growth_rates ), _xlfn.LAMBDA(_xlpm.i,_xlpm.j, INDEX( _xlfn.SCAN( 1, INDEX( _xlpm.growth_rates, _xlpm.i, 0 ), _xlfn.LAMBDA(_xlpm.s,_xlpm.c, _xlpm.s * ( 1 + _xlpm.c ) ) ), _xlpm.j ) ) ), _xlpm.compounded_rows, CaseData!$C$50:$C$52, _xlpm.compounded_columns, CaseData!$F$42:$K$42, _xlpm.compounded_table, _xlfn.VSTACK( _xlpm.compounded_columns, _xlfn.HSTACK( _xlpm.compounded_rows, _xlpm.compounded_rates ) ), _xlpm.compounded_growth, IF( _xlpm.start_of_production_date = _xlpm.current_year, 1, INDEX( _xlpm.compounded_table, _xlfn.XMATCH( _xlpm.current_scenario, _xlpm.compounded_rows, 0, 1 ) + 1, _xlfn.XMATCH( _xlpm.current_year, _xlpm.compounded_columns, 0, 1 ) ) ), _xlpm.operating_flag * _xlpm.first_year_unit_sales * _xlpm.compounded_growth )} -> 0 | K24: 375 | L24: 412.5 | M24: 453.75 | N24: 499.125
E26: =CaseData!C$40 -> Maximum capacity - Pyrenees | F26: =CaseData!D$40 -> 475 | G26: =CaseData!E$40 -> units
E27: Forecasted unit sales - Pyrenées | G27: units | H27: {=_xlfn.BYROW(_xlfn.ANCHORARRAY( J27), _xleta.SUM )} -> 1716.25 | J27: {=_xlfn.LET( _xlpm.max_capacity, CaseData!$D$40, _xlfn.BYCOL(_xlfn.ANCHORARRAY( Production!J24), _xlfn.LAMBDA(_xlpm.d, MIN( _xlpm.max_capacity, _xlpm.d ) ) ) )} -> 0 | K27: 375 | L27: 412.5 | M27: 453.75 | N27: 475
B29: Unit price
E30: =CaseData!C$39 -> First year unit price - Pyrenées | F30: =CaseData!D$39 -> 7500 | G30: =CaseData!E$39 -> EUR / unit
E31: Forecasted unit price - Pyrenées | G31: EUR / unit | J31: {=_xlfn.LET( _xlpm.operating_flag,_xlfn.ANCHORARRAY( Time!$J$21), _xlpm.first_year_unit_sales, CaseData!$D$39, _xlpm.start_of_production_date, YEAR( CaseData!$D$41 ), _xlpm.current_year,_xlfn.ANCHORARRAY(Time!$J$14), _xlpm.current_scenario, INDEX( production, production_selector ), _xlpm.growth_rates, IF( CaseData!$G$42:$K$42 <= _xlpm.start_of_production_date, 0, CaseData!$G$45:$K$47 ), _xlpm.compounded_rates, _xlfn.MAKEARRAY( ROWS( _xlpm.growth_rates ), COLUMNS( _xlpm.growth_rates ), _xlfn.LAMBDA(_xlpm.i,_xlpm.j, INDEX( _xlfn.SCAN( 1, INDEX( _xlpm.growth_rates, _xlpm.i, 0 ), _xlfn.LAMBDA(_xlpm.s,_xlpm.c, _xlpm.s * ( 1 + _xlpm.c ) ) ), _xlpm.j ) ) ), _xlpm.compounded_rows, CaseData!$C$50:$C$52, _xlpm.compounded_columns, CaseData!$F$42:$K$42, _xlpm.compounded_table, _xlfn.VSTACK( _xlpm.compounded_columns, _xlfn.HSTACK( _xlpm.compounded_rows, _xlpm.compounded_rates ) ), _xlpm.compounded_growth, IF( _xlpm.start_of_production_date = _xlpm.current_year, 1, INDEX( _xlpm.compounded_table, _xlfn.XMATCH( _xlpm.current_scenario, _xlpm.compounded_rows, 0, 1 ) + 1, _xlfn.XMATCH( _xlpm.current_year, _xlpm.compounded_columns, 0, 1 ) ) ), _xlpm.operating_flag * _xlpm.first_year_unit_sales * _xlpm.compounded_growth )} -> 0 | K31: 7500 | L31: 7875 | M31: 8268.75 | N31: 8682.1875
B33: Revenue
E34: Pyrenées revenue | G34: EUR | H34: {=_xlfn.BYROW(_xlfn.ANCHORARRAY( J34), _xleta.SUM )} -> 13936922 | J34: {=_xlfn.ANCHORARRAY( J27) *_xlfn.ANCHORARRAY( J31)} -> 0 | K34: 2812500 | L34: 3248437.5 | M34: 3751945.3 | N34: 4124039.1
A36: Production revenue
E38: =E18 -> Alp revenue | G38: =G18 -> EUR | H38: {=_xlfn.BYROW(_xlfn.ANCHORARRAY( J38), _xleta.SUM )} -> 23095192 | J38: {=_xlfn.ANCHORARRAY($J$18)} -> 4202400 | K38: 4415041.4 | L38: 4638442.5 | M38: 4870944.7 | N38: 4968363.6
E39: Pyrenées revenue | G39: EUR | H39: {=_xlfn.BYROW(_xlfn.ANCHORARRAY( J39), _xleta.SUM )} -> 13936922 | J39: {=_xlfn.ANCHORARRAY($J$34)} -> 0 | K39: 2812500 | L39: 3248437.5 | M39: 3751945.3 | N39: 4124039.1
E40: Production revenue | G40: EUR | H40: {=_xlfn.BYROW(_xlfn.ANCHORARRAY( J40), _xleta.SUM )} -> 37032114 | J40: {=_xlfn.BYCOL(_xlfn.ANCHORARRAY( $J$38):_xlfn.ANCHORARRAY($J$39), _xlfn.LAMBDA(_xlpm.c, SUM( _xlpm.c ) ) )} -> 4202400 | K40: 7227541.4 | L40: 7886880 | M40: 8622890 | N40: 9092402.7
A42: End of schedule

Sheet Time
A1: =company -> Domestique Rides Inc.
A2: {=topic} -> CFM Topic: Revenue | J2: {=_xlfn.ANCHORARRAY(J12)} -> 44197 | K2: 44562 | L2: 44927 | M2: 45292 | N2: 45658
A3: TIME SCHEDULE | F3: Constant | G3: Unit | H3: Total | J3: {=_xlfn.ANCHORARRAY(J13)} -> 44561 | K3: 44926 | L3: 45291 | M3: 45657 | N3: 46022
A5: Model technical inputs
E7: Model start date | F7: =ModelStartDate -> 44197 | G7: date
E8: Model periods | F8: =periods -> 5 | G8: years
E9: Model period counter | G9: counter | J9: {=_xlfn.SEQUENCE( 1, periods, 1, 1 )} -> 1 | K9: 2 | L9: 3 | M9: 4 | N9: 5
B11: Model timeline
E12: Model period beginning | G12: date | J12: {=EDATE( ModelStartDate, _xlfn.SEQUENCE( 1, periods, 0, 12 ) )} -> 44197 | K12: 44562 | L12: 44927 | M12: 45292 | N12: 45658
E13: Model period end | G13: date | J13: {=_xlfn.BYCOL(_xlfn.ANCHORARRAY( J12), _xlfn.LAMBDA(_xlpm.d, EOMONTH( _xlpm.d, 11 )))} -> 44561 | K13: 44926 | L13: 45291 | M13: 45657 | N13: 46022
E14: Annual timeline | G14: years | J14: {=YEAR(_xlfn.ANCHORARRAY( J13) )} -> 2021 | K14: 2022 | L14: 2023 | M14: 2024 | N14: 2025
E15: Effective number of days | G15: days | J15: {=_xlfn.ANCHORARRAY( J13) -_xlfn.ANCHORARRAY( J12) + 1} -> 365 | K15: 365 | L15: 365 | M15: 366 | N15: 365
B17: Operating flags
E18: Alp operating flag | G18: flag | J18: {=IF( NOT( ISBLANK(_xlfn.ANCHORARRAY( J9) ) ), 1, 0 )} -> 1 | K18: 1 | L18: 1 | M18: 1 | N18: 1
E20: =CaseData!C$41 -> Start of production - Pyrenees | F20: =CaseData!D$41 -> 44562 | G20: =CaseData!E$41 -> date
E21: Pyrenees operating flag | G21: flag | J21: {=IF( $F$20 <=_xlfn.ANCHORARRAY( J12), 1, 0 )} -> 0 | K21: 1 | L21: 1 | M21: 1 | N21: 1
B23: Subscription operating flag
E24: Subscription operating flag | G24: flag | J24: {=IF( NOT( ISBLANK(_xlfn.ANCHORARRAY( J15) ) ), 1, 0 )} -> 1 | K24: 1 | L24: 1 | M24: 1 | N24: 1
B26: Scenarios
E28: Production | F28: Base Case
F29: Best Case
F30: Worst Case
E31: Production scenario selector | F31: 1
E33: Subscription | F33: Base Case
F34: Best Case
F35: Worst Case
E36: Suscription scenario selector | F36: 1
A41: End of schedule

Sheet CaseData
B2: Domestique Rides Inc. | Q2: Revenue
B4: ASSUMPTIONS
B6: 2020 SUBSCRIPTION PRICING GRID | G6: MODEL ASSUMPTIONS | N6: 2020 SUBSCRIPTION REVENUE INFORMATION
D7: Number of Subscriptions | E7: Price (Local) | N7: Client | O7: Subscription Number | P7: Price (Local) | Q7: FX Rate (x/EUR) | S7: {=_xlfn.LET( _xlpm.c,CaseData!N8:N1331, _xlpm.pl,CaseData!P8:P1331, _xlpm.fx,CaseData!Q8:Q1331, _xlpm.pe,_xlpm.pl/_xlpm.fx, _xlpm.u,_xlfn._xlws.SORT(_xlfn.UNIQUE(_xlfn.HSTACK(_xlpm.c,_xlpm.pl,_xlpm.pe)),{1,2},{1,-1}), _xlpm.cu,INDEX(_xlpm.u,,1), _xlpm.plu,INDEX(_xlpm.u,,2), _xlpm.peu,INDEX(_xlpm.u,,3), _xlpm.cnt,_xlfn.MAP(_xlpm.cu,_xlpm.plu,_xlfn.LAMBDA(_xlpm.x,_xlpm.y,SUMPRODUCT((_xlpm.c=_xlpm.x)*(_xlpm.pl=_xlpm.y)))), _xlpm.sm,_xlfn.MAP(_xlpm.cu,_xlpm.peu,_xlfn.LAMBDA(_xlpm.x,_xlpm.y,SUMPRODUCT((_xlpm.c=_xlpm.x)*(_xlpm.pe=_xlpm.y)*_xlpm.pe))), _xlfn.VSTACK( _xlfn.HSTACK( "Client","Price (Local)","Number of subscriptions","Price (EUR)","Sum (EUR)" ), _xlfn.HSTACK( _xlpm.cu, _xlpm.plu, _xlpm.cnt, _xlpm.peu, _xlpm.sm ), _xlfn.HSTACK( "Grand Total","","",SUM( _xlpm.cnt ),SUM( _xlpm.sm ) ) ) )} -> Client | T7: Price (Local) | U7: Number of subscriptions | V7: Price (EUR) | W7: Sum (EUR)
C8: 0 | D8: =C9-1 -> 250 | E8: 150 | G8: Start date | H8: 44197 | I8: date | N8: Client #2 | O8: 5195760 | P8: 150 | Q8: 1 | S8: Client #1 | T8: 150 | U8: 250 | V8: 120 | W8: 30000
C9: 251 | D9: =C10-1 -> 500 | E9: 140 | G9: Model periods | H9: 5 | I9: years | N9: Client #2 | O9: 4015428 | P9: 140 | Q9: 1 | S9: Client #1 | T9: 140 | U9: 200 | V9: 112 | W9: 22400
C10: 501 | D10: =C11-1 -> 750 | E10: 130 | N10: Client #2 | O10: 6288858 | P10: 140 | Q10: 1 | S10: Client #2 | T10: 150 | U10: 250 | V10: 150 | W10: 37500
C11: 751 | D11: =C12-1 -> 1000 | E11: 120 | G11: Production scenarios | I11: Subscription scenarios | N11: Client #2 | O11: 5970638 | P11: 130 | Q11: 1 | S11: Client #2 | T11: 140 | U11: 250 | V11: 140 | W11: 35000
C12: 1001 | D12: n.a. | E12: 110 | N12: Client #1 | O12: 6677359 | P12: 150 | Q12: 1.25 | S12: Client #2 | T12: 130 | U12: 250 | V12: 130 | W12: 32500
N13: Client #1 | O13: 7996896 | P13: 150 | Q13: 1.25 | S13: Client #2 | T13: 120 | U13: 124 | V13: 120 | W13: 14880
N14: Client #1 | O14: 9523830 | P14: 140 | Q14: 1.25 | S14: Grand Total | V14: 1324 | W14: 172280
B15: SCENARIO ANALYSIS | N15: Client #1 | O15: 9041668 | P15: 140 | Q15: 1.25
N16: Client #2 | O16: 5902110 | P16: 130 | Q16: 1
B17: ALP PRODUCTION REVENUE SCENARIOS | N17: Client #2 | O17: 7740826 | P17: 150 | Q17: 1
N18: Client #2 | O18: 3169246 | P18: 120 | Q18: 1
C19: Units produced in 2020 - Alp | D19: 800 | E19: units | N19: Client #2 | O19: 3507520 | P19: 130 | Q19: 1
C20: Unit price in 2020 - Alp | D20: 5000 | E20: EUR / unit | N20: Client #2 | O20: 4093772 | P20: 150 | Q20: 1
C21: Maximum capacity - Alp | D21: 900 | E21: units | N21: Client #2 | O21: 5198881 | P21: 140 | Q21: 1
G22: Forecast | N22: Client #2 | O22: 7554664 | P22: 130 | Q22: 1
F23: 2020 | G23: 2021 | H23: 2022 | I23: 2023 | J23: 2024 | K23: 2025 | N23: Client #2 | O23: 3557630 | P23: 130 | Q23: 1
N24: Client #2 | O24: 3131810 | P24: 120 | Q24: 1
C25: Annual Price Growth | N25: Client #1 | O25: 8917986 | P25: 150 | Q25: 1.25
C26: Base Case | G26: 0.02 | H26: 0.02 | I26: 0.02 | J26: 0.02 | K26: 0.02 | N26: Client #1 | O26: 6804324 | P26: 140 | Q26: 1.25
C27: Best Case | G27: 0.035 | H27: 0.035 | I27: 0.035 | J27: 0.035 | K27: 0.035 | N27: Client #1 | O27: 6607306 | P27: 150 | Q27: 1.25
C28: Worst Case | G28: 0.005 | H28: 0.005 | I28: 0.005 | J28: 0.005 | K28: 0.005 | N28: Client #2 | O28: 5106781 | P28: 150 | Q28: 1
N29: Client #2 | O29: 1538441 | P29: 150 | Q29: 1
C30: Annual Production Growth | N30: Client #1 | O30: 9288908 | P30: 150 | Q30: 1.25
C31: Base Case | G31: 0.03 | H31: 0.03 | I31: 0.03 | J31: 0.03 | K31: 0.03 | N31: Client #1 | O31: 6390626 | P31: 150 | Q31: 1.25
C32: Best Case | G32: 0.04 | H32: 0.04 | I32: 0.04 | J32: 0.04 | K32: 0.04 | N32: Client #1 | O32: 4541935 | P32: 150 | Q32: 1.25
C33: Worst Case | G33: 0.02 | H33: 0.02 | I33: 0.02 | J33: 0.02 | K33: 0.02 | N33: Client #1 | O33: 7246752 | P33: 150 | Q33: 1.25
N34: Client #2 | O34: 5858008 | P34: 140 | Q34: 1
N35: Client #2 | O35: 1801470 | P35: 150 | Q35: 1
B36: PYRENEES PRODUCTION REVENUE SCENARIOS | N36: Client #2 | O36: 1948394 | P36: 140 | Q36: 1
N37: Client #2 | O37: 1044101 | P37: 150 | Q37: 1
C38: First year production forecast | D38: 375 | E38: units | N38: Client #1 | O38: 6774692 | P38: 140 | Q38: 1.25
C39: First year unit price - Pyrenées | D39: 7500 | E39: EUR / unit | N39: Client #2 | O39: 7745323 | P39: 130 | Q39: 1
C40: Maximum capacity - Pyrenees | D40: 475 | E40: units | N40: Client #1 | O40: 9400349 | P40: 150 | Q40: 1.25
C41: Start of production - Pyrenees | D41: 44562 | E41: date | G41: Forecast | N41: Client #2 | O41: 6844448 | P41: 140 | Q41: 1
F42: 2020 | G42: 2021 | H42: 2022 | I42: 2023 | J42: 2024 | K42: 2025 | N42: Client #2 | O42: 3006078 | P42: 120 | Q42: 1
N43: Client #1 | O43: 1644586 | P43: 150 | Q43: 1.25
...

Sheet Tmp
A1: =company -> Domestique Rides Inc.
A3: TMP SCHEDULE | F3: Constant | G3: Unit | H3: Total
J6: {=_xlfn.LET( _xlpm.operating_flag,_xlfn.ANCHORARRAY( Time!$J$21), _xlpm.first_year_unit_price, CaseData!$D$39, _xlpm.start_of_production_date, YEAR( CaseData!$D$41 ), _xlpm.current_year,_xlfn.ANCHORARRAY( Time!$J$14), _xlpm.current_scenario, INDEX( production, production_selector ), _xlpm.growth_rates, _xlfn.LET( _xlpm.cols, CaseData!$G$42:$K$42, _xlpm.rates, CaseData!$G$45:$K$47, _xlpm.lead, SUM( --( _xlpm.cols <= _xlpm.start_of_production_date ) ), _xlpm.shifted, _xlfn.MAKEARRAY( ROWS( _xlpm.rates ), COLUMNS( _xlpm.rates ), _xlfn.LAMBDA(_xlpm.i,_xlpm.j, INDEX( _xlpm.rates, _xlpm.i, MIN( COLUMNS( _xlpm.rates ), MAX( 1, _xlpm.j - _xlpm.lead ) ) ) ) ), IF( _xlpm.cols <= _xlpm.start_of_production_date, 0, _xlpm.shifted ) ), _xlpm.compounded_rates, _xlfn.MAKEARRAY( ROWS( _xlpm.growth_rates ), COLUMNS( _xlpm.growth_rates ), _xlfn.LAMBDA(_xlpm.i,_xlpm.j, INDEX( _xlfn.SCAN( 1, INDEX( _xlpm.growth_rates, _xlpm.i, 0 ), _xlfn.LAMBDA(_xlpm.s,_xlpm.c, _xlpm.s * ( 1 + _xlpm.c ) ) ), _xlpm.j ) ) ), _xlpm.compounded_rows, CaseData!$C$45:$C$47, _xlpm.compounded_columns, CaseData!$F$42:$K$42, _xlpm.compounded_table, _xlfn.VSTACK( _xlpm.compounded_columns, _xlfn.HSTACK( _xlpm.compounded_rows, _xlpm.compounded_rates ) ), _xlpm.compounded_growth, IF( _xlpm.start_of_production_date = _xlpm.current_year, 1, INDEX( _xlpm.compounded_table, _xlfn.XMATCH( _xlpm.current_scenario, _xlpm.compounded_rows, 0, 1 ) + 1, _xlfn.XMATCH( _xlpm.current_year, _xlpm.compounded_columns, 0, 1 ) ) ), _xlpm.operating_flag * _xlpm.first_year_unit_price * _xlpm.compounded_growth )} -> 0 | K6: 7500 | L6: 7875 | M6: 8268.75 | N6: 8682.1875
A30: End of schedule
