Workbook
Name company: Assumptions!$E$88
Name last_actual_date: Assumptions!$F$6
Name periods: Time!$F$8
Name start_date: Assumptions!$G$6
Name topic: "CFM Topic: " & Assumptions!$E$89

Sheet Answers
A1: {=company} -> Powerstill Inc.
A2: {=topic} -> CFM Topic: Costs
A3: FINANCIAL STATEMENTS | J3: {=EOMONTH( last_actual_date, _xlfn.SEQUENCE( 1, periods, 12, 12 ) )} -> 43830 | K3: 44196 | L3: 44561 | M3: 44926 | N3: 45291
E5: {=_xlfn.LET( _xlpm.accounts, _xlfn.CHOOSECOLS(_xlfn.ANCHORARRAY( DataPull!$G$7), 2 ), _xlpm.rank, IFERROR( MATCH( _xlpm.accounts, Drivers!$C$9:$C$56, 0 ), MATCH( _xlpm.accounts, Drivers!$B$9:$B$56, 0 ) ), _xlfn.TAKE( _xlfn.SORTBY( _xlpm.accounts, _xlpm.rank, 1 ), 1 ) )} -> Revenue | J5: {=_xlfn.LET( _xlpm.date,_xlfn.ANCHORARRAY( Calculations!$J$3), _xlpm.account, $E$5:$E$43, _xlpm.growth_data, Calculations!$J$7:$N$13, _xlpm.growth_rows, Calculations!$E$7:$E$13, _xlpm.margin_data, Calculations!$J$17:$N$49, _xlpm.margins_rows, Calculations!$E$17:$E$49, _xlpm.step_data, _xlfn.VSTACK(_xlfn.ANCHORARRAY( Calculations!J57),_xlfn.ANCHORARRAY( Calculations!J62) ), _xlpm.step_rows, _xlfn.VSTACK( Calculations!$E$57:$E$59, Calculations!$E$62 ), _xlpm.calculation_data, _xlfn.VSTACK( _xlfn.HSTACK( _xlpm.growth_rows, _xlpm.growth_data ), _xlfn.HSTACK( _xlpm.margins_rows, _xlpm.margin_data ), _xlfn.HSTACK( _xlpm.step_rows, _xlpm.step_data ) ), _xlpm.calculation_table, _xlfn._xlws.FILTER( _xlpm.calculation_data, _xlfn.CHOOSECOLS( _xlpm.calculation_data, 1 ) <> "" ), _xlfn.IFNA( INDEX( _xlfn.DROP( _xlpm.calculation_table,, 1), MATCH( _xlpm.account, _xlfn.CHOOSECOLS( _xlpm.calculation_table, 1 ), 0 ), MATCH( _xlpm.date,_xlfn.ANCHORARRAY( Time!J10), 0 ) ), "" ) )} -> 839.50996 | K5: 881.48546 | L5: 934.37458 | M5: 999.7808 | N5: 1019.7764
E7: {=_xlfn.LET( _xlpm.accounts, _xlfn.DROP( _xlfn.CHOOSECOLS(_xlfn.ANCHORARRAY( DataPull!$G$7), 2 ), 1 ), _xlpm.rank, IFERROR( MATCH( _xlpm.accounts, Drivers!$C$9:$C$56, 0 ), MATCH( _xlpm.accounts, Drivers!$B$9:$B$56, 0 ) ), _xlfn.DROP( _xlfn.SORTBY( _xlpm.accounts, _xlpm.rank, 1 ), 1 ) )} -> Purchases (Cost of Goods) | J7: 167.90199 | K7: 176.29709 | L7: 205.56241 | M7: 249.9452 | N7: 254.94411
E8: General Liability Insurance | J8: 35.3391 | K8: 37.106055 | L8: 39.332418 | M8: 42.085688 | N8: 42.927401
E9: Owner's Health Insurance | J9: 62.272053 | K9: 65.385655 | L9: 69.308795 | M9: 74.16041 | N9: 75.643619
E10: Professional Liability Insurance | J10: 4.1975498 | K10: 4.4074273 | L10: 4.6718729 | M10: 4.998904 | N10: 5.0988821
E11: Worker's Compensation | J11: 0.57450953 | K11: 0.58599972 | L11: 0.72916092 | M11: 0.74374414 | N11: 0.75861902
E12: Employee Benefits
E13: Payroll Tax Expenses | J13: 2.8725477 | K13: 2.9299986 | L13: 3.6458046 | M13: 3.7187207 | N13: 3.7930951
E14: Salaries - Office Staff | J14: 14.353132 | K14: 14.640195 | L14: 18.446645 | M14: 18.815578 | N14: 19.19189
E15: Salaries - Inside Sales | J15: 30.358891 | K15: 30.966069 | L15: 37.902469 | M15: 38.660518 | N15: 39.433728
E16: Salaries - Warehouse | J16: 12.73893 | K16: 12.993709 | L16: 16.566979 | M16: 16.898318 | N16: 17.236285
E17: Car Lease | J17: 20.987749 | K17: 22.037136 | L17: 23.359365 | M17: 29.993424 | N17: 30.593293
E18: Gas | J18: 5.2469372 | K18: 5.5092841 | L18: 5.8398411 | M18: 7.498356 | N18: 7.6483232
E19: Insurance-Auto | J19: 2.6234686 | K19: 2.7546421 | L19: 2.9199206 | M19: 3.749178 | N19: 3.8241616
E20: Registration & License | J20: 3.9876723 | K20: 4.1870559 | L20: 4.4382793 | M20: 5.6987506 | N20: 5.8127256
E21: Repairs & Maintenance | J21: 5.8765697 | K21: 6.1703982 | L21: 6.5406221 | M21: 8.3981588 | N21: 8.5661219
E22: Rent | J22: 11.604674 | K22: 11.836768 | L22: 12.073503 | M22: 12.314973 | N22: 12.561273
E23: Supplies | J23: 20.148239 | K23: 21.155651 | L23: 22.42499 | M23: 23.994739 | N23: 24.474634
E24: Marketing Expense | J24: 14.271669 | K24: 14.985253 | L24: 15.884368 | M24: 16.996274 | N24: 17.336199
... E43: Utilities | J43: 2.1468647 | K43: 2.189802 | L43: 2.2335981 | M43: 2.27827 | N43: 2.3238354
E46: =E$5 -> Revenue | J46: {=_xlfn.CHOOSEROWS(_xlfn.ANCHORARRAY( J5), 1 )} -> 839.50996 | K46: 881.48546 | L46: 934.37458 | M46: 999.7808 | N46: 1019.7764
E47: Total Costs | J47: {=_xlfn.LET( _xlpm.anchor, $J$7, _xlpm.block, OFFSET( _xlpm.anchor, 0, 0, COUNTA(_xlfn.ANCHORARRAY( E7) ), periods ), _xlfn.BYCOL( _xlpm.block, _xleta.SUM ) )} -> 709.97274 | K47: 742.88443 | L47: 817.08529 | M47: 908.28898 | N47: 926.45476
E48: Operating Profit | J48: {=_xlfn.LET( _xlpm.revenue,_xlfn.ANCHORARRAY( J46), _xlpm.costs,_xlfn.ANCHORARRAY( J47), _xlpm.revenue - _xlpm.costs )} -> 129.53722 | K48: 138.60102 | L48: 117.2893 | M48: 91.491826 | N48: 93.321662
E50: Operating Profit | J50: {=_xlfn.LET( _xlpm.revenue,_xlfn.ANCHORARRAY( J46), _xlpm.costs,_xlfn.ANCHORARRAY( J47), _xlpm.revenue - _xlpm.costs )} -> 129.53722 | K50: 138.60102 | L50: 117.2893 | M50: 91.491826 | N50: 93.321662
E51: Revenue | J51: {=_xlfn.ANCHORARRAY(J46)} -> 839.50996 | K51: 881.48546 | L51: 934.37458 | M51: 999.7808 | N51: 1019.7764
E52: Operating Margin | J52: {=_xlfn.LET( _xlpm.operating_profit,_xlfn.ANCHORARRAY( J50), _xlpm.revenue,_xlfn.ANCHORARRAY( J51), _xlpm.operating_profit / _xlpm.revenue )} -> 0.15430099 | K52: 0.15723574 | L52: 0.12552706 | M52: 0.091511885 | N52: 0.091511885
C55: a) | E55: What will be the Company’s Total Car/Truck Expense in 2022? | H55: =SUM(M17:M21) -> 55.337868
C56: b) | E56: How many people will the Company employ at the end of fiscal 2021? | H56: =SUM(Calculations!L53:L55) -> 24.5
C57: c) | E57: How much Operating Profit will the Company generate in fiscal 2023? | H57: =N48 -> 93.321662
C58: d) | E58: What will be the Company's Operating Profit Margin in fiscal 2022? | H58: =M52 -> 0.091511885

Sheet Calculations
A1: {=company} -> Powerstill Inc.
A2: {=topic} -> CFM Topic: Costs
A3: CALCULATION SCHEDULE | F3: Method | G3: Driver | H3: Unit | J3: {=EOMONTH( last_actual_date, _xlfn.SEQUENCE( 1, periods, 12, 12 ))} -> 43830 | K3: 44196 | L3: 44561 | M3: 44926 | N3: 45291
A5: Growth calculation
E7: {=_xlfn.LET( _xlpm.driver_table, _xlfn.CHOOSECOLS( Drivers!$B$7:$F$64,{1,2,4,5} ), _xlpm.filter_cols, _xlfn._xlws.FILTER( _xlpm.driver_table, ( INDEX( _xlpm.driver_table,, 3 ) <> 0 ) * ISNUMBER( SEARCH( "Growth", IFERROR( INDEX( _xlpm.driver_table,, 3), "" ) ) ) * ISNUMBER( SEARCH( "n.a.", IFERROR( INDEX( _xlpm.driver_table,, 4), "" ) ) ) ), _xlpm.merge_cols, IF( INDEX( _xlpm.filter_cols,,2 ) = 0, INDEX( _xlpm.filter_cols,, 1 ), INDEX( _xlpm.filter_cols,, 2 ) ), _xlfn.HSTACK( _xlpm.merge_cols, _xlfn.CHOOSECOLS( _xlpm.filter_cols, {3,4} ) ) )} -> Revenue | F7: Growth | G7: n.a. | H7: USD | J7: {=_xlfn.LET( _xlpm.last_actual_data, _xlfn.DROP(_xlfn.ANCHORARRAY( DataPull!$G$7), 1 ), _xlpm.last_actual_rows, INDEX( _xlpm.last_actual_data,,2), _xlpm.last_actual, _xlfn.IFNA( INDEX( _xlpm.last_actual_data, MATCH( $E$7:$E$13, _xlpm.last_actual_rows, 0 ), 3 ), "" ), _xlpm.growth_data, Assumptions!$G$11:$K$25, _xlpm.growth_rows, Assumptions!$D$11:$D$25, _xlpm.growth_factors, _xlfn.CHOOSEROWS( _xlpm.growth_data, MATCH( _xlfn.CHOOSECOLS($E$7, 1 ), _xlpm.growth_rows, 0 ) ), _xlpm.compounded_rates, _xlfn.MAKEARRAY( ROWS( _xlpm.growth_factors ), COLUMNS( _xlpm.growth_factors ), _xlfn.LAMBDA(_xlpm.i,_xlpm.j, INDEX( _xlfn.SCAN( 1, INDEX( _xlpm.growth_factors, _xlpm.i, 0 ), _xlfn.LAMBDA(_xlpm.s,_xlpm.c, _xlpm.s * ( 1 + _xlpm.c ) ) ), _xlpm.j ) ) ), _xlpm.last_actual * _xlpm.compounded_rates )} -> 839.50996 | K7: 881.48546 | L7: 934.37458 | M7: 999.7808 | N7: 1019.7764 | P7: {=_xlfn.LET( _xlpm.last_actual_data, _xlfn.DROP(_xlfn.ANCHORARRAY( DataPull!$G$7), 1 ), _xlpm.last_actual_rows, INDEX( _xlpm.last_actual_data,,2), _xlpm.last_actual, _xlfn.IFNA( INDEX( _xlpm.last_actual_data, MATCH( $E$7:$E$13, _xlpm.last_actual_rows, 0 ), 3 ), "" ), _xlpm.compound_rates, INDEX(_xlfn.ANCHORARRAY( Assumptions!$M$10), _xlfn.XMATCH( INDEX(_xlfn.ANCHORARRAY( E7),,1 ), INDEX(_xlfn.ANCHORARRAY(Assumptions!$M$10),,1) ), _xlfn.XMATCH(_xlfn.ANCHORARRAY( Calculations!J3), INDEX(_xlfn.ANCHORARRAY(Assumptions!$M$10),1,0) ) ), _xlpm.last_actual * _xlpm.compound_rates )} -> 839.50996 | Q7: 881.48546 | R7: 934.37458 | S7: 999.7808 | T7: 1019.7764
E8: General Liability Insurance | F8: Growth | G8: n.a. | H8: USD | J8: 35.3391 | K8: 37.106055 | L8: 39.332418 | M8: 42.085688 | N8: 42.927401 | P8: 32.768984 | Q8: 33.424363 | R8: 34.092851 | S8: 34.604243 | T8: 35.123307
E9: Owner's Health Insurance | F9: Growth | G9: n.a. | H9: USD | J9: 62.272053 | K9: 65.385655 | L9: 69.308795 | M9: 74.16041 | N9: 75.643619 | P9: 57.743176 | Q9: 58.89804 | R9: 60.076 | S9: 60.97714 | T9: 61.891798
E10: Other Expense | F10: Growth | G10: n.a. | H10: USD | J10: 2.7125588 | K10: 2.8481867 | L10: 3.0190779 | M10: 3.2304133 | N10: 3.2950216 | P10: 2.4782923 | Q10: 2.4906838 | R10: 2.5031372 | S10: 2.5156529 | T10: 2.5282311
E11: Advertising Expense | F11: Growth | G11: n.a. | H11: USD | J11: 3.6642461 | K11: 3.8474585 | L11: 4.078306 | M11: 4.3637874 | N11: 4.4510631 | P11: 3.4144112 | Q11: 3.4997715 | R11: 3.5872657 | S11: 3.6769474 | T11: 3.7688711
E12: Dues and Subscriptions | F12: Growth | G12: n.a. | H12: USD | J12: 49.088052 | K12: 51.542455 | L12: 54.635002 | M12: 58.459452 | N12: 59.628641 | P12: 45.964267 | Q12: 47.343195 | R12: 48.763491 | S12: 50.226395 | T12: 51.733187
E13: Business License & Fees | F13: Growth | G13: n.a. | H13: USD | J13: 84.469832 | K13: 88.693324 | L13: 94.014924 | M13: 100.59597 | N13: 102.60789 | P13: 78.326572 | Q13: 79.893103 | R13: 81.490965 | S13: 83.120785 | T13: 84.7832
A15: Margin calculation
E17: {=_xlfn.LET( _xlpm.driver_table, _xlfn.CHOOSECOLS( Drivers!$B$7:$F$64,{1,2,4,5} ), _xlpm.filter_cols, _xlfn._xlws.FILTER( _xlpm.driver_table, ( INDEX( _xlpm.driver_table,, 3 ) <> 0 ) * ISNUMBER( SEARCH( "Margin", IFERROR( INDEX( _xlpm.driver_table,, 3), "" ) ) ) * ISNUMBER( SEARCH( "Revenue", IFERROR( INDEX( _xlpm.driver_table,, 4), "" ) ) ) ), _xlpm.merge_cols, IF( INDEX( _xlpm.filter_cols,,2 ) = 0, INDEX( _xlpm.filter_cols,, 1 ), INDEX( _xlpm.filter_cols,, 2 ) ), _xlfn.HSTACK( _xlpm.merge_cols, _xlfn.CHOOSECOLS( _xlpm.filter_cols, {3,4} ) ) )} -> Purchases (Cost of Goods) | F17: Margin | G17: Revenue | H17: USD | J17: {=_xlfn.LET( _xlpm.current_account, _xlfn.CHOOSECOLS(_xlfn.ANCHORARRAY( $E$17), 1), _xlpm.margin_data, Assumptions!$G$29:$K$54, _xlpm.margin_rows, Assumptions!$D$29:$D$54, _xlpm.margin_columns, Assumptions!$G$6:$K$6, _xlpm.margin, INDEX( _xlpm.margin_data, MATCH( _xlpm.current_account, _xlpm.margin_rows, 0 ), MATCH(_xlfn.ANCHORARRAY( J$3), _xlpm.margin_columns, 0 ) ), _xlpm.current_driver, _xlfn.CHOOSECOLS(_xlfn.ANCHORARRAY( $E$17), 3), _xlpm.driver_data,_xlfn.ANCHORARRAY( $J$7), _xlpm.driver_rows, $E$7:$E$13, _xlpm.driver_columns,_xlfn.ANCHORARRAY( Time!J$10), _xlpm.driver, INDEX( _xlpm.driver_data, MATCH( _xlpm.current_driver, _xlpm.driver_rows, 0 ), MATCH(_xlfn.ANCHORARRAY( J$3), _xlpm.driver_columns, 0 ) ), _xlfn.IFNA( _xlpm.driver * _xlpm.margin, 0 ) )} -> 167.90199 | K17: 176.29709 | L17: 205.56241 | M17: 249.9452 | N17: 254.94411
E18: Professional Liability Insurance | F18: Margin | G18: Revenue | H18: USD | J18: 4.1975498 | K18: 4.4074273 | L18: 4.6718729 | M18: 4.998904 | N18: 5.0988821
E19: Car Lease | F19: Margin | G19: Revenue | H19: USD | J19: 20.987749 | K19: 22.037136 | L19: 23.359365 | M19: 29.993424 | N19: 30.593293
E20: Accounting Fees | F20: Margin | G20: Revenue | H20: USD | J20: 0 | K20: 0 | L20: 0 | M20: 0 | N20: 0
E21: Legal Fees | F21: Margin | G21: Revenue | H21: USD | J21: 0 | K21: 0 | L21: 0 | M21: 0 | N21: 0
E22: Supplies | F22: Margin | G22: Revenue | H22: USD | J22: 20.148239 | K22: 21.155651 | L22: 22.42499 | M22: 23.994739 | N22: 24.474634
E23: Marketing Expense | F23: Margin | G23: Revenue | H23: USD | J23: 14.271669 | K23: 14.985253 | L23: 15.884368 | M23: 16.996274 | N23: 17.336199
E24: Conferences and Seminars | F24: Margin | G24: Revenue | H24: USD | J24: 0.83950996 | K24: 0.88148546 | L24: 0.93437458 | M24: 0.9997808 | N24: 1.0197764
E25: Telephone | F25: Margin | G25: Revenue | H25: USD | J25: 6.7160797 | K25: 7.0518836 | L25: 7.4749967 | M25: 7.9982464 | N25: 8.1582114
E26: Sales Commission (outside reps) | F26: Margin | G26: Revenue | H26: USD | J26: 2.5185299 | K26: 2.6444564 | L26: 2.8031238 | M26: 2.9993424 | N26: 3.0593293
E27: Travel | F27: Margin | G27: Revenue | H27: USD | J27: 7.5555896 | K27: 7.9333691 | L27: 8.4093713 | M27: 8.9980272 | N27: 9.1779878
E28: Contributions | F28: Margin | G28: Revenue | H28: USD | J28: 6.7160797 | K28: 7.0518836 | L28: 7.4749967 | M28: 7.9982464 | N28: 8.1582114
E29: Promotional Expense | F29: Margin | G29: Revenue | H29: USD | J29: 0.83950996 | K29: 0.88148546 | L29: 0.93437458 | M29: 0.9997808 | N29: 1.0197764
... E32: Computer Repairs | F32: Margin | G32: Revenue | H32: USD | J32: 26.024809 | K32: 27.326049 | L32: 28.965612 | M32: 30.993205 | N32: 31.613069
E34: {=_xlfn.LET( _xlpm.driver_table, _xlfn.CHOOSECOLS( Drivers!$B$7:$F$64,{1,2,4,5} ), _xlpm.filter_cols, _xlfn._xlws.FILTER( _xlpm.driver_table, ( INDEX( _xlpm.driver_table,, 3 ) <> 0 ) * ISNUMBER( SEARCH( "Margin", IFERROR( INDEX( _xlpm.driver_table,, 3), "" ) ) ) * ISNUMBER( SEARCH( "Car Lease", IFERROR( INDEX( _xlpm.driver_table,, 4), "" ) ) ) ), _xlpm.merge_cols, IF( INDEX( _xlpm.filter_cols,,2 ) = 0, INDEX( _xlpm.filter_cols,, 1 ), INDEX( _xlpm.filter_cols,, 2 ) ), _xlfn.HSTACK( _xlpm.merge_cols, _xlfn.CHOOSECOLS( _xlpm.filter_cols, {3,4} ) ) )} -> Gas | F34: Margin | G34: Car Lease | H34: USD | J34: {=_xlfn.LET( _xlpm.current_account, _xlfn.CHOOSECOLS(_xlfn.ANCHORARRAY( E34), 1), _xlpm.margin_data, Assumptions!$G$29:$K$54, _xlpm.margin_rows, Assumptions!$D$29:$D$54, _xlpm.margin_columns, Assumptions!$G$6:$K$6, _xlpm.margin, INDEX( _xlpm.margin_data, MATCH( _xlpm.current_account, _xlpm.margin_rows, 0 ), MATCH(_xlfn.ANCHORARRAY( J$3), _xlpm.margin_columns, 0 ) ), _xlpm.current_driver, _xlfn.CHOOSECOLS(_xlfn.ANCHORARRAY( E34), 3), _xlpm.driver_data,_xlfn.ANCHORARRAY( $J$17), _xlpm.driver_rows, $E$17:$E$32, _xlpm.driver_columns,_xlfn.ANCHORARRAY( Time!J$10), _xlpm.driver, INDEX( _xlpm.driver_data, MATCH( _xlpm.current_driver, _xlpm.driver_rows, 0 ), MATCH(_xlfn.ANCHORARRAY( J$3), _xlpm.driver_columns, 0 ) ), _xlfn.IFNA( _xlpm.driver * _xlpm.margin, 0 ) )} -> 5.2469372 | K34: 5.5092841 | L34: 5.8398411 | M34: 7.498356 | N34: 7.6483232
E35: Insurance-Auto | F35: Margin | G35: Car Lease | H35: USD | J35: 2.6234686 | K35: 2.7546421 | L35: 2.9199206 | M35: 3.749178 | N35: 3.8241616
E36: Registration & License | F36: Margin | G36: Car Lease | H36: USD | J36: 3.9876723 | K36: 4.1870559 | L36: 4.4382793 | M36: 5.6987506 | N36: 5.8127256
E37: Repairs & Maintenance | F37: Margin | G37: Car Lease | H37: USD | J37: 5.8765697 | K37: 6.1703982 | L37: 6.5406221 | M37: 8.3981588 | N37: 8.5661219
E39: {=_xlfn.LET( _xlpm.driver_table, _xlfn.CHOOSECOLS( Drivers!$B$7:$F$64,{1,2,4,5} ), _xlpm.filter_cols, _xlfn._xlws.FILTER( _xlpm.driver_table, ( INDEX( _xlpm.driver_table,, 3 ) <> 0 ) * ISNUMBER( SEARCH( "Margin", IFERROR( INDEX( _xlpm.driver_table,, 3), "" ) ) ) * ISNUMBER( SEARCH( "Packaging Material", IFERROR( INDEX( _xlpm.driver_table,, 4), "" ) ) ) ), _xlpm.merge_cols, IF( INDEX( _xlpm.filter_cols,,2 ) = 0, INDEX( _xlpm.filter_cols,, 1 ), INDEX( _xlpm.filter_cols,, 2 ) ), _xlfn.HSTACK( _xlpm.merge_cols, _xlfn.CHOOSECOLS( _xlpm.filter_cols, {3,4} ) ) )} -> Freight Costs | F39: Margin | G39: Packaging Materials | H39: USD | J39: {=_xlfn.LET( _xlpm.current_account, _xlfn.CHOOSECOLS(_xlfn.ANCHORARRAY( E39), 1), _xlpm.margin_data, Assumptions!$G$29:$K$54, _xlpm.margin_rows, Assumptions!$D$29:$D$54, _xlpm.margin_columns, Assumptions!$G$6:$K$6, _xlpm.margin, INDEX( _xlpm.margin_data, MATCH( _xlpm.current_account, _xlpm.margin_rows, 0 ), MATCH(_xlfn.ANCHORARRAY( J$3), _xlpm.margin_columns, 0 ) ), _xlpm.current_driver, _xlfn.CHOOSECOLS(_xlfn.ANCHORARRAY( E39), 3), _xlpm.driver_data,_xlfn.ANCHORARRAY( $J$17), _xlpm.driver_rows, $E$17:$E$32, _xlpm.driver_columns,_xlfn.ANCHORARRAY( Time!J$10), _xlpm.driver, INDEX( _xlpm.driver_data, MATCH( _xlpm.current_driver, _xlpm.driver_rows, 0 ), MATCH(_xlfn.ANCHORARRAY( J$3), _xlpm.driver_columns, 0 ) ), _xlfn.IFNA( _xlpm.driver * _xlpm.margin, 0 ) )} -> 1.5950689 | K39: 1.6748224 | L39: 1.7753117 | M39: 1.8995835 | N39: 1.9375752
E40: Postage and Delivery | F40: Margin | G40: Packaging Materials | H40: USD | J40: 8.3950996 | K40: 8.8148546 | L40: 9.3437458 | M40: 9.997808 | N40: 10.197764
E42: {=_xlfn.LET( _xlpm.driver_table, _xlfn.CHOOSECOLS( Drivers!$B$7:$F$64,{1,2,4,5} ), _xlpm.filter_cols, _xlfn._xlws.FILTER( _xlpm.driver_table, ( INDEX( _xlpm.driver_table,, 3 ) <> 0 ) * ISNUMBER( SEARCH( "Margin", IFERROR( INDEX( _xlpm.driver_table,, 3), "" ) ) ) * ISNUMBER( SEARCH( "Rent", IFERROR( INDEX( _xlpm.driver_table,, 4), "" ) ) ) ), _xlpm.merge_cols, IF( INDEX( _xlpm.filter_cols,,2 ) = 0, INDEX( _xlpm.filter_cols,, 1 ), INDEX( _xlpm.filter_cols,, 2 ) ), _xlfn.HSTACK( _xlpm.merge_cols, _xlfn.CHOOSECOLS( _xlpm.filter_cols, {3,4} ) ) )} -> Maintenance/Janitorial | F42: Margin | G42: Rent | H42: USD | J42: {=_xlfn.LET( _xlpm.current_account, _xlfn.CHOOSECOLS(_xlfn.ANCHORARRAY( E42), 1), _xlpm.margin_data, Assumptions!$G$29:$K$54, _xlpm.margin_rows, Assumptions!$D$29:$D$54, _xlpm.margin_columns, Assumptions!$G$6:$K$6, _xlpm.margin, INDEX( _xlpm.margin_data, MATCH( _xlpm.current_account, _xlpm.margin_rows, 0 ), MATCH(_xlfn.ANCHORARRAY( J$3), _xlpm.margin_columns, 0 ) ), _xlpm.current_driver, _xlfn.CHOOSECOLS(_xlfn.ANCHORARRAY( E42), 3), _xlpm.driver_data,_xlfn.ANCHORARRAY( $J$62), _xlpm.driver_rows, $E$62, _xlpm.driver_columns,_xlfn.ANCHORARRAY( Time!J$10), _xlpm.driver, INDEX( _xlpm.driver_data, MATCH( _xlpm.current_driver, _xlpm.driver_rows, 0 ), MATCH(_xlfn.ANCHORARRAY( J$3), _xlpm.driver_columns, 0 ) ), _xlfn.IFNA( _xlpm.driver * _xlpm.margin, 0 ) )} -> 1.1604674 | K42: 1.1836768 | L42: 1.2073503 | M42: 1.2314973 | N42: 1.2561273
E43: Office Equipment | F43: Margin | G43: Rent | H43: USD | J43: 8.123272 | K43: 8.2857374 | L43: 8.4514522 | M43: 8.6204812 | N43: 8.7928908
E44: Utilities | F44: Margin | G44: Rent | H44: USD | J44: 2.1468647 | K44: 2.189802 | L44: 2.2335981 | M44: 2.27827 | N44: 2.3238354
E46: {=_xlfn.LET( _xlpm.driver_table, _xlfn.CHOOSECOLS( Drivers!$B$7:$F$64,{1,2,4,5} ), _xlpm.filter_cols, _xlfn._xlws.FILTER( _xlpm.driver_table, ( INDEX( _xlpm.driver_table,, 3 ) <> 0 ) * ISNUMBER( SEARCH( "Margin", IFERROR( INDEX( _xlpm.driver_table,, 3), "" ) ) ) * ISNUMBER( SEARCH( "Total Wages", IFERROR( INDEX( _xlpm.driver_table,, 4), "" ) ) ) ), _xlpm.merge_cols, IF( INDEX( _xlpm.filter_cols,,2 ) = 0, INDEX( _xlpm.filter_cols,, 1 ), INDEX( _xlpm.filter_cols,, 2 ) ), _xlfn.HSTACK( _xlpm.merge_cols, _xlfn.CHOOSECOLS( _xlpm.filter_cols, {3,4} ) ) )} -> Worker's Compensation | F46: Margin | G46: Total Wages | H46: USD | J46: {=_xlfn.LET( _xlpm.current_account, _xlfn.CHOOSECOLS(_xlfn.ANCHORARRAY( E46), 1), _xlpm.margin_data, Assumptions!$G$29:$K$54, _xlpm.margin_rows, Assumptions!$D$29:$D$54, _xlpm.margin_columns, Assumptions!$G$6:$K$6, _xlpm.margin, INDEX( _xlpm.margin_data, MATCH( _xlpm.current_account, _xlpm.margin_rows, 0 ), MATCH(_xlfn.ANCHORARRAY( J$3), _xlpm.margin_columns, 0 ) ), _xlpm.anchor, $J$57, _xlpm.block, OFFSET( _xlpm.anchor, 0, 0, 3, periods ), _xlpm.driver, _xlfn.BYCOL( _xlpm.block, _xleta.SUM ), _xlfn.IFNA( _xlpm.driver * _xlpm.margin, 0 ) )} -> 0.57450953 | K46: 0.58599972 | L46: 0.72916092 | M46: 0.74374414 | N46: 0.75861902
E47: Payroll Tax Expenses | F47: Margin | G47: Total Wages | H47: USD | J47: 2.8725477 | K47: 2.9299986 | L47: 3.6458046 | M47: 3.7187207 | N47: 3.7930951
E48: Payroll Service Fees | F48: Margin | G48: Total Wages | H48: USD | J48: 0 | K48: 0 | L48: 0 | M48: 0 | N48: 0
E49: Meals and Entertainment | F49: Margin | G49: Total Wages | H49: USD | J49: 2.2980381 | K49: 2.3439989 | L49: 2.9166437 | M49: 2.9749766 | N49: 3.0344761
A51: Step calculation
...

Sheet Drivers
B2: =DataPull!$B$2 -> CFM - April 2019 Exam
B3: Model Driver Mapping
B5: ($ mm, unless otherwise noted)
B7: Line Item | E7: Method | F7: Driver
B9: Revenue | E9: Growth | F9: n.a. | H9: =B9&C9 -> Revenue
H10: =B10&C10
B11: Purchases (Cost of Goods) | E11: Margin | F11: Revenue | H11: =B11&C11 -> Purchases (Cost of Goods)
B12: Insurance | H12: =B12&C12 -> Insurance
C13: General Liability Insurance | E13: Growth | F13: n.a. | H13: =B13&C13 -> General Liability Insurance
C14: Owner's Health Insurance | E14: Growth | F14: n.a. | H14: =B14&C14 -> Owner's Health Insurance
C15: Professional Liability Insurance | E15: Margin | F15: Revenue | H15: =B15&C15 -> Professional Liability Insurance
C16: Worker's Compensation | E16: Margin | F16: Total Wages | H16: =B16&C16 -> Worker's Compensation
B17: Wages | H17: =B17&C17 -> Wages
C18: Employee Benefits | E18: Growth | F18: $ / Employee | H18: =B18&C18 -> Employee Benefits
C19: Payroll Tax Expenses | E19: Margin | F19: Total Wages | H19: =B19&C19 -> Payroll Tax Expenses
C20: Salaries - Office Staff | E20: Step | F20: Growth in Salaries | H20: =B20&C20 -> Salaries - Office Staff
B21: Direct Labor | H21: =B21&C21 -> Direct Labor
C22: Salaries - Inside Sales | E22: Step | F22: Growth in Salaries | H22: =B22&C22 -> Salaries - Inside Sales
C23: Salaries - Warehouse | E23: Step | F23: Growth in Salaries | H23: =B23&C23 -> Salaries - Warehouse
B24: Car/Truck Expense | H24: =B24&C24 -> Car/Truck Expense
C25: Car Lease | E25: Margin | F25: Revenue | H25: =B25&C25 -> Car Lease
C26: Gas | E26: Margin | F26: Car Lease | H26: =B26&C26 -> Gas
C27: Insurance-Auto | E27: Margin | F27: Car Lease | H27: =B27&C27 -> Insurance-Auto
C28: Registration & License | E28: Margin | F28: Car Lease | H28: =B28&C28 -> Registration & License
C29: Repairs & Maintenance | E29: Margin | F29: Car Lease | H29: =B29&C29 -> Repairs & Maintenance
B30: Professional Fees | H30: =B30&C30 -> Professional Fees
C31: Accounting Fees | E31: Margin | F31: Revenue | H31: =B31&C31 -> Accounting Fees
C32: Legal Fees | E32: Margin | F32: Revenue | H32: =B32&C32 -> Legal Fees
C33: Payroll Service Fees | E33: Margin | F33: Total Wages | H33: =B33&C33 -> Payroll Service Fees
B34: Rent | E34: Step | F34: Growth in Cost per Sqft | H34: =B34&C34 -> Rent
B35: Supplies | E35: Margin | F35: Revenue | H35: =B35&C35 -> Supplies
B36: Marketing Expense | E36: Margin | F36: Revenue | H36: =B36&C36 -> Marketing Expense
B37: Conferences and Seminars | E37: Margin | F37: Revenue | H37: =B37&C37 -> Conferences and Seminars
B38: Telephone | E38: Margin | F38: Revenue | H38: =B38&C38 -> Telephone
B39: Sales Commission (outside reps) | E39: Margin | F39: Revenue | H39: =B39&C39 -> Sales Commission (outside reps)
B40: Travel | E40: Margin | F40: Revenue | H40: =B40&C40 -> Travel
B41: Maintenance/Janitorial | E41: Margin | F41: Rent | H41: =B41&C41 -> Maintenance/Janitorial
B42: Contributions | E42: Margin | F42: Revenue | H42: =B42&C42 -> Contributions
B43: Other Expense | E43: Growth | F43: n.a. | H43: =B43&C43 -> Other Expense
B44: Promotional Expense | E44: Margin | F44: Revenue | H44: =B44&C44 -> Promotional Expense
...

Sheet Time
A1: {=company} -> Powerstill Inc.
A2: {=topic} -> CFM Topic: Costs
A3: TMP SCHEDULE | J3: {=EOMONTH(last_actual_date,_xlfn.SEQUENCE(1,periods,12,12))} -> 43830 | K3: 44196 | L3: 44561 | M3: 44926 | N3: 45291
A5: Model timeline and flags
E7: Last actual date | F7: =last_actual_date -> 43465 | G7: date
E8: Model periods | F8: =COUNT( Assumptions!G6:K6 ) -> 5 | G8: years
E10: Model period end | G10: date | J10: {=EOMONTH(last_actual_date,_xlfn.SEQUENCE(1,periods,12,12))} -> 43830 | K10: 44196 | L10: 44561 | M10: 44926 | N10: 45291
A45: End of Schedule

Sheet DataPull
B2: CFM - April 2019 Exam
B3: Historical Financials
B5: ($ mm, unless otherwise noted)
B7: CATEGORY | C7: EXPENSE ITEM | D7: DATE | E7: AMOUNT | G7: {=_xlfn.CHOOSECOLS( _xlfn.PIVOTBY( _xlfn.CHOOSECOLS( _01_data[], {1,2} ), _01_data[DATE], _01_data[AMOUNT],_xleta.SUM,,0,,,,), {1,2,14})} | I7: 43465
B8: Revenue | C8: Revenue | D8: 39447 | E8: 561 | G8: Advertising Expense | H8: Advertising Expense | I8: 3.3311329
B9: Revenue | C9: Revenue | D9: 39813 | E9: 585.43701 | G9: Business License & Fees | H9: Business License & Fees | I9: 76.790757
B10: Revenue | C10: Revenue | D10: 40178 | E10: 610.11853 | G10: Car/Truck Expense | H10: Car Lease | I10: 32.515964
B11: Revenue | C11: Revenue | D11: 40543 | E11: 611.1861 | G11: Car/Truck Expense | H11: Gas | I11: 0.97075996
B12: Revenue | C12: Revenue | D12: 40908 | E12: 626.39199 | G12: Car/Truck Expense | H12: Insurance-Auto | I12: 1.3867685
B13: Revenue | C13: Revenue | D13: 41274 | E13: 628.02173 | G13: Car/Truck Expense | H13: Registration & License | I13: 7.5342497
B14: Revenue | C14: Revenue | D14: 41639 | E14: 656.99087 | G14: Car/Truck Expense | H14: Repairs & Maintenance | I14: 3.1109049
B15: Revenue | C15: Revenue | D15: 42004 | E15: 667.6824 | G15: Conferences and Seminars | H15: Conferences and Seminars | I15: 0.81296385
B16: Revenue | C16: Revenue | D16: 42369 | E16: 692.38855 | G16: Contributions | H16: Contributions | I16: 4.7928999
B17: Revenue | C17: Revenue | D17: 42735 | E17: 715.9986 | G17: Depreciation Expense | H17: Depreciation Expense | I17: 21.872142
B18: Revenue | C18: Revenue | D18: 43100 | E18: 738.97711 | G18: Direct Labor | H18: Salaries - Inside Sales | I18: 17.858171
B19: Revenue | C19: Revenue | D19: 43465 | E19: 763.19087 | G19: Direct Labor | H19: Salaries - Warehouse | I19: 12.489147
... B45: Insurance | C45: Owner's Health Insurance | D45: 39813 | E45: 50.567651 | G45: Wages | H45: Salaries - Office Staff | I45: 14.899445
B46: Insurance | C46: Owner's Health Insurance | D46: 40178 | E46: 51.141746
B47: Insurance | C47: Owner's Health Insurance | D47: 40543 | E47: 51.722359
B48: Insurance | C48: Owner's Health Insurance | D48: 40908 | E48: 52.309563
B49: Insurance | C49: Owner's Health Insurance | D49: 41274 | E49: 52.903434
B50: Insurance | C50: Owner's Health Insurance | D50: 41639 | E50: 53.504047
B51: Insurance | C51: Owner's Health Insurance | D51: 42004 | E51: 54.11148
B52: Insurance | C52: Owner's Health Insurance | D52: 42369 | E52: 54.725808
B53: Insurance | C53: Owner's Health Insurance | D53: 42735 | E53: 55.347111
B54: Insurance | C54: Owner's Health Insurance | D54: 43100 | E54: 55.975467
B55: Insurance | C55: Owner's Health Insurance | D55: 43465 | E55: 56.610957
B56: Insurance | C56: Professional Liability Insurance | D56: 39447 | E56: 1.6044402
B57: Insurance | C57: Professional Liability Insurance | D57: 39813 | E57: 1.6743292
... B463: Utilities | C463: Utilities | D463: 43465 | E463: 0.90460006

Sheet Assumptions
B2: =DataPull!$B$2 -> CFM - April 2019 Exam
B3: Model Driver Assumptions
B5: ($ mm, unless otherwise noted)
F6: =MAX(DataPull!D8:D463) -> 43465 | G6: =EOMONTH(F6,12) -> 43830 | H6: =EOMONTH(G6,12) -> 44196 | I6: =EOMONTH(H6,12) -> 44561 | J6: =EOMONTH(I6,12) -> 44926 | K6: =EOMONTH(J6,12) -> 45291
B8: Assumptions
C10: Growth Rates | M10: {=_xlfn.LET( _xlpm.growth_factors, $G$11:$K$25, _xlpm.growth_rows, $D$11:$D$25, _xlpm.growth_columns, $G$6:$K$6, _xlpm.title, "Compounded growth", _xlpm.compounded_rates, _xlfn.LAMBDA(_xlpm.i,_xlpm.j, INDEX( _xlfn.SCAN( 1, INDEX( _xlpm.growth_factors, _xlpm.i, 0 ), _xlfn.LAMBDA(_xlpm.s,_xlpm.c, _xlpm.s * ( 1 + _xlpm.c ) ) ), _xlpm.j ) ), _xlfn.VSTACK( _xlfn.HSTACK( _xlpm.title, _xlpm.growth_columns ), _xlfn.HSTACK( _xlpm.growth_rows, _xlfn.MAKEARRAY( ROWS( _xlpm.growth_rows ), COLUMNS( _xlpm.growth_columns ), _xlpm.compounded_rates ) ) ) )} -> Compounded growth | N10: 43830 | O10: 44196 | P10: 44561 | Q10: 44926 | R10: 45291
D11: Revenue | G11: 0.1 | H11: 0.05 | I11: 0.06 | J11: 0.07 | K11: 0.02 | M11: Revenue | N11: 1.1 | O11: 1.155 | P11: 1.2243 | Q11: 1.310001 | R11: 1.336201
D12: General Liability Insurance | G12: 0.02 | H12: 0.02 | I12: 0.02 | J12: 0.015 | K12: 0.015 | M12: General Liability Insurance | N12: 1.02 | O12: 1.0404 | P12: 1.061208 | Q12: 1.0771261 | R12: 1.093283
D13: Owner's Health Insurance | G13: 0.02 | H13: 0.02 | I13: 0.02 | J13: 0.015 | K13: 0.015 | M13: Owner's Health Insurance | N13: 1.02 | O13: 1.0404 | P13: 1.061208 | Q13: 1.0771261 | R13: 1.093283
D14: Other Expense | G14: 0.005 | H14: 0.005 | I14: 0.005 | J14: 0.005 | K14: 0.005 | M14: Other Expense | N14: 1.005 | O14: 1.010025 | P14: 1.0150751 | Q14: 1.0201505 | R14: 1.0252513
D15: Advertising Expense | G15: 0.025 | H15: 0.025 | I15: 0.025 | J15: 0.025 | K15: 0.025 | M15: Advertising Expense | N15: 1.025 | O15: 1.050625 | P15: 1.0768906 | Q15: 1.1038129 | R15: 1.1314082
D16: Dues and Subscriptions | G16: 0.03 | H16: 0.03 | I16: 0.03 | J16: 0.03 | K16: 0.03 | M16: Dues and Subscriptions | N16: 1.03 | O16: 1.0609 | P16: 1.092727 | Q16: 1.1255088 | R16: 1.1592741
D17: Business License & Fees | G17: 0.02 | H17: 0.02 | I17: 0.02 | J17: 0.02 | K17: 0.02 | M17: Business License & Fees | N17: 1.02 | O17: 1.0404 | P17: 1.061208 | Q17: 1.0824322 | R17: 1.1040808
D18: Average Salaries | M18: Average Salaries | N18: 1 | O18: 1 | P18: 1 | Q18: 1 | R18: 1
D19: Salaries - Office Staff | G19: 0.02 | H19: 0.02 | I19: 0.02 | J19: 0.02 | K19: 0.02 | M19: Salaries - Office Staff | N19: 1.02 | O19: 1.0404 | P19: 1.061208 | Q19: 1.0824322 | R19: 1.1040808
D20: Salaries - Inside Sales | G20: 0.05 | H20: 0.05 | I20: 0.05 | J20: 0.03 | K20: 0.03 | M20: Salaries - Inside Sales | N20: 1.05 | O20: 1.1025 | P20: 1.157625 | Q20: 1.1923538 | R20: 1.2281244
D21: Salaries - Warehouse | G21: 0.01 | H21: 0.01 | I21: 0.01 | J21: 0.01 | K21: 0.01 | M21: Salaries - Warehouse | N21: 1.01 | O21: 1.0201 | P21: 1.030301 | Q21: 1.040604 | R21: 1.0510101
D22: Cost / Sqft | M22: Cost / Sqft | N22: 1 | O22: 1 | P22: 1 | Q22: 1 | R22: 1
D23: Rent | G23: 0.02 | H23: 0.02 | I23: 0.02 | J23: 0.1 | K23: 0.02 | M23: Rent | N23: 1.02 | O23: 1.0404 | P23: 1.061208 | Q23: 1.1673288 | R23: 1.1906754
D24: Cost / Employee | M24: Cost / Employee | N24: 1 | O24: 1 | P24: 1 | Q24: 1 | R24: 1
D25: Employee Benefits | G25: 0.03 | H25: 0.03 | I25: 0.03 | J25: 0.03 | K25: 0.03 | M25: Employee Benefits | N25: 1.03 | O25: 1.0609 | P25: 1.092727 | Q25: 1.1255088 | R25: 1.1592741
C28: Margins | M28: {=_xlfn.LET( _xlpm.margin_factors, $G$29:$K$54, _xlpm.margins_rows, $D$29:$D$54, _xlpm.margin_columns, $G$6:$K$6, _xlpm.title, "Margins", _xlfn.VSTACK( _xlfn.HSTACK( _xlpm.title, _xlpm.margin_columns ), _xlfn.HSTACK( _xlpm.margins_rows, _xlpm.margin_factors ) ) )} -> Margins | N28: 43830 | O28: 44196 | P28: 44561 | Q28: 44926 | R28: 45291
D29: Purchases (Cost of Goods) | G29: 0.2 | H29: 0.2 | I29: 0.22 | J29: 0.25 | K29: 0.25 | M29: Purchases (Cost of Goods) | N29: 0.2 | O29: 0.2 | P29: 0.22 | Q29: 0.25 | R29: 0.25
D30: Professional Liability Insurance | G30: 0.005 | H30: 0.005 | I30: 0.005 | J30: 0.005 | K30: 0.005 | M30: Professional Liability Insurance | N30: 0.005 | O30: 0.005 | P30: 0.005 | Q30: 0.005 | R30: 0.005
D31: Worker's Compensation | G31: 0.01 | H31: 0.01 | I31: 0.01 | J31: 0.01 | K31: 0.01 | M31: Worker's Compensation | N31: 0.01 | O31: 0.01 | P31: 0.01 | Q31: 0.01 | R31: 0.01
D32: Payroll Tax Expenses | G32: 0.05 | H32: 0.05 | I32: 0.05 | J32: 0.05 | K32: 0.05 | M32: Payroll Tax Expenses | N32: 0.05 | O32: 0.05 | P32: 0.05 | Q32: 0.05 | R32: 0.05
D33: Car Lease | G33: 0.025 | H33: 0.025 | I33: 0.025 | J33: 0.03 | K33: 0.03 | M33: Car Lease | N33: 0.025 | O33: 0.025 | P33: 0.025 | Q33: 0.03 | R33: 0.03
D34: Gas | G34: 0.25 | H34: 0.25 | I34: 0.25 | J34: 0.25 | K34: 0.25 | M34: Gas | N34: 0.25 | O34: 0.25 | P34: 0.25 | Q34: 0.25 | R34: 0.25
D35: Insurance-Auto | G35: 0.125 | H35: 0.125 | I35: 0.125 | J35: 0.125 | K35: 0.125 | M35: Insurance-Auto | N35: 0.125 | O35: 0.125 | P35: 0.125 | Q35: 0.125 | R35: 0.125
D36: Registration & License | G36: 0.19 | H36: 0.19 | I36: 0.19 | J36: 0.19 | K36: 0.19 | M36: Registration & License | N36: 0.19 | O36: 0.19 | P36: 0.19 | Q36: 0.19 | R36: 0.19
D37: Repairs & Maintenance | G37: 0.28 | H37: 0.28 | I37: 0.28 | J37: 0.28 | K37: 0.28 | M37: Repairs & Maintenance | N37: 0.28 | O37: 0.28 | P37: 0.28 | Q37: 0.28 | R37: 0.28
D38: Supplies | G38: 0.024 | H38: 0.024 | I38: 0.024 | J38: 0.024 | K38: 0.024 | M38: Supplies | N38: 0.024 | O38: 0.024 | P38: 0.024 | Q38: 0.024 | R38: 0.024
D39: Marketing Expense | G39: 0.017 | H39: 0.017 | I39: 0.017 | J39: 0.017 | K39: 0.017 | M39: Marketing Expense | N39: 0.017 | O39: 0.017 | P39: 0.017 | Q39: 0.017 | R39: 0.017
D40: Conferences and Seminars | G40: 0.001 | H40: 0.001 | I40: 0.001 | J40: 0.001 | K40: 0.001 | M40: Conferences and Seminars | N40: 0.001 | O40: 0.001 | P40: 0.001 | Q40: 0.001 | R40: 0.001
... D54: Utilities | G54: 0.185 | H54: 0.185 | I54: 0.185 | J54: 0.185 | K54: 0.185 | M54: Utilities | N54: 0.185 | O54: 0.185 | P54: 0.185 | Q54: 0.185 | R54: 0.185
C57: Office Staff | F57: Minimum of 1 Office Staff for each | G57: 6 | H57: Other Staff (Inside Sales & Warehouse)
C60: Step Functions | F60: FTE
D61: If Revenue >= | F61: Inside Sales | G61: Warehouse
D62: 0 | F62: 0 | G62: 2 | I62: {=_xlfn.LET( _xlpm.step_data, $F$62:$G$71, _xlpm.step_rows, $D$62:$D$71, _xlpm.step_columns, _xlfn.CHOOSECOLS( $D$61:$G$61, {1,3,4} ), _xlpm.step_table, _xlfn.VSTACK( _xlpm.step_columns, _xlfn.HSTACK( _xlpm.step_rows, _xlpm.step_data ) ), _xlpm.step_table )} -> If Revenue >= | J62: Inside Sales | K62: Warehouse
D63: =D62+150 -> 150 | F63: 1 | G63: 5 | I63: 0 | J63: 0 | K63: 2
...

Sheet Tmp
A1: {=company} -> Powerstill Inc.
A2: {=topic} -> CFM Topic: Costs
A3: TMP SCHEDULE
A45: End of Schedule
