Workbook
Name company: CaseData!$K$17
Name periods: CaseData!$K$16
Name start_date: CaseData!$K$15
Name topic: "CFM Topic: Costs"

Sheet Summary
A1: =company -> Big Fish Co.
A2: {=topic} -> CFM Topic: Costs
A3: EXCUTIVE SUMMARY | F3: Constant | G3: Unit | H3: Total | J3: {=_xlfn.TAKE( EOMONTH( start_date, _xlfn.SEQUENCE( 1, periods, 1, 1 ) - 1 ),, -12 )} -> 43861 | K3: 43890 | L3: 43921 | M3: 43951 | N3: 43982 | O3: 44012 | P3: 44043 | Q3: 44074 | R3: 44104 | S3: 44135 | T3: 44165 | U3: 44196
A5: REVENUE BY CLIENT
E7: {=_xlfn.LET( _xlpm.revenue,_xlfn.ANCHORARRAY( Calculations!V197), _xlpm.revenue_rows, _xlfn.DROP( INDEX(_xlfn.ANCHORARRAY( Calculations!E196),, 1 ), 1 ), _xlpm.grouped, _xlfn.GROUPBY( _xlpm.revenue_rows, _xlpm.revenue, _xleta.SUM, 0, 0 ), _xlpm.labels, INDEX( _xlpm.grouped,, 1 ), _xlpm.rev_matrix, _xlfn.DROP( _xlpm.grouped,, 1 ), _xlpm.sort_order, MMULT( _xlpm.rev_matrix, _xlfn.SEQUENCE( COLUMNS(_xlpm.rev_matrix), 1, 1, 0 ) ), _xlfn.SORTBY( _xlpm.labels, _xlpm.sort_order, -1 ) )} -> Client 4 | G7: USD | H7: {=_xlfn.BYROW(_xlfn.ANCHORARRAY( J7), _xleta.SUM )} -> 28589247 | J7: {=_xlfn.LET( _xlpm.revenue,_xlfn.ANCHORARRAY( Calculations!V197), _xlpm.revenue_rows, _xlfn.DROP( INDEX(_xlfn.ANCHORARRAY( Calculations!E196),, 1 ), 1 ), _xlpm.grouped, _xlfn.GROUPBY( _xlpm.revenue_rows, _xlpm.revenue, _xleta.SUM, 0, 0 ), _xlpm.rev_matrix, _xlfn.DROP( _xlpm.grouped,, 1 ), _xlpm.sort_order, MMULT( _xlpm.rev_matrix, _xlfn.SEQUENCE( COLUMNS(_xlpm.rev_matrix), 1, 1, 0 ) ), _xlfn.SORTBY( _xlpm.rev_matrix, _xlpm.sort_order, -1 ) )} -> 2609106.4 | K7: 2016183.1 | L7: 2617854.2 | M7: 3339089.9 | N7: 1965966 | O7: 1920737 | P7: 1715634.6 | Q7: 2755115.8 | R7: 2434191.6 | S7: 3058445.4 | T7: 2377408.1 | U7: 1779514.4
E8: Client 3 | G8: USD | H8: 12009800 | J8: 1008120 | K8: 1166334.6 | L8: 1113695.8 | M8: 971973.94 | N8: 1094743.3 | O8: 947009.91 | P8: 884676.63 | Q8: 716452.51 | R8: 1137308.1 | S8: 1174666 | T8: 907736.94 | U8: 887082.2
E9: Client 1 | G9: USD | H9: 4738211.4 | J9: 465255.09 | K9: 239206.5 | L9: 237128.48 | M9: 278555.84 | N9: 353406.45 | O9: 455370.72 | P9: 445532.62 | Q9: 534480.41 | R9: 496536.8 | S9: 221558.57 | T9: 480971.25 | U9: 530208.67
E10: Client 2 | G10: USD | H10: 3057575.4 | J10: 196205.13 | K10: 205465.91 | L10: 88478.315 | M10: 0 | N10: 356951.62 | O10: 408808.04 | P10: 478364.3 | Q10: 379898.96 | R10: 166506.8 | S10: 26271.283 | T10: 261399.37 | U10: 489225.72
E11: Client 5 | G11: USD | H11: 2692257.9 | J11: 201000.68 | K11: 336551.94 | L11: 336551.94 | M11: 292156.74 | N11: 228994.11 | O11: 247682.68 | P11: 238377.82 | Q11: 140203.69 | R11: 254700.75 | S11: 116862.7 | T11: 142569.33 | U11: 156605.47
E12: Total revenue | G12: USD | H12: {=_xlfn.BYROW(_xlfn.ANCHORARRAY( J12), _xleta.SUM )} -> 51087091 | J12: {=_xlfn.BYCOL(_xlfn.ANCHORARRAY( J7), _xleta.SUM )} -> 4479687.3 | K12: 3963742 | L12: 4393708.7 | M12: 4881776.4 | N12: 4000061.4 | O12: 3979608.4 | P12: 3762586 | Q12: 4526151.4 | R12: 4489244 | S12: 4597803.9 | T12: 4170085 | U12: 3842636.4
A15: COSTS OF GOODS SOLD
E17: {=_xlfn.LET( _xlpm.COGS,_xlfn.ANCHORARRAY( Calculations!V229), _xlpm.cogs_rows, _xlfn.DROP( INDEX(_xlfn.ANCHORARRAY( Calculations!E228),, 2 ), 1 ), _xlpm.grouped, _xlfn.GROUPBY( _xlpm.cogs_rows, _xlpm.COGS, _xleta.SUM, 0, 0 ), _xlpm.labels, "Product " & INDEX( _xlpm.grouped,, 1 ), _xlpm.rev_matrix, _xlfn.DROP( _xlpm.grouped,, 1 ), _xlpm.sort_order, MMULT( _xlpm.rev_matrix, _xlfn.SEQUENCE( COLUMNS(_xlpm.rev_matrix), 1, 1, 0 ) ), _xlfn.SORTBY( _xlpm.labels, _xlpm.sort_order, -1 ) )} -> Product 1 | G17: USD | H17: {=_xlfn.BYROW(_xlfn.ANCHORARRAY( J17), _xleta.SUM )} -> 18606705 | J17: {=_xlfn.LET( _xlpm.COGS,_xlfn.ANCHORARRAY( Calculations!V229), _xlpm.cogs_rows, _xlfn.DROP( INDEX(_xlfn.ANCHORARRAY( Calculations!E228),, 2 ), 1 ), _xlpm.grouped, _xlfn.GROUPBY( _xlpm.cogs_rows, _xlpm.COGS, _xleta.SUM, 0, 0 ), _xlpm.rev_matrix, _xlfn.DROP( _xlpm.grouped,, 1 ), _xlpm.sort_order, MMULT( _xlpm.rev_matrix, _xlfn.SEQUENCE( COLUMNS(_xlpm.rev_matrix), 1, 1, 0 ) ), _xlfn.SORTBY( _xlpm.rev_matrix, _xlpm.sort_order, -1 ) )} -> 1723557.1 | K17: 1287513.9 | L17: 1632961.2 | M17: 2056926.3 | N17: 1320722.4 | O17: 1337494.6 | P17: 1189469.8 | Q17: 1805591.8 | R17: 1776040.6 | S17: 1785241.5 | T17: 1463691.5 | U17: 1227494.4
E18: Product 2 | G18: USD | H18: 4054788.6 | J18: 397972.22 | K18: 382305.26 | L18: 419266.12 | M18: 391174.49 | N18: 370246 | O18: 239220.26 | P18: 258980.18 | Q18: 269083.47 | R18: 287437.21 | S18: 367380.27 | T18: 340079.85 | U18: 331643.28
E19: Product 5 | G19: USD | H19: 2356945.8 | J19: 129141.31 | K19: 236479.71 | L19: 179464.99 | M19: 140639.06 | N19: 180953.38 | O19: 273769.92 | P19: 243733.94 | Q19: 140887.52 | R19: 218029.04 | S19: 219705.15 | T19: 214676.81 | U19: 179464.99
E20: Product 3 | G20: USD | H20: 1310248.8 | J20: 88328.614 | K20: 99038.011 | L20: 49943.126 | M20: 14461.452 | N20: 147254.35 | O20: 156634.32 | P20: 198788.12 | Q20: 150936.07 | R20: 79411.47 | S20: 20620.21 | T20: 110265.31 | U20: 194567.71
E21: Product 4 | G21: USD | H21: 0 | J21: 0 | K21: 0 | L21: 0 | M21: 0 | N21: 0 | O21: 0 | P21: 0 | Q21: 0 | R21: 0 | S21: 0 | T21: 0 | U21: 0
E22: Total Costs of Goods Sold | G22: USD | H22: {=_xlfn.BYROW(_xlfn.ANCHORARRAY( J22), _xleta.SUM )} -> 26328688 | J22: {=_xlfn.BYCOL(_xlfn.ANCHORARRAY( J17), _xleta.SUM )} -> 2338999.2 | K22: 2005336.9 | L22: 2281635.5 | M22: 2603201.3 | N22: 2019176.1 | O22: 2007119.2 | P22: 1890972 | Q22: 2366498.9 | R22: 2360918.3 | S22: 2392947.1 | T22: 2128713.5 | U22: 1933170.3
A25: MANUFACTORING PLAN
E27: {=_xlfn.LET( _xlpm.volume,_xlfn.ANCHORARRAY( Calculations!V166), _xlpm.volume_rows, _xlfn.DROP( INDEX(_xlfn.ANCHORARRAY( Calculations!E228),, 2 ), 1 ), _xlpm.grouped, _xlfn.GROUPBY( _xlpm.volume_rows, _xlpm.volume, _xleta.SUM, 0, 0 ), _xlpm.labels, "Product " & INDEX( _xlpm.grouped,, 1 ), _xlpm.rev_matrix, _xlfn.DROP( _xlpm.grouped,, 1 ), _xlpm.sort_order, MMULT( _xlpm.rev_matrix, _xlfn.SEQUENCE( COLUMNS(_xlpm.rev_matrix), 1, 1, 0 ) ), _xlfn.SORTBY( _xlpm.labels, _xlpm.sort_order, -1 ) )} -> Product 1 | G27: units | H27: {=_xlfn.BYROW(_xlfn.ANCHORARRAY( J27), _xleta.SUM )} -> 695577.76 | J27: {=_xlfn.LET( _xlpm.volume,_xlfn.ANCHORARRAY( Calculations!V166), _xlpm.volume_rows, _xlfn.DROP( INDEX(_xlfn.ANCHORARRAY( Calculations!E228),, 2 ), 1 ), _xlpm.grouped, _xlfn.GROUPBY( _xlpm.volume_rows, _xlpm.volume, _xleta.SUM, 0, 0 ), _xlpm.rev_matrix, _xlfn.DROP( _xlpm.grouped,, 1 ), _xlpm.sort_order, MMULT( _xlpm.rev_matrix, _xlfn.SEQUENCE( COLUMNS(_xlpm.rev_matrix), 1, 1, 0 ) ), _xlfn.SORTBY( _xlpm.rev_matrix, _xlpm.sort_order, -1 ) )} -> 64432.04 | K27: 48131.36 | L27: 61045.28 | M27: 76894.44 | N27: 49372.8 | O27: 49999.8 | P27: 44466.16 | Q27: 67498.76 | R27: 66394.04 | S27: 66738 | T27: 54717.44 | U27: 45887.64
E28: Product 2 | G28: units | H28: 508890.5 | J28: 49946.94 | K28: 47980.68 | L28: 52619.4 | M28: 49093.8 | N28: 46467.2 | O28: 30023 | P28: 32502.94 | Q28: 33770.94 | R28: 36074.4 | S28: 46107.54 | T28: 42681.24 | U28: 41622.42
E29: Product 5 | G29: units | H29: 358579.92 | J29: 19647.24 | K29: 35977.44 | L29: 27303.36 | M29: 21396.48 | N29: 27529.8 | O29: 41650.68 | P29: 37081.08 | Q29: 21434.28 | R29: 33170.4 | S29: 33425.4 | T29: 32660.4 | U29: 27303.36
E30: Product 3 | G30: units | H30: 236951.82 | J30: 15973.78 | K30: 17910.52 | L30: 9031.96 | M30: 2615.28 | N30: 26630.2 | O30: 28326.52 | P30: 35949.82 | Q30: 27296.02 | R30: 14361.16 | S30: 3729.06 | T30: 19940.92 | U30: 35186.58
E31: Product 4 | G31: units | H31: 0 | J31: 0 | K31: 0 | L31: 0 | M31: 0 | N31: 0 | O31: 0 | P31: 0 | Q31: 0 | R31: 0 | S31: 0 | T31: 0 | U31: 0
E32: Total Production | G32: units | H32: {=_xlfn.BYROW(_xlfn.ANCHORARRAY( J32), _xleta.SUM )} -> 1800000 | J32: {=_xlfn.BYCOL(_xlfn.ANCHORARRAY( J27), _xleta.SUM )} -> 150000 | K32: 150000 | L32: 150000 | M32: 150000 | N32: 150000 | O32: 150000 | P32: 150000 | Q32: 150000 | R32: 150000 | S32: 150000 | T32: 150000 | U32: 150000
A68: End of schedule

Sheet Calculations
A1: =company -> Big Fish Co.
A2: {=topic} -> CFM Topic: Costs
A3: CALCULATIONS SCHEDULE | G3: Unit | H3: Total | J3: {=EOMONTH( start_date, _xlfn.SEQUENCE( 1, periods, 1, 1 ) - 1 )} -> 43496 | K3: 43524 | L3: 43555 | M3: 43585 | N3: 43616 | O3: 43646 | P3: 43677 | Q3: 43708 | R3: 43738 | S3: 43769 | T3: 43799 | U3: 43830 | V3: 43861 | W3: 43890 | X3: 43921 | Y3: 43951 | Z3: 43982 | AA3: 44012 | AB3: 44043 | AC3: 44074 | AD3: 44104 | AE3: 44135 | AF3: 44165 | AG3: 44196
A6: PRICE (unranked by profitability)
E8: Client | F8: Product
E9: {=_xlfn.LET( _xlpm.historicals, CaseData!$B$8:$G$307, _xlpm.month, INDEX( _xlpm.historicals,, 1 ), _xlpm.client, "Client " & INDEX( _xlpm.historicals,, 2), _xlpm.product, INDEX( _xlpm.historicals,, 3), _xlpm.volume, INDEX( _xlpm.historicals,, 4 ), _xlpm.price, INDEX( _xlpm.historicals,, 5), _xlfn.TAKE( _xlfn.PIVOTBY( _xlfn.HSTACK( _xlpm.client, _xlpm.product ), _xlpm.month, _xlpm.volume, _xleta.SUM, ,0 ),, 2 ) )}
E10: Client 1 | F10: 1 | G10: USD / kg | J10: {=_xlfn.LET( _xlpm.historicals, CaseData!$B$8:$G$307, _xlpm.month, INDEX(_xlpm.historicals,,1), _xlpm.client, INDEX(_xlpm.historicals,,2), _xlpm.product, INDEX(_xlpm.historicals,,3), _xlpm.volume, INDEX(_xlpm.historicals,,4), _xlpm.price, INDEX(_xlpm.historicals,,5), _xlfn.DROP( _xlfn.DROP( _xlfn.DROP( _xlfn.PIVOTBY( _xlfn.HSTACK( _xlpm.client, _xlpm.product ), _xlpm.month, _xlpm.price, _xleta.SUM,,0 ),,2 ),, -1 ), 1) )} -> 40 | K10: 40 | L10: 40 | M10: 40 | N10: 40 | O10: 40 | P10: 40 | Q10: 40 | R10: 40 | S10: 40 | T10: 40 | U10: 40 | V10: {=_xlfn.LET( _xlpm.historicals, CaseData!$B$8:$G$307, _xlpm.month, INDEX(_xlpm.historicals,,1), _xlpm.client, "Client " & INDEX(_xlpm.historicals,,2), _xlpm.product, INDEX(_xlpm.historicals,,3), _xlpm.volume, INDEX(_xlpm.historicals,,4), _xlpm.price, INDEX(_xlpm.historicals,,5), _xlpm.last_actual, _xlfn.DROP( _xlfn.DROP( _xlfn.DROP( _xlfn.PIVOTBY( _xlfn.HSTACK( _xlpm.client, _xlpm.product ), _xlpm.month, _xlpm.price, _xleta.SUM,,0 ),,2 ),, -1 ), 1), _xlpm.current_client, _xlfn.DROP( INDEX(_xlfn.ANCHORARRAY( E9),, 1 ), 1 ), _xlpm.growth_table, CaseData!$I$8:$K$12, _xlpm.growth_rows, INDEX( _xlpm.growth_table,, 1 ), _xlpm.growth_rate, INDEX( _xlpm.growth_table, MATCH( _xlpm.current_client, _xlpm.growth_rows, 0 ), 3 ), _xlpm.last_actual * ( 1 + _xlpm.growth_rate ) )} -> 42.8 | W10: 42.8 | X10: 42.8 | Y10: 42.8 | Z10: 42.8 | AA10: 42.8 | AB10: 42.8 | AC10: 42.8 | AD10: 42.8 | AE10: 42.8 | AF10: 42.8 | AG10: 42.8
E11: Client 1 | F11: 2 | G11: USD / kg | J11: 17 | K11: 17 | L11: 17 | M11: 17 | N11: 17 | O11: 17 | P11: 17 | Q11: 17 | R11: 17 | S11: 17 | T11: 17 | U11: 17 | V11: 18.19 | W11: 18.19 | X11: 18.19 | Y11: 18.19 | Z11: 18.19 | AA11: 18.19 | AB11: 18.19 | AC11: 18.19 | AD11: 18.19 | AE11: 18.19 | AF11: 18.19 | AG11: 18.19
E12: Client 1 | F12: 3 | G12: USD / kg | J12: 12.8 | K12: 12.8 | L12: 12.8 | M12: 12.8 | N12: 12.8 | O12: 12.8 | P12: 12.8 | Q12: 12.8 | R12: 12.8 | S12: 12.8 | T12: 12.8 | U12: 12.8 | V12: 13.696 | W12: 13.696 | X12: 13.696 | Y12: 13.696 | Z12: 13.696 | AA12: 13.696 | AB12: 13.696 | AC12: 13.696 | AD12: 13.696 | AE12: 13.696 | AF12: 13.696 | AG12: 13.696
E13: Client 1 | F13: 4 | G13: USD / kg | J13: 10.8 | K13: 10.8 | L13: 10.8 | M13: 10.8 | N13: 10.8 | O13: 10.8 | P13: 10.8 | Q13: 10.8 | R13: 10.8 | S13: 10.8 | T13: 10.8 | U13: 10.8 | V13: 11.556 | W13: 11.556 | X13: 11.556 | Y13: 11.556 | Z13: 11.556 | AA13: 11.556 | AB13: 11.556 | AC13: 11.556 | AD13: 11.556 | AE13: 11.556 | AF13: 11.556 | AG13: 11.556
E14: Client 1 | F14: 5 | G14: USD / kg | J14: 14.9 | K14: 14.9 | L14: 14.9 | M14: 14.9 | N14: 14.9 | O14: 14.9 | P14: 14.9 | Q14: 14.9 | R14: 14.9 | S14: 14.9 | T14: 14.9 | U14: 14.9 | V14: 15.943 | W14: 15.943 | X14: 15.943 | Y14: 15.943 | Z14: 15.943 | AA14: 15.943 | AB14: 15.943 | AC14: 15.943 | AD14: 15.943 | AE14: 15.943 | AF14: 15.943 | AG14: 15.943
E15: Client 2 | F15: 1 | G15: USD / kg | J15: 34 | K15: 34 | L15: 34 | M15: 34 | N15: 34 | O15: 34 | P15: 34 | Q15: 34 | R15: 34 | S15: 34 | T15: 34 | U15: 34 | V15: 36.04 | W15: 36.04 | X15: 36.04 | Y15: 36.04 | Z15: 36.04 | AA15: 36.04 | AB15: 36.04 | AC15: 36.04 | AD15: 36.04 | AE15: 36.04 | AF15: 36.04 | AG15: 36.04
E16: Client 2 | F16: 2 | G16: USD / kg | J16: 16.32 | K16: 16.32 | L16: 16.32 | M16: 16.32 | N16: 16.32 | O16: 16.32 | P16: 16.32 | Q16: 16.32 | R16: 16.32 | S16: 16.32 | T16: 16.32 | U16: 16.32 | V16: 17.2992 | W16: 17.2992 | X16: 17.2992 | Y16: 17.2992 | Z16: 17.2992 | AA16: 17.2992 | AB16: 17.2992 | AC16: 17.2992 | AD16: 17.2992 | AE16: 17.2992 | AF16: 17.2992 | AG16: 17.2992
E17: Client 2 | F17: 3 | G17: USD / kg | J17: 14.21 | K17: 14.21 | L17: 14.21 | M17: 14.21 | N17: 14.21 | O17: 14.21 | P17: 14.21 | Q17: 14.21 | R17: 14.21 | S17: 14.21 | T17: 14.21 | U17: 14.21 | V17: 15.0626 | W17: 15.0626 | X17: 15.0626 | Y17: 15.0626 | Z17: 15.0626 | AA17: 15.0626 | AB17: 15.0626 | AC17: 15.0626 | AD17: 15.0626 | AE17: 15.0626 | AF17: 15.0626 | AG17: 15.0626
E18: Client 2 | F18: 4 | G18: USD / kg | J18: 9.83 | K18: 9.83 | L18: 9.83 | M18: 9.83 | N18: 9.83 | O18: 9.83 | P18: 9.83 | Q18: 9.83 | R18: 9.83 | S18: 9.83 | T18: 9.83 | U18: 9.83 | V18: 10.4198 | W18: 10.4198 | X18: 10.4198 | Y18: 10.4198 | Z18: 10.4198 | AA18: 10.4198 | AB18: 10.4198 | AC18: 10.4198 | AD18: 10.4198 | AE18: 10.4198 | AF18: 10.4198 | AG18: 10.4198
E19: Client 2 | F19: 5 | G19: USD / kg | J19: 14.16 | K19: 14.16 | L19: 14.16 | M19: 14.16 | N19: 14.16 | O19: 14.16 | P19: 14.16 | Q19: 14.16 | R19: 14.16 | S19: 14.16 | T19: 14.16 | U19: 14.16 | V19: 15.0096 | W19: 15.0096 | X19: 15.0096 | Y19: 15.0096 | Z19: 15.0096 | AA19: 15.0096 | AB19: 15.0096 | AC19: 15.0096 | AD19: 15.0096 | AE19: 15.0096 | AF19: 15.0096 | AG19: 15.0096
E20: Client 3 | F20: 1 | G20: USD / kg | J20: 39.6 | K20: 39.6 | L20: 39.6 | M20: 39.6 | N20: 39.6 | O20: 39.6 | P20: 39.6 | Q20: 39.6 | R20: 39.6 | S20: 39.6 | T20: 39.6 | U20: 39.6 | V20: 41.976 | W20: 41.976 | X20: 41.976 | Y20: 41.976 | Z20: 41.976 | AA20: 41.976 | AB20: 41.976 | AC20: 41.976 | AD20: 41.976 | AE20: 41.976 | AF20: 41.976 | AG20: 41.976
E21: Client 3 | F21: 2 | G21: USD / kg | J21: 17.85 | K21: 17.85 | L21: 17.85 | M21: 17.85 | N21: 17.85 | O21: 17.85 | P21: 17.85 | Q21: 17.85 | R21: 17.85 | S21: 17.85 | T21: 17.85 | U21: 17.85 | V21: 18.921 | W21: 18.921 | X21: 18.921 | Y21: 18.921 | Z21: 18.921 | AA21: 18.921 | AB21: 18.921 | AC21: 18.921 | AD21: 18.921 | AE21: 18.921 | AF21: 18.921 | AG21: 18.921
E22: Client 3 | F22: 3 | G22: USD / kg | J22: 14.72 | K22: 14.72 | L22: 14.72 | M22: 14.72 | N22: 14.72 | O22: 14.72 | P22: 14.72 | Q22: 14.72 | R22: 14.72 | S22: 14.72 | T22: 14.72 | U22: 14.72 | V22: 15.6032 | W22: 15.6032 | X22: 15.6032 | Y22: 15.6032 | Z22: 15.6032 | AA22: 15.6032 | AB22: 15.6032 | AC22: 15.6032 | AD22: 15.6032 | AE22: 15.6032 | AF22: 15.6032 | AG22: 15.6032
... E34: Client 5 | F34: 5 | G34: USD / kg | J34: 12.67 | K34: 12.67 | L34: 12.67 | M34: 12.67 | N34: 12.67 | O34: 12.67 | P34: 12.67 | Q34: 12.67 | R34: 12.67 | S34: 12.67 | T34: 12.67 | U34: 12.67 | V34: 13.5569 | W34: 13.5569 | X34: 13.5569 | Y34: 13.5569 | Z34: 13.5569 | AA34: 13.5569 | AB34: 13.5569 | AC34: 13.5569 | AD34: 13.5569 | AE34: 13.5569 | AF34: 13.5569 | AG34: 13.5569
A37: DIRECT COSTS
E39: Client | F39: Product
E40: {=_xlfn.LET( _xlpm.historicals, CaseData!$B$8:$G$307, _xlpm.month, INDEX( _xlpm.historicals,, 1 ), _xlpm.client, "Client " & INDEX( _xlpm.historicals,, 2), _xlpm.product, INDEX( _xlpm.historicals,, 3), _xlpm.volume, INDEX( _xlpm.historicals,, 4 ), _xlpm.price, INDEX( _xlpm.historicals,, 5), _xlfn.TAKE( _xlfn.PIVOTBY( _xlfn.HSTACK( _xlpm.client, _xlpm.product ), _xlpm.month, _xlpm.volume, _xleta.SUM, ,0 ),, 2 ) )}
E41: Client 1 | F41: 1 | G41: USD / kg | J41: {=_xlfn.LET( _xlpm.historicals, CaseData!$B$8:$G$307, _xlpm.month, INDEX(_xlpm.historicals,,1), _xlpm.client, INDEX(_xlpm.historicals,,2), _xlpm.product, INDEX(_xlpm.historicals,,3), _xlpm.volume, INDEX(_xlpm.historicals,,4), _xlpm.costs, INDEX(_xlpm.historicals,,6), _xlfn.DROP( _xlfn.DROP( _xlfn.DROP( _xlfn.PIVOTBY( _xlfn.HSTACK( _xlpm.client, _xlpm.product ), _xlpm.month, _xlpm.costs, _xleta.SUM,,0 ),,2 ),, -1 ), 1) )} -> 25 | K41: 25 | L41: 25 | M41: 25 | N41: 25 | O41: 25 | P41: 25 | Q41: 25 | R41: 25 | S41: 25 | T41: 25 | U41: 25 | V41: {=_xlfn.LET( _xlpm.historicals, CaseData!$B$8:$G$307, _xlpm.month, INDEX(_xlpm.historicals,,1), _xlpm.client, "Client " & INDEX(_xlpm.historicals,,2), _xlpm.product, INDEX(_xlpm.historicals,,3), _xlpm.volume, INDEX(_xlpm.historicals,,4), _xlpm.costs, INDEX(_xlpm.historicals,,6), _xlpm.last_actual, _xlfn.DROP( _xlfn.DROP( _xlfn.DROP( _xlfn.PIVOTBY( _xlfn.HSTACK( _xlpm.client, _xlpm.product ), _xlpm.month, _xlpm.costs, _xleta.SUM,,0 ),,2 ),, -1 ), 1), _xlpm.current_product, _xlfn.DROP( INDEX(_xlfn.ANCHORARRAY( E40),, 2 ), 1 ), _xlpm.growth_table, CaseData!$M$8:$N$12, _xlpm.growth_rows, INDEX( _xlpm.growth_table,, 1 ), _xlpm.growth_rate, INDEX( _xlpm.growth_table, MATCH( _xlpm.current_product, _xlpm.growth_rows, 0 ), 2 ), _xlpm.last_actual * ( 1 + _xlpm.growth_rate ) )} -> 26.75 | W41: 26.75 | X41: 26.75 | Y41: 26.75 | Z41: 26.75 | AA41: 26.75 | AB41: 26.75 | AC41: 26.75 | AD41: 26.75 | AE41: 26.75 | AF41: 26.75 | AG41: 26.75
E42: Client 1 | F42: 2 | G42: USD / kg | J42: 7.31 | K42: 7.31 | L42: 7.31 | M42: 7.31 | N42: 7.31 | O42: 7.31 | P42: 7.31 | Q42: 7.31 | R42: 7.31 | S42: 7.31 | T42: 7.31 | U42: 7.31 | V42: 7.9679 | W42: 7.9679 | X42: 7.9679 | Y42: 7.9679 | Z42: 7.9679 | AA42: 7.9679 | AB42: 7.9679 | AC42: 7.9679 | AD42: 7.9679 | AE42: 7.9679 | AF42: 7.9679 | AG42: 7.9679
E43: Client 1 | F43: 3 | G43: USD / kg | J43: 5.12 | K43: 5.12 | L43: 5.12 | M43: 5.12 | N43: 5.12 | O43: 5.12 | P43: 5.12 | Q43: 5.12 | R43: 5.12 | S43: 5.12 | T43: 5.12 | U43: 5.12 | V43: 5.5296 | W43: 5.5296 | X43: 5.5296 | Y43: 5.5296 | Z43: 5.5296 | AA43: 5.5296 | AB43: 5.5296 | AC43: 5.5296 | AD43: 5.5296 | AE43: 5.5296 | AF43: 5.5296 | AG43: 5.5296
E44: Client 1 | F44: 4 | G44: USD / kg | J44: 6.48 | K44: 6.48 | L44: 6.48 | M44: 6.48 | N44: 6.48 | O44: 6.48 | P44: 6.48 | Q44: 6.48 | R44: 6.48 | S44: 6.48 | T44: 6.48 | U44: 6.48 | V44: 6.9336 | W44: 6.9336 | X44: 6.9336 | Y44: 6.9336 | Z44: 6.9336 | AA44: 6.9336 | AB44: 6.9336 | AC44: 6.9336 | AD44: 6.9336 | AE44: 6.9336 | AF44: 6.9336 | AG44: 6.9336
E45: Client 1 | F45: 5 | G45: USD / kg | J45: 6.26 | K45: 6.26 | L45: 6.26 | M45: 6.26 | N45: 6.26 | O45: 6.26 | P45: 6.26 | Q45: 6.26 | R45: 6.26 | S45: 6.26 | T45: 6.26 | U45: 6.26 | V45: 6.573 | W45: 6.573 | X45: 6.573 | Y45: 6.573 | Z45: 6.573 | AA45: 6.573 | AB45: 6.573 | AC45: 6.573 | AD45: 6.573 | AE45: 6.573 | AF45: 6.573 | AG45: 6.573
E46: Client 2 | F46: 1 | G46: USD / kg | J46: 25 | K46: 25 | L46: 25 | M46: 25 | N46: 25 | O46: 25 | P46: 25 | Q46: 25 | R46: 25 | S46: 25 | T46: 25 | U46: 25 | V46: 26.75 | W46: 26.75 | X46: 26.75 | Y46: 26.75 | Z46: 26.75 | AA46: 26.75 | AB46: 26.75 | AC46: 26.75 | AD46: 26.75 | AE46: 26.75 | AF46: 26.75 | AG46: 26.75
E47: Client 2 | F47: 2 | G47: USD / kg | J47: 7.31 | K47: 7.31 | L47: 7.31 | M47: 7.31 | N47: 7.31 | O47: 7.31 | P47: 7.31 | Q47: 7.31 | R47: 7.31 | S47: 7.31 | T47: 7.31 | U47: 7.31 | V47: 7.9679 | W47: 7.9679 | X47: 7.9679 | Y47: 7.9679 | Z47: 7.9679 | AA47: 7.9679 | AB47: 7.9679 | AC47: 7.9679 | AD47: 7.9679 | AE47: 7.9679 | AF47: 7.9679 | AG47: 7.9679
E48: Client 2 | F48: 3 | G48: USD / kg | J48: 5.12 | K48: 5.12 | L48: 5.12 | M48: 5.12 | N48: 5.12 | O48: 5.12 | P48: 5.12 | Q48: 5.12 | R48: 5.12 | S48: 5.12 | T48: 5.12 | U48: 5.12 | V48: 5.5296 | W48: 5.5296 | X48: 5.5296 | Y48: 5.5296 | Z48: 5.5296 | AA48: 5.5296 | AB48: 5.5296 | AC48: 5.5296 | AD48: 5.5296 | AE48: 5.5296 | AF48: 5.5296 | AG48: 5.5296
E49: Client 2 | F49: 4 | G49: USD / kg | J49: 6.48 | K49: 6.48 | L49: 6.48 | M49: 6.48 | N49: 6.48 | O49: 6.48 | P49: 6.48 | Q49: 6.48 | R49: 6.48 | S49: 6.48 | T49: 6.48 | U49: 6.48 | V49: 6.9336 | W49: 6.9336 | X49: 6.9336 | Y49: 6.9336 | Z49: 6.9336 | AA49: 6.9336 | AB49: 6.9336 | AC49: 6.9336 | AD49: 6.9336 | AE49: 6.9336 | AF49: 6.9336 | AG49: 6.9336
E50: Client 2 | F50: 5 | G50: USD / kg | J50: 6.26 | K50: 6.26 | L50: 6.26 | M50: 6.26 | N50: 6.26 | O50: 6.26 | P50: 6.26 | Q50: 6.26 | R50: 6.26 | S50: 6.26 | T50: 6.26 | U50: 6.26 | V50: 6.573 | W50: 6.573 | X50: 6.573 | Y50: 6.573 | Z50: 6.573 | AA50: 6.573 | AB50: 6.573 | AC50: 6.573 | AD50: 6.573 | AE50: 6.573 | AF50: 6.573 | AG50: 6.573
E51: Client 3 | F51: 1 | G51: USD / kg | J51: 25 | K51: 25 | L51: 25 | M51: 25 | N51: 25 | O51: 25 | P51: 25 | Q51: 25 | R51: 25 | S51: 25 | T51: 25 | U51: 25 | V51: 26.75 | W51: 26.75 | X51: 26.75 | Y51: 26.75 | Z51: 26.75 | AA51: 26.75 | AB51: 26.75 | AC51: 26.75 | AD51: 26.75 | AE51: 26.75 | AF51: 26.75 | AG51: 26.75
E52: Client 3 | F52: 2 | G52: USD / kg | J52: 7.31 | K52: 7.31 | L52: 7.31 | M52: 7.31 | N52: 7.31 | O52: 7.31 | P52: 7.31 | Q52: 7.31 | R52: 7.31 | S52: 7.31 | T52: 7.31 | U52: 7.31 | V52: 7.9679 | W52: 7.9679 | X52: 7.9679 | Y52: 7.9679 | Z52: 7.9679 | AA52: 7.9679 | AB52: 7.9679 | AC52: 7.9679 | AD52: 7.9679 | AE52: 7.9679 | AF52: 7.9679 | AG52: 7.9679
E53: Client 3 | F53: 3 | G53: USD / kg | J53: 5.12 | K53: 5.12 | L53: 5.12 | M53: 5.12 | N53: 5.12 | O53: 5.12 | P53: 5.12 | Q53: 5.12 | R53: 5.12 | S53: 5.12 | T53: 5.12 | U53: 5.12 | V53: 5.5296 | W53: 5.5296 | X53: 5.5296 | Y53: 5.5296 | Z53: 5.5296 | AA53: 5.5296 | AB53: 5.5296 | AC53: 5.5296 | AD53: 5.5296 | AE53: 5.5296 | AF53: 5.5296 | AG53: 5.5296
... E65: Client 5 | F65: 5 | G65: USD / kg | J65: 6.26 | K65: 6.26 | L65: 6.26 | M65: 6.26 | N65: 6.26 | O65: 6.26 | P65: 6.26 | Q65: 6.26 | R65: 6.26 | S65: 6.26 | T65: 6.26 | U65: 6.26 | V65: 6.573 | W65: 6.573 | X65: 6.573 | Y65: 6.573 | Z65: 6.573 | AA65: 6.573 | AB65: 6.573 | AC65: 6.573 | AD65: 6.573 | AE65: 6.573 | AF65: 6.573 | AG65: 6.573
A68: GROSS PROFIT (per kg)
E70: Client | F70: Product
E71: {=_xlfn.LET( _xlpm.historicals, CaseData!$B$8:$G$307, _xlpm.month, INDEX( _xlpm.historicals,, 1 ), _xlpm.client, "Client " & INDEX( _xlpm.historicals,, 2), _xlpm.product, INDEX( _xlpm.historicals,, 3), _xlpm.volume, INDEX( _xlpm.historicals,, 4 ), _xlpm.price, INDEX( _xlpm.historicals,, 5), _xlfn.TAKE( _xlfn.PIVOTBY( _xlfn.HSTACK( _xlpm.client, _xlpm.product ), _xlpm.month, _xlpm.volume, _xleta.SUM, ,0 ),, 2 ) )}
...

Sheet CaseData
B2: Big Fish Co.
B3: Inputs and Assumptions
B5: Previous Year's Sales Report | I5: Projected Change of Prices and Volumes by Client (y/y) | M5: Projected Direct Cost Increase by Product (y/y) | P5: Maximum Factory Capacity
B6: Month | C6: Client | D6: Product | E6: Volume (Kg) | F6: Sales Price | G6: Direct Costs | I6: Client | J6: Volume | K6: Price | M6: Product | N6: Cost Increase | P6: kg/Month
E7: kg | F7: $/kg | G7: $/kg | J7: % | K7: % | N7: % | P7: 150000
B8: 43496 | C8: 1 | D8: 1 | E8: 10438 | F8: 40 | G8: 25 | I8: Client 1 | J8: 0.02 | K8: 0.07 | M8: 1 | N8: 0.07
B9: 43496 | C9: 1 | D9: 2 | E9: 516 | F9: 17 | G9: 7.31 | I9: Client 2 | J9: 0.04 | K9: 0.06 | M9: 2 | N9: 0.09
B10: 43496 | C10: 1 | D10: 3 | E10: 24860 | F10: 12.8 | G10: 5.12 | I10: Client 3 | J10: 0.02 | K10: 0.06 | M10: 3 | N10: 0.08
B11: 43496 | C11: 1 | D11: 4 | E11: 17812 | F11: 10.8 | G11: 6.48 | I11: Client 4 | J11: 0.05 | K11: 0.08 | M11: 4 | N11: 0.07
B12: 43496 | C12: 1 | D12: 5 | E12: 8018 | F12: 14.9 | G12: 6.26 | I12: Client 5 | J12: -0.02 | K12: 0.07 | M12: 5 | N12: 0.05
B13: 43496 | C13: 2 | D13: 1 | E13: 1814 | F13: 34 | G13: 25
B14: 43496 | C14: 2 | D14: 2 | E14: 1994 | F14: 16.32 | G14: 7.31
B15: 43496 | C15: 2 | D15: 3 | E15: 32108 | F15: 14.21 | G15: 5.12 | I15: Model period start | K15: 43466
B16: 43496 | C16: 2 | D16: 4 | E16: 11892 | F16: 9.83 | G16: 6.48 | I16: Number of periods | K16: 24
B17: 43496 | C17: 2 | D17: 5 | E17: 16336 | F17: 14.16 | G17: 6.26 | I17: Company name | K17: Big Fish Co.
B18: 43496 | C18: 3 | D18: 1 | E18: 3362 | F18: 39.6 | G18: 25
B19: 43496 | C19: 3 | D19: 2 | E19: 25506 | F19: 17.85 | G19: 7.31
B20: 43496 | C20: 3 | D20: 3 | E20: 2890 | F20: 14.72 | G20: 5.12
B21: 43496 | C21: 3 | D21: 4 | E21: 20270 | F21: 10.8 | G21: 6.48
B22: 43496 | C22: 3 | D22: 5 | E22: 19262 | F22: 15.65 | G22: 6.26
B23: 43496 | C23: 4 | D23: 1 | E23: 43200 | F23: 44.4 | G23: 25
B24: 43496 | C24: 4 | D24: 2 | E24: 22290 | F24: 17.17 | G24: 7.31
B25: 43496 | C25: 4 | D25: 3 | E25: 24338 | F25: 13.57 | G25: 5.12
B26: 43496 | C26: 4 | D26: 4 | E26: 552 | F26: 12.42 | G26: 6.48
B27: 43496 | C27: 4 | D27: 5 | E27: 11418 | F27: 14.16 | G27: 6.26
B28: 43496 | C28: 5 | D28: 1 | E28: 5098 | F28: 37.6 | G28: 25
B29: 43496 | C29: 5 | D29: 2 | E29: 36672 | F29: 15.13 | G29: 7.31
... B307: 43830 | C307: 5 | D307: 5 | E307: 16042 | F307: 12.67 | G307: 6.26

Sheet CaseSolution - Calculations
B2: =CaseData!B2 -> Big Fish Co.
B3: Operating Model
D5: Client | E5: Product | G5: Growth | I5: =CaseData!B8 -> 43496 | J5: =EOMONTH(I5,1) -> 43524 | K5: =EOMONTH(J5,1) -> 43555 | L5: =EOMONTH(K5,1) -> 43585 | M5: =EOMONTH(L5,1) -> 43616 | N5: =EOMONTH(M5,1) -> 43646 | O5: =EOMONTH(N5,1) -> 43677 | P5: =EOMONTH(O5,1) -> 43708 | Q5: =EOMONTH(P5,1) -> 43738 | ... AF5: =EOMONTH(AE5,1) -> 44196
B7: Sales Price
D8: =CaseData!C8 -> 1 | E8: =CaseData!D8 -> 1 | G8: =INDEX(CaseData!$K$8:$K$12,MATCH("Client "&$D8,CaseData!$I$8:$I$12,0)) -> 0.07 | I8: =SUMIFS(CaseData!$F$8:$F$307,CaseData!$B$8:$B$307,I$5,CaseData!$C$8:$C$307,$D8,CaseData!$D$8:$D$307,$E8) -> 40 | J8: =SUMIFS(CaseData!$F$8:$F$307,CaseData!$B$8:$B$307,J$5,CaseData!$C$8:$C$307,$D8,CaseData!$D$8:$D$307,$E8) -> 40 | K8: =SUMIFS(CaseData!$F$8:$F$307,CaseData!$B$8:$B$307,K$5,CaseData!$C$8:$C$307,$D8,CaseData!$D$8:$D$307,$E8) -> 40 | L8: =SUMIFS(CaseData!$F$8:$F$307,CaseData!$B$8:$B$307,L$5,CaseData!$C$8:$C$307,$D8,CaseData!$D$8:$D$307,$E8) -> 40 | M8: =SUMIFS(CaseData!$F$8:$F$307,CaseData!$B$8:$B$307,M$5,CaseData!$C$8:$C$307,$D8,CaseData!$D$8:$D$307,$E8) -> 40 | N8: =SUMIFS(CaseData!$F$8:$F$307,CaseData!$B$8:$B$307,N$5,CaseData!$C$8:$C$307,$D8,CaseData!$D$8:$D$307,$E8) -> 40 | O8: =SUMIFS(CaseData!$F$8:$F$307,CaseData!$B$8:$B$307,O$5,CaseData!$C$8:$C$307,$D8,CaseData!$D$8:$D$307,$E8) -> 40 | P8: =SUMIFS(CaseData!$F$8:$F$307,CaseData!$B$8:$B$307,P$5,CaseData!$C$8:$C$307,$D8,CaseData!$D$8:$D$307,$E8) -> 40 | ... T8: =SUMIFS(CaseData!$F$8:$F$307,CaseData!$B$8:$B$307,T$5,CaseData!$C$8:$C$307,$D8,CaseData!$D$8:$D$307,$E8) -> 40 | U8: =I8*(1+$G8) -> 42.8 | V8: =J8*(1+$G8) -> 42.8 | W8: =K8*(1+$G8) -> 42.8 | X8: =L8*(1+$G8) -> 42.8 | Y8: =M8*(1+$G8) -> 42.8 | Z8: =N8*(1+$G8) -> 42.8 | AA8: =O8*(1+$G8) -> 42.8 | AB8: =P8*(1+$G8) -> 42.8 | ... AF8: =T8*(1+$G8) -> 42.8
D9: =CaseData!C9 -> 1 | E9: =CaseData!D9 -> 2 | G9: =INDEX(CaseData!$K$8:$K$12,MATCH("Client "&$D9,CaseData!$I$8:$I$12,0)) -> 0.07 | I9: =SUMIFS(CaseData!$F$8:$F$307,CaseData!$B$8:$B$307,I$5,CaseData!$C$8:$C$307,$D9,CaseData!$D$8:$D$307,$E9) -> 17 | J9: =SUMIFS(CaseData!$F$8:$F$307,CaseData!$B$8:$B$307,J$5,CaseData!$C$8:$C$307,$D9,CaseData!$D$8:$D$307,$E9) -> 17 | K9: =SUMIFS(CaseData!$F$8:$F$307,CaseData!$B$8:$B$307,K$5,CaseData!$C$8:$C$307,$D9,CaseData!$D$8:$D$307,$E9) -> 17 | L9: =SUMIFS(CaseData!$F$8:$F$307,CaseData!$B$8:$B$307,L$5,CaseData!$C$8:$C$307,$D9,CaseData!$D$8:$D$307,$E9) -> 17 | M9: =SUMIFS(CaseData!$F$8:$F$307,CaseData!$B$8:$B$307,M$5,CaseData!$C$8:$C$307,$D9,CaseData!$D$8:$D$307,$E9) -> 17 | N9: =SUMIFS(CaseData!$F$8:$F$307,CaseData!$B$8:$B$307,N$5,CaseData!$C$8:$C$307,$D9,CaseData!$D$8:$D$307,$E9) -> 17 | O9: =SUMIFS(CaseData!$F$8:$F$307,CaseData!$B$8:$B$307,O$5,CaseData!$C$8:$C$307,$D9,CaseData!$D$8:$D$307,$E9) -> 17 | P9: =SUMIFS(CaseData!$F$8:$F$307,CaseData!$B$8:$B$307,P$5,CaseData!$C$8:$C$307,$D9,CaseData!$D$8:$D$307,$E9) -> 17 | ... T9: =SUMIFS(CaseData!$F$8:$F$307,CaseData!$B$8:$B$307,T$5,CaseData!$C$8:$C$307,$D9,CaseData!$D$8:$D$307,$E9) -> 17 | U9: =I9*(1+$G9) -> 18.19 | V9: =J9*(1+$G9) -> 18.19 | W9: =K9*(1+$G9) -> 18.19 | X9: =L9*(1+$G9) -> 18.19 | Y9: =M9*(1+$G9) -> 18.19 | Z9: =N9*(1+$G9) -> 18.19 | AA9: =O9*(1+$G9) -> 18.19 | AB9: =P9*(1+$G9) -> 18.19 | ... AF9: =T9*(1+$G9) -> 18.19
D10: =CaseData!C10 -> 1 | E10: =CaseData!D10 -> 3 | G10: =INDEX(CaseData!$K$8:$K$12,MATCH("Client "&$D10,CaseData!$I$8:$I$12,0)) -> 0.07 | I10: =SUMIFS(CaseData!$F$8:$F$307,CaseData!$B$8:$B$307,I$5,CaseData!$C$8:$C$307,$D10,CaseData!$D$8:$D$307,$E10) -> 12.8 | J10: =SUMIFS(CaseData!$F$8:$F$307,CaseData!$B$8:$B$307,J$5,CaseData!$C$8:$C$307,$D10,CaseData!$D$8:$D$307,$E10) -> 12.8 | K10: =SUMIFS(CaseData!$F$8:$F$307,CaseData!$B$8:$B$307,K$5,CaseData!$C$8:$C$307,$D10,CaseData!$D$8:$D$307,$E10) -> 12.8 | L10: =SUMIFS(CaseData!$F$8:$F$307,CaseData!$B$8:$B$307,L$5,CaseData!$C$8:$C$307,$D10,CaseData!$D$8:$D$307,$E10) -> 12.8 | M10: =SUMIFS(CaseData!$F$8:$F$307,CaseData!$B$8:$B$307,M$5,CaseData!$C$8:$C$307,$D10,CaseData!$D$8:$D$307,$E10) -> 12.8 | N10: =SUMIFS(CaseData!$F$8:$F$307,CaseData!$B$8:$B$307,N$5,CaseData!$C$8:$C$307,$D10,CaseData!$D$8:$D$307,$E10) -> 12.8 | O10: =SUMIFS(CaseData!$F$8:$F$307,CaseData!$B$8:$B$307,O$5,CaseData!$C$8:$C$307,$D10,CaseData!$D$8:$D$307,$E10) -> 12.8 | P10: =SUMIFS(CaseData!$F$8:$F$307,CaseData!$B$8:$B$307,P$5,CaseData!$C$8:$C$307,$D10,CaseData!$D$8:$D$307,$E10) -> 12.8 | ... T10: =SUMIFS(CaseData!$F$8:$F$307,CaseData!$B$8:$B$307,T$5,CaseData!$C$8:$C$307,$D10,CaseData!$D$8:$D$307,$E10) -> 12.8 | U10: =I10*(1+$G10) -> 13.696 | V10: =J10*(1+$G10) -> 13.696 | W10: =K10*(1+$G10) -> 13.696 | X10: =L10*(1+$G10) -> 13.696 | Y10: =M10*(1+$G10) -> 13.696 | Z10: =N10*(1+$G10) -> 13.696 | AA10: =O10*(1+$G10) -> 13.696 | AB10: =P10*(1+$G10) -> 13.696 | ... AF10: =T10*(1+$G10) -> 13.696
D11: =CaseData!C11 -> 1 | E11: =CaseData!D11 -> 4 | G11: =INDEX(CaseData!$K$8:$K$12,MATCH("Client "&$D11,CaseData!$I$8:$I$12,0)) -> 0.07 | I11: =SUMIFS(CaseData!$F$8:$F$307,CaseData!$B$8:$B$307,I$5,CaseData!$C$8:$C$307,$D11,CaseData!$D$8:$D$307,$E11) -> 10.8 | J11: =SUMIFS(CaseData!$F$8:$F$307,CaseData!$B$8:$B$307,J$5,CaseData!$C$8:$C$307,$D11,CaseData!$D$8:$D$307,$E11) -> 10.8 | K11: =SUMIFS(CaseData!$F$8:$F$307,CaseData!$B$8:$B$307,K$5,CaseData!$C$8:$C$307,$D11,CaseData!$D$8:$D$307,$E11) -> 10.8 | L11: =SUMIFS(CaseData!$F$8:$F$307,CaseData!$B$8:$B$307,L$5,CaseData!$C$8:$C$307,$D11,CaseData!$D$8:$D$307,$E11) -> 10.8 | M11: =SUMIFS(CaseData!$F$8:$F$307,CaseData!$B$8:$B$307,M$5,CaseData!$C$8:$C$307,$D11,CaseData!$D$8:$D$307,$E11) -> 10.8 | N11: =SUMIFS(CaseData!$F$8:$F$307,CaseData!$B$8:$B$307,N$5,CaseData!$C$8:$C$307,$D11,CaseData!$D$8:$D$307,$E11) -> 10.8 | O11: =SUMIFS(CaseData!$F$8:$F$307,CaseData!$B$8:$B$307,O$5,CaseData!$C$8:$C$307,$D11,CaseData!$D$8:$D$307,$E11) -> 10.8 | P11: =SUMIFS(CaseData!$F$8:$F$307,CaseData!$B$8:$B$307,P$5,CaseData!$C$8:$C$307,$D11,CaseData!$D$8:$D$307,$E11) -> 10.8 | ... T11: =SUMIFS(CaseData!$F$8:$F$307,CaseData!$B$8:$B$307,T$5,CaseData!$C$8:$C$307,$D11,CaseData!$D$8:$D$307,$E11) -> 10.8 | U11: =I11*(1+$G11) -> 11.556 | V11: =J11*(1+$G11) -> 11.556 | W11: =K11*(1+$G11) -> 11.556 | X11: =L11*(1+$G11) -> 11.556 | Y11: =M11*(1+$G11) -> 11.556 | Z11: =N11*(1+$G11) -> 11.556 | AA11: =O11*(1+$G11) -> 11.556 | AB11: =P11*(1+$G11) -> 11.556 | ... AF11: =T11*(1+$G11) -> 11.556
D12: =CaseData!C12 -> 1 | E12: =CaseData!D12 -> 5 | G12: =INDEX(CaseData!$K$8:$K$12,MATCH("Client "&$D12,CaseData!$I$8:$I$12,0)) -> 0.07 | I12: =SUMIFS(CaseData!$F$8:$F$307,CaseData!$B$8:$B$307,I$5,CaseData!$C$8:$C$307,$D12,CaseData!$D$8:$D$307,$E12) -> 14.9 | J12: =SUMIFS(CaseData!$F$8:$F$307,CaseData!$B$8:$B$307,J$5,CaseData!$C$8:$C$307,$D12,CaseData!$D$8:$D$307,$E12) -> 14.9 | K12: =SUMIFS(CaseData!$F$8:$F$307,CaseData!$B$8:$B$307,K$5,CaseData!$C$8:$C$307,$D12,CaseData!$D$8:$D$307,$E12) -> 14.9 | L12: =SUMIFS(CaseData!$F$8:$F$307,CaseData!$B$8:$B$307,L$5,CaseData!$C$8:$C$307,$D12,CaseData!$D$8:$D$307,$E12) -> 14.9 | M12: =SUMIFS(CaseData!$F$8:$F$307,CaseData!$B$8:$B$307,M$5,CaseData!$C$8:$C$307,$D12,CaseData!$D$8:$D$307,$E12) -> 14.9 | N12: =SUMIFS(CaseData!$F$8:$F$307,CaseData!$B$8:$B$307,N$5,CaseData!$C$8:$C$307,$D12,CaseData!$D$8:$D$307,$E12) -> 14.9 | O12: =SUMIFS(CaseData!$F$8:$F$307,CaseData!$B$8:$B$307,O$5,CaseData!$C$8:$C$307,$D12,CaseData!$D$8:$D$307,$E12) -> 14.9 | P12: =SUMIFS(CaseData!$F$8:$F$307,CaseData!$B$8:$B$307,P$5,CaseData!$C$8:$C$307,$D12,CaseData!$D$8:$D$307,$E12) -> 14.9 | ... T12: =SUMIFS(CaseData!$F$8:$F$307,CaseData!$B$8:$B$307,T$5,CaseData!$C$8:$C$307,$D12,CaseData!$D$8:$D$307,$E12) -> 14.9 | U12: =I12*(1+$G12) -> 15.943 | V12: =J12*(1+$G12) -> 15.943 | W12: =K12*(1+$G12) -> 15.943 | X12: =L12*(1+$G12) -> 15.943 | Y12: =M12*(1+$G12) -> 15.943 | Z12: =N12*(1+$G12) -> 15.943 | AA12: =O12*(1+$G12) -> 15.943 | AB12: =P12*(1+$G12) -> 15.943 | ... AF12: =T12*(1+$G12) -> 15.943
D13: =CaseData!C13 -> 2 | E13: =CaseData!D13 -> 1 | G13: =INDEX(CaseData!$K$8:$K$12,MATCH("Client "&$D13,CaseData!$I$8:$I$12,0)) -> 0.06 | I13: =SUMIFS(CaseData!$F$8:$F$307,CaseData!$B$8:$B$307,I$5,CaseData!$C$8:$C$307,$D13,CaseData!$D$8:$D$307,$E13) -> 34 | J13: =SUMIFS(CaseData!$F$8:$F$307,CaseData!$B$8:$B$307,J$5,CaseData!$C$8:$C$307,$D13,CaseData!$D$8:$D$307,$E13) -> 34 | K13: =SUMIFS(CaseData!$F$8:$F$307,CaseData!$B$8:$B$307,K$5,CaseData!$C$8:$C$307,$D13,CaseData!$D$8:$D$307,$E13) -> 34 | L13: =SUMIFS(CaseData!$F$8:$F$307,CaseData!$B$8:$B$307,L$5,CaseData!$C$8:$C$307,$D13,CaseData!$D$8:$D$307,$E13) -> 34 | M13: =SUMIFS(CaseData!$F$8:$F$307,CaseData!$B$8:$B$307,M$5,CaseData!$C$8:$C$307,$D13,CaseData!$D$8:$D$307,$E13) -> 34 | N13: =SUMIFS(CaseData!$F$8:$F$307,CaseData!$B$8:$B$307,N$5,CaseData!$C$8:$C$307,$D13,CaseData!$D$8:$D$307,$E13) -> 34 | O13: =SUMIFS(CaseData!$F$8:$F$307,CaseData!$B$8:$B$307,O$5,CaseData!$C$8:$C$307,$D13,CaseData!$D$8:$D$307,$E13) -> 34 | P13: =SUMIFS(CaseData!$F$8:$F$307,CaseData!$B$8:$B$307,P$5,CaseData!$C$8:$C$307,$D13,CaseData!$D$8:$D$307,$E13) -> 34 | ... T13: =SUMIFS(CaseData!$F$8:$F$307,CaseData!$B$8:$B$307,T$5,CaseData!$C$8:$C$307,$D13,CaseData!$D$8:$D$307,$E13) -> 34 | U13: =I13*(1+$G13) -> 36.04 | V13: =J13*(1+$G13) -> 36.04 | W13: =K13*(1+$G13) -> 36.04 | X13: =L13*(1+$G13) -> 36.04 | Y13: =M13*(1+$G13) -> 36.04 | Z13: =N13*(1+$G13) -> 36.04 | AA13: =O13*(1+$G13) -> 36.04 | AB13: =P13*(1+$G13) -> 36.04 | ... AF13: =T13*(1+$G13) -> 36.04
D14: =CaseData!C14 -> 2 | E14: =CaseData!D14 -> 2 | G14: =INDEX(CaseData!$K$8:$K$12,MATCH("Client "&$D14,CaseData!$I$8:$I$12,0)) -> 0.06 | I14: =SUMIFS(CaseData!$F$8:$F$307,CaseData!$B$8:$B$307,I$5,CaseData!$C$8:$C$307,$D14,CaseData!$D$8:$D$307,$E14) -> 16.32 | J14: =SUMIFS(CaseData!$F$8:$F$307,CaseData!$B$8:$B$307,J$5,CaseData!$C$8:$C$307,$D14,CaseData!$D$8:$D$307,$E14) -> 16.32 | K14: =SUMIFS(CaseData!$F$8:$F$307,CaseData!$B$8:$B$307,K$5,CaseData!$C$8:$C$307,$D14,CaseData!$D$8:$D$307,$E14) -> 16.32 | L14: =SUMIFS(CaseData!$F$8:$F$307,CaseData!$B$8:$B$307,L$5,CaseData!$C$8:$C$307,$D14,CaseData!$D$8:$D$307,$E14) -> 16.32 | M14: =SUMIFS(CaseData!$F$8:$F$307,CaseData!$B$8:$B$307,M$5,CaseData!$C$8:$C$307,$D14,CaseData!$D$8:$D$307,$E14) -> 16.32 | N14: =SUMIFS(CaseData!$F$8:$F$307,CaseData!$B$8:$B$307,N$5,CaseData!$C$8:$C$307,$D14,CaseData!$D$8:$D$307,$E14) -> 16.32 | O14: =SUMIFS(CaseData!$F$8:$F$307,CaseData!$B$8:$B$307,O$5,CaseData!$C$8:$C$307,$D14,CaseData!$D$8:$D$307,$E14) -> 16.32 | P14: =SUMIFS(CaseData!$F$8:$F$307,CaseData!$B$8:$B$307,P$5,CaseData!$C$8:$C$307,$D14,CaseData!$D$8:$D$307,$E14) -> 16.32 | ... T14: =SUMIFS(CaseData!$F$8:$F$307,CaseData!$B$8:$B$307,T$5,CaseData!$C$8:$C$307,$D14,CaseData!$D$8:$D$307,$E14) -> 16.32 | U14: =I14*(1+$G14) -> 17.2992 | V14: =J14*(1+$G14) -> 17.2992 | W14: =K14*(1+$G14) -> 17.2992 | X14: =L14*(1+$G14) -> 17.2992 | Y14: =M14*(1+$G14) -> 17.2992 | Z14: =N14*(1+$G14) -> 17.2992 | AA14: =O14*(1+$G14) -> 17.2992 | AB14: =P14*(1+$G14) -> 17.2992 | ... AF14: =T14*(1+$G14) -> 17.2992
D15: =CaseData!C15 -> 2 | E15: =CaseData!D15 -> 3 | G15: =INDEX(CaseData!$K$8:$K$12,MATCH("Client "&$D15,CaseData!$I$8:$I$12,0)) -> 0.06 | I15: =SUMIFS(CaseData!$F$8:$F$307,CaseData!$B$8:$B$307,I$5,CaseData!$C$8:$C$307,$D15,CaseData!$D$8:$D$307,$E15) -> 14.21 | J15: =SUMIFS(CaseData!$F$8:$F$307,CaseData!$B$8:$B$307,J$5,CaseData!$C$8:$C$307,$D15,CaseData!$D$8:$D$307,$E15) -> 14.21 | K15: =SUMIFS(CaseData!$F$8:$F$307,CaseData!$B$8:$B$307,K$5,CaseData!$C$8:$C$307,$D15,CaseData!$D$8:$D$307,$E15) -> 14.21 | L15: =SUMIFS(CaseData!$F$8:$F$307,CaseData!$B$8:$B$307,L$5,CaseData!$C$8:$C$307,$D15,CaseData!$D$8:$D$307,$E15) -> 14.21 | M15: =SUMIFS(CaseData!$F$8:$F$307,CaseData!$B$8:$B$307,M$5,CaseData!$C$8:$C$307,$D15,CaseData!$D$8:$D$307,$E15) -> 14.21 | N15: =SUMIFS(CaseData!$F$8:$F$307,CaseData!$B$8:$B$307,N$5,CaseData!$C$8:$C$307,$D15,CaseData!$D$8:$D$307,$E15) -> 14.21 | O15: =SUMIFS(CaseData!$F$8:$F$307,CaseData!$B$8:$B$307,O$5,CaseData!$C$8:$C$307,$D15,CaseData!$D$8:$D$307,$E15) -> 14.21 | P15: =SUMIFS(CaseData!$F$8:$F$307,CaseData!$B$8:$B$307,P$5,CaseData!$C$8:$C$307,$D15,CaseData!$D$8:$D$307,$E15) -> 14.21 | ... T15: =SUMIFS(CaseData!$F$8:$F$307,CaseData!$B$8:$B$307,T$5,CaseData!$C$8:$C$307,$D15,CaseData!$D$8:$D$307,$E15) -> 14.21 | U15: =I15*(1+$G15) -> 15.0626 | V15: =J15*(1+$G15) -> 15.0626 | W15: =K15*(1+$G15) -> 15.0626 | X15: =L15*(1+$G15) -> 15.0626 | Y15: =M15*(1+$G15) -> 15.0626 | Z15: =N15*(1+$G15) -> 15.0626 | AA15: =O15*(1+$G15) -> 15.0626 | AB15: =P15*(1+$G15) -> 15.0626 | ... AF15: =T15*(1+$G15) -> 15.0626
D16: =CaseData!C16 -> 2 | E16: =CaseData!D16 -> 4 | G16: =INDEX(CaseData!$K$8:$K$12,MATCH("Client "&$D16,CaseData!$I$8:$I$12,0)) -> 0.06 | I16: =SUMIFS(CaseData!$F$8:$F$307,CaseData!$B$8:$B$307,I$5,CaseData!$C$8:$C$307,$D16,CaseData!$D$8:$D$307,$E16) -> 9.83 | J16: =SUMIFS(CaseData!$F$8:$F$307,CaseData!$B$8:$B$307,J$5,CaseData!$C$8:$C$307,$D16,CaseData!$D$8:$D$307,$E16) -> 9.83 | K16: =SUMIFS(CaseData!$F$8:$F$307,CaseData!$B$8:$B$307,K$5,CaseData!$C$8:$C$307,$D16,CaseData!$D$8:$D$307,$E16) -> 9.83 | L16: =SUMIFS(CaseData!$F$8:$F$307,CaseData!$B$8:$B$307,L$5,CaseData!$C$8:$C$307,$D16,CaseData!$D$8:$D$307,$E16) -> 9.83 | M16: =SUMIFS(CaseData!$F$8:$F$307,CaseData!$B$8:$B$307,M$5,CaseData!$C$8:$C$307,$D16,CaseData!$D$8:$D$307,$E16) -> 9.83 | N16: =SUMIFS(CaseData!$F$8:$F$307,CaseData!$B$8:$B$307,N$5,CaseData!$C$8:$C$307,$D16,CaseData!$D$8:$D$307,$E16) -> 9.83 | O16: =SUMIFS(CaseData!$F$8:$F$307,CaseData!$B$8:$B$307,O$5,CaseData!$C$8:$C$307,$D16,CaseData!$D$8:$D$307,$E16) -> 9.83 | P16: =SUMIFS(CaseData!$F$8:$F$307,CaseData!$B$8:$B$307,P$5,CaseData!$C$8:$C$307,$D16,CaseData!$D$8:$D$307,$E16) -> 9.83 | ... T16: =SUMIFS(CaseData!$F$8:$F$307,CaseData!$B$8:$B$307,T$5,CaseData!$C$8:$C$307,$D16,CaseData!$D$8:$D$307,$E16) -> 9.83 | U16: =I16*(1+$G16) -> 10.4198 | V16: =J16*(1+$G16) -> 10.4198 | W16: =K16*(1+$G16) -> 10.4198 | X16: =L16*(1+$G16) -> 10.4198 | Y16: =M16*(1+$G16) -> 10.4198 | Z16: =N16*(1+$G16) -> 10.4198 | AA16: =O16*(1+$G16) -> 10.4198 | AB16: =P16*(1+$G16) -> 10.4198 | ... AF16: =T16*(1+$G16) -> 10.4198
D17: =CaseData!C17 -> 2 | E17: =CaseData!D17 -> 5 | G17: =INDEX(CaseData!$K$8:$K$12,MATCH("Client "&$D17,CaseData!$I$8:$I$12,0)) -> 0.06 | I17: =SUMIFS(CaseData!$F$8:$F$307,CaseData!$B$8:$B$307,I$5,CaseData!$C$8:$C$307,$D17,CaseData!$D$8:$D$307,$E17) -> 14.16 | J17: =SUMIFS(CaseData!$F$8:$F$307,CaseData!$B$8:$B$307,J$5,CaseData!$C$8:$C$307,$D17,CaseData!$D$8:$D$307,$E17) -> 14.16 | K17: =SUMIFS(CaseData!$F$8:$F$307,CaseData!$B$8:$B$307,K$5,CaseData!$C$8:$C$307,$D17,CaseData!$D$8:$D$307,$E17) -> 14.16 | L17: =SUMIFS(CaseData!$F$8:$F$307,CaseData!$B$8:$B$307,L$5,CaseData!$C$8:$C$307,$D17,CaseData!$D$8:$D$307,$E17) -> 14.16 | M17: =SUMIFS(CaseData!$F$8:$F$307,CaseData!$B$8:$B$307,M$5,CaseData!$C$8:$C$307,$D17,CaseData!$D$8:$D$307,$E17) -> 14.16 | N17: =SUMIFS(CaseData!$F$8:$F$307,CaseData!$B$8:$B$307,N$5,CaseData!$C$8:$C$307,$D17,CaseData!$D$8:$D$307,$E17) -> 14.16 | O17: =SUMIFS(CaseData!$F$8:$F$307,CaseData!$B$8:$B$307,O$5,CaseData!$C$8:$C$307,$D17,CaseData!$D$8:$D$307,$E17) -> 14.16 | P17: =SUMIFS(CaseData!$F$8:$F$307,CaseData!$B$8:$B$307,P$5,CaseData!$C$8:$C$307,$D17,CaseData!$D$8:$D$307,$E17) -> 14.16 | ... T17: =SUMIFS(CaseData!$F$8:$F$307,CaseData!$B$8:$B$307,T$5,CaseData!$C$8:$C$307,$D17,CaseData!$D$8:$D$307,$E17) -> 14.16 | U17: =I17*(1+$G17) -> 15.0096 | V17: =J17*(1+$G17) -> 15.0096 | W17: =K17*(1+$G17) -> 15.0096 | X17: =L17*(1+$G17) -> 15.0096 | Y17: =M17*(1+$G17) -> 15.0096 | Z17: =N17*(1+$G17) -> 15.0096 | AA17: =O17*(1+$G17) -> 15.0096 | AB17: =P17*(1+$G17) -> 15.0096 | ... AF17: =T17*(1+$G17) -> 15.0096
D18: =CaseData!C18 -> 3 | E18: =CaseData!D18 -> 1 | G18: =INDEX(CaseData!$K$8:$K$12,MATCH("Client "&$D18,CaseData!$I$8:$I$12,0)) -> 0.06 | I18: =SUMIFS(CaseData!$F$8:$F$307,CaseData!$B$8:$B$307,I$5,CaseData!$C$8:$C$307,$D18,CaseData!$D$8:$D$307,$E18) -> 39.6 | J18: =SUMIFS(CaseData!$F$8:$F$307,CaseData!$B$8:$B$307,J$5,CaseData!$C$8:$C$307,$D18,CaseData!$D$8:$D$307,$E18) -> 39.6 | K18: =SUMIFS(CaseData!$F$8:$F$307,CaseData!$B$8:$B$307,K$5,CaseData!$C$8:$C$307,$D18,CaseData!$D$8:$D$307,$E18) -> 39.6 | L18: =SUMIFS(CaseData!$F$8:$F$307,CaseData!$B$8:$B$307,L$5,CaseData!$C$8:$C$307,$D18,CaseData!$D$8:$D$307,$E18) -> 39.6 | M18: =SUMIFS(CaseData!$F$8:$F$307,CaseData!$B$8:$B$307,M$5,CaseData!$C$8:$C$307,$D18,CaseData!$D$8:$D$307,$E18) -> 39.6 | N18: =SUMIFS(CaseData!$F$8:$F$307,CaseData!$B$8:$B$307,N$5,CaseData!$C$8:$C$307,$D18,CaseData!$D$8:$D$307,$E18) -> 39.6 | O18: =SUMIFS(CaseData!$F$8:$F$307,CaseData!$B$8:$B$307,O$5,CaseData!$C$8:$C$307,$D18,CaseData!$D$8:$D$307,$E18) -> 39.6 | P18: =SUMIFS(CaseData!$F$8:$F$307,CaseData!$B$8:$B$307,P$5,CaseData!$C$8:$C$307,$D18,CaseData!$D$8:$D$307,$E18) -> 39.6 | ... T18: =SUMIFS(CaseData!$F$8:$F$307,CaseData!$B$8:$B$307,T$5,CaseData!$C$8:$C$307,$D18,CaseData!$D$8:$D$307,$E18) -> 39.6 | U18: =I18*(1+$G18) -> 41.976 | V18: =J18*(1+$G18) -> 41.976 | W18: =K18*(1+$G18) -> 41.976 | X18: =L18*(1+$G18) -> 41.976 | Y18: =M18*(1+$G18) -> 41.976 | Z18: =N18*(1+$G18) -> 41.976 | AA18: =O18*(1+$G18) -> 41.976 | AB18: =P18*(1+$G18) -> 41.976 | ... AF18: =T18*(1+$G18) -> 41.976
D19: =CaseData!C19 -> 3 | E19: =CaseData!D19 -> 2 | G19: =INDEX(CaseData!$K$8:$K$12,MATCH("Client "&$D19,CaseData!$I$8:$I$12,0)) -> 0.06 | I19: =SUMIFS(CaseData!$F$8:$F$307,CaseData!$B$8:$B$307,I$5,CaseData!$C$8:$C$307,$D19,CaseData!$D$8:$D$307,$E19) -> 17.85 | J19: =SUMIFS(CaseData!$F$8:$F$307,CaseData!$B$8:$B$307,J$5,CaseData!$C$8:$C$307,$D19,CaseData!$D$8:$D$307,$E19) -> 17.85 | K19: =SUMIFS(CaseData!$F$8:$F$307,CaseData!$B$8:$B$307,K$5,CaseData!$C$8:$C$307,$D19,CaseData!$D$8:$D$307,$E19) -> 17.85 | L19: =SUMIFS(CaseData!$F$8:$F$307,CaseData!$B$8:$B$307,L$5,CaseData!$C$8:$C$307,$D19,CaseData!$D$8:$D$307,$E19) -> 17.85 | M19: =SUMIFS(CaseData!$F$8:$F$307,CaseData!$B$8:$B$307,M$5,CaseData!$C$8:$C$307,$D19,CaseData!$D$8:$D$307,$E19) -> 17.85 | N19: =SUMIFS(CaseData!$F$8:$F$307,CaseData!$B$8:$B$307,N$5,CaseData!$C$8:$C$307,$D19,CaseData!$D$8:$D$307,$E19) -> 17.85 | O19: =SUMIFS(CaseData!$F$8:$F$307,CaseData!$B$8:$B$307,O$5,CaseData!$C$8:$C$307,$D19,CaseData!$D$8:$D$307,$E19) -> 17.85 | P19: =SUMIFS(CaseData!$F$8:$F$307,CaseData!$B$8:$B$307,P$5,CaseData!$C$8:$C$307,$D19,CaseData!$D$8:$D$307,$E19) -> 17.85 | ... T19: =SUMIFS(CaseData!$F$8:$F$307,CaseData!$B$8:$B$307,T$5,CaseData!$C$8:$C$307,$D19,CaseData!$D$8:$D$307,$E19) -> 17.85 | U19: =I19*(1+$G19) -> 18.921 | V19: =J19*(1+$G19) -> 18.921 | W19: =K19*(1+$G19) -> 18.921 | X19: =L19*(1+$G19) -> 18.921 | Y19: =M19*(1+$G19) -> 18.921 | Z19: =N19*(1+$G19) -> 18.921 | AA19: =O19*(1+$G19) -> 18.921 | AB19: =P19*(1+$G19) -> 18.921 | ... AF19: =T19*(1+$G19) -> 18.921
... D32: =CaseData!C32 -> 5 | E32: =CaseData!D32 -> 5 | G32: =INDEX(CaseData!$K$8:$K$12,MATCH("Client "&$D32,CaseData!$I$8:$I$12,0)) -> 0.07 | I32: =SUMIFS(CaseData!$F$8:$F$307,CaseData!$B$8:$B$307,I$5,CaseData!$C$8:$C$307,$D32,CaseData!$D$8:$D$307,$E32) -> 12.67 | J32: =SUMIFS(CaseData!$F$8:$F$307,CaseData!$B$8:$B$307,J$5,CaseData!$C$8:$C$307,$D32,CaseData!$D$8:$D$307,$E32) -> 12.67 | K32: =SUMIFS(CaseData!$F$8:$F$307,CaseData!$B$8:$B$307,K$5,CaseData!$C$8:$C$307,$D32,CaseData!$D$8:$D$307,$E32) -> 12.67 | L32: =SUMIFS(CaseData!$F$8:$F$307,CaseData!$B$8:$B$307,L$5,CaseData!$C$8:$C$307,$D32,CaseData!$D$8:$D$307,$E32) -> 12.67 | M32: =SUMIFS(CaseData!$F$8:$F$307,CaseData!$B$8:$B$307,M$5,CaseData!$C$8:$C$307,$D32,CaseData!$D$8:$D$307,$E32) -> 12.67 | N32: =SUMIFS(CaseData!$F$8:$F$307,CaseData!$B$8:$B$307,N$5,CaseData!$C$8:$C$307,$D32,CaseData!$D$8:$D$307,$E32) -> 12.67 | O32: =SUMIFS(CaseData!$F$8:$F$307,CaseData!$B$8:$B$307,O$5,CaseData!$C$8:$C$307,$D32,CaseData!$D$8:$D$307,$E32) -> 12.67 | P32: =SUMIFS(CaseData!$F$8:$F$307,CaseData!$B$8:$B$307,P$5,CaseData!$C$8:$C$307,$D32,CaseData!$D$8:$D$307,$E32) -> 12.67 | ... T32: =SUMIFS(CaseData!$F$8:$F$307,CaseData!$B$8:$B$307,T$5,CaseData!$C$8:$C$307,$D32,CaseData!$D$8:$D$307,$E32) -> 12.67 | U32: =I32*(1+$G32) -> 13.5569 | V32: =J32*(1+$G32) -> 13.5569 | W32: =K32*(1+$G32) -> 13.5569 | X32: =L32*(1+$G32) -> 13.5569 | Y32: =M32*(1+$G32) -> 13.5569 | Z32: =N32*(1+$G32) -> 13.5569 | AA32: =O32*(1+$G32) -> 13.5569 | AB32: =P32*(1+$G32) -> 13.5569 | ... AF32: =T32*(1+$G32) -> 13.5569
B34: Direct Cost per unit
D35: =D$8 -> 1 | E35: =E$8 -> 1 | G35: =INDEX(CaseData!$N$8:$N$12,MATCH($E35,CaseData!$M$8:$M$12,0)) -> 0.07 | I35: =SUMIFS(CaseData!$G$8:$G$307,CaseData!$B$8:$B$307,I$5,CaseData!$C$8:$C$307,$D35,CaseData!$D$8:$D$307,$E35) -> 25 | J35: =SUMIFS(CaseData!$G$8:$G$307,CaseData!$B$8:$B$307,J$5,CaseData!$C$8:$C$307,$D35,CaseData!$D$8:$D$307,$E35) -> 25 | K35: =SUMIFS(CaseData!$G$8:$G$307,CaseData!$B$8:$B$307,K$5,CaseData!$C$8:$C$307,$D35,CaseData!$D$8:$D$307,$E35) -> 25 | L35: =SUMIFS(CaseData!$G$8:$G$307,CaseData!$B$8:$B$307,L$5,CaseData!$C$8:$C$307,$D35,CaseData!$D$8:$D$307,$E35) -> 25 | M35: =SUMIFS(CaseData!$G$8:$G$307,CaseData!$B$8:$B$307,M$5,CaseData!$C$8:$C$307,$D35,CaseData!$D$8:$D$307,$E35) -> 25 | N35: =SUMIFS(CaseData!$G$8:$G$307,CaseData!$B$8:$B$307,N$5,CaseData!$C$8:$C$307,$D35,CaseData!$D$8:$D$307,$E35) -> 25 | O35: =SUMIFS(CaseData!$G$8:$G$307,CaseData!$B$8:$B$307,O$5,CaseData!$C$8:$C$307,$D35,CaseData!$D$8:$D$307,$E35) -> 25 | P35: =SUMIFS(CaseData!$G$8:$G$307,CaseData!$B$8:$B$307,P$5,CaseData!$C$8:$C$307,$D35,CaseData!$D$8:$D$307,$E35) -> 25 | ... T35: =SUMIFS(CaseData!$G$8:$G$307,CaseData!$B$8:$B$307,T$5,CaseData!$C$8:$C$307,$D35,CaseData!$D$8:$D$307,$E35) -> 25 | U35: =I35*(1+$G35) -> 26.75 | V35: =J35*(1+$G35) -> 26.75 | W35: =K35*(1+$G35) -> 26.75 | X35: =L35*(1+$G35) -> 26.75 | Y35: =M35*(1+$G35) -> 26.75 | Z35: =N35*(1+$G35) -> 26.75 | AA35: =O35*(1+$G35) -> 26.75 | AB35: =P35*(1+$G35) -> 26.75 | ... AF35: =T35*(1+$G35) -> 26.75
D36: =D$9 -> 1 | E36: =E$9 -> 2 | G36: =INDEX(CaseData!$N$8:$N$12,MATCH($E36,CaseData!$M$8:$M$12,0)) -> 0.09 | I36: =SUMIFS(CaseData!$G$8:$G$307,CaseData!$B$8:$B$307,I$5,CaseData!$C$8:$C$307,$D36,CaseData!$D$8:$D$307,$E36) -> 7.31 | J36: =SUMIFS(CaseData!$G$8:$G$307,CaseData!$B$8:$B$307,J$5,CaseData!$C$8:$C$307,$D36,CaseData!$D$8:$D$307,$E36) -> 7.31 | K36: =SUMIFS(CaseData!$G$8:$G$307,CaseData!$B$8:$B$307,K$5,CaseData!$C$8:$C$307,$D36,CaseData!$D$8:$D$307,$E36) -> 7.31 | L36: =SUMIFS(CaseData!$G$8:$G$307,CaseData!$B$8:$B$307,L$5,CaseData!$C$8:$C$307,$D36,CaseData!$D$8:$D$307,$E36) -> 7.31 | M36: =SUMIFS(CaseData!$G$8:$G$307,CaseData!$B$8:$B$307,M$5,CaseData!$C$8:$C$307,$D36,CaseData!$D$8:$D$307,$E36) -> 7.31 | N36: =SUMIFS(CaseData!$G$8:$G$307,CaseData!$B$8:$B$307,N$5,CaseData!$C$8:$C$307,$D36,CaseData!$D$8:$D$307,$E36) -> 7.31 | O36: =SUMIFS(CaseData!$G$8:$G$307,CaseData!$B$8:$B$307,O$5,CaseData!$C$8:$C$307,$D36,CaseData!$D$8:$D$307,$E36) -> 7.31 | P36: =SUMIFS(CaseData!$G$8:$G$307,CaseData!$B$8:$B$307,P$5,CaseData!$C$8:$C$307,$D36,CaseData!$D$8:$D$307,$E36) -> 7.31 | ... T36: =SUMIFS(CaseData!$G$8:$G$307,CaseData!$B$8:$B$307,T$5,CaseData!$C$8:$C$307,$D36,CaseData!$D$8:$D$307,$E36) -> 7.31 | U36: =I36*(1+$G36) -> 7.9679 | V36: =J36*(1+$G36) -> 7.9679 | W36: =K36*(1+$G36) -> 7.9679 | X36: =L36*(1+$G36) -> 7.9679 | Y36: =M36*(1+$G36) -> 7.9679 | Z36: =N36*(1+$G36) -> 7.9679 | AA36: =O36*(1+$G36) -> 7.9679 | AB36: =P36*(1+$G36) -> 7.9679 | ... AF36: =T36*(1+$G36) -> 7.9679
D37: =D$10 -> 1 | E37: =E$10 -> 3 | G37: =INDEX(CaseData!$N$8:$N$12,MATCH($E37,CaseData!$M$8:$M$12,0)) -> 0.08 | I37: =SUMIFS(CaseData!$G$8:$G$307,CaseData!$B$8:$B$307,I$5,CaseData!$C$8:$C$307,$D37,CaseData!$D$8:$D$307,$E37) -> 5.12 | J37: =SUMIFS(CaseData!$G$8:$G$307,CaseData!$B$8:$B$307,J$5,CaseData!$C$8:$C$307,$D37,CaseData!$D$8:$D$307,$E37) -> 5.12 | K37: =SUMIFS(CaseData!$G$8:$G$307,CaseData!$B$8:$B$307,K$5,CaseData!$C$8:$C$307,$D37,CaseData!$D$8:$D$307,$E37) -> 5.12 | L37: =SUMIFS(CaseData!$G$8:$G$307,CaseData!$B$8:$B$307,L$5,CaseData!$C$8:$C$307,$D37,CaseData!$D$8:$D$307,$E37) -> 5.12 | M37: =SUMIFS(CaseData!$G$8:$G$307,CaseData!$B$8:$B$307,M$5,CaseData!$C$8:$C$307,$D37,CaseData!$D$8:$D$307,$E37) -> 5.12 | N37: =SUMIFS(CaseData!$G$8:$G$307,CaseData!$B$8:$B$307,N$5,CaseData!$C$8:$C$307,$D37,CaseData!$D$8:$D$307,$E37) -> 5.12 | O37: =SUMIFS(CaseData!$G$8:$G$307,CaseData!$B$8:$B$307,O$5,CaseData!$C$8:$C$307,$D37,CaseData!$D$8:$D$307,$E37) -> 5.12 | P37: =SUMIFS(CaseData!$G$8:$G$307,CaseData!$B$8:$B$307,P$5,CaseData!$C$8:$C$307,$D37,CaseData!$D$8:$D$307,$E37) -> 5.12 | ... T37: =SUMIFS(CaseData!$G$8:$G$307,CaseData!$B$8:$B$307,T$5,CaseData!$C$8:$C$307,$D37,CaseData!$D$8:$D$307,$E37) -> 5.12 | U37: =I37*(1+$G37) -> 5.5296 | V37: =J37*(1+$G37) -> 5.5296 | W37: =K37*(1+$G37) -> 5.5296 | X37: =L37*(1+$G37) -> 5.5296 | Y37: =M37*(1+$G37) -> 5.5296 | Z37: =N37*(1+$G37) -> 5.5296 | AA37: =O37*(1+$G37) -> 5.5296 | AB37: =P37*(1+$G37) -> 5.5296 | ... AF37: =T37*(1+$G37) -> 5.5296
D38: =D$11 -> 1 | E38: =E$11 -> 4 | G38: =INDEX(CaseData!$N$8:$N$12,MATCH($E38,CaseData!$M$8:$M$12,0)) -> 0.07 | I38: =SUMIFS(CaseData!$G$8:$G$307,CaseData!$B$8:$B$307,I$5,CaseData!$C$8:$C$307,$D38,CaseData!$D$8:$D$307,$E38) -> 6.48 | J38: =SUMIFS(CaseData!$G$8:$G$307,CaseData!$B$8:$B$307,J$5,CaseData!$C$8:$C$307,$D38,CaseData!$D$8:$D$307,$E38) -> 6.48 | K38: =SUMIFS(CaseData!$G$8:$G$307,CaseData!$B$8:$B$307,K$5,CaseData!$C$8:$C$307,$D38,CaseData!$D$8:$D$307,$E38) -> 6.48 | L38: =SUMIFS(CaseData!$G$8:$G$307,CaseData!$B$8:$B$307,L$5,CaseData!$C$8:$C$307,$D38,CaseData!$D$8:$D$307,$E38) -> 6.48 | M38: =SUMIFS(CaseData!$G$8:$G$307,CaseData!$B$8:$B$307,M$5,CaseData!$C$8:$C$307,$D38,CaseData!$D$8:$D$307,$E38) -> 6.48 | N38: =SUMIFS(CaseData!$G$8:$G$307,CaseData!$B$8:$B$307,N$5,CaseData!$C$8:$C$307,$D38,CaseData!$D$8:$D$307,$E38) -> 6.48 | O38: =SUMIFS(CaseData!$G$8:$G$307,CaseData!$B$8:$B$307,O$5,CaseData!$C$8:$C$307,$D38,CaseData!$D$8:$D$307,$E38) -> 6.48 | P38: =SUMIFS(CaseData!$G$8:$G$307,CaseData!$B$8:$B$307,P$5,CaseData!$C$8:$C$307,$D38,CaseData!$D$8:$D$307,$E38) -> 6.48 | ... T38: =SUMIFS(CaseData!$G$8:$G$307,CaseData!$B$8:$B$307,T$5,CaseData!$C$8:$C$307,$D38,CaseData!$D$8:$D$307,$E38) -> 6.48 | U38: =I38*(1+$G38) -> 6.9336 | V38: =J38*(1+$G38) -> 6.9336 | W38: =K38*(1+$G38) -> 6.9336 | X38: =L38*(1+$G38) -> 6.9336 | Y38: =M38*(1+$G38) -> 6.9336 | Z38: =N38*(1+$G38) -> 6.9336 | AA38: =O38*(1+$G38) -> 6.9336 | AB38: =P38*(1+$G38) -> 6.9336 | ... AF38: =T38*(1+$G38) -> 6.9336
D39: =D$12 -> 1 | E39: =E$12 -> 5 | G39: =INDEX(CaseData!$N$8:$N$12,MATCH($E39,CaseData!$M$8:$M$12,0)) -> 0.05 | I39: =SUMIFS(CaseData!$G$8:$G$307,CaseData!$B$8:$B$307,I$5,CaseData!$C$8:$C$307,$D39,CaseData!$D$8:$D$307,$E39) -> 6.26 | J39: =SUMIFS(CaseData!$G$8:$G$307,CaseData!$B$8:$B$307,J$5,CaseData!$C$8:$C$307,$D39,CaseData!$D$8:$D$307,$E39) -> 6.26 | K39: =SUMIFS(CaseData!$G$8:$G$307,CaseData!$B$8:$B$307,K$5,CaseData!$C$8:$C$307,$D39,CaseData!$D$8:$D$307,$E39) -> 6.26 | L39: =SUMIFS(CaseData!$G$8:$G$307,CaseData!$B$8:$B$307,L$5,CaseData!$C$8:$C$307,$D39,CaseData!$D$8:$D$307,$E39) -> 6.26 | M39: =SUMIFS(CaseData!$G$8:$G$307,CaseData!$B$8:$B$307,M$5,CaseData!$C$8:$C$307,$D39,CaseData!$D$8:$D$307,$E39) -> 6.26 | N39: =SUMIFS(CaseData!$G$8:$G$307,CaseData!$B$8:$B$307,N$5,CaseData!$C$8:$C$307,$D39,CaseData!$D$8:$D$307,$E39) -> 6.26 | O39: =SUMIFS(CaseData!$G$8:$G$307,CaseData!$B$8:$B$307,O$5,CaseData!$C$8:$C$307,$D39,CaseData!$D$8:$D$307,$E39) -> 6.26 | P39: =SUMIFS(CaseData!$G$8:$G$307,CaseData!$B$8:$B$307,P$5,CaseData!$C$8:$C$307,$D39,CaseData!$D$8:$D$307,$E39) -> 6.26 | ... T39: =SUMIFS(CaseData!$G$8:$G$307,CaseData!$B$8:$B$307,T$5,CaseData!$C$8:$C$307,$D39,CaseData!$D$8:$D$307,$E39) -> 6.26 | U39: =I39*(1+$G39) -> 6.573 | V39: =J39*(1+$G39) -> 6.573 | W39: =K39*(1+$G39) -> 6.573 | X39: =L39*(1+$G39) -> 6.573 | Y39: =M39*(1+$G39) -> 6.573 | Z39: =N39*(1+$G39) -> 6.573 | AA39: =O39*(1+$G39) -> 6.573 | AB39: =P39*(1+$G39) -> 6.573 | ... AF39: =T39*(1+$G39) -> 6.573
D40: =D$13 -> 2 | E40: =E$13 -> 1 | G40: =INDEX(CaseData!$N$8:$N$12,MATCH($E40,CaseData!$M$8:$M$12,0)) -> 0.07 | I40: =SUMIFS(CaseData!$G$8:$G$307,CaseData!$B$8:$B$307,I$5,CaseData!$C$8:$C$307,$D40,CaseData!$D$8:$D$307,$E40) -> 25 | J40: =SUMIFS(CaseData!$G$8:$G$307,CaseData!$B$8:$B$307,J$5,CaseData!$C$8:$C$307,$D40,CaseData!$D$8:$D$307,$E40) -> 25 | K40: =SUMIFS(CaseData!$G$8:$G$307,CaseData!$B$8:$B$307,K$5,CaseData!$C$8:$C$307,$D40,CaseData!$D$8:$D$307,$E40) -> 25 | L40: =SUMIFS(CaseData!$G$8:$G$307,CaseData!$B$8:$B$307,L$5,CaseData!$C$8:$C$307,$D40,CaseData!$D$8:$D$307,$E40) -> 25 | M40: =SUMIFS(CaseData!$G$8:$G$307,CaseData!$B$8:$B$307,M$5,CaseData!$C$8:$C$307,$D40,CaseData!$D$8:$D$307,$E40) -> 25 | N40: =SUMIFS(CaseData!$G$8:$G$307,CaseData!$B$8:$B$307,N$5,CaseData!$C$8:$C$307,$D40,CaseData!$D$8:$D$307,$E40) -> 25 | O40: =SUMIFS(CaseData!$G$8:$G$307,CaseData!$B$8:$B$307,O$5,CaseData!$C$8:$C$307,$D40,CaseData!$D$8:$D$307,$E40) -> 25 | P40: =SUMIFS(CaseData!$G$8:$G$307,CaseData!$B$8:$B$307,P$5,CaseData!$C$8:$C$307,$D40,CaseData!$D$8:$D$307,$E40) -> 25 | ... T40: =SUMIFS(CaseData!$G$8:$G$307,CaseData!$B$8:$B$307,T$5,CaseData!$C$8:$C$307,$D40,CaseData!$D$8:$D$307,$E40) -> 25 | U40: =I40*(1+$G40) -> 26.75 | V40: =J40*(1+$G40) -> 26.75 | W40: =K40*(1+$G40) -> 26.75 | X40: =L40*(1+$G40) -> 26.75 | Y40: =M40*(1+$G40) -> 26.75 | Z40: =N40*(1+$G40) -> 26.75 | AA40: =O40*(1+$G40) -> 26.75 | AB40: =P40*(1+$G40) -> 26.75 | ... AF40: =T40*(1+$G40) -> 26.75
D41: =D$14 -> 2 | E41: =E$14 -> 2 | G41: =INDEX(CaseData!$N$8:$N$12,MATCH($E41,CaseData!$M$8:$M$12,0)) -> 0.09 | I41: =SUMIFS(CaseData!$G$8:$G$307,CaseData!$B$8:$B$307,I$5,CaseData!$C$8:$C$307,$D41,CaseData!$D$8:$D$307,$E41) -> 7.31 | J41: =SUMIFS(CaseData!$G$8:$G$307,CaseData!$B$8:$B$307,J$5,CaseData!$C$8:$C$307,$D41,CaseData!$D$8:$D$307,$E41) -> 7.31 | K41: =SUMIFS(CaseData!$G$8:$G$307,CaseData!$B$8:$B$307,K$5,CaseData!$C$8:$C$307,$D41,CaseData!$D$8:$D$307,$E41) -> 7.31 | L41: =SUMIFS(CaseData!$G$8:$G$307,CaseData!$B$8:$B$307,L$5,CaseData!$C$8:$C$307,$D41,CaseData!$D$8:$D$307,$E41) -> 7.31 | M41: =SUMIFS(CaseData!$G$8:$G$307,CaseData!$B$8:$B$307,M$5,CaseData!$C$8:$C$307,$D41,CaseData!$D$8:$D$307,$E41) -> 7.31 | N41: =SUMIFS(CaseData!$G$8:$G$307,CaseData!$B$8:$B$307,N$5,CaseData!$C$8:$C$307,$D41,CaseData!$D$8:$D$307,$E41) -> 7.31 | O41: =SUMIFS(CaseData!$G$8:$G$307,CaseData!$B$8:$B$307,O$5,CaseData!$C$8:$C$307,$D41,CaseData!$D$8:$D$307,$E41) -> 7.31 | P41: =SUMIFS(CaseData!$G$8:$G$307,CaseData!$B$8:$B$307,P$5,CaseData!$C$8:$C$307,$D41,CaseData!$D$8:$D$307,$E41) -> 7.31 | ... T41: =SUMIFS(CaseData!$G$8:$G$307,CaseData!$B$8:$B$307,T$5,CaseData!$C$8:$C$307,$D41,CaseData!$D$8:$D$307,$E41) -> 7.31 | U41: =I41*(1+$G41) -> 7.9679 | V41: =J41*(1+$G41) -> 7.9679 | W41: =K41*(1+$G41) -> 7.9679 | X41: =L41*(1+$G41) -> 7.9679 | Y41: =M41*(1+$G41) -> 7.9679 | Z41: =N41*(1+$G41) -> 7.9679 | AA41: =O41*(1+$G41) -> 7.9679 | AB41: =P41*(1+$G41) -> 7.9679 | ... AF41: =T41*(1+$G41) -> 7.9679
D42: =D$15 -> 2 | E42: =E$15 -> 3 | G42: =INDEX(CaseData!$N$8:$N$12,MATCH($E42,CaseData!$M$8:$M$12,0)) -> 0.08 | I42: =SUMIFS(CaseData!$G$8:$G$307,CaseData!$B$8:$B$307,I$5,CaseData!$C$8:$C$307,$D42,CaseData!$D$8:$D$307,$E42) -> 5.12 | J42: =SUMIFS(CaseData!$G$8:$G$307,CaseData!$B$8:$B$307,J$5,CaseData!$C$8:$C$307,$D42,CaseData!$D$8:$D$307,$E42) -> 5.12 | K42: =SUMIFS(CaseData!$G$8:$G$307,CaseData!$B$8:$B$307,K$5,CaseData!$C$8:$C$307,$D42,CaseData!$D$8:$D$307,$E42) -> 5.12 | L42: =SUMIFS(CaseData!$G$8:$G$307,CaseData!$B$8:$B$307,L$5,CaseData!$C$8:$C$307,$D42,CaseData!$D$8:$D$307,$E42) -> 5.12 | M42: =SUMIFS(CaseData!$G$8:$G$307,CaseData!$B$8:$B$307,M$5,CaseData!$C$8:$C$307,$D42,CaseData!$D$8:$D$307,$E42) -> 5.12 | N42: =SUMIFS(CaseData!$G$8:$G$307,CaseData!$B$8:$B$307,N$5,CaseData!$C$8:$C$307,$D42,CaseData!$D$8:$D$307,$E42) -> 5.12 | O42: =SUMIFS(CaseData!$G$8:$G$307,CaseData!$B$8:$B$307,O$5,CaseData!$C$8:$C$307,$D42,CaseData!$D$8:$D$307,$E42) -> 5.12 | P42: =SUMIFS(CaseData!$G$8:$G$307,CaseData!$B$8:$B$307,P$5,CaseData!$C$8:$C$307,$D42,CaseData!$D$8:$D$307,$E42) -> 5.12 | ... T42: =SUMIFS(CaseData!$G$8:$G$307,CaseData!$B$8:$B$307,T$5,CaseData!$C$8:$C$307,$D42,CaseData!$D$8:$D$307,$E42) -> 5.12 | U42: =I42*(1+$G42) -> 5.5296 | V42: =J42*(1+$G42) -> 5.5296 | W42: =K42*(1+$G42) -> 5.5296 | X42: =L42*(1+$G42) -> 5.5296 | Y42: =M42*(1+$G42) -> 5.5296 | Z42: =N42*(1+$G42) -> 5.5296 | AA42: =O42*(1+$G42) -> 5.5296 | AB42: =P42*(1+$G42) -> 5.5296 | ... AF42: =T42*(1+$G42) -> 5.5296
D43: =D$16 -> 2 | E43: =E$16 -> 4 | G43: =INDEX(CaseData!$N$8:$N$12,MATCH($E43,CaseData!$M$8:$M$12,0)) -> 0.07 | I43: =SUMIFS(CaseData!$G$8:$G$307,CaseData!$B$8:$B$307,I$5,CaseData!$C$8:$C$307,$D43,CaseData!$D$8:$D$307,$E43) -> 6.48 | J43: =SUMIFS(CaseData!$G$8:$G$307,CaseData!$B$8:$B$307,J$5,CaseData!$C$8:$C$307,$D43,CaseData!$D$8:$D$307,$E43) -> 6.48 | K43: =SUMIFS(CaseData!$G$8:$G$307,CaseData!$B$8:$B$307,K$5,CaseData!$C$8:$C$307,$D43,CaseData!$D$8:$D$307,$E43) -> 6.48 | L43: =SUMIFS(CaseData!$G$8:$G$307,CaseData!$B$8:$B$307,L$5,CaseData!$C$8:$C$307,$D43,CaseData!$D$8:$D$307,$E43) -> 6.48 | M43: =SUMIFS(CaseData!$G$8:$G$307,CaseData!$B$8:$B$307,M$5,CaseData!$C$8:$C$307,$D43,CaseData!$D$8:$D$307,$E43) -> 6.48 | N43: =SUMIFS(CaseData!$G$8:$G$307,CaseData!$B$8:$B$307,N$5,CaseData!$C$8:$C$307,$D43,CaseData!$D$8:$D$307,$E43) -> 6.48 | O43: =SUMIFS(CaseData!$G$8:$G$307,CaseData!$B$8:$B$307,O$5,CaseData!$C$8:$C$307,$D43,CaseData!$D$8:$D$307,$E43) -> 6.48 | P43: =SUMIFS(CaseData!$G$8:$G$307,CaseData!$B$8:$B$307,P$5,CaseData!$C$8:$C$307,$D43,CaseData!$D$8:$D$307,$E43) -> 6.48 | ... T43: =SUMIFS(CaseData!$G$8:$G$307,CaseData!$B$8:$B$307,T$5,CaseData!$C$8:$C$307,$D43,CaseData!$D$8:$D$307,$E43) -> 6.48 | U43: =I43*(1+$G43) -> 6.9336 | V43: =J43*(1+$G43) -> 6.9336 | W43: =K43*(1+$G43) -> 6.9336 | X43: =L43*(1+$G43) -> 6.9336 | Y43: =M43*(1+$G43) -> 6.9336 | Z43: =N43*(1+$G43) -> 6.9336 | AA43: =O43*(1+$G43) -> 6.9336 | AB43: =P43*(1+$G43) -> 6.9336 | ... AF43: =T43*(1+$G43) -> 6.9336
D44: =D$17 -> 2 | E44: =E$17 -> 5 | G44: =INDEX(CaseData!$N$8:$N$12,MATCH($E44,CaseData!$M$8:$M$12,0)) -> 0.05 | I44: =SUMIFS(CaseData!$G$8:$G$307,CaseData!$B$8:$B$307,I$5,CaseData!$C$8:$C$307,$D44,CaseData!$D$8:$D$307,$E44) -> 6.26 | J44: =SUMIFS(CaseData!$G$8:$G$307,CaseData!$B$8:$B$307,J$5,CaseData!$C$8:$C$307,$D44,CaseData!$D$8:$D$307,$E44) -> 6.26 | K44: =SUMIFS(CaseData!$G$8:$G$307,CaseData!$B$8:$B$307,K$5,CaseData!$C$8:$C$307,$D44,CaseData!$D$8:$D$307,$E44) -> 6.26 | L44: =SUMIFS(CaseData!$G$8:$G$307,CaseData!$B$8:$B$307,L$5,CaseData!$C$8:$C$307,$D44,CaseData!$D$8:$D$307,$E44) -> 6.26 | M44: =SUMIFS(CaseData!$G$8:$G$307,CaseData!$B$8:$B$307,M$5,CaseData!$C$8:$C$307,$D44,CaseData!$D$8:$D$307,$E44) -> 6.26 | N44: =SUMIFS(CaseData!$G$8:$G$307,CaseData!$B$8:$B$307,N$5,CaseData!$C$8:$C$307,$D44,CaseData!$D$8:$D$307,$E44) -> 6.26 | O44: =SUMIFS(CaseData!$G$8:$G$307,CaseData!$B$8:$B$307,O$5,CaseData!$C$8:$C$307,$D44,CaseData!$D$8:$D$307,$E44) -> 6.26 | P44: =SUMIFS(CaseData!$G$8:$G$307,CaseData!$B$8:$B$307,P$5,CaseData!$C$8:$C$307,$D44,CaseData!$D$8:$D$307,$E44) -> 6.26 | ... T44: =SUMIFS(CaseData!$G$8:$G$307,CaseData!$B$8:$B$307,T$5,CaseData!$C$8:$C$307,$D44,CaseData!$D$8:$D$307,$E44) -> 6.26 | U44: =I44*(1+$G44) -> 6.573 | V44: =J44*(1+$G44) -> 6.573 | W44: =K44*(1+$G44) -> 6.573 | X44: =L44*(1+$G44) -> 6.573 | Y44: =M44*(1+$G44) -> 6.573 | Z44: =N44*(1+$G44) -> 6.573 | AA44: =O44*(1+$G44) -> 6.573 | AB44: =P44*(1+$G44) -> 6.573 | ... AF44: =T44*(1+$G44) -> 6.573
