Workbook
Name company: Assumptions!$F$7
Name it_expansion_date: Assumptions!$F$41
Name periods_bldg: Assumptions!$F$18
Name periods_it: Assumptions!$F$26
Name start_date: Assumptions!$F$9
Name topic: Assumptions!$E$8 & ": " & Assumptions!$F$8

Sheet Calculations
A1: {=company} -> Galway Inc.
A2: {=topic} -> CFM topic: Capex and Depreciation
A3: CALCULATIONS SCHEDULE | J3: {=EOMONTH( start_date, _xlfn.SEQUENCE( 1, MAX( periods_bldg, periods_it ), 0, 12 ) )} -> 43465 | K3: 43830 | L3: 44196 | M3: 44561 | N3: 44926 | O3: 45291 | P3: 45657 | Q3: 46022 | R3: 46387 | S3: 46752
A5: BUILDINGS
B7: Depreciation of existing assets
E9: Depreciation of existing building assets | G9: USD m | J9: {=_xlfn.LET( _xlpm.model_operating_flag,_xlfn.ANCHORARRAY( Time!J9), _xlpm.PPE, Assumptions!$F$13, _xlpm.useful_life, Assumptions!$F$14, _xlpm.depreciation, _xlpm.PPE / _xlpm.useful_life, _xlpm.model_operating_flag * _xlpm.depreciation )} -> 101.72 | K9: 101.72 | L9: 101.72 | M9: 101.72 | N9: 101.72 | O9: 101.72 | P9: 101.72 | Q9: 101.72 | R9: 101.72 | S9: 101.72
B11: Depreciation of new building assets
E13: Annual spent on new assets | G13: USD m | J13: {=_xlfn.LET( _xlpm.initial_spent, Assumptions!$F$16, _xlpm.annual_growth, Assumptions!$F$17, _xlpm.period,_xlfn.ANCHORARRAY( Time!J8), _xlpm.initial_spent * ( 1 + _xlpm.annual_growth ) ^ _xlpm.period )} -> 132.7625 | K13: 142.71969 | L13: 153.42366 | M13: 164.93044 | N13: 177.30022 | O13: 190.59774 | P13: 204.89257 | Q13: 220.25951 | R13: 236.77897 | S13: 254.5374
E15: Depreciation of new building assets | F15: Acquisition date | G15: Acqusition cost | H15: Remaining value | J15: {=_xlfn.ANCHORARRAY(J3)} -> 43465 | K15: 43830 | L15: 44196 | M15: 44561 | N15: 44926 | O15: 45291 | P15: 45657 | Q15: 46022 | R15: 46387 | S15: 46752
F16: {=TRANSPOSE(_xlfn.ANCHORARRAY( J3) )} -> 43465 | G16: {=TRANSPOSE(_xlfn.ANCHORARRAY( J13) )} -> 132.7625 | H16: {=_xlfn.ANCHORARRAY(G16) - _xlfn.BYROW(_xlfn.ANCHORARRAY(J16), _xleta.SUM )} -> 0 | J16: {=_xlfn.LET( _xlpm.acquisition_cost,_xlfn.ANCHORARRAY( $G$16), _xlpm.acquisition_date,_xlfn.ANCHORARRAY( $F$16), _xlpm.current_date,_xlfn.ANCHORARRAY( J15), _xlpm.useful_life, Assumptions!$F$19, _xlpm.period, YEAR( _xlpm.current_date ) - YEAR( _xlpm.acquisition_date ), _xlpm.rate, 1 / _xlpm.useful_life * 2, _xlpm.book_value, _xlpm.acquisition_cost * ( 1 - _xlpm.rate / 2 ) * ( 1 - _xlpm.rate ) ^ ( _xlpm.period - 1 ), IF( _xlpm.period < 0, 0, IF( _xlpm.period = 0, _xlpm.acquisition_cost * _xlpm.rate / 2, IF( _xlpm.period < _xlpm.useful_life, _xlpm.book_value * _xlpm.rate, IF( _xlpm.period = _xlpm.useful_life, _xlpm.book_value, 0 ) ) ) ) )} -> 18.966071 | K16: 32.513265 | L16: 23.223761 | M16: 16.588401 | N16: 11.848858 | O16: 8.4634697 | P16: 6.0453355 | Q16: 15.113339 | R16: 0 | S16: 0
F17: 43830 | G17: 142.71969 | H17: 0 | J17: 0 | K17: 20.388527 | L17: 34.95176 | M17: 24.965543 | N17: 17.832531 | O17: 12.737522 | P17: 9.09823 | Q17: 6.4987357 | R17: 16.246839 | S17: 0
F18: 44196 | G18: 153.42366 | H18: 0 | J18: 0 | K18: 0 | L18: 21.917666 | M18: 37.573142 | N18: 26.837959 | O18: 19.169971 | P18: 13.692836 | Q18: 9.7805972 | R18: 6.9861409 | S18: 17.465352
F19: 44561 | G19: 164.93044 | H19: 18.775254 | J19: 0 | K19: 0 | L19: 0 | M19: 23.561491 | N19: 40.391128 | O19: 28.850806 | P19: 20.607718 | Q19: 14.719799 | R19: 10.514142 | S19: 7.5101014
F20: 44926 | G20: 177.30022 | H20: 28.256757 | J20: 0 | K20: 0 | L20: 0 | M20: 0 | N20: 25.328603 | O20: 43.420462 | P20: 31.014616 | Q20: 22.153297 | R20: 15.823784 | S20: 11.302703
F21: 45291 | G21: 190.59774 | H21: 42.526419 | J21: 0 | K21: 0 | L21: 0 | M21: 0 | N21: 0 | O21: 27.228248 | P21: 46.676997 | Q21: 33.340712 | R21: 23.814794 | S21: 17.010567
F22: 45657 | G22: 204.89257 | H22: 64.00226 | J22: 0 | K22: 0 | L22: 0 | M22: 0 | N22: 0 | O22: 0 | P22: 29.270367 | Q22: 50.177772 | R22: 35.841266 | S22: 25.600904
F23: 46022 | G23: 220.25951 | H23: 96.323402 | J23: 0 | K23: 0 | L23: 0 | M23: 0 | N23: 0 | O23: 0 | P23: 0 | Q23: 31.465644 | R23: 53.941105 | S23: 38.529361
F24: 46387 | G24: 236.77897 | H24: 144.96672 | J24: 0 | K24: 0 | L24: 0 | M24: 0 | N24: 0 | O24: 0 | P24: 0 | Q24: 0 | R24: 33.825568 | S24: 57.986688
F25: 46752 | G25: 254.5374 | H25: 218.17491 | J25: 0 | K25: 0 | L25: 0 | M25: 0 | N25: 0 | O25: 0 | P25: 0 | Q25: 0 | R25: 0 | S25: 36.362485
G26: USD m | J26: {=_xlfn.BYCOL(_xlfn.ANCHORARRAY(J16), _xleta.SUM )} -> 18.966071 | K26: 52.901792 | L26: 80.093187 | M26: 102.68858 | N26: 122.23908 | O26: 139.87048 | P26: 156.4061 | Q26: 183.2499 | R26: 196.99364 | S26: 211.76816
B30: Net PP&E - buildings
E32: PP&E initial balance | G32: USD m | J32: {=_xlfn.DROP( _xlfn.HSTACK( Assumptions!$F$13,_xlfn.ANCHORARRAY( J37) ), , -1 )} -> 2543 | K32: 2555.0764 | L32: 2543.1743 | M32: 2514.7848 | N32: 2475.3067 | O32: 2428.6478 | P32: 1825.6551 | Q32: 1772.4215 | R32: 1707.7111 | S32: 1645.7765
E33: Sale of building assets | G33: USD m | J33: {=_xlfn.LET( _xlpm.date_sale_assets, Assumptions!$F$45, _xlpm.carrying_value, Assumptions!$F$46 * -1, _xlpm.current_date,_xlfn.ANCHORARRAY( J3), IF( _xlpm.current_date = _xlpm.date_sale_assets, _xlpm.carrying_value, 0 ) )} -> 0 | K33: 0 | L33: 0 | M33: 0 | N33: 0 | O33: -552 | P33: 0 | Q33: 0 | R33: 0 | S33: 0
E34: Depreciation of existing assets | G34: USD m | J34: {=_xlfn.ANCHORARRAY(J9) * -1} -> -101.72 | K34: -101.72 | L34: -101.72 | M34: -101.72 | N34: -101.72 | O34: -101.72 | P34: -101.72 | Q34: -101.72 | R34: -101.72 | S34: -101.72
E35: Annual spent on new buildings | G35: USD m | J35: {=_xlfn.ANCHORARRAY( J13)} -> 132.7625 | K35: 142.71969 | L35: 153.42366 | M35: 164.93044 | N35: 177.30022 | O35: 190.59774 | P35: 204.89257 | Q35: 220.25951 | R35: 236.77897 | S35: 254.5374
E36: Depreciation of new buildings | G36: USD m | J36: {=_xlfn.ANCHORARRAY( J26) * -1} -> -18.966071 | K36: -52.901792 | L36: -80.093187 | M36: -102.68858 | N36: -122.23908 | O36: -139.87048 | P36: -156.4061 | Q36: -183.2499 | R36: -196.99364 | S36: -211.76816
E37: PP&E final balance | G37: USD m | J37: {=_xlfn.LET( _xlpm.initial_PPE, Assumptions!$F$13, _xlpm.movement,_xlfn.ANCHORARRAY( J33) +_xlfn.ANCHORARRAY( J34) +_xlfn.ANCHORARRAY( J35) +_xlfn.ANCHORARRAY( J36), _xlfn.SCAN( _xlpm.initial_PPE, _xlpm.movement, _xleta.SUM ) )} -> 2555.0764 | K37: 2543.1743 | L37: 2514.7848 | M37: 2475.3067 | N37: 2428.6478 | O37: 1825.6551 | P37: 1772.4215 | Q37: 1707.7111 | R37: 1645.7765 | S37: 1586.8257
A40: IT CAPEX
B42: Depreciation of IT capex - base
E44: Annual base investment plan | F44: Acquisition date | G44: Acqusition cost | H44: Remaining value | J44: {=_xlfn.ANCHORARRAY( J3)} -> 43465 | K44: 43830 | L44: 44196 | M44: 44561 | N44: 44926 | O44: 45291 | P44: 45657 | Q44: 46022 | R44: 46387 | S44: 46752
F45: {=TRANSPOSE(_xlfn.ANCHORARRAY( J3) )} -> 43465 | G45: {=_xlfn.SEQUENCE( COUNTA(_xlfn.ANCHORARRAY( F45) ), 1, Assumptions!$F$25, 0 )} -> 50 | H45: {=_xlfn.ANCHORARRAY( G45) - _xlfn.BYROW(_xlfn.ANCHORARRAY( J45), _xleta.SUM )} -> 0 | J45: {=_xlfn.LET( _xlpm.acquisition_cost,_xlfn.ANCHORARRAY( $G$45), _xlpm.acquisition_date,_xlfn.ANCHORARRAY( $F$45), _xlpm.useful_life, Assumptions!$F$24, _xlpm.depreciation_cost, _xlpm.acquisition_cost / _xlpm.useful_life, _xlpm.current_date,_xlfn.ANCHORARRAY( J3), _xlpm.period, YEAR( _xlpm.current_date ) - YEAR( _xlpm.acquisition_date ), _xlpm.accumulated_depreciation, _xlpm.depreciation_cost * ( _xlpm.period - 0.5 ), _xlpm.book_value, _xlpm.acquisition_cost - _xlpm.accumulated_depreciation, IF( _xlpm.period < 0, 0, IF( _xlpm.period = 0, _xlpm.depreciation_cost / 2, IF( _xlpm.period < _xlpm.useful_life, _xlpm.depreciation_cost, IF( _xlpm.book_value > 0, _xlpm.book_value, 0 ) ) ) ) )} -> 5 | K45: 10 | L45: 10 | M45: 10 | N45: 10 | O45: 5 | P45: 0 | Q45: 0 | R45: 0 | S45: 0
F46: 43830 | G46: 50 | H46: 0 | J46: 0 | K46: 5 | L46: 10 | M46: 10 | N46: 10 | O46: 10 | P46: 5 | Q46: 0 | R46: 0 | S46: 0
F47: 44196 | G47: 50 | H47: 0 | J47: 0 | K47: 0 | L47: 5 | M47: 10 | N47: 10 | O47: 10 | P47: 10 | Q47: 5 | R47: 0 | S47: 0
F48: 44561 | G48: 50 | H48: 0 | J48: 0 | K48: 0 | L48: 0 | M48: 5 | N48: 10 | O48: 10 | P48: 10 | Q48: 10 | R48: 5 | S48: 0
F49: 44926 | G49: 50 | H49: 0 | J49: 0 | K49: 0 | L49: 0 | M49: 0 | N49: 5 | O49: 10 | P49: 10 | Q49: 10 | R49: 10 | S49: 5
F50: 45291 | G50: 50 | H50: 5 | J50: 0 | K50: 0 | L50: 0 | M50: 0 | N50: 0 | O50: 5 | P50: 10 | Q50: 10 | R50: 10 | S50: 10
F51: 45657 | G51: 50 | H51: 15 | J51: 0 | K51: 0 | L51: 0 | M51: 0 | N51: 0 | O51: 0 | P51: 5 | Q51: 10 | R51: 10 | S51: 10
F52: 46022 | G52: 50 | H52: 25 | J52: 0 | K52: 0 | L52: 0 | M52: 0 | N52: 0 | O52: 0 | P52: 0 | Q52: 5 | R52: 10 | S52: 10
F53: 46387 | G53: 50 | H53: 35 | J53: 0 | K53: 0 | L53: 0 | M53: 0 | N53: 0 | O53: 0 | P53: 0 | Q53: 0 | R53: 5 | S53: 10
F54: 46752 | G54: 50 | H54: 45 | J54: 0 | K54: 0 | L54: 0 | M54: 0 | N54: 0 | O54: 0 | P54: 0 | Q54: 0 | R54: 0 | S54: 5
...

Sheet Assumptions
A1: {=company} -> Galway Inc.
A2: {=topic} -> CFM topic: Capex and Depreciation
A3: ASSUMPTIONS SCHEDULE
A5: Model technical inputs
E7: Company name | F7: Galway Inc. | G7: label
E8: CFM topic | F8: Capex and Depreciation | G8: label
E9: End of first forecasting year | F9: 43465 | G9: date
A11: PP&E - Buildings
E13: Net PP&E - Buildings in 2017 | F13: 2543 | G13: USD m
E14: Estimated useful life - existing bldg | F14: 25 | G14: years
E16: Spent in 2017 - buildings | F16: 123.5 | G16: USD m
E17: Annual spent on building growth factor | F17: 0.075 | G17: %
E18: Duration of the building investment plan | F18: 10 | G18: years
E19: Estimated useful life - new bldg assets | F19: 7 | G19: years
E20: Method of depreciation | F20: DD | G20: method
A22: IT Department
E24: Estimated useful life - IT equipment | F24: 5 | G24: years
E25: Annual spent on IT equipment | F25: 50 | G25: USD m
E26: Duration of the IT equipment investment plan | F26: 10 | G26: years
E27: Method of depreciation | F27: straight line | G27: method
C29: Additional expansion plan
E30: Year 1 | F30: 5 | G30: USD m
E31: Year 2 | F31: 15 | G31: USD m
E32: Year 3 | F32: 7.5 | G32: USD m
E33: Year 4 | F33: 20.2 | G33: USD m
E34: Year 5 | F34: 60.7 | G34: USD m
E35: Year 6 | F35: 1 | G35: USD m
E36: Year 7 | F36: 0.3 | G36: USD m
E37: Year 8 | F37: 0 | G37: USD m
E38: Year 9 | F38: 0 | G38: USD m
E39: Year 10 | F39: 0.5 | G39: USD m
E41: Start date of the additional expansion plan | F41: 43465 | G41: date
A43: Scenario assumptions
E45: Date of sale of building | F45: 45291 | G45: date
E46: Carrying value of building sold | F46: 552 | G46: USD m
A48: End of schedule

Sheet Time
A1: {=company} -> Galway Inc.
A2: {=topic} -> CFM topic: Capex and Depreciation
A3: TIME SCHEDULE
A5: MODEL TIMELINE AND COUNTER
E7: Model timeline | G7: date | J7: {=EOMONTH( start_date, _xlfn.SEQUENCE( 1, MAX( periods_bldg, periods_it ), 0, 12 ) )} -> 43465 | K7: 43830 | L7: 44196 | M7: 44561 | N7: 44926 | O7: 45291 | P7: 45657 | Q7: 46022 | R7: 46387 | S7: 46752
E8: Model period counter | G8: counter | J8: {=_xlfn.SEQUENCE( 1, MAX( periods_bldg, periods_it ), 1, 1 )} -> 1 | K8: 2 | L8: 3 | M8: 4 | N8: 5 | O8: 6 | P8: 7 | Q8: 8 | R8: 9 | S8: 10
E9: Model operating period flag | G9: flag | J9: {=_xlfn.SEQUENCE( 1, periods_bldg, 1, 0 )} -> 1 | K9: 1 | L9: 1 | M9: 1 | N9: 1 | O9: 1 | P9: 1 | Q9: 1 | R9: 1 | S9: 1
A13: MODEL FLAGS
A48: End of schedule

Sheet Tmp
A1: {=company} -> Galway Inc.
A2: {=topic} -> CFM topic: Capex and Depreciation
A3: TMP SCHEDULE
A45: End of schedule

Sheet Dep_Ans
B2: CFM Sample Exam Questions
B3: Fully Depreciated Assets
D6: 2017 | E6: =D6+1 -> 2018 | F6: =E6+1 -> 2019 | G6: =F6+1 -> 2020 | H6: =G6+1 -> 2021 | I6: =H6+1 -> 2022 | J6: =I6+1 -> 2023 | K6: =J6+1 -> 2024 | L6: =K6+1 -> 2025 | ... N6: =M6+1 -> 2027
B8: Depreciation on Existing Assets (Buildings)
B9: Useful Life | C9: 25
B11: Sale of Assets | C11: =$D$104 -> 0
B12: Year of Sale | C12: 2020
B14: Opening | E14: =D16 -> 2543 | F14: =E16 -> 2543 | G14: =F16 -> 2543 | H14: =G16 -> 2543 | I14: =H16 -> 2543 | J14: =I16 -> 2543 | K14: =J16 -> 2543 | L14: =K16 -> 2543 | ... N14: =M16 -> 2543
B15: Sale of Assets | E15: =IF(E$6=$C$12,-$C$11,0) -> 0 | F15: =IF(F$6=$C$12,-$C$11,0) -> 0 | G15: =IF(G$6=$C$12,-$C$11,0) -> 0 | H15: =IF(H$6=$C$12,-$C$11,0) -> 0 | I15: =IF(I$6=$C$12,-$C$11,0) -> 0 | J15: =IF(J$6=$C$12,-$C$11,0) -> 0 | K15: =IF(K$6=$C$12,-$C$11,0) -> 0 | L15: =IF(L$6=$C$12,-$C$11,0) -> 0 | ... N15: =IF(N$6=$C$12,-$C$11,0) -> 0
B16: Ending | D16: 2543 | E16: =SUM(E14:E15) -> 2543 | F16: =SUM(F14:F15) -> 2543 | G16: =SUM(G14:G15) -> 2543 | H16: =SUM(H14:H15) -> 2543 | I16: =SUM(I14:I15) -> 2543 | J16: =SUM(J14:J15) -> 2543 | K16: =SUM(K14:K15) -> 2543 | L16: =SUM(L14:L15) -> 2543 | ... N16: =SUM(N14:N15) -> 2543
B18: Depreciation | E18: =E14/$C$9 -> 101.72 | F18: =F14/$C$9 -> 101.72 | G18: =G14/$C$9 -> 101.72 | H18: =H14/$C$9 -> 101.72 | I18: =I14/$C$9 -> 101.72 | J18: =J14/$C$9 -> 101.72 | K18: =K14/$C$9 -> 101.72 | L18: =L14/$C$9 -> 101.72 | ... N18: =N14/$C$9 -> 101.72
B20: Depreciation on New Assets (Buildings)
B21: Capex | D21: 123.5 | E21: =D21*(1+E22) -> 132.7625 | F21: =E21*(1+F22) -> 142.71969 | G21: =F21*(1+G22) -> 153.42366 | H21: =G21*(1+H22) -> 164.93044 | I21: =H21*(1+I22) -> 177.30022 | J21: =I21*(1+J22) -> 190.59774 | K21: =J21*(1+K22) -> 204.89257 | L21: =K21*(1+L22) -> 220.25951 | ... N21: =M21*(1+N22) -> 254.5374
B22: Growth | E22: 0.075 | F22: =E22 -> 0.075 | G22: =F22 -> 0.075 | H22: =G22 -> 0.075 | I22: =H22 -> 0.075 | J22: =I22 -> 0.075 | K22: =J22 -> 0.075 | L22: =K22 -> 0.075 | M22: =L22 -> 0.075 | N22: =M22 -> 0.075
B25: Useful Life | C25: 7
B26: Depreciation Rate (% of Book Value) | C26: =1/C25*2 -> 0.28571429
B28: Depreciation Expense | P28: Check
B29: {=TRANSPOSE(E6:N6)} -> 2018 | C29: =INDEX($D$21:$N$21,MATCH($B29,$D$6:$N$6,0)) -> 132.7625 | E29: =IF(E$6=$B29,($C29-SUM($D29:D29))*$C$26/2,IF(E$6<$B29+$C$25,($C29-SUM($D29:D29))*$C$26,$C29-SUM($D29:D29))) -> 18.966071 | F29: =IF(F$6=$B29,($C29-SUM($D29:E29))*$C$26/2,IF(F$6<$B29+$C$25,($C29-SUM($D29:E29))*$C$26,$C29-SUM($D29:E29))) -> 32.513265 | G29: =IF(G$6=$B29,($C29-SUM($D29:F29))*$C$26/2,IF(G$6<$B29+$C$25,($C29-SUM($D29:F29))*$C$26,$C29-SUM($D29:F29))) -> 23.223761 | H29: =IF(H$6=$B29,($C29-SUM($D29:G29))*$C$26/2,IF(H$6<$B29+$C$25,($C29-SUM($D29:G29))*$C$26,$C29-SUM($D29:G29))) -> 16.588401 | I29: =IF(I$6=$B29,($C29-SUM($D29:H29))*$C$26/2,IF(I$6<$B29+$C$25,($C29-SUM($D29:H29))*$C$26,$C29-SUM($D29:H29))) -> 11.848858 | J29: =IF(J$6=$B29,($C29-SUM($D29:I29))*$C$26/2,IF(J$6<$B29+$C$25,($C29-SUM($D29:I29))*$C$26,$C29-SUM($D29:I29))) -> 8.4634697 | K29: =IF(K$6=$B29,($C29-SUM($D29:J29))*$C$26/2,IF(K$6<$B29+$C$25,($C29-SUM($D29:J29))*$C$26,$C29-SUM($D29:J29))) -> 6.0453355 | L29: =IF(L$6=$B29,($C29-SUM($D29:K29))*$C$26/2,IF(L$6<$B29+$C$25,($C29-SUM($D29:K29))*$C$26,$C29-SUM($D29:K29))) -> 15.113339 | ... N29: =IF(N$6=$B29,($C29-SUM($D29:M29))*$C$26/2,IF(N$6<$B29+$C$25,($C29-SUM($D29:M29))*$C$26,$C29-SUM($D29:M29))) -> 0 | P29: =SUM(E29:N29) -> 132.7625 | Q29: =P29<=C29 -> TRUE
B30: 2019 | C30: =INDEX($D$21:$N$21,MATCH($B30,$D$6:$N$6,0)) -> 142.71969 | F30: =IF(F$6=$B30,($C30-SUM($D30:E30))*$C$26/2,IF(F$6<$B30+$C$25,($C30-SUM($D30:E30))*$C$26,$C30-SUM($D30:E30))) -> 20.388527 | G30: =IF(G$6=$B30,($C30-SUM($D30:F30))*$C$26/2,IF(G$6<$B30+$C$25,($C30-SUM($D30:F30))*$C$26,$C30-SUM($D30:F30))) -> 34.95176 | H30: =IF(H$6=$B30,($C30-SUM($D30:G30))*$C$26/2,IF(H$6<$B30+$C$25,($C30-SUM($D30:G30))*$C$26,$C30-SUM($D30:G30))) -> 24.965543 | I30: =IF(I$6=$B30,($C30-SUM($D30:H30))*$C$26/2,IF(I$6<$B30+$C$25,($C30-SUM($D30:H30))*$C$26,$C30-SUM($D30:H30))) -> 17.832531 | J30: =IF(J$6=$B30,($C30-SUM($D30:I30))*$C$26/2,IF(J$6<$B30+$C$25,($C30-SUM($D30:I30))*$C$26,$C30-SUM($D30:I30))) -> 12.737522 | K30: =IF(K$6=$B30,($C30-SUM($D30:J30))*$C$26/2,IF(K$6<$B30+$C$25,($C30-SUM($D30:J30))*$C$26,$C30-SUM($D30:J30))) -> 9.09823 | L30: =IF(L$6=$B30,($C30-SUM($D30:K30))*$C$26/2,IF(L$6<$B30+$C$25,($C30-SUM($D30:K30))*$C$26,$C30-SUM($D30:K30))) -> 6.4987357 | M30: =IF(M$6=$B30,($C30-SUM($D30:L30))*$C$26/2,IF(M$6<$B30+$C$25,($C30-SUM($D30:L30))*$C$26,$C30-SUM($D30:L30))) -> 16.246839 | N30: =IF(N$6=$B30,($C30-SUM($D30:M30))*$C$26/2,IF(N$6<$B30+$C$25,($C30-SUM($D30:M30))*$C$26,$C30-SUM($D30:M30))) -> 0 | P30: =SUM(E30:N30) -> 142.71969 | Q30: =P30<=C30 -> TRUE
B31: 2020 | C31: =INDEX($D$21:$N$21,MATCH($B31,$D$6:$N$6,0)) -> 153.42366 | G31: =IF(G$6=$B31,($C31-SUM($D31:F31))*$C$26/2,IF(G$6<$B31+$C$25,($C31-SUM($D31:F31))*$C$26,$C31-SUM($D31:F31))) -> 21.917666 | H31: =IF(H$6=$B31,($C31-SUM($D31:G31))*$C$26/2,IF(H$6<$B31+$C$25,($C31-SUM($D31:G31))*$C$26,$C31-SUM($D31:G31))) -> 37.573142 | I31: =IF(I$6=$B31,($C31-SUM($D31:H31))*$C$26/2,IF(I$6<$B31+$C$25,($C31-SUM($D31:H31))*$C$26,$C31-SUM($D31:H31))) -> 26.837959 | J31: =IF(J$6=$B31,($C31-SUM($D31:I31))*$C$26/2,IF(J$6<$B31+$C$25,($C31-SUM($D31:I31))*$C$26,$C31-SUM($D31:I31))) -> 19.169971 | K31: =IF(K$6=$B31,($C31-SUM($D31:J31))*$C$26/2,IF(K$6<$B31+$C$25,($C31-SUM($D31:J31))*$C$26,$C31-SUM($D31:J31))) -> 13.692836 | L31: =IF(L$6=$B31,($C31-SUM($D31:K31))*$C$26/2,IF(L$6<$B31+$C$25,($C31-SUM($D31:K31))*$C$26,$C31-SUM($D31:K31))) -> 9.7805972 | M31: =IF(M$6=$B31,($C31-SUM($D31:L31))*$C$26/2,IF(M$6<$B31+$C$25,($C31-SUM($D31:L31))*$C$26,$C31-SUM($D31:L31))) -> 6.9861409 | N31: =IF(N$6=$B31,($C31-SUM($D31:M31))*$C$26/2,IF(N$6<$B31+$C$25,($C31-SUM($D31:M31))*$C$26,$C31-SUM($D31:M31))) -> 17.465352 | P31: =SUM(E31:N31) -> 153.42366 | Q31: =P31<=C31 -> TRUE
B32: 2021 | C32: =INDEX($D$21:$N$21,MATCH($B32,$D$6:$N$6,0)) -> 164.93044 | H32: =IF(H$6=$B32,($C32-SUM($D32:G32))*$C$26/2,IF(H$6<$B32+$C$25,($C32-SUM($D32:G32))*$C$26,$C32-SUM($D32:G32))) -> 23.561491 | I32: =IF(I$6=$B32,($C32-SUM($D32:H32))*$C$26/2,IF(I$6<$B32+$C$25,($C32-SUM($D32:H32))*$C$26,$C32-SUM($D32:H32))) -> 40.391128 | J32: =IF(J$6=$B32,($C32-SUM($D32:I32))*$C$26/2,IF(J$6<$B32+$C$25,($C32-SUM($D32:I32))*$C$26,$C32-SUM($D32:I32))) -> 28.850806 | K32: =IF(K$6=$B32,($C32-SUM($D32:J32))*$C$26/2,IF(K$6<$B32+$C$25,($C32-SUM($D32:J32))*$C$26,$C32-SUM($D32:J32))) -> 20.607718 | L32: =IF(L$6=$B32,($C32-SUM($D32:K32))*$C$26/2,IF(L$6<$B32+$C$25,($C32-SUM($D32:K32))*$C$26,$C32-SUM($D32:K32))) -> 14.719799 | M32: =IF(M$6=$B32,($C32-SUM($D32:L32))*$C$26/2,IF(M$6<$B32+$C$25,($C32-SUM($D32:L32))*$C$26,$C32-SUM($D32:L32))) -> 10.514142 | N32: =IF(N$6=$B32,($C32-SUM($D32:M32))*$C$26/2,IF(N$6<$B32+$C$25,($C32-SUM($D32:M32))*$C$26,$C32-SUM($D32:M32))) -> 7.5101014 | P32: =SUM(E32:N32) -> 146.15519 | Q32: =P32<=C32 -> TRUE
B33: 2022 | C33: =INDEX($D$21:$N$21,MATCH($B33,$D$6:$N$6,0)) -> 177.30022 | I33: =IF(I$6=$B33,($C33-SUM($D33:H33))*$C$26/2,IF(I$6<$B33+$C$25,($C33-SUM($D33:H33))*$C$26,$C33-SUM($D33:H33))) -> 25.328603 | J33: =IF(J$6=$B33,($C33-SUM($D33:I33))*$C$26/2,IF(J$6<$B33+$C$25,($C33-SUM($D33:I33))*$C$26,$C33-SUM($D33:I33))) -> 43.420462 | K33: =IF(K$6=$B33,($C33-SUM($D33:J33))*$C$26/2,IF(K$6<$B33+$C$25,($C33-SUM($D33:J33))*$C$26,$C33-SUM($D33:J33))) -> 31.014616 | L33: =IF(L$6=$B33,($C33-SUM($D33:K33))*$C$26/2,IF(L$6<$B33+$C$25,($C33-SUM($D33:K33))*$C$26,$C33-SUM($D33:K33))) -> 22.153297 | M33: =IF(M$6=$B33,($C33-SUM($D33:L33))*$C$26/2,IF(M$6<$B33+$C$25,($C33-SUM($D33:L33))*$C$26,$C33-SUM($D33:L33))) -> 15.823784 | N33: =IF(N$6=$B33,($C33-SUM($D33:M33))*$C$26/2,IF(N$6<$B33+$C$25,($C33-SUM($D33:M33))*$C$26,$C33-SUM($D33:M33))) -> 11.302703 | P33: =SUM(E33:N33) -> 149.04347 | Q33: =P33<=C33 -> TRUE
B34: 2023 | C34: =INDEX($D$21:$N$21,MATCH($B34,$D$6:$N$6,0)) -> 190.59774 | J34: =IF(J$6=$B34,($C34-SUM($D34:I34))*$C$26/2,IF(J$6<$B34+$C$25,($C34-SUM($D34:I34))*$C$26,$C34-SUM($D34:I34))) -> 27.228248 | K34: =IF(K$6=$B34,($C34-SUM($D34:J34))*$C$26/2,IF(K$6<$B34+$C$25,($C34-SUM($D34:J34))*$C$26,$C34-SUM($D34:J34))) -> 46.676997 | L34: =IF(L$6=$B34,($C34-SUM($D34:K34))*$C$26/2,IF(L$6<$B34+$C$25,($C34-SUM($D34:K34))*$C$26,$C34-SUM($D34:K34))) -> 33.340712 | M34: =IF(M$6=$B34,($C34-SUM($D34:L34))*$C$26/2,IF(M$6<$B34+$C$25,($C34-SUM($D34:L34))*$C$26,$C34-SUM($D34:L34))) -> 23.814794 | N34: =IF(N$6=$B34,($C34-SUM($D34:M34))*$C$26/2,IF(N$6<$B34+$C$25,($C34-SUM($D34:M34))*$C$26,$C34-SUM($D34:M34))) -> 17.010567 | P34: =SUM(E34:N34) -> 148.07132 | Q34: =P34<=C34 -> TRUE
B35: 2024 | C35: =INDEX($D$21:$N$21,MATCH($B35,$D$6:$N$6,0)) -> 204.89257 | K35: =IF(K$6=$B35,($C35-SUM($D35:J35))*$C$26/2,IF(K$6<$B35+$C$25,($C35-SUM($D35:J35))*$C$26,$C35-SUM($D35:J35))) -> 29.270367 | L35: =IF(L$6=$B35,($C35-SUM($D35:K35))*$C$26/2,IF(L$6<$B35+$C$25,($C35-SUM($D35:K35))*$C$26,$C35-SUM($D35:K35))) -> 50.177772 | M35: =IF(M$6=$B35,($C35-SUM($D35:L35))*$C$26/2,IF(M$6<$B35+$C$25,($C35-SUM($D35:L35))*$C$26,$C35-SUM($D35:L35))) -> 35.841266 | N35: =IF(N$6=$B35,($C35-SUM($D35:M35))*$C$26/2,IF(N$6<$B35+$C$25,($C35-SUM($D35:M35))*$C$26,$C35-SUM($D35:M35))) -> 25.600904 | P35: =SUM(E35:N35) -> 140.89031 | Q35: =P35<=C35 -> TRUE
B36: 2025 | C36: =INDEX($D$21:$N$21,MATCH($B36,$D$6:$N$6,0)) -> 220.25951 | L36: =IF(L$6=$B36,($C36-SUM($D36:K36))*$C$26/2,IF(L$6<$B36+$C$25,($C36-SUM($D36:K36))*$C$26,$C36-SUM($D36:K36))) -> 31.465644 | M36: =IF(M$6=$B36,($C36-SUM($D36:L36))*$C$26/2,IF(M$6<$B36+$C$25,($C36-SUM($D36:L36))*$C$26,$C36-SUM($D36:L36))) -> 53.941105 | N36: =IF(N$6=$B36,($C36-SUM($D36:M36))*$C$26/2,IF(N$6<$B36+$C$25,($C36-SUM($D36:M36))*$C$26,$C36-SUM($D36:M36))) -> 38.529361 | P36: =SUM(E36:N36) -> 123.93611 | Q36: =P36<=C36 -> TRUE
B37: 2026 | C37: =INDEX($D$21:$N$21,MATCH($B37,$D$6:$N$6,0)) -> 236.77897 | M37: =IF(M$6=$B37,($C37-SUM($D37:L37))*$C$26/2,IF(M$6<$B37+$C$25,($C37-SUM($D37:L37))*$C$26,$C37-SUM($D37:L37))) -> 33.825568 | N37: =IF(N$6=$B37,($C37-SUM($D37:M37))*$C$26/2,IF(N$6<$B37+$C$25,($C37-SUM($D37:M37))*$C$26,$C37-SUM($D37:M37))) -> 57.986688 | P37: =SUM(E37:N37) -> 91.812256 | Q37: =P37<=C37 -> TRUE
B38: 2027 | C38: =INDEX($D$21:$N$21,MATCH($B38,$D$6:$N$6,0)) -> 254.5374 | N38: =IF(N$6=$B38,($C38-SUM($D38:M38))*$C$26/2,IF(N$6<$B38+$C$25,($C38-SUM($D38:M38))*$C$26,$C38-SUM($D38:M38))) -> 36.362485 | P38: =SUM(E38:N38) -> 36.362485 | Q38: =P38<=C38 -> TRUE
B40: Total | E40: =SUM(E29:E38) -> 18.966071 | F40: =SUM(F29:F38) -> 52.901792 | G40: =SUM(G29:G38) -> 80.093187 | H40: =SUM(H29:H38) -> 102.68858 | I40: =SUM(I29:I38) -> 122.23908 | J40: =SUM(J29:J38) -> 139.87048 | K40: =SUM(K29:K38) -> 156.4061 | L40: =SUM(L29:L38) -> 183.2499 | ... N40: =SUM(N29:N38) -> 211.76816
B42: Total Building Depreciation | E42: =E40+E18 -> 120.68607 | F42: =F40+F18 -> 154.62179 | G42: =G40+G18 -> 181.81319 | H42: =H40+H18 -> 204.40858 | I42: =I40+I18 -> 223.95908 | J42: =J40+J18 -> 241.59048 | K42: =K40+K18 -> 258.1261 | L42: =L40+L18 -> 284.9699 | ... N42: =N40+N18 -> 313.48816
B45: IT Department Assets
B47: Start Year of Expansion Project | C47: =$D$106 -> 2018
B48: 1 | C48: 5
B49: =B48+1 -> 2 | C49: 15
B50: =B49+1 -> 3 | C50: 7.5
B51: =B50+1 -> 4 | C51: 20.2
B52: =B51+1 -> 5 | C52: 60.7
B53: =B52+1 -> 6 | C53: 1
B54: =B53+1 -> 7 | C54: 0.3
B55: =B54+1 -> 8 | C55: 0
B56: =B55+1 -> 9 | C56: 0
...
