Workbook
Name company: CaseData!$G$3
Name ListAssetClasses: CaseData!$C$15:$C$17
Name ListDepMethods: CaseData!$C$22:$C$25
Name periods: CaseData!$G$11
Name start_date: CaseData!$G$6
Name topic: "CFM Topic: " & CaseData!$G$4

Sheet Answers
A1: {=company} -> Big Dog Construction
A2: {=topic} -> CFM Topic: CAPEX and Depreciation
A3: TAX SCHEDULE | F3: Constant | G3: Unit | H3: Total | J3: {=EOMONTH( start_date, _xlfn.SEQUENCE( 1, periods, 0, 12 ) )} -> 43861 | K3: 44227 | L3: 44592 | M3: 44957 | N3: 45322 | O3: 45688 | P3: 46053 | Q3: 46418 | R3: 46783 | S3: 47149 | T3: 47514 | U3: 47879 | V3: 48244 | W3: 48610 | X3: 48975 | Y3: 49340 | Z3: 49705 | AA3: 50071 | AB3: 50436 | AC3: 50801 | AD3: 51166 | AE3: 51532 | AF3: 51897 | AG3: 52262 | AH3: 52627
E5: Depreciation method | F5: 4
B7: Long term assets
E9: Long term assets initial balance | G9: USD m | J9: {=_xlfn.DROP( _xlfn.HSTACK( 0,_xlfn.ANCHORARRAY( $J$12) ),, -1)} -> 0 | K9: 1995882.4 | L9: 2141691.2 | M9: 3229720.6 | N9: 3129625 | O9: 4102713.2 | P9: 4997205.9 | Q9: 5501860.3 | R9: 4755051.5 | S9: 3992404.4 | T9: 3802742.6 | U9: 3850441.2 | V9: 3995213.2 | W9: 3606676.5 | X9: 4491698.5 | Y9: 4753220.6 | Z9: 5020352.9 | AA9: 5090147.1 | AB9: 5120411.8 | AC9: 4546411.8 | AD9: 4087808.8 | AE9: 4378889.7 | AF9: 4460823.5 | AG9: 4094132.4 | AH9: 4438933.8
E10: Long term assets CAPEX | G10: USD m | H10: {=_xlfn.BYROW(_xlfn.ANCHORARRAY( $J$10), _xleta.SUM )} -> 24507000 | J10: {=IF( _xlfn.DROP( TRANSPOSE( INDEX(_xlfn.ANCHORARRAY( Calculations!$E$7),, 2 ) ),, 1 ) = "", 0, _xlfn.DROP( TRANSPOSE( INDEX(_xlfn.ANCHORARRAY( Calculations!$E$7),, 2 ) ),, 1 ) )} -> 2262000 | K10: 448000 | L10: 1553000 | M10: 378000 | N10: 1606000 | O10: 1679000 | P10: 1395000 | Q10: 85000 | R10: 0 | S10: 571000 | T10: 833000 | U10: 964000 | V10: 390000 | W10: 1784000 | X10: 1199000 | Y10: 1239000 | Z10: 1044000 | AA10: 1012000 | AB10: 331000 | AC10: 385000 | AD10: 1165000 | AE10: 966000 | AF10: 475000 | AG10: 1241000 | AH10: 1502000
E11: Depreciation | G11: USD m | H11: {=_xlfn.BYROW(_xlfn.ANCHORARRAY( $J$11), _xleta.SUM )} -> -19538978 | J11: {=_xlfn.LET( _xlpm.declining,_xlfn.ANCHORARRAY( Calculations!$J$63), _xlpm.straight,_xlfn.ANCHORARRAY( Calculations!$J$93), _xlpm.adjusted_MACS,_xlfn.ANCHORARRAY( Calculations!$J$124), _xlpm.sum_of_digits,_xlfn.ANCHORARRAY( Calculations!$J$154), _xlpm.selector, Answers!$F$5, CHOOSE( _xlpm.selector, _xlpm.declining, _xlpm.straight, _xlpm.adjusted_MACS, _xlpm.sum_of_digits ) * -1 )} -> -266117.65 | K11: -302191.18 | L11: -464970.59 | M11: -478095.59 | N11: -632911.76 | O11: -784507.35 | P11: -890345.59 | Q11: -831808.82 | R11: -762647.06 | S11: -760661.76 | T11: -785301.47 | U11: -819227.94 | V11: -778536.76 | W11: -898977.94 | X11: -937477.94 | Y11: -971867.65 | Z11: -974205.88 | AA11: -981735.29 | AB11: -905000 | AC11: -843602.94 | AD11: -873919.12 | AE11: -884066.18 | AF11: -841691.18 | AG11: -896198.53 | AH11: -972911.76
E12: Long term assets final balance | G12: USD m | J12: {=_xlfn.LET( _xlpm.initial_balance, 0, _xlpm.movements,_xlfn.ANCHORARRAY( $J$10) +_xlfn.ANCHORARRAY( $J$11), _xlfn.SCAN( _xlpm.initial_balance, _xlpm.movements, _xleta.SUM ) )} -> 1995882.4 | K12: 2141691.2 | L12: 3229720.6 | M12: 3129625 | N12: 4102713.2 | O12: 4997205.9 | P12: 5501860.3 | Q12: 4755051.5 | R12: 3992404.4 | S12: 3802742.6 | T12: 3850441.2 | U12: 3995213.2 | V12: 3606676.5 | W12: 4491698.5 | X12: 4753220.6 | Y12: 5020352.9 | Z12: 5090147.1 | AA12: 5120411.8 | AB12: 4546411.8 | AC12: 4087808.8 | AD12: 4378889.7 | AE12: 4460823.5 | AF12: 4094132.4 | AG12: 4438933.8 | AH12: 4968022.1
B14: Medium term assets
E16: Medium term assets initial balance | G16: USD m | J16: {=_xlfn.DROP( _xlfn.HSTACK( 0,_xlfn.ANCHORARRAY( $J$19) ),, -1)} -> 0 | K16: 1491000 | L16: 1551472.2 | M16: 1663444.4 | N16: 1639194.4 | O16: 1584722.2 | P16: 2438666.7 | Q16: 1781777.8 | R16: 2000138.9 | S16: 2372027.8 | T16: 2522277.8 | U16: 3483638.9 | V16: 2718833.3 | W16: 2540166.7 | X16: 2481972.2 | Y16: 2961888.9 | Z16: 2165750 | AA16: 3121944.4 | AB16: 2450000 | AC16: 2089333.3 | AD16: 2479777.8 | AE16: 2685583.3 | AF16: 2873666.7 | AG16: 3108194.4 | AH16: 2790944.4
E17: Medium term assets CAPEX | G17: USD m | H17: {=_xlfn.BYROW(_xlfn.ANCHORARRAY( $J$17), _xleta.SUM )} -> 27830000 | J17: {=IF( _xlfn.DROP( TRANSPOSE( INDEX(_xlfn.ANCHORARRAY( Calculations!$E$7),, 3 ) ),, 1 ) = "", 0, _xlfn.DROP( TRANSPOSE( INDEX(_xlfn.ANCHORARRAY( Calculations!$E$7),, 3 ) ),, 1 ) )} -> 1917000 | K17: 557000 | L17: 694000 | M17: 604000 | N17: 603000 | O17: 1787000 | P17: 135000 | Q17: 1074000 | R17: 1315000 | S17: 1164000 | T17: 2276000 | U17: 387000 | V17: 939000 | W17: 1038000 | X17: 1729000 | Y17: 228000 | Z17: 2222000 | AA17: 407000 | AB17: 594000 | AC17: 1460000 | AD17: 1332000 | AE17: 1368000 | AF17: 1485000 | AG17: 875000 | AH17: 1640000
E18: Depreciation | G18: USD m | H18: {=_xlfn.BYROW(_xlfn.ANCHORARRAY( $J$18), _xleta.SUM )} -> -24685111 | J18: {=_xlfn.LET( _xlpm.declining,_xlfn.ANCHORARRAY( Calculations!$J$186), _xlpm.straight,_xlfn.ANCHORARRAY( Calculations!$J$216), _xlpm.adjusted_MACS,_xlfn.ANCHORARRAY( Calculations!$J$247), _xlpm.sum_of_digits,_xlfn.ANCHORARRAY( Calculations!$J$277), _xlpm.selector, Answers!$F$5, CHOOSE( _xlpm.selector, _xlpm.declining, _xlpm.straight, _xlpm.adjusted_MACS, _xlpm.sum_of_digits ) * -1 )} -> -426000 | K18: -496527.78 | L18: -582027.78 | M18: -628250 | N18: -657472.22 | O18: -933055.56 | P18: -791888.89 | Q18: -855638.89 | R18: -943111.11 | S18: -1013750 | T18: -1314638.9 | U18: -1151805.6 | V18: -1117666.7 | W18: -1096194.4 | X18: -1249083.3 | Y18: -1024138.9 | Z18: -1265805.6 | AA18: -1078944.4 | AB18: -954666.67 | AC18: -1069555.6 | AD18: -1126194.4 | AE18: -1179916.7 | AF18: -1250472.2 | AG18: -1192250 | AH18: -1286055.6
E19: Medium term assets final balance | G19: USD m | J19: {=_xlfn.LET( _xlpm.initial_balance, 0, _xlpm.movements,_xlfn.ANCHORARRAY( $J$17) +_xlfn.ANCHORARRAY( $J$18), _xlfn.SCAN( _xlpm.initial_balance, _xlpm.movements, _xleta.SUM ) )} -> 1491000 | K19: 1551472.2 | L19: 1663444.4 | M19: 1639194.4 | N19: 1584722.2 | O19: 2438666.7 | P19: 1781777.8 | Q19: 2000138.9 | R19: 2372027.8 | S19: 2522277.8 | T19: 3483638.9 | U19: 2718833.3 | V19: 2540166.7 | W19: 2481972.2 | X19: 2961888.9 | Y19: 2165750 | Z19: 3121944.4 | AA19: 2450000 | AB19: 2089333.3 | AC19: 2479777.8 | AD19: 2685583.3 | AE19: 2873666.7 | AF19: 3108194.4 | AG19: 2790944.4 | AH19: 3144888.9
B21: Short term assets
E23: Short term assets initial balance | G23: USD m | J23: {=_xlfn.DROP( _xlfn.HSTACK( 0,_xlfn.ANCHORARRAY( $J$26) ),, -1)} -> 0 | K23: 1210666.7 | L23: 862400 | M23: 860133.33 | N23: 1537733.3 | O23: 1380200 | P23: 1493133.3 | Q23: 1288866.7 | R23: 742666.67 | S23: 810533.33 | T23: 1430800 | U23: 1448733.3 | V23: 1724200 | W23: 1364466.7 | X23: 1257933.3 | Y23: 1392200 | Z23: 935400 | AA23: 1532933.3 | AB23: 1251666.7 | AC23: 1622200 | AD23: 1668200 | AE23: 1458000 | AF23: 1631800 | AG23: 1627933.3 | AH23: 1229066.7
E24: Short term assets CAPEX | G24: USD m | H24: {=_xlfn.BYROW(_xlfn.ANCHORARRAY( J24), _xleta.SUM )} -> 25342000 | J24: {=IF( _xlfn.DROP( TRANSPOSE( INDEX(_xlfn.ANCHORARRAY( Calculations!$E$7),, 4 ) ),, 1 ) = "", 0, _xlfn.DROP( TRANSPOSE( INDEX(_xlfn.ANCHORARRAY( Calculations!$E$7),, 4 ) ),, 1 ) )} -> 1816000 | K24: 204000 | L24: 623000 | M24: 1690000 | N24: 849000 | O24: 1161000 | P24: 813000 | Q24: 193000 | R24: 740000 | S24: 1563000 | T24: 994000 | U24: 1447000 | V24: 724000 | W24: 919000 | X24: 1175000 | Y24: 350000 | Z24: 1645000 | AA24: 668000 | AB24: 1504000 | AC24: 1235000 | AD24: 928000 | AE24: 1370000 | AF24: 1218000 | AG24: 609000 | AH24: 904000
E25: Depreciation | G25: USD m | H25: {=_xlfn.BYROW(_xlfn.ANCHORARRAY( J25), _xleta.SUM )} -> -24160800 | J25: {=_xlfn.LET( _xlpm.declining,_xlfn.ANCHORARRAY( Calculations!$J$309), _xlpm.straight,_xlfn.ANCHORARRAY( Calculations!$J$339), _xlpm.adjusted_MACS,_xlfn.ANCHORARRAY( Calculations!$J$370), _xlpm.sum_of_digits,_xlfn.ANCHORARRAY( Calculations!$J$400), _xlpm.selector, Answers!$F$5, CHOOSE( _xlpm.selector, _xlpm.declining, _xlpm.straight, _xlpm.adjusted_MACS, _xlpm.sum_of_digits ) * -1 )} -> -605333.33 | K25: -552266.67 | L25: -625266.67 | M25: -1012400 | N25: -1006533.3 | O25: -1048066.7 | P25: -1017266.7 | Q25: -739200 | R25: -672133.33 | S25: -942733.33 | T25: -976066.67 | U25: -1171533.3 | V25: -1083733.3 | W25: -1025533.3 | X25: -1040733.3 | Y25: -806800 | Z25: -1047466.7 | AA25: -949266.67 | AB25: -1133466.7 | AC25: -1189000 | AD25: -1138200 | AE25: -1196200 | AF25: -1221866.7 | AG25: -1007866.7 | AH25: -951866.67
E26: Short term assets final balance | G26: USD m | J26: {=_xlfn.LET( _xlpm.initial_balance, 0, _xlpm.movements,_xlfn.ANCHORARRAY( $J$24) +_xlfn.ANCHORARRAY( $J$25), _xlfn.SCAN( _xlpm.initial_balance, _xlpm.movements, _xleta.SUM ) )} -> 1210666.7 | K26: 862400 | L26: 860133.33 | M26: 1537733.3 | N26: 1380200 | O26: 1493133.3 | P26: 1288866.7 | Q26: 742666.67 | R26: 810533.33 | S26: 1430800 | T26: 1448733.3 | U26: 1724200 | V26: 1364466.7 | W26: 1257933.3 | X26: 1392200 | Y26: 935400 | Z26: 1532933.3 | AA26: 1251666.7 | AB26: 1622200 | AC26: 1668200 | AD26: 1458000 | AE26: 1631800 | AF26: 1627933.3 | AG26: 1229066.7 | AH26: 1181200
B28: Assets schedule
E30: Assets opening balance | G30: USD m | J30: {=_xlfn.ANCHORARRAY( J9) +_xlfn.ANCHORARRAY( J16) +_xlfn.ANCHORARRAY( J23)} -> 0 | K30: 4697549 | L30: 4555563.4 | M30: 5753298.4 | N30: 6306552.8 | O30: 7067635.5 | P30: 8929005.9 | Q30: 8572504.7 | R30: 7497857 | S30: 7174965.5 | T30: 7755820.4 | U30: 8782813.4 | V30: 8438246.6 | W30: 7511309.8 | X30: 8231604.1 | Y30: 9107309.5 | Z30: 8121502.9 | AA30: 9745024.8 | AB30: 8822078.4 | AC30: 8257945.1 | AD30: 8235786.6 | AE30: 8522473 | AF30: 8966290.2 | AG30: 8830260.1 | AH30: 8458944.9
E31: CAPEX | G31: USD m | H31: {=_xlfn.BYROW(_xlfn.ANCHORARRAY( J31), _xleta.SUM )} -> 77679000 | J31: {=_xlfn.ANCHORARRAY( J10) +_xlfn.ANCHORARRAY( J17) +_xlfn.ANCHORARRAY( J24)} -> 5995000 | K31: 1209000 | L31: 2870000 | M31: 2672000 | N31: 3058000 | O31: 4627000 | P31: 2343000 | Q31: 1352000 | R31: 2055000 | S31: 3298000 | T31: 4103000 | U31: 2798000 | V31: 2053000 | W31: 3741000 | X31: 4103000 | Y31: 1817000 | Z31: 4911000 | AA31: 2087000 | AB31: 2429000 | AC31: 3080000 | AD31: 3425000 | AE31: 3704000 | AF31: 3178000 | AG31: 2725000 | AH31: 4046000
E32: Depreciation | G32: USD m | H32: {=_xlfn.BYROW(_xlfn.ANCHORARRAY( J32), _xleta.SUM )} -> -68384889 | J32: {=_xlfn.ANCHORARRAY( J11) +_xlfn.ANCHORARRAY( J18) +_xlfn.ANCHORARRAY( J25)} -> -1297451 | K32: -1350985.6 | L32: -1672265 | M32: -2118745.6 | N32: -2296917.3 | O32: -2765629.6 | P32: -2699501.1 | Q32: -2426647.7 | R32: -2377891.5 | S32: -2717145.1 | T32: -3076007 | U32: -3142566.8 | V32: -2979936.8 | W32: -3020705.7 | X32: -3227294.6 | Y32: -2802806.5 | Z32: -3287478.1 | AA32: -3009946.4 | AB32: -2993133.3 | AC32: -3102158.5 | AD32: -3138313.6 | AE32: -3260182.8 | AF32: -3314030.1 | AG32: -3096315.2 | AH32: -3210834
E33: Assets closing balance | G33: USD m | H33: {=_xlfn.BYCOL(H30:H32, _xleta.SUM )} -> 9294110.9 | J33: {=_xlfn.ANCHORARRAY( J12) +_xlfn.ANCHORARRAY( J19) +_xlfn.ANCHORARRAY( J26)} -> 4697549 | K33: 4555563.4 | L33: 5753298.4 | M33: 6306552.8 | N33: 7067635.5 | O33: 8929005.9 | P33: 8572504.7 | Q33: 7497857 | R33: 7174965.5 | S33: 7755820.4 | T33: 8782813.4 | U33: 8438246.6 | V33: 7511309.8 | W33: 8231604.1 | X33: 9107309.5 | Y33: 8121502.9 | Z33: 9745024.8 | AA33: 8822078.4 | AB33: 8257945.1 | AC33: 8235786.6 | AD33: 8522473 | AE33: 8966290.2 | AF33: 8830260.1 | AG33: 8458944.9 | AH33: 9294110.9
B35: Tax deduction
E37: Depreciation | G37: USD m | J37: {=_xlfn.ANCHORARRAY( J32) * -1} -> 1297451 | K37: 1350985.6 | L37: 1672265 | M37: 2118745.6 | N37: 2296917.3 | O37: 2765629.6 | P37: 2699501.1 | Q37: 2426647.7 | R37: 2377891.5 | S37: 2717145.1 | T37: 3076007 | U37: 3142566.8 | V37: 2979936.8 | W37: 3020705.7 | X37: 3227294.6 | Y37: 2802806.5 | Z37: 3287478.1 | AA37: 3009946.4 | AB37: 2993133.3 | AC37: 3102158.5 | AD37: 3138313.6 | AE37: 3260182.8 | AF37: 3314030.1 | AG37: 3096315.2 | AH37: 3210834
E38: Tax deduction | G38: USD m | J38: {=_xlfn.LET( _xlpm.tax_deduction, CaseData!$G$7, _xlpm.depreciation,_xlfn.ANCHORARRAY( Answers!$J$37), _xlpm.tax_deduction * _xlpm.depreciation )} -> 389235.29 | K38: 405295.69 | L38: 501679.51 | M38: 635623.68 | N38: 689075.2 | O38: 829688.87 | P38: 809850.34 | Q38: 727994.31 | R38: 713367.45 | S38: 815143.53 | T38: 922802.11 | U38: 942770.05 | V38: 893981.03 | W38: 906211.72 | X38: 968188.38 | Y38: 840841.96 | Z38: 986243.43 | AA38: 902983.92 | AB38: 897940 | AC38: 930647.55 | AD38: 941494.07 | AE38: 978054.85 | AF38: 994209.02 | AG38: 928894.56 | AH38: 963250.2
J41: NPV | K41: XNPV
J42: =_xlfn.LET( _xlpm.rate, CaseData!$G$8, _xlpm.deduction,_xlfn.ANCHORARRAY( Answers!$J$38), NPV( _xlpm.rate, _xlpm.deduction ) ) -> 7119925.4 | K42: =_xlfn.LET( _xlpm.rate, CaseData!$G$8, _xlpm.deduction,_xlfn.ANCHORARRAY( Answers!$J$38), XNPV( _xlpm.rate, _xlpm.deduction,_xlfn.ANCHORARRAY( J3) ) ) -> 7755756
H43: {=ListDepMethods} -> Declining Balance | I43: 1 | J43: 6827908.5 | K43: 7437668
H44: Straight Line | I44: 2 | J44: 6276501.2 | K44: 6836712.6
H45: Adjusted MACRS | I45: 3 | J45: 6995081.2 | K45: 7619765.4
H46: Sum of Years Digits | I46: 4 | J46: 7119925.4 | K46: 7755756
B48: Answers
C50: c | D50: i | E50: 905400
D51: ii | E51: 650133.31
D52: iii | E52: 24457487
D53: iv | E53: 4087808.8

Sheet Calculations
A1: {=company} -> Big Dog Construction
A2: {=topic} -> CFM Topic: CAPEX and Depreciation
A3: CALCULATIONS SCHEDULE | F3: Constant | G3: Unit | H3: Total | J3: {=EOMONTH( start_date, _xlfn.SEQUENCE( 1, periods, 0, 12 ) )} -> 43861 | K3: 44227 | L3: 44592 | M3: 44957 | N3: 45322 | O3: 45688 | P3: 46053 | Q3: 46418 | R3: 46783 | S3: 47149 | T3: 47514 | U3: 47879 | V3: 48244 | W3: 48610 | X3: 48975 | Y3: 49340 | Z3: 49705 | AA3: 50071 | AB3: 50436 | AC3: 50801 | AD3: 51166 | AE3: 51532 | AF3: 51897 | AG3: 52262 | AH3: 52627
B5: Capital expenditures
E7: {=_xlfn.PIVOTBY( YEAR(CaseData!$D$134:$D$433), CaseData!$F$134:$F$433,CaseData!$E$134:$E$433, _xleta.SUM,,0,,0 )} | F7: Long Term | G7: Medium Term | H7: Short Term
E8: 2020 | F8: 2262000 | G8: 1917000 | H8: 1816000
E9: 2021 | F9: 448000 | G9: 557000 | H9: 204000
E10: 2022 | F10: 1553000 | G10: 694000 | H10: 623000
E11: 2023 | F11: 378000 | G11: 604000 | H11: 1690000
E12: 2024 | F12: 1606000 | G12: 603000 | H12: 849000
E13: 2025 | F13: 1679000 | G13: 1787000 | H13: 1161000
E14: 2026 | F14: 1395000 | G14: 135000 | H14: 813000
E15: 2027 | F15: 85000 | G15: 1074000 | H15: 193000
E16: 2028 | G16: 1315000 | H16: 740000
E17: 2029 | F17: 571000 | G17: 1164000 | H17: 1563000
E18: 2030 | F18: 833000 | G18: 2276000 | H18: 994000
E19: 2031 | F19: 964000 | G19: 387000 | H19: 1447000
E20: 2032 | F20: 390000 | G20: 939000 | H20: 724000
E21: 2033 | F21: 1784000 | G21: 1038000 | H21: 919000
E22: 2034 | F22: 1199000 | G22: 1729000 | H22: 1175000
E23: 2035 | F23: 1239000 | G23: 228000 | H23: 350000
E24: 2036 | F24: 1044000 | G24: 2222000 | H24: 1645000
E25: 2037 | F25: 1012000 | G25: 407000 | H25: 668000
E26: 2038 | F26: 331000 | G26: 594000 | H26: 1504000
E27: 2039 | F27: 385000 | G27: 1460000 | H27: 1235000
E28: 2040 | F28: 1165000 | G28: 1332000 | H28: 928000
... E32: 2044 | F32: 1502000 | G32: 1640000 | H32: 904000
B34: Long Term Assets
C36: Declining balance
F37: Date | G37: Cost | J37: {=_xlfn.ANCHORARRAY($J$3)} -> 43861 | K37: 44227 | L37: 44592 | M37: 44957 | N37: 45322 | O37: 45688 | P37: 46053 | Q37: 46418 | R37: 46783 | S37: 47149 | T37: 47514 | U37: 47879 | V37: 48244 | W37: 48610 | X37: 48975 | Y37: 49340 | Z37: 49705 | AA37: 50071 | AB37: 50436 | AC37: 50801 | AD37: 51166 | AE37: 51532 | AF37: 51897 | AG37: 52262 | AH37: 52627
F38: {=_xlfn.LET( _xlpm.assets,_xlfn.ANCHORARRAY(E7), _xlpm.long_term, INDEX( _xlpm.assets,, 2 ), _xlpm.acq_date, INDEX( _xlpm.assets,, 1 ), _xlfn.DROP( _xlfn.HSTACK( _xlpm.acq_date, _xlpm.long_term ), 1 ) )} -> 2020 | G38: 2262000 | H38: {=IFERROR( _xlfn.BYROW(_xlfn.ANCHORARRAY( J38), _xleta.SUM ), 0 )} -> 2181704 | J38: {=_xlfn.LET( _xlpm.acquisition_date, INDEX(_xlfn.ANCHORARRAY( F38),, 1 ), _xlpm.acquisition_cost, INDEX(_xlfn.ANCHORARRAY( F38),, 2 ), _xlpm.current_date,_xlfn.ANCHORARRAY( J3), _xlpm.period, YEAR( _xlpm.current_date ) - _xlpm.acquisition_date, _xlpm.depreciation_rate, CaseData!$I$32, _xlpm.book_value, _xlpm.acquisition_cost * ( 1 - _xlpm.depreciation_rate ) ^ _xlpm.period, _xlpm.depreciation, _xlpm.depreciation_rate * _xlpm.book_value, IFERROR( IF( _xlpm.period < 0, 0, IF( _xlpm.period >= 0, _xlpm.depreciation, 0 ) ), 0 ) )} -> 282750 | K38: 247406.25 | L38: 216480.47 | M38: 189420.41 | N38: 165742.86 | O38: 145025 | P38: 126896.88 | Q38: 111034.77 | R38: 97155.421 | S38: 85010.993 | T38: 74384.619 | U38: 65086.542 | V38: 56950.724 | W38: 49831.884 | X38: 43602.898 | Y38: 38152.536 | Z38: 33383.469 | AA38: 29210.535 | AB38: 25559.218 | AC38: 22364.316 | AD38: 19568.777 | AE38: 17122.679 | AF38: 14982.345 | AG38: 13109.551 | AH38: 11470.858
F39: 2021 | G39: 448000 | H39: 429825.13 | J39: 0 | K39: 56000 | L39: 49000 | M39: 42875 | N39: 37515.625 | O39: 32826.172 | P39: 28722.9 | Q39: 25132.538 | R39: 21990.971 | S39: 19242.099 | T39: 16836.837 | U39: 14732.232 | V39: 12890.703 | W39: 11279.365 | X39: 9869.4447 | Y39: 8635.7641 | Z39: 7556.2936 | AA39: 6611.7569 | AB39: 5785.2873 | AC39: 5062.1264 | AD39: 4429.3606 | AE39: 3875.6905 | AF39: 3391.2292 | AG39: 2967.3255 | AH39: 2596.4098
F40: 2022 | G40: 1553000 | H40: 1480996 | J40: 0 | K40: 0 | L40: 194125 | M40: 169859.38 | N40: 148626.95 | O40: 130048.58 | P40: 113792.51 | Q40: 99568.447 | R40: 87122.391 | S40: 76232.092 | T40: 66703.081 | U40: 58365.196 | V40: 51069.546 | W40: 44685.853 | X40: 39100.121 | Y40: 34212.606 | Z40: 29936.03 | AA40: 26194.027 | AB40: 22919.773 | AC40: 20054.802 | AD40: 17547.951 | AE40: 15354.457 | AF40: 13435.15 | AG40: 11755.757 | AH40: 10286.287
F41: 2023 | G41: 378000 | H41: 357970.55 | J41: 0 | K41: 0 | L41: 0 | M41: 47250 | N41: 41343.75 | O41: 36175.781 | P41: 31653.809 | Q41: 27697.083 | R41: 24234.947 | S41: 21205.579 | T41: 18554.881 | U41: 16235.521 | V41: 14206.081 | W41: 12430.321 | X41: 10876.531 | Y41: 9516.9645 | Z41: 8327.3439 | AA41: 7286.4259 | AB41: 6375.6227 | AC41: 5578.6699 | AD41: 4881.3361 | AE41: 4271.1691 | AF41: 3737.273 | AG41: 3270.1139 | AH41: 2861.3496
F42: 2024 | G42: 1606000 | H42: 1508744.4 | J42: 0 | K42: 0 | L42: 0 | M42: 0 | N42: 200750 | O42: 175656.25 | P42: 153699.22 | Q42: 134486.82 | R42: 117675.96 | S42: 102966.47 | T42: 90095.66 | U42: 78833.703 | V42: 68979.49 | W42: 60357.054 | X42: 52812.422 | Y42: 46210.869 | Z42: 40434.511 | AA42: 35380.197 | AB42: 30957.672 | AC42: 27087.963 | AD42: 23701.968 | AE42: 20739.222 | AF42: 18146.819 | AG42: 15878.467 | AH42: 13893.658
F43: 2025 | G43: 1679000 | H43: 1562798.5 | J43: 0 | K43: 0 | L43: 0 | M43: 0 | N43: 0 | O43: 209875 | P43: 183640.62 | Q43: 160685.55 | R43: 140599.85 | S43: 123024.87 | T43: 107646.76 | U43: 94190.917 | V43: 82417.053 | W43: 72114.921 | X43: 63100.556 | Y43: 55212.987 | Z43: 48311.363 | AA43: 42272.443 | AB43: 36988.387 | AC43: 32364.839 | AD43: 28319.234 | AE43: 24779.33 | AF43: 21681.914 | AG43: 18971.674 | AH43: 16600.215
F44: 2026 | G44: 1395000 | H44: 1284661.5 | J44: 0 | K44: 0 | L44: 0 | M44: 0 | N44: 0 | O44: 0 | P44: 174375 | Q44: 152578.12 | R44: 133505.86 | S44: 116817.63 | T44: 102215.42 | U44: 89438.496 | V44: 78258.684 | W44: 68476.348 | X44: 59916.805 | Y44: 52427.204 | Z44: 45873.804 | AA44: 40139.578 | AB44: 35122.131 | AC44: 30731.865 | AD44: 26890.381 | AE44: 23529.084 | AF44: 20587.948 | AG44: 18014.455 | AH44: 15762.648
F45: 2027 | G45: 85000 | H45: 77316.415 | J45: 0 | K45: 0 | L45: 0 | M45: 0 | N45: 0 | O45: 0 | P45: 0 | Q45: 10625 | R45: 9296.875 | S45: 8134.7656 | T45: 7117.9199 | U45: 6228.1799 | V45: 5449.6574 | W45: 4768.4503 | X45: 4172.394 | Y45: 3650.8447 | Z45: 3194.4891 | AA45: 2795.178 | AB45: 2445.7807 | AC45: 2140.0582 | AD45: 1872.5509 | AE45: 1638.482 | AF45: 1433.6718 | AG45: 1254.4628 | AH45: 1097.6549
F46: 2028 | H46: 0 | J46: 0 | K46: 0 | L46: 0 | M46: 0 | N46: 0 | O46: 0 | P46: 0 | Q46: 0 | R46: 0 | S46: 0 | T46: 0 | U46: 0 | V46: 0 | W46: 0 | X46: 0 | Y46: 0 | Z46: 0 | AA46: 0 | AB46: 0 | AC46: 0 | AD46: 0 | AE46: 0 | AF46: 0 | AG46: 0 | AH46: 0
F47: 2029 | G47: 571000 | H47: 503583.69 | J47: 0 | K47: 0 | L47: 0 | M47: 0 | N47: 0 | O47: 0 | P47: 0 | Q47: 0 | R47: 0 | S47: 71375 | T47: 62453.125 | U47: 54646.484 | V47: 47815.674 | W47: 41838.715 | X47: 36608.875 | Y47: 32032.766 | Z47: 28028.67 | AA47: 24525.086 | AB47: 21459.451 | AC47: 18777.019 | AD47: 16429.892 | AE47: 14376.155 | AF47: 12579.136 | AG47: 11006.744 | AH47: 9630.901
...

Sheet Time
A1: {=company} -> Big Dog Construction
A2: {=topic} -> CFM Topic: CAPEX and Depreciation
A3: TIME SCHEDULE | F3: Constant | G3: Unit | H3: Total | J3: {=EOMONTH( start_date, _xlfn.SEQUENCE( 1, periods, 0, 12 ) )} -> 43861 | K3: 44227 | L3: 44592 | M3: 44957 | N3: 45322 | O3: 45688 | P3: 46053 | Q3: 46418 | R3: 46783 | S3: 47149 | T3: 47514 | U3: 47879 | V3: 48244 | W3: 48610 | X3: 48975 | Y3: 49340 | Z3: 49705 | AA3: 50071 | AB3: 50436 | AC3: 50801 | AD3: 51166 | AE3: 51532 | AF3: 51897 | AG3: 52262 | AH3: 52627
B5: Model timeline and flags
E7: Model timeline | G7: date | J7: {=EOMONTH( start_date, _xlfn.SEQUENCE( 1, periods, 0, 12 ) )} -> 43861 | K7: 44227 | L7: 44592 | M7: 44957 | N7: 45322 | O7: 45688 | P7: 46053 | Q7: 46418 | R7: 46783 | S7: 47149 | T7: 47514 | U7: 47879 | V7: 48244 | W7: 48610 | X7: 48975 | Y7: 49340 | Z7: 49705 | AA7: 50071 | AB7: 50436 | AC7: 50801 | AD7: 51166 | AE7: 51532 | AF7: 51897 | AG7: 52262 | AH7: 52627

Sheet Tmp
A1: {=company} -> Big Dog Construction
A2: {=topic} -> CFM Topic: CAPEX and Depreciation
A3: TMP SCHEDULE | F3: Constant | G3: Unit | H3: Total | J3: {=EOMONTH( start_date, _xlfn.SEQUENCE( 1, periods, 0, 12 ) )} -> 43861 | K3: 44227 | L3: 44592 | M3: 44957 | N3: 45322 | O3: 45688 | P3: 46053 | Q3: 46418 | R3: 46783 | S3: 47149 | T3: 47514 | U3: 47879 | V3: 48244 | W3: 48610 | X3: 48975 | Y3: 49340 | Z3: 49705 | AA3: 50071 | AB3: 50436 | AC3: 50801 | AD3: 51166 | AE3: 51532 | AF3: 51897 | AG3: 52262 | AH3: 52627

Sheet CaseData
A1: General Assumptions
C3: Company name | G3: Big Dog Construction
C4: CFM Topic | G4: CAPEX and Depreciation
C6: Model Start Date (do not change) | E6: [date] | G6: 43831
C7: Tax Rate | E7: [%] | G7: 0.3
C8: Discount Rate per Annum | E8: [%] | G8: 0.09
C9: Discount Date for Present Value of Tax Benefits | E9: [date] | G9: =G6-1 -> 43830
C11: Model periods | E11: years | G11: 25
B13: Names of Asset Classes
C14: ListAssetClasses
C15: Short Term
C16: Medium Term
C17: Long Term
B20: Names of Depreciation Methods
C21: ListDepMethods
C22: Declining Balance
C23: Straight Line
C24: Adjusted MACRS
C25: Sum of Years Digits
A28: Depreciation Assumptions
B30: General Depreciation Assumption Data
G31: {=TRANSPOSE(ListAssetClasses)} -> Short Term | H31: Medium Term | I31: Long Term
C32: {=ListDepMethods} -> Declining Balance | E32: Annual % | F32: [%] | G32: 0.4 | H32: 0.25 | I32: 0.125
C33: Straight Line | E33: Useful Life | F33: [years] | G33: 5 | H33: 8 | I33: 16
C34: Adjusted MACRS | D34: (See below) | E34: Class # | F34: [#] | G34: 5 | H34: 8 | I34: 16
C35: Sum of Years Digits | D35: (See below) | E35: Useful Life | F35: [years] | G35: 5 | H35: 8 | I35: 16
B38: =$C$24&" Tables" -> Adjusted MACRS Tables
D39: Class # --> | E39: 5 | F39: =E39+1 -> 6 | G39: =F39+1 -> 7 | H39: =G39+1 -> 8 | I39: =H39+1 -> 9 | J39: =I39+1 -> 10 | K39: =J39+1 -> 11 | L39: =K39+1 -> 12 | M39: =L39+1 -> 13 | ... T39: =S39+1 -> 20
D40: Year
D41: 1 | E41: 0.4 | F41: 0.333 | G41: 0.286 | H41: 0.25 | I41: 0.222 | J41: 0.2 | K41: 0.182 | L41: 0.167 | M41: 0.154 | N41: 0.143 | O41: 0.133 | P41: 0.125 | Q41: 0.118 | R41: 0.111 | S41: 0.105 | T41: 0.1
D42: =D41+1 -> 2 | E42: 0.24 | F42: 0.222 | G42: 0.204 | H42: 0.188 | I42: 0.173 | J42: 0.16 | K42: 0.149 | L42: 0.139 | M42: 0.13 | N42: 0.122 | O42: 0.116 | P42: 0.109 | Q42: 0.104 | R42: 0.099 | S42: 0.094 | T42: 0.09
D43: =D42+1 -> 3 | E43: 0.144 | F43: 0.148 | G43: 0.146 | H43: 0.141 | I43: 0.134 | J43: 0.128 | K43: 0.122 | L43: 0.116 | M43: 0.11 | N43: 0.105 | O43: 0.1 | P43: 0.096 | Q43: 0.092 | R43: 0.088 | S43: 0.084 | T43: 0.081
D44: =D43+1 -> 4 | E44: 0.108 | F44: 0.099 | G44: 0.104 | H44: 0.105 | I44: 0.105 | J44: 0.102 | K44: 0.1 | L44: 0.096 | M44: 0.093 | N44: 0.09 | O44: 0.087 | P44: 0.084 | Q44: 0.081 | R44: 0.078 | S44: 0.075 | T44: 0.073
D45: =D44+1 -> 5 | E45: 0.108 | F45: 0.099 | G45: 0.087 | H45: 0.079 | I45: 0.081 | J45: 0.082 | K45: 0.081 | L45: 0.08 | M45: 0.079 | N45: 0.077 | O45: 0.075 | P45: 0.073 | Q45: 0.071 | R45: 0.069 | S45: 0.067 | T45: 0.066
D46: =D45+1 -> 6 | E46: 0 | F46: 0.099 | G46: 0.087 | H46: 0.079 | I46: 0.071 | J46: 0.066 | K46: 0.067 | L46: 0.067 | M46: 0.067 | N46: 0.066 | O46: 0.065 | P46: 0.064 | Q46: 0.063 | R46: 0.062 | S46: 0.06 | T46: 0.059
D47: =D46+1 -> 7 | E47: 0 | F47: 0 | G47: 0.086 | H47: 0.079 | I47: 0.071 | J47: 0.066 | K47: 0.06 | L47: 0.056 | M47: 0.056 | N47: 0.057 | O47: 0.057 | P47: 0.056 | Q47: 0.056 | R47: 0.055 | S47: 0.054 | T47: 0.053
D48: =D47+1 -> 8 | E48: 0 | F48: 0 | G48: 0 | H48: 0.079 | I48: 0.071 | J48: 0.066 | K48: 0.06 | L48: 0.056 | M48: 0.052 | N48: 0.049 | O48: 0.049 | P48: 0.049 | Q48: 0.049 | R48: 0.049 | S48: 0.048 | T48: 0.048
D49: =D48+1 -> 9 | E49: 0 | F49: 0 | G49: 0 | H49: 0 | I49: 0.072 | J49: 0.066 | K49: 0.06 | L49: 0.056 | M49: 0.052 | N49: 0.049 | O49: 0.045 | P49: 0.043 | Q49: 0.043 | R49: 0.043 | S49: 0.043 | T49: 0.043
D50: =D49+1 -> 10 | E50: 0 | F50: 0 | G50: 0 | H50: 0 | I50: 0 | J50: 0.064 | K50: 0.06 | L50: 0.056 | M50: 0.052 | N50: 0.049 | O50: 0.045 | P50: 0.043 | Q50: 0.041 | R50: 0.038 | S50: 0.039 | T50: 0.039
D51: =D50+1 -> 11 | E51: 0 | F51: 0 | G51: 0 | H51: 0 | I51: 0 | J51: 0 | K51: 0.059 | L51: 0.056 | M51: 0.052 | N51: 0.049 | O51: 0.045 | P51: 0.043 | Q51: 0.041 | R51: 0.038 | S51: 0.037 | T51: 0.035
...
