Workbook
Name company: CaseData!$G$3
Name ListAssetClasses1: CaseData!$C$15:$C$17
Name ListDepMethods1: CaseData!$C$22:$C$25
Name periods: CaseData!$G$5
Name selector: Answers!$F$5
Name start_date: CaseData!$G$7
Name topic: "CFM Topic: " & CaseData!$G$4

Sheet Answers
A1: =company -> Mineral to Rock
A2: {=topic} -> CFM Topic: CAPEX and depreciation
A3: ANSWERS SCHEDULE | J3: {=EOMONTH( start_date, _xlfn.SEQUENCE( 1, periods, 0, 12 ) )} -> 44592 | K3: 44957 | L3: 45322 | M3: 45688 | N3: 46053 | O3: 46418 | P3: 46783 | Q3: 47149 | R3: 47514 | S3: 47879 | T3: 48244 | U3: 48610 | V3: 48975 | W3: 49340 | X3: 49705 | Y3: 50071 | Z3: 50436 | AA3: 50801 | AB3: 51166 | AC3: 51532 | AD3: 51897 | AE3: 52262 | AF3: 52627 | AG3: 52993 | AH3: 53358
E5: Depreciation method | F5: 1
B7: Long Term assets
E9: Long Term assets opening balance | G9: USD m | J9: {=_xlfn.DROP( _xlfn.HSTACK( 0,_xlfn.ANCHORARRAY( J12) ),, -1 )} -> 0 | K9: 2909497.5 | L9: 3074760.4 | M9: 4641580.1 | N9: 4479504.3 | O9: 5925507.4 | P9: 7266573.8 | Q9: 8060074 | R9: 7065255.4 | S9: 6111284.6 | T9: 6034858.1 | U9: 6313316.9 | V9: 6727876.9 | W9: 6352790.3 | X9: 7831386.8 | Y9: 8355807.5 | Z9: 8866503.9 | AA9: 9063715.8 | AB9: 9201930.9 | AC9: 8454862.6 | AD9: 7893035.7 | AE9: 8423089.1 | AF9: 8630777 | AG9: 8186630.4 | AH9: 8799717.1
E10: CAPEX | G10: USD m | J10: {=IF( _xlfn.DROP( TRANSPOSE( INDEX(_xlfn.ANCHORARRAY( Calculations!$E$8),, 2 ) ), , 1 ) = "", 0, _xlfn.DROP( TRANSPOSE( INDEX(_xlfn.ANCHORARRAY( Calculations!E8),, 2 ) ), , 1 ) )} -> 3393000 | K10: 672000 | L10: 2329500 | M10: 567000 | N10: 2409000 | O10: 2518500 | P10: 2092500 | Q10: 127500 | R10: 0 | S10: 856500 | T10: 1249500 | U10: 1446000 | V10: 585000 | W10: 2676000 | X10: 1798500 | Y10: 1858500 | Z10: 1566000 | AA10: 1518000 | AB10: 496500 | AC10: 577500 | AD10: 1747500 | AE10: 1449000 | AF10: 712500 | AG10: 1861500 | AH10: 2253000
E11: Depreciation | G11: USD m | J11: {=_xlfn.LET( _xlpm.depreciation_method, selector, _xlpm.declining_balance,_xlfn.ANCHORARRAY( Calculations!J65), _xlpm.straight_line,_xlfn.ANCHORARRAY( Calculations!J94), _xlpm.units_of_production,_xlfn.ANCHORARRAY( Calculations!J123), _xlpm.sum_of_digits,_xlfn.ANCHORARRAY( Calculations!J152), CHOOSE( selector, _xlpm.declining_balance, _xlpm.straight_line, _xlpm.units_of_production, _xlpm.sum_of_digits ) ) * - 1} -> -483502.5 | K11: -506737.12 | L11: -762680.31 | M11: -729075.76 | N11: -962996.9 | O11: -1177433.6 | P11: -1298999.8 | Q11: -1122318.6 | R11: -953970.81 | S11: -932926.44 | T11: -971041.22 | U11: -1031440 | V11: -960086.53 | W11: -1197403.6 | X11: -1274079.3 | Y11: -1347803.6 | Z11: -1368788.1 | AA11: -1379784.9 | AB11: -1243568.4 | AC11: -1139326.9 | AD11: -1217446.6 | AE11: -1241312.1 | AF11: -1156646.5 | AG11: -1248413.3 | AH11: -1382203.8
E12: Long Term assets closing balance | G12: USD m | J12: {=_xlfn.LET( _xlpm.opening_balance, 0, _xlpm.mouvements,_xlfn.ANCHORARRAY( J10) +_xlfn.ANCHORARRAY( J11), _xlfn.SCAN( _xlpm.opening_balance, _xlpm.mouvements, _xleta.SUM ) )} -> 2909497.5 | K12: 3074760.4 | L12: 4641580.1 | M12: 4479504.3 | N12: 5925507.4 | O12: 7266573.8 | P12: 8060074 | Q12: 7065255.4 | R12: 6111284.6 | S12: 6034858.1 | T12: 6313316.9 | U12: 6727876.9 | V12: 6352790.3 | W12: 7831386.8 | X12: 8355807.5 | Y12: 8866503.9 | Z12: 9063715.8 | AA12: 9201930.9 | AB12: 8454862.6 | AC12: 7893035.7 | AD12: 8423089.1 | AE12: 8630777 | AF12: 8186630.4 | AG12: 8799717.1 | AH12: 9670513.3
B14: Medium Term assets
E16: Medium Term assets opening balance | G16: USD m | J16: {=_xlfn.DROP( _xlfn.HSTACK( 0,_xlfn.ANCHORARRAY( J19) ),, -1 )} -> 0 | K16: 2260861.9 | L16: 2441429.2 | M16: 2752342.6 | N16: 2898868 | O16: 3021438.4 | P16: 4522986 | Q16: 3768513.5 | R16: 4293508.6 | S16: 5002732.9 | T16: 5396486.8 | U16: 7032753.5 | V16: 6111428.3 | W16: 6054947 | X16: 6143777.6 | Y16: 7045085.8 | Z16: 6002534.6 | AA16: 7550078.7 | AB16: 6646356 | AC16: 6173382.1 | AD16: 6838189.9 | AE16: 7227093.4 | AF16: 7593428.7 | AG16: 8038410.3 | AH16: 7688911.8
E17: CAPEX | G17: USD m | J17: {=IF( _xlfn.DROP( TRANSPOSE( INDEX(_xlfn.ANCHORARRAY( Calculations!$E$8),, 3 ) ), , 1 ) = "", 0, _xlfn.DROP( TRANSPOSE( INDEX(_xlfn.ANCHORARRAY( Calculations!$E$8),,3 ) ), , 1 ) )} -> 2875500 | K17: 835500 | L17: 1041000 | M17: 906000 | N17: 904500 | O17: 2680500 | P17: 202500 | Q17: 1611000 | R17: 1972500 | S17: 1746000 | T17: 3414000 | U17: 580500 | V17: 1408500 | W17: 1557000 | X17: 2593500 | Y17: 342000 | Z17: 3333000 | AA17: 610500 | AB17: 891000 | AC17: 2190000 | AD17: 1998000 | AE17: 2052000 | AF17: 2227500 | AG17: 1312500 | AH17: 2460000
E18: Depreciation | G18: USD m | J18: {=_xlfn.LET( _xlpm.depreciation_method, selector, _xlpm.declining_balance,_xlfn.ANCHORARRAY( Calculations!$J184), _xlpm.straight_line,_xlfn.ANCHORARRAY( Calculations!$J213), _xlpm.units_of_production,_xlfn.ANCHORARRAY( Calculations!$J242), _xlpm.sum_of_digits,_xlfn.ANCHORARRAY( Calculations!$J271), CHOOSE( selector, _xlpm.declining_balance, _xlpm.straight_line, _xlpm.units_of_production, _xlpm.sum_of_digits ) ) * - 1} -> -614638.12 | K18: -654932.67 | L18: -730086.57 | M18: -759474.59 | N18: -781929.68 | O18: -1178952.4 | P18: -956972.47 | Q18: -1086004.9 | R18: -1263275.7 | S18: -1352246.2 | T18: -1777733.3 | U18: -1501825.2 | V18: -1464981.4 | W18: -1468169.3 | X18: -1692191.8 | Y18: -1384551.2 | Z18: -1785455.9 | AA18: -1514222.7 | AB18: -1363973.8 | AC18: -1525192.2 | AD18: -1609096.5 | AE18: -1685664.8 | AF18: -1782518.3 | AG18: -1661998.6 | AH18: -1813873.9
E19: Medium Term assets closing balance | G19: USD m | J19: {=_xlfn.LET( _xlpm.opening_balance, 0, _xlpm.mouvements,_xlfn.ANCHORARRAY( J17) +_xlfn.ANCHORARRAY( J18), _xlfn.SCAN( _xlpm.opening_balance, _xlpm.mouvements, _xleta.SUM ) )} -> 2260861.9 | K19: 2441429.2 | L19: 2752342.6 | M19: 2898868 | N19: 3021438.4 | O19: 4522986 | P19: 3768513.5 | Q19: 4293508.6 | R19: 5002732.9 | S19: 5396486.8 | T19: 7032753.5 | U19: 6111428.3 | V19: 6054947 | W19: 6143777.6 | X19: 7045085.8 | Y19: 6002534.6 | Z19: 7550078.7 | AA19: 6646356 | AB19: 6173382.1 | AC19: 6838189.9 | AD19: 7227093.4 | AE19: 7593428.7 | AF19: 8038410.3 | AG19: 7688911.8 | AH19: 8335037.9
B21: Short Term assets
E23: Short Term assets opening balance | G23: USD m | J23: {=_xlfn.DROP( _xlfn.HSTACK( 0,_xlfn.ANCHORARRAY( J26) ),, -1 )} -> 0 | K23: 1559490 | L23: 1094194.5 | M23: 1204983.2 | N23: 2203229.5 | O23: 2087093.7 | P23: 2319802.8 | Q23: 2188131.5 | R23: 1610726.1 | S23: 1769403.1 | T23: 2588401.7 | U23: 2602973.4 | V23: 3033549.1 | W23: 2698325.8 | X23: 2705844.2 | Y23: 2960835.5 | Z23: 2432268.3 | AA23: 3265450.1 | AB23: 2940220 | AC23: 3501803.5 | AD23: 3630430.7 | AE23: 3479220.6 | AF23: 3806942.6 | AG23: 3902897.2 | AH23: 3473800.9
E24: CAPEX | G24: USD m | J24: {=IF( _xlfn.DROP( TRANSPOSE( INDEX(_xlfn.ANCHORARRAY( Calculations!$E$8),, 4 ) ), , 1 ) = "", 0, _xlfn.DROP( TRANSPOSE( INDEX(_xlfn.ANCHORARRAY( Calculations!$E$8),, 4 ) ), , 1 ) )} -> 2724000 | K24: 306000 | L24: 934500 | M24: 2535000 | N24: 1273500 | O24: 1741500 | P24: 1219500 | Q24: 289500 | R24: 1110000 | S24: 2344500 | T24: 1491000 | U24: 2170500 | V24: 1086000 | W24: 1378500 | X24: 1762500 | Y24: 525000 | Z24: 2467500 | AA24: 1002000 | AB24: 2256000 | AC24: 1852500 | AD24: 1392000 | AE24: 2055000 | AF24: 1827000 | AG24: 913500 | AH24: 1356000
E25: Depreciation | G25: USD m | J25: {=_xlfn.LET( _xlpm.depreciation_method, selector, _xlpm.declining_balance,_xlfn.ANCHORARRAY( Calculations!J303), _xlpm.straight_line,_xlfn.ANCHORARRAY( Calculations!J332), _xlpm.units_of_production,_xlfn.ANCHORARRAY( Calculations!J361), _xlpm.sum_of_digits,_xlfn.ANCHORARRAY( Calculations!J390), CHOOSE( selector, _xlpm.declining_balance, _xlpm.straight_line, _xlpm.units_of_production, _xlpm.sum_of_digits ) ) * - 1} -> -1164510 | K25: -771295.5 | L25: -823711.28 | M25: -1536753.7 | N25: -1389635.8 | O25: -1508790.9 | P25: -1351171.3 | Q25: -866905.44 | R25: -951322.99 | S25: -1525501.4 | T25: -1476428.3 | U25: -1739924.3 | V25: -1421223.4 | W25: -1370981.6 | X25: -1507508.6 | Y25: -1053567.2 | Z25: -1634318.2 | AA25: -1327230 | AB25: -1694416.5 | AC25: -1723872.8 | AD25: -1543210.1 | AE25: -1727278 | AF25: -1731045.4 | AG25: -1342596.2 | AH25: -1318117.9
E26: Short Term assets closing balance | G26: USD m | J26: {=_xlfn.LET( _xlpm.opening_balance, 0, _xlpm.mouvements,_xlfn.ANCHORARRAY( J24) +_xlfn.ANCHORARRAY( J25), _xlfn.SCAN( _xlpm.opening_balance, _xlpm.mouvements, _xleta.SUM ) )} -> 1559490 | K26: 1094194.5 | L26: 1204983.2 | M26: 2203229.5 | N26: 2087093.7 | O26: 2319802.8 | P26: 2188131.5 | Q26: 1610726.1 | R26: 1769403.1 | S26: 2588401.7 | T26: 2602973.4 | U26: 3033549.1 | V26: 2698325.8 | W26: 2705844.2 | X26: 2960835.5 | Y26: 2432268.3 | Z26: 3265450.1 | AA26: 2940220 | AB26: 3501803.5 | AC26: 3630430.7 | AD26: 3479220.6 | AE26: 3806942.6 | AF26: 3902897.2 | AG26: 3473800.9 | AH26: 3511683
B28: Assets Schedule
E30: Assets opening balance | G30: USD m | J30: {=_xlfn.ANCHORARRAY( J9) +_xlfn.ANCHORARRAY( J16) +_xlfn.ANCHORARRAY( J23)} -> 0 | K30: 6729849.4 | L30: 6610384.1 | M30: 8598905.9 | N30: 9581601.9 | O30: 11034040 | P30: 14109363 | Q30: 14016719 | R30: 12969490 | S30: 12883421 | T30: 14019747 | U30: 15949044 | V30: 15872854 | W30: 15106063 | X30: 16681009 | Y30: 18361729 | Z30: 17301307 | AA30: 19879245 | AB30: 18788507 | AC30: 18130048 | AD30: 18361656 | AE30: 19129403 | AF30: 20031148 | AG30: 20127938 | AH30: 19962430
E31: CAPEX | G31: USD m | J31: {=_xlfn.ANCHORARRAY( J10) +_xlfn.ANCHORARRAY( J17) +_xlfn.ANCHORARRAY( J24)} -> 8992500 | K31: 1813500 | L31: 4305000 | M31: 4008000 | N31: 4587000 | O31: 6940500 | P31: 3514500 | Q31: 2028000 | R31: 3082500 | S31: 4947000 | T31: 6154500 | U31: 4197000 | V31: 3079500 | W31: 5611500 | X31: 6154500 | Y31: 2725500 | Z31: 7366500 | AA31: 3130500 | AB31: 3643500 | AC31: 4620000 | AD31: 5137500 | AE31: 5556000 | AF31: 4767000 | AG31: 4087500 | AH31: 6069000
E32: Depreciation | G32: USD m | J32: {=_xlfn.ANCHORARRAY( J11) +_xlfn.ANCHORARRAY( J18) +_xlfn.ANCHORARRAY( J25)} -> -2262650.6 | K32: -1932965.3 | L32: -2316478.2 | M32: -3025304.1 | N32: -3134562.4 | O32: -3865176.9 | P32: -3607143.6 | Q32: -3075229 | R32: -3168569.5 | S32: -3810674 | T32: -4225202.8 | U32: -4273189.5 | V32: -3846291.3 | W32: -4036554.5 | X32: -4473779.7 | Y32: -3785922.1 | Z32: -4788562.2 | AA32: -4221237.6 | AB32: -4301958.8 | AC32: -4388391.9 | AD32: -4369753.1 | AE32: -4654254.9 | AF32: -4670210.3 | AG32: -4253008.1 | AH32: -4514195.6
E33: Assets closing balance | G33: USD m | J33: {=_xlfn.BYCOL(_xlfn.ANCHORARRAY( J30) +_xlfn.ANCHORARRAY( J31) +_xlfn.ANCHORARRAY( J32), _xleta.SUM )} -> 6729849.4 | K33: 6610384.1 | L33: 8598905.9 | M33: 9581601.9 | N33: 11034040 | O33: 14109363 | P33: 14016719 | Q33: 12969490 | R33: 12883421 | S33: 14019747 | T33: 15949044 | U33: 15872854 | V33: 15106063 | W33: 16681009 | X33: 18361729 | Y33: 17301307 | Z33: 19879245 | AA33: 18788507 | AB33: 18130048 | AC33: 18361656 | AD33: 19129403 | AE33: 20031148 | AF33: 20127938 | AG33: 19962430 | AH33: 21517234
B35: Tax deduction
E37: Depreciation | G37: USD m | J37: {=_xlfn.ANCHORARRAY( J32) * -1} -> 2262650.6 | K37: 1932965.3 | L37: 2316478.2 | M37: 3025304.1 | N37: 3134562.4 | O37: 3865176.9 | P37: 3607143.6 | Q37: 3075229 | R37: 3168569.5 | S37: 3810674 | T37: 4225202.8 | U37: 4273189.5 | V37: 3846291.3 | W37: 4036554.5 | X37: 4473779.7 | Y37: 3785922.1 | Z37: 4788562.2 | AA37: 4221237.6 | AB37: 4301958.8 | AC37: 4388391.9 | AD37: 4369753.1 | AE37: 4654254.9 | AF37: 4670210.3 | AG37: 4253008.1 | AH37: 4514195.6
E38: Tax deduction | G38: USD m | J38: {=_xlfn.LET( _xlpm.tax_rate, CaseData!$G$8, _xlpm.depreciation,_xlfn.ANCHORARRAY( Answers!$J$37), _xlpm.depreciation * _xlpm.tax_rate )} -> 565662.66 | K38: 483241.32 | L38: 579119.54 | M38: 756326.01 | N38: 783640.59 | O38: 966294.23 | P38: 901785.89 | Q38: 768807.24 | R38: 792142.37 | S38: 952668.5 | T38: 1056300.7 | U38: 1068297.4 | V38: 961572.82 | W38: 1009138.6 | X38: 1118444.9 | Y38: 946480.51 | Z38: 1197140.6 | AA38: 1055309.4 | AB38: 1075489.7 | AC38: 1097098 | AD38: 1092438.3 | AE38: 1163563.7 | AF38: 1167552.6 | AG38: 1063252 | AH38: 1128548.9
E40: NPV | G40: USD m | H40: =_xlfn.LET( _xlpm.discount_rate, CaseData!$G$9, _xlpm.tax_deduction,_xlfn.ANCHORARRAY( Answers!J38), NPV( _xlpm.discount_rate, _xlpm.tax_deduction ) ) -> 7549234.7
E41: XNPV | G41: USD m | H41: =_xlfn.LET( _xlpm.discount_rate, CaseData!$G$9, _xlpm.tax_deduction,_xlfn.ANCHORARRAY( Answers!J38), XNPV( _xlpm.discount_rate, _xlpm.tax_deduction,_xlfn.ANCHORARRAY( J3) ) ) -> 8299633.5
J43: NPV | K43: XNPV
H44: Declining Balance | J44: =_xlfn.LET( _xlpm.discount_rate, CaseData!$G$9, _xlpm.tax_deduction,_xlfn.ANCHORARRAY( Answers!J38), NPV( _xlpm.discount_rate, _xlpm.tax_deduction ) ) -> 7549234.7 | K44: =H41 -> 8299633.5
H45: {=ListDepMethods1} -> Declining Balance | I45: 1 | J45: 7549234.7 | K45: 8299633.5
H46: Straight Line | I46: 2 | J46: 6602901 | K46: 7258752.7
H47: Units of Production | I47: 3 | J47: 7445364 | K47: 8185326.5
H48: Sum of Years Digits | I48: 4 | J48: 7602001.9 | K48: 8357542.9

Sheet Calculations
A1: =company -> Mineral to Rock
A2: {=topic} -> CFM Topic: CAPEX and depreciation
A3: CALCULATION SCHEDULE | J3: {=EOMONTH( start_date, _xlfn.SEQUENCE( 1, periods, 0, 12 ) )} -> 44592 | K3: 44957 | L3: 45322 | M3: 45688 | N3: 46053 | O3: 46418 | P3: 46783 | Q3: 47149 | R3: 47514 | S3: 47879 | T3: 48244 | U3: 48610 | V3: 48975 | W3: 49340 | X3: 49705 | Y3: 50071 | Z3: 50436 | AA3: 50801 | AB3: 51166 | AC3: 51532 | AD3: 51897 | AE3: 52262 | AF3: 52627 | AG3: 52993 | AH3: 53358
B5: CAPEX
D7: Capital investments | K7: Salvage value
E8: {=_xlfn.PIVOTBY( YEAR( CaseData!$D$138:$D$437 ), CaseData!$F$138:$F$437, CaseData!$E$138:$E$437, _xleta.SUM,,0,,0 )} | F8: Long Term | G8: Medium Term | H8: Short Term | K8: {=_xlfn.LET( _xlpm.capex, _xlfn.DROP( _xlfn.CHOOSECOLS(_xlfn.ANCHORARRAY(E8), {2,3,4} ), 1 ), _xlpm.years, _xlfn.DROP( INDEX(_xlfn.ANCHORARRAY( E8),, 1 ), 1 ), _xlpm.residual_rate, CaseData!$G$11, IFERROR( _xlfn.VSTACK( _xlfn.HSTACK("", "Long Term", "Medium Term", "Short Term" ), _xlfn.HSTACK( _xlpm.years, _xlpm.capex * _xlpm.residual_rate ) ), 0 ) )} | L8: Long Term | M8: Medium Term | N8: Short Term
E9: 2022 | F9: 3393000 | G9: 2875500 | H9: 2724000 | K9: 2022 | L9: 169650 | M9: 143775 | N9: 136200
E10: 2023 | F10: 672000 | G10: 835500 | H10: 306000 | K10: 2023 | L10: 33600 | M10: 41775 | N10: 15300
E11: 2024 | F11: 2329500 | G11: 1041000 | H11: 934500 | K11: 2024 | L11: 116475 | M11: 52050 | N11: 46725
E12: 2025 | F12: 567000 | G12: 906000 | H12: 2535000 | K12: 2025 | L12: 28350 | M12: 45300 | N12: 126750
E13: 2026 | F13: 2409000 | G13: 904500 | H13: 1273500 | K13: 2026 | L13: 120450 | M13: 45225 | N13: 63675
E14: 2027 | F14: 2518500 | G14: 2680500 | H14: 1741500 | K14: 2027 | L14: 125925 | M14: 134025 | N14: 87075
E15: 2028 | F15: 2092500 | G15: 202500 | H15: 1219500 | K15: 2028 | L15: 104625 | M15: 10125 | N15: 60975
E16: 2029 | F16: 127500 | G16: 1611000 | H16: 289500 | K16: 2029 | L16: 6375 | M16: 80550 | N16: 14475
E17: 2030 | G17: 1972500 | H17: 1110000 | K17: 2030 | L17: 0 | M17: 98625 | N17: 55500
E18: 2031 | F18: 856500 | G18: 1746000 | H18: 2344500 | K18: 2031 | L18: 42825 | M18: 87300 | N18: 117225
E19: 2032 | F19: 1249500 | G19: 3414000 | H19: 1491000 | K19: 2032 | L19: 62475 | M19: 170700 | N19: 74550
E20: 2033 | F20: 1446000 | G20: 580500 | H20: 2170500 | K20: 2033 | L20: 72300 | M20: 29025 | N20: 108525
E21: 2034 | F21: 585000 | G21: 1408500 | H21: 1086000 | K21: 2034 | L21: 29250 | M21: 70425 | N21: 54300
E22: 2035 | F22: 2676000 | G22: 1557000 | H22: 1378500 | K22: 2035 | L22: 133800 | M22: 77850 | N22: 68925
E23: 2036 | F23: 1798500 | G23: 2593500 | H23: 1762500 | K23: 2036 | L23: 89925 | M23: 129675 | N23: 88125
E24: 2037 | F24: 1858500 | G24: 342000 | H24: 525000 | K24: 2037 | L24: 92925 | M24: 17100 | N24: 26250
E25: 2038 | F25: 1566000 | G25: 3333000 | H25: 2467500 | K25: 2038 | L25: 78300 | M25: 166650 | N25: 123375
E26: 2039 | F26: 1518000 | G26: 610500 | H26: 1002000 | K26: 2039 | L26: 75900 | M26: 30525 | N26: 50100
E27: 2040 | F27: 496500 | G27: 891000 | H27: 2256000 | K27: 2040 | L27: 24825 | M27: 44550 | N27: 112800
E28: 2041 | F28: 577500 | G28: 2190000 | H28: 1852500 | K28: 2041 | L28: 28875 | M28: 109500 | N28: 92625
E29: 2042 | F29: 1747500 | G29: 1998000 | H29: 1392000 | K29: 2042 | L29: 87375 | M29: 99900 | N29: 69600
... E33: 2046 | F33: 2253000 | G33: 2460000 | H33: 1356000 | K33: 2046 | L33: 112650 | M33: 123000 | N33: 67800
B36: Long Term assets
C38: Declining balance
F39: Date | G39: Cost | J39: {=_xlfn.ANCHORARRAY(J3)} -> 44592 | K39: 44957 | L39: 45322 | M39: 45688 | N39: 46053 | O39: 46418 | P39: 46783 | Q39: 47149 | R39: 47514 | S39: 47879 | T39: 48244 | U39: 48610 | V39: 48975 | W39: 49340 | X39: 49705 | Y39: 50071 | Z39: 50436 | AA39: 50801 | AB39: 51166 | AC39: 51532 | AD39: 51897 | AE39: 52262 | AF39: 52627 | AG39: 52993 | AH39: 53358
F40: {=_xlfn.LET( _xlpm.date, INDEX(_xlfn.ANCHORARRAY( $E$8),, 1 ), _xlpm.asset, INDEX(_xlfn.ANCHORARRAY( $E$8),, 2 ), _xlfn.DROP( _xlfn.HSTACK( _xlpm.date, _xlpm.asset ), 1 ) )} -> 2022 | G40: 3393000 | H40: {=_xlfn.BYROW(_xlfn.ANCHORARRAY( J40), _xleta.SUM )} -> 3167915.4 | J40: {=_xlfn.LET( _xlpm.acquisition_date, INDEX(_xlfn.ANCHORARRAY( $F40),,1 ), _xlpm.acquisition_cost, INDEX(_xlfn.ANCHORARRAY( $F40),,2 ), _xlpm.current_date,_xlfn.ANCHORARRAY( J3), _xlpm.salvage_value, CaseData!$G$11, _xlpm.depreciable_amount, _xlpm.acquisition_cost * ( 1 - _xlpm.salvage_value ), _xlpm.depreciation_rate, CaseData!$I$32, _xlpm.period, YEAR( _xlpm.current_date ) - _xlpm.acquisition_date, _xlpm.book_value, _xlpm.depreciable_amount * ( 1 - _xlpm.depreciation_rate ) ^ _xlpm.period, _xlpm.depreciation, _xlpm.depreciation_rate * _xlpm.book_value, IFERROR( IF( _xlpm.period < 0, 0, IF( _xlpm.period >= 0, _xlpm.depreciation, 0 ) ), 0 ) )} -> 483502.5 | K40: 410977.12 | L40: 349330.56 | M40: 296930.97 | N40: 252391.33 | O40: 214532.63 | P40: 182352.73 | Q40: 154999.82 | R40: 131749.85 | S40: 111987.37 | T40: 95189.267 | U40: 80910.877 | V40: 68774.245 | W40: 58458.108 | X40: 49689.392 | Y40: 42235.983 | Z40: 35900.586 | AA40: 30515.498 | AB40: 25938.173 | AC40: 22047.447 | AD40: 18740.33 | AE40: 15929.281 | AF40: 13539.889 | AG40: 11508.905 | AH40: 9782.5695
F41: 2023 | G41: 672000 | H41: 625483.43 | J41: 0 | K41: 95760 | L41: 81396 | M41: 69186.6 | N41: 58808.61 | O41: 49987.318 | P41: 42489.221 | Q41: 36115.838 | R41: 30698.462 | S41: 26093.693 | T41: 22179.639 | U41: 18852.693 | V41: 16024.789 | W41: 13621.071 | X41: 11577.91 | Y41: 9841.2236 | Z41: 8365.04 | AA41: 7110.284 | AB41: 6043.7414 | AC41: 5137.1802 | AD41: 4366.6032 | AE41: 3711.6127 | AF41: 3154.8708 | AG41: 2681.6402 | AH41: 2279.3941
F42: 2024 | G42: 2329500 | H42: 2160347.9 | J42: 0 | K42: 0 | L42: 331953.75 | M42: 282160.69 | N42: 239836.58 | O42: 203861.1 | P42: 173281.93 | Q42: 147289.64 | R42: 125196.2 | S42: 106416.77 | T42: 90454.252 | U42: 76886.114 | V42: 65353.197 | W42: 55550.217 | X42: 47217.685 | Y42: 40135.032 | Z42: 34114.777 | AA42: 28997.561 | AB42: 24647.927 | AC42: 20950.738 | AD42: 17808.127 | AE42: 15136.908 | AF42: 12866.372 | AG42: 10936.416 | AH42: 9295.9535
F43: 2025 | G43: 567000 | H43: 523565.77 | J43: 0 | K43: 0 | L43: 0 | M43: 80797.5 | N43: 68677.875 | O43: 58376.194 | P43: 49619.765 | Q43: 42176.8 | R43: 35850.28 | S43: 30472.738 | T43: 25901.827 | U43: 22016.553 | V43: 18714.07 | W43: 15906.96 | X43: 13520.916 | Y43: 11492.778 | Z43: 9768.8616 | AA43: 8303.5324 | AB43: 7058.0025 | AC43: 5999.3021 | AD43: 5099.4068 | AE43: 4334.4958 | AF43: 3684.3214 | AG43: 3131.6732 | AH43: 2661.9222
F44: 2026 | G44: 2409000 | H44: 2213152.3 | J44: 0 | K44: 0 | L44: 0 | M44: 0 | N44: 343282.5 | O44: 291790.12 | P44: 248021.61 | Q44: 210818.37 | R44: 179195.61 | S44: 152316.27 | T44: 129468.83 | U44: 110048.5 | V44: 93541.229 | W44: 79510.044 | X44: 67583.538 | Y44: 57446.007 | Z44: 48829.106 | AA44: 41504.74 | AB44: 35279.029 | AC44: 29987.175 | AD44: 25489.099 | AE44: 21665.734 | AF44: 18415.874 | AG44: 15653.493 | AH44: 13305.469
F45: 2027 | G45: 2518500 | H45: 2299839.9 | J45: 0 | K45: 0 | L45: 0 | M45: 0 | N45: 0 | O45: 358886.25 | P45: 305053.31 | Q45: 259295.32 | R45: 220401.02 | S45: 187340.87 | T45: 159239.74 | U45: 135353.78 | V45: 115050.71 | W45: 97793.103 | X45: 83124.137 | Y45: 70655.517 | Z45: 60057.189 | AA45: 51048.611 | AB45: 43391.319 | AC45: 36882.621 | AD45: 31350.228 | AE45: 26647.694 | AF45: 22650.54 | AG45: 19252.959 | AH45: 16365.015
F46: 2028 | G46: 2092500 | H46: 1897229 | J46: 0 | K46: 0 | L46: 0 | M46: 0 | N46: 0 | O46: 0 | P46: 298181.25 | Q46: 253454.06 | R46: 215435.95 | S46: 183120.56 | T46: 155652.48 | U46: 132304.6 | V46: 112458.91 | W46: 95590.077 | X46: 81251.565 | Y46: 69063.831 | Z46: 58704.256 | AA46: 49898.618 | AB46: 42413.825 | AC46: 36051.751 | AD46: 30643.989 | AE46: 26047.39 | AF46: 22140.282 | AG46: 18819.239 | AH46: 15996.354
F47: 2029 | G47: 127500 | H47: 114627.08 | J47: 0 | K47: 0 | L47: 0 | M47: 0 | N47: 0 | O47: 0 | P47: 0 | Q47: 18168.75 | R47: 15443.438 | S47: 13126.922 | T47: 11157.884 | U47: 9484.2011 | V47: 8061.5709 | W47: 6852.3353 | X47: 5824.485 | Y47: 4950.8122 | Z47: 4208.1904 | AA47: 3576.9618 | AB47: 3040.4176 | AC47: 2584.3549 | AD47: 2196.7017 | AE47: 1867.1964 | AF47: 1587.117 | AG47: 1349.0494 | AH47: 1146.692
F48: 2030 | H48: 0 | J48: 0 | K48: 0 | L48: 0 | M48: 0 | N48: 0 | O48: 0 | P48: 0 | Q48: 0 | R48: 0 | S48: 0 | T48: 0 | U48: 0 | V48: 0 | W48: 0 | X48: 0 | Y48: 0 | Z48: 0 | AA48: 0 | AB48: 0 | AC48: 0 | AD48: 0 | AE48: 0 | AF48: 0 | AG48: 0 | AH48: 0
...

Sheet CaseData
A1: General Assumptions
C3: Company name | E3: [label] | G3: Mineral to Rock
C4: CFM Topic | E4: [label] | G4: CAPEX and depreciation
C5: Number of periods | E5: [years] | G5: 25
C7: Model Start Date (do not change) | E7: [date] | G7: 44562
C8: Tax Rate | E8: [%] | G8: 0.25
C9: Discount Rate per Annum | E9: [%] | G9: 0.1
C10: Discount Date for Present Value of Tax Benefits | E10: [date] | G10: =G7-1 -> 44561
C11: Salvage Value (% of CAPEX) | E11: [%] | G11: 0.05
B13: Names of Asset Classes
C14: ListAssetClasses1
C15: Short Term
C16: Medium Term
C17: Long Term
B20: Names of Depreciation Methods
C21: ListDepMethods1
C22: Declining Balance
C23: Straight Line
C24: Units of Production
C25: Sum of Years Digits
A28: Depreciation Assumptions
B30: General Depreciation Assumption Data
G31: {=TRANSPOSE(ListAssetClasses1)} -> Short Term | H31: Medium Term | I31: Long Term
C32: {=ListDepMethods1} -> Declining Balance | E32: Annual % | F32: [%] | G32: 0.45 | H32: 0.225 | I32: 0.15
C33: Straight Line | E33: Useful Life | F33: [years] | G33: 5 | H33: 10 | I33: 15
C34: Units of Production | D34: (See below) | E34: Useful Life | F34: [years] | G34: 5 | H34: 10 | I34: 15
C35: Sum of Years Digits | D35: (See below) | E35: Useful Life | F35: [years] | G35: 5 | H35: 10 | I35: 15
B38: =$C$24&" Tables" -> Units of Production Tables
D39: Total Prod. --> | E39: 1000000 | F39: =$E$39 -> 1000000 | G39: =$E$39 -> 1000000 | H39: =$E$39 -> 1000000 | I39: =$E$39 -> 1000000 | J39: =$E$39 -> 1000000 | K39: =$E$39 -> 1000000 | L39: =$E$39 -> 1000000 | M39: =$E$39 -> 1000000 | ... T39: =$E$39 -> 1000000
D40: Useful Life --> | E40: 5 | F40: =E40+1 -> 6 | G40: =F40+1 -> 7 | H40: =G40+1 -> 8 | I40: =H40+1 -> 9 | J40: =I40+1 -> 10 | K40: =J40+1 -> 11 | L40: =K40+1 -> 12 | M40: =L40+1 -> 13 | ... T40: =S40+1 -> 20
D41: Year
D42: 1 | E42: 400000 | F42: 333000 | G42: 286000 | H42: 250000 | I42: 222000 | J42: 200000 | K42: 182000 | L42: 167000 | M42: 154000 | N42: 143000 | O42: 133000 | P42: 125000 | Q42: 118000 | R42: 111000 | S42: 105000 | T42: 100000
D43: =D42+1 -> 2 | E43: 240000 | F43: 222000 | G43: 204000 | H43: 188000 | I43: 173000 | J43: 160000 | K43: 149000 | L43: 139000 | M43: 130000 | N43: 122000 | O43: 116000 | P43: 109000 | Q43: 104000 | R43: 99000 | S43: 94000 | T43: 90000
D44: =D43+1 -> 3 | E44: 144000 | F44: 148000 | G44: 146000 | H44: 141000 | I44: 134000 | J44: 128000 | K44: 122000 | L44: 116000 | M44: 110000 | N44: 105000 | O44: 100000 | P44: 96000 | Q44: 92000 | R44: 88000 | S44: 84000 | T44: 81000
D45: =D44+1 -> 4 | E45: 108000 | F45: 99000 | G45: 104000 | H45: 105000 | I45: 105000 | J45: 102000 | K45: 100000 | L45: 96000 | M45: 93000 | N45: 90000 | O45: 87000 | P45: 84000 | Q45: 81000 | R45: 78000 | S45: 75000 | T45: 73000
D46: =D45+1 -> 5 | E46: 108000 | F46: 99000 | G46: 87000 | H46: 79000 | I46: 81000 | J46: 82000 | K46: 81000 | L46: 80000 | M46: 79000 | N46: 77000 | O46: 75000 | P46: 73000 | Q46: 71000 | R46: 69000 | S46: 67000 | T46: 66000
D47: =D46+1 -> 6 | E47: 0 | F47: 99000 | G47: 87000 | H47: 79000 | I47: 71000 | J47: 66000 | K47: 67000 | L47: 67000 | M47: 67000 | N47: 66000 | O47: 65000 | P47: 64000 | Q47: 63000 | R47: 62000 | S47: 60000 | T47: 59000
D48: =D47+1 -> 7 | E48: 0 | F48: 0 | G48: 86000 | H48: 79000 | I48: 71000 | J48: 66000 | K48: 60000 | L48: 56000 | M48: 56000 | N48: 57000 | O48: 57000 | P48: 56000 | Q48: 56000 | R48: 55000 | S48: 54000 | T48: 53000
D49: =D48+1 -> 8 | E49: 0 | F49: 0 | G49: 0 | H49: 79000 | I49: 71000 | J49: 66000 | K49: 60000 | L49: 56000 | M49: 52000 | N49: 49000 | O49: 49000 | P49: 49000 | Q49: 49000 | R49: 49000 | S49: 48000 | T49: 48000
D50: =D49+1 -> 9 | E50: 0 | F50: 0 | G50: 0 | H50: 0 | I50: 72000 | J50: 66000 | K50: 60000 | L50: 56000 | M50: 52000 | N50: 49000 | O50: 45000 | P50: 43000 | Q50: 43000 | R50: 43000 | S50: 43000 | T50: 43000
...

Sheet CaseSolution
C2: Case 1 Answers
C3: c) i)Depn MTA, 2027 SL | F3: =K160 -> 878085
C4: ii)Depn STA, 2032 DB | F4: =-P58 -> 1476428.3
C5: iii)Depn LTA, all 25yrs, Units of Production | F5: =SUM(F196:AD196) -> 27255766
C6: iv) Closing Bal, MTA pool, Dec 2041, SYD | F6: =$Y$329 -> 6126199.1
C7: e)
C8: =INDEX(ListDepMethods1,MATCH(F8,$F$41:$F$44,0)) -> Sum of Years Digits | E8: NPV | F8: =MAX(F41:F44) -> 7602001.9
E9: XNPV | F9: =MAX(G41:G44) -> 7597275.7
E10: =CaseData!$G$10 -> 44561 | F10: =DATE(F11,12,31) -> 44926 | G10: =DATE(G11,12,31) -> 45291 | H10: =DATE(H11,12,31) -> 45657 | I10: =DATE(I11,12,31) -> 46022 | J10: =DATE(J11,12,31) -> 46387 | K10: =DATE(K11,12,31) -> 46752 | L10: =DATE(L11,12,31) -> 47118 | M10: =DATE(M11,12,31) -> 47483 | ... AD10: =DATE(AD11,12,31) -> 53692
C11: Year | D11: Units | E11: =YEAR(E10) -> 2021 | F11: =YEAR(CaseData!$G$7) -> 2022 | G11: =F11+1 -> 2023 | H11: =G11+1 -> 2024 | I11: =H11+1 -> 2025 | J11: =I11+1 -> 2026 | K11: =J11+1 -> 2027 | L11: =K11+1 -> 2028 | M11: =L11+1 -> 2029 | N11: =M11+1 -> 2030 | ... AD11: =AC11+1 -> 2046
A12: 1 | C12: Summary
C13: Capex
B14: 1 | C14: {=INDEX(ListAssetClasses1,B14)} -> Short Term | D14: $ | F14: =SUMIFS(CaseData!$E$138:$E$437,CaseData!$F$138:$F$437,$C14,CaseData!$G$138:$G$437,F$11) -> 2724000 | G14: =SUMIFS(CaseData!$E$138:$E$437,CaseData!$F$138:$F$437,$C14,CaseData!$G$138:$G$437,G$11) -> 306000 | H14: =SUMIFS(CaseData!$E$138:$E$437,CaseData!$F$138:$F$437,$C14,CaseData!$G$138:$G$437,H$11) -> 934500 | I14: =SUMIFS(CaseData!$E$138:$E$437,CaseData!$F$138:$F$437,$C14,CaseData!$G$138:$G$437,I$11) -> 2535000 | J14: =SUMIFS(CaseData!$E$138:$E$437,CaseData!$F$138:$F$437,$C14,CaseData!$G$138:$G$437,J$11) -> 1273500 | K14: =SUMIFS(CaseData!$E$138:$E$437,CaseData!$F$138:$F$437,$C14,CaseData!$G$138:$G$437,K$11) -> 1741500 | L14: =SUMIFS(CaseData!$E$138:$E$437,CaseData!$F$138:$F$437,$C14,CaseData!$G$138:$G$437,L$11) -> 1219500 | M14: =SUMIFS(CaseData!$E$138:$E$437,CaseData!$F$138:$F$437,$C14,CaseData!$G$138:$G$437,M$11) -> 289500 | ... AD14: =SUMIFS(CaseData!$E$138:$E$437,CaseData!$F$138:$F$437,$C14,CaseData!$G$138:$G$437,AD$11) -> 1356000
B15: =B14+1 -> 2 | C15: {=INDEX(ListAssetClasses1,B15)} -> Medium Term | D15: $ | F15: =SUMIFS(CaseData!$E$138:$E$437,CaseData!$F$138:$F$437,$C15,CaseData!$G$138:$G$437,F$11) -> 2875500 | G15: =SUMIFS(CaseData!$E$138:$E$437,CaseData!$F$138:$F$437,$C15,CaseData!$G$138:$G$437,G$11) -> 835500 | H15: =SUMIFS(CaseData!$E$138:$E$437,CaseData!$F$138:$F$437,$C15,CaseData!$G$138:$G$437,H$11) -> 1041000 | I15: =SUMIFS(CaseData!$E$138:$E$437,CaseData!$F$138:$F$437,$C15,CaseData!$G$138:$G$437,I$11) -> 906000 | J15: =SUMIFS(CaseData!$E$138:$E$437,CaseData!$F$138:$F$437,$C15,CaseData!$G$138:$G$437,J$11) -> 904500 | K15: =SUMIFS(CaseData!$E$138:$E$437,CaseData!$F$138:$F$437,$C15,CaseData!$G$138:$G$437,K$11) -> 2680500 | L15: =SUMIFS(CaseData!$E$138:$E$437,CaseData!$F$138:$F$437,$C15,CaseData!$G$138:$G$437,L$11) -> 202500 | M15: =SUMIFS(CaseData!$E$138:$E$437,CaseData!$F$138:$F$437,$C15,CaseData!$G$138:$G$437,M$11) -> 1611000 | ... AD15: =SUMIFS(CaseData!$E$138:$E$437,CaseData!$F$138:$F$437,$C15,CaseData!$G$138:$G$437,AD$11) -> 2460000
B16: =B15+1 -> 3 | C16: {=INDEX(ListAssetClasses1,B16)} -> Long Term | D16: $ | F16: =SUMIFS(CaseData!$E$138:$E$437,CaseData!$F$138:$F$437,$C16,CaseData!$G$138:$G$437,F$11) -> 3393000 | G16: =SUMIFS(CaseData!$E$138:$E$437,CaseData!$F$138:$F$437,$C16,CaseData!$G$138:$G$437,G$11) -> 672000 | H16: =SUMIFS(CaseData!$E$138:$E$437,CaseData!$F$138:$F$437,$C16,CaseData!$G$138:$G$437,H$11) -> 2329500 | I16: =SUMIFS(CaseData!$E$138:$E$437,CaseData!$F$138:$F$437,$C16,CaseData!$G$138:$G$437,I$11) -> 567000 | J16: =SUMIFS(CaseData!$E$138:$E$437,CaseData!$F$138:$F$437,$C16,CaseData!$G$138:$G$437,J$11) -> 2409000 | K16: =SUMIFS(CaseData!$E$138:$E$437,CaseData!$F$138:$F$437,$C16,CaseData!$G$138:$G$437,K$11) -> 2518500 | L16: =SUMIFS(CaseData!$E$138:$E$437,CaseData!$F$138:$F$437,$C16,CaseData!$G$138:$G$437,L$11) -> 2092500 | M16: =SUMIFS(CaseData!$E$138:$E$437,CaseData!$F$138:$F$437,$C16,CaseData!$G$138:$G$437,M$11) -> 127500 | ... AD16: =SUMIFS(CaseData!$E$138:$E$437,CaseData!$F$138:$F$437,$C16,CaseData!$G$138:$G$437,AD$11) -> 2253000
C17: Total Capex | D17: $ | F17: =SUM(F14:F16) -> 8992500 | G17: =SUM(G14:G16) -> 1813500 | H17: =SUM(H14:H16) -> 4305000 | I17: =SUM(I14:I16) -> 4008000 | J17: =SUM(J14:J16) -> 4587000 | K17: =SUM(K14:K16) -> 6940500 | L17: =SUM(L14:L16) -> 3514500 | M17: =SUM(M14:M16) -> 2028000 | ... AD17: =SUM(AD14:AD16) -> 6069000
C19: Total Depreciation
C20: =CaseData!C22 -> Declining Balance | D20: $ | F20: =F51 -> 2262650.6 | G20: =G51 -> 1932965.3 | H20: =H51 -> 2316478.2 | I20: =I51 -> 3025304.1 | J20: =J51 -> 3134562.4 | K20: =K51 -> 3865176.9 | L20: =L51 -> 3607143.6 | M20: =M51 -> 3075229 | ... AD20: =AD51 -> 4514195.6
C21: =CaseData!C23 -> Straight Line | D21: $ | F21: =F83 -> 1005622.5 | G21: =G83 -> 1185695 | H21: =H83 -> 1609680 | I21: =I83 -> 2213310 | J21: =J83 -> 2693772.5 | K21: =K83 -> 2921250 | L21: =L83 -> 3246577.5 | M21: =M83 -> 3285147.5 | ... AD21: =AD83 -> 4468182.5
C22: =CaseData!C24 -> Units of Production | D22: $ | F22: =F197 -> 2010170.6 | G22: =G197 -> 1791988.8 | H22: =H197 -> 2162689.7 | I22: =I197 -> 2880936.7 | J22: =J197 -> 3127196.7 | K22: =K197 -> 3616872.3 | L22: =L197 -> 3556968.2 | M22: =M197 -> 3199680.7 | ... AD22: =AD197 -> 4497084.8
C23: =CaseData!C25 -> Sum of Years Digits | D23: $ | F23: =F317 -> 1762196 | G23: =G317 -> 1834160.7 | H23: =H317 -> 2298342.6 | I23: =I317 -> 2941126.6 | J23: =J317 -> 3222226.2 | K23: =K317 -> 3855943.1 | L23: =L317 -> 3841741.7 | M23: =M317 -> 3465064.5 | ... AD23: =AD317 -> 4543630.9
A25: =MAX(A$11:A24)+1 -> 2 | C25: Net PP&E
C26: Modeled Depn | D26: $ | E26: Straight Line | F26: =INDEX(F20:F23,MATCH($E$26,$C$20:$C$23,0)) -> 1005622.5 | G26: =INDEX(G20:G23,MATCH($E$26,$C$20:$C$23,0)) -> 1185695 | H26: =INDEX(H20:H23,MATCH($E$26,$C$20:$C$23,0)) -> 1609680 | I26: =INDEX(I20:I23,MATCH($E$26,$C$20:$C$23,0)) -> 2213310 | J26: =INDEX(J20:J23,MATCH($E$26,$C$20:$C$23,0)) -> 2693772.5 | K26: =INDEX(K20:K23,MATCH($E$26,$C$20:$C$23,0)) -> 2921250 | L26: =INDEX(L20:L23,MATCH($E$26,$C$20:$C$23,0)) -> 3246577.5 | M26: =INDEX(M20:M23,MATCH($E$26,$C$20:$C$23,0)) -> 3285147.5 | ... AD26: =INDEX(AD20:AD23,MATCH($E$26,$C$20:$C$23,0)) -> 4468182.5
C28: Net PP&E
C29: Opening Balance | D29: $ | F29: 0 | G29: =F32 -> 7986877.5 | H29: =G32 -> 8614682.5 | I29: =H32 -> 11310002 | J29: =I32 -> 13104692 | K29: =J32 -> 14997920 | L29: =K32 -> 19017170 | M29: =L32 -> 19285092 | N29: =M32 -> 18027945 | ... AD29: =AC32 -> 24835690
C30: New Capex | D30: $ | F30: =F17 -> 8992500 | G30: =G17 -> 1813500 | H30: =H17 -> 4305000 | I30: =I17 -> 4008000 | J30: =J17 -> 4587000 | K30: =K17 -> 6940500 | L30: =L17 -> 3514500 | M30: =M17 -> 2028000 | ... AD30: =AD17 -> 6069000
C31: Depreciation | D31: $ | F31: =-F26 -> -1005622.5 | G31: =-G26 -> -1185695 | H31: =-H26 -> -1609680 | I31: =-I26 -> -2213310 | J31: =-J26 -> -2693772.5 | K31: =-K26 -> -2921250 | L31: =-L26 -> -3246577.5 | M31: =-M26 -> -3285147.5 | ... AD31: =-AD26 -> -4468182.5
C32: Closing Balance | D32: $ | F32: =SUM(F29:F31) -> 7986877.5 | G32: =SUM(G29:G31) -> 8614682.5 | H32: =SUM(H29:H31) -> 11310002 | I32: =SUM(I29:I31) -> 13104692 | J32: =SUM(J29:J31) -> 14997920 | K32: =SUM(K29:K31) -> 19017170 | L32: =SUM(L29:L31) -> 19285092 | M32: =SUM(M29:M31) -> 18027945 | ... AD32: =SUM(AD29:AD31) -> 26436508
A34: =MAX(A$11:A33)+1 -> 3 | C34: Tax Deduction
C35: Tax Rate | D35: =CaseData!$G$8 -> 0.25
C36: Tax Deduction | D36: $ | E36: 0 | F36: =-$D$35*F31 -> 251405.62 | G36: =-$D$35*G31 -> 296423.75 | H36: =-$D$35*H31 -> 402420 | I36: =-$D$35*I31 -> 553327.5 | J36: =-$D$35*J31 -> 673443.12 | K36: =-$D$35*K31 -> 730312.5 | L36: =-$D$35*L31 -> 811644.38 | M36: =-$D$35*M31 -> 821286.88 | ... AD36: =-$D$35*AD31 -> 1117045.6
C37: NPV | D37: =CaseData!$G$9 -> 0.1 | E37: =NPV($D$37,F36:AD36) -> 6602901
C38: XNPV | D38: =CaseData!$G$9 -> 0.1 | E38: =XNPV($D$37,E36:AD36,E10:AD10) -> 6598440.4
F39: NPV | G39: XNPV
F40: =E37 -> 6602901 | G40: =E38 -> 6598440.4
B41: 1 | D41: $ | E41: {=INDEX(ListDepMethods1,B41)} -> Declining Balance | F41: 7549234.7 | G41: 7544640.6
B42: =B41+1 -> 2 | D42: $ | E42: {=INDEX(ListDepMethods1,B42)} -> Straight Line | F42: 6602901 | G42: 6598440.4
B43: =B42+1 -> 3 | D43: $ | E43: {=INDEX(ListDepMethods1,B43)} -> Units of Production | F43: 7445364 | G43: 7440731.6
B44: =B43+1 -> 4 | D44: $ | E44: {=INDEX(ListDepMethods1,B44)} -> Sum of Years Digits | F44: 7602001.9 | G44: 7597275.7
A46: =MAX(A$11:A45)+1 -> 4 | C46: =CaseData!C22 -> Declining Balance
...
