Workbook
Name company: CaseData!$C$34
Name expansion_selector: Expansion!$F$7
Name overlay_selector: Overlay!$F$7
Name periods: CaseData!$C$36
Name start_date: CaseData!$C$9
Name switch: CaseData!$C$37:$C$38
Name topic: "CFM Topic: " & CaseData!$C$35

Sheet Summary
A1: {=company} -> Stanbridge Inc.
A2: {=topic} -> CFM Topic: CAPEX and Depreciation
A3: SUMMARY SCHEDULE | J3: {=EOMONTH( start_date, _xlfn.SEQUENCE( 1, periods, 0, 12 ) )} -> 46053 | K3: 46418 | L3: 46783 | M3: 47149 | N3: 47514 | O3: 47879 | P3: 48244 | Q3: 48610 | R3: 48975 | S3: 49340
B5: Depreciation summary
E7: Depreciation on land | G7: USD m | J7: {=_xlfn.ANCHORARRAY( Existing!J14)} -> 0 | K7: 0 | L7: 0 | M7: 0 | N7: 0 | O7: 0 | P7: 0 | Q7: 0 | R7: 0 | S7: 0
E8: Depreciation on existing buildings | G8: USD m | J8: {=_xlfn.ANCHORARRAY( Existing!J19) +_xlfn.ANCHORARRAY( Existing!J35)} -> 49.281556 | K8: 51.960076 | L8: 54.692166 | M8: 57.478898 | N8: 60.321365 | O8: 63.220681 | P8: 66.177984 | Q8: 69.194432 | R8: 72.27121 | S8: 75.409523
E9: Depreciation on existing machinery | G9: USD m | J9: {=_xlfn.ANCHORARRAY( Existing!J47) +_xlfn.ANCHORARRAY( Existing!J63)} -> 622.76 | K9: 435.468 | L9: 324.32904 | M9: 258.90663 | N9: 220.93937 | O9: 268.54046 | P9: 160.30018 | Q9: 165.79046 | R9: 172.53268 | S9: 175.98334
E10: Depreciation on manufactoring explansion | G10: USD m | J10: {=_xlfn.ANCHORARRAY( Expansion!J20)} -> 0 | K10: 21.333333 | L10: 55.466667 | M10: 75.946667 | N10: 66.901333 | O10: 40.1408 | P10: 24.08448 | Q10: 18.432 | R10: 11.0592 | S10: 6.63552
E11: Depreciation on tachnology overlay | G11: USD m | J11: {=_xlfn.ANCHORARRAY( Overlay!J20)} -> 18.505 | K11: 30.424167 | L11: 20.545417 | M11: 15.606042 | N11: 13.939375 | O11: 4 | P11: 2 | Q11: 1 | R11: 0 | S11: 0
E12: Total depreciation | G12: USD m | J12: {=_xlfn.BYCOL( J7:S11, _xleta.SUM )} -> 690.54656 | K12: 539.18558 | L12: 455.03329 | M12: 407.93824 | N12: 362.10144 | O12: 375.90194 | P12: 252.56264 | Q12: 254.41689 | R12: 255.86309 | S12: 258.02838
B15: Net PP&E
E17: Land | G17: USD m | J17: {=_xlfn.ANCHORARRAY(Existing!J12)} -> 12.4 | K17: 12.4 | L17: 12.4 | M17: 12.4 | N17: 12.4 | O17: 12.4 | P17: 12.4 | Q17: 12.4 | R17: 12.4 | S17: 12.4
E18: Buildings | G18: USD m | J18: {=_xlfn.ANCHORARRAY( Existing!J41)} -> 880.21844 | K18: 895.88437 | L18: 910.17072 | M18: 923.04992 | N18: 934.4938 | O18: 944.47368 | P18: 952.96026 | Q18: 959.92369 | R18: 965.3335 | S18: 969.15861
E19: Machinery | G19: USD m | J19: {=_xlfn.ANCHORARRAY( Existing!J69)} -> 1010.64 | K19: 731.232 | L19: 566.08416 | M19: 469.54236 | N19: 414.21511 | O19: 314.59901 | P19: 326.60169 | Q19: 336.56014 | R19: 343.29134 | S19: 350.15717
E20: Manufactoring expansion | G20: USD m | J20: {=_xlfn.ANCHORARRAY( Expansion!J26)} -> 0 | K20: 85.333333 | L20: 136.53333 | M20: 167.25333 | N20: 100.352 | O20: 60.2112 | P20: 36.12672 | Q20: 17.69472 | R20: 6.63552 | S20: -3.9968029e-14
E21: Technology overlay | G21: USD m | J21: {=_xlfn.ANCHORARRAY( Overlay!J26)} -> 55.515 | K21: 35.7575 | L21: 25.87875 | M21: 20.939375 | N21: 7 | O21: 3 | P21: 1 | Q21: 0 | R21: 0 | S21: 0
E22: Net PP&E | G22: USD m | J22: {=_xlfn.BYCOL( J17:S21, _xleta.SUM)} -> 1958.7734 | K22: 1760.6072 | L22: 1651.067 | M22: 1593.185 | N22: 1468.4609 | O22: 1334.6839 | P22: 1329.0887 | Q22: 1326.5785 | R22: 1327.6604 | S22: 1331.7158

Sheet Overlay
A1: {=company} -> Stanbridge Inc.
A2: {=topic} -> CFM Topic: CAPEX and Depreciation
A3: TECHNOLOGY OVERLAY SCHEDULE | J3: {=EOMONTH( start_date, _xlfn.SEQUENCE( 1, periods, 0, 12 ) )} -> 46053 | K3: 46418 | L3: 46783 | M3: 47149 | N3: 47514 | O3: 47879 | P3: 48244 | Q3: 48610 | R3: 48975 | S3: 49340
B5: TECHNOLOGY OVERLAY
E7: Technology overlay switch | F7: 1
E9: Depreciation on overlay | J9: {=_xlfn.ANCHORARRAY(J3)} -> 46053 | K9: 46418 | L9: 46783 | M9: 47149 | N9: 47514 | O9: 47879 | P9: 48244 | Q9: 48610 | R9: 48975 | S9: 49340
F10: {=TRANSPOSE(_xlfn.ANCHORARRAY( J3) )} -> 46053 | G10: {=_xlfn.LET( _xlpm.switch, $F$7, _xlpm.expansion_cost, _xlfn.DROP( INDEX(_xlfn.ANCHORARRAY( Expansion!$G$10),, 1 ) * 0.1, 1 ), _xlpm.overlay_cost, CaseData!$E$16 * 0.05, _xlpm.overlay_date, CaseData!$I$24, _xlpm.useful_life, CaseData!$I$27, _xlpm.current_year,_xlfn.ANCHORARRAY( J3), IF( _xlpm.switch = 1, _xlfn.VSTACK( _xlpm.overlay_cost, _xlpm.expansion_cost ), 0 ) )} -> 74.02 | H10: {=_xlfn.BYROW(_xlfn.ANCHORARRAY( J10), _xleta.SUM )} -> 74.02 | J10: {=_xlfn.LET( _xlpm.acquisition_cost, INDEX(_xlfn.ANCHORARRAY( G10),, 1 ), _xlpm.acquisition_date, INDEX(_xlfn.ANCHORARRAY( F10),, 1 ), _xlpm.current_date,_xlfn.ANCHORARRAY( J3), _xlpm.useful_life, CaseData!$I$27, _xlpm.depreciation_rate, 1 / _xlpm.useful_life * 2, _xlpm.period, YEAR( _xlpm.current_date ) - YEAR( _xlpm.acquisition_date ), _xlpm.book_value, _xlpm.acquisition_cost * ( 1 - _xlpm.depreciation_rate / 2 ) * ( 1 - _xlpm.depreciation_rate ) ^ ( _xlpm.period - 1), _xlpm.depreciation, _xlpm.book_value * _xlpm.depreciation_rate, IF( _xlpm.period < 0, 0, IF( _xlpm.period = 0, _xlpm.acquisition_cost * _xlpm.depreciation_rate / 2, IF( _xlpm.period < _xlpm.useful_life, _xlpm.depreciation, IF( _xlpm.period = _xlpm.useful_life, _xlpm.book_value, 0 ) ) ) ) )} -> 18.505 | K10: 27.7575 | L10: 13.87875 | M10: 6.939375 | N10: 6.939375 | O10: 0 | P10: 0 | Q10: 0 | R10: 0 | S10: 0
F11: 46418 | G11: 10.666667 | H11: 10.666667 | J11: 0 | K11: 2.6666667 | L11: 4 | M11: 2 | N11: 1 | O11: 1 | P11: 0 | Q11: 0 | R11: 0 | S11: 0
F12: 46783 | G12: 10.666667 | H12: 10.666667 | J12: 0 | K12: 0 | L12: 2.6666667 | M12: 4 | N12: 2 | O12: 1 | P12: 1 | Q12: 0 | R12: 0 | S12: 0
F13: 47149 | G13: 10.666667 | H13: 10.666667 | J13: 0 | K13: 0 | L13: 0 | M13: 2.6666667 | N13: 4 | O13: 2 | P13: 1 | Q13: 1 | R13: 0 | S13: 0
F14: 47514 | G14: 0 | H14: 0 | J14: 0 | K14: 0 | L14: 0 | M14: 0 | N14: 0 | O14: 0 | P14: 0 | Q14: 0 | R14: 0 | S14: 0
F15: 47879 | G15: 0 | H15: 0 | J15: 0 | K15: 0 | L15: 0 | M15: 0 | N15: 0 | O15: 0 | P15: 0 | Q15: 0 | R15: 0 | S15: 0
F16: 48244 | G16: 0 | H16: 0 | J16: 0 | K16: 0 | L16: 0 | M16: 0 | N16: 0 | O16: 0 | P16: 0 | Q16: 0 | R16: 0 | S16: 0
F17: 48610 | G17: 0 | H17: 0 | J17: 0 | K17: 0 | L17: 0 | M17: 0 | N17: 0 | O17: 0 | P17: 0 | Q17: 0 | R17: 0 | S17: 0
F18: 48975 | G18: 0 | H18: 0 | J18: 0 | K18: 0 | L18: 0 | M18: 0 | N18: 0 | O18: 0 | P18: 0 | Q18: 0 | R18: 0 | S18: 0
F19: 49340 | G19: 0 | H19: 0 | J19: 0 | K19: 0 | L19: 0 | M19: 0 | N19: 0 | O19: 0 | P19: 0 | Q19: 0 | R19: 0 | S19: 0
J20: {=_xlfn.BYCOL(_xlfn.ANCHORARRAY( J10), _xleta.SUM )} -> 18.505 | K20: 30.424167 | L20: 20.545417 | M20: 15.606042 | N20: 13.939375 | O20: 4 | P20: 2 | Q20: 1 | R20: 0 | S20: 0
E23: Technology overlay opening balance | J23: {=_xlfn.DROP( _xlfn.HSTACK( 0,_xlfn.ANCHORARRAY( J26) ),, -1 )} -> 0 | K23: 55.515 | L23: 35.7575 | M23: 25.87875 | N23: 20.939375 | O23: 7 | P23: 3 | Q23: 1 | R23: 0 | S23: 0
E24: CAPEX in technology overlay | J24: {=TRANSPOSE(_xlfn.ANCHORARRAY( G10))} -> 74.02 | K24: 10.666667 | L24: 10.666667 | M24: 10.666667 | N24: 0 | O24: 0 | P24: 0 | Q24: 0 | R24: 0 | S24: 0
E25: Depreciation costs on new technology overlay | J25: {=_xlfn.ANCHORARRAY( J20) * -1} -> -18.505 | K25: -30.424167 | L25: -20.545417 | M25: -15.606042 | N25: -13.939375 | O25: -4 | P25: -2 | Q25: -1 | R25: 0 | S25: 0
E26: Technology overlay closing balance | J26: {=_xlfn.LET( _xlpm.opening_balance, 0, _xlpm.movements,_xlfn.ANCHORARRAY( J24) +_xlfn.ANCHORARRAY( J25), _xlfn.SCAN( _xlpm.opening_balance, _xlpm.movements, _xleta.SUM ) )} -> 55.515 | K26: 35.7575 | L26: 25.87875 | M26: 20.939375 | N26: 7 | O26: 3 | P26: 1 | Q26: 0 | R26: 0 | S26: 0
B28: End of schedule

Sheet Expansion
A1: {=company} -> Stanbridge Inc.
A2: {=topic} -> CFM Topic: CAPEX and Depreciation
A3: MANUFACTORING EXPANSION SCHEDULE | J3: {=EOMONTH( start_date, _xlfn.SEQUENCE( 1, periods, 0, 12 ) )} -> 46053 | K3: 46418 | L3: 46783 | M3: 47149 | N3: 47514 | O3: 47879 | P3: 48244 | Q3: 48610 | R3: 48975 | S3: 49340
B5: Manufactoring expansion
E7: Manufactoring switch | F7: 1
E9: Depreciation on new expansion | J9: {=_xlfn.ANCHORARRAY(J3)} -> 46053 | K9: 46418 | L9: 46783 | M9: 47149 | N9: 47514 | O9: 47879 | P9: 48244 | Q9: 48610 | R9: 48975 | S9: 49340
F10: {=TRANSPOSE(_xlfn.ANCHORARRAY( J3) )} -> 46053 | G10: {=_xlfn.LET( _xlpm.expansion_cost, CaseData!$C$23, _xlpm.expansion_date, CaseData!$C$24, _xlpm.years_to_complete, CaseData!$C$25, _xlpm.current_year,_xlfn.ANCHORARRAY( J3), _xlpm.period, YEAR( _xlpm.current_year ) - _xlpm.expansion_date, _xlpm.expansion_per_year, _xlpm.expansion_cost / _xlpm.years_to_complete, _xlpm.switch, $F$7, IF( _xlpm.switch = 1, TRANSPOSE( IF( _xlpm.period < 0, 0, IF( _xlpm.period < _xlpm.years_to_complete, _xlpm.expansion_per_year, 0 ) ) ), 0 ) )} -> 0 | H10: {=_xlfn.BYROW(_xlfn.ANCHORARRAY( J10), _xleta.SUM )} -> 0 | J10: {=_xlfn.LET( _xlpm.acquisition_cost, INDEX(_xlfn.ANCHORARRAY( G10),, 1 ), _xlpm.acquisition_date, INDEX(_xlfn.ANCHORARRAY( F10),, 1 ), _xlpm.current_date,_xlfn.ANCHORARRAY( J3), _xlpm.useful_life, CaseData!$C$27, _xlpm.depreciation_rate, CaseData!$C$28, _xlpm.period, YEAR( _xlpm.current_date ) - YEAR( _xlpm.acquisition_date ), _xlpm.book_value, _xlpm.acquisition_cost * ( 1 - _xlpm.depreciation_rate / 2 ) * ( 1 - _xlpm.depreciation_rate ) ^ ( _xlpm.period - 1), _xlpm.depreciation, _xlpm.book_value * _xlpm.depreciation_rate, IF( _xlpm.period < 0, 0, IF( _xlpm.period = 0, _xlpm.acquisition_cost * _xlpm.depreciation_rate / 2, IF( _xlpm.period < _xlpm.useful_life, _xlpm.depreciation, IF( _xlpm.period = _xlpm.useful_life, _xlpm.book_value, 0 ) ) ) ) )} -> 0 | K10: 0 | L10: 0 | M10: 0 | N10: 0 | O10: 0 | P10: 0 | Q10: 0 | R10: 0 | S10: 0
F11: 46418 | G11: 106.66667 | H11: 106.66667 | J11: 0 | K11: 21.333333 | L11: 34.133333 | M11: 20.48 | N11: 12.288 | O11: 7.3728 | P11: 4.42368 | Q11: 6.63552 | R11: 0 | S11: 0
F12: 46783 | G12: 106.66667 | H12: 106.66667 | J12: 0 | K12: 0 | L12: 21.333333 | M12: 34.133333 | N12: 20.48 | O12: 12.288 | P12: 7.3728 | Q12: 4.42368 | R12: 6.63552 | S12: 0
F13: 47149 | G13: 106.66667 | H13: 106.66667 | J13: 0 | K13: 0 | L13: 0 | M13: 21.333333 | N13: 34.133333 | O13: 20.48 | P13: 12.288 | Q13: 7.3728 | R13: 4.42368 | S13: 6.63552
F14: 47514 | G14: 0 | H14: 0 | J14: 0 | K14: 0 | L14: 0 | M14: 0 | N14: 0 | O14: 0 | P14: 0 | Q14: 0 | R14: 0 | S14: 0
F15: 47879 | G15: 0 | H15: 0 | J15: 0 | K15: 0 | L15: 0 | M15: 0 | N15: 0 | O15: 0 | P15: 0 | Q15: 0 | R15: 0 | S15: 0
F16: 48244 | G16: 0 | H16: 0 | J16: 0 | K16: 0 | L16: 0 | M16: 0 | N16: 0 | O16: 0 | P16: 0 | Q16: 0 | R16: 0 | S16: 0
F17: 48610 | G17: 0 | H17: 0 | J17: 0 | K17: 0 | L17: 0 | M17: 0 | N17: 0 | O17: 0 | P17: 0 | Q17: 0 | R17: 0 | S17: 0
F18: 48975 | G18: 0 | H18: 0 | J18: 0 | K18: 0 | L18: 0 | M18: 0 | N18: 0 | O18: 0 | P18: 0 | Q18: 0 | R18: 0 | S18: 0
F19: 49340 | G19: 0 | H19: 0 | J19: 0 | K19: 0 | L19: 0 | M19: 0 | N19: 0 | O19: 0 | P19: 0 | Q19: 0 | R19: 0 | S19: 0
J20: {=_xlfn.BYCOL(_xlfn.ANCHORARRAY( J10), _xleta.SUM )} -> 0 | K20: 21.333333 | L20: 55.466667 | M20: 75.946667 | N20: 66.901333 | O20: 40.1408 | P20: 24.08448 | Q20: 18.432 | R20: 11.0592 | S20: 6.63552
E23: Manufactoring expansion opening balance | J23: {=_xlfn.DROP( _xlfn.HSTACK( 0,_xlfn.ANCHORARRAY( J26) ),, -1 )} -> 0 | K23: 0 | L23: 85.333333 | M23: 136.53333 | N23: 167.25333 | O23: 100.352 | P23: 60.2112 | Q23: 36.12672 | R23: 17.69472 | S23: 6.63552
E24: CAPEX in manufactoring expansion | J24: {=TRANSPOSE(_xlfn.ANCHORARRAY( G10))} -> 0 | K24: 106.66667 | L24: 106.66667 | M24: 106.66667 | N24: 0 | O24: 0 | P24: 0 | Q24: 0 | R24: 0 | S24: 0
E25: Depreciation costs on new manufactoring expansion | J25: {=_xlfn.ANCHORARRAY( J20) * -1} -> 0 | K25: -21.333333 | L25: -55.466667 | M25: -75.946667 | N25: -66.901333 | O25: -40.1408 | P25: -24.08448 | Q25: -18.432 | R25: -11.0592 | S25: -6.63552
E26: Manufactoring expansion closing balance | J26: {=_xlfn.LET( _xlpm.opening_balance, 0, _xlpm.movements,_xlfn.ANCHORARRAY( J24) +_xlfn.ANCHORARRAY( J25), _xlfn.SCAN( _xlpm.opening_balance, _xlpm.movements, _xleta.SUM ) )} -> 0 | K26: 85.333333 | L26: 136.53333 | M26: 167.25333 | N26: 100.352 | O26: 60.2112 | P26: 36.12672 | Q26: 17.69472 | R26: 6.63552 | S26: -3.9968029e-14
B28: End of schedule

Sheet Existing
A1: {=company} -> Stanbridge Inc.
A2: {=topic} -> CFM Topic: CAPEX and Depreciation
A3: EXISTING ASSETS SCHEDULE | J3: {=EOMONTH( start_date, _xlfn.SEQUENCE( 1, periods, 0, 12 ) )} -> 46053 | K3: 46418 | L3: 46783 | M3: 47149 | N3: 47514 | O3: 47879 | P3: 48244 | Q3: 48610 | R3: 48975 | S3: 49340
B5: Existing Property, Plant & Equipment (“PP&E”)
C7: Land
E9: Land opening balance | J9: {=_xlfn.DROP( _xlfn.HSTACK( CaseData!$E$14,_xlfn.ANCHORARRAY( J12) ),, -1 )} -> 12.4 | K9: 12.4 | L9: 12.4 | M9: 12.4 | N9: 12.4 | O9: 12.4 | P9: 12.4 | Q9: 12.4 | R9: 12.4 | S9: 12.4
E10: Land purchases | J10: {=_xlfn.SEQUENCE( 1, periods, 0, 0 )} -> 0 | K10: 0 | L10: 0 | M10: 0 | N10: 0 | O10: 0 | P10: 0 | Q10: 0 | R10: 0 | S10: 0
E11: Land sales | J11: {=_xlfn.SEQUENCE( 1, periods, 0, 0 )} -> 0 | K11: 0 | L11: 0 | M11: 0 | N11: 0 | O11: 0 | P11: 0 | Q11: 0 | R11: 0 | S11: 0
E12: Land closing balance | J12: {=_xlfn.LET( _xlpm.opening_balance, CaseData!$E$14, _xlpm.movements,_xlfn.ANCHORARRAY( Existing!J10) +_xlfn.ANCHORARRAY( Existing!J11), _xlfn.SCAN( _xlpm.opening_balance, _xlpm.movements, _xleta.SUM ) )} -> 12.4 | K12: 12.4 | L12: 12.4 | M12: 12.4 | N12: 12.4 | O12: 12.4 | P12: 12.4 | Q12: 12.4 | R12: 12.4 | S12: 12.4
E14: Depreciation on land | G14: USD m | J14: {=_xlfn.SEQUENCE( 1, periods, 0, 0 )} -> 0 | K14: 0 | L14: 0 | M14: 0 | N14: 0 | O14: 0 | P14: 0 | Q14: 0 | R14: 0 | S14: 0
C16: Buildings
D18: Existing buildings
E19: Depreciation on existing buildings | G19: USD m | H19: {=_xlfn.BYROW(_xlfn.ANCHORARRAY( J19), _xleta.SUM )} -> 479.55556 | J19: {=_xlfn.LET( _xlpm.Net_PPE, CaseData!$E$15, _xlpm.remaining_life, CaseData!$F$15, _xlpm.period, YEAR(_xlfn.ANCHORARRAY( Existing!J3) ) - YEAR( start_date ), _xlpm.depreciation, _xlpm.Net_PPE / _xlpm.remaining_life, IF( _xlpm.period < _xlpm.remaining_life, _xlpm.depreciation, 0 ) )} -> 47.955556 | K19: 47.955556 | L19: 47.955556 | M19: 47.955556 | N19: 47.955556 | O19: 47.955556 | P19: 47.955556 | Q19: 47.955556 | R19: 47.955556 | S19: 47.955556
D21: New buildings
E22: Capex on new buildings | G22: USD m | J22: {=_xlfn.LET( _xlpm.first_year_CAPEX, CaseData!$I$15, _xlpm.CAPEX_growth, 1 + CaseData!$L$15, _xlpm.useful_life, CaseData!$J$15, _xlpm.period, YEAR(_xlfn.ANCHORARRAY( Existing!J3) ) - YEAR( start_date ) + 1, _xlpm.book_value, _xlpm.first_year_CAPEX * _xlpm.CAPEX_growth ^ _xlpm.period, IF( _xlpm.period = 0, _xlpm.first_year_CAPEX, _xlpm.book_value ) )} -> 66.3 | K22: 67.626 | L22: 68.97852 | M22: 70.35809 | N22: 71.765252 | O22: 73.200557 | P22: 74.664568 | Q22: 76.15786 | R22: 77.681017 | S22: 79.234637
J24: {=_xlfn.ANCHORARRAY(J3)} -> 46053 | K24: 46418 | L24: 46783 | M24: 47149 | N24: 47514 | O24: 47879 | P24: 48244 | Q24: 48610 | R24: 48975 | S24: 49340
E25: Depreciation on new buildings | F25: {=TRANSPOSE(_xlfn.ANCHORARRAY( J3))} -> 46053 | G25: {=TRANSPOSE(_xlfn.ANCHORARRAY( J22) )} -> 66.3 | H25: {=_xlfn.BYROW(_xlfn.ANCHORARRAY(J25), _xleta.SUM )} -> 25.194 | J25: {=_xlfn.LET( _xlpm.CAPEX_date, INDEX(_xlfn.ANCHORARRAY(F25),,1), _xlpm.CAPEX_cost, INDEX(_xlfn.ANCHORARRAY(G25),,1), _xlpm.period, YEAR(_xlfn.ANCHORARRAY(J24))-YEAR(_xlpm.CAPEX_date), _xlpm.useful_life, CaseData!$J$15, _xlpm.depreciation_cost, _xlpm.CAPEX_cost/_xlpm.useful_life, _xlpm.accumulated_depreciation, _xlpm.depreciation_cost * ( _xlpm.period - 0.5 ), _xlpm.book_value, _xlpm.CAPEX_cost - _xlpm.accumulated_depreciation, IF( _xlpm.period < 0, 0, IF( _xlpm.period = 0, _xlpm.depreciation_cost / 2, IF( _xlpm.period < _xlpm.useful_life, _xlpm.depreciation_cost, IF( _xlpm.book_value > 0, _xlpm.book_value, 0 ) ) ) ) )} -> 1.326 | K25: 2.652 | L25: 2.652 | M25: 2.652 | N25: 2.652 | O25: 2.652 | P25: 2.652 | Q25: 2.652 | R25: 2.652 | S25: 2.652
F26: 46418 | G26: 67.626 | H26: 22.99284 | J26: 0 | K26: 1.35252 | L26: 2.70504 | M26: 2.70504 | N26: 2.70504 | O26: 2.70504 | P26: 2.70504 | Q26: 2.70504 | R26: 2.70504 | S26: 2.70504
F27: 46783 | G27: 68.97852 | H27: 20.693556 | J27: 0 | K27: 0 | L27: 1.3795704 | M27: 2.7591408 | N27: 2.7591408 | O27: 2.7591408 | P27: 2.7591408 | Q27: 2.7591408 | R27: 2.7591408 | S27: 2.7591408
F28: 47149 | G28: 70.35809 | H28: 18.293104 | J28: 0 | K28: 0 | L28: 0 | M28: 1.4071618 | N28: 2.8143236 | O28: 2.8143236 | P28: 2.8143236 | Q28: 2.8143236 | R28: 2.8143236 | S28: 2.8143236
F29: 47514 | G29: 71.765252 | H29: 15.788355 | J29: 0 | K29: 0 | L29: 0 | M29: 0 | N29: 1.435305 | O29: 2.8706101 | P29: 2.8706101 | Q29: 2.8706101 | R29: 2.8706101 | S29: 2.8706101
F30: 47879 | G30: 73.200557 | H30: 13.1761 | J30: 0 | K30: 0 | L30: 0 | M30: 0 | N30: 0 | O30: 1.4640111 | P30: 2.9280223 | Q30: 2.9280223 | R30: 2.9280223 | S30: 2.9280223
F31: 48244 | G31: 74.664568 | H31: 10.45304 | J31: 0 | K31: 0 | L31: 0 | M31: 0 | N31: 0 | O31: 0 | P31: 1.4932914 | Q31: 2.9865827 | R31: 2.9865827 | S31: 2.9865827
F32: 48610 | G32: 76.15786 | H32: 7.615786 | J32: 0 | K32: 0 | L32: 0 | M32: 0 | N32: 0 | O32: 0 | P32: 0 | Q32: 1.5231572 | R32: 3.0463144 | S32: 3.0463144
F33: 48975 | G33: 77.681017 | H33: 4.660861 | J33: 0 | K33: 0 | L33: 0 | M33: 0 | N33: 0 | O33: 0 | P33: 0 | Q33: 0 | R33: 1.5536203 | S33: 3.1072407
F34: 49340 | G34: 79.234637 | H34: 1.5846927 | J34: 0 | K34: 0 | L34: 0 | M34: 0 | N34: 0 | O34: 0 | P34: 0 | Q34: 0 | R34: 0 | S34: 1.5846927
J35: {=_xlfn.BYCOL(_xlfn.ANCHORARRAY( J25), _xleta.SUM )} -> 1.326 | K35: 4.00452 | L35: 6.7366104 | M35: 9.5233426 | N35: 12.365809 | O35: 15.265126 | P35: 18.222428 | Q35: 21.238877 | R35: 24.315654 | S35: 27.453967
E37: Buildings opening balance | G37: USD m | J37: {=_xlfn.DROP( _xlfn.HSTACK( CaseData!$E$15,_xlfn.ANCHORARRAY( Existing!J41) ),, -1 )} -> 863.2 | K37: 880.21844 | L37: 895.88437 | M37: 910.17072 | N37: 923.04992 | O37: 934.4938 | P37: 944.47368 | Q37: 952.96026 | R37: 959.92369 | S37: 965.3335
E38: CAPEX in new buildings | G38: USD m | J38: {=_xlfn.ANCHORARRAY( J22)} -> 66.3 | K38: 67.626 | L38: 68.97852 | M38: 70.35809 | N38: 71.765252 | O38: 73.200557 | P38: 74.664568 | Q38: 76.15786 | R38: 77.681017 | S38: 79.234637
E39: Depreciation costs on existing buildings | G39: USD m | J39: {=_xlfn.ANCHORARRAY( J19) * -1} -> -47.955556 | K39: -47.955556 | L39: -47.955556 | M39: -47.955556 | N39: -47.955556 | O39: -47.955556 | P39: -47.955556 | Q39: -47.955556 | R39: -47.955556 | S39: -47.955556
E40: Depreciation costs on new buildings | G40: USD m | J40: {=_xlfn.ANCHORARRAY( J35) * -1} -> -1.326 | K40: -4.00452 | L40: -6.7366104 | M40: -9.5233426 | N40: -12.365809 | O40: -15.265126 | P40: -18.222428 | Q40: -21.238877 | R40: -24.315654 | S40: -27.453967
E41: Buildings closing balance | G41: USD m | J41: {=_xlfn.LET( _xlpm.opening_balance, CaseData!E15, _xlpm.movements,_xlfn.ANCHORARRAY( Existing!J38) +_xlfn.ANCHORARRAY( Existing!J39) +_xlfn.ANCHORARRAY( Existing!J40), _xlfn.SCAN( _xlpm.opening_balance, _xlpm.movements, _xleta.SUM ) )} -> 880.21844 | K41: 895.88437 | L41: 910.17072 | M41: 923.04992 | N41: 934.4938 | O41: 944.47368 | P41: 952.96026 | Q41: 959.92369 | R41: 965.3335 | S41: 969.15861
C44: Machinery
D46: Existing machinery
E47: Depreciation on existing machinery | G47: USD m | H47: {=_xlfn.BYROW(_xlfn.ANCHORARRAY( J47), _xleta.SUM)} -> 1480.4 | J47: {=_xlfn.LET( _xlpm.net_PPE, CaseData!$E$16, _xlpm.remaining_life, CaseData!$F$16, _xlpm.depreciation_rate, CaseData!$G$16, _xlpm.current_date,_xlfn.ANCHORARRAY( J3), _xlpm.period, YEAR( _xlpm.current_date ) - YEAR( start_date ) + 1, _xlpm.book_value, _xlpm.net_PPE * ( 1 - _xlpm.depreciation_rate ) ^ ( _xlpm.period - 1 ), _xlpm.depreciation, _xlpm.book_value * _xlpm.depreciation_rate, IF( _xlpm.period < 0, 0, IF( _xlpm.period < _xlpm.remaining_life, _xlpm.depreciation, IF( _xlpm.period = _xlpm.remaining_life, _xlpm.book_value, 0 ) ) ) )} -> 592.16 | K47: 355.296 | L47: 213.1776 | M47: 127.90656 | N47: 76.743936 | O47: 115.1159 | P47: 0 | Q47: 0 | R47: 0 | S47: 0
D49: New machinery
E50: Capex on new machinery | G50: USD m | J50: {=_xlfn.LET( _xlpm.first_year_CAPEX, CaseData!$I$16, _xlpm.CAPEX_growth, 1 + CaseData!$L$16, _xlpm.useful_life, CaseData!$J$16, _xlpm.period, YEAR(_xlfn.ANCHORARRAY( Existing!J3) ) - YEAR( start_date ) + 1, _xlpm.book_value, _xlpm.first_year_CAPEX * _xlpm.CAPEX_growth ^ _xlpm.period, IF( _xlpm.period = 0, _xlpm.first_year_CAPEX, _xlpm.book_value ) )} -> 153 | K50: 156.06 | L50: 159.1812 | M50: 162.36482 | N50: 165.61212 | O50: 168.92436 | P50: 172.30285 | Q50: 175.74891 | R50: 179.26389 | S50: 182.84916
E52: Depreciation on new machinery | J52: {=_xlfn.ANCHORARRAY(J3)} -> 46053 | K52: 46418 | L52: 46783 | M52: 47149 | N52: 47514 | O52: 47879 | P52: 48244 | Q52: 48610 | R52: 48975 | S52: 49340
F53: {=TRANSPOSE(_xlfn.ANCHORARRAY( J3) )} -> 46053 | G53: {=TRANSPOSE(_xlfn.ANCHORARRAY( J50) )} -> 153 | H53: {=_xlfn.BYROW(_xlfn.ANCHORARRAY(J53), _xleta.SUM )} -> 153 | J53: {=_xlfn.LET( _xlpm.acquisition_cost, INDEX(_xlfn.ANCHORARRAY( G53),, 1 ), _xlpm.acquisition_date, INDEX(_xlfn.ANCHORARRAY( F53),, 1 ), _xlpm.current_date,_xlfn.ANCHORARRAY( J3), _xlpm.remaining_life, CaseData!$J$16, _xlpm.depreciation_rate, CaseData!$K$16, _xlpm.period, YEAR( _xlpm.current_date ) - YEAR( _xlpm.acquisition_date ), _xlpm.book_value, _xlpm.acquisition_cost * ( 1 - _xlpm.depreciation_rate / 2 ) * ( 1 - _xlpm.depreciation_rate ) ^ ( _xlpm.period - 1), _xlpm.depreciation, _xlpm.book_value * _xlpm.depreciation_rate, IF( _xlpm.period < 0, 0, IF( _xlpm.period = 0, _xlpm.acquisition_cost * _xlpm.depreciation_rate / 2, IF( _xlpm.period < _xlpm.remaining_life, _xlpm.book_value * _xlpm.depreciation_rate, IF( _xlpm.period = _xlpm.remaining_life, _xlpm.book_value, 0 ) ) ) ) )} -> 30.6 | K53: 48.96 | L53: 29.376 | M53: 17.6256 | N53: 10.57536 | O53: 6.345216 | P53: 3.8071296 | Q53: 2.2842778 | R53: 3.4264166 | S53: 0
F54: 46418 | G54: 156.06 | H54: 156.06 | J54: 0 | K54: 31.212 | L54: 49.9392 | M54: 29.96352 | N54: 17.978112 | O54: 10.786867 | P54: 6.4721203 | Q54: 3.8832722 | R54: 2.3299633 | S54: 3.494945
...

Sheet CaseData
B2: CFM Sample Exam Question
B3: Capex & Depreciation - Case Data
B5: (in $ mm, unless otherwise noted)
B7: EXISTING PROPERTY, PLANT & EQUIPMENT
B9: Current Date | C9: 46023
E11: EXISTING ASSETS | I11: NEW ASSETS
B12: Asset | C12: Depreciation | E12: Net Balance | F12: Remaining | G12: Depreciation | I12: Annual | J12: Useful | K12: Depreciation | L12: Capex
B13: Type | C13: Method | E13: ($mm) | F13: Life | G13: Rate | I13: Capex | J13: Life | K13: Rate | L13: Growth
B14: Land | C14: N/A | E14: 12.4 | F14: N/A | G14: N/A | I14: N/A | J14: N/A | K14: N/A | L14: N/A
B15: Buildings | C15: Straight-Line | E15: 863.2 | F15: 18 | G15: N/A | I15: 65 | J15: 25 | K15: N/A | L15: 0.02
B16: Machinery | C16: Declining Balance | E16: 1480.4 | F16: 6 | G16: 0.4 | I16: 150 | J16: 8 | K16: 0.4 | L16: 0.02
B17: Total | E17: =SUM(E14:E16) -> 2356
B21: MANUFACTURING EXPANSION | F21: TECHNOLOGY OVERLAY
B22: On (=1) / Off (=0) | C22: 1 | F22: On (=1) / Off (=0) | I22: 1
B23: Total Cost | C23: 320 | F23: % of Existing Machiney | I23: 0.05
B24: Start Year | C24: 2027 | F24: Start Year | I24: 2026
B25: Years to Complete | C25: 3 | F25: % of Expansion Capex | I25: 0.1
B26: Method | C26: Declining Balance | F26: Method | I26: Double Declining
B27: Useful Life | C27: 6 | F27: Useful Life | I27: 4
B28: Depreciation Rate | C28: 0.4 | F28: Depreciation Rate | I28: =1/I27*2 -> 0.5
B32: Model technical inputs
B34: Company name | C34: Stanbridge Inc.
B35: Topic | C35: CAPEX and Depreciation
B36: Periods | C36: 10 | D36: years
B37: Switch | C37: On
C38: Off
