Workbook
Name company: Case2Data!$D$33
Name quarters: Case2Data!$D$36
Name start_date: Case2Data!$E$6
Name topic: "CFM Topic: " & Case2Data!$D$34
Name years: Case2Data!$D$35

Sheet Financials
A1: =company -> Thermin Corp
A2: {=topic} -> CFM Topic: Working capital | J2: {=_xlfn.ANCHORARRAY( Calculations!J$7)} -> 43831 | K2: 43922 | L2: 44013 | M2: 44105 | N2: 44197 | O2: 44287 | P2: 44378 | Q2: 44470 | R2: 44562 | S2: 44652 | T2: 44743 | U2: 44835 | V2: 44927 | W2: 45017 | X2: 45108 | Y2: 45200 | Z2: 45292 | AA2: 45383 | AB2: 45474 | AC2: 45566 | AD2: 45658 | AE2: 45748 | AF2: 45839 | AG2: 45931
A3: FINANCIAL STATEMENTS | F3: Constant | G3: Unit | H3: Total | J3: {=_xlfn.ANCHORARRAY( Calculations!J$8)} -> 43921 | K3: 44012 | L3: 44104 | M3: 44196 | N3: 44286 | O3: 44377 | P3: 44469 | Q3: 44561 | R3: 44651 | S3: 44742 | T3: 44834 | U3: 44926 | V3: 45016 | W3: 45107 | X3: 45199 | Y3: 45291 | Z3: 45382 | AA3: 45473 | AB3: 45565 | AC3: 45657 | AD3: 45747 | AE3: 45838 | AF3: 45930 | AG3: 46022
B5: Income statement
C7: FIFO
E9: Revenue | G9: USD m | H9: {=_xlfn.BYROW(_xlfn.ANCHORARRAY( J9), _xleta.SUM )} -> 5392141.3 | J9: {=_xlfn.ANCHORARRAY( Calculations!J$43)} -> 110644.5 | K9: 184407.5 | L9: 147526 | M9: 295052 | N9: 119334.6 | O9: 198891 | P9: 159112.8 | Q9: 318225.6 | R9: 128722.94 | S9: 214538.23 | T9: 171630.58 | U9: 343261.17 | V9: 138819.5 | W9: 231365.83 | X9: 185092.66 | Y9: 370185.32 | Z9: 149760.7 | AA9: 249601.17 | AB9: 199680.94 | AC9: 399361.87 | AD9: 161538.96 | AE9: 269231.6 | AF9: 215385.28 | AG9: 430770.55
E10: FIFO Cost of Goods of Sold | G10: USD m | H10: {=_xlfn.BYROW(_xlfn.ANCHORARRAY( J10), _xleta.SUM )} -> 4322194.7 | J10: {=_xlfn.ANCHORARRAY( Calculations!J$110)} -> 88515 | K10: 147525 | L10: 118020 | M10: 236040 | N10: 92940.75 | O10: 158966.82 | P10: 127801.77 | Q10: 255603.55 | R10: 100643.9 | S10: 169481.04 | T10: 138410.95 | U10: 276821.9 | V10: 108998.62 | W10: 181969.37 | X10: 149872.64 | Y10: 299745.28 | Z10: 118024.7 | AA10: 196707.84 | AB10: 162267.67 | AC10: 324685.7 | AD10: 127844.99 | AE10: 213834.56 | AF10: 175824.22 | AG10: 351648.44
E11: Gross profit | G11: USD m | H11: {=_xlfn.BYROW(_xlfn.ANCHORARRAY( J11), _xleta.SUM )} -> 1069946.6 | J11: {=_xlfn.ANCHORARRAY( J9) -_xlfn.ANCHORARRAY( J10)} -> 22129.5 | K11: 36882.5 | L11: 29506 | M11: 59012 | N11: 26393.85 | O11: 39924.176 | P11: 31311.025 | Q11: 62622.05 | R11: 28079.041 | S11: 45057.192 | T11: 33219.636 | U11: 66439.272 | V11: 29820.874 | W11: 49396.458 | X11: 35220.02 | Y11: 70440.04 | Z11: 31735.997 | AA11: 52893.328 | AB11: 37413.267 | AC11: 74676.173 | AD11: 33693.963 | AE11: 55397.04 | AF11: 39561.058 | AG11: 79122.115
E13: Overheads | G13: USD m | H13: {=_xlfn.BYROW(_xlfn.ANCHORARRAY( J13), _xleta.SUM )} -> 600000 | J13: {=_xlfn.SEQUENCE( 1, quarters * years, Case2Data!$E$25 / 1000, 0 )} -> 25000 | K13: 25000 | L13: 25000 | M13: 25000 | N13: 25000 | O13: 25000 | P13: 25000 | Q13: 25000 | R13: 25000 | S13: 25000 | T13: 25000 | U13: 25000 | V13: 25000 | W13: 25000 | X13: 25000 | Y13: 25000 | Z13: 25000 | AA13: 25000 | AB13: 25000 | AC13: 25000 | AD13: 25000 | AE13: 25000 | AF13: 25000 | AG13: 25000
E14: EBITDA | G14: USD m | H14: {=_xlfn.BYROW(_xlfn.ANCHORARRAY( J14), _xleta.SUM )} -> 469946.58 | J14: {=_xlfn.ANCHORARRAY( J11) -_xlfn.ANCHORARRAY( J13)} -> -2870.5 | K14: 11882.5 | L14: 4506 | M14: 34012 | N14: 1393.85 | O14: 14924.176 | P14: 6311.0252 | Q14: 37622.05 | R14: 3079.0411 | S14: 20057.192 | T14: 8219.6362 | U14: 41439.272 | V14: 4820.8737 | W14: 24396.458 | X14: 10220.02 | Y14: 45440.04 | Z14: 6735.9968 | AA14: 27893.328 | AB14: 12413.267 | AC14: 49676.173 | AD14: 8693.9634 | AE14: 30397.04 | AF14: 14561.058 | AG14: 54122.115
E16: Current taxes | G16: USD m | H16: {=_xlfn.BYROW(_xlfn.ANCHORARRAY( J16), _xleta.SUM )} -> 165485.98 | J16: {=IF(_xlfn.ANCHORARRAY( J14) < 0, 0,_xlfn.ANCHORARRAY( J14) * Case2Data!$E$27 )} -> 0 | K16: 4158.875 | L16: 1577.1 | M16: 11904.2 | N16: 487.8475 | O16: 5223.4617 | P16: 2208.8588 | Q16: 13167.718 | R16: 1077.6644 | S16: 7020.0172 | T16: 2876.8727 | U16: 14503.745 | V16: 1687.3058 | W16: 8538.7602 | X16: 3577.007 | Y16: 15904.014 | Z16: 2357.5989 | AA16: 9762.6648 | AB16: 4344.6434 | AC16: 17386.66 | AD16: 3042.8872 | AE16: 10638.964 | AF16: 5096.3702 | AG16: 18942.74
E18: Net Income | G18: USD | H18: {=_xlfn.BYROW(_xlfn.ANCHORARRAY( J18), _xleta.SUM )} -> 304460.6 | J18: {=_xlfn.ANCHORARRAY( J14) -_xlfn.ANCHORARRAY( J16)} -> -2870.5 | K18: 7723.625 | L18: 2928.9 | M18: 22107.8 | N18: 906.0025 | O18: 9700.7147 | P18: 4102.1664 | Q18: 24454.333 | R18: 2001.3767 | S18: 13037.175 | T18: 5342.7635 | U18: 26935.527 | V18: 3133.5679 | W18: 15857.697 | X18: 6643.013 | Y18: 29536.026 | Z18: 4378.3979 | AA18: 18130.663 | AB18: 8068.6234 | AC18: 32289.512 | AD18: 5651.0762 | AE18: 19758.076 | AF18: 9464.6875 | AG18: 35179.375
C21: LIFO
E23: Revenue | G23: USD m | H23: {=_xlfn.BYROW(_xlfn.ANCHORARRAY( J23), _xleta.SUM )} -> 5392141.3 | J23: {=_xlfn.ANCHORARRAY( Calculations!J$43)} -> 110644.5 | K23: 184407.5 | L23: 147526 | M23: 295052 | N23: 119334.6 | O23: 198891 | P23: 159112.8 | Q23: 318225.6 | R23: 128722.94 | S23: 214538.23 | T23: 171630.58 | U23: 343261.17 | V23: 138819.5 | W23: 231365.83 | X23: 185092.66 | Y23: 370185.32 | Z23: 149760.7 | AA23: 249601.17 | AB23: 199680.94 | AC23: 399361.87 | AD23: 161538.96 | AE23: 269231.6 | AF23: 215385.28 | AG23: 430770.55
E24: LIFO Cost of Goods of Sold | G24: USD m | H24: {=_xlfn.BYROW(_xlfn.ANCHORARRAY( J24), _xleta.SUM )} -> 4356910.9 | J24: {=_xlfn.ANCHORARRAY( Calculations!J$185)} -> 88515 | K24: 147525 | L24: 118020 | M24: 236040 | N24: 95851.331 | O24: 159752.22 | P24: 127801.77 | Q24: 255603.55 | R24: 103808.21 | S24: 173013.69 | T24: 138410.95 | U24: 276821.9 | V24: 112404.48 | W24: 187340.8 | X24: 149872.64 | Y24: 299745.28 | Z24: 121757.14 | AA24: 202928.56 | AB24: 162342.85 | AC24: 324368.27 | AD24: 131868.16 | AE24: 219780.27 | AF24: 175824.22 | AG24: 347514.61
E25: Gross profit | G25: USD m | H25: {=_xlfn.BYROW(_xlfn.ANCHORARRAY( J25), _xleta.SUM )} -> 1035230.4 | J25: {=_xlfn.ANCHORARRAY( J23) -_xlfn.ANCHORARRAY( J24)} -> 22129.5 | K25: 36882.5 | L25: 29506 | M25: 59012 | N25: 23483.269 | O25: 39138.781 | P25: 31311.025 | Q25: 62622.05 | R25: 24914.727 | S25: 41524.545 | T25: 33219.636 | U25: 66439.272 | V25: 26415.015 | W25: 44025.025 | X25: 35220.02 | Y25: 70440.04 | Z25: 28003.565 | AA25: 46672.608 | AB25: 37338.086 | AC25: 74993.604 | AD25: 29670.793 | AE25: 49451.322 | AF25: 39561.058 | AG25: 83255.939
E27: Overheads | G27: USD m | H27: {=_xlfn.BYROW(_xlfn.ANCHORARRAY( J27), _xleta.SUM )} -> 600000 | J27: {=_xlfn.SEQUENCE( 1, quarters * years, Case2Data!$E$25 / 1000, 0 )} -> 25000 | K27: 25000 | L27: 25000 | M27: 25000 | N27: 25000 | O27: 25000 | P27: 25000 | Q27: 25000 | R27: 25000 | S27: 25000 | T27: 25000 | U27: 25000 | V27: 25000 | W27: 25000 | X27: 25000 | Y27: 25000 | Z27: 25000 | AA27: 25000 | AB27: 25000 | AC27: 25000 | AD27: 25000 | AE27: 25000 | AF27: 25000 | AG27: 25000
E28: EBITDA | G28: USD m | H28: {=_xlfn.BYROW(_xlfn.ANCHORARRAY( J28), _xleta.SUM )} -> 435230.38 | J28: {=_xlfn.ANCHORARRAY( J25) -_xlfn.ANCHORARRAY( J27)} -> -2870.5 | K28: 11882.5 | L28: 4506 | M28: 34012 | N28: -1516.7311 | O28: 14138.781 | P28: 6311.0252 | Q28: 37622.05 | R28: -85.272864 | S28: 16524.545 | T28: 8219.6362 | U28: 41439.272 | V28: 1415.015 | W28: 19025.025 | X28: 10220.02 | Y28: 45440.04 | Z28: 3003.5647 | AA28: 21672.608 | AB28: 12338.086 | AC28: 49993.604 | AD28: 4670.7933 | AE28: 24451.322 | AF28: 14561.058 | AG28: 58255.939
E30: Current taxes | G30: USD m | H30: {=_xlfn.BYROW(_xlfn.ANCHORARRAY( J30), _xleta.SUM )} -> 153896.01 | J30: {=IF(_xlfn.ANCHORARRAY( J28) < 0, 0,_xlfn.ANCHORARRAY( J28) * Case2Data!$E$27 )} -> 0 | K30: 4158.875 | L30: 1577.1 | M30: 11904.2 | N30: 0 | O30: 4948.5735 | P30: 2208.8588 | Q30: 13167.718 | R30: 0 | S30: 5783.5908 | T30: 2876.8727 | U30: 14503.745 | V30: 495.25525 | W30: 6658.7588 | X30: 3577.007 | Y30: 15904.014 | Z30: 1051.2476 | AA30: 7585.4127 | AB30: 4318.3302 | AC30: 17497.761 | AD30: 1634.7777 | AE30: 8557.9628 | AF30: 5096.3702 | AG30: 20389.579
E32: Net Income | G32: USD | H32: {=_xlfn.BYROW(_xlfn.ANCHORARRAY( J32), _xleta.SUM )} -> 281334.37 | J32: {=_xlfn.ANCHORARRAY( J28) -_xlfn.ANCHORARRAY( J30)} -> -2870.5 | K32: 7723.625 | L32: 2928.9 | M32: 22107.8 | N32: -1516.7311 | O32: 9190.208 | P32: 4102.1664 | Q32: 24454.333 | R32: -85.272864 | S32: 10740.954 | T32: 5342.7635 | U32: 26935.527 | V32: 919.75975 | W32: 12366.266 | X32: 6643.013 | Y32: 29536.026 | Z32: 1952.317 | AA32: 14087.195 | AB32: 8019.7561 | AC32: 32495.843 | AD32: 3036.0156 | AE32: 15893.359 | AF32: 9464.6875 | AG32: 37866.36
B35: Balance sheet - inventory
C37: FIFO
E39: =Calculations!E98 -> Inventory opening balance | G39: =Calculations!G98 -> USD | J39: =Calculations!J98 -> 0 | K39: =Calculations!K98 -> 88515 | L39: =Calculations!L98 -> 118020 | M39: =Calculations!M98 -> 177030 | N39: =Calculations!N98 -> 118020 | O39: =Calculations!O98 -> 207653.21 | P39: =Calculations!P98 -> 231260.35 | Q39: =Calculations!Q98 -> 286032.54 | ... AG39: =Calculations!AG98 -> 419212.3
D40: add | E40: =Calculations!E99 -> Production | G40: =Calculations!G99 -> USD | J40: =Calculations!J99 -> 177030 | K40: =Calculations!K99 -> 177030 | L40: =Calculations!L99 -> 177030 | M40: =Calculations!M99 -> 177030 | N40: =Calculations!N99 -> 182573.96 | O40: =Calculations!O99 -> 182573.96 | P40: =Calculations!P99 -> 182573.96 | Q40: =Calculations!Q99 -> 182573.96 | ... AG40: =Calculations!AG99 -> 206644.31
D41: minus | E41: =Calculations!E100 -> Units sold from inventory | G41: =Calculations!G100 -> USD | J41: =Calculations!J100 -> 0 | K41: =Calculations!K100 -> -88515 | L41: =Calculations!L100 -> -118020 | M41: =Calculations!M100 -> -177030 | N41: =Calculations!N100 -> -92940.75 | O41: =Calculations!O100 -> -158966.82 | P41: =Calculations!P100 -> -127801.77 | Q41: =Calculations!Q100 -> -255603.55 | ... AG41: =Calculations!AG100 -> -351648.44
D42: minus | E42: =Calculations!E101 -> Units sold from current production | G42: =Calculations!G101 -> USD | J42: =Calculations!J101 -> -88515 | K42: =Calculations!K101 -> -59010 | L42: =Calculations!L101 -> 0 | M42: =Calculations!M101 -> -59010 | N42: =Calculations!N101 -> 0 | O42: =Calculations!O101 -> 0 | P42: =Calculations!P101 -> 0 | Q42: =Calculations!Q101 -> 0 | ... AG42: =Calculations!AG101 -> 0
E43: =Calculations!E102 -> Inventory closing balance | G43: =Calculations!G102 -> USD | J43: =Calculations!J102 -> 88515 | K43: =Calculations!K102 -> 118020 | L43: =Calculations!L102 -> 177030 | M43: =Calculations!M102 -> 118020 | N43: =Calculations!N102 -> 207653.21 | O43: =Calculations!O102 -> 231260.35 | P43: =Calculations!P102 -> 286032.54 | Q43: =Calculations!Q102 -> 213002.96 | ... AG43: =Calculations!AG102 -> 274208.18
C45: LIFO
E47: =Calculations!E173 -> Inventory opening balance | G47: =Calculations!G173 -> USD | J47: =Calculations!J173 -> 0 | K47: =Calculations!K173 -> 88515 | L47: =Calculations!L173 -> 118020 | M47: =Calculations!M173 -> 177030 | N47: =Calculations!N173 -> 118020 | O47: =Calculations!O173 -> 204742.63 | P47: =Calculations!P173 -> 227564.38 | Q47: =Calculations!Q173 -> 282336.57 | ... AG47: =Calculations!AG173 -> 380362.29
D48: add | E48: =Calculations!E174 -> Production | G48: =Calculations!G174 -> USD | J48: =Calculations!J174 -> 177030 | K48: =Calculations!K174 -> 177030 | L48: =Calculations!L174 -> 177030 | M48: =Calculations!M174 -> 177030 | N48: =Calculations!N174 -> 182573.96 | O48: =Calculations!O174 -> 182573.96 | P48: =Calculations!P174 -> 182573.96 | Q48: =Calculations!Q174 -> 182573.96 | ... AG48: =Calculations!AG174 -> 206644.31
D49: minus | E49: =Calculations!E175 -> Units sold from current production | G49: =Calculations!G175 -> USD | J49: =Calculations!J175 -> -88515 | K49: =Calculations!K175 -> -147525 | L49: =Calculations!L175 -> -118020 | M49: =Calculations!M175 -> -177030 | N49: =Calculations!N175 -> -95851.331 | O49: =Calculations!O175 -> -159752.22 | P49: =Calculations!P175 -> -127801.77 | Q49: =Calculations!Q175 -> -182573.96 | ... AG49: =Calculations!AG175 -> -206644.31
D50: minus | E50: =Calculations!E176 -> Units sold from inventory | G50: =Calculations!G176 -> USD | J50: =Calculations!J176 -> 0 | K50: =Calculations!K176 -> 0 | L50: =Calculations!L176 -> 0 | M50: =Calculations!M176 -> -59010 | N50: =Calculations!N176 -> 0 | O50: =Calculations!O176 -> 0 | P50: =Calculations!P176 -> 0 | Q50: =Calculations!Q176 -> -73029.586 | ... AG50: =Calculations!AG176 -> -140870.3
E51: =Calculations!E177 -> Inventory closing balance | G51: =Calculations!G177 -> USD | J51: =Calculations!J177 -> 88515 | K51: =Calculations!K177 -> 118020 | L51: =Calculations!L177 -> 177030 | M51: =Calculations!M177 -> 118020 | N51: =Calculations!N177 -> 204742.63 | O51: =Calculations!O177 -> 227564.38 | P51: =Calculations!P177 -> 282336.57 | Q51: =Calculations!Q177 -> 209306.98 | ... AG51: =Calculations!AG177 -> 239491.99
B54: Answers

Sheet Calculations
A1: =company -> Thermin Corp
A2: {=topic} -> CFM Topic: Working capital | J2: {=_xlfn.ANCHORARRAY( J7)} -> 43831 | K2: 43922 | L2: 44013 | M2: 44105 | N2: 44197 | O2: 44287 | P2: 44378 | Q2: 44470 | R2: 44562 | S2: 44652 | T2: 44743 | U2: 44835 | V2: 44927 | W2: 45017 | X2: 45108 | Y2: 45200 | Z2: 45292 | AA2: 45383 | AB2: 45474 | AC2: 45566 | AD2: 45658 | AE2: 45748 | AF2: 45839 | AG2: 45931
A3: CALCULATIONS SCHEDULE | F3: Constant | G3: Unit | H3: Total | J3: {=_xlfn.ANCHORARRAY(J8)} -> 43921 | K3: 44012 | L3: 44104 | M3: 44196 | N3: 44286 | O3: 44377 | P3: 44469 | Q3: 44561 | R3: 44651 | S3: 44742 | T3: 44834 | U3: 44926 | V3: 45016 | W3: 45107 | X3: 45199 | Y3: 45291 | Z3: 45382 | AA3: 45473 | AB3: 45565 | AC3: 45657 | AD3: 45747 | AE3: 45838 | AF3: 45930 | AG3: 46022
B5: Model timeline
E7: Model period beginning | G7: date | J7: {=EDATE( start_date, _xlfn.SEQUENCE( 1, years * quarters, 0, 3 ) )} -> 43831 | K7: 43922 | L7: 44013 | M7: 44105 | N7: 44197 | O7: 44287 | P7: 44378 | Q7: 44470 | R7: 44562 | S7: 44652 | T7: 44743 | U7: 44835 | V7: 44927 | W7: 45017 | X7: 45108 | Y7: 45200 | Z7: 45292 | AA7: 45383 | AB7: 45474 | AC7: 45566 | AD7: 45658 | AE7: 45748 | AF7: 45839 | AG7: 45931
E8: Model period ending | G8: date | J8: {=EOMONTH( start_date, _xlfn.SEQUENCE( 1, years * quarters, 2, 3 ) )} -> 43921 | K8: 44012 | L8: 44104 | M8: 44196 | N8: 44286 | O8: 44377 | P8: 44469 | Q8: 44561 | R8: 44651 | S8: 44742 | T8: 44834 | U8: 44926 | V8: 45016 | W8: 45107 | X8: 45199 | Y8: 45291 | Z8: 45382 | AA8: 45473 | AB8: 45565 | AC8: 45657 | AD8: 45747 | AE8: 45838 | AF8: 45930 | AG8: 46022
E10: Quarter | G10: label | J10: {=_xlfn.LET( _xlpm.model_period_ending, MONTH(_xlfn.ANCHORARRAY( J8) ), _xlpm.model_period_ending / 3 )} -> 1 | K10: 2 | L10: 3 | M10: 4 | N10: 1 | O10: 2 | P10: 3 | Q10: 4 | R10: 1 | S10: 2 | T10: 3 | U10: 4 | V10: 1 | W10: 2 | X10: 3 | Y10: 4 | Z10: 1 | AA10: 2 | AB10: 3 | AC10: 4 | AD10: 1 | AE10: 2 | AF10: 3 | AG10: 4
E11: Year | G11: label | J11: {=YEAR(_xlfn.ANCHORARRAY( J8) )} -> 2020 | K11: 2020 | L11: 2020 | M11: 2020 | N11: 2021 | O11: 2021 | P11: 2021 | Q11: 2021 | R11: 2022 | S11: 2022 | T11: 2022 | U11: 2022 | V11: 2023 | W11: 2023 | X11: 2023 | Y11: 2023 | Z11: 2024 | AA11: 2024 | AB11: 2024 | AC11: 2024 | AD11: 2025 | AE11: 2025 | AF11: 2025 | AG11: 2025
B13: Revenue
C15: Volume
E17: Demand | G17: units | J17: {=_xlfn.LET( _xlpm.first_year_demand, Case2Data!$E$11:$H$11, _xlpm.first_year_quarters, Case2Data!$E$10:$H$10, _xlpm.current_quarter, "Q" &_xlfn.ANCHORARRAY( Calculations!J10), _xlpm.demand, INDEX( _xlpm.first_year_demand, MATCH( _xlpm.current_quarter, _xlpm.first_year_quarters, 0 ) ), _xlpm.growth_rate, Case2Data!$E$13, _xlpm.current_year,_xlfn.ANCHORARRAY( Calculations!J8), _xlpm.period, YEAR( _xlpm.current_year ) - YEAR( start_date ), _xlpm.growth_factor, IF( _xlpm.period = 0, 1, ( 1 + _xlpm.growth_rate ) ^ _xlpm.period ), _xlpm.demand * _xlpm.growth_factor )} -> 150000 | K17: 250000 | L17: 200000 | M17: 400000 | N17: 157500 | O17: 262500 | P17: 210000 | Q17: 420000 | R17: 165375 | S17: 275625 | T17: 220500 | U17: 441000 | V17: 173643.75 | W17: 289406.25 | X17: 231525 | Y17: 463050 | Z17: 182325.94 | AA17: 303876.56 | AB17: 243101.25 | AC17: 486202.5 | AD17: 191442.23 | AE17: 319070.39 | AF17: 255256.31 | AG17: 510512.63
E19: Inventory beginning balance | G19: units | J19: {=_xlfn.DROP( _xlfn.HSTACK( Case2Data!$E$30,_xlfn.ANCHORARRAY( J22) ), , -1 )} -> 0 | K19: 150000 | L19: 200000 | M19: 300000 | N19: 200000 | O19: 342500 | P19: 380000 | Q19: 470000 | R19: 350000 | S19: 484625 | T19: 509000 | U19: 588500 | V19: 447500 | W19: 573856.25 | X19: 584450 | Y19: 652925 | Z19: 489875 | AA19: 607549.06 | AB19: 603672.5 | AC19: 660571.25 | AD19: 474368.75 | AE19: 582926.52 | AF19: 563856.12 | AG19: 608599.81
E20: Production | G20: units | J20: {=_xlfn.SEQUENCE( 1, years * quarters, Case2Data!$E$8, 0 )} -> 300000 | K20: 300000 | L20: 300000 | M20: 300000 | N20: 300000 | O20: 300000 | P20: 300000 | Q20: 300000 | R20: 300000 | S20: 300000 | T20: 300000 | U20: 300000 | V20: 300000 | W20: 300000 | X20: 300000 | Y20: 300000 | Z20: 300000 | AA20: 300000 | AB20: 300000 | AC20: 300000 | AD20: 300000 | AE20: 300000 | AF20: 300000 | AG20: 300000
E21: Demand | J21: {=_xlfn.ANCHORARRAY( J17) * -1} -> -150000 | K21: -250000 | L21: -200000 | M21: -400000 | N21: -157500 | O21: -262500 | P21: -210000 | Q21: -420000 | R21: -165375 | S21: -275625 | T21: -220500 | U21: -441000 | V21: -173643.75 | W21: -289406.25 | X21: -231525 | Y21: -463050 | Z21: -182325.94 | AA21: -303876.56 | AB21: -243101.25 | AC21: -486202.5 | AD21: -191442.23 | AE21: -319070.39 | AF21: -255256.31 | AG21: -510512.63
E22: Inventory ending balance | G22: units | J22: {=_xlfn.LET( _xlpm.production,_xlfn.ANCHORARRAY( J20), _xlpm.demand,_xlfn.ANCHORARRAY( J21), _xlpm.change, _xlpm.production + _xlpm.demand, _xlfn.SCAN( 0, _xlpm.change, _xleta.SUM ))} -> 150000 | K22: 200000 | L22: 300000 | M22: 200000 | N22: 342500 | O22: 380000 | P22: 470000 | Q22: 350000 | R22: 484625 | S22: 509000 | T22: 588500 | U22: 447500 | V22: 573856.25 | W22: 584450 | X22: 652925 | Y22: 489875 | Z22: 607549.06 | AA22: 603672.5 | AB22: 660571.25 | AC22: 474368.75 | AD22: 582926.52 | AE22: 563856.12 | AF22: 608599.81 | AG22: 398087.19
E24: Units sold | G24: units | J24: {=_xlfn.LET( _xlpm.demand,_xlfn.ANCHORARRAY( J17), _xlpm.inventory_available_for_sale,_xlfn.ANCHORARRAY( J19) +_xlfn.ANCHORARRAY( J20), IF( _xlpm.inventory_available_for_sale < _xlpm.demand, _xlpm.inventory_available_for_sale, _xlpm.demand ) )} -> 150000 | K24: 250000 | L24: 200000 | M24: 400000 | N24: 157500 | O24: 262500 | P24: 210000 | Q24: 420000 | R24: 165375 | S24: 275625 | T24: 220500 | U24: 441000 | V24: 173643.75 | W24: 289406.25 | X24: 231525 | Y24: 463050 | Z24: 182325.94 | AA24: 303876.56 | AB24: 243101.25 | AC24: 486202.5 | AD24: 191442.23 | AE24: 319070.39 | AF24: 255256.31 | AG24: 510512.63
C26: Costs of production
E28: Hourly salary rate | G28: USD / hr | J28: {=_xlfn.LET( _xlpm.first_year_value, Case2Data!$E$16, _xlpm.year_on_year_growth, Case2Data!$F$16, _xlpm.current_year,_xlfn.ANCHORARRAY( Calculations!$J$3), _xlpm.period, YEAR( _xlpm.current_year ) - YEAR( start_date ), _xlpm.growth_factor, IF( _xlpm.period = 0, 1, ( 1 + _xlpm.year_on_year_growth ) ^ _xlpm.period ), ROUND( _xlpm.first_year_value * _xlpm.growth_factor, 2 ) )} -> 18.5 | K28: 18.5 | L28: 18.5 | M28: 18.5 | N28: 19.61 | O28: 19.61 | P28: 19.61 | Q28: 19.61 | R28: 20.79 | S28: 20.79 | T28: 20.79 | U28: 20.79 | V28: 22.03 | W28: 22.03 | X28: 22.03 | Y28: 22.03 | Z28: 23.36 | AA28: 23.36 | AB28: 23.36 | AC28: 23.36 | AD28: 24.76 | AE28: 24.76 | AF28: 24.76 | AG28: 24.76
E29: Production time | G29: hr / unit | J29: {=_xlfn.LET( _xlpm.first_year_value, Case2Data!$E$17, _xlpm.year_on_year_growth, Case2Data!$F$17, _xlpm.current_year,_xlfn.ANCHORARRAY( Calculations!$J$3), _xlpm.period, YEAR( _xlpm.current_year ) - YEAR( start_date ), _xlpm.growth_factor, IF( _xlpm.period = 0, 1, ( 1 + _xlpm.year_on_year_growth ) ^ _xlpm.period ), _xlpm.first_year_value * _xlpm.growth_factor )} -> 14.6 | K29: 14.6 | L29: 14.6 | M29: 14.6 | N29: 14.308 | O29: 14.308 | P29: 14.308 | Q29: 14.308 | R29: 14.02184 | S29: 14.02184 | T29: 14.02184 | U29: 14.02184 | V29: 13.741403 | W29: 13.741403 | X29: 13.741403 | Y29: 13.741403 | Z29: 13.466575 | AA29: 13.466575 | AB29: 13.466575 | AC29: 13.466575 | AD29: 13.197244 | AE29: 13.197244 | AF29: 13.197244 | AG29: 13.197244
E30: Materials | G30: USD / unit | J30: {=_xlfn.LET( _xlpm.first_year_value, Case2Data!$E$18, _xlpm.year_on_year_growth, Case2Data!$F$18, _xlpm.current_year,_xlfn.ANCHORARRAY( Calculations!$J$3), _xlpm.period, YEAR( _xlpm.current_year ) - YEAR( start_date ), _xlpm.growth_factor, IF( _xlpm.period = 0, 1, ( 1 + _xlpm.year_on_year_growth ) ^ _xlpm.period ), _xlpm.first_year_value * _xlpm.growth_factor )} -> 320 | K30: 320 | L30: 320 | M30: 320 | N30: 328 | O30: 328 | P30: 328 | Q30: 328 | R30: 336.2 | S30: 336.2 | T30: 336.2 | U30: 336.2 | V30: 344.605 | W30: 344.605 | X30: 344.605 | Y30: 344.605 | Z30: 353.22012 | AA30: 353.22012 | AB30: 353.22012 | AC30: 353.22012 | AD30: 362.05063 | AE30: 362.05063 | AF30: 362.05063 | AG30: 362.05063
E32: Salaries | G32: USD m | J32: {=_xlfn.LET( _xlpm.production,_xlfn.ANCHORARRAY( J20), _xlpm.time_per_unit,_xlfn.ANCHORARRAY( J29), _xlpm.hourly_rate,_xlfn.ANCHORARRAY( J28), _xlpm.production * _xlpm.time_per_unit * _xlpm.hourly_rate / 1000 )} -> 81030 | K32: 81030 | L32: 81030 | M32: 81030 | N32: 84173.964 | O32: 84173.964 | P32: 84173.964 | Q32: 84173.964 | R32: 87454.216 | S32: 87454.216 | T32: 87454.216 | U32: 87454.216 | V32: 90816.934 | W32: 90816.934 | X32: 90816.934 | Y32: 90816.934 | Z32: 94373.759 | AA32: 94373.759 | AB32: 94373.759 | AC32: 94373.759 | AD32: 98029.126 | AE32: 98029.126 | AF32: 98029.126 | AG32: 98029.126
E33: Materials | G33: USD m | J33: {=_xlfn.LET( _xlpm.production,_xlfn.ANCHORARRAY( J20), _xlpm.material_per_unit,_xlfn.ANCHORARRAY( J30), _xlpm.production * _xlpm.material_per_unit / 1000 )} -> 96000 | K33: 96000 | L33: 96000 | M33: 96000 | N33: 98400 | O33: 98400 | P33: 98400 | Q33: 98400 | R33: 100860 | S33: 100860 | T33: 100860 | U33: 100860 | V33: 103381.5 | W33: 103381.5 | X33: 103381.5 | Y33: 103381.5 | Z33: 105966.04 | AA33: 105966.04 | AB33: 105966.04 | AC33: 105966.04 | AD33: 108615.19 | AE33: 108615.19 | AF33: 108615.19 | AG33: 108615.19
E34: Cost of production | G34: USD m | J34: {=_xlfn.BYCOL( _xlfn.VSTACK(_xlfn.ANCHORARRAY( J32),_xlfn.ANCHORARRAY( J33) ), _xleta.SUM )} -> 177030 | K34: 177030 | L34: 177030 | M34: 177030 | N34: 182573.96 | O34: 182573.96 | P34: 182573.96 | Q34: 182573.96 | R34: 188314.22 | S34: 188314.22 | T34: 188314.22 | U34: 188314.22 | V34: 194198.43 | W34: 194198.43 | X34: 194198.43 | Y34: 194198.43 | Z34: 200339.8 | AA34: 200339.8 | AB34: 200339.8 | AC34: 200339.8 | AD34: 206644.31 | AE34: 206644.31 | AF34: 206644.31 | AG34: 206644.31
E36: Cost per unit | G36: USD / unit | J36: {=_xlfn.LET( _xlpm.production,_xlfn.ANCHORARRAY( J20), _xlpm.cost_of_production,_xlfn.ANCHORARRAY( J34), _xlpm.cost_of_production / _xlpm.production * 1000 )} -> 590.1 | K36: 590.1 | L36: 590.1 | M36: 590.1 | N36: 608.57988 | O36: 608.57988 | P36: 608.57988 | Q36: 608.57988 | R36: 627.71405 | S36: 627.71405 | T36: 627.71405 | U36: 627.71405 | V36: 647.32811 | W36: 647.32811 | X36: 647.32811 | Y36: 647.32811 | Z36: 667.79932 | AA36: 667.79932 | AB36: 667.79932 | AC36: 667.79932 | AD36: 688.81438 | AE36: 688.81438 | AF36: 688.81438 | AG36: 688.81438
E37: Check | H37: {=IF( _xlfn.BYROW(_xlfn.ANCHORARRAY( J37), _xleta.SUM ) = 0, "OK", "Check" )} -> OK | J37: {=_xlfn.LET( _xlpm.hourly_rate,_xlfn.ANCHORARRAY( J28), _xlpm.production_time,_xlfn.ANCHORARRAY( J29), _xlpm.salaries, _xlpm.hourly_rate * _xlpm.production_time, _xlpm.material_cost,_xlfn.ANCHORARRAY( J30), _xlpm.cost_per_unit,_xlfn.ANCHORARRAY( J36), ROUND( _xlpm.cost_per_unit - ( _xlpm.salaries + _xlpm.material_cost ), 2 ) )} -> 0 | K37: 0 | L37: 0 | M37: 0 | N37: 0 | O37: 0 | P37: 0 | Q37: 0 | R37: 0 | S37: 0 | T37: 0 | U37: 0 | V37: 0 | W37: 0 | X37: 0 | Y37: 0 | Z37: 0 | AA37: 0 | AB37: 0 | AC37: 0 | AD37: 0 | AE37: 0 | AF37: 0 | AG37: 0
C39: Revenue
E41: Sell price | G41: USD / unit | J41: {=_xlfn.LET( _xlpm.unit_cost,_xlfn.ANCHORARRAY( J36), _xlpm.mark_up, Case2Data!$E$21, _xlpm.yoy_change, Case2Data!$E$22, _xlpm.period, YEAR(_xlfn.ANCHORARRAY( J$3) ) - YEAR( start_date ), _xlpm.growth_rate, 1 + ( _xlpm.mark_up + ( _xlpm.yoy_change * _xlpm.period ) ), ROUND( _xlpm.unit_cost * _xlpm.growth_rate, 2 ) )} -> 737.63 | K41: 737.63 | L41: 737.63 | M41: 737.63 | N41: 757.68 | O41: 757.68 | P41: 757.68 | Q41: 757.68 | R41: 778.37 | S41: 778.37 | T41: 778.37 | U41: 778.37 | V41: 799.45 | W41: 799.45 | X41: 799.45 | Y41: 799.45 | Z41: 821.39 | AA41: 821.39 | AB41: 821.39 | AC41: 821.39 | AD41: 843.8 | AE41: 843.8 | AF41: 843.8 | AG41: 843.8
E42: Units sold | G42: units | J42: {=_xlfn.ANCHORARRAY( J24)} -> 150000 | K42: 250000 | L42: 200000 | M42: 400000 | N42: 157500 | O42: 262500 | P42: 210000 | Q42: 420000 | R42: 165375 | S42: 275625 | T42: 220500 | U42: 441000 | V42: 173643.75 | W42: 289406.25 | X42: 231525 | Y42: 463050 | Z42: 182325.94 | AA42: 303876.56 | AB42: 243101.25 | AC42: 486202.5 | AD42: 191442.23 | AE42: 319070.39 | AF42: 255256.31 | AG42: 510512.63
E43: Revenue | G43: USD m | J43: {=_xlfn.ANCHORARRAY( J41) *_xlfn.ANCHORARRAY( J42) / 1000} -> 110644.5 | K43: 184407.5 | L43: 147526 | M43: 295052 | N43: 119334.6 | O43: 198891 | P43: 159112.8 | Q43: 318225.6 | R43: 128722.94 | S43: 214538.23 | T43: 171630.58 | U43: 343261.17 | V43: 138819.5 | W43: 231365.83 | X43: 185092.66 | Y43: 370185.32 | Z43: 149760.7 | AA43: 249601.17 | AB43: 199680.94 | AC43: 399361.87 | AD43: 161538.96 | AE43: 269231.6 | AF43: 215385.28 | AG43: 430770.55
B45: FIFO Cost of Goods Sold and Inventory
D47: FIFO units sold
E49: Production | G49: units | J49: {=_xlfn.ANCHORARRAY( $J$20)} -> 300000 | K49: 300000 | L49: 300000 | M49: 300000 | N49: 300000 | O49: 300000 | P49: 300000 | Q49: 300000 | R49: 300000 | S49: 300000 | T49: 300000 | U49: 300000 | V49: 300000 | W49: 300000 | X49: 300000 | Y49: 300000 | Z49: 300000 | AA49: 300000 | AB49: 300000 | AC49: 300000 | AD49: 300000 | AE49: 300000 | AF49: 300000 | AG49: 300000
E50: Units sold | G50: units | J50: {=_xlfn.ANCHORARRAY( $J$24)} -> 150000 | K50: 250000 | L50: 200000 | M50: 400000 | N50: 157500 | O50: 262500 | P50: 210000 | Q50: 420000 | R50: 165375 | S50: 275625 | T50: 220500 | U50: 441000 | V50: 173643.75 | W50: 289406.25 | X50: 231525 | Y50: 463050 | Z50: 182325.94 | AA50: 303876.56 | AB50: 243101.25 | AC50: 486202.5 | AD50: 191442.23 | AE50: 319070.39 | AF50: 255256.31 | AG50: 510512.63
E51: Inventory beginning balance | G51: units | J51: {=_xlfn.ANCHORARRAY( $J$19)} -> 0 | K51: 150000 | L51: 200000 | M51: 300000 | N51: 200000 | O51: 342500 | P51: 380000 | Q51: 470000 | R51: 350000 | S51: 484625 | T51: 509000 | U51: 588500 | V51: 447500 | W51: 573856.25 | X51: 584450 | Y51: 652925 | Z51: 489875 | AA51: 607549.06 | AB51: 603672.5 | AC51: 660571.25 | AD51: 474368.75 | AE51: 582926.52 | AF51: 563856.12 | AG51: 608599.81
E53: Units sold from inventory | G53: units | J53: {=_xlfn.LET( _xlpm.units_sold,_xlfn.ANCHORARRAY( J50), _xlpm.inventory_beginning_balance,_xlfn.ANCHORARRAY( J51), IF( _xlpm.inventory_beginning_balance < _xlpm.units_sold, _xlpm.inventory_beginning_balance, _xlpm.units_sold ) )} -> 0 | K53: 150000 | L53: 200000 | M53: 300000 | N53: 157500 | O53: 262500 | P53: 210000 | Q53: 420000 | R53: 165375 | S53: 275625 | T53: 220500 | U53: 441000 | V53: 173643.75 | W53: 289406.25 | X53: 231525 | Y53: 463050 | Z53: 182325.94 | AA53: 303876.56 | AB53: 243101.25 | AC53: 486202.5 | AD53: 191442.23 | AE53: 319070.39 | AF53: 255256.31 | AG53: 510512.63
E54: Units sold from current production | G54: units | J54: {=_xlfn.LET( _xlpm.units_sold,_xlfn.ANCHORARRAY( J50), _xlpm.units_sold_from_inventory,_xlfn.ANCHORARRAY( J53), _xlpm.units_sold - _xlpm.units_sold_from_inventory )} -> 150000 | K54: 100000 | L54: 0 | M54: 100000 | N54: 0 | O54: 0 | P54: 0 | Q54: 0 | R54: 0 | S54: 0 | T54: 0 | U54: 0 | V54: 0 | W54: 0 | X54: 0 | Y54: 0 | Z54: 0 | AA54: 0 | AB54: 0 | AC54: 0 | AD54: 0 | AE54: 0 | AF54: 0 | AG54: 0
E55: FIFO units sold | G55: units | J55: {=_xlfn.ANCHORARRAY( J53) +_xlfn.ANCHORARRAY( J54)} -> 150000 | K55: 250000 | L55: 200000 | M55: 400000 | N55: 157500 | O55: 262500 | P55: 210000 | Q55: 420000 | R55: 165375 | S55: 275625 | T55: 220500 | U55: 441000 | V55: 173643.75 | W55: 289406.25 | X55: 231525 | Y55: 463050 | Z55: 182325.94 | AA55: 303876.56 | AB55: 243101.25 | AC55: 486202.5 | AD55: 191442.23 | AE55: 319070.39 | AF55: 255256.31 | AG55: 510512.63
D57: FIFO COGS from current production
E59: Cost per unit | G59: USD / unit | J59: {=_xlfn.ANCHORARRAY( $J$36)} -> 590.1 | K59: 590.1 | L59: 590.1 | M59: 590.1 | N59: 608.57988 | O59: 608.57988 | P59: 608.57988 | Q59: 608.57988 | R59: 627.71405 | S59: 627.71405 | T59: 627.71405 | U59: 627.71405 | V59: 647.32811 | W59: 647.32811 | X59: 647.32811 | Y59: 647.32811 | Z59: 667.79932 | AA59: 667.79932 | AB59: 667.79932 | AC59: 667.79932 | AD59: 688.81438 | AE59: 688.81438 | AF59: 688.81438 | AG59: 688.81438
E60: Units sold from current production | G60: units | J60: {=_xlfn.ANCHORARRAY( $J$54)} -> 150000 | K60: 100000 | L60: 0 | M60: 100000 | N60: 0 | O60: 0 | P60: 0 | Q60: 0 | R60: 0 | S60: 0 | T60: 0 | U60: 0 | V60: 0 | W60: 0 | X60: 0 | Y60: 0 | Z60: 0 | AA60: 0 | AB60: 0 | AC60: 0 | AD60: 0 | AE60: 0 | AF60: 0 | AG60: 0
...

Sheet Case2Data
B2: Thermin Corp forecast model - Assumptions
B4: Assumption | D4: Units | E4: Value
B6: Model start date | D6: [date] | E6: 43831
B8: Production | D8: [units / quarter] | E8: 300000
E10: Q1 | F10: Q2 | G10: Q3 | H10: Q4
B11: Year 1 demand | D11: [units] | E11: 150000 | F11: 250000 | G11: 200000 | H11: 400000
B13: Demand growth YoY | D13: [%] | E13: 0.05
B15: Production costs | E15: Year 1 | F15: % ∆ YoY | G15: Note
C16: Salaries | D16: [$ / hr] | E16: 18.5 | F16: 0.06 | G16: Rounded to nearest $0.01
C17: Production time | D17: [hrs / unit] | E17: 14.6 | F17: -0.02 | G17: Not rounded
C18: Materials | D18: [$ / unit] | E18: 320 | F18: 0.025 | G18: Not rounded
B20: Mark-up
C21: Year 1 mark-up | D21: [%] | E21: 0.25
C22: YoY change | D22: [% pts] | E22: -0.005
C23: Note: final sale price rounded to nearest $0.01
B25: Overhead | D25: [$ / quarter] | E25: 25000000
B27: Tax rate | D27: [%] | E27: 0.35
B29: Inventory Balance | D29: [$] | E29: 0
C30: ="As at "&TEXT(E6,"dd-mm-yy") -> As at 01-01-20 | D30: [units] | E30: 0
C33: Company name | D33: Thermin Corp
C34: Topic | D34: Working capital
C35: Model years | D35: 6 | E35: year
C36: Number of periods | D36: 4 | E36: quarters

Sheet Tmp
