Workbook
Name Capacity: CaseData!$E$4
Name company: LEFT( CaseData!$A$1, 20 )
Name homeGames: 'AltSolution (Daily Sales)'!$I$48
Name homeGames: 'CaseSolution (Original)'!$G$48
Name periods: Calculations!$F$9
Name SeasonTicketPrice: CaseData!$E$3
Name soldPrice: 'AltSolution (Daily Sales)'!$E$3
Name soldPrice: 'CaseSolution (Original)'!$E$3
Name SpreadSTs: CaseData!$E$5
Name topic: "CFM Topic: " & CaseData!$J$24

Sheet Calculations
A1: {=company} -> Wichita Warblers Inc
A2: {=topic} -> CFM Topic: Working Capital
A3: CALCULATIONS SCHEDULE | F3: Constant | G3: Unit | H3: Total | J3: {=_xlfn.ANCHORARRAY(J11)} -> 44003 | K3: 44004 | L3: 44005 | M3: 44006 | N3: 44007 | O3: 44008 | P3: 44009 | Q3: 44010 | R3: 44011 | S3: 44012 | T3: 44013 | U3: 44014 | V3: 44015 | W3: 44016 | X3: 44017 | Y3: 44018 | Z3: 44019 | AA3: 44020 | AB3: 44021 | AC3: 44022 | AD3: 44023 | AE3: 44024 | AF3: 44025 | AG3: 44026 | AH3: 44027 | AI3: 44028 | AJ3: 44029 | AK3: 44030 | AL3: 44031 | AM3: 44032 | AN3: 44033 | AO3: 44034 | AP3: 44035 | AQ3: 44036 | AR3: 44037 | AS3: 44038 | AT3: 44039 | AU3: 44040 | AV3: 44041 | AW3: 44042 | AX3: 44043 | AY3: 44044 | AZ3: 44045 | BA3: 44046 | BB3: 44047 | BC3: 44048 | BD3: 44049 | BE3: 44050 | BF3: 44051 | BG3: 44052 | BH3: 44053 | BI3: 44054 | BJ3: 44055 | BK3: 44056 | BL3: 44057 | BM3: 44058 | BN3: 44059 | BO3: 44060 | BP3: 44061 | BQ3: 44062 | BR3: 44063 | BS3: 44064 | BT3: 44065 | BU3: 44066 | BV3: 44067 | BW3: 44068 | BX3: 44069 | BY3: 44070 | BZ3: 44071 | CA3: 44072 | CB3: 44073 | CC3: 44074 | CD3: 44075 | CE3: 44076 | CF3: 44077 | CG3: 44078 | CH3: 44079 | CI3: 44080 | CJ3: 44081 | CK3: 44082 | CL3: 44083 | CM3: 44084 | CN3: 44085 | CO3: 44086 | CP3: 44087 | CQ3: 44088 | CR3: 44089 | CS3: 44090 | CT3: 44091 | CU3: 44092 | CV3: 44093 | CW3: 44094 | CX3: 44095 | CY3: 44096 | CZ3: 44097 | DA3: 44098 | DB3: 44099 | DC3: 44100 | DD3: 44101 | DE3: 44102 | DF3: 44103 | DG3: 44104 | DH3: 44105 | DI3: 44106 | DJ3: 44107 | DK3: 44108 | DL3: 44109 | DM3: 44110 | DN3: 44111 | DO3: 44112 | DP3: 44113 | DQ3: 44114 | DR3: 44115 | DS3: 44116 | DT3: 44117 | DU3: 44118 | DV3: 44119 | DW3: 44120 | DX3: 44121 | DY3: 44122 | DZ3: 44123 | EA3: 44124 | EB3: 44125 | EC3: 44126 | ED3: 44127 | EE3: 44128 | EF3: 44129 | EG3: 44130 | EH3: 44131 | EI3: 44132 | EJ3: 44133 | EK3: 44134 | EL3: 44135 | EM3: 44136 | EN3: 44137 | EO3: 44138 | EP3: 44139 | EQ3: 44140 | ER3: 44141 | ES3: 44142 | ET3: 44143 | EU3: 44144 | EV3: 44145 | EW3: 44146 | EX3: 44147 | EY3: 44148 | EZ3: 44149 | FA3: 44150 | FB3: 44151 | FC3: 44152 | FD3: 44153 | FE3: 44154 | FF3: 44155 | FG3: 44156 | FH3: 44157 | FI3: 44158 | FJ3: 44159 | FK3: 44160 | FL3: 44161 | FM3: 44162 | FN3: 44163 | FO3: 44164 | FP3: 44165 | FQ3: 44166 | FR3: 44167 | FS3: 44168 | FT3: 44169 | FU3: 44170 | FV3: 44171 | FW3: 44172 | FX3: 44173 | FY3: 44174 | FZ3: 44175 | GA3: 44176 | GB3: 44177 | GC3: 44178 | GD3: 44179 | GE3: 44180 | GF3: 44181 | GG3: 44182 | GH3: 44183 | GI3: 44184 | GJ3: 44185 | GK3: 44186 | GL3: 44187 | GM3: 44188 | GN3: 44189 | GO3: 44190 | GP3: 44191 | GQ3: 44192 | GR3: 44193 | GS3: 44194 | GT3: 44195 | GU3: 44196 | GV3: 44197 | GW3: 44198 | GX3: 44199 | GY3: 44200 | GZ3: 44201 | HA3: 44202 | HB3: 44203 | HC3: 44204 | HD3: 44205 | HE3: 44206 | HF3: 44207 | HG3: 44208 | HH3: 44209 | HI3: 44210 | HJ3: 44211 | HK3: 44212 | HL3: 44213 | HM3: 44214 | HN3: 44215 | HO3: 44216 | HP3: 44217 | HQ3: 44218 | HR3: 44219 | HS3: 44220 | HT3: 44221 | HU3: 44222 | HV3: 44223 | HW3: 44224 | HX3: 44225 | HY3: 44226 | HZ3: 44227 | IA3: 44228 | IB3: 44229 | IC3: 44230 | ID3: 44231 | IE3: 44232 | IF3: 44233 | IG3: 44234 | IH3: 44235 | II3: 44236 | IJ3: 44237 | IK3: 44238 | IL3: 44239 | IM3: 44240 | IN3: 44241 | IO3: 44242 | IP3: 44243 | IQ3: 44244 | IR3: 44245 | IS3: 44246 | IT3: 44247 | IU3: 44248 | IV3: 44249 | IW3: 44250 | IX3: 44251 | IY3: 44252 | IZ3: 44253 | JA3: 44254 | JB3: 44255 | JC3: 44256 | JD3: 44257 | JE3: 44258 | JF3: 44259 | JG3: 44260 | JH3: 44261 | JI3: 44262 | JJ3: 44263 | JK3: 44264 | JL3: 44265 | JM3: 44266 | JN3: 44267 | JO3: 44268 | JP3: 44269 | JQ3: 44270 | JR3: 44271 | JS3: 44272 | JT3: 44273 | JU3: 44274 | JV3: 44275 | JW3: 44276 | JX3: 44277 | JY3: 44278 | JZ3: 44279 | KA3: 44280 | KB3: 44281 | KC3: 44282 | KD3: 44283 | KE3: 44284 | KF3: 44285 | KG3: 44286 | KH3: 44287 | KI3: 44288 | KJ3: 44289 | KK3: 44290 | KL3: 44291 | KM3: 44292 | KN3: 44293 | KO3: 44294 | KP3: 44295 | KQ3: 44296 | KR3: 44297 | KS3: 44298 | KT3: 44299 | KU3: 44300 | KV3: 44301 | KW3: 44302 | KX3: 44303 | KY3: 44304 | KZ3: 44305 | LA3: 44306 | LB3: 44307 | LC3: 44308 | LD3: 44309 | LE3: 44310 | LF3: 44311 | LG3: 44312 | LH3: 44313 | LI3: 44314 | LJ3: 44315 | LK3: 44316 | LL3: 44317 | LM3: 44318 | LN3: 44319 | LO3: 44320 | LP3: 44321 | LQ3: 44322 | LR3: 44323 | LS3: 44324 | LT3: 44325 | LU3: 44326 | LV3: 44327 | LW3: 44328 | LX3: 44329 | LY3: 44330 | LZ3: 44331 | MA3: 44332 | MB3: 44333 | MC3: 44334 | MD3: 44335 | ME3: 44336 | MF3: 44337 | MG3: 44338 | MH3: 44339 | MI3: 44340 | MJ3: 44341 | MK3: 44342 | ML3: 44343 | MM3: 44344 | MN3: 44345 | MO3: 44346 | MP3: 44347 | MQ3: 44348 | MR3: 44349 | MS3: 44350 | MT3: 44351 | MU3: 44352 | MV3: 44353
A5: Model timeline
E7: Beginning date | F7: =MIN( tbl_SeasonTicketSale[Week ending] ) - 6 -> 44003 | G7: date
E8: Ending date | F8: =MAX( tbl_GameDates[Date] ) + 1 -> 44353 | G8: date
E9: Number of days | F9: =F8 - F7 + 1 -> 351 | G9: days
E11: Model timeline | G11: date | J11: {=_xlfn.SEQUENCE( 1, periods, $F$7, 1 )} -> 44003 | K11: 44004 | L11: 44005 | M11: 44006 | N11: 44007 | O11: 44008 | P11: 44009 | Q11: 44010 | R11: 44011 | S11: 44012 | T11: 44013 | U11: 44014 | V11: 44015 | W11: 44016 | X11: 44017 | Y11: 44018 | Z11: 44019 | AA11: 44020 | AB11: 44021 | AC11: 44022 | AD11: 44023 | AE11: 44024 | AF11: 44025 | AG11: 44026 | AH11: 44027 | AI11: 44028 | AJ11: 44029 | AK11: 44030 | AL11: 44031 | AM11: 44032 | AN11: 44033 | AO11: 44034 | AP11: 44035 | AQ11: 44036 | AR11: 44037 | AS11: 44038 | AT11: 44039 | AU11: 44040 | AV11: 44041 | AW11: 44042 | AX11: 44043 | AY11: 44044 | AZ11: 44045 | BA11: 44046 | BB11: 44047 | BC11: 44048 | BD11: 44049 | BE11: 44050 | BF11: 44051 | BG11: 44052 | BH11: 44053 | BI11: 44054 | BJ11: 44055 | BK11: 44056 | BL11: 44057 | BM11: 44058 | BN11: 44059 | BO11: 44060 | BP11: 44061 | BQ11: 44062 | BR11: 44063 | BS11: 44064 | BT11: 44065 | BU11: 44066 | BV11: 44067 | BW11: 44068 | BX11: 44069 | BY11: 44070 | BZ11: 44071 | CA11: 44072 | CB11: 44073 | CC11: 44074 | CD11: 44075 | CE11: 44076 | CF11: 44077 | CG11: 44078 | CH11: 44079 | CI11: 44080 | CJ11: 44081 | CK11: 44082 | CL11: 44083 | CM11: 44084 | CN11: 44085 | CO11: 44086 | CP11: 44087 | CQ11: 44088 | CR11: 44089 | CS11: 44090 | CT11: 44091 | CU11: 44092 | CV11: 44093 | CW11: 44094 | CX11: 44095 | CY11: 44096 | CZ11: 44097 | DA11: 44098 | DB11: 44099 | DC11: 44100 | DD11: 44101 | DE11: 44102 | DF11: 44103 | DG11: 44104 | DH11: 44105 | DI11: 44106 | DJ11: 44107 | DK11: 44108 | DL11: 44109 | DM11: 44110 | DN11: 44111 | DO11: 44112 | DP11: 44113 | DQ11: 44114 | DR11: 44115 | DS11: 44116 | DT11: 44117 | DU11: 44118 | DV11: 44119 | DW11: 44120 | DX11: 44121 | DY11: 44122 | DZ11: 44123 | EA11: 44124 | EB11: 44125 | EC11: 44126 | ED11: 44127 | EE11: 44128 | EF11: 44129 | EG11: 44130 | EH11: 44131 | EI11: 44132 | EJ11: 44133 | EK11: 44134 | EL11: 44135 | EM11: 44136 | EN11: 44137 | EO11: 44138 | EP11: 44139 | EQ11: 44140 | ER11: 44141 | ES11: 44142 | ET11: 44143 | EU11: 44144 | EV11: 44145 | EW11: 44146 | EX11: 44147 | EY11: 44148 | EZ11: 44149 | FA11: 44150 | FB11: 44151 | FC11: 44152 | FD11: 44153 | FE11: 44154 | FF11: 44155 | FG11: 44156 | FH11: 44157 | FI11: 44158 | FJ11: 44159 | FK11: 44160 | FL11: 44161 | FM11: 44162 | FN11: 44163 | FO11: 44164 | FP11: 44165 | FQ11: 44166 | FR11: 44167 | FS11: 44168 | FT11: 44169 | FU11: 44170 | FV11: 44171 | FW11: 44172 | FX11: 44173 | FY11: 44174 | FZ11: 44175 | GA11: 44176 | GB11: 44177 | GC11: 44178 | GD11: 44179 | GE11: 44180 | GF11: 44181 | GG11: 44182 | GH11: 44183 | GI11: 44184 | GJ11: 44185 | GK11: 44186 | GL11: 44187 | GM11: 44188 | GN11: 44189 | GO11: 44190 | GP11: 44191 | GQ11: 44192 | GR11: 44193 | GS11: 44194 | GT11: 44195 | GU11: 44196 | GV11: 44197 | GW11: 44198 | GX11: 44199 | GY11: 44200 | GZ11: 44201 | HA11: 44202 | HB11: 44203 | HC11: 44204 | HD11: 44205 | HE11: 44206 | HF11: 44207 | HG11: 44208 | HH11: 44209 | HI11: 44210 | HJ11: 44211 | HK11: 44212 | HL11: 44213 | HM11: 44214 | HN11: 44215 | HO11: 44216 | HP11: 44217 | HQ11: 44218 | HR11: 44219 | HS11: 44220 | HT11: 44221 | HU11: 44222 | HV11: 44223 | HW11: 44224 | HX11: 44225 | HY11: 44226 | HZ11: 44227 | IA11: 44228 | IB11: 44229 | IC11: 44230 | ID11: 44231 | IE11: 44232 | IF11: 44233 | IG11: 44234 | IH11: 44235 | II11: 44236 | IJ11: 44237 | IK11: 44238 | IL11: 44239 | IM11: 44240 | IN11: 44241 | IO11: 44242 | IP11: 44243 | IQ11: 44244 | IR11: 44245 | IS11: 44246 | IT11: 44247 | IU11: 44248 | IV11: 44249 | IW11: 44250 | IX11: 44251 | IY11: 44252 | IZ11: 44253 | JA11: 44254 | JB11: 44255 | JC11: 44256 | JD11: 44257 | JE11: 44258 | JF11: 44259 | JG11: 44260 | JH11: 44261 | JI11: 44262 | JJ11: 44263 | JK11: 44264 | JL11: 44265 | JM11: 44266 | JN11: 44267 | JO11: 44268 | JP11: 44269 | JQ11: 44270 | JR11: 44271 | JS11: 44272 | JT11: 44273 | JU11: 44274 | JV11: 44275 | JW11: 44276 | JX11: 44277 | JY11: 44278 | JZ11: 44279 | KA11: 44280 | KB11: 44281 | KC11: 44282 | KD11: 44283 | KE11: 44284 | KF11: 44285 | KG11: 44286 | KH11: 44287 | KI11: 44288 | KJ11: 44289 | KK11: 44290 | KL11: 44291 | KM11: 44292 | KN11: 44293 | KO11: 44294 | KP11: 44295 | KQ11: 44296 | KR11: 44297 | KS11: 44298 | KT11: 44299 | KU11: 44300 | KV11: 44301 | KW11: 44302 | KX11: 44303 | KY11: 44304 | KZ11: 44305 | LA11: 44306 | LB11: 44307 | LC11: 44308 | LD11: 44309 | LE11: 44310 | LF11: 44311 | LG11: 44312 | LH11: 44313 | LI11: 44314 | LJ11: 44315 | LK11: 44316 | LL11: 44317 | LM11: 44318 | LN11: 44319 | LO11: 44320 | LP11: 44321 | LQ11: 44322 | LR11: 44323 | LS11: 44324 | LT11: 44325 | LU11: 44326 | LV11: 44327 | LW11: 44328 | LX11: 44329 | LY11: 44330 | LZ11: 44331 | MA11: 44332 | MB11: 44333 | MC11: 44334 | MD11: 44335 | ME11: 44336 | MF11: 44337 | MG11: 44338 | MH11: 44339 | MI11: 44340 | MJ11: 44341 | MK11: 44342 | ML11: 44343 | MM11: 44344 | MN11: 44345 | MO11: 44346 | MP11: 44347 | MQ11: 44348 | MR11: 44349 | MS11: 44350 | MT11: 44351 | MU11: 44352 | MV11: 44353
E12: Weekend date | G12: date | J12: {=_xlfn.ANCHORARRAY( J11) - WEEKDAY(_xlfn.ANCHORARRAY( J11) ) + 7} -> 44009 | K12: 44009 | L12: 44009 | M12: 44009 | N12: 44009 | O12: 44009 | P12: 44009 | Q12: 44016 | R12: 44016 | S12: 44016 | T12: 44016 | U12: 44016 | V12: 44016 | W12: 44016 | X12: 44023 | Y12: 44023 | Z12: 44023 | AA12: 44023 | AB12: 44023 | AC12: 44023 | AD12: 44023 | AE12: 44030 | AF12: 44030 | AG12: 44030 | AH12: 44030 | AI12: 44030 | AJ12: 44030 | AK12: 44030 | AL12: 44037 | AM12: 44037 | AN12: 44037 | AO12: 44037 | AP12: 44037 | AQ12: 44037 | AR12: 44037 | AS12: 44044 | AT12: 44044 | AU12: 44044 | AV12: 44044 | AW12: 44044 | AX12: 44044 | AY12: 44044 | AZ12: 44051 | BA12: 44051 | BB12: 44051 | BC12: 44051 | BD12: 44051 | BE12: 44051 | BF12: 44051 | BG12: 44058 | BH12: 44058 | BI12: 44058 | BJ12: 44058 | BK12: 44058 | BL12: 44058 | BM12: 44058 | BN12: 44065 | BO12: 44065 | BP12: 44065 | BQ12: 44065 | BR12: 44065 | BS12: 44065 | BT12: 44065 | BU12: 44072 | BV12: 44072 | BW12: 44072 | BX12: 44072 | BY12: 44072 | BZ12: 44072 | CA12: 44072 | CB12: 44079 | CC12: 44079 | CD12: 44079 | CE12: 44079 | CF12: 44079 | CG12: 44079 | CH12: 44079 | CI12: 44086 | CJ12: 44086 | CK12: 44086 | CL12: 44086 | CM12: 44086 | CN12: 44086 | CO12: 44086 | CP12: 44093 | CQ12: 44093 | CR12: 44093 | CS12: 44093 | CT12: 44093 | CU12: 44093 | CV12: 44093 | CW12: 44100 | CX12: 44100 | CY12: 44100 | CZ12: 44100 | DA12: 44100 | DB12: 44100 | DC12: 44100 | DD12: 44107 | DE12: 44107 | DF12: 44107 | DG12: 44107 | DH12: 44107 | DI12: 44107 | DJ12: 44107 | DK12: 44114 | DL12: 44114 | DM12: 44114 | DN12: 44114 | DO12: 44114 | DP12: 44114 | DQ12: 44114 | DR12: 44121 | DS12: 44121 | DT12: 44121 | DU12: 44121 | DV12: 44121 | DW12: 44121 | DX12: 44121 | DY12: 44128 | DZ12: 44128 | EA12: 44128 | EB12: 44128 | EC12: 44128 | ED12: 44128 | EE12: 44128 | EF12: 44135 | EG12: 44135 | EH12: 44135 | EI12: 44135 | EJ12: 44135 | EK12: 44135 | EL12: 44135 | EM12: 44142 | EN12: 44142 | EO12: 44142 | EP12: 44142 | EQ12: 44142 | ER12: 44142 | ES12: 44142 | ET12: 44149 | EU12: 44149 | EV12: 44149 | EW12: 44149 | EX12: 44149 | EY12: 44149 | EZ12: 44149 | FA12: 44156 | FB12: 44156 | FC12: 44156 | FD12: 44156 | FE12: 44156 | FF12: 44156 | FG12: 44156 | FH12: 44163 | FI12: 44163 | FJ12: 44163 | FK12: 44163 | FL12: 44163 | FM12: 44163 | FN12: 44163 | FO12: 44170 | FP12: 44170 | FQ12: 44170 | FR12: 44170 | FS12: 44170 | FT12: 44170 | FU12: 44170 | FV12: 44177 | FW12: 44177 | FX12: 44177 | FY12: 44177 | FZ12: 44177 | GA12: 44177 | GB12: 44177 | GC12: 44184 | GD12: 44184 | GE12: 44184 | GF12: 44184 | GG12: 44184 | GH12: 44184 | GI12: 44184 | GJ12: 44191 | GK12: 44191 | GL12: 44191 | GM12: 44191 | GN12: 44191 | GO12: 44191 | GP12: 44191 | GQ12: 44198 | GR12: 44198 | GS12: 44198 | GT12: 44198 | GU12: 44198 | GV12: 44198 | GW12: 44198 | GX12: 44205 | GY12: 44205 | GZ12: 44205 | HA12: 44205 | HB12: 44205 | HC12: 44205 | HD12: 44205 | HE12: 44212 | HF12: 44212 | HG12: 44212 | HH12: 44212 | HI12: 44212 | HJ12: 44212 | HK12: 44212 | HL12: 44219 | HM12: 44219 | HN12: 44219 | HO12: 44219 | HP12: 44219 | HQ12: 44219 | HR12: 44219 | HS12: 44226 | HT12: 44226 | HU12: 44226 | HV12: 44226 | HW12: 44226 | HX12: 44226 | HY12: 44226 | HZ12: 44233 | IA12: 44233 | IB12: 44233 | IC12: 44233 | ID12: 44233 | IE12: 44233 | IF12: 44233 | IG12: 44240 | IH12: 44240 | II12: 44240 | IJ12: 44240 | IK12: 44240 | IL12: 44240 | IM12: 44240 | IN12: 44247 | IO12: 44247 | IP12: 44247 | IQ12: 44247 | IR12: 44247 | IS12: 44247 | IT12: 44247 | IU12: 44254 | IV12: 44254 | IW12: 44254 | IX12: 44254 | IY12: 44254 | IZ12: 44254 | JA12: 44254 | JB12: 44261 | JC12: 44261 | JD12: 44261 | JE12: 44261 | JF12: 44261 | JG12: 44261 | JH12: 44261 | JI12: 44268 | JJ12: 44268 | JK12: 44268 | JL12: 44268 | JM12: 44268 | JN12: 44268 | JO12: 44268 | JP12: 44275 | JQ12: 44275 | JR12: 44275 | JS12: 44275 | JT12: 44275 | JU12: 44275 | JV12: 44275 | JW12: 44282 | JX12: 44282 | JY12: 44282 | JZ12: 44282 | KA12: 44282 | KB12: 44282 | KC12: 44282 | KD12: 44289 | KE12: 44289 | KF12: 44289 | KG12: 44289 | KH12: 44289 | KI12: 44289 | KJ12: 44289 | KK12: 44296 | KL12: 44296 | KM12: 44296 | KN12: 44296 | KO12: 44296 | KP12: 44296 | KQ12: 44296 | KR12: 44303 | KS12: 44303 | KT12: 44303 | KU12: 44303 | KV12: 44303 | KW12: 44303 | KX12: 44303 | KY12: 44310 | KZ12: 44310 | LA12: 44310 | LB12: 44310 | LC12: 44310 | LD12: 44310 | LE12: 44310 | LF12: 44317 | LG12: 44317 | LH12: 44317 | LI12: 44317 | LJ12: 44317 | LK12: 44317 | LL12: 44317 | LM12: 44324 | LN12: 44324 | LO12: 44324 | LP12: 44324 | LQ12: 44324 | LR12: 44324 | LS12: 44324 | LT12: 44331 | LU12: 44331 | LV12: 44331 | LW12: 44331 | LX12: 44331 | LY12: 44331 | LZ12: 44331 | MA12: 44338 | MB12: 44338 | MC12: 44338 | MD12: 44338 | ME12: 44338 | MF12: 44338 | MG12: 44338 | MH12: 44345 | MI12: 44345 | MJ12: 44345 | MK12: 44345 | ML12: 44345 | MM12: 44345 | MN12: 44345 | MO12: 44352 | MP12: 44352 | MQ12: 44352 | MR12: 44352 | MS12: 44352 | MT12: 44352 | MU12: 44352 | MV12: 44359
E13: Month end | G13: date | J13: {=_xlfn.BYCOL(_xlfn.ANCHORARRAY( J11), _xlfn.LAMBDA(_xlpm.d, EOMONTH( _xlpm.d, 0 ) ) )} -> 44012 | K13: 44012 | L13: 44012 | M13: 44012 | N13: 44012 | O13: 44012 | P13: 44012 | Q13: 44012 | R13: 44012 | S13: 44012 | T13: 44043 | U13: 44043 | V13: 44043 | W13: 44043 | X13: 44043 | Y13: 44043 | Z13: 44043 | AA13: 44043 | AB13: 44043 | AC13: 44043 | AD13: 44043 | AE13: 44043 | AF13: 44043 | AG13: 44043 | AH13: 44043 | AI13: 44043 | AJ13: 44043 | AK13: 44043 | AL13: 44043 | AM13: 44043 | AN13: 44043 | AO13: 44043 | AP13: 44043 | AQ13: 44043 | AR13: 44043 | AS13: 44043 | AT13: 44043 | AU13: 44043 | AV13: 44043 | AW13: 44043 | AX13: 44043 | AY13: 44074 | AZ13: 44074 | BA13: 44074 | BB13: 44074 | BC13: 44074 | BD13: 44074 | BE13: 44074 | BF13: 44074 | BG13: 44074 | BH13: 44074 | BI13: 44074 | BJ13: 44074 | BK13: 44074 | BL13: 44074 | BM13: 44074 | BN13: 44074 | BO13: 44074 | BP13: 44074 | BQ13: 44074 | BR13: 44074 | BS13: 44074 | BT13: 44074 | BU13: 44074 | BV13: 44074 | BW13: 44074 | BX13: 44074 | BY13: 44074 | BZ13: 44074 | CA13: 44074 | CB13: 44074 | CC13: 44074 | CD13: 44104 | CE13: 44104 | CF13: 44104 | CG13: 44104 | CH13: 44104 | CI13: 44104 | CJ13: 44104 | CK13: 44104 | CL13: 44104 | CM13: 44104 | CN13: 44104 | CO13: 44104 | CP13: 44104 | CQ13: 44104 | CR13: 44104 | CS13: 44104 | CT13: 44104 | CU13: 44104 | CV13: 44104 | CW13: 44104 | CX13: 44104 | CY13: 44104 | CZ13: 44104 | DA13: 44104 | DB13: 44104 | DC13: 44104 | DD13: 44104 | DE13: 44104 | DF13: 44104 | DG13: 44104 | DH13: 44135 | DI13: 44135 | DJ13: 44135 | DK13: 44135 | DL13: 44135 | DM13: 44135 | DN13: 44135 | DO13: 44135 | DP13: 44135 | DQ13: 44135 | DR13: 44135 | DS13: 44135 | DT13: 44135 | DU13: 44135 | DV13: 44135 | DW13: 44135 | DX13: 44135 | DY13: 44135 | DZ13: 44135 | EA13: 44135 | EB13: 44135 | EC13: 44135 | ED13: 44135 | EE13: 44135 | EF13: 44135 | EG13: 44135 | EH13: 44135 | EI13: 44135 | EJ13: 44135 | EK13: 44135 | EL13: 44135 | EM13: 44165 | EN13: 44165 | EO13: 44165 | EP13: 44165 | EQ13: 44165 | ER13: 44165 | ES13: 44165 | ET13: 44165 | EU13: 44165 | EV13: 44165 | EW13: 44165 | EX13: 44165 | EY13: 44165 | EZ13: 44165 | FA13: 44165 | FB13: 44165 | FC13: 44165 | FD13: 44165 | FE13: 44165 | FF13: 44165 | FG13: 44165 | FH13: 44165 | FI13: 44165 | FJ13: 44165 | FK13: 44165 | FL13: 44165 | FM13: 44165 | FN13: 44165 | FO13: 44165 | FP13: 44165 | FQ13: 44196 | FR13: 44196 | FS13: 44196 | FT13: 44196 | FU13: 44196 | FV13: 44196 | FW13: 44196 | FX13: 44196 | FY13: 44196 | FZ13: 44196 | GA13: 44196 | GB13: 44196 | GC13: 44196 | GD13: 44196 | GE13: 44196 | GF13: 44196 | GG13: 44196 | GH13: 44196 | GI13: 44196 | GJ13: 44196 | GK13: 44196 | GL13: 44196 | GM13: 44196 | GN13: 44196 | GO13: 44196 | GP13: 44196 | GQ13: 44196 | GR13: 44196 | GS13: 44196 | GT13: 44196 | GU13: 44196 | GV13: 44227 | GW13: 44227 | GX13: 44227 | GY13: 44227 | GZ13: 44227 | HA13: 44227 | HB13: 44227 | HC13: 44227 | HD13: 44227 | HE13: 44227 | HF13: 44227 | HG13: 44227 | HH13: 44227 | HI13: 44227 | HJ13: 44227 | HK13: 44227 | HL13: 44227 | HM13: 44227 | HN13: 44227 | HO13: 44227 | HP13: 44227 | HQ13: 44227 | HR13: 44227 | HS13: 44227 | HT13: 44227 | HU13: 44227 | HV13: 44227 | HW13: 44227 | HX13: 44227 | HY13: 44227 | HZ13: 44227 | IA13: 44255 | IB13: 44255 | IC13: 44255 | ID13: 44255 | IE13: 44255 | IF13: 44255 | IG13: 44255 | IH13: 44255 | II13: 44255 | IJ13: 44255 | IK13: 44255 | IL13: 44255 | IM13: 44255 | IN13: 44255 | IO13: 44255 | IP13: 44255 | IQ13: 44255 | IR13: 44255 | IS13: 44255 | IT13: 44255 | IU13: 44255 | IV13: 44255 | IW13: 44255 | IX13: 44255 | IY13: 44255 | IZ13: 44255 | JA13: 44255 | JB13: 44255 | JC13: 44286 | JD13: 44286 | JE13: 44286 | JF13: 44286 | JG13: 44286 | JH13: 44286 | JI13: 44286 | JJ13: 44286 | JK13: 44286 | JL13: 44286 | JM13: 44286 | JN13: 44286 | JO13: 44286 | JP13: 44286 | JQ13: 44286 | JR13: 44286 | JS13: 44286 | JT13: 44286 | JU13: 44286 | JV13: 44286 | JW13: 44286 | JX13: 44286 | JY13: 44286 | JZ13: 44286 | KA13: 44286 | KB13: 44286 | KC13: 44286 | KD13: 44286 | KE13: 44286 | KF13: 44286 | KG13: 44286 | KH13: 44316 | KI13: 44316 | KJ13: 44316 | KK13: 44316 | KL13: 44316 | KM13: 44316 | KN13: 44316 | KO13: 44316 | KP13: 44316 | KQ13: 44316 | KR13: 44316 | KS13: 44316 | KT13: 44316 | KU13: 44316 | KV13: 44316 | KW13: 44316 | KX13: 44316 | KY13: 44316 | KZ13: 44316 | LA13: 44316 | LB13: 44316 | LC13: 44316 | LD13: 44316 | LE13: 44316 | LF13: 44316 | LG13: 44316 | LH13: 44316 | LI13: 44316 | LJ13: 44316 | LK13: 44316 | LL13: 44347 | LM13: 44347 | LN13: 44347 | LO13: 44347 | LP13: 44347 | LQ13: 44347 | LR13: 44347 | LS13: 44347 | LT13: 44347 | LU13: 44347 | LV13: 44347 | LW13: 44347 | LX13: 44347 | LY13: 44347 | LZ13: 44347 | MA13: 44347 | MB13: 44347 | MC13: 44347 | MD13: 44347 | ME13: 44347 | MF13: 44347 | MG13: 44347 | MH13: 44347 | MI13: 44347 | MJ13: 44347 | MK13: 44347 | ML13: 44347 | MM13: 44347 | MN13: 44347 | MO13: 44347 | MP13: 44347 | MQ13: 44377 | MR13: 44377 | MS13: 44377 | MT13: 44377 | MU13: 44377 | MV13: 44377
E14: Game date | G14: date | J14: {=_xlfn.XLOOKUP(_xlfn.ANCHORARRAY( J11), tbl_GameDates[Date], tbl_GameDates[Date], "n/a", 1 )} -> 44058 | K14: 44058 | L14: 44058 | M14: 44058 | N14: 44058 | O14: 44058 | P14: 44058 | Q14: 44058 | R14: 44058 | S14: 44058 | T14: 44058 | U14: 44058 | V14: 44058 | W14: 44058 | X14: 44058 | Y14: 44058 | Z14: 44058 | AA14: 44058 | AB14: 44058 | AC14: 44058 | AD14: 44058 | AE14: 44058 | AF14: 44058 | AG14: 44058 | AH14: 44058 | AI14: 44058 | AJ14: 44058 | AK14: 44058 | AL14: 44058 | AM14: 44058 | AN14: 44058 | AO14: 44058 | AP14: 44058 | AQ14: 44058 | AR14: 44058 | AS14: 44058 | AT14: 44058 | AU14: 44058 | AV14: 44058 | AW14: 44058 | AX14: 44058 | AY14: 44058 | AZ14: 44058 | BA14: 44058 | BB14: 44058 | BC14: 44058 | BD14: 44058 | BE14: 44058 | BF14: 44058 | BG14: 44058 | BH14: 44058 | BI14: 44058 | BJ14: 44058 | BK14: 44058 | BL14: 44058 | BM14: 44058 | BN14: 44065 | BO14: 44065 | BP14: 44065 | BQ14: 44065 | BR14: 44065 | BS14: 44065 | BT14: 44065 | BU14: 44072 | BV14: 44072 | BW14: 44072 | BX14: 44072 | BY14: 44072 | BZ14: 44072 | CA14: 44072 | CB14: 44079 | CC14: 44079 | CD14: 44079 | CE14: 44079 | CF14: 44079 | CG14: 44079 | CH14: 44079 | CI14: 44086 | CJ14: 44086 | CK14: 44086 | CL14: 44086 | CM14: 44086 | CN14: 44086 | CO14: 44086 | CP14: 44093 | CQ14: 44093 | CR14: 44093 | CS14: 44093 | CT14: 44093 | CU14: 44093 | CV14: 44093 | CW14: 44100 | CX14: 44100 | CY14: 44100 | CZ14: 44100 | DA14: 44100 | DB14: 44100 | DC14: 44100 | DD14: 44107 | DE14: 44107 | DF14: 44107 | DG14: 44107 | DH14: 44107 | DI14: 44107 | DJ14: 44107 | DK14: 44114 | DL14: 44114 | DM14: 44114 | DN14: 44114 | DO14: 44114 | DP14: 44114 | DQ14: 44114 | DR14: 44121 | DS14: 44121 | DT14: 44121 | DU14: 44121 | DV14: 44121 | DW14: 44121 | DX14: 44121 | DY14: 44128 | DZ14: 44128 | EA14: 44128 | EB14: 44128 | EC14: 44128 | ED14: 44128 | EE14: 44128 | EF14: 44135 | EG14: 44135 | EH14: 44135 | EI14: 44135 | EJ14: 44135 | EK14: 44135 | EL14: 44135 | EM14: 44142 | EN14: 44142 | EO14: 44142 | EP14: 44142 | EQ14: 44142 | ER14: 44142 | ES14: 44142 | ET14: 44149 | EU14: 44149 | EV14: 44149 | EW14: 44149 | EX14: 44149 | EY14: 44149 | EZ14: 44149 | FA14: 44156 | FB14: 44156 | FC14: 44156 | FD14: 44156 | FE14: 44156 | FF14: 44156 | FG14: 44156 | FH14: 44163 | FI14: 44163 | FJ14: 44163 | FK14: 44163 | FL14: 44163 | FM14: 44163 | FN14: 44163 | FO14: 44170 | FP14: 44170 | FQ14: 44170 | FR14: 44170 | FS14: 44170 | FT14: 44170 | FU14: 44170 | FV14: 44177 | FW14: 44177 | FX14: 44177 | FY14: 44177 | FZ14: 44177 | GA14: 44177 | GB14: 44177 | GC14: 44198 | GD14: 44198 | GE14: 44198 | GF14: 44198 | GG14: 44198 | GH14: 44198 | GI14: 44198 | GJ14: 44198 | GK14: 44198 | GL14: 44198 | GM14: 44198 | GN14: 44198 | GO14: 44198 | GP14: 44198 | GQ14: 44198 | GR14: 44198 | GS14: 44198 | GT14: 44198 | GU14: 44198 | GV14: 44198 | GW14: 44198 | GX14: 44205 | GY14: 44205 | GZ14: 44205 | HA14: 44205 | HB14: 44205 | HC14: 44205 | HD14: 44205 | HE14: 44212 | HF14: 44212 | HG14: 44212 | HH14: 44212 | HI14: 44212 | HJ14: 44212 | HK14: 44212 | HL14: 44219 | HM14: 44219 | HN14: 44219 | HO14: 44219 | HP14: 44219 | HQ14: 44219 | HR14: 44219 | HS14: 44226 | HT14: 44226 | HU14: 44226 | HV14: 44226 | HW14: 44226 | HX14: 44226 | HY14: 44226 | HZ14: 44233 | IA14: 44233 | IB14: 44233 | IC14: 44233 | ID14: 44233 | IE14: 44233 | IF14: 44233 | IG14: 44240 | IH14: 44240 | II14: 44240 | IJ14: 44240 | IK14: 44240 | IL14: 44240 | IM14: 44240 | IN14: 44247 | IO14: 44247 | IP14: 44247 | IQ14: 44247 | IR14: 44247 | IS14: 44247 | IT14: 44247 | IU14: 44254 | IV14: 44254 | IW14: 44254 | IX14: 44254 | IY14: 44254 | IZ14: 44254 | JA14: 44254 | JB14: 44261 | JC14: 44261 | JD14: 44261 | JE14: 44261 | JF14: 44261 | JG14: 44261 | JH14: 44261 | JI14: 44268 | JJ14: 44268 | JK14: 44268 | JL14: 44268 | JM14: 44268 | JN14: 44268 | JO14: 44268 | JP14: 44275 | JQ14: 44275 | JR14: 44275 | JS14: 44275 | JT14: 44275 | JU14: 44275 | JV14: 44275 | JW14: 44282 | JX14: 44282 | JY14: 44282 | JZ14: 44282 | KA14: 44282 | KB14: 44282 | KC14: 44282 | KD14: 44289 | KE14: 44289 | KF14: 44289 | KG14: 44289 | KH14: 44289 | KI14: 44289 | KJ14: 44289 | KK14: 44296 | KL14: 44296 | KM14: 44296 | KN14: 44296 | KO14: 44296 | KP14: 44296 | KQ14: 44296 | KR14: 44303 | KS14: 44303 | KT14: 44303 | KU14: 44303 | KV14: 44303 | KW14: 44303 | KX14: 44303 | KY14: 44310 | KZ14: 44310 | LA14: 44310 | LB14: 44310 | LC14: 44310 | LD14: 44310 | LE14: 44310 | LF14: 44317 | LG14: 44317 | LH14: 44317 | LI14: 44317 | LJ14: 44317 | LK14: 44317 | LL14: 44317 | LM14: 44324 | LN14: 44324 | LO14: 44324 | LP14: 44324 | LQ14: 44324 | LR14: 44324 | LS14: 44324 | LT14: 44331 | LU14: 44331 | LV14: 44331 | LW14: 44331 | LX14: 44331 | LY14: 44331 | LZ14: 44331 | MA14: 44338 | MB14: 44338 | MC14: 44338 | MD14: 44338 | ME14: 44338 | MF14: 44338 | MG14: 44338 | MH14: 44352 | MI14: 44352 | MJ14: 44352 | MK14: 44352 | ML14: 44352 | MM14: 44352 | MN14: 44352 | MO14: 44352 | MP14: 44352 | MQ14: 44352 | MR14: 44352 | MS14: 44352 | MT14: 44352 | MU14: 44352 | MV14: n/a
E15: Days to next game | G15: days | J15: {=IFERROR(_xlfn.ANCHORARRAY( J14) -_xlfn.ANCHORARRAY( J11), "n/a" )} -> 55 | K15: 54 | L15: 53 | M15: 52 | N15: 51 | O15: 50 | P15: 49 | Q15: 48 | R15: 47 | S15: 46 | T15: 45 | U15: 44 | V15: 43 | W15: 42 | X15: 41 | Y15: 40 | Z15: 39 | AA15: 38 | AB15: 37 | AC15: 36 | AD15: 35 | AE15: 34 | AF15: 33 | AG15: 32 | AH15: 31 | AI15: 30 | AJ15: 29 | AK15: 28 | AL15: 27 | AM15: 26 | AN15: 25 | AO15: 24 | AP15: 23 | AQ15: 22 | AR15: 21 | AS15: 20 | AT15: 19 | AU15: 18 | AV15: 17 | AW15: 16 | AX15: 15 | AY15: 14 | AZ15: 13 | BA15: 12 | BB15: 11 | BC15: 10 | BD15: 9 | BE15: 8 | BF15: 7 | BG15: 6 | BH15: 5 | BI15: 4 | BJ15: 3 | BK15: 2 | BL15: 1 | BM15: 0 | BN15: 6 | BO15: 5 | BP15: 4 | BQ15: 3 | BR15: 2 | BS15: 1 | BT15: 0 | BU15: 6 | BV15: 5 | BW15: 4 | BX15: 3 | BY15: 2 | BZ15: 1 | CA15: 0 | CB15: 6 | CC15: 5 | CD15: 4 | CE15: 3 | CF15: 2 | CG15: 1 | CH15: 0 | CI15: 6 | CJ15: 5 | CK15: 4 | CL15: 3 | CM15: 2 | CN15: 1 | CO15: 0 | CP15: 6 | CQ15: 5 | CR15: 4 | CS15: 3 | CT15: 2 | CU15: 1 | CV15: 0 | CW15: 6 | CX15: 5 | CY15: 4 | CZ15: 3 | DA15: 2 | DB15: 1 | DC15: 0 | DD15: 6 | DE15: 5 | DF15: 4 | DG15: 3 | DH15: 2 | DI15: 1 | DJ15: 0 | DK15: 6 | DL15: 5 | DM15: 4 | DN15: 3 | DO15: 2 | DP15: 1 | DQ15: 0 | DR15: 6 | DS15: 5 | DT15: 4 | DU15: 3 | DV15: 2 | DW15: 1 | DX15: 0 | DY15: 6 | DZ15: 5 | EA15: 4 | EB15: 3 | EC15: 2 | ED15: 1 | EE15: 0 | EF15: 6 | EG15: 5 | EH15: 4 | EI15: 3 | EJ15: 2 | EK15: 1 | EL15: 0 | EM15: 6 | EN15: 5 | EO15: 4 | EP15: 3 | EQ15: 2 | ER15: 1 | ES15: 0 | ET15: 6 | EU15: 5 | EV15: 4 | EW15: 3 | EX15: 2 | EY15: 1 | EZ15: 0 | FA15: 6 | FB15: 5 | FC15: 4 | FD15: 3 | FE15: 2 | FF15: 1 | FG15: 0 | FH15: 6 | FI15: 5 | FJ15: 4 | FK15: 3 | FL15: 2 | FM15: 1 | FN15: 0 | FO15: 6 | FP15: 5 | FQ15: 4 | FR15: 3 | FS15: 2 | FT15: 1 | FU15: 0 | FV15: 6 | FW15: 5 | FX15: 4 | FY15: 3 | FZ15: 2 | GA15: 1 | GB15: 0 | GC15: 20 | GD15: 19 | GE15: 18 | GF15: 17 | GG15: 16 | GH15: 15 | GI15: 14 | GJ15: 13 | GK15: 12 | GL15: 11 | GM15: 10 | GN15: 9 | GO15: 8 | GP15: 7 | GQ15: 6 | GR15: 5 | GS15: 4 | GT15: 3 | GU15: 2 | GV15: 1 | GW15: 0 | GX15: 6 | GY15: 5 | GZ15: 4 | HA15: 3 | HB15: 2 | HC15: 1 | HD15: 0 | HE15: 6 | HF15: 5 | HG15: 4 | HH15: 3 | HI15: 2 | HJ15: 1 | HK15: 0 | HL15: 6 | HM15: 5 | HN15: 4 | HO15: 3 | HP15: 2 | HQ15: 1 | HR15: 0 | HS15: 6 | HT15: 5 | HU15: 4 | HV15: 3 | HW15: 2 | HX15: 1 | HY15: 0 | HZ15: 6 | IA15: 5 | IB15: 4 | IC15: 3 | ID15: 2 | IE15: 1 | IF15: 0 | IG15: 6 | IH15: 5 | II15: 4 | IJ15: 3 | IK15: 2 | IL15: 1 | IM15: 0 | IN15: 6 | IO15: 5 | IP15: 4 | IQ15: 3 | IR15: 2 | IS15: 1 | IT15: 0 | IU15: 6 | IV15: 5 | IW15: 4 | IX15: 3 | IY15: 2 | IZ15: 1 | JA15: 0 | JB15: 6 | JC15: 5 | JD15: 4 | JE15: 3 | JF15: 2 | JG15: 1 | JH15: 0 | JI15: 6 | JJ15: 5 | JK15: 4 | JL15: 3 | JM15: 2 | JN15: 1 | JO15: 0 | JP15: 6 | JQ15: 5 | JR15: 4 | JS15: 3 | JT15: 2 | JU15: 1 | JV15: 0 | JW15: 6 | JX15: 5 | JY15: 4 | JZ15: 3 | KA15: 2 | KB15: 1 | KC15: 0 | KD15: 6 | KE15: 5 | KF15: 4 | KG15: 3 | KH15: 2 | KI15: 1 | KJ15: 0 | KK15: 6 | KL15: 5 | KM15: 4 | KN15: 3 | KO15: 2 | KP15: 1 | KQ15: 0 | KR15: 6 | KS15: 5 | KT15: 4 | KU15: 3 | KV15: 2 | KW15: 1 | KX15: 0 | KY15: 6 | KZ15: 5 | LA15: 4 | LB15: 3 | LC15: 2 | LD15: 1 | LE15: 0 | LF15: 6 | LG15: 5 | LH15: 4 | LI15: 3 | LJ15: 2 | LK15: 1 | LL15: 0 | LM15: 6 | LN15: 5 | LO15: 4 | LP15: 3 | LQ15: 2 | LR15: 1 | LS15: 0 | LT15: 6 | LU15: 5 | LV15: 4 | LW15: 3 | LX15: 2 | LY15: 1 | LZ15: 0 | MA15: 6 | MB15: 5 | MC15: 4 | MD15: 3 | ME15: 2 | MF15: 1 | MG15: 0 | MH15: 13 | MI15: 12 | MJ15: 11 | MK15: 10 | ML15: 9 | MM15: 8 | MN15: 7 | MO15: 6 | MP15: 5 | MQ15: 4 | MR15: 3 | MS15: 2 | MT15: 1 | MU15: 0 | MV15: n/a
E16: Weekday | G16: day | J16: {=WEEKDAY(_xlfn.ANCHORARRAY( J11), 1 )} -> 1 | K16: 2 | L16: 3 | M16: 4 | N16: 5 | O16: 6 | P16: 7 | Q16: 1 | R16: 2 | S16: 3 | T16: 4 | U16: 5 | V16: 6 | W16: 7 | X16: 1 | Y16: 2 | Z16: 3 | AA16: 4 | AB16: 5 | AC16: 6 | AD16: 7 | AE16: 1 | AF16: 2 | AG16: 3 | AH16: 4 | AI16: 5 | AJ16: 6 | AK16: 7 | AL16: 1 | AM16: 2 | AN16: 3 | AO16: 4 | AP16: 5 | AQ16: 6 | AR16: 7 | AS16: 1 | AT16: 2 | AU16: 3 | AV16: 4 | AW16: 5 | AX16: 6 | AY16: 7 | AZ16: 1 | BA16: 2 | BB16: 3 | BC16: 4 | BD16: 5 | BE16: 6 | BF16: 7 | BG16: 1 | BH16: 2 | BI16: 3 | BJ16: 4 | BK16: 5 | BL16: 6 | BM16: 7 | BN16: 1 | BO16: 2 | BP16: 3 | BQ16: 4 | BR16: 5 | BS16: 6 | BT16: 7 | BU16: 1 | BV16: 2 | BW16: 3 | BX16: 4 | BY16: 5 | BZ16: 6 | CA16: 7 | CB16: 1 | CC16: 2 | CD16: 3 | CE16: 4 | CF16: 5 | CG16: 6 | CH16: 7 | CI16: 1 | CJ16: 2 | CK16: 3 | CL16: 4 | CM16: 5 | CN16: 6 | CO16: 7 | CP16: 1 | CQ16: 2 | CR16: 3 | CS16: 4 | CT16: 5 | CU16: 6 | CV16: 7 | CW16: 1 | CX16: 2 | CY16: 3 | CZ16: 4 | DA16: 5 | DB16: 6 | DC16: 7 | DD16: 1 | DE16: 2 | DF16: 3 | DG16: 4 | DH16: 5 | DI16: 6 | DJ16: 7 | DK16: 1 | DL16: 2 | DM16: 3 | DN16: 4 | DO16: 5 | DP16: 6 | DQ16: 7 | DR16: 1 | DS16: 2 | DT16: 3 | DU16: 4 | DV16: 5 | DW16: 6 | DX16: 7 | DY16: 1 | DZ16: 2 | EA16: 3 | EB16: 4 | EC16: 5 | ED16: 6 | EE16: 7 | EF16: 1 | EG16: 2 | EH16: 3 | EI16: 4 | EJ16: 5 | EK16: 6 | EL16: 7 | EM16: 1 | EN16: 2 | EO16: 3 | EP16: 4 | EQ16: 5 | ER16: 6 | ES16: 7 | ET16: 1 | EU16: 2 | EV16: 3 | EW16: 4 | EX16: 5 | EY16: 6 | EZ16: 7 | FA16: 1 | FB16: 2 | FC16: 3 | FD16: 4 | FE16: 5 | FF16: 6 | FG16: 7 | FH16: 1 | FI16: 2 | FJ16: 3 | FK16: 4 | FL16: 5 | FM16: 6 | FN16: 7 | FO16: 1 | FP16: 2 | FQ16: 3 | FR16: 4 | FS16: 5 | FT16: 6 | FU16: 7 | FV16: 1 | FW16: 2 | FX16: 3 | FY16: 4 | FZ16: 5 | GA16: 6 | GB16: 7 | GC16: 1 | GD16: 2 | GE16: 3 | GF16: 4 | GG16: 5 | GH16: 6 | GI16: 7 | GJ16: 1 | GK16: 2 | GL16: 3 | GM16: 4 | GN16: 5 | GO16: 6 | GP16: 7 | GQ16: 1 | GR16: 2 | GS16: 3 | GT16: 4 | GU16: 5 | GV16: 6 | GW16: 7 | GX16: 1 | GY16: 2 | GZ16: 3 | HA16: 4 | HB16: 5 | HC16: 6 | HD16: 7 | HE16: 1 | HF16: 2 | HG16: 3 | HH16: 4 | HI16: 5 | HJ16: 6 | HK16: 7 | HL16: 1 | HM16: 2 | HN16: 3 | HO16: 4 | HP16: 5 | HQ16: 6 | HR16: 7 | HS16: 1 | HT16: 2 | HU16: 3 | HV16: 4 | HW16: 5 | HX16: 6 | HY16: 7 | HZ16: 1 | IA16: 2 | IB16: 3 | IC16: 4 | ID16: 5 | IE16: 6 | IF16: 7 | IG16: 1 | IH16: 2 | II16: 3 | IJ16: 4 | IK16: 5 | IL16: 6 | IM16: 7 | IN16: 1 | IO16: 2 | IP16: 3 | IQ16: 4 | IR16: 5 | IS16: 6 | IT16: 7 | IU16: 1 | IV16: 2 | IW16: 3 | IX16: 4 | IY16: 5 | IZ16: 6 | JA16: 7 | JB16: 1 | JC16: 2 | JD16: 3 | JE16: 4 | JF16: 5 | JG16: 6 | JH16: 7 | JI16: 1 | JJ16: 2 | JK16: 3 | JL16: 4 | JM16: 5 | JN16: 6 | JO16: 7 | JP16: 1 | JQ16: 2 | JR16: 3 | JS16: 4 | JT16: 5 | JU16: 6 | JV16: 7 | JW16: 1 | JX16: 2 | JY16: 3 | JZ16: 4 | KA16: 5 | KB16: 6 | KC16: 7 | KD16: 1 | KE16: 2 | KF16: 3 | KG16: 4 | KH16: 5 | KI16: 6 | KJ16: 7 | KK16: 1 | KL16: 2 | KM16: 3 | KN16: 4 | KO16: 5 | KP16: 6 | KQ16: 7 | KR16: 1 | KS16: 2 | KT16: 3 | KU16: 4 | KV16: 5 | KW16: 6 | KX16: 7 | KY16: 1 | KZ16: 2 | LA16: 3 | LB16: 4 | LC16: 5 | LD16: 6 | LE16: 7 | LF16: 1 | LG16: 2 | LH16: 3 | LI16: 4 | LJ16: 5 | LK16: 6 | LL16: 7 | LM16: 1 | LN16: 2 | LO16: 3 | LP16: 4 | LQ16: 5 | LR16: 6 | LS16: 7 | LT16: 1 | LU16: 2 | LV16: 3 | LW16: 4 | LX16: 5 | LY16: 6 | LZ16: 7 | MA16: 1 | MB16: 2 | MC16: 3 | MD16: 4 | ME16: 5 | MF16: 6 | MG16: 7 | MH16: 1 | MI16: 2 | MJ16: 3 | MK16: 4 | ML16: 5 | MM16: 6 | MN16: 7 | MO16: 1 | MP16: 2 | MQ16: 3 | MR16: 4 | MS16: 5 | MT16: 6 | MU16: 7 | MV16: 1
A18: Season Tickets
E20: Weekly sales | G20: tickets | J20: {=_xlfn.XLOOKUP(_xlfn.ANCHORARRAY( J12), tbl_SeasonTicketSale[Week ending], tbl_SeasonTicketSale[Sales], 0,,)} -> 4800 | K20: 4800 | L20: 4800 | M20: 4800 | N20: 4800 | O20: 4800 | P20: 4800 | Q20: 3800 | R20: 3800 | S20: 3800 | T20: 3800 | U20: 3800 | V20: 3800 | W20: 3800 | X20: 3400 | Y20: 3400 | Z20: 3400 | AA20: 3400 | AB20: 3400 | AC20: 3400 | AD20: 3400 | AE20: 2800 | AF20: 2800 | AG20: 2800 | AH20: 2800 | AI20: 2800 | AJ20: 2800 | AK20: 2800 | AL20: 2700 | AM20: 2700 | AN20: 2700 | AO20: 2700 | AP20: 2700 | AQ20: 2700 | AR20: 2700 | AS20: 2750 | AT20: 2750 | AU20: 2750 | AV20: 2750 | AW20: 2750 | AX20: 2750 | AY20: 2750 | AZ20: 2600 | BA20: 2600 | BB20: 2600 | BC20: 2600 | BD20: 2600 | BE20: 2600 | BF20: 2600 | BG20: 2800 | BH20: 2800 | BI20: 2800 | BJ20: 2800 | BK20: 2800 | BL20: 2800 | BM20: 2800 | BN20: 1400 | BO20: 1400 | BP20: 1400 | BQ20: 1400 | BR20: 1400 | BS20: 1400 | BT20: 1400 | BU20: 800 | BV20: 800 | BW20: 800 | BX20: 800 | BY20: 800 | BZ20: 800 | CA20: 800 | CB20: 500 | CC20: 500 | CD20: 500 | CE20: 500 | CF20: 500 | CG20: 500 | CH20: 500 | CI20: 200 | CJ20: 200 | CK20: 200 | CL20: 200 | CM20: 200 | CN20: 200 | CO20: 200 | CP20: 150 | CQ20: 150 | CR20: 150 | CS20: 150 | CT20: 150 | CU20: 150 | CV20: 150 | CW20: 50 | CX20: 50 | CY20: 50 | CZ20: 50 | DA20: 50 | DB20: 50 | DC20: 50 | DD20: 50 | DE20: 50 | DF20: 50 | DG20: 50 | DH20: 50 | DI20: 50 | DJ20: 50 | DK20: 50 | DL20: 50 | DM20: 50 | DN20: 50 | DO20: 50 | DP20: 50 | DQ20: 50 | DR20: 50 | DS20: 50 | DT20: 50 | DU20: 50 | DV20: 50 | DW20: 50 | DX20: 50 | DY20: 50 | DZ20: 50 | EA20: 50 | EB20: 50 | EC20: 50 | ED20: 50 | EE20: 50 | EF20: 50 | EG20: 50 | EH20: 50 | EI20: 50 | EJ20: 50 | EK20: 50 | EL20: 50 | EM20: 50 | EN20: 50 | EO20: 50 | EP20: 50 | EQ20: 50 | ER20: 50 | ES20: 50 | ET20: 50 | EU20: 50 | EV20: 50 | EW20: 50 | EX20: 50 | EY20: 50 | EZ20: 50 | FA20: 50 | FB20: 50 | FC20: 50 | FD20: 50 | FE20: 50 | FF20: 50 | FG20: 50 | FH20: 50 | FI20: 50 | FJ20: 50 | FK20: 50 | FL20: 50 | FM20: 50 | FN20: 50 | FO20: 50 | FP20: 50 | FQ20: 50 | FR20: 50 | FS20: 50 | FT20: 50 | FU20: 50 | FV20: 250 | FW20: 250 | FX20: 250 | FY20: 250 | FZ20: 250 | GA20: 250 | GB20: 250 | GC20: 250 | GD20: 250 | GE20: 250 | GF20: 250 | GG20: 250 | GH20: 250 | GI20: 250 | GJ20: 50 | GK20: 50 | GL20: 50 | GM20: 50 | GN20: 50 | GO20: 50 | GP20: 50 | GQ20: 50 | GR20: 50 | GS20: 50 | GT20: 50 | GU20: 50 | GV20: 50 | GW20: 50 | GX20: 50 | GY20: 50 | GZ20: 50 | HA20: 50 | HB20: 50 | HC20: 50 | HD20: 50 | HE20: 50 | HF20: 50 | HG20: 50 | HH20: 50 | HI20: 50 | HJ20: 50 | HK20: 50 | HL20: 50 | HM20: 50 | HN20: 50 | HO20: 50 | HP20: 50 | HQ20: 50 | HR20: 50 | HS20: 0 | HT20: 0 | HU20: 0 | HV20: 0 | HW20: 0 | HX20: 0 | HY20: 0 | HZ20: 0 | IA20: 0 | IB20: 0 | IC20: 0 | ID20: 0 | IE20: 0 | IF20: 0 | IG20: 0 | IH20: 0 | II20: 0 | IJ20: 0 | IK20: 0 | IL20: 0 | IM20: 0 | IN20: 0 | IO20: 0 | IP20: 0 | IQ20: 0 | IR20: 0 | IS20: 0 | IT20: 0 | IU20: 0 | IV20: 0 | IW20: 0 | IX20: 0 | IY20: 0 | IZ20: 0 | JA20: 0 | JB20: 0 | JC20: 0 | JD20: 0 | JE20: 0 | JF20: 0 | JG20: 0 | JH20: 0 | JI20: 0 | JJ20: 0 | JK20: 0 | JL20: 0 | JM20: 0 | JN20: 0 | JO20: 0 | JP20: 0 | JQ20: 0 | JR20: 0 | JS20: 0 | JT20: 0 | JU20: 0 | JV20: 0 | JW20: 0 | JX20: 0 | JY20: 0 | JZ20: 0 | KA20: 0 | KB20: 0 | KC20: 0 | KD20: 0 | KE20: 0 | KF20: 0 | KG20: 0 | KH20: 0 | KI20: 0 | KJ20: 0 | KK20: 0 | KL20: 0 | KM20: 0 | KN20: 0 | KO20: 0 | KP20: 0 | KQ20: 0 | KR20: 0 | KS20: 0 | KT20: 0 | KU20: 0 | KV20: 0 | KW20: 0 | KX20: 0 | KY20: 0 | KZ20: 0 | LA20: 0 | LB20: 0 | LC20: 0 | LD20: 0 | LE20: 0 | LF20: 0 | LG20: 0 | LH20: 0 | LI20: 0 | LJ20: 0 | LK20: 0 | LL20: 0 | LM20: 0 | LN20: 0 | LO20: 0 | LP20: 0 | LQ20: 0 | LR20: 0 | LS20: 0 | LT20: 0 | LU20: 0 | LV20: 0 | LW20: 0 | LX20: 0 | LY20: 0 | LZ20: 0 | MA20: 0 | MB20: 0 | MC20: 0 | MD20: 0 | ME20: 0 | MF20: 0 | MG20: 0 | MH20: 0 | MI20: 0 | MJ20: 0 | MK20: 0 | ML20: 0 | MM20: 0 | MN20: 0 | MO20: 0 | MP20: 0 | MQ20: 0 | MR20: 0 | MS20: 0 | MT20: 0 | MU20: 0 | MV20: 0
E21: Sales date flag | G21: flag | J21: {=IF( ISNUMBER( _xlfn.XMATCH(_xlfn.ANCHORARRAY( J11), tbl_SeasonTicketSale[Date sold] ) ), 1, 0 )} -> 1 | K21: 0 | L21: 0 | M21: 0 | N21: 0 | O21: 0 | P21: 0 | Q21: 1 | R21: 0 | S21: 0 | T21: 0 | U21: 0 | V21: 0 | W21: 0 | X21: 1 | Y21: 0 | Z21: 0 | AA21: 0 | AB21: 0 | AC21: 0 | AD21: 0 | AE21: 1 | AF21: 0 | AG21: 0 | AH21: 0 | AI21: 0 | AJ21: 0 | AK21: 0 | AL21: 1 | AM21: 0 | AN21: 0 | AO21: 0 | AP21: 0 | AQ21: 0 | AR21: 0 | AS21: 1 | AT21: 0 | AU21: 0 | AV21: 0 | AW21: 0 | AX21: 0 | AY21: 0 | AZ21: 1 | BA21: 0 | BB21: 0 | BC21: 0 | BD21: 0 | BE21: 0 | BF21: 0 | BG21: 1 | BH21: 0 | BI21: 0 | BJ21: 0 | BK21: 0 | BL21: 0 | BM21: 0 | BN21: 1 | BO21: 0 | BP21: 0 | BQ21: 0 | BR21: 0 | BS21: 0 | BT21: 0 | BU21: 1 | BV21: 0 | BW21: 0 | BX21: 0 | BY21: 0 | BZ21: 0 | CA21: 0 | CB21: 1 | CC21: 0 | CD21: 0 | CE21: 0 | CF21: 0 | CG21: 0 | CH21: 0 | CI21: 1 | CJ21: 0 | CK21: 0 | CL21: 0 | CM21: 0 | CN21: 0 | CO21: 0 | CP21: 1 | CQ21: 0 | CR21: 0 | CS21: 0 | CT21: 0 | CU21: 0 | CV21: 0 | CW21: 1 | CX21: 0 | CY21: 0 | CZ21: 0 | DA21: 0 | DB21: 0 | DC21: 0 | DD21: 1 | DE21: 0 | DF21: 0 | DG21: 0 | DH21: 0 | DI21: 0 | DJ21: 0 | DK21: 1 | DL21: 0 | DM21: 0 | DN21: 0 | DO21: 0 | DP21: 0 | DQ21: 0 | DR21: 1 | DS21: 0 | DT21: 0 | DU21: 0 | DV21: 0 | DW21: 0 | DX21: 0 | DY21: 1 | DZ21: 0 | EA21: 0 | EB21: 0 | EC21: 0 | ED21: 0 | EE21: 0 | EF21: 1 | EG21: 0 | EH21: 0 | EI21: 0 | EJ21: 0 | EK21: 0 | EL21: 0 | EM21: 1 | EN21: 0 | EO21: 0 | EP21: 0 | EQ21: 0 | ER21: 0 | ES21: 0 | ET21: 1 | EU21: 0 | EV21: 0 | EW21: 0 | EX21: 0 | EY21: 0 | EZ21: 0 | FA21: 1 | FB21: 0 | FC21: 0 | FD21: 0 | FE21: 0 | FF21: 0 | FG21: 0 | FH21: 1 | FI21: 0 | FJ21: 0 | FK21: 0 | FL21: 0 | FM21: 0 | FN21: 0 | FO21: 1 | FP21: 0 | FQ21: 0 | FR21: 0 | FS21: 0 | FT21: 0 | FU21: 0 | FV21: 1 | FW21: 0 | FX21: 0 | FY21: 0 | FZ21: 0 | GA21: 0 | GB21: 0 | GC21: 1 | GD21: 0 | GE21: 0 | GF21: 0 | GG21: 0 | GH21: 0 | GI21: 0 | GJ21: 1 | GK21: 0 | GL21: 0 | GM21: 0 | GN21: 0 | GO21: 0 | GP21: 0 | GQ21: 1 | GR21: 0 | GS21: 0 | GT21: 0 | GU21: 0 | GV21: 0 | GW21: 0 | GX21: 1 | GY21: 0 | GZ21: 0 | HA21: 0 | HB21: 0 | HC21: 0 | HD21: 0 | HE21: 1 | HF21: 0 | HG21: 0 | HH21: 0 | HI21: 0 | HJ21: 0 | HK21: 0 | HL21: 1 | HM21: 0 | HN21: 0 | HO21: 0 | HP21: 0 | HQ21: 0 | HR21: 0 | HS21: 0 | HT21: 0 | HU21: 0 | HV21: 0 | HW21: 0 | HX21: 0 | HY21: 0 | HZ21: 0 | IA21: 0 | IB21: 0 | IC21: 0 | ID21: 0 | IE21: 0 | IF21: 0 | IG21: 0 | IH21: 0 | II21: 0 | IJ21: 0 | IK21: 0 | IL21: 0 | IM21: 0 | IN21: 0 | IO21: 0 | IP21: 0 | IQ21: 0 | IR21: 0 | IS21: 0 | IT21: 0 | IU21: 0 | IV21: 0 | IW21: 0 | IX21: 0 | IY21: 0 | IZ21: 0 | JA21: 0 | JB21: 0 | JC21: 0 | JD21: 0 | JE21: 0 | JF21: 0 | JG21: 0 | JH21: 0 | JI21: 0 | JJ21: 0 | JK21: 0 | JL21: 0 | JM21: 0 | JN21: 0 | JO21: 0 | JP21: 0 | JQ21: 0 | JR21: 0 | JS21: 0 | JT21: 0 | JU21: 0 | JV21: 0 | JW21: 0 | JX21: 0 | JY21: 0 | JZ21: 0 | KA21: 0 | KB21: 0 | KC21: 0 | KD21: 0 | KE21: 0 | KF21: 0 | KG21: 0 | KH21: 0 | KI21: 0 | KJ21: 0 | KK21: 0 | KL21: 0 | KM21: 0 | KN21: 0 | KO21: 0 | KP21: 0 | KQ21: 0 | KR21: 0 | KS21: 0 | KT21: 0 | KU21: 0 | KV21: 0 | KW21: 0 | KX21: 0 | KY21: 0 | KZ21: 0 | LA21: 0 | LB21: 0 | LC21: 0 | LD21: 0 | LE21: 0 | LF21: 0 | LG21: 0 | LH21: 0 | LI21: 0 | LJ21: 0 | LK21: 0 | LL21: 0 | LM21: 0 | LN21: 0 | LO21: 0 | LP21: 0 | LQ21: 0 | LR21: 0 | LS21: 0 | LT21: 0 | LU21: 0 | LV21: 0 | LW21: 0 | LX21: 0 | LY21: 0 | LZ21: 0 | MA21: 0 | MB21: 0 | MC21: 0 | MD21: 0 | ME21: 0 | MF21: 0 | MG21: 0 | MH21: 0 | MI21: 0 | MJ21: 0 | MK21: 0 | ML21: 0 | MM21: 0 | MN21: 0 | MO21: 0 | MP21: 0 | MQ21: 0 | MR21: 0 | MS21: 0 | MT21: 0 | MU21: 0 | MV21: 0
E22: Daily sales of season tickets | G22: tickets | H22: {=_xlfn.BYROW(_xlfn.ANCHORARRAY( J22), _xleta.SUM )} -> 30000 | J22: {=IF( SpreadSTs,_xlfn.ANCHORARRAY( J20) / 7,_xlfn.ANCHORARRAY( J20) *_xlfn.ANCHORARRAY( J21) )} -> 4800 | K22: 0 | L22: 0 | M22: 0 | N22: 0 | O22: 0 | P22: 0 | Q22: 3800 | R22: 0 | S22: 0 | T22: 0 | U22: 0 | V22: 0 | W22: 0 | X22: 3400 | Y22: 0 | Z22: 0 | AA22: 0 | AB22: 0 | AC22: 0 | AD22: 0 | AE22: 2800 | AF22: 0 | AG22: 0 | AH22: 0 | AI22: 0 | AJ22: 0 | AK22: 0 | AL22: 2700 | AM22: 0 | AN22: 0 | AO22: 0 | AP22: 0 | AQ22: 0 | AR22: 0 | AS22: 2750 | AT22: 0 | AU22: 0 | AV22: 0 | AW22: 0 | AX22: 0 | AY22: 0 | AZ22: 2600 | BA22: 0 | BB22: 0 | BC22: 0 | BD22: 0 | BE22: 0 | BF22: 0 | BG22: 2800 | BH22: 0 | BI22: 0 | BJ22: 0 | BK22: 0 | BL22: 0 | BM22: 0 | BN22: 1400 | BO22: 0 | BP22: 0 | BQ22: 0 | BR22: 0 | BS22: 0 | BT22: 0 | BU22: 800 | BV22: 0 | BW22: 0 | BX22: 0 | BY22: 0 | BZ22: 0 | CA22: 0 | CB22: 500 | CC22: 0 | CD22: 0 | CE22: 0 | CF22: 0 | CG22: 0 | CH22: 0 | CI22: 200 | CJ22: 0 | CK22: 0 | CL22: 0 | CM22: 0 | CN22: 0 | CO22: 0 | CP22: 150 | CQ22: 0 | CR22: 0 | CS22: 0 | CT22: 0 | CU22: 0 | CV22: 0 | CW22: 50 | CX22: 0 | CY22: 0 | CZ22: 0 | DA22: 0 | DB22: 0 | DC22: 0 | DD22: 50 | DE22: 0 | DF22: 0 | DG22: 0 | DH22: 0 | DI22: 0 | DJ22: 0 | DK22: 50 | DL22: 0 | DM22: 0 | DN22: 0 | DO22: 0 | DP22: 0 | DQ22: 0 | DR22: 50 | DS22: 0 | DT22: 0 | DU22: 0 | DV22: 0 | DW22: 0 | DX22: 0 | DY22: 50 | DZ22: 0 | EA22: 0 | EB22: 0 | EC22: 0 | ED22: 0 | EE22: 0 | EF22: 50 | EG22: 0 | EH22: 0 | EI22: 0 | EJ22: 0 | EK22: 0 | EL22: 0 | EM22: 50 | EN22: 0 | EO22: 0 | EP22: 0 | EQ22: 0 | ER22: 0 | ES22: 0 | ET22: 50 | EU22: 0 | EV22: 0 | EW22: 0 | EX22: 0 | EY22: 0 | EZ22: 0 | FA22: 50 | FB22: 0 | FC22: 0 | FD22: 0 | FE22: 0 | FF22: 0 | FG22: 0 | FH22: 50 | FI22: 0 | FJ22: 0 | FK22: 0 | FL22: 0 | FM22: 0 | FN22: 0 | FO22: 50 | FP22: 0 | FQ22: 0 | FR22: 0 | FS22: 0 | FT22: 0 | FU22: 0 | FV22: 250 | FW22: 0 | FX22: 0 | FY22: 0 | FZ22: 0 | GA22: 0 | GB22: 0 | GC22: 250 | GD22: 0 | GE22: 0 | GF22: 0 | GG22: 0 | GH22: 0 | GI22: 0 | GJ22: 50 | GK22: 0 | GL22: 0 | GM22: 0 | GN22: 0 | GO22: 0 | GP22: 0 | GQ22: 50 | GR22: 0 | GS22: 0 | GT22: 0 | GU22: 0 | GV22: 0 | GW22: 0 | GX22: 50 | GY22: 0 | GZ22: 0 | HA22: 0 | HB22: 0 | HC22: 0 | HD22: 0 | HE22: 50 | HF22: 0 | HG22: 0 | HH22: 0 | HI22: 0 | HJ22: 0 | HK22: 0 | HL22: 50 | HM22: 0 | HN22: 0 | HO22: 0 | HP22: 0 | HQ22: 0 | HR22: 0 | HS22: 0 | HT22: 0 | HU22: 0 | HV22: 0 | HW22: 0 | HX22: 0 | HY22: 0 | HZ22: 0 | IA22: 0 | IB22: 0 | IC22: 0 | ID22: 0 | IE22: 0 | IF22: 0 | IG22: 0 | IH22: 0 | II22: 0 | IJ22: 0 | IK22: 0 | IL22: 0 | IM22: 0 | IN22: 0 | IO22: 0 | IP22: 0 | IQ22: 0 | IR22: 0 | IS22: 0 | IT22: 0 | IU22: 0 | IV22: 0 | IW22: 0 | IX22: 0 | IY22: 0 | IZ22: 0 | JA22: 0 | JB22: 0 | JC22: 0 | JD22: 0 | JE22: 0 | JF22: 0 | JG22: 0 | JH22: 0 | JI22: 0 | JJ22: 0 | JK22: 0 | JL22: 0 | JM22: 0 | JN22: 0 | JO22: 0 | JP22: 0 | JQ22: 0 | JR22: 0 | JS22: 0 | JT22: 0 | JU22: 0 | JV22: 0 | JW22: 0 | JX22: 0 | JY22: 0 | JZ22: 0 | KA22: 0 | KB22: 0 | KC22: 0 | KD22: 0 | KE22: 0 | KF22: 0 | KG22: 0 | KH22: 0 | KI22: 0 | KJ22: 0 | KK22: 0 | KL22: 0 | KM22: 0 | KN22: 0 | KO22: 0 | KP22: 0 | KQ22: 0 | KR22: 0 | KS22: 0 | KT22: 0 | KU22: 0 | KV22: 0 | KW22: 0 | KX22: 0 | KY22: 0 | KZ22: 0 | LA22: 0 | LB22: 0 | LC22: 0 | LD22: 0 | LE22: 0 | LF22: 0 | LG22: 0 | LH22: 0 | LI22: 0 | LJ22: 0 | LK22: 0 | LL22: 0 | LM22: 0 | LN22: 0 | LO22: 0 | LP22: 0 | LQ22: 0 | LR22: 0 | LS22: 0 | LT22: 0 | LU22: 0 | LV22: 0 | LW22: 0 | LX22: 0 | LY22: 0 | LZ22: 0 | MA22: 0 | MB22: 0 | MC22: 0 | MD22: 0 | ME22: 0 | MF22: 0 | MG22: 0 | MH22: 0 | MI22: 0 | MJ22: 0 | MK22: 0 | ML22: 0 | MM22: 0 | MN22: 0 | MO22: 0 | MP22: 0 | MQ22: 0 | MR22: 0 | MS22: 0 | MT22: 0 | MU22: 0 | MV22: 0
E24: Cash from season tickets sale | G24: USD | H24: {=_xlfn.BYROW(_xlfn.ANCHORARRAY( J24), _xleta.SUM )} -> 22500000 | J24: {=_xlfn.ANCHORARRAY( J22) * SeasonTicketPrice} -> 3600000 | K24: 0 | L24: 0 | M24: 0 | N24: 0 | O24: 0 | P24: 0 | Q24: 2850000 | R24: 0 | S24: 0 | T24: 0 | U24: 0 | V24: 0 | W24: 0 | X24: 2550000 | Y24: 0 | Z24: 0 | AA24: 0 | AB24: 0 | AC24: 0 | AD24: 0 | AE24: 2100000 | AF24: 0 | AG24: 0 | AH24: 0 | AI24: 0 | AJ24: 0 | AK24: 0 | AL24: 2025000 | AM24: 0 | AN24: 0 | AO24: 0 | AP24: 0 | AQ24: 0 | AR24: 0 | AS24: 2062500 | AT24: 0 | AU24: 0 | AV24: 0 | AW24: 0 | AX24: 0 | AY24: 0 | AZ24: 1950000 | BA24: 0 | BB24: 0 | BC24: 0 | BD24: 0 | BE24: 0 | BF24: 0 | BG24: 2100000 | BH24: 0 | BI24: 0 | BJ24: 0 | BK24: 0 | BL24: 0 | BM24: 0 | BN24: 1050000 | BO24: 0 | BP24: 0 | BQ24: 0 | BR24: 0 | BS24: 0 | BT24: 0 | BU24: 600000 | BV24: 0 | BW24: 0 | BX24: 0 | BY24: 0 | BZ24: 0 | CA24: 0 | CB24: 375000 | CC24: 0 | CD24: 0 | CE24: 0 | CF24: 0 | CG24: 0 | CH24: 0 | CI24: 150000 | CJ24: 0 | CK24: 0 | CL24: 0 | CM24: 0 | CN24: 0 | CO24: 0 | CP24: 112500 | CQ24: 0 | CR24: 0 | CS24: 0 | CT24: 0 | CU24: 0 | CV24: 0 | CW24: 37500 | CX24: 0 | CY24: 0 | CZ24: 0 | DA24: 0 | DB24: 0 | DC24: 0 | DD24: 37500 | DE24: 0 | DF24: 0 | DG24: 0 | DH24: 0 | DI24: 0 | DJ24: 0 | DK24: 37500 | DL24: 0 | DM24: 0 | DN24: 0 | DO24: 0 | DP24: 0 | DQ24: 0 | DR24: 37500 | DS24: 0 | DT24: 0 | DU24: 0 | DV24: 0 | DW24: 0 | DX24: 0 | DY24: 37500 | DZ24: 0 | EA24: 0 | EB24: 0 | EC24: 0 | ED24: 0 | EE24: 0 | EF24: 37500 | EG24: 0 | EH24: 0 | EI24: 0 | EJ24: 0 | EK24: 0 | EL24: 0 | EM24: 37500 | EN24: 0 | EO24: 0 | EP24: 0 | EQ24: 0 | ER24: 0 | ES24: 0 | ET24: 37500 | EU24: 0 | EV24: 0 | EW24: 0 | EX24: 0 | EY24: 0 | EZ24: 0 | FA24: 37500 | FB24: 0 | FC24: 0 | FD24: 0 | FE24: 0 | FF24: 0 | FG24: 0 | FH24: 37500 | FI24: 0 | FJ24: 0 | FK24: 0 | FL24: 0 | FM24: 0 | FN24: 0 | FO24: 37500 | FP24: 0 | FQ24: 0 | FR24: 0 | FS24: 0 | FT24: 0 | FU24: 0 | FV24: 187500 | FW24: 0 | FX24: 0 | FY24: 0 | FZ24: 0 | GA24: 0 | GB24: 0 | GC24: 187500 | GD24: 0 | GE24: 0 | GF24: 0 | GG24: 0 | GH24: 0 | GI24: 0 | GJ24: 37500 | GK24: 0 | GL24: 0 | GM24: 0 | GN24: 0 | GO24: 0 | GP24: 0 | GQ24: 37500 | GR24: 0 | GS24: 0 | GT24: 0 | GU24: 0 | GV24: 0 | GW24: 0 | GX24: 37500 | GY24: 0 | GZ24: 0 | HA24: 0 | HB24: 0 | HC24: 0 | HD24: 0 | HE24: 37500 | HF24: 0 | HG24: 0 | HH24: 0 | HI24: 0 | HJ24: 0 | HK24: 0 | HL24: 37500 | HM24: 0 | HN24: 0 | HO24: 0 | HP24: 0 | HQ24: 0 | HR24: 0 | HS24: 0 | HT24: 0 | HU24: 0 | HV24: 0 | HW24: 0 | HX24: 0 | HY24: 0 | HZ24: 0 | IA24: 0 | IB24: 0 | IC24: 0 | ID24: 0 | IE24: 0 | IF24: 0 | IG24: 0 | IH24: 0 | II24: 0 | IJ24: 0 | IK24: 0 | IL24: 0 | IM24: 0 | IN24: 0 | IO24: 0 | IP24: 0 | IQ24: 0 | IR24: 0 | IS24: 0 | IT24: 0 | IU24: 0 | IV24: 0 | IW24: 0 | IX24: 0 | IY24: 0 | IZ24: 0 | JA24: 0 | JB24: 0 | JC24: 0 | JD24: 0 | JE24: 0 | JF24: 0 | JG24: 0 | JH24: 0 | JI24: 0 | JJ24: 0 | JK24: 0 | JL24: 0 | JM24: 0 | JN24: 0 | JO24: 0 | JP24: 0 | JQ24: 0 | JR24: 0 | JS24: 0 | JT24: 0 | JU24: 0 | JV24: 0 | JW24: 0 | JX24: 0 | JY24: 0 | JZ24: 0 | KA24: 0 | KB24: 0 | KC24: 0 | KD24: 0 | KE24: 0 | KF24: 0 | KG24: 0 | KH24: 0 | KI24: 0 | KJ24: 0 | KK24: 0 | KL24: 0 | KM24: 0 | KN24: 0 | KO24: 0 | KP24: 0 | KQ24: 0 | KR24: 0 | KS24: 0 | KT24: 0 | KU24: 0 | KV24: 0 | KW24: 0 | KX24: 0 | KY24: 0 | KZ24: 0 | LA24: 0 | LB24: 0 | LC24: 0 | LD24: 0 | LE24: 0 | LF24: 0 | LG24: 0 | LH24: 0 | LI24: 0 | LJ24: 0 | LK24: 0 | LL24: 0 | LM24: 0 | LN24: 0 | LO24: 0 | LP24: 0 | LQ24: 0 | LR24: 0 | LS24: 0 | LT24: 0 | LU24: 0 | LV24: 0 | LW24: 0 | LX24: 0 | LY24: 0 | LZ24: 0 | MA24: 0 | MB24: 0 | MC24: 0 | MD24: 0 | ME24: 0 | MF24: 0 | MG24: 0 | MH24: 0 | MI24: 0 | MJ24: 0 | MK24: 0 | ML24: 0 | MM24: 0 | MN24: 0 | MO24: 0 | MP24: 0 | MQ24: 0 | MR24: 0 | MS24: 0 | MT24: 0 | MU24: 0 | MV24: 0
E25: Pct of games played | G25: % | J25: {=_xlfn.LET( _xlpm.days_to_game,_xlfn.ANCHORARRAY( J15), _xlpm.number_of_games, ROWS( tbl_GameDates[Date] ), _xlfn.SCAN( 0, _xlpm.days_to_game, _xlfn.LAMBDA(_xlpm.acc,_xlpm.dtg, IF( _xlpm.dtg = 0, _xlpm.acc + 1 / _xlpm.number_of_games, _xlpm.acc ) ) ) )} -> 0 | K25: 0 | L25: 0 | M25: 0 | N25: 0 | O25: 0 | P25: 0 | Q25: 0 | R25: 0 | S25: 0 | T25: 0 | U25: 0 | V25: 0 | W25: 0 | X25: 0 | Y25: 0 | Z25: 0 | AA25: 0 | AB25: 0 | AC25: 0 | AD25: 0 | AE25: 0 | AF25: 0 | AG25: 0 | AH25: 0 | AI25: 0 | AJ25: 0 | AK25: 0 | AL25: 0 | AM25: 0 | AN25: 0 | AO25: 0 | AP25: 0 | AQ25: 0 | AR25: 0 | AS25: 0 | AT25: 0 | AU25: 0 | AV25: 0 | AW25: 0 | AX25: 0 | AY25: 0 | AZ25: 0 | BA25: 0 | BB25: 0 | BC25: 0 | BD25: 0 | BE25: 0 | BF25: 0 | BG25: 0 | BH25: 0 | BI25: 0 | BJ25: 0 | BK25: 0 | BL25: 0 | BM25: 0.025 | BN25: 0.025 | BO25: 0.025 | BP25: 0.025 | BQ25: 0.025 | BR25: 0.025 | BS25: 0.025 | BT25: 0.05 | BU25: 0.05 | BV25: 0.05 | BW25: 0.05 | BX25: 0.05 | BY25: 0.05 | BZ25: 0.05 | CA25: 0.075 | CB25: 0.075 | CC25: 0.075 | CD25: 0.075 | CE25: 0.075 | CF25: 0.075 | CG25: 0.075 | CH25: 0.1 | CI25: 0.1 | CJ25: 0.1 | CK25: 0.1 | CL25: 0.1 | CM25: 0.1 | CN25: 0.1 | CO25: 0.125 | CP25: 0.125 | CQ25: 0.125 | CR25: 0.125 | CS25: 0.125 | CT25: 0.125 | CU25: 0.125 | CV25: 0.15 | CW25: 0.15 | CX25: 0.15 | CY25: 0.15 | CZ25: 0.15 | DA25: 0.15 | DB25: 0.15 | DC25: 0.175 | DD25: 0.175 | DE25: 0.175 | DF25: 0.175 | DG25: 0.175 | DH25: 0.175 | DI25: 0.175 | DJ25: 0.2 | DK25: 0.2 | DL25: 0.2 | DM25: 0.2 | DN25: 0.2 | DO25: 0.2 | DP25: 0.2 | DQ25: 0.225 | DR25: 0.225 | DS25: 0.225 | DT25: 0.225 | DU25: 0.225 | DV25: 0.225 | DW25: 0.225 | DX25: 0.25 | DY25: 0.25 | DZ25: 0.25 | EA25: 0.25 | EB25: 0.25 | EC25: 0.25 | ED25: 0.25 | EE25: 0.275 | EF25: 0.275 | EG25: 0.275 | EH25: 0.275 | EI25: 0.275 | EJ25: 0.275 | EK25: 0.275 | EL25: 0.3 | EM25: 0.3 | EN25: 0.3 | EO25: 0.3 | EP25: 0.3 | EQ25: 0.3 | ER25: 0.3 | ES25: 0.325 | ET25: 0.325 | EU25: 0.325 | EV25: 0.325 | EW25: 0.325 | EX25: 0.325 | EY25: 0.325 | EZ25: 0.35 | FA25: 0.35 | FB25: 0.35 | FC25: 0.35 | FD25: 0.35 | FE25: 0.35 | FF25: 0.35 | FG25: 0.375 | FH25: 0.375 | FI25: 0.375 | FJ25: 0.375 | FK25: 0.375 | FL25: 0.375 | FM25: 0.375 | FN25: 0.4 | FO25: 0.4 | FP25: 0.4 | FQ25: 0.4 | FR25: 0.4 | FS25: 0.4 | FT25: 0.4 | FU25: 0.425 | FV25: 0.425 | FW25: 0.425 | FX25: 0.425 | FY25: 0.425 | FZ25: 0.425 | GA25: 0.425 | GB25: 0.45 | GC25: 0.45 | GD25: 0.45 | GE25: 0.45 | GF25: 0.45 | GG25: 0.45 | GH25: 0.45 | GI25: 0.45 | GJ25: 0.45 | GK25: 0.45 | GL25: 0.45 | GM25: 0.45 | GN25: 0.45 | GO25: 0.45 | GP25: 0.45 | GQ25: 0.45 | GR25: 0.45 | GS25: 0.45 | GT25: 0.45 | GU25: 0.45 | GV25: 0.45 | GW25: 0.475 | GX25: 0.475 | GY25: 0.475 | GZ25: 0.475 | HA25: 0.475 | HB25: 0.475 | HC25: 0.475 | HD25: 0.5 | HE25: 0.5 | HF25: 0.5 | HG25: 0.5 | HH25: 0.5 | HI25: 0.5 | HJ25: 0.5 | HK25: 0.525 | HL25: 0.525 | HM25: 0.525 | HN25: 0.525 | HO25: 0.525 | HP25: 0.525 | HQ25: 0.525 | HR25: 0.55 | HS25: 0.55 | HT25: 0.55 | HU25: 0.55 | HV25: 0.55 | HW25: 0.55 | HX25: 0.55 | HY25: 0.575 | HZ25: 0.575 | IA25: 0.575 | IB25: 0.575 | IC25: 0.575 | ID25: 0.575 | IE25: 0.575 | IF25: 0.6 | IG25: 0.6 | IH25: 0.6 | II25: 0.6 | IJ25: 0.6 | IK25: 0.6 | IL25: 0.6 | IM25: 0.625 | IN25: 0.625 | IO25: 0.625 | IP25: 0.625 | IQ25: 0.625 | IR25: 0.625 | IS25: 0.625 | IT25: 0.65 | IU25: 0.65 | IV25: 0.65 | IW25: 0.65 | IX25: 0.65 | IY25: 0.65 | IZ25: 0.65 | JA25: 0.675 | JB25: 0.675 | JC25: 0.675 | JD25: 0.675 | JE25: 0.675 | JF25: 0.675 | JG25: 0.675 | JH25: 0.7 | JI25: 0.7 | JJ25: 0.7 | JK25: 0.7 | JL25: 0.7 | JM25: 0.7 | JN25: 0.7 | JO25: 0.725 | JP25: 0.725 | JQ25: 0.725 | JR25: 0.725 | JS25: 0.725 | JT25: 0.725 | JU25: 0.725 | JV25: 0.75 | JW25: 0.75 | JX25: 0.75 | JY25: 0.75 | JZ25: 0.75 | KA25: 0.75 | KB25: 0.75 | KC25: 0.775 | KD25: 0.775 | KE25: 0.775 | KF25: 0.775 | KG25: 0.775 | KH25: 0.775 | KI25: 0.775 | KJ25: 0.8 | KK25: 0.8 | KL25: 0.8 | KM25: 0.8 | KN25: 0.8 | KO25: 0.8 | KP25: 0.8 | KQ25: 0.825 | KR25: 0.825 | KS25: 0.825 | KT25: 0.825 | KU25: 0.825 | KV25: 0.825 | KW25: 0.825 | KX25: 0.85 | KY25: 0.85 | KZ25: 0.85 | LA25: 0.85 | LB25: 0.85 | LC25: 0.85 | LD25: 0.85 | LE25: 0.875 | LF25: 0.875 | LG25: 0.875 | LH25: 0.875 | LI25: 0.875 | LJ25: 0.875 | LK25: 0.875 | LL25: 0.9 | LM25: 0.9 | LN25: 0.9 | LO25: 0.9 | LP25: 0.9 | LQ25: 0.9 | LR25: 0.9 | LS25: 0.925 | LT25: 0.925 | LU25: 0.925 | LV25: 0.925 | LW25: 0.925 | LX25: 0.925 | LY25: 0.925 | LZ25: 0.95 | MA25: 0.95 | MB25: 0.95 | MC25: 0.95 | MD25: 0.95 | ME25: 0.95 | MF25: 0.95 | MG25: 0.975 | MH25: 0.975 | MI25: 0.975 | MJ25: 0.975 | MK25: 0.975 | ML25: 0.975 | MM25: 0.975 | MN25: 0.975 | MO25: 0.975 | MP25: 0.975 | MQ25: 0.975 | MR25: 0.975 | MS25: 0.975 | MT25: 0.975 | MU25: 1 | MV25: 1
E26: Cumulative cash from season ticket sale | G26: USD | J26: {=_xlfn.LET( _xlpm.cash_from_sales,_xlfn.ANCHORARRAY( J24), _xlfn.SCAN( 0, _xlpm.cash_from_sales, _xlfn.LAMBDA(_xlpm.a,_xlpm.cash, _xlpm.a + _xlpm.cash ) ) )} -> 3600000 | K26: 3600000 | L26: 3600000 | M26: 3600000 | N26: 3600000 | O26: 3600000 | P26: 3600000 | Q26: 6450000 | R26: 6450000 | S26: 6450000 | T26: 6450000 | U26: 6450000 | V26: 6450000 | W26: 6450000 | X26: 9000000 | Y26: 9000000 | Z26: 9000000 | AA26: 9000000 | AB26: 9000000 | AC26: 9000000 | AD26: 9000000 | AE26: 11100000 | AF26: 11100000 | AG26: 11100000 | AH26: 11100000 | AI26: 11100000 | AJ26: 11100000 | AK26: 11100000 | AL26: 13125000 | AM26: 13125000 | AN26: 13125000 | AO26: 13125000 | AP26: 13125000 | AQ26: 13125000 | AR26: 13125000 | AS26: 15187500 | AT26: 15187500 | AU26: 15187500 | AV26: 15187500 | AW26: 15187500 | AX26: 15187500 | AY26: 15187500 | AZ26: 17137500 | BA26: 17137500 | BB26: 17137500 | BC26: 17137500 | BD26: 17137500 | BE26: 17137500 | BF26: 17137500 | BG26: 19237500 | BH26: 19237500 | BI26: 19237500 | BJ26: 19237500 | BK26: 19237500 | BL26: 19237500 | BM26: 19237500 | BN26: 20287500 | BO26: 20287500 | BP26: 20287500 | BQ26: 20287500 | BR26: 20287500 | BS26: 20287500 | BT26: 20287500 | BU26: 20887500 | BV26: 20887500 | BW26: 20887500 | BX26: 20887500 | BY26: 20887500 | BZ26: 20887500 | CA26: 20887500 | CB26: 21262500 | CC26: 21262500 | CD26: 21262500 | CE26: 21262500 | CF26: 21262500 | CG26: 21262500 | CH26: 21262500 | CI26: 21412500 | CJ26: 21412500 | CK26: 21412500 | CL26: 21412500 | CM26: 21412500 | CN26: 21412500 | CO26: 21412500 | CP26: 21525000 | CQ26: 21525000 | CR26: 21525000 | CS26: 21525000 | CT26: 21525000 | CU26: 21525000 | CV26: 21525000 | CW26: 21562500 | CX26: 21562500 | CY26: 21562500 | CZ26: 21562500 | DA26: 21562500 | DB26: 21562500 | DC26: 21562500 | DD26: 21600000 | DE26: 21600000 | DF26: 21600000 | DG26: 21600000 | DH26: 21600000 | DI26: 21600000 | DJ26: 21600000 | DK26: 21637500 | DL26: 21637500 | DM26: 21637500 | DN26: 21637500 | DO26: 21637500 | DP26: 21637500 | DQ26: 21637500 | DR26: 21675000 | DS26: 21675000 | DT26: 21675000 | DU26: 21675000 | DV26: 21675000 | DW26: 21675000 | DX26: 21675000 | DY26: 21712500 | DZ26: 21712500 | EA26: 21712500 | EB26: 21712500 | EC26: 21712500 | ED26: 21712500 | EE26: 21712500 | EF26: 21750000 | EG26: 21750000 | EH26: 21750000 | EI26: 21750000 | EJ26: 21750000 | EK26: 21750000 | EL26: 21750000 | EM26: 21787500 | EN26: 21787500 | EO26: 21787500 | EP26: 21787500 | EQ26: 21787500 | ER26: 21787500 | ES26: 21787500 | ET26: 21825000 | EU26: 21825000 | EV26: 21825000 | EW26: 21825000 | EX26: 21825000 | EY26: 21825000 | EZ26: 21825000 | FA26: 21862500 | FB26: 21862500 | FC26: 21862500 | FD26: 21862500 | FE26: 21862500 | FF26: 21862500 | FG26: 21862500 | FH26: 21900000 | FI26: 21900000 | FJ26: 21900000 | FK26: 21900000 | FL26: 21900000 | FM26: 21900000 | FN26: 21900000 | FO26: 21937500 | FP26: 21937500 | FQ26: 21937500 | FR26: 21937500 | FS26: 21937500 | FT26: 21937500 | FU26: 21937500 | FV26: 22125000 | FW26: 22125000 | FX26: 22125000 | FY26: 22125000 | FZ26: 22125000 | GA26: 22125000 | GB26: 22125000 | GC26: 22312500 | GD26: 22312500 | GE26: 22312500 | GF26: 22312500 | GG26: 22312500 | GH26: 22312500 | GI26: 22312500 | GJ26: 22350000 | GK26: 22350000 | GL26: 22350000 | GM26: 22350000 | GN26: 22350000 | GO26: 22350000 | GP26: 22350000 | GQ26: 22387500 | GR26: 22387500 | GS26: 22387500 | GT26: 22387500 | GU26: 22387500 | GV26: 22387500 | GW26: 22387500 | GX26: 22425000 | GY26: 22425000 | GZ26: 22425000 | HA26: 22425000 | HB26: 22425000 | HC26: 22425000 | HD26: 22425000 | HE26: 22462500 | HF26: 22462500 | HG26: 22462500 | HH26: 22462500 | HI26: 22462500 | HJ26: 22462500 | HK26: 22462500 | HL26: 22500000 | HM26: 22500000 | HN26: 22500000 | HO26: 22500000 | HP26: 22500000 | HQ26: 22500000 | HR26: 22500000 | HS26: 22500000 | HT26: 22500000 | HU26: 22500000 | HV26: 22500000 | HW26: 22500000 | HX26: 22500000 | HY26: 22500000 | HZ26: 22500000 | IA26: 22500000 | IB26: 22500000 | IC26: 22500000 | ID26: 22500000 | IE26: 22500000 | IF26: 22500000 | IG26: 22500000 | IH26: 22500000 | II26: 22500000 | IJ26: 22500000 | IK26: 22500000 | IL26: 22500000 | IM26: 22500000 | IN26: 22500000 | IO26: 22500000 | IP26: 22500000 | IQ26: 22500000 | IR26: 22500000 | IS26: 22500000 | IT26: 22500000 | IU26: 22500000 | IV26: 22500000 | IW26: 22500000 | IX26: 22500000 | IY26: 22500000 | IZ26: 22500000 | JA26: 22500000 | JB26: 22500000 | JC26: 22500000 | JD26: 22500000 | JE26: 22500000 | JF26: 22500000 | JG26: 22500000 | JH26: 22500000 | JI26: 22500000 | JJ26: 22500000 | JK26: 22500000 | JL26: 22500000 | JM26: 22500000 | JN26: 22500000 | JO26: 22500000 | JP26: 22500000 | JQ26: 22500000 | JR26: 22500000 | JS26: 22500000 | JT26: 22500000 | JU26: 22500000 | JV26: 22500000 | JW26: 22500000 | JX26: 22500000 | JY26: 22500000 | JZ26: 22500000 | KA26: 22500000 | KB26: 22500000 | KC26: 22500000 | KD26: 22500000 | KE26: 22500000 | KF26: 22500000 | KG26: 22500000 | KH26: 22500000 | KI26: 22500000 | KJ26: 22500000 | KK26: 22500000 | KL26: 22500000 | KM26: 22500000 | KN26: 22500000 | KO26: 22500000 | KP26: 22500000 | KQ26: 22500000 | KR26: 22500000 | KS26: 22500000 | KT26: 22500000 | KU26: 22500000 | KV26: 22500000 | KW26: 22500000 | KX26: 22500000 | KY26: 22500000 | KZ26: 22500000 | LA26: 22500000 | LB26: 22500000 | LC26: 22500000 | LD26: 22500000 | LE26: 22500000 | LF26: 22500000 | LG26: 22500000 | LH26: 22500000 | LI26: 22500000 | LJ26: 22500000 | LK26: 22500000 | LL26: 22500000 | LM26: 22500000 | LN26: 22500000 | LO26: 22500000 | LP26: 22500000 | LQ26: 22500000 | LR26: 22500000 | LS26: 22500000 | LT26: 22500000 | LU26: 22500000 | LV26: 22500000 | LW26: 22500000 | LX26: 22500000 | LY26: 22500000 | LZ26: 22500000 | MA26: 22500000 | MB26: 22500000 | MC26: 22500000 | MD26: 22500000 | ME26: 22500000 | MF26: 22500000 | MG26: 22500000 | MH26: 22500000 | MI26: 22500000 | MJ26: 22500000 | MK26: 22500000 | ML26: 22500000 | MM26: 22500000 | MN26: 22500000 | MO26: 22500000 | MP26: 22500000 | MQ26: 22500000 | MR26: 22500000 | MS26: 22500000 | MT26: 22500000 | MU26: 22500000 | MV26: 22500000
