Workbook
Name company: CaseData!$C$55
Name days_per_month: CaseData!$L$33
Name periods: CaseData!$C$57
Name start_date: CaseData!$C$3
Name topic: "CFM Topic: " & CaseData!$C$56

Sheet Working Capital
A1: =company -> Sweet Dreams Co.
A2: {=topic} -> CFM Topic: Working Capital
A3: WORKING CAPITAL SCHEDULE | F3: Constant | G3: Unit | H3: Total | J3: {=EOMONTH( start_date, _xlfn.SEQUENCE( 1, periods, 0, 1 ) )} -> 44592 | K3: 44620 | L3: 44651 | M3: 44681 | N3: 44712 | O3: 44742 | P3: 44773 | Q3: 44804 | R3: 44834 | S3: 44865 | T3: 44895 | U3: 44926
A5: Working capital
E8: Accounts receivable | G8: USD | J8: {=_xlfn.ANCHORARRAY('Accounts Receivables'!J103)} -> 1177500 | K8: 1221863 | L8: 1307818.5 | M8: 1416863.5 | N8: 1523910 | O8: 1630955 | P8: 1736000.5 | Q8: 1846043.5 | R8: 1952091 | S8: 2059136 | T8: 2164182.5 | U8: 2274227.5
E9: Inventory | G9: USD | J9: {=_xlfn.ANCHORARRAY(Inventory!J128)} -> 64959.044 | K9: 70608.896 | L9: 76154.322 | M9: 81489.402 | N9: 87033.586 | O9: 92370.663 | P9: 97912.64 | Q9: 103039.81 | R9: 108792.01 | S9: 113925.51 | T9: 119671.27 | U9: 119671.27
E10: Accounts payable | G10: USD | J10: {=_xlfn.ANCHORARRAY( 'Accounts Payable'!J151)} -> 155978.3 | K10: 169502.84 | L10: 183521.61 | M10: 197908.02 | N10: 211399.22 | O10: 225781.25 | P10: 239281.41 | Q10: 253531.87 | R10: 267117.12 | S10: 281407.67 | T10: 295000.2 | U10: 306591.69
E12: Working capital | G12: USD | J12: {=_xlfn.ANCHORARRAY( J8) +_xlfn.ANCHORARRAY( J9) -_xlfn.ANCHORARRAY( J10)} -> 1086480.7 | K12: 1122969.1 | L12: 1200451.2 | M12: 1300444.9 | N12: 1399544.4 | O12: 1497544.4 | P12: 1594631.7 | Q12: 1695551.4 | R12: 1793765.9 | S12: 1891653.8 | T12: 1988853.6 | U12: 2087307.1
A45: End of schedule

Sheet Accounts Payable
A1: =company -> Sweet Dreams Co.
A2: {=topic} -> CFM Topic: Working Capital
A3: ACCOUNTS PAYABLE SCHEDULE | F3: Constant | G3: Unit | H3: Total | J3: {=EOMONTH( start_date, _xlfn.SEQUENCE( 1, periods, 0, 1 ) )} -> 44592 | K3: 44620 | L3: 44651 | M3: 44681 | N3: 44712 | O3: 44742 | P3: 44773 | Q3: 44804 | R3: 44834 | S3: 44865 | T3: 44895 | U3: 44926
A5: Accounts payable
B7: Payment Terms
C9: Supplier I
E11: Payment terms | F11: =INDEX( CaseData!$L$26:$L$30, MATCH( $C9, CaseData!$I$26:$I$30, 0 ) ) / days_per_month -> 0.5 | G11: months
F13: Months | G13: POs | J13: {=_xlfn.SEQUENCE( 1, periods, 1, 1 )} -> 1 | K13: 2 | L13: 3 | M13: 4 | N13: 5 | O13: 6 | P13: 7 | Q13: 8 | R13: 9 | S13: 10 | T13: 11 | U13: 12
F14: =$F15 - 1 -> 0 | G14: =INDEX( CaseData!$M$26:$M$30, MATCH( $C9, CaseData!$I$26:$I$30, 0 ) ) -> 75000 | J14: {=IF(_xlfn.ANCHORARRAY( J13) - $F14:$F26 < 0, 0, IF(_xlfn.ANCHORARRAY( J13) - $F14:$F26 < INT($F11), 1, IF(_xlfn.ANCHORARRAY( J13) - $F14:$F26 < $F11, MOD($F11, 1), 0 ) ) )} -> 0 | K14: 0 | L14: 0 | M14: 0 | N14: 0 | O14: 0 | P14: 0 | Q14: 0 | R14: 0 | S14: 0 | T14: 0 | U14: 0
F15: {=_xlfn.SEQUENCE( periods, 1, 1, 1 )} -> 1 | G15: {=_xlfn.LET( _xlpm.purchase_orders,_xlfn.ANCHORARRAY( 'Purchasing Plan'!$J$99), _xlpm.suppliers,_xlfn.ANCHORARRAY( 'Purchasing Plan'!$E$99), _xlpm.current_supplier, $C9, _xlpm.zero_row, _xlfn.SEQUENCE( 1, COLUMNS( _xlpm.purchase_orders ), 0, 0 ), IFERROR( TRANSPOSE( INDEX( _xlpm.purchase_orders, MATCH( _xlpm.current_supplier, _xlpm.suppliers, 0 ), 0 ) ), TRANSPOSE( _xlpm.zero_row ) ) )} -> 0 | J15: 0.5 | K15: 0 | L15: 0 | M15: 0 | N15: 0 | O15: 0 | P15: 0 | Q15: 0 | R15: 0 | S15: 0 | T15: 0 | U15: 0
F16: 2 | G16: 0 | J16: 0 | K16: 0.5 | L16: 0 | M16: 0 | N16: 0 | O16: 0 | P16: 0 | Q16: 0 | R16: 0 | S16: 0 | T16: 0 | U16: 0
F17: 3 | G17: 0 | J17: 0 | K17: 0 | L17: 0.5 | M17: 0 | N17: 0 | O17: 0 | P17: 0 | Q17: 0 | R17: 0 | S17: 0 | T17: 0 | U17: 0
F18: 4 | G18: 0 | J18: 0 | K18: 0 | L18: 0 | M18: 0.5 | N18: 0 | O18: 0 | P18: 0 | Q18: 0 | R18: 0 | S18: 0 | T18: 0 | U18: 0
F19: 5 | G19: 0 | J19: 0 | K19: 0 | L19: 0 | M19: 0 | N19: 0.5 | O19: 0 | P19: 0 | Q19: 0 | R19: 0 | S19: 0 | T19: 0 | U19: 0
F20: 6 | G20: 0 | J20: 0 | K20: 0 | L20: 0 | M20: 0 | N20: 0 | O20: 0.5 | P20: 0 | Q20: 0 | R20: 0 | S20: 0 | T20: 0 | U20: 0
F21: 7 | G21: 0 | J21: 0 | K21: 0 | L21: 0 | M21: 0 | N21: 0 | O21: 0 | P21: 0.5 | Q21: 0 | R21: 0 | S21: 0 | T21: 0 | U21: 0
F22: 8 | G22: 0 | J22: 0 | K22: 0 | L22: 0 | M22: 0 | N22: 0 | O22: 0 | P22: 0 | Q22: 0.5 | R22: 0 | S22: 0 | T22: 0 | U22: 0
F23: 9 | G23: 0 | J23: 0 | K23: 0 | L23: 0 | M23: 0 | N23: 0 | O23: 0 | P23: 0 | Q23: 0 | R23: 0.5 | S23: 0 | T23: 0 | U23: 0
F24: 10 | G24: 0 | J24: 0 | K24: 0 | L24: 0 | M24: 0 | N24: 0 | O24: 0 | P24: 0 | Q24: 0 | R24: 0 | S24: 0.5 | T24: 0 | U24: 0
F25: 11 | G25: 0 | J25: 0 | K25: 0 | L25: 0 | M25: 0 | N25: 0 | O25: 0 | P25: 0 | Q25: 0 | R25: 0 | S25: 0 | T25: 0.5 | U25: 0
F26: 12 | G26: 0 | J26: 0 | K26: 0 | L26: 0 | M26: 0 | N26: 0 | O26: 0 | P26: 0 | Q26: 0 | R26: 0 | S26: 0 | T26: 0 | U26: 0.5
E27: Accounts payable closing balance | J27: {=_xlfn.BYCOL(_xlfn.ANCHORARRAY( J14), _xlfn.LAMBDA(_xlpm.month_col, SUMPRODUCT( $G14:$G26, _xlpm.month_col ) ) )} -> 0 | K27: 0 | L27: 0 | M27: 0 | N27: 0 | O27: 0 | P27: 0 | Q27: 0 | R27: 0 | S27: 0 | T27: 0 | U27: 0
E30: Accounts payable opening balance | G30: USD | J30: {=_xlfn.DROP( _xlfn.HSTACK( $G14,_xlfn.ANCHORARRAY( J33) ),, - 1 )} -> 75000 | K30: 0 | L30: 0 | M30: 0 | N30: 0 | O30: 0 | P30: 0 | Q30: 0 | R30: 0 | S30: 0 | T30: 0 | U30: 0
E31: Purchase Orders | G31: USD | J31: {=TRANSPOSE(_xlfn.ANCHORARRAY( $G15) )} -> 0 | K31: 0 | L31: 0 | M31: 0 | N31: 0 | O31: 0 | P31: 0 | Q31: 0 | R31: 0 | S31: 0 | T31: 0 | U31: 0
E32: Payments made to supplier | G32: USD | J32: {=_xlfn.LET( _xlpm.ap_opening,_xlfn.ANCHORARRAY( J30), _xlpm.po,_xlfn.ANCHORARRAY( J31), _xlpm.ap_closing,_xlfn.ANCHORARRAY( J33), ( _xlpm.ap_opening + _xlpm.po - _xlpm.ap_closing ) * - 1 )} -> -75000 | K32: 0 | L32: 0 | M32: 0 | N32: 0 | O32: 0 | P32: 0 | Q32: 0 | R32: 0 | S32: 0 | T32: 0 | U32: 0
E33: Supplier I: Accounts payable closing balance | G33: USD | J33: {=_xlfn.ANCHORARRAY( J27)} -> 0 | K33: 0 | L33: 0 | M33: 0 | N33: 0 | O33: 0 | P33: 0 | Q33: 0 | R33: 0 | S33: 0 | T33: 0 | U33: 0
C36: Supplier II
E38: Payment terms | F38: =INDEX( CaseData!$L$26:$L$30, MATCH( $C36, CaseData!$I$26:$I$30, 0 ) ) / days_per_month -> 1 | G38: months
F40: Months | G40: POs | J40: {=_xlfn.SEQUENCE( 1, periods, 1, 1 )} -> 1 | K40: 2 | L40: 3 | M40: 4 | N40: 5 | O40: 6 | P40: 7 | Q40: 8 | R40: 9 | S40: 10 | T40: 11 | U40: 12
F41: =$F42 - 1 -> 0 | G41: =INDEX( CaseData!$M$26:$M$30, MATCH( $C36, CaseData!$I$26:$I$30, 0 ) ) -> 0 | J41: {=IF(_xlfn.ANCHORARRAY( J40) - $F41:$F53 < 0, 0, IF(_xlfn.ANCHORARRAY( J40) - $F41:$F53 < INT($F38), 1, IF(_xlfn.ANCHORARRAY( J40) - $F41:$F53 < $F38, MOD($F38, 1), 0 ) ) )} -> 0 | K41: 0 | L41: 0 | M41: 0 | N41: 0 | O41: 0 | P41: 0 | Q41: 0 | R41: 0 | S41: 0 | T41: 0 | U41: 0
F42: {=_xlfn.SEQUENCE( periods, 1, 1, 1 )} -> 1 | G42: {=_xlfn.LET( _xlpm.purchase_orders,_xlfn.ANCHORARRAY( 'Purchasing Plan'!$J$99), _xlpm.suppliers,_xlfn.ANCHORARRAY( 'Purchasing Plan'!$E$99), _xlpm.current_supplier, $C36, _xlpm.zero_row, _xlfn.SEQUENCE( 1, COLUMNS( _xlpm.purchase_orders ), 0, 0 ), IFERROR( TRANSPOSE( INDEX( _xlpm.purchase_orders, MATCH( _xlpm.current_supplier, _xlpm.suppliers, 0 ), 0 ) ), TRANSPOSE( _xlpm.zero_row ) ) )} -> 75542.091 | J42: 1 | K42: 0 | L42: 0 | M42: 0 | N42: 0 | O42: 0 | P42: 0 | Q42: 0 | R42: 0 | S42: 0 | T42: 0 | U42: 0
F43: 2 | G43: 82056.489 | J43: 0 | K43: 1 | L43: 0 | M43: 0 | N43: 0 | O43: 0 | P43: 0 | Q43: 0 | R43: 0 | S43: 0 | T43: 0 | U43: 0
F44: 3 | G44: 88960.502 | J44: 0 | K44: 0 | L44: 1 | M44: 0 | N44: 0 | O44: 0 | P44: 0 | Q44: 0 | R44: 0 | S44: 0 | T44: 0 | U44: 0
F45: 4 | G45: 95851.232 | J45: 0 | K45: 0 | L45: 0 | M45: 1 | N45: 0 | O45: 0 | P45: 0 | Q45: 0 | R45: 0 | S45: 0 | T45: 0 | U45: 0
F46: 5 | G46: 102444.86 | J46: 0 | K46: 0 | L46: 0 | M46: 0 | N46: 1 | O46: 0 | P46: 0 | Q46: 0 | R46: 0 | S46: 0 | T46: 0 | U46: 0
F47: 6 | G47: 109334.06 | J47: 0 | K47: 0 | L47: 0 | M47: 0 | N47: 0 | O47: 1 | P47: 0 | Q47: 0 | R47: 0 | S47: 0 | T47: 0 | U47: 0
F48: 7 | G48: 115930.64 | J48: 0 | K48: 0 | L48: 0 | M48: 0 | N48: 0 | O48: 0 | P48: 1 | Q48: 0 | R48: 0 | S48: 0 | T48: 0 | U48: 0
F49: 8 | G49: 122731.55 | J49: 0 | K49: 0 | L49: 0 | M49: 0 | N49: 0 | O49: 0 | P49: 0 | Q49: 1 | R49: 0 | S49: 0 | T49: 0 | U49: 0
F50: 9 | G50: 129267.18 | J50: 0 | K50: 0 | L50: 0 | M50: 0 | N50: 0 | O50: 0 | P50: 0 | Q50: 0 | R50: 1 | S50: 0 | T50: 0 | U50: 0
F51: 10 | G51: 136216.23 | J51: 0 | K51: 0 | L51: 0 | M51: 0 | N51: 0 | O51: 0 | P51: 0 | Q51: 0 | R51: 0 | S51: 1 | T51: 0 | U51: 0
...

Sheet Purchasing Plan
A1: =company -> Sweet Dreams Co.
A2: {=topic} -> CFM Topic: Working Capital
A3: PURCHASING PLAN SCHEDULE | F3: Constant | G3: Unit | H3: Total | J3: {=EOMONTH( start_date, _xlfn.SEQUENCE( 1, periods, 0, 1 ) )} -> 44592 | K3: 44620 | L3: 44651 | M3: 44681 | N3: 44712 | O3: 44742 | P3: 44773 | Q3: 44804 | R3: 44834 | S3: 44865 | T3: 44895 | U3: 44926
A5: Ingredients used in product manufactured
E8: Product A
E9: {=TRANSPOSE( CaseData!$C$39:$J$39 )} -> Flour | F9: {=TRANSPOSE( CaseData!$C40:$J40)} -> 0.3 | G9: kg | J9: {=_xlfn.LET( _xlpm.volume, INDEX( Inventory!$J$91:$U$93, MATCH( $E8,_xlfn.ANCHORARRAY( Inventory!$E$59), 0), 0 ), _xlpm.quantities, INDEX(_xlfn.ANCHORARRAY( $F9), 0, 1 ), _xlpm.volume * _xlpm.quantities)} -> 32270.368 | K9: 35002.738 | L9: 38091.168 | M9: 40965.969 | N9: 43840.876 | O9: 46715.572 | P9: 49590.478 | Q9: 52394.741 | R9: 55128.818 | S9: 58145.932 | T9: 60882.869 | U9: 63245.766
E10: Sugar | F10: 0.25 | G10: kg | J10: 26891.973 | K10: 29168.948 | L10: 31742.64 | M10: 34138.308 | N10: 36534.063 | O10: 38929.643 | P10: 41325.398 | Q10: 43662.284 | R10: 45940.682 | S10: 48454.943 | T10: 50735.724 | U10: 52704.805
E11: Butter | F11: 0.15 | G11: kg | J11: 16135.184 | K11: 17501.369 | L11: 19045.584 | M11: 20482.985 | N11: 21920.438 | O11: 23357.786 | P11: 24795.239 | Q11: 26197.371 | R11: 27564.409 | S11: 29072.966 | T11: 30441.434 | U11: 31622.883
E12: Milk | F12: 0.15 | G12: kg | J12: 16135.184 | K12: 17501.369 | L12: 19045.584 | M12: 20482.985 | N12: 21920.438 | O12: 23357.786 | P12: 24795.239 | Q12: 26197.371 | R12: 27564.409 | S12: 29072.966 | T12: 30441.434 | U12: 31622.883
E13: Eggs | F13: 0.15 | G13: kg | J13: 16135.184 | K13: 17501.369 | L13: 19045.584 | M13: 20482.985 | N13: 21920.438 | O13: 23357.786 | P13: 24795.239 | Q13: 26197.371 | R13: 27564.409 | S13: 29072.966 | T13: 30441.434 | U13: 31622.883
E14: Chocolate | F14: 0.1 | G14: kg | J14: 10756.789 | K14: 11667.579 | L14: 12697.056 | M14: 13655.323 | N14: 14613.625 | O14: 15571.857 | P14: 16530.159 | Q14: 17464.914 | R14: 18376.273 | S14: 19381.977 | T14: 20294.29 | U14: 21081.922
E15: Raisins | F15: 0 | G15: kg | J15: 0 | K15: 0 | L15: 0 | M15: 0 | N15: 0 | O15: 0 | P15: 0 | Q15: 0 | R15: 0 | S15: 0 | T15: 0 | U15: 0
E16: Bananas | F16: 0 | G16: kg | J16: 0 | K16: 0 | L16: 0 | M16: 0 | N16: 0 | O16: 0 | P16: 0 | Q16: 0 | R16: 0 | S16: 0 | T16: 0 | U16: 0
E17: Total ingredients | G17: kg | J17: {=_xlfn.BYCOL(_xlfn.ANCHORARRAY( J9), _xleta.SUM )} -> 118324.68 | K17: 128343.37 | L17: 139667.62 | M17: 150208.55 | N17: 160749.88 | O17: 171290.43 | P17: 181831.75 | Q17: 192114.05 | R17: 202139 | S17: 213201.75 | T17: 223237.18 | U17: 231901.14
E18: of which lost due to baking | G18: kg | J18: {=_xlfn.LET( _xlpm.volume, INDEX(_xlfn.ANCHORARRAY( Inventory!$J$59), MATCH( $E8,_xlfn.ANCHORARRAY( Inventory!E59), 0), 0 ), _xlpm.ingredients, INDEX(_xlfn.ANCHORARRAY( J17), 1, 0 ), _xlpm.ingredients - _xlpm.volume )} -> 12915.072 | K18: 14300.632 | L18: 15092.665 | M18: 16051.166 | N18: 17009.117 | O18: 17967.7 | P18: 18925.651 | Q18: 19625.982 | R18: 21006.657 | S18: 21547.871 | T18: 22919.731 | U18: 21081.922
E22: Product B
E23: {=TRANSPOSE( CaseData!$C$39:$J$39 )} -> Flour | F23: {=TRANSPOSE( CaseData!$C41:$J41)} -> 0.321 | G23: kg | J23: {=_xlfn.LET( _xlpm.volume, INDEX( Inventory!$J$91:$U$93, MATCH( $E22,_xlfn.ANCHORARRAY( Inventory!$E$59), 0), 0 ), _xlpm.quantities, INDEX(_xlfn.ANCHORARRAY( $F23), 0, 1 ), _xlpm.volume * _xlpm.quantities)} -> 21035.584 | K23: 22908.472 | L23: 24626.461 | M23: 26698.956 | N23: 28418.765 | O23: 30489.662 | P23: 32213.062 | Q23: 34301.272 | R23: 36196.39 | S23: 38091.432 | T23: 39986.646 | U23: 41692.164
E24: Sugar | F24: 0.24 | G24: kg | J24: 15727.539 | K24: 17127.83 | L24: 18412.307 | M24: 19961.836 | N24: 21247.674 | O24: 22796.009 | P24: 24084.532 | Q24: 25645.811 | R24: 27062.722 | S24: 28479.575 | T24: 29896.558 | U24: 31171.711
E25: Butter | F25: 0.155 | G25: kg | J25: 10157.369 | K25: 11061.723 | L25: 11891.282 | M25: 12892.019 | N25: 13722.456 | O25: 14722.422 | P25: 15554.594 | Q25: 16562.92 | R25: 17478.008 | S25: 18393.059 | T25: 19308.194 | U25: 20131.73
E26: Milk | F26: 0.161 | G26: kg | J26: 10550.558 | K26: 11489.919 | L26: 12351.59 | M26: 13391.065 | N26: 14253.648 | O26: 15292.323 | P26: 16156.707 | Q26: 17204.065 | R26: 18154.576 | S26: 19105.048 | T26: 20055.608 | U26: 20911.023
E27: Eggs | F27: 0.138 | G27: kg | J27: 9043.3352 | K27: 9848.502 | L27: 10587.077 | M27: 11478.056 | N27: 12217.413 | O27: 13107.705 | P27: 13848.606 | Q27: 14746.341 | R27: 15561.065 | S27: 16375.756 | T27: 17190.521 | U27: 17923.734
E28: Chocolate | F28: 0 | G28: kg | J28: 0 | K28: 0 | L28: 0 | M28: 0 | N28: 0 | O28: 0 | P28: 0 | Q28: 0 | R28: 0 | S28: 0 | T28: 0 | U28: 0
E29: Raisins | F29: 0.1 | G29: kg | J29: 6553.1414 | K29: 7136.5957 | L29: 7671.7948 | M29: 8317.4317 | N29: 8853.1977 | O29: 9498.3371 | P29: 10035.222 | Q29: 10685.755 | R29: 11276.134 | S29: 11866.49 | T29: 12456.899 | U29: 12988.213
E30: Bananas | F30: 0 | G30: kg | J30: 0 | K30: 0 | L30: 0 | M30: 0 | N30: 0 | O30: 0 | P30: 0 | Q30: 0 | R30: 0 | S30: 0 | T30: 0 | U30: 0
E31: Total ingredients | G31: kg | J31: {=_xlfn.BYCOL(_xlfn.ANCHORARRAY( J23), _xleta.SUM )} -> 73067.527 | K31: 79573.042 | L31: 85540.512 | M31: 92739.363 | N31: 98713.154 | O31: 105906.46 | P31: 111892.72 | Q31: 119146.16 | R31: 125728.89 | S31: 132311.36 | T31: 138894.43 | U31: 144818.58
E32: of which lost due to baking | G32: kg | J32: {=_xlfn.LET( _xlpm.volume, INDEX(_xlfn.ANCHORARRAY( Inventory!$J$59), MATCH( $E22,_xlfn.ANCHORARRAY( Inventory!$E$59), 0), 0 ), _xlpm.ingredients, INDEX(_xlfn.ANCHORARRAY( J31), 1, 0 ), _xlpm.ingredients - _xlpm.volume )} -> 8126.4614 | K32: 8728.4882 | L32: 9481.9259 | M32: 10087.158 | N32: 10839.831 | O32: 11446.602 | P32: 12197.721 | Q32: 12879.001 | R32: 13557.903 | S32: 14236.879 | T32: 14915.783 | U32: 14936.445
E36: Product C
E37: {=TRANSPOSE( CaseData!$C$39:$J$39 )} -> Flour | F37: {=TRANSPOSE( CaseData!$C42:$J42)} -> 0.306 | G37: kg | J37: {=_xlfn.LET( _xlpm.volume, INDEX( Inventory!$J$91:$U$93, MATCH( $E36,_xlfn.ANCHORARRAY( Inventory!$E$59), 0), 0 ), _xlpm.quantities, INDEX(_xlfn.ANCHORARRAY( $F37), 0, 1 ), _xlpm.volume * _xlpm.quantities)} -> 8813.4821 | K37: 9593.465 | L37: 10373.386 | M37: 11153.332 | N37: 11933.315 | O37: 12713.235 | P37: 13493.154 | Q37: 14273.102 | R37: 15053.084 | S37: 15833.004 | T37: 16612.952 | U37: 17158.959
E38: Sugar | F38: 0.233 | G38: kg | J38: 6710.9194 | K38: 7304.8279 | L38: 7898.6891 | M38: 8492.5698 | N38: 9086.4783 | O38: 9680.3392 | P38: 10274.199 | Q38: 10868.081 | R38: 11461.989 | S38: 12055.85 | T38: 12649.731 | U38: 13065.481
E39: Butter | F39: 0.149 | G39: kg | J39: 4291.5321 | K39: 4671.3277 | L39: 5051.093 | M39: 5430.8708 | N39: 5810.6664 | O39: 6190.4315 | P39: 6570.1961 | Q39: 6949.9745 | R39: 7329.7699 | S39: 7709.5348 | T39: 8089.3132 | U39: 8355.1791
E40: Milk | F40: 0.137 | G40: kg | J40: 3945.9054 | K40: 4295.1134 | L40: 4644.2936 | M40: 4993.4852 | N40: 5342.6933 | O40: 5691.8733 | P40: 6041.0528 | Q40: 6390.245 | R40: 6739.4528 | S40: 7088.6326 | T40: 7437.8249 | U40: 7682.2788
E41: Eggs | F41: 0.155 | G41: kg | J41: 4464.3455 | K41: 4859.4349 | L41: 5254.4927 | M41: 5649.5636 | N41: 6044.653 | O41: 6439.7107 | P41: 6834.7677 | Q41: 7229.8393 | R41: 7624.9284 | S41: 8019.9858 | T41: 8415.0573 | U41: 8691.6293
E42: Chocolate | F42: 0.05 | G42: kg | J42: 1440.1115 | K42: 1567.5596 | L42: 1694.9977 | M42: 1822.4399 | N42: 1949.8881 | O42: 2077.326 | P42: 2204.7638 | Q42: 2332.2062 | R42: 2459.6543 | S42: 2587.0922 | T42: 2714.5346 | U42: 2803.7514
E43: Raisins | F43: 0 | G43: kg | J43: 0 | K43: 0 | L43: 0 | M43: 0 | N43: 0 | O43: 0 | P43: 0 | Q43: 0 | R43: 0 | S43: 0 | T43: 0 | U43: 0
E44: Bananas | F44: 0.2 | G44: kg | J44: 5760.4458 | K44: 6270.2386 | L44: 6779.9906 | M44: 7289.7595 | N44: 7799.5522 | O44: 8309.3041 | P44: 8819.0552 | Q44: 9328.8249 | R44: 9838.6173 | S44: 10348.369 | T44: 10858.139 | U44: 11215.006
E45: Total ingredients | G45: kg | J45: {=_xlfn.BYCOL(_xlfn.ANCHORARRAY( J37), _xleta.SUM )} -> 35426.742 | K45: 38561.967 | L45: 41696.942 | M45: 44832.021 | N45: 47967.246 | O45: 51102.22 | P45: 54237.189 | Q45: 57372.273 | R45: 60507.496 | S45: 63642.468 | T45: 66777.552 | U45: 68972.284
E46: of which lost due to baking | G46: kg | J46: {=_xlfn.LET( _xlpm.volume, INDEX(_xlfn.ANCHORARRAY( Inventory!$J$59), MATCH( $E36,_xlfn.ANCHORARRAY( Inventory!$E$59), 0), 0 ), _xlpm.ingredients, INDEX(_xlfn.ANCHORARRAY( J45), 1, 0 ), _xlpm.ingredients - _xlpm.volume )} -> 7389.2278 | K46: 7975.403 | L46: 8561.6159 | M46: 9147.9385 | N46: 9734.1137 | O46: 10320.325 | P46: 10906.542 | Q46: 11492.864 | R46: 12079.037 | S46: 12665.253 | T46: 13251.574 | U46: 12897.256
A49: Purchase plan (in kg)
B51: Purchase orders by ingredient
E53: {=TRANSPOSE( CaseData!$C$39:$J$39 )} -> Flour | G53: kg | J53: {=_xlfn.LET( _xlpm.kg_data, IF( $J$9:$U$46="", 0, $J$9:$U$46 ), _xlpm.kg_rows, $E$9:$E$46, _xlpm.current_product,_xlfn.ANCHORARRAY( E53), _xlpm.match_matrix, --( _xlpm.kg_rows = TRANSPOSE( _xlpm.current_product ) ), MMULT( TRANSPOSE( _xlpm.match_matrix ), _xlpm.kg_data ) )} -> 62119.434 | K53: 67504.675 | L53: 73091.015 | M53: 78818.257 | N53: 84192.955 | O53: 89918.469 | P53: 95296.695 | Q53: 100969.12 | R53: 106378.29 | S53: 112070.37 | T53: 117482.47 | U53: 122096.89
...

Sheet Inventory
A1: {=company} -> Sweet Dreams Co.
A2: {=topic} -> CFM Topic: Working Capital
A3: INVENTORY SCHEDULE | F3: Constant | G3: Unit | H3: Total | J3: {=EOMONTH( start_date, _xlfn.SEQUENCE( 1, periods, 0, 1 ) )} -> 44592 | K3: 44620 | L3: 44651 | M3: 44681 | N3: 44712 | O3: 44742 | P3: 44773 | Q3: 44804 | R3: 44834 | S3: 44865 | T3: 44895 | U3: 44926
A5: Sales
B7: Product sales (after discount)
E9: {=IF( INDEX( CaseData!$A$7:$A$20,,1 ) = "", "", INDEX( CaseData!$A$7:$A$20,,1 ) )} -> Retailer 1 | G9: USD | J9: {=_xlfn.LET( _xlpm.revenue_data, CaseData!$C$7:$N$20, _xlpm.revenue_columns, CaseData!$C$3:$N$3, _xlpm.current_row,_xlfn.ANCHORARRAY( $E$9), _xlpm.current_column,_xlfn.ANCHORARRAY( $J$3), _xlpm.row_position, _xlfn.SEQUENCE( ROWS( _xlpm.current_row ) ), _xlpm.revenue, INDEX( _xlpm.revenue_data, _xlpm.row_position, _xlfn.XMATCH( _xlpm.current_column, _xlpm.revenue_columns ) ), IF( _xlpm.revenue = "","", _xlpm.revenue ) )} -> 210000 | K9: 229091 | L9: 248182 | M9: 267272 | N9: 284364 | O9: 305454 | P9: 324546 | Q9: 343636 | R9: 360728 | S9: 381818 | T9: 400909 | U9: 420000
E10: Product A | G10: USD | J10: 125000 | K10: 136364 | L10: 147727 | M10: 159091 | N10: 170455 | O10: 181818 | P10: 193182 | Q10: 204545 | R10: 213909 | S10: 227273 | T10: 238636 | U10: 250000
E11: Product B | G11: USD | J11: 50000 | K11: 54545 | L11: 59091 | M11: 63636 | N11: 66182 | O11: 72727 | P11: 77273 | Q11: 81818 | R11: 86364 | S11: 90909 | T11: 95455 | U11: 100000
E12: Product C | G12: USD | J12: 35000 | K12: 38182 | L12: 41364 | M12: 44545 | N12: 47727 | O12: 50909 | P12: 54091 | Q12: 57273 | R12: 60455 | S12: 63636 | T12: 66818 | U12: 70000
E14: Retailer 2 | G14: USD | J14: 105000 | K14: 114545 | L14: 124091 | M14: 133636 | N14: 143182 | O14: 152727 | P14: 160273 | Q14: 171818 | R14: 181364 | S14: 190909 | T14: 198455 | U14: 210000
E15: Product A | G15: USD | J15: 50000 | K15: 54545 | L15: 59091 | M15: 63636 | N15: 68182 | O15: 72727 | P15: 77273 | Q15: 81818 | R15: 86364 | S15: 90909 | T15: 93455 | U15: 100000
E16: Product B | G16: USD | J16: 40000 | K16: 43636 | L16: 47273 | M16: 50909 | N16: 54545 | O16: 58182 | P16: 59818 | Q16: 65455 | R16: 69091 | S16: 72727 | T16: 76364 | U16: 80000
E17: Product C | G17: USD | J17: 15000 | K17: 16364 | L17: 17727 | M17: 19091 | N17: 20455 | O17: 21818 | P17: 23182 | Q17: 24545 | R17: 25909 | S17: 27273 | T17: 28636 | U17: 30000
E19: Retailer 3 | G19: USD | J19: 195000 | K19: 210727 | L19: 228455 | M19: 248182 | N19: 265910 | O19: 283637 | P19: 301363 | Q19: 319090 | R19: 336818 | S19: 354545 | T19: 372273 | U19: 390000
E20: Product A | G20: USD | J20: 50000 | K20: 52545 | L20: 59091 | M20: 63636 | N20: 68182 | O20: 72727 | P20: 77273 | Q20: 81818 | R20: 86364 | S20: 90909 | T20: 95455 | U20: 100000
E21: Product B | G21: USD | J21: 100000 | K21: 109091 | L21: 116182 | M21: 127273 | N21: 136364 | O21: 145455 | P21: 154545 | Q21: 163636 | R21: 172727 | S21: 181818 | T21: 190909 | U21: 200000
E22: Product C | G22: USD | J22: 45000 | K22: 49091 | L22: 53182 | M22: 57273 | N22: 61364 | O22: 65455 | P22: 69545 | Q22: 73636 | R22: 77727 | S22: 81818 | T22: 85909 | U22: 90000
B24: Product sales (before discount)
E26: {=IF( INDEX( CaseData!$A$7:$A$20,,1 ) = "", "", INDEX( CaseData!$A$7:$A$20,,1 ) )} -> Retailer 1 | G26: USD | J26: {=_xlfn.LET( _xlpm.revenue,_xlfn.ANCHORARRAY( J9), _xlpm.current_row,_xlfn.ANCHORARRAY( E26), _xlpm.retailer_list, CaseData!$A$26:$A$28, _xlpm.retailer_fill, _xlfn.SCAN( "", _xlpm.current_row, _xlfn.LAMBDA(_xlpm.carry,_xlpm.lbl, IF( COUNTIF( _xlpm.retailer_list, _xlpm.lbl ) > 0, _xlpm.lbl, _xlpm.carry ) ) ), _xlpm.discount_rate, CaseData!$D$26:$D$28, _xlpm.discount, INDEX( _xlpm.discount_rate, _xlfn.XMATCH( _xlpm.retailer_fill, _xlpm.retailer_list ) ), IF( _xlpm.current_row = "", "", _xlpm.revenue / ( 1 - _xlpm.discount ) ) )} -> 225806.45 | K26: 246334.41 | L26: 266862.37 | M26: 287389.25 | N26: 305767.74 | O26: 328445.16 | P26: 348974.19 | Q26: 369501.08 | R26: 387879.57 | S26: 410556.99 | T26: 431084.95 | U26: 451612.9
E27: Product A | G27: USD | J27: 134408.6 | K27: 146627.96 | L27: 158846.24 | M27: 171065.59 | N27: 183284.95 | O27: 195503.23 | P27: 207722.58 | Q27: 219940.86 | R27: 230009.68 | S27: 244379.57 | T27: 256597.85 | U27: 268817.2
E28: Product B | G28: USD | J28: 53763.441 | K28: 58650.538 | L28: 63538.71 | M28: 68425.806 | N28: 71163.441 | O28: 78201.075 | P28: 83089.247 | Q28: 87976.344 | R28: 92864.516 | S28: 97751.613 | T28: 102639.78 | U28: 107526.88
E29: Product C | G29: USD | J29: 37634.409 | K29: 41055.914 | L29: 44477.419 | M29: 47897.849 | N29: 51319.355 | O29: 54740.86 | P29: 58162.366 | Q29: 61583.871 | R29: 65005.376 | S29: 68425.806 | T29: 71847.312 | U29: 75268.817
E31: Retailer 2 | G31: USD | J31: 110526.32 | K31: 120573.68 | L31: 130622.11 | M31: 140669.47 | N31: 150717.89 | O31: 160765.26 | P31: 168708.42 | Q31: 180861.05 | R31: 190909.47 | S31: 200956.84 | T31: 208900 | U31: 221052.63
E32: Product A | G32: USD | J32: 52631.579 | K32: 57415.789 | L32: 62201.053 | M32: 66985.263 | N32: 71770.526 | O32: 76554.737 | P32: 81340 | Q32: 86124.211 | R32: 90909.474 | S32: 95693.684 | T32: 98373.684 | U32: 105263.16
E33: Product B | G33: USD | J33: 42105.263 | K33: 45932.632 | L33: 49761.053 | M33: 53588.421 | N33: 57415.789 | O33: 61244.211 | P33: 62966.316 | Q33: 68900 | R33: 72727.368 | S33: 76554.737 | T33: 80383.158 | U33: 84210.526
E34: Product C | G34: USD | J34: 15789.474 | K34: 17225.263 | L34: 18660 | M34: 20095.789 | N34: 21531.579 | O34: 22966.316 | P34: 24402.105 | Q34: 25836.842 | R34: 27272.632 | S34: 28708.421 | T34: 30143.158 | U34: 31578.947
E36: Retailer 3 | G36: USD | J36: 211956.52 | K36: 229051.09 | L36: 248320.65 | M36: 269763.04 | N36: 289032.61 | O36: 308301.09 | P36: 327568.48 | Q36: 346836.96 | R36: 366106.52 | S36: 385375 | T36: 404644.57 | U36: 423913.04
E37: Product A | G37: USD | J37: 54347.826 | K37: 57114.13 | L37: 64229.348 | M37: 69169.565 | N37: 74110.87 | O37: 79051.087 | P37: 83992.391 | Q37: 88932.609 | R37: 93873.913 | S37: 98814.13 | T37: 103755.43 | U37: 108695.65
E38: Product B | G38: USD | J38: 108695.65 | K38: 118577.17 | L38: 126284.78 | M38: 138340.22 | N38: 148221.74 | O38: 158103.26 | P38: 167983.7 | Q38: 177865.22 | R38: 187746.74 | S38: 197628.26 | T38: 207509.78 | U38: 217391.3
E39: Product C | G39: USD | J39: 48913.043 | K39: 53359.783 | L39: 57806.522 | M39: 62253.261 | N39: 66700 | O39: 71146.739 | P39: 75592.391 | Q39: 80039.13 | R39: 84485.87 | S39: 88932.609 | T39: 93379.348 | U39: 97826.087
A41: Volume sold
E43: {=IF( INDEX( CaseData!$A$7:$A$20,,1 ) = "", "", INDEX( CaseData!$A$7:$A$20,,1 ) )} -> Retailer 1 | G43: kg | J43: {=_xlfn.LET( _xlpm.revenue,_xlfn.ANCHORARRAY( J26), _xlpm.current_row,_xlfn.ANCHORARRAY( E26), _xlpm.retailer_list, CaseData!$A$26:$A$28, _xlpm.product_list, CaseData!$A$31:$A$33, _xlpm.list_price, CaseData!$D$31:$D$33, _xlpm.retailer_fill, _xlfn.SCAN( "", _xlpm.current_row, _xlfn.LAMBDA(_xlpm.carry,_xlpm.lbl, IF( COUNTIF( _xlpm.retailer_list, _xlpm.lbl ) > 0, _xlpm.lbl, _xlpm.carry ) ) ), _xlpm.is_retailer_row, COUNTIF( _xlpm.retailer_list, _xlpm.current_row ) > 0, _xlpm.kg, IFERROR( _xlpm.revenue / _xlfn.XLOOKUP( _xlpm.current_row, _xlpm.product_list, _xlpm.list_price ), 0 ), _xlfn.MAKEARRAY( ROWS( _xlpm.current_row ), COLUMNS( _xlpm.kg ), _xlfn.LAMBDA(_xlpm.r,_xlpm.c, IF( INDEX( _xlpm.current_row, _xlpm.r, 1 ) = "", "", IF( INDEX( _xlpm.is_retailer_row, _xlpm.r, 1 ), SUMPRODUCT( ( _xlpm.retailer_fill = INDEX( _xlpm.retailer_fill, _xlpm.r, 1 ) ) * INDEX( _xlpm.kg, 0, _xlpm.c ) ), INDEX( _xlpm.kg, _xlpm.r, _xlpm.c ) ) ) ) ) )} -> 86072.269 | K43: 93897.089 | L43: 101721.78 | M43: 109546.31 | N43: 116688.76 | O43: 125195.82 | P43: 133020.98 | Q43: 140845.34 | R43: 147731.4 | S43: 156495.02 | T43: 164319.72 | U43: 172144.54
E44: Product A | G44: kg | J44: 58693.713 | K44: 64029.676 | L44: 69365.169 | M44: 74701.132 | N44: 80037.094 | O44: 85372.588 | P44: 90708.551 | Q44: 96044.044 | R44: 100440.91 | S44: 106715.97 | T44: 112051.46 | U44: 117387.43
E45: Product B | G45: kg | J45: 17067.759 | K45: 18619.218 | L45: 20171.019 | M45: 21722.478 | N45: 22591.569 | O45: 24825.738 | P45: 26377.539 | Q45: 27928.998 | R45: 29480.799 | S45: 31032.258 | T45: 32584.059 | U45: 34135.518
E46: Product C | G46: kg | J46: 10310.797 | K46: 11248.196 | L46: 12185.594 | M46: 13122.698 | N46: 14060.097 | O46: 14997.496 | P46: 15934.895 | Q46: 16872.293 | R46: 17809.692 | S46: 18746.796 | T46: 19684.195 | U46: 20621.594
E48: Retailer 2 | G48: kg | J48: 40675.856 | K48: 44373.435 | L48: 48071.52 | M48: 51769.1 | N48: 55467.139 | O48: 59164.764 | P48: 62194.466 | Q48: 66560.428 | R48: 70258.467 | S48: 73956.047 | T48: 76734.803 | U48: 81351.711
E49: Product A | G49: kg | J49: 22983.222 | K49: 25072.397 | L49: 27162.032 | M49: 29251.207 | N49: 31340.841 | O49: 33430.016 | P49: 35519.651 | Q49: 37608.826 | R49: 39698.46 | S49: 41787.635 | T49: 42957.941 | U49: 45966.444
E50: Product B | G50: kg | J50: 13366.75 | K50: 14581.788 | L50: 15797.16 | M50: 17012.197 | N50: 18227.235 | O50: 19442.607 | P50: 19989.307 | Q50: 21873.016 | R50: 23088.053 | S50: 24303.091 | T50: 25518.463 | U50: 26733.5
E51: Product C | G51: kg | J51: 4325.8832 | K51: 4719.2502 | L51: 5112.3288 | M51: 5505.6957 | N51: 5899.0627 | O51: 6292.1413 | P51: 6685.5083 | Q51: 7078.5869 | R51: 7471.9539 | S51: 7865.3208 | T51: 8258.3994 | U51: 8651.7664
E53: Retailer 3 | G53: kg | J53: 71640.065 | K53: 77203.334 | L53: 83975.561 | M53: 91178.268 | N53: 97691.318 | O53: 104203.89 | P53: 110716.3 | Q53: 117228.88 | R53: 123741.93 | S53: 130254.5 | T53: 136767.55 | U53: 143280.13
...

Sheet Accounts Receivables
A1: {=company} -> Sweet Dreams Co.
A2: {=topic} -> CFM Topic: Working Capital
A3: ACCOUNTS RECEIVABLE SCHEDULE | F3: Constant | G3: Unit | H3: Total | J3: {=EOMONTH( start_date, _xlfn.SEQUENCE( 1, periods, 0, 1 ) )} -> 44592 | K3: 44620 | L3: 44651 | M3: 44681 | N3: 44712 | O3: 44742 | P3: 44773 | Q3: 44804 | R3: 44834 | S3: 44865 | T3: 44895 | U3: 44926
A5: Accounts receivables
B7: Payment Terms
C9: Retailer 1
E11: Payment terms | F11: =INDEX( CaseData!$C$63:$C$65, MATCH( 'Accounts Receivables'!$C9, CaseData!$A$63:$A$65, 0 ) ) / days_per_month -> 3 | G11: months
F13: Months | G13: Sales | J13: {=_xlfn.SEQUENCE( 1, periods, 1, 1 )} -> 1 | K13: 2 | L13: 3 | M13: 4 | N13: 5 | O13: 6 | P13: 7 | Q13: 8 | R13: 9 | S13: 10 | T13: 11 | U13: 12
F14: =F15-1 -> -2 | G14: {=_xlfn.SEQUENCE( $F$11, 1, $G17, 0 )} -> 210000 | J14: {=IF(_xlfn.ANCHORARRAY( J13) - $F$14:$F$28 < 0, 0, IF(_xlfn.ANCHORARRAY( J13) - $F$14:$F$28 < INT($F$11), 1, IF(_xlfn.ANCHORARRAY( J13) - $F$14:$F$28 < $F$11, MOD($F$11, 1), 0 ) ) )} -> 0 | K14: 0 | L14: 0 | M14: 0 | N14: 0 | O14: 0 | P14: 0 | Q14: 0 | R14: 0 | S14: 0 | T14: 0 | U14: 0
F15: =F16-1 -> -1 | G15: 210000 | J15: 1 | K15: 0 | L15: 0 | M15: 0 | N15: 0 | O15: 0 | P15: 0 | Q15: 0 | R15: 0 | S15: 0 | T15: 0 | U15: 0
F16: =F17-1 -> 0 | G16: 210000 | J16: 1 | K16: 1 | L16: 0 | M16: 0 | N16: 0 | O16: 0 | P16: 0 | Q16: 0 | R16: 0 | S16: 0 | T16: 0 | U16: 0
F17: {=_xlfn.SEQUENCE( periods, 1, 1, 1 )} -> 1 | G17: {=_xlfn.LET( _xlpm.revenue_table, CaseData!$C$7:$N$20, _xlpm.revenue_rows, CaseData!$A$7:$A$20, _xlpm.revenue_columns, CaseData!$C$3:$N$3, _xlpm.current_retailer, $C9, _xlpm.current_month,_xlfn.ANCHORARRAY( 'Accounts Receivables'!$J$3), _xlpm.revenue, INDEX( _xlpm.revenue_table, MATCH( _xlpm.current_retailer, _xlpm.revenue_rows, 0 ), MATCH( _xlpm.current_month, _xlpm.revenue_columns, 0 ) ), TRANSPOSE( _xlpm.revenue ) )} -> 210000 | J17: 1 | K17: 1 | L17: 1 | M17: 0 | N17: 0 | O17: 0 | P17: 0 | Q17: 0 | R17: 0 | S17: 0 | T17: 0 | U17: 0
F18: 2 | G18: 229091 | J18: 0 | K18: 1 | L18: 1 | M18: 1 | N18: 0 | O18: 0 | P18: 0 | Q18: 0 | R18: 0 | S18: 0 | T18: 0 | U18: 0
F19: 3 | G19: 248182 | J19: 0 | K19: 0 | L19: 1 | M19: 1 | N19: 1 | O19: 0 | P19: 0 | Q19: 0 | R19: 0 | S19: 0 | T19: 0 | U19: 0
F20: 4 | G20: 267272 | J20: 0 | K20: 0 | L20: 0 | M20: 1 | N20: 1 | O20: 1 | P20: 0 | Q20: 0 | R20: 0 | S20: 0 | T20: 0 | U20: 0
F21: 5 | G21: 284364 | J21: 0 | K21: 0 | L21: 0 | M21: 0 | N21: 1 | O21: 1 | P21: 1 | Q21: 0 | R21: 0 | S21: 0 | T21: 0 | U21: 0
F22: 6 | G22: 305454 | J22: 0 | K22: 0 | L22: 0 | M22: 0 | N22: 0 | O22: 1 | P22: 1 | Q22: 1 | R22: 0 | S22: 0 | T22: 0 | U22: 0
F23: 7 | G23: 324546 | J23: 0 | K23: 0 | L23: 0 | M23: 0 | N23: 0 | O23: 0 | P23: 1 | Q23: 1 | R23: 1 | S23: 0 | T23: 0 | U23: 0
F24: 8 | G24: 343636 | J24: 0 | K24: 0 | L24: 0 | M24: 0 | N24: 0 | O24: 0 | P24: 0 | Q24: 1 | R24: 1 | S24: 1 | T24: 0 | U24: 0
F25: 9 | G25: 360728 | J25: 0 | K25: 0 | L25: 0 | M25: 0 | N25: 0 | O25: 0 | P25: 0 | Q25: 0 | R25: 1 | S25: 1 | T25: 1 | U25: 0
F26: 10 | G26: 381818 | J26: 0 | K26: 0 | L26: 0 | M26: 0 | N26: 0 | O26: 0 | P26: 0 | Q26: 0 | R26: 0 | S26: 1 | T26: 1 | U26: 1
F27: 11 | G27: 400909 | J27: 0 | K27: 0 | L27: 0 | M27: 0 | N27: 0 | O27: 0 | P27: 0 | Q27: 0 | R27: 0 | S27: 0 | T27: 1 | U27: 1
F28: 12 | G28: 420000 | J28: 0 | K28: 0 | L28: 0 | M28: 0 | N28: 0 | O28: 0 | P28: 0 | Q28: 0 | R28: 0 | S28: 0 | T28: 0 | U28: 1
E29: Accounts receivable closing balance | J29: {=_xlfn.BYCOL(_xlfn.ANCHORARRAY( $J14), _xlfn.LAMBDA(_xlpm.month_col, SUMPRODUCT( $G14:$G28, _xlpm.month_col ) ) )} -> 630000 | K29: 649091 | L29: 687273 | M29: 744545 | N29: 799818 | O29: 857090 | P29: 914364 | Q29: 973636 | R29: 1028910 | S29: 1086182 | T29: 1143455 | U29: 1202727
E32: Accounts receivable opening balance | G32: USD | J32: {=_xlfn.DROP( _xlfn.HSTACK( SUM( $G$14:$G$16 ) / 3 * $F11,_xlfn.ANCHORARRAY( J35) ),, -1 )} -> 630000 | K32: 630000 | L32: 649091 | M32: 687273 | N32: 744545 | O32: 799818 | P32: 857090 | Q32: 914364 | R32: 973636 | S32: 1028910 | T32: 1086182 | U32: 1143455
D33: plus | E33: Sales | G33: USD | J33: {=TRANSPOSE(_xlfn.ANCHORARRAY( G17))} -> 210000 | K33: 229091 | L33: 248182 | M33: 267272 | N33: 284364 | O33: 305454 | P33: 324546 | Q33: 343636 | R33: 360728 | S33: 381818 | T33: 400909 | U33: 420000
D34: minus | E34: Payments received from retailers | G34: USD | J34: {=_xlfn.LET( _xlpm.ar_opening,_xlfn.ANCHORARRAY( J32), _xlpm.revenue,_xlfn.ANCHORARRAY( J33), _xlpm.ar_closing,_xlfn.ANCHORARRAY( J35), ( _xlpm.ar_opening + _xlpm.revenue - _xlpm.ar_closing ) * - 1)} -> -210000 | K34: -210000 | L34: -210000 | M34: -210000 | N34: -229091 | O34: -248182 | P34: -267272 | Q34: -284364 | R34: -305454 | S34: -324546 | T34: -343636 | U34: -360728
E35: Retailer 1: Accounts receivable closing balance | G35: USD | J35: {=J29:U29} -> 630000 | K35: 649091 | L35: 687273 | M35: 744545 | N35: 799818 | O35: 857090 | P35: 914364 | Q35: 973636 | R35: 1028910 | S35: 1086182 | T35: 1143455 | U35: 1202727
C38: Retailer 2
E40: Payment terms | F40: =INDEX( CaseData!$C$63:$C$65, MATCH( 'Accounts Receivables'!$C38, CaseData!$A$63:$A$65, 0 ) ) / days_per_month -> 1.5 | G40: months
F42: Months | G42: Sales | J42: {=_xlfn.SEQUENCE( 1, periods, 1, 1 )} -> 1 | K42: 2 | L42: 3 | M42: 4 | N42: 5 | O42: 6 | P42: 7 | Q42: 8 | R42: 9 | S42: 10 | T42: 11 | U42: 12
F43: =F44-1 -> -2 | G43: {=_xlfn.SEQUENCE( $F$11, 1, $G46, 0 )} -> 105000 | J43: {=IF(_xlfn.ANCHORARRAY( J42) - $F$14:$F$28 < 0, 0, IF(_xlfn.ANCHORARRAY( J42) - $F$14:$F$28 < INT($F$40), 1, IF(_xlfn.ANCHORARRAY( J42) - $F$14:$F$28 < $F$40, MOD($F$40, 1), 0 ) ) )} -> 0 | K43: 0 | L43: 0 | M43: 0 | N43: 0 | O43: 0 | P43: 0 | Q43: 0 | R43: 0 | S43: 0 | T43: 0 | U43: 0
F44: =F45-1 -> -1 | G44: 105000 | J44: 0 | K44: 0 | L44: 0 | M44: 0 | N44: 0 | O44: 0 | P44: 0 | Q44: 0 | R44: 0 | S44: 0 | T44: 0 | U44: 0
F45: =F46-1 -> 0 | G45: 105000 | J45: 0.5 | K45: 0 | L45: 0 | M45: 0 | N45: 0 | O45: 0 | P45: 0 | Q45: 0 | R45: 0 | S45: 0 | T45: 0 | U45: 0
F46: {=_xlfn.SEQUENCE( periods, 1, 1, 1 )} -> 1 | G46: {=_xlfn.LET( _xlpm.revenue_table, CaseData!$C$7:$N$20, _xlpm.revenue_rows, CaseData!$A$7:$A$20, _xlpm.revenue_columns, CaseData!$C$3:$N$3, _xlpm.current_retailer, $C38, _xlpm.current_month,_xlfn.ANCHORARRAY( 'Accounts Receivables'!$J$3), _xlpm.revenue, INDEX( _xlpm.revenue_table, MATCH( _xlpm.current_retailer, _xlpm.revenue_rows, 0 ), MATCH( _xlpm.current_month, _xlpm.revenue_columns, 0 ) ), TRANSPOSE( _xlpm.revenue ) )} -> 105000 | J46: 1 | K46: 0.5 | L46: 0 | M46: 0 | N46: 0 | O46: 0 | P46: 0 | Q46: 0 | R46: 0 | S46: 0 | T46: 0 | U46: 0
F47: 2 | G47: 114545 | J47: 0 | K47: 1 | L47: 0.5 | M47: 0 | N47: 0 | O47: 0 | P47: 0 | Q47: 0 | R47: 0 | S47: 0 | T47: 0 | U47: 0
F48: 3 | G48: 124091 | J48: 0 | K48: 0 | L48: 1 | M48: 0.5 | N48: 0 | O48: 0 | P48: 0 | Q48: 0 | R48: 0 | S48: 0 | T48: 0 | U48: 0
F49: 4 | G49: 133636 | J49: 0 | K49: 0 | L49: 0 | M49: 1 | N49: 0.5 | O49: 0 | P49: 0 | Q49: 0 | R49: 0 | S49: 0 | T49: 0 | U49: 0
F50: 5 | G50: 143182 | J50: 0 | K50: 0 | L50: 0 | M50: 0 | N50: 1 | O50: 0.5 | P50: 0 | Q50: 0 | R50: 0 | S50: 0 | T50: 0 | U50: 0
F51: 6 | G51: 152727 | J51: 0 | K51: 0 | L51: 0 | M51: 0 | N51: 0 | O51: 1 | P51: 0.5 | Q51: 0 | R51: 0 | S51: 0 | T51: 0 | U51: 0
...

Sheet CaseData
A1: 1. Sales Assumptions
A3: Retailer/Product - Base Case Scenario | C3: 44592 | D3: =EOMONTH(C3,1) -> 44620 | E3: =EOMONTH(D3,1) -> 44651 | F3: =EOMONTH(E3,1) -> 44681 | G3: =EOMONTH(F3,1) -> 44712 | H3: =EOMONTH(G3,1) -> 44742 | I3: =EOMONTH(H3,1) -> 44773 | J3: =EOMONTH(I3,1) -> 44804 | K3: =EOMONTH(J3,1) -> 44834 | ... N3: =EOMONTH(M3,1) -> 44926 | O3: Total
A5: Total Sales | B5: [$] | C5: =SUBTOTAL(9,C7:C21) -> 510000 | D5: =SUBTOTAL(9,D7:D21) -> 554363 | E5: =SUBTOTAL(9,E7:E21) -> 600728 | F5: =SUBTOTAL(9,F7:F21) -> 649090 | G5: =SUBTOTAL(9,G7:G21) -> 693456 | H5: =SUBTOTAL(9,H7:H21) -> 741818 | I5: =SUBTOTAL(9,I7:I21) -> 786182 | J5: =SUBTOTAL(9,J7:J21) -> 834544 | ... O5: =SUBTOTAL(9,O7:O21) -> 9168000
A7: Retailer 1 | B7: [$] | C7: =SUBTOTAL(9,C8:C10) -> 210000 | D7: =SUBTOTAL(9,D8:D10) -> 229091 | E7: =SUBTOTAL(9,E8:E10) -> 248182 | F7: =SUBTOTAL(9,F8:F10) -> 267272 | G7: =SUBTOTAL(9,G8:G10) -> 284364 | H7: =SUBTOTAL(9,H8:H10) -> 305454 | I7: =SUBTOTAL(9,I8:I10) -> 324546 | J7: =SUBTOTAL(9,J8:J10) -> 343636 | ... O7: =SUBTOTAL(9,O8:O10) -> 3776000
A8: Product A | B8: [$] | C8: 125000 | D8: 136364 | E8: 147727 | F8: 159091 | G8: 170455 | H8: 181818 | I8: 193182 | J8: 204545 | K8: 213909 | L8: 227273 | M8: 238636 | N8: 250000 | O8: =SUM(C8:N8) -> 2248000
A9: Product B | B9: [$] | C9: 50000 | D9: 54545 | E9: 59091 | F9: 63636 | G9: 66182 | H9: 72727 | I9: 77273 | J9: 81818 | K9: 86364 | L9: 90909 | M9: 95455 | N9: 100000 | O9: =SUM(C9:N9) -> 898000
A10: Product C | B10: [$] | C10: 35000 | D10: 38182 | E10: 41364 | F10: 44545 | G10: 47727 | H10: 50909 | I10: 54091 | J10: 57273 | K10: 60455 | L10: 63636 | M10: 66818 | N10: 70000 | O10: =SUM(C10:N10) -> 630000
A12: Retailer 2 | B12: [$] | C12: =SUBTOTAL(9,C13:C15) -> 105000 | D12: =SUBTOTAL(9,D13:D15) -> 114545 | E12: =SUBTOTAL(9,E13:E15) -> 124091 | F12: =SUBTOTAL(9,F13:F15) -> 133636 | G12: =SUBTOTAL(9,G13:G15) -> 143182 | H12: =SUBTOTAL(9,H13:H15) -> 152727 | I12: =SUBTOTAL(9,I13:I15) -> 160273 | J12: =SUBTOTAL(9,J13:J15) -> 171818 | ... O12: =SUBTOTAL(9,O13:O15) -> 1886000
A13: Product A | B13: [$] | C13: 50000 | D13: 54545 | E13: 59091 | F13: 63636 | G13: 68182 | H13: 72727 | I13: 77273 | J13: 81818 | K13: 86364 | L13: 90909 | M13: 93455 | N13: 100000 | O13: =SUM(C13:N13) -> 898000
A14: Product B | B14: [$] | C14: 40000 | D14: 43636 | E14: 47273 | F14: 50909 | G14: 54545 | H14: 58182 | I14: 59818 | J14: 65455 | K14: 69091 | L14: 72727 | M14: 76364 | N14: 80000 | O14: =SUM(C14:N14) -> 718000
A15: Product C | B15: [$] | C15: 15000 | D15: 16364 | E15: 17727 | F15: 19091 | G15: 20455 | H15: 21818 | I15: 23182 | J15: 24545 | K15: 25909 | L15: 27273 | M15: 28636 | N15: 30000 | O15: =SUM(C15:N15) -> 270000
A17: Retailer 3 | B17: [$] | C17: =SUBTOTAL(9,C18:C20) -> 195000 | D17: =SUBTOTAL(9,D18:D20) -> 210727 | E17: =SUBTOTAL(9,E18:E20) -> 228455 | F17: =SUBTOTAL(9,F18:F20) -> 248182 | G17: =SUBTOTAL(9,G18:G20) -> 265910 | H17: =SUBTOTAL(9,H18:H20) -> 283637 | I17: =SUBTOTAL(9,I18:I20) -> 301363 | J17: =SUBTOTAL(9,J18:J20) -> 319090 | ... O17: =SUBTOTAL(9,O18:O20) -> 3506000
A18: Product A | B18: [$] | C18: 50000 | D18: 52545 | E18: 59091 | F18: 63636 | G18: 68182 | H18: 72727 | I18: 77273 | J18: 81818 | K18: 86364 | L18: 90909 | M18: 95455 | N18: 100000 | O18: =SUM(C18:N18) -> 898000
A19: Product B | B19: [$] | C19: 100000 | D19: 109091 | E19: 116182 | F19: 127273 | G19: 136364 | H19: 145455 | I19: 154545 | J19: 163636 | K19: 172727 | L19: 181818 | M19: 190909 | N19: 200000 | O19: =SUM(C19:N19) -> 1798000
A20: Product C | B20: [$] | C20: 45000 | D20: 49091 | E20: 53182 | F20: 57273 | G20: 61364 | H20: 65455 | I20: 69545 | J20: 73636 | K20: 77727 | L20: 81818 | M20: 85909 | N20: 90000 | O20: =SUM(C20:N20) -> 810000
A22: 2. Working Capital Assumptions
A24: Retailer Deferred Payment Days and Price Discounts | I24: Supplier Deferred Payment Days and Opening A/P
C25: Days | D25: Discount | L25: Days | M25: Opening A/P
A26: Retailer 1 | B26: [days] | C26: 90 | D26: 0.07 | I26: Supplier I | K26: [days] | L26: 15 | M26: 75000
A27: Retailer 2 | B27: [days] | C27: 45 | D27: 0.05 | I27: Supplier II | K27: [days] | L27: 30 | M27: 0
A28: Retailer 3 | B28: [days] | C28: 60 | D28: 0.08 | I28: Supplier III | K28: [days] | L28: 30 | M28: 0
I29: Supplier IV | K29: [days] | L29: 30 | M29: 100000
A30: Product Target Inventory (% of next month's unit sales) and List Prices | C30: % | D30: List Price ($/kg) | I30: Supplier V | K30: [days] | L30: 15 | M30: 75000
A31: Product A | B31: [%] | C31: 0.25 | D31: 2.29
A32: Product B | B32: [%] | C32: 0.1 | D32: 3.15
A33: Product C | B33: [%] | C33: 0.3 | D33: 3.65 | I33: Days per Month | K33: [days] | L33: 30
A35: 3. Other Assumptions
A37: Product Ingredients
C38: Ingredients (per 1 kg of Product) | L38: Other Direct Costs
A39: Product | C39: Flour | D39: Sugar | E39: Butter | F39: Milk | G39: Eggs | H39: Chocolate | I39: Raisins | J39: Bananas | L39: (as % of Ingredient Cost)
A40: Product A | B40: [kg] | C40: 0.3 | D40: 0.25 | E40: 0.15 | F40: 0.15 | G40: 0.15 | H40: 0.1 | I40: 0 | J40: 0 | L40: 0.5
A41: Product B | B41: [kg] | C41: 0.321 | D41: 0.24 | E41: 0.155 | F41: 0.161 | G41: 0.138 | H41: 0 | I41: 0.1 | J41: 0 | L41: 0.6
A42: Product C | B42: [kg] | C42: 0.306 | D42: 0.233 | E42: 0.149 | F42: 0.137 | G42: 0.155 | H42: 0.05 | I42: 0 | J42: 0.2 | L42: 0.75
A45: Supplier Prices | C45: Flour | D45: Sugar | E45: Butter | F45: Milk | G45: Eggs | H45: Chocolate | I45: Raisins | J45: Bananas
A46: Supplier I | B46: [$/kg] | C46: 0.2781 | D46: 0.2077 | E46: 2.01 | F46: 0.67 | G46: 1.675 | H46: 1.608 | I46: 2.345 | J46: 1.005
A47: Supplier II | B47: [$/kg] | C47: 0.2725 | D47: 0.1932 | E47: 1.9497 | F47: 0.7236 | G47: 1.6248 | H47: 1.4633 | I47: 2.2512 | J47: 1.0251
A48: Supplier III | B48: [$/kg] | C48: 0.2531 | D48: 0.2015 | E48: 1.9698 | F48: 0.6231 | G48: 1.742 | H48: 1.5115 | I48: 2.4154 | J48: 0.9749
A49: Supplier IV | B49: [$/kg] | C49: 0.2864 | D49: 0.2181 | E49: 2.0502 | F49: 0.6968 | G49: 1.7923 | H49: 1.5758 | I49: 2.1809 | J49: 0.9749
A50: Supplier V | B50: [$/kg] | C50: 0.2586 | D50: 0.2015 | E50: 1.8693 | F50: 0.7169 | G50: 1.7085 | H50: 1.6562 | I50: 2.2981 | J50: 0.9548
A53: Supporting assumptions
...

Sheet Tmp
F3: Constant | G3: Unit | H3: Total | J3: {=EOMONTH( start_date, _xlfn.SEQUENCE( 1, periods, 0, 1 ) )} -> 44592 | K3: 44620 | L3: 44651 | M3: 44681 | N3: 44712 | O3: 44742 | P3: 44773 | Q3: 44804 | R3: 44834 | S3: 44865 | T3: 44895 | U3: 44926
A45: End of schedule
