Workbook
Name company: CaseData!$E$55
Name quarters: CaseData!$E$58
Name start_date: CaseData!$E$6
Name topic: "CFM Topic: " & CaseData!$E$56
Name years: CaseData!$E$57

Sheet Calculations
A1: =company -> Waterworks Corp
A2: {=topic} -> CFM Topic: Working capital | J2: {=_xlfn.ANCHORARRAY(J7)} -> 44927 | K2: 45017 | L2: 45108 | M2: 45200 | N2: 45292 | O2: 45383 | P2: 45474 | Q2: 45566 | R2: 45658 | S2: 45748 | T2: 45839 | U2: 45931 | V2: 46023 | W2: 46113 | X2: 46204 | Y2: 46296 | Z2: 46388 | AA2: 46478 | AB2: 46569 | AC2: 46661 | AD2: 46753 | AE2: 46844 | AF2: 46935 | AG2: 47027 | AH2: 47119 | AI2: 47209 | AJ2: 47300 | AK2: 47392
A3: CALCULATIONS SCHEDULE | F3: Constant | G3: Unit | H3: Total | J3: {=_xlfn.ANCHORARRAY(J8)} -> 45016 | K3: 45107 | L3: 45199 | M3: 45291 | N3: 45382 | O3: 45473 | P3: 45565 | Q3: 45657 | R3: 45747 | S3: 45838 | T3: 45930 | U3: 46022 | V3: 46112 | W3: 46203 | X3: 46295 | Y3: 46387 | Z3: 46477 | AA3: 46568 | AB3: 46660 | AC3: 46752 | AD3: 46843 | AE3: 46934 | AF3: 47026 | AG3: 47118 | AH3: 47208 | AI3: 47299 | AJ3: 47391 | AK3: 47483
A5: Model timeline
E7: Model period beginning | G7: date | J7: {=EDATE( start_date, _xlfn.SEQUENCE( 1, years * quarters, 0, 3 ) )} -> 44927 | K7: 45017 | L7: 45108 | M7: 45200 | N7: 45292 | O7: 45383 | P7: 45474 | Q7: 45566 | R7: 45658 | S7: 45748 | T7: 45839 | U7: 45931 | V7: 46023 | W7: 46113 | X7: 46204 | Y7: 46296 | Z7: 46388 | AA7: 46478 | AB7: 46569 | AC7: 46661 | AD7: 46753 | AE7: 46844 | AF7: 46935 | AG7: 47027 | AH7: 47119 | AI7: 47209 | AJ7: 47300 | AK7: 47392
E8: Model period ending | G8: date | J8: {=EOMONTH( start_date, _xlfn.SEQUENCE( 1, years * quarters, 2, 3 ) )} -> 45016 | K8: 45107 | L8: 45199 | M8: 45291 | N8: 45382 | O8: 45473 | P8: 45565 | Q8: 45657 | R8: 45747 | S8: 45838 | T8: 45930 | U8: 46022 | V8: 46112 | W8: 46203 | X8: 46295 | Y8: 46387 | Z8: 46477 | AA8: 46568 | AB8: 46660 | AC8: 46752 | AD8: 46843 | AE8: 46934 | AF8: 47026 | AG8: 47118 | AH8: 47208 | AI8: 47299 | AJ8: 47391 | AK8: 47483
E10: Quarter | G10: label | J10: {=MONTH(_xlfn.ANCHORARRAY( J8) ) / 3} -> 1 | K10: 2 | L10: 3 | M10: 4 | N10: 1 | O10: 2 | P10: 3 | Q10: 4 | R10: 1 | S10: 2 | T10: 3 | U10: 4 | V10: 1 | W10: 2 | X10: 3 | Y10: 4 | Z10: 1 | AA10: 2 | AB10: 3 | AC10: 4 | AD10: 1 | AE10: 2 | AF10: 3 | AG10: 4 | AH10: 1 | AI10: 2 | AJ10: 3 | AK10: 4
E11: Year | G11: label | J11: {=YEAR(_xlfn.ANCHORARRAY( J8) )} -> 2023 | K11: 2023 | L11: 2023 | M11: 2023 | N11: 2024 | O11: 2024 | P11: 2024 | Q11: 2024 | R11: 2025 | S11: 2025 | T11: 2025 | U11: 2025 | V11: 2026 | W11: 2026 | X11: 2026 | Y11: 2026 | Z11: 2027 | AA11: 2027 | AB11: 2027 | AC11: 2027 | AD11: 2028 | AE11: 2028 | AF11: 2028 | AG11: 2028 | AH11: 2029 | AI11: 2029 | AJ11: 2029 | AK11: 2029
A13: Revenue
B15: Volume
E17: Demand | G17: units | J17: {=_xlfn.LET( _xlpm.first_year_demand, CaseData!$E$11:$H$11, _xlpm.first_year_quarters, CaseData!$E$10:$H$10, _xlpm.current_quarter, "Q" &_xlfn.ANCHORARRAY( J$10), _xlpm.demand, INDEX( _xlpm.first_year_demand, MATCH( _xlpm.current_quarter, _xlpm.first_year_quarters, 0 ) ), _xlpm.growth_rate, CaseData!$E$13, _xlpm.current_year,_xlfn.ANCHORARRAY( $J$11), _xlpm.period, _xlpm.current_year - YEAR( start_date ), _xlpm.growth_factor, IF( _xlpm.period = 0, 1, ( 1 + _xlpm.growth_rate ) ^ _xlpm.period ), _xlpm.demand * _xlpm.growth_factor )} -> 225000 | K17: 375000 | L17: 300000 | M17: 600000 | N17: 236250 | O17: 393750 | P17: 315000 | Q17: 630000 | R17: 248062.5 | S17: 413437.5 | T17: 330750 | U17: 661500 | V17: 260465.63 | W17: 434109.38 | X17: 347287.5 | Y17: 694575 | Z17: 273488.91 | AA17: 455814.84 | AB17: 364651.88 | AC17: 729303.75 | AD17: 287163.35 | AE17: 478605.59 | AF17: 382884.47 | AG17: 765768.94 | AH17: 301521.52 | AI17: 502535.87 | AJ17: 402028.69 | AK17: 804057.38
E18: Rollover-in demand | G18: units | J18: =CaseData!$E$15*I27 -> 0 | K18: =CaseData!$E$15*J27 -> 0 | L18: =CaseData!$E$15*K27 -> 0 | M18: =CaseData!$E$15*L27 -> 0 | N18: =CaseData!$E$15*M27 -> 0 | O18: =CaseData!$E$15*N27 -> 0 | P18: =CaseData!$E$15*O27 -> 0 | Q18: =CaseData!$E$15*P27 -> 0 | ... AK18: =CaseData!$E$15*AJ27 -> 338955.3
E19: Total demand | G19: units | J19: =J17+J18 -> 225000 | K19: =K17+K18 -> 375000 | L19: =L17+L18 -> 300000 | M19: =M17+M18 -> 600000 | N19: =N17+N18 -> 236250 | O19: =O17+O18 -> 393750 | P19: =P17+P18 -> 315000 | Q19: =Q17+Q18 -> 630000 | ... AK19: =AK17+AK18 -> 1143012.7
E21: Inventory opening balance | G21: units | J21: =I25 -> 0 | K21: =J25 -> 185000 | L21: =K25 -> 220000 | M21: =L25 -> 330000 | N21: =M25 -> 140000 | O21: =N25 -> 313750 | P21: =O25 -> 330000 | Q21: =P25 -> 425000 | ... AK21: =AJ25 -> 0
E22: Production | G22: units | J22: {=_xlfn.SEQUENCE(1, years*quarters, CaseData!$E$8, 0)} -> 410000 | K22: 410000 | L22: 410000 | M22: 410000 | N22: 410000 | O22: 410000 | P22: 410000 | Q22: 410000 | R22: 410000 | S22: 410000 | T22: 410000 | U22: 410000 | V22: 410000 | W22: 410000 | X22: 410000 | Y22: 410000 | Z22: 410000 | AA22: 410000 | AB22: 410000 | AC22: 410000 | AD22: 410000 | AE22: 410000 | AF22: 410000 | AG22: 410000 | AH22: 410000 | AI22: 410000 | AJ22: 410000 | AK22: 410000
E23: Inventory available for sale | G23: units | J23: =J21+J22 -> 410000 | K23: =K21+K22 -> 595000 | L23: =L21+L22 -> 630000 | M23: =M21+M22 -> 740000 | N23: =N21+N22 -> 550000 | O23: =O21+O22 -> 723750 | P23: =P21+P22 -> 740000 | Q23: =Q21+Q22 -> 835000 | ... AK23: =AK21+AK22 -> 410000
E24: Units sold | G24: units | J24: =MIN(J23,J19) -> 225000 | K24: =MIN(K23,K19) -> 375000 | L24: =MIN(L23,L19) -> 300000 | M24: =MIN(M23,M19) -> 600000 | N24: =MIN(N23,N19) -> 236250 | O24: =MIN(O23,O19) -> 393750 | P24: =MIN(P23,P19) -> 315000 | Q24: =MIN(Q23,Q19) -> 630000 | ... AK24: =MIN(AK23,AK19) -> 410000
E25: Inventory closing balance | G25: units | J25: =J23-J24 -> 185000 | K25: =K23-K24 -> 220000 | L25: =L23-L24 -> 330000 | M25: =M23-M24 -> 140000 | N25: =N23-N24 -> 313750 | O25: =O23-O24 -> 330000 | P25: =P23-P24 -> 425000 | Q25: =Q23-Q24 -> 205000 | ... AK25: =AK23-AK24 -> 0
E27: Demand not met in the current quarter | G27: units | J27: =J19-J24 -> 0 | K27: =K19-K24 -> 0 | L27: =L19-L24 -> 0 | M27: =M19-M24 -> 0 | N27: =N19-N24 -> 0 | O27: =O19-O24 -> 0 | P27: =P19-P24 -> 0 | Q27: =Q19-Q24 -> 0 | ... AK27: =AK19-AK24 -> 733012.68
E28: Sale of units permanently lost to other suppliers | G28: units | J28: 0 | K28: =(1-CaseData!$E$15)*J27 -> 0 | L28: =(1-CaseData!$E$15)*K27 -> 0 | M28: =(1-CaseData!$E$15)*L27 -> 0 | N28: =(1-CaseData!$E$15)*M27 -> 0 | O28: =(1-CaseData!$E$15)*N27 -> 0 | P28: =(1-CaseData!$E$15)*O27 -> 0 | Q28: =(1-CaseData!$E$15)*P27 -> 0 | R28: =(1-CaseData!$E$15)*Q27 -> 0 | ... AK28: =(1-CaseData!$E$15)*AJ27 -> 0
E30: =E$24 -> Units sold | G30: units | J30: =J$24 -> 225000 | K30: =K$24 -> 375000 | L30: =L$24 -> 300000 | M30: =M$24 -> 600000 | N30: =N$24 -> 236250 | O30: =O$24 -> 393750 | P30: =P$24 -> 315000 | Q30: =Q$24 -> 630000 | ... AK30: =AK$24 -> 410000
B32: Production cost
E34: Hourly salary rate | G34: USD / hr | J34: {=_xlfn.LET( _xlpm.hourly_salary_rate, CaseData!$E$18, _xlpm.year_on_year_pct, CaseData!$F$18, _xlpm.period,_xlfn.ANCHORARRAY( J11) - YEAR( start_date ), ROUND( IF( _xlpm.period = 0, _xlpm.hourly_salary_rate, _xlpm.hourly_salary_rate * ( 1 + _xlpm.year_on_year_pct ) ^ _xlpm.period ), 2 ) )} -> 27.75 | K34: 27.75 | L34: 27.75 | M34: 27.75 | N34: 29.69 | O34: 29.69 | P34: 29.69 | Q34: 29.69 | R34: 31.77 | S34: 31.77 | T34: 31.77 | U34: 31.77 | V34: 33.99 | W34: 33.99 | X34: 33.99 | Y34: 33.99 | Z34: 36.37 | AA34: 36.37 | AB34: 36.37 | AC34: 36.37 | AD34: 38.92 | AE34: 38.92 | AF34: 38.92 | AG34: 38.92 | AH34: 41.65 | AI34: 41.65 | AJ34: 41.65 | AK34: 41.65
E35: Production time | G35: hr / unit | J35: {=_xlfn.LET( _xlpm.production_time, CaseData!$E$19, _xlpm.year_on_year_pct, CaseData!$F$19, _xlpm.period,_xlfn.ANCHORARRAY( J11) - YEAR( start_date ), IF( _xlpm.period = 0, _xlpm.production_time, _xlpm.production_time * ( 1 + _xlpm.year_on_year_pct ) ^ _xlpm.period ) )} -> 21.9 | K35: 21.9 | L35: 21.9 | M35: 21.9 | N35: 21.462 | O35: 21.462 | P35: 21.462 | Q35: 21.462 | R35: 21.03276 | S35: 21.03276 | T35: 21.03276 | U35: 21.03276 | V35: 20.612105 | W35: 20.612105 | X35: 20.612105 | Y35: 20.612105 | Z35: 20.199863 | AA35: 20.199863 | AB35: 20.199863 | AC35: 20.199863 | AD35: 19.795865 | AE35: 19.795865 | AF35: 19.795865 | AG35: 19.795865 | AH35: 19.399948 | AI35: 19.399948 | AJ35: 19.399948 | AK35: 19.399948
E36: Materials | G36: USD / unit | J36: {=_xlfn.LET( _xlpm.material_cost, CaseData!$E$20, _xlpm.year_on_year_pct, CaseData!$F$20, _xlpm.period,_xlfn.ANCHORARRAY( J11) - YEAR( start_date ), IF( _xlpm.period = 0, _xlpm.material_cost, _xlpm.material_cost * ( 1 + _xlpm.year_on_year_pct ) ^ _xlpm.period ) )} -> 480 | K36: 480 | L36: 480 | M36: 480 | N36: 499.2 | O36: 499.2 | P36: 499.2 | Q36: 499.2 | R36: 519.168 | S36: 519.168 | T36: 519.168 | U36: 519.168 | V36: 539.93472 | W36: 539.93472 | X36: 539.93472 | Y36: 539.93472 | Z36: 561.53211 | AA36: 561.53211 | AB36: 561.53211 | AC36: 561.53211 | AD36: 583.99339 | AE36: 583.99339 | AF36: 583.99339 | AG36: 583.99339 | AH36: 607.35313 | AI36: 607.35313 | AJ36: 607.35313 | AK36: 607.35313
E38: Salaries | G38: USD m | J38: {=_xlfn.LET( _xlpm.hourly_salary_rate,_xlfn.ANCHORARRAY( J34), _xlpm.unit_production_time,_xlfn.ANCHORARRAY( J35), _xlpm.production,_xlfn.ANCHORARRAY( J22), _xlpm.hourly_salary_rate * _xlpm.unit_production_time * _xlpm.production / 1000 )} -> 249167.25 | K38: 249167.25 | L38: 249167.25 | M38: 249167.25 | N38: 261254.78 | O38: 261254.78 | P38: 261254.78 | Q38: 261254.78 | R38: 273966.42 | S38: 273966.42 | T38: 273966.42 | U38: 273966.42 | V38: 287248.23 | W38: 287248.23 | X38: 287248.23 | Y38: 287248.23 | Z38: 301214.29 | AA38: 301214.29 | AB38: 301214.29 | AC38: 301214.29 | AD38: 315886.58 | AE38: 315886.58 | AF38: 315886.58 | AG38: 315886.58 | AH38: 331283.21 | AI38: 331283.21 | AJ38: 331283.21 | AK38: 331283.21
E39: Materials | G39: USD m | J39: {=_xlfn.LET( _xlpm.production,_xlfn.ANCHORARRAY( J22), _xlpm.material_costs,_xlfn.ANCHORARRAY( J36), _xlpm.production * _xlpm.material_costs / 1000 )} -> 196800 | K39: 196800 | L39: 196800 | M39: 196800 | N39: 204672 | O39: 204672 | P39: 204672 | Q39: 204672 | R39: 212858.88 | S39: 212858.88 | T39: 212858.88 | U39: 212858.88 | V39: 221373.24 | W39: 221373.24 | X39: 221373.24 | Y39: 221373.24 | Z39: 230228.16 | AA39: 230228.16 | AB39: 230228.16 | AC39: 230228.16 | AD39: 239437.29 | AE39: 239437.29 | AF39: 239437.29 | AG39: 239437.29 | AH39: 249014.78 | AI39: 249014.78 | AJ39: 249014.78 | AK39: 249014.78
E40: Production costs | G40: USD m | J40: {=_xlfn.BYCOL(_xlfn.ANCHORARRAY( J38):_xlfn.ANCHORARRAY(J39), _xleta.SUM )} -> 445967.25 | K40: 445967.25 | L40: 445967.25 | M40: 445967.25 | N40: 465926.78 | O40: 465926.78 | P40: 465926.78 | Q40: 465926.78 | R40: 486825.3 | S40: 486825.3 | T40: 486825.3 | U40: 486825.3 | V40: 508621.47 | W40: 508621.47 | X40: 508621.47 | Y40: 508621.47 | Z40: 531442.46 | AA40: 531442.46 | AB40: 531442.46 | AC40: 531442.46 | AD40: 555323.88 | AE40: 555323.88 | AF40: 555323.88 | AG40: 555323.88 | AH40: 580298 | AI40: 580298 | AJ40: 580298 | AK40: 580298
E42: Average cost per unit | G42: USD | J42: {=_xlfn.LET( _xlpm.production,_xlfn.ANCHORARRAY( J22), _xlpm.costs,_xlfn.ANCHORARRAY( J40), _xlpm.costs / _xlpm.production * 1000 )} -> 1087.725 | K42: 1087.725 | L42: 1087.725 | M42: 1087.725 | N42: 1136.4068 | O42: 1136.4068 | P42: 1136.4068 | Q42: 1136.4068 | R42: 1187.3788 | S42: 1187.3788 | T42: 1187.3788 | U42: 1187.3788 | V42: 1240.5402 | W42: 1240.5402 | X42: 1240.5402 | Y42: 1240.5402 | Z42: 1296.2011 | AA42: 1296.2011 | AB42: 1296.2011 | AC42: 1296.2011 | AD42: 1354.4485 | AE42: 1354.4485 | AF42: 1354.4485 | AG42: 1354.4485 | AH42: 1415.361 | AI42: 1415.361 | AJ42: 1415.361 | AK42: 1415.361
E43: Check | G43: USD | J43: {=_xlfn.LET( _xlpm.hourly_salary_rate,_xlfn.ANCHORARRAY( J34), _xlpm.production_time,_xlfn.ANCHORARRAY( J35), _xlpm.material_cost,_xlfn.ANCHORARRAY( J36), _xlpm.cost_per_unit,_xlfn.ANCHORARRAY( J42), ROUNDDOWN( _xlpm.cost_per_unit - ( (_xlpm.hourly_salary_rate * _xlpm.production_time ) + _xlpm.material_cost ), 2 ) )} -> 0 | K43: 0 | L43: 0 | M43: 0 | N43: 0 | O43: 0 | P43: 0 | Q43: 0 | R43: 0 | S43: 0 | T43: 0 | U43: 0 | V43: 0 | W43: 0 | X43: 0 | Y43: 0 | Z43: 0 | AA43: 0 | AB43: 0 | AC43: 0 | AD43: 0 | AE43: 0 | AF43: 0 | AG43: 0 | AH43: 0 | AI43: 0 | AJ43: 0 | AK43: 0
B45: Revenue
E47: Sell price | G47: USD | J47: {=_xlfn.LET( _xlpm.cost_per_unit,_xlfn.ANCHORARRAY( J42), _xlpm.mark_up, CaseData!$E$23, _xlpm.year_on_year_pct, CaseData!$E$24, _xlpm.period,_xlfn.ANCHORARRAY( $J$11) - YEAR( start_date ), _xlpm.growth_rate, 1 + ( _xlpm.mark_up + ( _xlpm.year_on_year_pct * _xlpm.period ) ), ROUND( _xlpm.cost_per_unit * _xlpm.growth_rate, 2 ) )} -> 1414.04 | K47: 1414.04 | L47: 1414.04 | M47: 1414.04 | N47: 1471.65 | O47: 1471.65 | P47: 1471.65 | Q47: 1471.65 | R47: 1531.72 | S47: 1531.72 | T47: 1531.72 | U47: 1531.72 | V47: 1594.09 | W47: 1594.09 | X47: 1594.09 | Y47: 1594.09 | Z47: 1659.14 | AA47: 1659.14 | AB47: 1659.14 | AC47: 1659.14 | AD47: 1726.92 | AE47: 1726.92 | AF47: 1726.92 | AG47: 1726.92 | AH47: 1797.51 | AI47: 1797.51 | AJ47: 1797.51 | AK47: 1797.51
E48: =E$24 -> Units sold | G48: units | J48: =J$24 -> 225000 | K48: =K$24 -> 375000 | L48: =L$24 -> 300000 | M48: =M$24 -> 600000 | N48: =N$24 -> 236250 | O48: =O$24 -> 393750 | P48: =P$24 -> 315000 | Q48: =Q$24 -> 630000 | ... AK48: =AK$24 -> 410000
E49: Revenue | G49: USD m | J49: {=_xlfn.ANCHORARRAY( J47) * $J$48:$AK$48 / 1000} -> 318159 | K49: 530265 | L49: 424212 | M49: 848424 | N49: 347677.31 | O49: 579462.19 | P49: 463569.75 | Q49: 927139.5 | R49: 379962.29 | S49: 633270.49 | T49: 506616.39 | U49: 1013232.8 | V49: 415205.65 | W49: 692009.41 | X49: 553607.53 | Y49: 1107215.1 | Z49: 453756.38 | AA49: 756260.64 | AB49: 605008.51 | AC49: 1063271.3 | AD49: 648648.81 | AE49: 767425.59 | AF49: 708037.2 | AG49: 708037.2 | AH49: 736979.1 | AI49: 736979.1 | AJ49: 736979.1 | AK49: 736979.1
B52: FIFO Cost of Goods Sold and Inventory
B54: FIFO units sold
E56: Production | G56: units | J56: {=_xlfn.ANCHORARRAY( J22)} -> 410000 | K56: 410000 | L56: 410000 | M56: 410000 | N56: 410000 | O56: 410000 | P56: 410000 | Q56: 410000 | R56: 410000 | S56: 410000 | T56: 410000 | U56: 410000 | V56: 410000 | W56: 410000 | X56: 410000 | Y56: 410000 | Z56: 410000 | AA56: 410000 | AB56: 410000 | AC56: 410000 | AD56: 410000 | AE56: 410000 | AF56: 410000 | AG56: 410000 | AH56: 410000 | AI56: 410000 | AJ56: 410000 | AK56: 410000
E57: Units sold | G57: units | J57: =J$30 -> 225000 | K57: =K$30 -> 375000 | L57: =L$30 -> 300000 | M57: =M$30 -> 600000 | N57: =N$30 -> 236250 | O57: =O$30 -> 393750 | P57: =P$30 -> 315000 | Q57: =Q$30 -> 630000 | ... AK57: =AK$30 -> 410000
E58: Inventory beginning balance | G58: units | J58: =J$21 -> 0 | K58: =K$21 -> 185000 | L58: =L$21 -> 220000 | M58: =M$21 -> 330000 | N58: =N$21 -> 140000 | O58: =O$21 -> 313750 | P58: =P$21 -> 330000 | Q58: =Q$21 -> 425000 | ... AK58: =AK$21 -> 0
E60: Units sold from inventory | G60: units | J60: {=_xlfn.LET( _xlpm.units_sold, $J$57:$AK$57, _xlpm.inventory_beginning_balance, $J$58:$AK$58, _xlpm.period,_xlfn.ANCHORARRAY( J11) - YEAR( start_date ), IF( _xlpm.inventory_beginning_balance < _xlpm.units_sold, _xlpm.inventory_beginning_balance, _xlpm.units_sold ) )} -> 0 | K60: 185000 | L60: 220000 | M60: 330000 | N60: 140000 | O60: 313750 | P60: 315000 | Q60: 425000 | R60: 205000 | S60: 366937.5 | T60: 330750 | U60: 442750 | V60: 191250 | W60: 340784.38 | X60: 316675 | Y60: 379387.5 | Z60: 94812.5 | AA60: 231323.59 | AB60: 185508.75 | AC60: 230856.87 | AD60: 0 | AE60: 34389.773 | AF60: 0 | AG60: 0 | AH60: 0 | AI60: 0 | AJ60: 0 | AK60: 0
...

Sheet CaseData
B2: Waterworks Corp forecast model - Assumptions
B4: Assumption | D4: Units | E4: Value
B6: Model start date | D6: [date] | E6: 44927
B8: Production | D8: [units / quarter] | E8: 410000
E10: Q1 | F10: Q2 | G10: Q3 | H10: Q4
B11: Year 1 demand | D11: [units] | E11: 225000 | F11: 375000 | G11: 300000 | H11: 600000
B13: New demand growth YoY | D13: [%] | E13: 0.05
B15: Unmet Demand Rollover | D15: [%] | E15: 1
B17: Production costs | E17: Year 1 | F17: % ∆ YoY | G17: Note
C18: Salaries | D18: [$ / hr] | E18: 27.75 | F18: 0.07 | G18: Rounded to nearest $0.01
C19: Production time | D19: [hrs / unit] | E19: 21.9 | F19: -0.02 | G19: Not rounded
C20: Materials | D20: [$ / unit] | E20: 480 | F20: 0.04 | G20: Not rounded
B22: Mark-up
C23: Year 1 mark-up | D23: [%] | E23: 0.3
C24: YoY change | D24: [% pts] | E24: -0.005
C25: Note: final sale price rounded to nearest $0.01
B27: Overhead | D27: [$ / quarter] | E27: 37500000
B29: Tax rate | D29: [%] | E29: 0.35
B31: Inventory opening balance | D31: [units] | E31: 0
D32: [$ / quarter] | E32: 0
B34: Example of Weighted Average Cost Accounting Methodology
E36: Year 1 | F36: Year 2
C37: Beginning Inventory | D37: [units] | E37: 0 | F37: 500
C38: Production | D38: [units] | E38: 1000 | F38: 500
C39: Units Available for Sale | D39: [units] | E39: 1000 | F39: =SUM(F37:F38) -> 1000 | G39: A
C41: Units Sold | D41: [units] | E41: 500 | F41: 500
C42: Ending Inventory | D42: [units] | E42: 500 | F42: 500
C44: Production Cost | D44: [$/unit] | E44: 150 | F44: 100
C46: Beginning Inventory | D46: [$] | E46: 0 | F46: 75000
C47: Production Costs | D47: [$] | E47: 150000 | F47: =F38*F44 -> 50000
C48: Cost of Available Units | D48: [$] | E48: 150000 | F48: 125000 | G48: B
C50: WAC | D50: [$/unit] | E50: 150 | F50: 125 | G50: B/A
C52: COGS Period | E52: 75000 | F52: 62500
C53: Ending Inventory | E53: 75000 | F53: 62500
C55: Company name | E55: Waterworks Corp
C56: CFM Topic | E56: Working capital
C57: Model years | E57: 7 | F57: years
C58: Number of periods | E58: 4 | F58: quarters

Sheet Tmp
A1: =company -> Waterworks Corp
A2: {=topic} -> CFM Topic: Working capital
A3: TMP SCHEDULE | F3: Constant | G3: Unit | H3: Total
