Workbook
Name company: CaseData!$B$1
Name periods: CaseData!$C$59
Name start_date: CaseData!$C$58
Name topic: "CFM Topic: " & CaseData!$C$57

Sheet Calculations
A1: {=company} -> JAK Holdings Inc.
A2: {=topic} -> CFM Topic: Income Tax
A3: CALCULATION SCHEDULE | F3: Constant | G3: Unit | H3: Total | J3: {=YEAR( EOMONTH( start_date, _xlfn.SEQUENCE( 1, periods, 0, 12 ) ) )} -> 2019 | K3: 2020 | L3: 2021 | M3: 2022 | N3: 2023
E5: Country | F5: U.S.
A7: Tax schedule
E9: Projected Accounting Pre-tax Income | G9: USD m | J9: {=_xlfn.LET( _xlpm.values, CaseData!$F$9:$I$13, _xlpm.years, VALUE( RIGHT( CaseData!$B$9:$B$13, 4 ) ), _xlpm.countries, CaseData!$F$3:$I$3, _xlpm.current_year,_xlfn.ANCHORARRAY( $J$3), _xlpm.current_country, $F$5, _xlpm.fx_rate, INDEX( CaseData!$F$7:$I$7, 1, MATCH( _xlpm.current_country, _xlpm.countries, 0 ) ), _xlpm.projected, INDEX( _xlpm.values, MATCH( _xlpm.current_year, _xlpm.years, 0 ), MATCH( _xlpm.current_country, _xlpm.countries, 0 ) ), _xlpm.projected / _xlpm.fx_rate )} -> 17840 | K9: 17062 | L9: 19307 | M9: 17314 | N9: 14576
D10: plus | E10: Non deductible expenses | G10: {=$G$9:$G$9} -> USD m | J10: {=_xlfn.LET( _xlpm.values, CaseData!$F$35:$I$39, _xlpm.years, VALUE( RIGHT( CaseData!$B$9:$B$13, 4 ) ), _xlpm.countries, CaseData!$F$3:$I$3, _xlpm.current_year,_xlfn.ANCHORARRAY( $J$3), _xlpm.current_country, $F$5, _xlpm.fx_rate, INDEX( CaseData!$F$7:$I$7, 1, MATCH( _xlpm.current_country, _xlpm.countries, 0 ) ), _xlpm.projected, INDEX( _xlpm.values, MATCH( _xlpm.current_year, _xlpm.years, 0 ), MATCH( _xlpm.current_country, _xlpm.countries, 0 ) ), _xlpm.projected / _xlpm.fx_rate )} -> 6742 | K10: 0 | L10: 0 | M10: 0 | N10: 0
E11: Taxable Income for Accounting Purposes (A) | G11: {=$G$9:$G$9} -> USD m | J11: {=_xlfn.ANCHORARRAY( J9) +_xlfn.ANCHORARRAY( J10)} -> 24582 | K11: 17062 | L11: 19307 | M11: 17314 | N11: 14576
D13: plus | E13: Accounting depreciation | G13: {=$G$9:$G$9} -> USD m | J13: {=_xlfn.LET( _xlpm.values, CaseData!$F$23:$I$27, _xlpm.years, VALUE( RIGHT( CaseData!$B$9:$B$13, 4 ) ), _xlpm.countries, CaseData!$F$3:$I$3, _xlpm.current_year,_xlfn.ANCHORARRAY( $J$3), _xlpm.current_country, $F$5, _xlpm.fx_rate, INDEX( CaseData!$F$7:$I$7, 1, MATCH( _xlpm.current_country, _xlpm.countries, 0 ) ), _xlpm.projected, INDEX( _xlpm.values, MATCH( _xlpm.current_year, _xlpm.years, 0 ), MATCH( _xlpm.current_country, _xlpm.countries, 0 ) ), _xlpm.projected / _xlpm.fx_rate )} -> 5432 | K13: 5595 | L13: 5875 | M13: 6169 | N13: 6416
D14: minus | E14: Taxable depreciation | G14: USD m | J14: {=$J$31:$N$31} -> 8825.742 | K14: 8402.8997 | L14: 8319.2721 | M14: 8124.1606 | N14: 7596.7168
D15: minus | E15: Incremental deduction for tax purposes | G15: USD m | J15: {=_xlfn.LET( _xlpm.values, CaseData!$F$42:$I$46, _xlpm.years, VALUE( RIGHT( CaseData!$B$9:$B$13, 4 ) ), _xlpm.countries, CaseData!$F$3:$I$3, _xlpm.current_year,_xlfn.ANCHORARRAY( $J$3), _xlpm.current_country, $F$5, _xlpm.fx_rate, INDEX( CaseData!$F$7:$I$7, 1, MATCH( _xlpm.current_country, _xlpm.countries, 0 ) ), _xlpm.projected, INDEX( _xlpm.values, MATCH( _xlpm.current_year, _xlpm.years, 0 ), MATCH( _xlpm.current_country, _xlpm.countries, 0 ) ), _xlpm.projected / _xlpm.fx_rate )} -> 5709 | K15: 5972 | L15: 2317 | M15: 3809 | N15: 3790
E16: Taxable Income for Tax Purposes before NOL | G16: USD m | J16: =J11 + J13 - J14 - J15 -> 15479.258 | K16: =K11 + K13 - K14 - K15 -> 8282.1003 | L16: =L11 + L13 - L14 - L15 -> 14545.728 | M16: =M11 + M13 - M14 - M15 -> 11549.839 | N16: =N11 + N13 - N14 - N15 -> 9605.2832
E18: Utilization of Tax Loss Carry Forwards | G18: USD m | J18: =J$36 -> 15479.258 | K18: =K$36 -> 8282.1003 | L18: =L$36 -> 14545.728 | M18: =M$36 -> 5106.9138 | N18: =N$36 -> 4400
E19: Taxable Income for Tax Purposes after NOL | G19: USD m | J19: =J16 - J18 -> 0 | K19: =K16 - K18 -> 0 | L19: =L16 - L18 -> 0 | M19: =M16 - M18 -> 6442.9256 | N19: =N16 - N18 -> 5205.2832
E22: Current corporate tax rate | F22: {=_xlfn.LET( _xlpm.countries, CaseData!$F$3:$I$3, _xlpm.current_country, $F$5, _xlfn.XLOOKUP( _xlpm.current_country, _xlpm.countries, CaseData!$F$5:$I$5, 0, 0 ) )} -> 0.256
E23: Current tax | G23: USD m | J23: =J19 * $F$22 -> 0 | K23: =K19 * $F$22 -> 0 | L23: =L19 * $F$22 -> 0 | M23: =M19 * $F$22 -> 1649.389 | N23: =N19 * $F$22 -> 1332.5525
E24: Deferred tax | G24: USD m | J24: =J25 - J23 -> 6292.992 | K24: =K25 - K23 -> 4367.872 | L24: =L25 - L23 -> 4942.592 | M24: =M25 - M23 -> 2782.995 | N24: =N25 - N23 -> 2398.9035
E25: Tax | G25: USD m | J25: =J$11 * $F$22 -> 6292.992 | K25: =K$11 * $F$22 -> 4367.872 | L25: =L$11 * $F$22 -> 4942.592 | M25: =M$11 * $F$22 -> 4432.384 | N25: =N$11 * $F$22 -> 3731.456
A27: Taxable depreciation
E29: Tax Basis in Depreciable Assets opening balance | G29: {=$G$9:$G$9} -> USD m | J29: {=_xlfn.LET( _xlpm.countries, CaseData!$F$3:$I$3, _xlpm.current_country, $F$5, _xlpm.opening_balance, _xlfn.XLOOKUP( _xlpm.current_country, _xlpm.countries, CaseData!$F$29:$I$29, 0, 0 ), _xlpm.fx_rate, _xlfn.XLOOKUP( _xlpm.current_country, _xlpm.countries, CaseData!$F$7:$I$7, 0, 0 ), _xlpm.opening_balance / _xlpm.fx_rate )} -> 65510 | K29: =J32 -> 62928.258 | L29: =K32 -> 59913.358 | M29: =L32 -> 59317.086 | N29: =M32 -> 57925.926
D30: plus | E30: Addition to fixed assets | G30: USD m | J30: {=_xlfn.LET( _xlpm.values, CaseData!$F$16:$I$20, _xlpm.years, VALUE( RIGHT( CaseData!$B$9:$B$13, 4 ) ), _xlpm.countries, CaseData!$F$3:$I$3, _xlpm.current_year,_xlfn.ANCHORARRAY( $J$3), _xlpm.current_country, $F$5, _xlpm.fx_rate, INDEX( CaseData!$F$7:$I$7, 1, MATCH( _xlpm.current_country, _xlpm.countries, 0 ) ), _xlpm.projected, INDEX( _xlpm.values, MATCH( _xlpm.current_year, _xlpm.years, 0 ), MATCH( _xlpm.current_country, _xlpm.countries, 0 ) ), _xlpm.projected / _xlpm.fx_rate )} -> 6244 | K30: 5388 | L30: 7723 | M30: 6733 | N30: 3836
D31: minus | E31: Taxable Depreciation at blended rate | F31: {=_xlfn.LET( _xlpm.countries, CaseData!$F$3:$I$3, _xlpm.current_country, $F$5, _xlfn.XLOOKUP( _xlpm.current_country, _xlpm.countries, CaseData!$F$31:$I$31, 0, 0 ) )} -> 0.123 | G31: USD m | J31: =SUM( J29:J30 ) * $F$31 -> 8825.742 | K31: =SUM( K29:K30 ) * $F$31 -> 8402.8997 | L31: =SUM( L29:L30 ) * $F$31 -> 8319.2721 | M31: =SUM( M29:M30 ) * $F$31 -> 8124.1606 | N31: =SUM( N29:N30 ) * $F$31 -> 7596.7168
E32: Tax Basis in Depreciable Assets closing balance | G32: USD m | J32: =J29 + J30 - J31 -> 62928.258 | K32: =K29 + K30 - K31 -> 59913.358 | L32: =L29 + L30 - L31 -> 59317.086 | M32: =M29 + M30 - M31 -> 57925.926 | N32: =N29 + N30 - N31 -> 54165.209
A34: Tax Loss Carry Forward
E36: Utilization of Tax Loss Carry Forwards | G36: USD m | J36: =MIN( J16, SUM( I47:I52 ) ) -> 15479.258 | K36: =MIN( K16, SUM( J47:J52 ) ) -> 8282.1003 | L36: =MIN( L16, SUM( K47:K52 ) ) -> 14545.728 | M36: =MIN( M16, SUM( L47:L52 ) ) -> 5106.9138 | N36: =MIN( N16, SUM( M47:M52 ) ) -> 4400
E37: 43830 | G37: USD m | J37: =MIN( J36, I47) -> 3425 | K37: =MIN( K36, J47) -> 0 | L37: =MIN( L36, K47) -> 0 | M37: =MIN( M36, L47) -> 0 | N37: =MIN( N36, M47) -> 0
E38: 44196 | G38: USD m | J38: =MIN( I48, J36 - SUM( J$37:J37 ) ) -> 12054.258 | K38: =MIN( J48, K$36 - SUM( K$37:K37 ) ) -> 2066.742 | L38: =MIN( K48, L$36 - SUM( L$37:L37 ) ) -> 0 | M38: =MIN( L48, M$36 - SUM( M$37:M37 ) ) -> 0 | N38: =MIN( M48, N$36 - SUM( N$37:N37 ) ) -> 0
E39: 44561 | G39: USD m | J39: =MIN( I49, J$36 - SUM( J$37:J38 ) ) -> 0 | K39: =MIN( J49, K$36 - SUM( K$37:K38 ) ) -> 0 | L39: =MIN( K49, L$36 - SUM( L$37:L38 ) ) -> 0 | M39: =MIN( L49, M$36 - SUM( M$37:M38 ) ) -> 0 | N39: =MIN( M49, N$36 - SUM( N$37:N38 ) ) -> 0
E40: 44926 | G40: USD m | J40: =MIN( I50, J$36 - SUM( J$37:J39 ) ) -> 0 | K40: =MIN( J50, K$36 - SUM( K$37:K39 ) ) -> 6215.3583 | L40: =MIN( K50, L$36 - SUM( L$37:L39 ) ) -> 6105.6417 | M40: =MIN( L50, M$36 - SUM( M$37:M39 ) ) -> 0 | N40: =MIN( M50, N$36 - SUM( N$37:N39 ) ) -> 0
E41: 45291 | G41: USD m | J41: =MIN( I51, J$36 - SUM( J$37:J40 ) ) -> 0 | K41: =MIN( J51, K$36 - SUM( K$37:K40 ) ) -> 0 | L41: =MIN( K51, L$36 - SUM( L$37:L40 ) ) -> 8440.0862 | M41: =MIN( L51, M$36 - SUM( M$37:M40 ) ) -> 706.9138 | N41: =MIN( M51, N$36 - SUM( N$37:N40 ) ) -> 0
E42: Expiring thereafter | G42: USD m
J45: {=YEAR( EOMONTH( start_date, _xlfn.SEQUENCE( 1, periods, 0, 12 ) ) )} -> 2019 | K45: 2020 | L45: 2021 | M45: 2022 | N45: 2023
E46: Tax Loss Carry Forwards Ending Balances | G46: USD m
E47: 43830 | G47: USD m | I47: {=_xlfn.LET( _xlpm.values, CaseData!$F$49:$I$54, _xlpm.years, VALUE( RIGHT( CaseData!$B$9:$B$13, 4 ) ), _xlpm.countries, CaseData!$F$3:$I$3, _xlpm.current_year,_xlfn.ANCHORARRAY( $J$3), _xlpm.current_country, $F$5, _xlpm.fx_rate, INDEX( CaseData!$F$7:$I$7, 1, MATCH( _xlpm.current_country, _xlpm.countries, 0 ) ), _xlpm.projected, INDEX( _xlpm.values, MATCH( _xlpm.current_year, _xlpm.years, 0 ), MATCH( _xlpm.current_country, _xlpm.countries, 0 ) ), TRANSPOSE( _xlpm.projected / _xlpm.fx_rate ) )} -> 3425 | J47: =IF( J$45 < $E47, I47 - J37, 0 ) -> 0 | K47: =IF( K$45 < $E47, J47 - K37, 0 ) -> 0 | L47: =IF( L$45 < $E47, K47 - L37, 0 ) -> 0 | M47: =IF( M$45 < $E47, L47 - M37, 0 ) -> 0 | N47: =IF( N$45 < $E47, M47 - N37, 0 ) -> 0
E48: 44196 | G48: USD m | I48: 14121 | J48: =IF( J$45 < $E48, I48 - J38, 0 ) -> 2066.742 | K48: =IF( K$45 < $E48, J48 - K38, 0 ) -> 0 | L48: =IF( L$45 < $E48, K48 - L38, 0 ) -> 0 | M48: =IF( M$45 < $E48, L48 - M38, 0 ) -> 0 | N48: =IF( N$45 < $E48, M48 - N38, 0 ) -> 0
E49: 44561 | G49: USD m | I49: 0 | J49: =IF( J$45 < $E49, I49 - J39, 0 ) -> 0 | K49: =IF( K$45 < $E49, J49 - K39, 0 ) -> 0 | L49: =IF( L$45 < $E49, K49 - L39, 0 ) -> 0 | M49: =IF( M$45 < $E49, L49 - M39, 0 ) -> 0 | N49: =IF( N$45 < $E49, M49 - N39, 0 ) -> 0
E50: 44926 | G50: USD m | I50: 12321 | J50: =IF( J$45 < $E50, I50 - J40, 0 ) -> 12321 | K50: =IF( K$45 < $E50, J50 - K40, 0 ) -> 6105.6417 | L50: =IF( L$45 < $E50, K50 - L40, 0 ) -> 0 | M50: =IF( M$45 < $E50, L50 - M40, 0 ) -> 0 | N50: =IF( N$45 < $E50, M50 - N40, 0 ) -> 0
E51: 45291 | G51: USD m | I51: 9147 | J51: =IF( J$45 < $E51, I51 - J41, 0 ) -> 9147 | K51: =IF( K$45 < $E51, J51 - K41, 0 ) -> 9147 | L51: =IF( L$45 < $E51, K51 - L41, 0 ) -> 706.9138 | M51: =IF( M$45 < $E51, L51 - M41, 0 ) -> 0 | N51: =IF( N$45 < $E51, M51 - N41, 0 ) -> 0
E52: Expiring thereafter | G52: USD m m | I52: {=_xlfn.LET( _xlpm.countries, CaseData!$F$3:$I$3, _xlpm.current_country, $F$5, _xlpm.expiring_after, _xlfn.XLOOKUP( _xlpm.current_country, _xlpm.countries, CaseData!$F$54:$I$54, 0, 0 ), _xlpm.fx_rate, _xlfn.XLOOKUP( _xlpm.current_country, _xlpm.countries, CaseData!$F$7:$I$7, 0, 0 ), _xlfn.SEQUENCE( 1, periods + 1, _xlpm.expiring_after / _xlpm.fx_rate, 0 ) )} -> 4400 | J52: 4400 | K52: 4400 | L52: 4400 | M52: 4400 | N52: 4400
A54: Consolidation
...

Sheet CaseData
B1: JAK Holdings Inc.
B2: (in thousands, local currency as indicated)
F3: U.S. | G3: Canada | H3: Mexico | I3: Germany
F4: (USD) | G4: (CAD) | H4: (MXN) | I4: (EUR)
B5: Corporate Tax Rate | F5: 0.256 | G5: 0.265 | H5: 0.31 | I5: 0.326
B7: Exchange Rate (per USD) | F7: 1 | G7: 1.29 | H7: 19.89 | I7: 0.85
B8: Projected Accounting Pre-tax Income:
B9: Fiscal 2019 | F9: 17840 | G9: 27240 | H9: 265571 | I9: 29762
B10: Fiscal 2020 | F10: 17062 | G10: 26094 | H10: 208746 | I10: 30206
B11: Fiscal 2021 | F11: 19307 | G11: 27635 | H11: 270027 | I11: 32919
B12: Fiscal 2022 | F12: 17314 | G12: 24296 | H12: 267759 | I12: 31658
B13: Fiscal 2023 | F13: 14576 | G13: 29861 | H13: 240888 | I13: 29101
B15: Additions to Fixed Assets:
B16: Fiscal 2019 | F16: 6244 | G16: 9729 | H16: 79671 | I16: 16641
B17: Fiscal 2020 | F17: 5388 | G17: 16605 | H17: 80287 | I17: 8487
B18: Fiscal 2021 | F18: 7723 | G18: 9212 | H18: 67507 | I18: 9810
B19: Fiscal 2022 | F19: 6733 | G19: 9718 | H19: 80328 | I19: 19922
B20: Fiscal 2023 | F20: 3836 | G20: 16288 | H20: 80296 | I20: 16301
B22: Accounting Depreciation:
B23: Fiscal 2019 | F23: 5432 | G23: 7394 | H23: 66127 | I23: 14311
B24: Fiscal 2020 | F24: 5595 | G24: 7690 | H24: 69433 | I24: 14740
B25: Fiscal 2021 | F25: 5875 | G25: 7998 | H25: 72905 | I25: 15624
B26: Fiscal 2022 | F26: 6169 | G26: 8478 | H26: 76550 | I26: 16405
B27: Fiscal 2023 | F27: 6416 | G27: 8817 | H27: 80378 | I27: 16897
B29: Tax Basis in Depreciable Assets | F29: 65510 | G29: 85696 | H29: 645400 | I29: 163002
B31: Blended Tax Depreciation Rate | F31: 0.123 | G31: 0.142 | H31: 0.165 | I31: 0.156
B32: (% of beginning basis + additions to fixed assets)
B34: Expenses Not Deductible:
B35: Fiscal 2019 | F35: 6742 | G35: 0 | H35: 0 | I35: 10343
B36: Fiscal 2020 | F36: 0 | G36: 0 | H36: 88951 | I36: 0
B37: Fiscal 2021 | F37: 0 | G37: 0 | H37: 0 | I37: 12434
B38: Fiscal 2022 | F38: 0 | G38: 0 | H38: 0 | I38: 0
B39: Fiscal 2023 | F39: 0 | G39: 0 | H39: 0 | I39: 0
B41: Incremental Deductions for Tax Purposes:
B42: Fiscal 2019 | F42: 5709 | G42: 7355 | H42: 69048 | I42: 6036
B43: Fiscal 2020 | F43: 5972 | G43: 8350 | H43: 50099 | I43: 3551
B44: Fiscal 2021 | F44: 2317 | G44: 6080 | H44: 62106 | I44: 10537
B45: Fiscal 2022 | F45: 3809 | G45: 4373 | H45: 26776 | I45: 6970
B46: Fiscal 2023 | F46: 3790 | G46: 9854 | H46: 24089 | I46: 9642
B48: Tax Loss Carry Forwards:
...

Sheet Tmp
A1: {=company} -> JAK Holdings Inc.
A2: {=topic} -> CFM Topic: Income Tax
A3: TMP SCHEDULE | F3: Constant | G3: Unit | H3: Total | J3: {=YEAR( EOMONTH( start_date, _xlfn.SEQUENCE( 1, periods, 0, 12 ) ) )} -> 2019 | K3: 2020 | L3: 2021 | M3: 2022 | N3: 2023
A50: End of schedule

Sheet CaseSolution
B1: JAK Holdings Inc.
B2: (in thousands, local currency as indicated)
F3: U.S. | G3: Canada | H3: Mexico | I3: Germany
F4: (USD) | G4: (CAD) | H4: (MXN) | I4: (EUR)
B5: Corporate Tax Rate | F5: =CaseData!F5 -> 0.256 | G5: =CaseData!G5 -> 0.265 | H5: =CaseData!H5 -> 0.31 | I5: =CaseData!I5 -> 0.326
B7: Exchange Rate (per USD) | F7: =CaseData!F7 -> 1 | G7: =CaseData!G7 -> 1.29 | H7: =CaseData!H7 -> 19.89 | I7: =CaseData!I7 -> 0.85
B8: Projected Accounting Pre-tax Income:
B9: Fiscal 2019 | F9: =CaseData!F9 -> 17840 | G9: =CaseData!G9 -> 27240 | H9: =CaseData!H9 -> 265571 | I9: =CaseData!I9 -> 29762
B10: Fiscal 2020 | F10: =CaseData!F10 -> 17062 | G10: =CaseData!G10 -> 26094 | H10: =CaseData!H10 -> 208746 | I10: =CaseData!I10 -> 30206
B11: Fiscal 2021 | F11: =CaseData!F11 -> 19307 | G11: =CaseData!G11 -> 27635 | H11: =CaseData!H11 -> 270027 | I11: =CaseData!I11 -> 32919
B12: Fiscal 2022 | F12: =CaseData!F12 -> 17314 | G12: =CaseData!G12 -> 24296 | H12: =CaseData!H12 -> 267759 | I12: =CaseData!I12 -> 31658
B13: Fiscal 2023 | F13: =CaseData!F13 -> 14576 | G13: =CaseData!G13 -> 29861 | H13: =CaseData!H13 -> 240888 | I13: =CaseData!I13 -> 29101
B15: Additions to Fixed Assets:
B16: Fiscal 2019 | F16: =CaseData!F16 -> 6244 | G16: =CaseData!G16 -> 9729 | H16: =CaseData!H16 -> 79671 | I16: =CaseData!I16 -> 16641
B17: Fiscal 2020 | F17: =CaseData!F17 -> 5388 | G17: =CaseData!G17 -> 16605 | H17: =CaseData!H17 -> 80287 | I17: =CaseData!I17 -> 8487
B18: Fiscal 2021 | F18: =CaseData!F18 -> 7723 | G18: =CaseData!G18 -> 9212 | H18: =CaseData!H18 -> 67507 | I18: =CaseData!I18 -> 9810
B19: Fiscal 2022 | F19: =CaseData!F19 -> 6733 | G19: =CaseData!G19 -> 9718 | H19: =CaseData!H19 -> 80328 | I19: =CaseData!I19 -> 19922
B20: Fiscal 2023 | F20: =CaseData!F20 -> 3836 | G20: =CaseData!G20 -> 16288 | H20: =CaseData!H20 -> 80296 | I20: =CaseData!I20 -> 16301
B22: Accounting Depreciation:
B23: Fiscal 2019 | F23: =CaseData!F23 -> 5432 | G23: =CaseData!G23 -> 7394 | H23: =CaseData!H23 -> 66127 | I23: =CaseData!I23 -> 14311
B24: Fiscal 2020 | F24: =CaseData!F24 -> 5595 | G24: =CaseData!G24 -> 7690 | H24: =CaseData!H24 -> 69433 | I24: =CaseData!I24 -> 14740
B25: Fiscal 2021 | F25: =CaseData!F25 -> 5875 | G25: =CaseData!G25 -> 7998 | H25: =CaseData!H25 -> 72905 | I25: =CaseData!I25 -> 15624
B26: Fiscal 2022 | F26: =CaseData!F26 -> 6169 | G26: =CaseData!G26 -> 8478 | H26: =CaseData!H26 -> 76550 | I26: =CaseData!I26 -> 16405
B27: Fiscal 2023 | F27: =CaseData!F27 -> 6416 | G27: =CaseData!G27 -> 8817 | H27: =CaseData!H27 -> 80378 | I27: =CaseData!I27 -> 16897
B29: Tax Basis in Depreciable Assets | F29: =CaseData!F29 -> 65510 | G29: =CaseData!G29 -> 85696 | H29: =CaseData!H29 -> 645400 | I29: =CaseData!I29 -> 163002
B31: Blended Tax Depreciation Rate | F31: =CaseData!F31 -> 0.123 | G31: =CaseData!G31 -> 0.142 | H31: =CaseData!H31 -> 0.165 | I31: =CaseData!I31 -> 0.156
B32: (% of beginning basis + additions to fixed assets)
B34: Expenses Not Deductible:
B35: Fiscal 2019 | F35: =CaseData!F35 -> 6742 | G35: =CaseData!G35 -> 0 | H35: =CaseData!H35 -> 0 | I35: =CaseData!I35 -> 10343
B36: Fiscal 2020 | F36: =CaseData!F36 -> 0 | G36: =CaseData!G36 -> 0 | H36: =CaseData!H36 -> 88951 | I36: =CaseData!I36 -> 0
B37: Fiscal 2021 | F37: =CaseData!F37 -> 0 | G37: =CaseData!G37 -> 0 | H37: =CaseData!H37 -> 0 | I37: =CaseData!I37 -> 12434
B38: Fiscal 2022 | F38: =CaseData!F38 -> 0 | G38: =CaseData!G38 -> 0 | H38: =CaseData!H38 -> 0 | I38: =CaseData!I38 -> 0
B39: Fiscal 2023 | F39: =CaseData!F39 -> 0 | G39: =CaseData!G39 -> 0 | H39: =CaseData!H39 -> 0 | I39: =CaseData!I39 -> 0
B41: Incremental Deductions for Tax Purposes:
B42: Fiscal 2019 | F42: =CaseData!F42 -> 5709 | G42: =CaseData!G42 -> 7355 | H42: =CaseData!H42 -> 69048 | I42: =CaseData!I42 -> 6036
B43: Fiscal 2020 | F43: =CaseData!F43 -> 5972 | G43: =CaseData!G43 -> 8350 | H43: =CaseData!H43 -> 50099 | I43: =CaseData!I43 -> 3551
B44: Fiscal 2021 | F44: =CaseData!F44 -> 2317 | G44: =CaseData!G44 -> 6080 | H44: =CaseData!H44 -> 62106 | I44: =CaseData!I44 -> 10537
B45: Fiscal 2022 | F45: =CaseData!F45 -> 3809 | G45: =CaseData!G45 -> 4373 | H45: =CaseData!H45 -> 26776 | I45: =CaseData!I45 -> 6970
B46: Fiscal 2023 | F46: =CaseData!F46 -> 3790 | G46: =CaseData!G46 -> 9854 | H46: =CaseData!H46 -> 24089 | I46: =CaseData!I46 -> 9642
B48: Tax Loss Carry Forwards:
...
