Workbook
Name company: CaseData!$B$2
Name periods: CaseData!$C$70
Name start_date: CaseData!$C$69
Name topic: "CFM Topic: " & CaseData!$C$68

Sheet Calculations
A1: {=company} -> BCS Holdings Inc.
A2: {=topic} -> CFM Topic: Income Tax
A3: CALCULATIONS SCHEDULE | F3: Constant | G3: Unit | H3: Total | J3: {=YEAR( EOMONTH( start_date, _xlfn.SEQUENCE( 1, periods, 0, 12 ) ) )} -> 2023 | K3: 2024 | L3: 2025 | M3: 2026 | N3: 2027
E5: Country | F5: U.S.
A7: Tax schedule
E9: Projected Accounting Pre-tax Income | G9: USD m | J9: {=_xlfn.LET( _xlpm.values, CaseData!$F$11:$H$15, _xlpm.years, VALUE( RIGHT( CaseData!$B$11:$B$15, 4 ) ), _xlpm.countries, CaseData!$F$4:$I$4, _xlpm.current_year,_xlfn.ANCHORARRAY( $J$3), _xlpm.current_country, $F$5, _xlpm.fx_rate, INDEX( CaseData!$F$8:$I$8, 1, MATCH( _xlpm.current_country, _xlpm.countries, 0 ) ), _xlpm.projected, INDEX( _xlpm.values, MATCH( _xlpm.current_year, _xlpm.years, 0 ), MATCH( _xlpm.current_country, _xlpm.countries, 0 ) ), _xlpm.projected / _xlpm.fx_rate )} -> 26760 | K9: 25593 | L9: 28960.5 | M9: 25971 | N9: 21864
D10: plus | E10: Non deductible expenses | G10: {=$G$9:$G$9} -> USD m | J10: {=_xlfn.LET( _xlpm.values, CaseData!$F$37:$H$41, _xlpm.years, VALUE( RIGHT( CaseData!$B$11:$B$15, 4 ) ), _xlpm.countries, CaseData!$F$4:$I$4, _xlpm.current_year,_xlfn.ANCHORARRAY( $J$3), _xlpm.current_country, $F$5, _xlpm.fx_rate, INDEX( CaseData!$F$8:$I$8, 1, MATCH( _xlpm.current_country, _xlpm.countries, 0 ) ), _xlpm.projected, INDEX( _xlpm.values, MATCH( _xlpm.current_year, _xlpm.years, 0 ), MATCH( _xlpm.current_country, _xlpm.countries, 0 ) ), _xlpm.projected / _xlpm.fx_rate )} -> 10113 | K10: 0 | L10: 0 | M10: 0 | N10: 0
E11: Taxable Income for Accounting Purposes (A) | G11: {=$G$9:$G$9} -> USD m | J11: =SUM(J9:J10) -> 36873 | K11: =SUM(K9:K10) -> 25593 | L11: =SUM(L9:L10) -> 28960.5 | M11: =SUM(M9:M10) -> 25971 | N11: =SUM(N9:N10) -> 21864
D13: plus | E13: Accounting depreciation | G13: {=$G$9:$G$9} -> USD m | J13: {=_xlfn.LET( _xlpm.values, CaseData!$F$25:$H$29, _xlpm.years, VALUE( RIGHT( CaseData!$B$11:$B$15, 4 ) ), _xlpm.countries, CaseData!$F$4:$I$4, _xlpm.current_year,_xlfn.ANCHORARRAY( $J$3), _xlpm.current_country, $F$5, _xlpm.fx_rate, INDEX( CaseData!$F$8:$I$8, 1, MATCH( _xlpm.current_country, _xlpm.countries, 0 ) ), _xlpm.projected, INDEX( _xlpm.values, MATCH( _xlpm.current_year, _xlpm.years, 0 ), MATCH( _xlpm.current_country, _xlpm.countries, 0 ) ), _xlpm.projected / _xlpm.fx_rate )} -> 8148 | K13: 8392.5 | L13: 8812.5 | M13: 9253.5 | N13: 9624
D14: minus | E14: Taxable depreciation | G14: USD m | J14: =J32 -> 13238.613 | K14: =K32 -> 12604.35 | L14: =L32 -> 12478.908 | M14: =M32 -> 12186.241 | N14: =N32 -> 11395.075
D15: minus | E15: Incremental deduction for tax purposes | G15: USD m | J15: {=_xlfn.LET( _xlpm.values, CaseData!$F$44:$H$48, _xlpm.years, VALUE( RIGHT( CaseData!$B$11:$B$15, 4 ) ), _xlpm.countries, CaseData!$F$4:$I$4, _xlpm.current_year,_xlfn.ANCHORARRAY( $J$3), _xlpm.current_country, $F$5, _xlpm.fx_rate, INDEX( CaseData!$F$8:$I$8, 1, MATCH( _xlpm.current_country, _xlpm.countries, 0 ) ), _xlpm.projected, INDEX( _xlpm.values, MATCH( _xlpm.current_year, _xlpm.years, 0 ), MATCH( _xlpm.current_country, _xlpm.countries, 0 ) ), _xlpm.projected / _xlpm.fx_rate )} -> 8563.5 | K15: 8958 | L15: 3475.5 | M15: 5713.5 | N15: 5685
D16: minus | E16: Qualifying Expenses | G16: USD m | J16: =J39 -> 3500 | K16: =K39 -> 3780 | L16: =L39 -> 4082.5 | M16: =M39 -> 4409 | N16: =N39 -> 4761.5
E17: Taxable Income for Tax Purposes before NOL | G17: USD m | J17: =J11 + J13 - J14 - J15 - J16 -> 19718.887 | K17: =K11 + K13 - K14 - K15 - K16 -> 8643.1504 | L17: =L11 + L13 - L14 - L15 - L16 -> 17736.092 | M17: =M11 + M13 - M14 - M15 - M16 -> 12915.759 | N17: =N11 + N13 - N14 - N15 - N16 -> 9646.4247
D19: minus | E19: Utilization of Tax Loss Carry Forwards | G19: USD m | J19: =J43 -> 19718.887 | K19: =K43 -> 8643.1504 | L19: =L43 -> 17736.092 | M19: =M43 -> 12915.759 | N19: =N43 -> 6600
E20: Taxable Income for Tax Purposes after NOL | G20: USD m | J20: =J17 - J19 -> 0 | K20: =K17 - K19 -> 0 | L20: =L17 - L19 -> 0 | M20: =M17 - M19 -> 0 | N20: =N17 - N19 -> 3046.4247
E23: Current corporate tax rate | F23: {=_xlfn.LET( _xlpm.countries, CaseData!$F$4:$H$4, _xlpm.current_country, $F$5, _xlfn.XLOOKUP( _xlpm.current_country, _xlpm.countries, CaseData!$F$6:$H$6, 0, 0 ) )} -> 0.21
E24: Current tax | G24: USD m | J24: =$F$23 * J20 -> 0 | K24: =$F$23 * K20 -> 0 | L24: =$F$23 * L20 -> 0 | M24: =$F$23 * M20 -> 0 | N24: =$F$23 * N20 -> 639.74919
E25: Deferred tax | G25: USD m | J25: =J26 - J24 -> 7743.33 | K25: =K26 - K24 -> 5374.53 | L25: =L26 - L24 -> 6081.705 | M25: =M26 - M24 -> 5453.91 | N25: =N26 - N24 -> 3951.6908
E26: Tax | G26: USD m | J26: =$F$23 * J11 -> 7743.33 | K26: =$F$23 * K11 -> 5374.53 | L26: =$F$23 * L11 -> 6081.705 | M26: =$F$23 * M11 -> 5453.91 | N26: =$F$23 * N11 -> 4591.44
A28: Taxable depreciation
E30: Tax Basis in Depreciable Assets opening balance | G30: {=$G$9:$G$9} -> USD m | J30: {=_xlfn.LET( _xlpm.countries, CaseData!$F$4:$H$4, _xlpm.current_country, $F$5, _xlfn.XLOOKUP( _xlpm.current_country, _xlpm.countries, CaseData!$F$31:$H$31, 0, 0 ) )} -> 98265 | K30: =J33 -> 94392.387 | L30: =K33 -> 89870.037 | M30: =L33 -> 88975.629 | N30: =M33 -> 86888.888
D31: plus | E31: Addition to fixed assets | G31: USD m | J31: {=_xlfn.LET( _xlpm.values, CaseData!$F$18:$H$22, _xlpm.years, VALUE( RIGHT( CaseData!$B$11:$B$15, 4 ) ), _xlpm.countries, CaseData!$F$4:$I$4, _xlpm.current_year,_xlfn.ANCHORARRAY( $J$3), _xlpm.current_country, $F$5, _xlpm.fx_rate, INDEX( CaseData!$F$8:$I$8, 1, MATCH( _xlpm.current_country, _xlpm.countries, 0 ) ), _xlpm.projected, INDEX( _xlpm.values, MATCH( _xlpm.current_year, _xlpm.years, 0 ), MATCH( _xlpm.current_country, _xlpm.countries, 0 ) ), _xlpm.projected / _xlpm.fx_rate )} -> 9366 | K31: 8082 | L31: 11584.5 | M31: 10099.5 | N31: 5754
D32: minus | E32: Taxable Depreciation at blended rate | F32: {=_xlfn.LET( _xlpm.countries, CaseData!$F$4:$H$4, _xlpm.current_country, $F$5, _xlfn.XLOOKUP( _xlpm.current_country, _xlpm.countries, CaseData!$F$33:$H$33, 0, 0 ) )} -> 0.123 | G32: USD m | J32: =$F$32 * SUM( J30:J31 ) -> 13238.613 | K32: =$F$32 * SUM( K30:K31 ) -> 12604.35 | L32: =$F$32 * SUM( L30:L31 ) -> 12478.908 | M32: =$F$32 * SUM( M30:M31 ) -> 12186.241 | N32: =$F$32 * SUM( N30:N31 ) -> 11395.075
E33: Tax Basis in Depreciable Assets closing balance | G33: USD m | J33: =J30 + J31 - J32 -> 94392.387 | K33: =K30 + K31 - K32 -> 89870.037 | L33: =L30 + L31 - L32 -> 88975.629 | M33: =M30 + M31 - M32 -> 86888.888 | N33: =N30 + N31 - N32 -> 81247.813
A35: Qualifying expenses
E37: Qualifying expenses (not capped) | G37: {=$G$9:$G$9} -> USD m | J37: {=_xlfn.LET( _xlpm.values, CaseData!$F$54:$H$58, _xlpm.years, VALUE( RIGHT( CaseData!$B$11:$B$15, 4 ) ), _xlpm.countries, CaseData!$F$4:$I$4, _xlpm.current_year,_xlfn.ANCHORARRAY( $J$3), _xlpm.current_country, $F$5, _xlpm.fx_rate, INDEX( CaseData!$F$8:$I$8, 1, MATCH( _xlpm.current_country, _xlpm.countries, 0 ) ), _xlpm.projected, INDEX( _xlpm.values, MATCH( _xlpm.current_year, _xlpm.years, 0 ), MATCH( _xlpm.current_country, _xlpm.countries, 0 ) ), _xlpm.projected / _xlpm.fx_rate )} -> 3500 | K37: 3780 | L37: 4082.5 | M37: 4409 | N37: 4761.5
E38: Qualifying Expenses: % of Expenditure Deductible | F38: {=_xlfn.LET( _xlpm.countries, CaseData!$F$4:$H$4, _xlpm.current_country, $F$5, _xlfn.XLOOKUP( _xlpm.current_country, _xlpm.countries, CaseData!$F$50:$H$50, 0, 0 ) )} -> 1 | G38: % | J38: =J37 * $F$38 -> 3500 | K38: =K37 * $F$38 -> 3780 | L38: =L37 * $F$38 -> 4082.5 | M38: =M37 * $F$38 -> 4409 | N38: =N37 * $F$38 -> 4761.5
E39: Qualifying Expenses: Maximum Dollar Deductible | F39: {=_xlfn.LET( _xlpm.countries, CaseData!$F$4:$H$4, _xlpm.current_country, $F$5, _xlfn.XLOOKUP( _xlpm.current_country, _xlpm.countries, CaseData!$F$51:$H$51, 0, 0 ) )} -> No limit | G39: {=$G$9:$G$9} -> USD m | J39: =IF( $F$39 = "No limit", J$38, MIN( J38, $F$39 ) ) -> 3500 | K39: =IF( $F$39 = "No limit", K$38, MIN( K38, $F$39 ) ) -> 3780 | L39: =IF( $F$39 = "No limit", L$38, MIN( L38, $F$39 ) ) -> 4082.5 | M39: =IF( $F$39 = "No limit", M$38, MIN( M38, $F$39 ) ) -> 4409 | N39: =IF( $F$39 = "No limit", N$38, MIN( N38, $F$39 ) ) -> 4761.5
A41: Tax Loss Carry Forward
E43: Utilization of Tax Loss Carry Forwards | G43: USD m | J43: =MIN( J17, SUM( I54:I59 ) ) -> 19718.887 | K43: =MIN( K17, SUM( J54:J59 ) ) -> 8643.1504 | L43: =MIN( L17, SUM( K54:K59 ) ) -> 17736.092 | M43: =MIN( M17, SUM( L54:L59 ) ) -> 12915.759 | N43: =MIN( N17, SUM( M54:M59 ) ) -> 6600
E44: 45291 | G44: USD m | J44: =MIN( J43, I54 ) -> 5137.5 | K44: =MIN( K43, J54 ) -> 0 | L44: =MIN( L43, K54 ) -> 0 | M44: =MIN( M43, L54 ) -> 0 | N44: =MIN( N43, M54 ) -> 0
E45: 45657 | G45: USD m | J45: =MIN( I55, J$43 - SUM( J$44:J44 ) ) -> 14581.387 | K45: =MIN( J55, K$43 - SUM( K$44:K44 ) ) -> 6600.113 | L45: =MIN( K55, L$43 - SUM( L$44:L44 ) ) -> 0 | M45: =MIN( L55, M$43 - SUM( M$44:M44 ) ) -> 0 | N45: =MIN( M55, N$43 - SUM( N$44:N44 ) ) -> 0
E46: 46022 | G46: USD m | J46: =MIN( I56, J$43 - SUM( J$44:J45 ) ) -> 0 | K46: =MIN( J56, K$43 - SUM( K$44:K45 ) ) -> 0 | L46: =MIN( K56, L$43 - SUM( L$44:L45 ) ) -> 0 | M46: =MIN( L56, M$43 - SUM( M$44:M45 ) ) -> 0 | N46: =MIN( M56, N$43 - SUM( N$44:N45 ) ) -> 0
E47: 46387 | G47: USD m | J47: =MIN( I57, J$43 - SUM( J$44:J46 ) ) -> 0 | K47: =MIN( J57, K$43 - SUM( K$44:K46 ) ) -> 2043.0374 | L47: =MIN( K57, L$43 - SUM( L$44:L46 ) ) -> 16438.463 | M47: =MIN( L57, M$43 - SUM( M$44:M46 ) ) -> 0 | N47: =MIN( M57, N$43 - SUM( N$44:N46 ) ) -> 0
E48: 46752 | G48: USD m | J48: =MIN( I58, J$43 - SUM( J$44:J47 ) ) -> 0 | K48: =MIN( J58, K$43 - SUM( K$44:K47 ) ) -> 0 | L48: =MIN( K58, L$43 - SUM( L$44:L47 ) ) -> 1297.6293 | M48: =MIN( L58, M$43 - SUM( M$44:M47 ) ) -> 12422.871 | N48: =MIN( M58, N$43 - SUM( N$44:N47 ) ) -> 0
E49: Expiring thereafter | G49: USD m | J49: =MIN( I59, J$43 - SUM( J$44:J48 ) ) -> 0 | K49: =MIN( J59, K$43 - SUM( K$44:K48 ) ) -> 0 | L49: =MIN( K59, L$43 - SUM( L$44:L48 ) ) -> 0 | M49: =MIN( L59, M$43 - SUM( M$44:M48 ) ) -> 492.8884 | N49: =MIN( M59, N$43 - SUM( N$44:N48 ) ) -> 6600
J52: {=YEAR( EOMONTH( start_date, _xlfn.SEQUENCE( 1, periods, 0, 12 ) ) )} -> 2023 | K52: 2024 | L52: 2025 | M52: 2026 | N52: 2027
E53: Tax Loss Carry Forwards Ending Balances
E54: 45291 | G54: USD m | I54: {=_xlfn.LET( _xlpm.values, CaseData!$F$61:$H$66, _xlpm.years, VALUE( RIGHT( CaseData!$B$11:$B$15, 4 ) ), _xlpm.countries, CaseData!$F$4:$H$4, _xlpm.current_year,_xlfn.ANCHORARRAY( $J$3), _xlpm.current_country, $F$5, _xlpm.fx_rate, INDEX( CaseData!$F$8:$H$8, 1, MATCH( _xlpm.current_country, _xlpm.countries, 0 ) ), _xlpm.projected, INDEX( _xlpm.values, MATCH( _xlpm.current_year, _xlpm.years, 0 ), MATCH( _xlpm.current_country, _xlpm.countries, 0 ) ), TRANSPOSE( _xlpm.projected / _xlpm.fx_rate ) )} -> 5137.5 | J54: =IF( J$52 < $E54, I54 - J44, 0 ) -> 0 | K54: =IF( K$52 < $E54, J54 - K44, 0 ) -> 0 | L54: =IF( L$52 < $E54, K54 - L44, 0 ) -> 0 | M54: =IF( M$52 < $E54, L54 - M44, 0 ) -> 0 | N54: =IF( N$52 < $E54, M54 - N44, 0 ) -> 0
E55: 45657 | G55: USD m | I55: 21181.5 | J55: =IF( J$52 < $E55, I55 - J45, 0 ) -> 6600.113 | K55: =IF( K$52 < $E55, J55 - K45, 0 ) -> 0 | L55: =IF( L$52 < $E55, K55 - L45, 0 ) -> 0 | M55: =IF( M$52 < $E55, L55 - M45, 0 ) -> 0 | N55: =IF( N$52 < $E55, M55 - N45, 0 ) -> 0
...

Sheet CaseData
B2: BCS Holdings Inc.
B3: (in thousands, local currency as indicated)
F4: U.S. | G4: Canada | H4: Italy
F5: (USD) | G5: (CAD) | H5: (EUR)
B6: Corporate Tax Rate | F6: 0.21 | G6: 0.265 | H6: 0.24
B8: Exchange Rate (per USD) | F8: 1 | G8: 1.25 | H8: 1
B10: Projected Accounting Pre-tax Income:
B11: Fiscal 2023 | F11: 26760 | G11: 40860 | H11: 44643
B12: Fiscal 2024 | F12: 25593 | G12: 39141 | H12: 45309
B13: Fiscal 2025 | F13: 28960.5 | G13: 41452.5 | H13: 49378.5
B14: Fiscal 2026 | F14: 25971 | G14: 36444 | H14: 47487
B15: Fiscal 2027 | F15: 21864 | G15: 44791.5 | H15: 43651.5
B17: Additions to Fixed Assets:
B18: Fiscal 2023 | F18: 9366 | G18: 14593.5 | H18: 24961.5
B19: Fiscal 2024 | F19: 8082 | G19: 24907.5 | H19: 12730.5
B20: Fiscal 2025 | F20: 11584.5 | G20: 13818 | H20: 14715
B21: Fiscal 2026 | F21: 10099.5 | G21: 14577 | H21: 29883
B22: Fiscal 2027 | F22: 5754 | G22: 24432 | H22: 24451.5
B24: Accounting Depreciation:
B25: Fiscal 2023 | F25: 8148 | G25: 11091 | H25: 21466.5
B26: Fiscal 2024 | F26: 8392.5 | G26: 11535 | H26: 22110
B27: Fiscal 2025 | F27: 8812.5 | G27: 11997 | H27: 23436
B28: Fiscal 2026 | F28: 9253.5 | G28: 12717 | H28: 24607.5
B29: Fiscal 2027 | F29: 9624 | G29: 13225.5 | H29: 25345.5
B31: Tax Basis in Depreciable Assets | F31: 98265 | G31: 128544 | H31: 244503
B33: Blended Tax Depreciation Rate | F33: 0.123 | G33: 0.142 | H33: 0.156
B34: (% of beginning basis + additions to fixed assets)
B36: Expenses Not Deductible:
B37: Fiscal 2023 | F37: 10113 | G37: 0 | H37: 15514.5
B38: Fiscal 2024 | F38: 0 | G38: 0 | H38: 0
B39: Fiscal 2025 | F39: 0 | G39: 0 | H39: 18651
B40: Fiscal 2026 | F40: 0 | G40: 0 | H40: 0
B41: Fiscal 2027 | F41: 0 | G41: 0 | H41: 0
B43: Incremental Deductions for Tax Purposes:
B44: Fiscal 2023 | F44: 8563.5 | G44: 11032.5 | H44: 9054
B45: Fiscal 2024 | F45: 8958 | G45: 12525 | H45: 5326.5
B46: Fiscal 2025 | F46: 3475.5 | G46: 9120 | H46: 15805.5
B47: Fiscal 2026 | F47: 5713.5 | G47: 6559.5 | H47: 10455
B48: Fiscal 2027 | F48: 5685 | G48: 14781 | H48: 14463
B50: Qualifying Expenses: % of Expenditure Deductible | F50: 1 | G50: 0.35 | H50: 0.2
...

Sheet CaseSolution
B2: =CaseData!B2 -> BCS Holdings Inc.
B3: =CaseData!B3 -> (in thousands, local currency as indicated)
B5: Answer Table
B7: Tasks to Complete / Questions:
A8: a) | B8: See below
A9: b) | B9: Use all US tax losses? | C9: If so, when?
B10: =IF(SUM(E66:E71)=SUM(F66:J71)=TRUE,"Yes","No") -> Yes | C10: =IF(B10="Yes",INDEX($F$21:$J$21,MATCH(0,$F$81:$J$81,0)),"N/A") -> 2027
A11: c) | B11: Effective tax rate in 2025:
B12: =H241 -> 0.27978866
A13: d) | B13: Total income tax expense in 2026:
B14: =I233 -> 24576.918
A15: e) | B15: Deferred income tax expense in 2027:
B16: =J227 -> 19350.192
B19: Tax Schedules
F20: =CaseData!B11 -> Fiscal 2023 | G20: =CaseData!B12 -> Fiscal 2024 | H20: =CaseData!B13 -> Fiscal 2025 | I20: =CaseData!B14 -> Fiscal 2026 | J20: =CaseData!B15 -> Fiscal 2027
B21: UNITED STATES (USD) | D21: Tax Rate | E21: =CaseData!F6 -> 0.21 | F21: =_xlfn.NUMBERVALUE(RIGHT(F20,4)) -> 2023 | G21: =_xlfn.NUMBERVALUE(RIGHT(G20,4)) -> 2024 | H21: =_xlfn.NUMBERVALUE(RIGHT(H20,4)) -> 2025 | I21: =_xlfn.NUMBERVALUE(RIGHT(I20,4)) -> 2026 | J21: =_xlfn.NUMBERVALUE(RIGHT(J20,4)) -> 2027
B22: Tax Calculation:
B23: Projected Accounting Pre-tax Income | F23: =INDEX(CaseData!$F$11:$F$15,MATCH(F$20,CaseData!$B$11:$B$15,0)) -> 26760 | G23: =INDEX(CaseData!$F$11:$F$15,MATCH(G$20,CaseData!$B$11:$B$15,0)) -> 25593 | H23: =INDEX(CaseData!$F$11:$F$15,MATCH(H$20,CaseData!$B$11:$B$15,0)) -> 28960.5 | I23: =INDEX(CaseData!$F$11:$F$15,MATCH(I$20,CaseData!$B$11:$B$15,0)) -> 25971 | J23: =INDEX(CaseData!$F$11:$F$15,MATCH(J$20,CaseData!$B$11:$B$15,0)) -> 21864
B24: Plus: Non-Deductible Expenses | F24: =INDEX(CaseData!$F$37:$F$41,MATCH(F$20,CaseData!$B$37:$B$41,0)) -> 10113 | G24: =INDEX(CaseData!$F$37:$F$41,MATCH(G$20,CaseData!$B$37:$B$41,0)) -> 0 | H24: =INDEX(CaseData!$F$37:$F$41,MATCH(H$20,CaseData!$B$37:$B$41,0)) -> 0 | I24: =INDEX(CaseData!$F$37:$F$41,MATCH(I$20,CaseData!$B$37:$B$41,0)) -> 0 | J24: =INDEX(CaseData!$F$37:$F$41,MATCH(J$20,CaseData!$B$37:$B$41,0)) -> 0
B25: Taxable Income for Accounting Purposes (A) | F25: =SUM(F23:F24) -> 36873 | G25: =SUM(G23:G24) -> 25593 | H25: =SUM(H23:H24) -> 28960.5 | I25: =SUM(I23:I24) -> 25971 | J25: =SUM(J23:J24) -> 21864
B27: Plus: Accounting Depreciation | F27: =INDEX(CaseData!$F$25:$F$29,MATCH(F$20,CaseData!$B$25:$B$29,0)) -> 8148 | G27: =INDEX(CaseData!$F$25:$F$29,MATCH(G$20,CaseData!$B$25:$B$29,0)) -> 8392.5 | H27: =INDEX(CaseData!$F$25:$F$29,MATCH(H$20,CaseData!$B$25:$B$29,0)) -> 8812.5 | I27: =INDEX(CaseData!$F$25:$F$29,MATCH(I$20,CaseData!$B$25:$B$29,0)) -> 9253.5 | J27: =INDEX(CaseData!$F$25:$F$29,MATCH(J$20,CaseData!$B$25:$B$29,0)) -> 9624
B28: Less: Tax Depreciation | F28: =F45 -> -13238.613 | G28: =G45 -> -12604.35 | H28: =H45 -> -12478.908 | I28: =I45 -> -12186.241 | J28: =J45 -> -11395.075
B29: Less: Incremental Deductions for Tax Purposes | F29: =-INDEX(CaseData!$F$44:$F$48,MATCH(F$20,CaseData!$B$44:$B$48,0)) -> -8563.5 | G29: =-INDEX(CaseData!$F$44:$F$48,MATCH(G$20,CaseData!$B$44:$B$48,0)) -> -8958 | H29: =-INDEX(CaseData!$F$44:$F$48,MATCH(H$20,CaseData!$B$44:$B$48,0)) -> -3475.5 | I29: =-INDEX(CaseData!$F$44:$F$48,MATCH(I$20,CaseData!$B$44:$B$48,0)) -> -5713.5 | J29: =-INDEX(CaseData!$F$44:$F$48,MATCH(J$20,CaseData!$B$44:$B$48,0)) -> -5685
B30: Less: Qualifying Expense Deductions | F30: =-F56 -> -3500 | G30: =-G56 -> -3780 | H30: =-H56 -> -4082.5 | I30: =-I56 -> -4409 | J30: =-J56 -> -4761.5
B31: Taxable Income for Gov't Purposes before Acc. Losses | F31: =SUM(F25:F30) -> 19718.887 | G31: =SUM(G25:G30) -> 8643.1504 | H31: =SUM(H25:H30) -> 17736.092 | I31: =SUM(I25:I30) -> 12915.759 | J31: =SUM(J25:J30) -> 9646.4247
B33: Less: Acc. Losses Used | F33: =-F72 -> -19718.887 | G33: =-G72 -> -8643.1504 | H33: =-H72 -> -17736.092 | I33: =-I72 -> -12915.759 | J33: =-J72 -> -6107.1116
B34: Taxable Income for Gov't Purposes After Acc. Losses (B) | F34: =SUM(F31:F33) -> 0 | G34: =SUM(G31:G33) -> 0 | H34: =SUM(H31:H33) -> 0 | I34: =SUM(I31:I33) -> 0 | J34: =SUM(J31:J33) -> 3539.3131
B36: Tax Summary:
B37: Current Tax Expense (Rate * B) | F37: =$E$21*F34 -> 0 | G37: =$E$21*G34 -> 0 | H37: =$E$21*H34 -> 0 | I37: =$E$21*I34 -> 0 | J37: =$E$21*J34 -> 743.25576
B38: Deferred Tax Expense | F38: =F39-F37 -> 7743.33 | G38: =G39-G37 -> 5374.53 | H38: =H39-H37 -> 6081.705 | I38: =I39-I37 -> 5453.91 | J38: =J39-J37 -> 3848.1842
B39: Total Tax Expense (Rate * A) | F39: =$E$21*F25 -> 7743.33 | G39: =$E$21*G25 -> 5374.53 | H39: =$E$21*H25 -> 6081.705 | I39: =$E$21*I25 -> 5453.91 | J39: =$E$21*J25 -> 4591.44
B42: Tax Depreciation Schedule: | D42: Tax Dep'n Rate | E42: =CaseData!F33 -> 0.123
B43: Opening Tax Basis in Depreciable Assets | F43: =E46 -> 98265 | G43: =F46 -> 94392.387 | H43: =G46 -> 89870.037 | I43: =H46 -> 88975.629 | J43: =I46 -> 86888.888
B44: Plus: Additions to Fixed Assets | F44: =INDEX(CaseData!$F$18:$F$22,MATCH(F$20,CaseData!$B$18:$B$22,0)) -> 9366 | G44: =INDEX(CaseData!$F$18:$F$22,MATCH(G$20,CaseData!$B$18:$B$22,0)) -> 8082 | H44: =INDEX(CaseData!$F$18:$F$22,MATCH(H$20,CaseData!$B$18:$B$22,0)) -> 11584.5 | I44: =INDEX(CaseData!$F$18:$F$22,MATCH(I$20,CaseData!$B$18:$B$22,0)) -> 10099.5 | J44: =INDEX(CaseData!$F$18:$F$22,MATCH(J$20,CaseData!$B$18:$B$22,0)) -> 5754
B45: Less: Tax Depreciation Claimed | F45: =-$E$42*SUM(F43:F44) -> -13238.613 | G45: =-$E$42*SUM(G43:G44) -> -12604.35 | H45: =-$E$42*SUM(H43:H44) -> -12478.908 | I45: =-$E$42*SUM(I43:I44) -> -12186.241 | J45: =-$E$42*SUM(J43:J44) -> -11395.075
B46: Closing Tax Basis in Depreciable Assets | E46: =CaseData!F31 -> 98265 | F46: =SUM(F43:F45) -> 94392.387 | G46: =SUM(G43:G45) -> 89870.037 | H46: =SUM(H43:H45) -> 88975.629 | I46: =SUM(I43:I45) -> 86888.888 | J46: =SUM(J43:J45) -> 81247.813
B49: Qualifying Expense Schedule:
B50: Qualifying Expenses | F50: =INDEX(CaseData!$F$54:$F$58,MATCH(F$20,CaseData!$B$54:$B$58,0)) -> 3500 | G50: =INDEX(CaseData!$F$54:$F$58,MATCH(G$20,CaseData!$B$54:$B$58,0)) -> 3780 | H50: =INDEX(CaseData!$F$54:$F$58,MATCH(H$20,CaseData!$B$54:$B$58,0)) -> 4082.5 | I50: =INDEX(CaseData!$F$54:$F$58,MATCH(I$20,CaseData!$B$54:$B$58,0)) -> 4409 | J50: =INDEX(CaseData!$F$54:$F$58,MATCH(J$20,CaseData!$B$54:$B$58,0)) -> 4761.5
B51: % of Expenditure Deductible | F51: =CaseData!$F$50 -> 1 | G51: =CaseData!$F$50 -> 1 | H51: =CaseData!$F$50 -> 1 | I51: =CaseData!$F$50 -> 1 | J51: =CaseData!$F$50 -> 1
B52: Maximum Dollar Deductible | F52: =CaseData!$F$51 -> No limit | G52: =CaseData!$F$51 -> No limit | H52: =CaseData!$F$51 -> No limit | I52: =CaseData!$F$51 -> No limit | J52: =CaseData!$F$51 -> No limit
...
