Workbook
Name company: CaseData!$B$1
Name Date: CaseData!$T$29:$Y$29
Name periods: CaseData!$D$47
Name start_date: CaseData!$D$46
Name topic: "CFM Topic: " & CaseData!$D$48

Sheet Debt
A1: {=company} -> Streamwise Ltd.
A2: {=topic} -> CFM Topic: Debt
A3: DEBT SCHEDULE | F3: Unit | G3: =EOMONTH( $H$3, - 1 ) -> 43373 | H3: {=EOMONTH( start_date, _xlfn.SEQUENCE( 1, periods, 0, 1 ) )} -> 43404 | I3: 43434 | J3: 43465 | K3: 43496 | L3: 43524 | M3: 43555
A5: Total Debt / EBIDTA
E8: =E$141 -> Total Debt | F8: =F$141 -> USD | G8: =SUM($G38, $G57, $G76, $G94 ) -> 686848 | H8: =H$141 -> 681911.17 | I8: =I$141 -> 678265.46 | J8: =J$141 -> 682917.34 | K8: =K$141 -> 680818.37 | L8: =L$141 -> 678745.64 | M8: =M$141 -> 677104.93
E9: EBIDTA | F9: USD | G9: =CaseData!$S$53 -> 191177 | H9: =CaseData!E$63 -> 193220 | I9: =CaseData!F$63 -> 189600 | J9: =CaseData!G$63 -> 186312 | K9: =CaseData!H$63 -> 185545 | L9: =CaseData!I$63 -> 185313 | M9: =CaseData!J$63 -> 183795
E10: Total Debt / EBIDTA | F10: multiple | G10: =G8 / G9 -> 3.5927334 | H10: =H8 / H9 -> 3.5291956 | I10: =I8 / I9 -> 3.5773495 | J10: =J8 / J9 -> 3.6654501 | K10: =K8 / K9 -> 3.6692898 | L10: =L8 / L9 -> 3.6626985 | M10: =M8 / M9 -> 3.6840226
A13: Taxes
E16: Free Cash Flow Before Debt Service & Taxes | F16: USD | H16: =CaseData!E$65 -> 10393.67 | I16: =CaseData!F$65 -> 8667.573 | J16: =CaseData!G$65 -> 6355.84 | K16: =CaseData!H$65 -> 8884.205 | L16: =CaseData!I$65 -> 11026.2 | M16: =CaseData!J$65 -> 5745.409
D17: less | E17: =E$112 -> Interest expenses accrued | F17: USD | H17: =H$112 * - 1 -> -3811.228 | I17: =I$112 * - 1 -> -3806.6267 | J17: =J$112 * - 1 -> -3806.2239 | K17: =K$112 * - 1 -> -3363.4927 | L17: =L$112 * - 1 -> -3453.4365 | M17: =M$112 * - 1 -> -3557.7918
E18: Taxable income | F18: USD | H18: =SUM(H16:H17) -> 6582.442 | I18: =SUM(I16:I17) -> 4860.9463 | J18: =SUM(J16:J17) -> 2549.6161 | K18: =SUM(K16:K17) -> 5520.7123 | L18: =SUM(L16:L17) -> 7572.7635 | M18: =SUM(M16:M17) -> 2187.6172
E20: Applicable tax rate | F20: % | G20: =CaseData!$K$8 -> 0.25
E21: Taxes paid | F21: USD | H21: =H$18 * $G$20 -> 1645.6105 | I21: =I$18 * $G$20 -> 1215.2366 | J21: =J$18 * $G$20 -> 637.40402 | K21: =K$18 * $G$20 -> 1380.1781 | L21: =L$18 * $G$20 -> 1893.1909 | M21: =M$18 * $G$20 -> 546.9043
A24: Revolver
C27: Free cash flow after repayment of debt service and taxes
E29: Free Cash Flow Before Debt Service & Taxes | F29: USD | H29: =CaseData!E$65 -> 10393.67 | I29: =CaseData!F$65 -> 8667.573 | J29: =CaseData!G$65 -> 6355.84 | K29: =CaseData!H$65 -> 8884.205 | L29: =CaseData!I$65 -> 11026.2 | M29: =CaseData!J$65 -> 5745.409
E30: Principal addition / (repayment) | F30: USD | H30: =H$131 -> -2179.6875 | I30: =I$131 -> -2152.4414 | J30: =J$131 -> 12874.464 | K30: =K$131 -> -2098.9667 | L30: =L$131 -> -2072.7296 | M30: =M$131 -> -2046.8205
D31: less | E31: =E$112 -> Interest expenses accrued | F31: USD | H31: =H$112 * - 1 -> -3811.228 | I31: =I$112 * - 1 -> -3806.6267 | J31: =J$112 * - 1 -> -3806.2239 | K31: =K$112 * - 1 -> -3363.4927 | L31: =L$112 * - 1 -> -3453.4365 | M31: =M$112 * - 1 -> -3557.7918
D32: less | E32: Taxes paid | F32: USD | H32: =H$21 * - 1 -> -1645.6105 | I32: =I$21 * - 1 -> -1215.2366 | J32: =J$21 * - 1 -> -637.40402 | K32: =K$21 * - 1 -> -1380.1781 | L32: =L$21 * - 1 -> -1893.1909 | M32: =M$21 * - 1 -> -546.9043
E33: Free cash flow after repayment of debt service and taxes | F33: USD | H33: =SUM( H29:H32) -> 2757.144 | I33: =SUM( I29:I32) -> 1493.2683 | J33: =SUM( J29:J32) -> 14786.676 | K33: =SUM( K29:K32) -> 2041.5676 | L33: =SUM( L29:L32) -> 3606.843 | M33: =SUM( M29:M32) -> -406.10757
E36: Revolver beginning balance | F36: USD | H36: =G$38 -> 12473 | I36: =H$38 -> 9715.856 | J36: =I$38 -> 8222.5877 | K36: =J$38 -> 0 | L36: =K$38 -> 0 | M36: =L$38 -> 0
E37: Revolver Drawdown / (Repayment) | F37: USD | H37: =- MIN( H36, H33) -> -2757.144 | I37: =- MIN( I36, I33) -> -1493.2683 | J37: =- MIN( J36, J33) -> -8222.5877 | K37: =- MIN( K36, K33) -> 0 | L37: =- MIN( L36, L33) -> 0 | M37: =- MIN( M36, M33) -> 406.10757
E38: Revolver closing balance | F38: USD | G38: =CaseData!$E$8 -> 12473 | H38: =SUM(H36:H37) -> 9715.856 | I38: =SUM(I36:I37) -> 8222.5877 | J38: =SUM(J36:J37) -> 0 | K38: =SUM(K36:K37) -> 0 | L38: =SUM(L36:L37) -> 0 | M38: =SUM(M36:M37) -> 406.10757
C40: Revolver interest expenses
E42: LIBOR | F42: % | H42: =CaseData!E$66 -> 0.0225 | I42: =CaseData!F$66 -> 0.0235 | J42: =CaseData!G$66 -> 0.0245 | K42: =CaseData!H$66 -> 0.0255 | L42: =CaseData!I$66 -> 0.0265 | M42: =CaseData!J$66 -> 0.027
E43: Spread to LIBOR based on Total Debt / EBIDTA | F43: % | H43: =_xlfn.XLOOKUP(G$10, CaseData!$G$11:$G$14, CaseData!$I$11:$I$14,,-1)/10000 -> 0.03 | I43: =_xlfn.XLOOKUP(H$10, CaseData!$G$11:$G$14, CaseData!$I$11:$I$14,,-1)/10000 -> 0.03 | J43: =_xlfn.XLOOKUP(I$10, CaseData!$G$11:$G$14, CaseData!$I$11:$I$14,,-1)/10000 -> 0.03 | K43: =_xlfn.XLOOKUP(J$10, CaseData!$G$11:$G$14, CaseData!$I$11:$I$14,,-1)/10000 -> 0.03 | L43: =_xlfn.XLOOKUP(K$10, CaseData!$G$11:$G$14, CaseData!$I$11:$I$14,,-1)/10000 -> 0.03 | M43: =_xlfn.XLOOKUP(L$10, CaseData!$G$11:$G$14, CaseData!$I$11:$I$14,,-1)/10000 -> 0.03
E44: Effective interest rate on revolver | F44: % | H44: =SUM(H42:H43) -> 0.0525 | I44: =SUM(I42:I43) -> 0.0535 | J44: =SUM(J42:J43) -> 0.0545 | K44: =SUM(K42:K43) -> 0.0555 | L44: =SUM(L42:L43) -> 0.0565 | M44: =SUM(M42:M43) -> 0.057
E47: Drawn Interest Expense | F47: USD | H47: =IF( H$3 = start_date, CaseData!$E$8 * H$44, H$36 * Debt!H$44 ) / 12 -> 54.569375 | I47: =IF( I$3 = start_date, CaseData!$E$8 * I$44, I$36 * Debt!I$44 ) / 12 -> 43.316525 | J47: =IF( J$3 = start_date, CaseData!$E$8 * J$44, J$36 * Debt!J$44 ) / 12 -> 37.344252 | K47: =IF( K$3 = start_date, CaseData!$E$8 * K$44, K$36 * Debt!K$44 ) / 12 -> 0 | L47: =IF( L$3 = start_date, CaseData!$E$8 * L$44, L$36 * Debt!L$44 ) / 12 -> 0 | M47: =IF( M$3 = start_date, CaseData!$E$8 * M$44, M$36 * Debt!M$44 ) / 12 -> 0
E48: Standby fee on undrawn revolver facility | F48: USD | H48: =IF(H$3 = start_date, ( CaseData!$E$7 - CaseData!$E$8 ) * ( CaseData!$E$10/10000 ) / 12, ( CaseData!$E$7 - Debt!H$36 ) * ( CaseData!$E$10 / 10000 ) / 12 ) -> 25.018 | I48: =IF(I$3=start_date, (CaseData!$E$7-CaseData!$E$8)*(CaseData!$E$10/10000)/12, (CaseData!$E$7-Debt!I$36)*(CaseData!$E$10/10000)/12) -> 26.856096 | J48: =IF(J$3=start_date, (CaseData!$E$7-CaseData!$E$8)*(CaseData!$E$10/10000)/12, (CaseData!$E$7-Debt!J$36)*(CaseData!$E$10/10000)/12) -> 27.851608 | K48: =IF(K$3=start_date, (CaseData!$E$7-CaseData!$E$8)*(CaseData!$E$10/10000)/12, (CaseData!$E$7-Debt!K$36)*(CaseData!$E$10/10000)/12) -> 33.333333 | L48: =IF(L$3=start_date, (CaseData!$E$7-CaseData!$E$8)*(CaseData!$E$10/10000)/12, (CaseData!$E$7-Debt!L$36)*(CaseData!$E$10/10000)/12) -> 33.333333 | M48: =IF(M$3=start_date, (CaseData!$E$7-CaseData!$E$8)*(CaseData!$E$10/10000)/12, (CaseData!$E$7-Debt!M$36)*(CaseData!$E$10/10000)/12) -> 33.333333
E49: Revolver interest expenses | F49: USD | H49: =SUM(H47:H48) -> 79.587375 | I49: =SUM(I47:I48) -> 70.172621 | J49: =SUM(J47:J48) -> 65.195861 | K49: =SUM(K47:K48) -> 33.333333 | L49: =SUM(L47:L48) -> 33.333333 | M49: =SUM(M47:M48) -> 33.333333
A52: Senior Secured Term Loan
E55: Senior Secured Term Loan opening balance | F55: USD | H55: =G$57 -> 174375 | I55: =H$57 -> 172195.31 | J55: =I$57 -> 170042.87 | K55: =J$57 -> 167917.34 | L55: =K$57 -> 165818.37 | M55: =L$57 -> 163745.64
E56: Senior Secured Term Loan drawdown / (repayments) | F56: USD | H56: =IF( H$3 = start_date, CaseData!$E$17 * CaseData!$E$20, H$55 * CaseData!$E$20 ) * - 1 -> -2179.6875 | I56: =IF( I$3 = start_date, CaseData!$E$17 * CaseData!$E$20, I$55 * CaseData!$E$20 ) * - 1 -> -2152.4414 | J56: =IF( J$3 = start_date, CaseData!$E$17 * CaseData!$E$20, J$55 * CaseData!$E$20 ) * - 1 -> -2125.5359 | K56: =IF( K$3 = start_date, CaseData!$E$17 * CaseData!$E$20, K$55 * CaseData!$E$20 ) * - 1 -> -2098.9667 | L56: =IF( L$3 = start_date, CaseData!$E$17 * CaseData!$E$20, L$55 * CaseData!$E$20 ) * - 1 -> -2072.7296 | M56: =IF( M$3 = start_date, CaseData!$E$17 * CaseData!$E$20, M$55 * CaseData!$E$20 ) * - 1 -> -2046.8205
E57: Senior Secured Term Loan closing balance | F57: USD | G57: =CaseData!$E$17 -> 174375 | H57: =SUM(H55:H56) -> 172195.31 | I57: =SUM(I55:I56) -> 170042.87 | J57: =SUM(J55:J56) -> 167917.34 | K57: =SUM(K55:K56) -> 165818.37 | L57: =SUM(L55:L56) -> 163745.64 | M57: =SUM(M55:M56) -> 161698.82
C60: Senior Secured Term Loan interest expenses
E62: LIBOR | F62: % | H62: =CaseData!E$66 -> 0.0225 | I62: =CaseData!F$66 -> 0.0235 | J62: =CaseData!G$66 -> 0.0245 | K62: =CaseData!H$66 -> 0.0255 | L62: =CaseData!I$66 -> 0.0265 | M62: =CaseData!J$66 -> 0.027
E63: Spread to LIBOR based on Total Debt / EBIDTA | F63: % | H63: =_xlfn.XLOOKUP( G$10, CaseData!$G$11:$G$14, CaseData!$I$11:$I$14,,-1 ) / 10000 -> 0.03 | I63: =_xlfn.XLOOKUP( H$10, CaseData!$G$11:$G$14, CaseData!$I$11:$I$14,,-1 ) / 10000 -> 0.03 | J63: =_xlfn.XLOOKUP( I$10, CaseData!$G$11:$G$14, CaseData!$I$11:$I$14,,-1 ) / 10000 -> 0.03 | K63: =_xlfn.XLOOKUP( J$10, CaseData!$G$11:$G$14, CaseData!$I$11:$I$14,,-1 ) / 10000 -> 0.03 | L63: =_xlfn.XLOOKUP( K$10, CaseData!$G$11:$G$14, CaseData!$I$11:$I$14,,-1 ) / 10000 -> 0.03 | M63: =_xlfn.XLOOKUP( L$10, CaseData!$G$11:$G$14, CaseData!$I$11:$I$14,,-1 ) / 10000 -> 0.03
E64: Effective interest rate on Senior Secured Term Loan | F64: % | H64: =SUM(H62:H63) -> 0.0525 | I64: =SUM(I62:I63) -> 0.0535 | J64: =SUM(J62:J63) -> 0.0545 | K64: =SUM(K62:K63) -> 0.0555 | L64: =SUM(L62:L63) -> 0.0565 | M64: =SUM(M62:M63) -> 0.057
E67: Senior Secured Term Loan interest expenses | F67: USD | H67: =H$55 * H64 / 12 -> 762.89062 | I67: =I$55 * I64 / 12 -> 767.7041 | J67: =J$55 * J64 / 12 -> 772.27804 | K67: =K$55 * K64 / 12 -> 776.61768 | L67: =L$55 * L64 / 12 -> 780.72815 | M67: =M$55 * M64 / 12 -> 777.79178
E68: (monthly amortization)
...

Sheet CaseData
B1: Streamwise Ltd.
B2: (in thousands of $)
B4: Existing Debt as at Sep. 30, 2018
B6: Revolving Credit Facility:
B7: Max. Amount | E7: 50000 | G7: Annual Drawn Rates | K7: Cash Taxes
B8: Balance Outstanding | E8: 12473 | G8: payable monthly based on prev. month | K8: 0.25
G9: Total Debt / | I9: Spread to
B10: Annual Undrawn Rate | E10: 80 | G10: EBITDA >= | I10: LIBOR
B11: (payable monthly) | G11: 0 | I11: 100
G12: 2 | I12: 175
B13: Interest Coverage Ratio | E13: 2.25 | G13: 3 | I13: 225
G14: 3.5 | I14: 300
B16: Senior Secured Term Loan: | G16: Subordinated Notes:
B17: Balance Outstanding | E17: 174375 | G17: Face Amount | I17: 500000 | K17: Call Date | N17: Annual Coupons:
B18: Original Amount | E18: 225000 | G18: Amortization | I18: 0 | N18: {=TRANSPOSE( E62:J62)} -> 43404 | P18: 0.0505
G19: Annual Coupon | I19: 0.07125 | N19: 43434 | P19: 0.0525
B20: Monthy Amortization | E20: 0.0125 | G20: Payable semi-annually on: | I20: Sep. 30 | N20: 43465 | P20: 0.057
I21: Mar. 31 | N21: 43496 | P21: 0.0595
B22: Annual Drawn Rate | E22: Same | G22: Final Maturity | I22: Mar. 31, 2019 | N22: 43524 | P22: 0.0615
B23: (payable monthly) | E23: as revolver | G23: Early Call Prices: | N23: 43555 | P23: 0.064
G24: On or before | H24: 43465 | I24: 1.03
B25: Final Maturity | E25: Jun. 30, 2022 | G25: Before | H25: 43555 | I25: 1.02 | N25: Payable semi-annually on: | P25: =EOMONTH(Debt!M166,6) -> 43646
P26: =EOMONTH(P25,6) -> 43830
B27: Historical Debt Details
B29: Revolving Credit Facility: | E29: 42947 | F29: 42978 | G29: 43008 | H29: 43039 | I29: 43069 | J29: 43100 | K29: 43131 | L29: 43159 | M29: 43190 | N29: 43220 | O29: 43251 | P29: 43281 | Q29: 43312 | R29: 43343 | S29: 43373 | T29: =EOMONTH(S29,1) -> 43404 | U29: =EOMONTH(T29,1) -> 43434 | V29: =EOMONTH(U29,1) -> 43465 | W29: =EOMONTH(V29,1) -> 43496 | X29: =EOMONTH(W29,1) -> 43524 | Y29: =EOMONTH(X29,1) -> 43555
B30: Ending Balance | D30: 10029 | E30: 5395 | F30: 11094 | G30: 12111 | H30: 12263 | I30: 21116 | J30: 26477 | K30: 31004 | L30: 18530 | M30: 8274 | N30: 31247 | O30: 33481 | P30: 15891 | Q30: 36380 | R30: 13877 | S30: 12473 | T30: =MAX(S30-E77,0) -> 10348.668 | U30: =MAX(T30-F77,0) -> 9287.7534 | V30: =MAX(U30-G77,0) -> 9964.186 | W30: =MAX(V30-H77,0) -> 6523.832 | X30: =MAX(W30-I77,0) -> 1475.4315 | Y30: =MAX(X30-J77,0) -> 377.27158
B31: Drawn Interest | E31: 44.337 | F31: 24.929 | G31: 49.137 | H31: 53.884 | I31: 51.709 | J31: 97.239 | K31: 112.814 | L31: 131.534 | M31: 82.721 | N31: 36.771 | O31: 130.274 | P31: 141.792 | Q31: 68.583 | R31: 165.832 | S31: 60.272 | T31: =S$30*T$57*(30/360) -> 54.569375 | U31: =T$30*U$57*(30/360) -> 28.890033 | V31: =U$30*V$57*(30/360) -> 26.702291 | W31: =V$30*W$57*(30/360) -> 29.477383 | X31: =W$30*X$57*(30/360) -> 19.843322 | Y31: =X$30*Y$57*(30/360) -> 4.549247
B32: Undrawn Interest | E32: 26.647 | F32: 29.737 | G32: 25.937 | H32: 25.259 | I32: 25.158 | J32: 19.256 | K32: 15.682 | L32: 12.664 | M32: 20.98 | N32: 27.817 | O32: 12.502 | P32: 11.013 | Q32: 22.739 | R32: 9.08 | S32: 24.082 | T32: =($E$7-S$30)*$E$10/10000*(30/360) -> 25.018 | U32: =($E$7-T$30)*$E$10/10000*(30/360) -> 26.434221 | V32: =($E$7-U$30)*$E$10/10000*(30/360) -> 27.141498 | W32: =($E$7-V$30)*$E$10/10000*(30/360) -> 26.690543 | X32: =($E$7-W$30)*$E$10/10000*(30/360) -> 28.984112 | Y32: =($E$7-X$30)*$E$10/10000*(30/360) -> 32.349712
B34: Senior Secured Term Loan:
B35: Ending Balance | D35: 216562.5 | E35: 213750 | F35: 210937.5 | G35: 208125 | H35: 205312.5 | I35: 202500 | J35: 199687.5 | K35: 196875 | L35: 194062.5 | M35: 191250 | N35: 188437.5 | O35: 185625 | P35: 182812.5 | Q35: 180000 | R35: 177187.5 | S35: 174375 | T35: =S35-(R35-S35) -> 171562.5 | U35: =T35-(S35-T35) -> 168750 | V35: =U35-(T35-U35) -> 165937.5 | W35: =V35-(U35-V35) -> 163125 | X35: =W35-(V35-W35) -> 160312.5 | Y35: =X35-(W35-X35) -> 157500
B36: Interest | E36: 957.387 | F36: 987.703 | G36: 934.277 | H36: 925.983 | I36: 865.734 | J36: 932.513 | K36: 850.835 | L36: 835.242 | M36: 866.327 | N36: 849.947 | O36: 785.627 | P36: 786.122 | Q36: 788.988 | R36: 820.5 | S36: 769.584 | T36: =(30/360)*T57*S35 -> 762.89062 | U36: =(30/360)*U57*T35 -> 478.94531 | V36: =(30/360)*V57*U35 -> 485.15625 | W36: =(30/360)*W57*V35 -> 490.89844 | X36: =(30/360)*X57*W35 -> 496.17187 | Y36: =(30/360)*Y57*X35 -> 494.29687
B38: Principal Repayment | E38: =D35-E35 -> 2812.5 | F38: =E35-F35 -> 2812.5 | G38: =F35-G35 -> 2812.5 | H38: =G35-H35 -> 2812.5 | I38: =H35-I35 -> 2812.5 | J38: =I35-J35 -> 2812.5 | K38: =J35-K35 -> 2812.5 | L38: =K35-L35 -> 2812.5 | ... Y38: =X35-Y35 -> 2812.5
B40: Subordinated Notes:
B41: Ending Balance | D41: 500000 | E41: 500000 | F41: 500000 | G41: 500000 | H41: 500000 | I41: 500000 | J41: 500000 | K41: 500000 | L41: 500000 | M41: 500000 | N41: 500000 | O41: 500000 | P41: 500000 | Q41: 500000 | R41: 500000 | S41: 500000 | T41: =IF(Debt!$M$166<T29,0,S41) -> 500000 | U41: =IF(Debt!$M$166<U29,0,T41) -> 500000 | V41: =IF(Debt!$M$166<V29,0,U41) -> 500000 | W41: =IF(Debt!$M$166<W29,0,V41) -> 0 | X41: =IF(Debt!$M$166<X29,0,W41) -> 0 | Y41: =IF(Debt!$M$166<Y29,0,X41) -> 0
B42: Interest | E42: 2968.75 | F42: 2968.75 | G42: 2968.75 | H42: 2968.75 | I42: 2968.75 | J42: 2968.75 | K42: 2968.75 | L42: 2968.75 | M42: 2968.75 | N42: 2968.75 | O42: 2968.75 | P42: 2968.75 | Q42: 2968.75 | R42: 2968.75 | S42: 2968.75 | T42: =IF(T41=0,0,S42) -> 2968.75 | U42: =IF(U41=0,0,T42) -> 2968.75 | V42: =IF(V41=0,0,U42) -> 2968.75 | W42: =IF(W41=0,0,V42) -> 0 | X42: =IF(X41=0,0,W42) -> 0 | Y42: =IF(Y41=0,0,X42) -> 0
B43: Interest Paid | G43: =SUM(B42:G42) -> 8906.25 | M43: =SUM(H42:M42) -> 17812.5 | S43: =SUM(N42:S42) -> 17812.5
B44: Call Payment | T44: =IF(T$29=Debt!$M$166,T$41*$I$24,0) -> 0 | U44: =IF(U$29=Debt!$M$166,U$41*$I$24,0) -> 0 | V44: =IF(V$29=Debt!$M$166,V$41*$I$24,0) -> 515000 | W44: =IF(W$29=Debt!$M$166,W$41*$I$25,0) -> 0 | X44: =IF(X$29=Debt!$M$166,X$41*$I$25,0) -> 0 | Y44: =IF(Y$29=Debt!$M$166,Y$41,0) -> 0
B46: Model start date | D46: 43404 | E46: date
B47: Number of periods | D47: 6 | E47: months
B48: Topic | D48: Debt
...

Sheet CaseSolution
B1: Streamwise Ltd.
B2: (in thousands of $)
B4: =CaseData!B4 -> Existing Debt as at Sep. 30, 2018
B6: Revolving Credit Facility:
B7: Max. Amount | E7: =CaseData!E7 -> 50000 | G7: Annual Drawn Rates | K7: Taxes
B8: Balance Outstanding | E8: =CaseData!E8 -> 12473 | G8: payable monthly based on prev. month
G9: Total Debt / | I9: Spread to | K9: Applicable Rate: | M9: 0.25
B10: Annual Undrawn Rate | E10: =CaseData!E10 -> 80 | G10: EBITDA >= | I10: LIBOR
B11: (payable monthly) | G11: =CaseData!G11 -> 0 | I11: =CaseData!I11 -> 100
G12: =CaseData!G12 -> 2 | I12: =CaseData!I12 -> 175
B13: Interest Coverage Ratio | E13: =CaseData!E13 -> 2.25 | G13: =CaseData!G13 -> 3 | I13: =CaseData!I13 -> 225
G14: =CaseData!G14 -> 3.5 | I14: =CaseData!I14 -> 300
B16: Senior Secured Term Loan: | G16: Subordinated Notes: | K16: New Senior Notes:
B17: Balance Outstanding | E17: =CaseData!E17 -> 174375 | G17: Face Amount | I17: =CaseData!I17 -> 500000 | K17: Date Issued | M17: 43465
B18: Original Amount | E18: =CaseData!E18 -> 225000 | G18: Amortization | I18: =CaseData!I18 -> 0 | K18: Annual Coupons:
G19: Annual Coupon | I19: =CaseData!I19 -> 0.07125 | K19: {=TRANSPOSE(E65:J65)} -> 43404 | M19: 0.0505
B20: Monthy Amortization | E20: =CaseData!E20 -> 0.0125 | G20: Payable semi-annually on: | I20: 43373 | K20: 43434 | M20: 0.0525
I21: =EOMONTH(I20,6) -> 43555 | K21: 43465 | M21: 0.057
B22: Annual Drawn Rate | E22: Same | G22: Final Maturity | I22: =I21 -> 43555 | K22: 43496 | M22: 0.0595
B23: (payable monthly) | E23: as revolver | G23: Period | H23: Date | I23: Call Prices | K23: 43524 | M23: 0.0615
G24: After | H24: =S31 -> 43373 | I24: 1.03 | K24: 43555 | M24: 0.064
B25: Final Maturity | E25: =CaseData!E25 -> Jun. 30, 2022 | G25: After | H25: 43465 | I25: 1.02
G26: After | H26: 43524 | I26: 1 | K26: Payable semi-annually on: | M26: =EOMONTH(M17,6) -> 43646
M27: =EOMONTH(M26,6) -> 43830
B29: Historical Debt Details
B31: =B6 -> Revolving Credit Facility: | E31: =CaseData!E29 -> 42947 | F31: =CaseData!F29 -> 42978 | G31: =CaseData!G29 -> 43008 | H31: =CaseData!H29 -> 43039 | I31: =CaseData!I29 -> 43069 | J31: =CaseData!J29 -> 43100 | K31: =CaseData!K29 -> 43131 | L31: =CaseData!L29 -> 43159 | ... S31: =CaseData!S29 -> 43373
B32: Ending Balance | D32: =CaseData!D30 -> 10029 | E32: =CaseData!E30 -> 5395 | F32: =CaseData!F30 -> 11094 | G32: =CaseData!G30 -> 12111 | H32: =CaseData!H30 -> 12263 | I32: =CaseData!I30 -> 21116 | J32: =CaseData!J30 -> 26477 | K32: =CaseData!K30 -> 31004 | ... S32: =CaseData!S30 -> 12473
B33: Drawn Interest | E33: =CaseData!E31 -> 44.337 | F33: =CaseData!F31 -> 24.929 | G33: =CaseData!G31 -> 49.137 | H33: =CaseData!H31 -> 53.884 | I33: =CaseData!I31 -> 51.709 | J33: =CaseData!J31 -> 97.239 | K33: =CaseData!K31 -> 112.814 | L33: =CaseData!L31 -> 131.534 | ... S33: =CaseData!S31 -> 60.272
B34: Undrawn Interest | E34: =CaseData!E32 -> 26.647 | F34: =CaseData!F32 -> 29.737 | G34: =CaseData!G32 -> 25.937 | H34: =CaseData!H32 -> 25.259 | I34: =CaseData!I32 -> 25.158 | J34: =CaseData!J32 -> 19.256 | K34: =CaseData!K32 -> 15.682 | L34: =CaseData!L32 -> 12.664 | ... S34: =CaseData!S32 -> 24.082
B35: Total Reveolver Interest | E35: =E33+E34 -> 70.984 | F35: =F33+F34 -> 54.666 | G35: =G33+G34 -> 75.074 | H35: =H33+H34 -> 79.143 | I35: =I33+I34 -> 76.867 | J35: =J33+J34 -> 116.495 | K35: =K33+K34 -> 128.496 | L35: =L33+L34 -> 144.198 | ... S35: =S33+S34 -> 84.354
B37: Senior Secured Term Loan:
B38: Ending Balance | D38: =CaseData!D35 -> 216562.5 | E38: =CaseData!E35 -> 213750 | F38: =CaseData!F35 -> 210937.5 | G38: =CaseData!G35 -> 208125 | H38: =CaseData!H35 -> 205312.5 | I38: =CaseData!I35 -> 202500 | J38: =CaseData!J35 -> 199687.5 | K38: =CaseData!K35 -> 196875 | ... S38: =CaseData!S35 -> 174375
B39: Interest | E39: =CaseData!E36 -> 957.387 | F39: =CaseData!F36 -> 987.703 | G39: =CaseData!G36 -> 934.277 | H39: =CaseData!H36 -> 925.983 | I39: =CaseData!I36 -> 865.734 | J39: =CaseData!J36 -> 932.513 | K39: =CaseData!K36 -> 850.835 | L39: =CaseData!L36 -> 835.242 | ... S39: =CaseData!S36 -> 769.584
B41: =G16 -> Subordinated Notes:
B42: Ending Balance | D42: =CaseData!D41 -> 500000 | E42: =CaseData!E41 -> 500000 | F42: =CaseData!F41 -> 500000 | G42: =CaseData!G41 -> 500000 | H42: =CaseData!H41 -> 500000 | I42: =CaseData!I41 -> 500000 | J42: =CaseData!J41 -> 500000 | K42: =CaseData!K41 -> 500000 | ... S42: =CaseData!S41 -> 500000
B43: Interest | E43: =CaseData!E42 -> 2968.75 | F43: =CaseData!F42 -> 2968.75 | G43: =CaseData!G42 -> 2968.75 | H43: =CaseData!H42 -> 2968.75 | I43: =CaseData!I42 -> 2968.75 | J43: =CaseData!J42 -> 2968.75 | K43: =CaseData!K42 -> 2968.75 | L43: =CaseData!L42 -> 2968.75 | ... S43: =CaseData!S42 -> 2968.75
B46: Total Debt | D46: =D32+D38+D42 -> 726591.5 | E46: =E32+E38+E42 -> 719145 | F46: =F32+F38+F42 -> 722031.5 | G46: =G32+G38+G42 -> 720236 | H46: =H32+H38+H42 -> 717575.5 | I46: =I32+I38+I42 -> 723616 | J46: =J32+J38+J42 -> 726164.5 | K46: =K32+K38+K42 -> 727879 | ... S46: =S32+S38+S42 -> 686848
B47: TTM EBITDA | D47: =CaseData!D53 -> 183244 | E47: =CaseData!E53 -> 191930 | F47: =CaseData!F53 -> 199032 | G47: =CaseData!G53 -> 175519 | H47: =CaseData!H53 -> 170868 | I47: =CaseData!I53 -> 156913 | J47: =CaseData!J53 -> 179890 | K47: =CaseData!K53 -> 174023 | ... S47: =CaseData!S53 -> 191177
B48: Total Debt / EBITDA | D48: =D46/D47 -> 3.9651585 | E48: =E46/E47 -> 3.7469129 | F48: =F46/F47 -> 3.6277156 | G48: =G46/G47 -> 4.1034646 | H48: =H46/H47 -> 4.1995897 | I48: =I46/I47 -> 4.6115746 | J48: =J46/J47 -> 4.0367141 | K48: =K46/K47 -> 4.1826598 | ... S48: =S46/S47 -> 3.5927334
B49: LIBOR | D49: =CaseData!D55 -> 0.02317 | E49: =CaseData!E55 -> 0.02305 | F49: =CaseData!F55 -> 0.02545 | G49: =CaseData!G55 -> 0.02315 | H49: =CaseData!H55 -> 0.02339 | I49: =CaseData!I55 -> 0.0206 | J49: =CaseData!J55 -> 0.02526 | K49: =CaseData!K55 -> 0.02113 | ... S49: =CaseData!S55 -> 0.02212
...
