Workbook
Name company: Case1Data!$A$1
Name EBIDTA_scenarios: Case1Data!$E$108:$E$111
Name EBIDTA_selector: Debt!$F$15
Name periods: Case1Data!$H$41
Name sculpting_scenarios: Case1Data!$E$104:$E$106
Name sculpting_selector: Debt!$F$8
Name start_date: Case1Data!$H$39
Name topic: "CFM Topic: " & Case1Data!$E$96

Sheet Debt
A1: {=company} -> Blackrat SPV Pty Ltd
A2: {=topic} -> CFM Topic: Debt | J2: {=EDATE( start_date + 1, _xlfn.SEQUENCE(1, periods, 0, 3 ) )} -> 43466 | K2: 43556 | L2: 43647 | M2: 43739 | N2: 43831 | O2: 43922 | P2: 44013 | Q2: 44105 | R2: 44197 | S2: 44287 | T2: 44378 | U2: 44470 | V2: 44562 | W2: 44652 | X2: 44743 | Y2: 44835 | Z2: 44927 | AA2: 45017 | AB2: 45108 | AC2: 45200 | AD2: 45292 | AE2: 45383 | AF2: 45474 | AG2: 45566 | AH2: 45658 | AI2: 45748 | AJ2: 45839 | AK2: 45931 | AL2: 46023 | AM2: 46113 | AN2: 46204 | AO2: 46296 | AP2: 46388 | AQ2: 46478 | AR2: 46569 | AS2: 46661 | AT2: 46753 | AU2: 46844 | AV2: 46935 | AW2: 47027
A3: DEBT SCHEDULE | F3: Constant | G3: Unit | H3: Total | J3: {=EOMONTH( start_date, _xlfn.SEQUENCE( 1, periods, 3, 3 ) )} -> 43555 | K3: 43646 | L3: 43738 | M3: 43830 | N3: 43921 | O3: 44012 | P3: 44104 | Q3: 44196 | R3: 44286 | S3: 44377 | T3: 44469 | U3: 44561 | V3: 44651 | W3: 44742 | X3: 44834 | Y3: 44926 | Z3: 45016 | AA3: 45107 | AB3: 45199 | AC3: 45291 | AD3: 45382 | AE3: 45473 | AF3: 45565 | AG3: 45657 | AH3: 45747 | AI3: 45838 | AJ3: 45930 | AK3: 46022 | AL3: 46112 | AM3: 46203 | AN3: 46295 | AO3: 46387 | AP3: 46477 | AQ3: 46568 | AR3: 46660 | AS3: 46752 | AT3: 46843 | AU3: 46934 | AV3: 47026 | AW3: 47118
A5: Scenarios
E8: Debt sculpting scenarios | F8: 1
E10: Scenario name | F10: =INDEX( Case1Data!$G$17:$I$19, MATCH( Debt!$E10, Case1Data!$D$17:$D$19, 0 ), MATCH( sculpting_selector, Case1Data!$G$16:$I$16, 0 ) ) -> Passive
E11: Sculpted senior DSCR | F11: =INDEX( Case1Data!$G$17:$I$19, MATCH( Debt!$E11, Case1Data!$D$17:$D$19, 0 ), MATCH( sculpting_selector, Case1Data!$G$16:$I$16, 0 ) ) -> 2
E12: Annual interest rate | F12: =INDEX( Case1Data!$G$17:$I$19, MATCH( Debt!$E12, Case1Data!$D$17:$D$19, 0 ), MATCH( sculpting_selector, Case1Data!$G$16:$I$16, 0 ) ) -> 0.045
E15: Selected EBIDTA scenario | F15: 1
A19: Senior Debt
E22: Senior Debt BEG | G22: USD | J22: =I24 -> 10000000 | K22: =J24 -> 9771868.5 | L22: =K24 -> 9544849.5 | M22: =L24 -> 9318438.1 | N22: =M24 -> 9090564 | O22: =N24 -> 8859628.9 | P22: =O24 -> 8633291.7 | Q22: =P24 -> 8404698.7 | ... AW22: =AV24 -> 0
E23: Senior Debt addition / (repayment) | G23: USD | J23: =- MIN( J$22, J$44 ) -> -228131.5 | K23: =- MIN( K$22, K$44 ) -> -227018.98 | L23: =- MIN( L$22, L$44 ) -> -226411.44 | M23: =- MIN( M$22, M$44 ) -> -227874.07 | N23: =- MIN( N$22, N$44 ) -> -230935.15 | O23: =- MIN( O$22, O$44 ) -> -226337.18 | P23: =- MIN( P$22, P$44 ) -> -228592.97 | Q23: =- MIN( Q$22, Q$44 ) -> -228913.64 | ... AW23: =- MIN( AW$22, AW$44 ) -> 0
E24: Senior Debt | G24: USD | I24: =Case1Data!H$13 -> 10000000 | J24: =SUM( J22:J23 ) -> 9771868.5 | K24: =SUM( K22:K23 ) -> 9544849.5 | L24: =SUM( L22:L23 ) -> 9318438.1 | M24: =SUM( M22:M23 ) -> 9090564 | N24: =SUM( N22:N23 ) -> 8859628.9 | O24: =SUM( O22:O23 ) -> 8633291.7 | P24: =SUM( P22:P23 ) -> 8404698.7 | Q24: =SUM( Q22:Q23 ) -> 8175785.1 | ... AW24: =SUM( AW22:AW23 ) -> 0
C27: Senior Debt interest
E28: Annual interest rate on Senior Debt | F28: =$F$12 -> 0.045 | G28: %
E29: Senior Debt interest expenses | G29: USD | J29: =J22 * $F$28 / 4 -> 112500 | K29: =K22 * $F$28 / 4 -> 109933.52 | L29: =L22 * $F$28 / 4 -> 107379.56 | M29: =M22 * $F$28 / 4 -> 104832.43 | N29: =N22 * $F$28 / 4 -> 102268.85 | O29: =O22 * $F$28 / 4 -> 99670.825 | P29: =P22 * $F$28 / 4 -> 97124.531 | Q29: =Q22 * $F$28 / 4 -> 94552.86 | ... AW29: =AW22 * $F$28 / 4 -> 0
A32: Debt Service Coverage Ratio ("DSCR")
E35: Target DSCR | G35: factor | J35: {=_xlfn.SEQUENCE( 1, periods, Debt!$F$11, 0 )} -> 2 | K35: 2 | L35: 2 | M35: 2 | N35: 2 | O35: 2 | P35: 2 | Q35: 2 | R35: 2 | S35: 2 | T35: 2 | U35: 2 | V35: 2 | W35: 2 | X35: 2 | Y35: 2 | Z35: 2 | AA35: 2 | AB35: 2 | AC35: 2 | AD35: 2 | AE35: 2 | AF35: 2 | AG35: 2 | AH35: 2 | AI35: 2 | AJ35: 2 | AK35: 2 | AL35: 2 | AM35: 2 | AN35: 2 | AO35: 2 | AP35: 2 | AQ35: 2 | AR35: 2 | AS35: 2 | AT35: 2 | AU35: 2 | AV35: 2 | AW35: 2
E37: EBIDTA | G37: USD | J37: {=INDEX( Case1Data!$G$52:$J$91, MATCH(_xlfn.ANCHORARRAY( Debt!J3), Case1Data!$E$52:$E$91, 0 ), MATCH( EBIDTA_selector, Case1Data!$G$49:$J$49, 0 ) )} -> 679388 | K37: 672030 | L37: 665707 | M37: 663538 | N37: 664533 | O37: 650141 | P37: 649560 | Q37: 645058 | R37: 676898 | S37: 642290 | T37: 652741 | U37: 643964 | V37: 642292 | W37: 671775 | X37: 674599 | Y37: 685274 | Z37: 660287 | AA37: 677193 | AB37: 687307 | AC37: 699274 | AD37: 719236 | AE37: 693326 | AF37: 713143 | AG37: 698365 | AH37: 699462 | AI37: 706344 | AJ37: 738541 | AK37: 706443 | AL37: 696744 | AM37: 714636 | AN37: 755656 | AO37: 750348 | AP37: 740563 | AQ37: 731253 | AR37: 755344 | AS37: 768793 | AT37: 764348 | AU37: 758728 | AV37: 771909 | AW37: 772307
D38: plus | E38: =E$57 -> Debt Service Reserve Account ("DSRA") interest income | G38: =G$57 -> USD | J38: =J$57 -> 1875 | K38: =K$57 -> 1875 | L38: =L$57 -> 1875 | M38: =M$57 -> 1875 | N38: =N$57 -> 1875 | O38: =O$57 -> 1875 | P38: =P$57 -> 1875 | Q38: =Q$57 -> 1875 | ... AW38: =AW$57 -> 0
E39: Cash available for debt service | G39: USD | J39: =SUM(J37:J38) -> 681263 | K39: =SUM(K37:K38) -> 673905 | L39: =SUM(L37:L38) -> 667582 | M39: =SUM(M37:M38) -> 665413 | N39: =SUM(N37:N38) -> 666408 | O39: =SUM(O37:O38) -> 652016 | P39: =SUM(P37:P38) -> 651435 | Q39: =SUM(Q37:Q38) -> 646933 | ... AW39: =SUM(AW37:AW38) -> 772307
E41: Target DSCR | F41: =$F$11 -> 2 | G41: factor
E42: Target Senior Debt Service | G42: USD | J42: =J$39 / J$35 -> 340631.5 | K42: =K$39 / K$35 -> 336952.5 | L42: =L$39 / L$35 -> 333791 | M42: =M$39 / M$35 -> 332706.5 | N42: =N$39 / N$35 -> 333204 | O42: =O$39 / O$35 -> 326008 | P42: =P$39 / P$35 -> 325717.5 | Q42: =Q$39 / Q$35 -> 323466.5 | ... AW42: =AW$39 / AW$35 -> 386153.5
D43: less | E43: =E$29 -> Senior Debt interest expenses | G43: =G$29 -> USD | J43: =J$29 * - 1 -> -112500 | K43: =K$29 * - 1 -> -109933.52 | L43: =L$29 * - 1 -> -107379.56 | M43: =M$29 * - 1 -> -104832.43 | N43: =N$29 * - 1 -> -102268.85 | O43: =O$29 * - 1 -> -99670.825 | P43: =P$29 * - 1 -> -97124.531 | Q43: =Q$29 * - 1 -> -94552.86 | ... AW43: =AW$29 * - 1 -> 0
E44: Target Debt Repayment | G44: USD | J44: =SUM(J42:J43) -> 228131.5 | K44: =SUM(K42:K43) -> 227018.98 | L44: =SUM(L42:L43) -> 226411.44 | M44: =SUM(M42:M43) -> 227874.07 | N44: =SUM(N42:N43) -> 230935.15 | O44: =SUM(O42:O43) -> 226337.18 | P44: =SUM(P42:P43) -> 228592.97 | Q44: =SUM(Q42:Q43) -> 228913.64 | ... AW44: =SUM(AW42:AW43) -> 386153.5
E46: Actual DSCR | G46: factor | J46: =IFERROR( J$39 / ( J29 - J23 ), 0 ) -> 2 | K46: =IFERROR( K$39 / ( K29 - K23 ), 0 ) -> 2 | L46: =IFERROR( L$39 / ( L29 - L23 ), 0 ) -> 2 | M46: =IFERROR( M$39 / ( M29 - M23 ), 0 ) -> 2 | N46: =IFERROR( N$39 / ( N29 - N23 ), 0 ) -> 2 | O46: =IFERROR( O$39 / ( O29 - O23 ), 0 ) -> 2 | P46: =IFERROR( P$39 / ( P29 - P23 ), 0 ) -> 2 | Q46: =IFERROR( Q$39 / ( Q29 - Q23 ), 0 ) -> 2 | ... AW46: =IFERROR( AW$39 / ( AW29 - AW23 ), 0 ) -> 0
A49: Debt Service Reserve Account ("DSRA") interest income
E52: Debt Service Reserve Account ("DSCA") BEG | G52: USD | J52: =I54 -> 500000 | K52: =J54 -> 500000 | L52: =K54 -> 500000 | M52: =L54 -> 500000 | N52: =M54 -> 500000 | O52: =N54 -> 500000 | P52: =O54 -> 500000 | Q52: =P54 -> 500000 | ... AW52: =AV54 -> 0
E53: Debt Service Reserve Account ("DSCA") addition / (release) | G53: USD | J53: =IF( J$24 = 0, - J$52, 0 ) -> 0 | K53: =IF( K$24 = 0, - K$52, 0 ) -> 0 | L53: =IF( L$24 = 0, - L$52, 0 ) -> 0 | M53: =IF( M$24 = 0, - M$52, 0 ) -> 0 | N53: =IF( N$24 = 0, - N$52, 0 ) -> 0 | O53: =IF( O$24 = 0, - O$52, 0 ) -> 0 | P53: =IF( P$24 = 0, - P$52, 0 ) -> 0 | Q53: =IF( Q$24 = 0, - Q$52, 0 ) -> 0 | ... AW53: =IF( AW$24 = 0, - AW$52, 0 ) -> 0
E54: Debt Service Reserve Account ("DSCA") | G54: USD | I54: =Case1Data!$H$23 -> 500000 | J54: =SUM(J52:J53) -> 500000 | K54: =SUM(K52:K53) -> 500000 | L54: =SUM(L52:L53) -> 500000 | M54: =SUM(M52:M53) -> 500000 | N54: =SUM(N52:N53) -> 500000 | O54: =SUM(O52:O53) -> 500000 | P54: =SUM(P52:P53) -> 500000 | Q54: =SUM(Q52:Q53) -> 500000 | ... AW54: =SUM(AW52:AW53) -> 0
E56: Interest rate on "DSRA" | F56: =Case1Data!$H$25 -> 0.015 | G56: %
E57: Debt Service Reserve Account ("DSRA") interest income | G57: USD | J57: =J$52 * $F$56 / 4 -> 1875 | K57: =K$52 * $F$56 / 4 -> 1875 | L57: =L$52 * $F$56 / 4 -> 1875 | M57: =M$52 * $F$56 / 4 -> 1875 | N57: =N$52 * $F$56 / 4 -> 1875 | O57: =O$52 * $F$56 / 4 -> 1875 | P57: =P$52 * $F$56 / 4 -> 1875 | Q57: =Q$52 * $F$56 / 4 -> 1875 | ... AW57: =AW$52 * $F$56 / 4 -> 0
A60: Junior Debt
E63: Junior Debt BEG | G63: USD | J63: =I$65 -> 6000000 | K63: =J$65 -> 5850000 | L63: =K$65 -> 5700000 | M63: =L$65 -> 5550000 | N63: =M$65 -> 5400000 | O63: =N$65 -> 5250000 | P63: =O$65 -> 5100000 | Q63: =P$65 -> 4950000 | ... AW63: =AV$65 -> 150000
E64: Junior Debt addition / (repayment) | G64: USD | J64: =MIN( $I$65 / Case1Data!$H$30, J$63 ) * - 1 -> -150000 | K64: =MIN( $I$65 / Case1Data!$H$30, K$63 ) * - 1 -> -150000 | L64: =MIN( $I$65 / Case1Data!$H$30, L$63 ) * - 1 -> -150000 | M64: =MIN( $I$65 / Case1Data!$H$30, M$63 ) * - 1 -> -150000 | N64: =MIN( $I$65 / Case1Data!$H$30, N$63 ) * - 1 -> -150000 | O64: =MIN( $I$65 / Case1Data!$H$30, O$63 ) * - 1 -> -150000 | P64: =MIN( $I$65 / Case1Data!$H$30, P$63 ) * - 1 -> -150000 | Q64: =MIN( $I$65 / Case1Data!$H$30, Q$63 ) * - 1 -> -150000 | ... AW64: =MIN( $I$65 / Case1Data!$H$30, AW$63 ) * - 1 -> -150000
E65: Junior Debt | G65: USD | I65: =Case1Data!$H$28 -> 6000000 | J65: =SUM(J63:J64) -> 5850000 | K65: =SUM(K63:K64) -> 5700000 | L65: =SUM(L63:L64) -> 5550000 | M65: =SUM(M63:M64) -> 5400000 | N65: =SUM(N63:N64) -> 5250000 | O65: =SUM(O63:O64) -> 5100000 | P65: =SUM(P63:P64) -> 4950000 | Q65: =SUM(Q63:Q64) -> 4800000 | ... AW65: =SUM(AW63:AW64) -> 0
C68: Junior Debt interest
E69: Annual interest rate on Junior Debt | F69: =Case1Data!$H$29 -> 0.07 | G69: %
E70: Junior Debt interest expenses | G70: USD | J70: =J$63 * $F$69 / 4 -> 105000 | K70: =K$63 * $F$69 / 4 -> 102375 | L70: =L$63 * $F$69 / 4 -> 99750 | M70: =M$63 * $F$69 / 4 -> 97125 | N70: =N$63 * $F$69 / 4 -> 94500 | O70: =O$63 * $F$69 / 4 -> 91875 | P70: =P$63 * $F$69 / 4 -> 89250 | Q70: =Q$63 * $F$69 / 4 -> 86625 | ... AW70: =AW$63 * $F$69 / 4 -> 2625
A73: Returns and value
...

Sheet Case1Data
A1: Blackrat SPV Pty Ltd
A3: 1 | C3: Assumptions
A10: =MAX(A$3:A9)+0.01 -> 1.01 | C10: Assumptions
B12: Senior Facility
D13: Facility balance at model start date | F13: [$] | H13: 10000000
C15: Sculpting and interest rate scenarios
D16: Scenario number | F16: [#] | G16: 1 | H16: 2 | I16: 3
D17: Scenario name | F17: [text] | G17: Passive | H17: Neutral | I17: Aggressive
D18: Sculpted senior DSCR | F18: [x] | G18: 2 | H18: 1.8 | I18: 1.7
D19: Annual interest rate | F19: [% p.a.] | G19: 0.045 | H19: 0.05 | I19: 0.055
B22: Debt Service Reserve Account
D23: Initial balance at project start (already funded) | F23: [$] | H23: 500000
D24: Required minimum balance during term of Senior Facility | F24: [$] | H24: 500000
D25: Interest rate earned on account balance | F25: [% p.a.] | H25: 0.015
B27: Junior Facility
D28: Facility balance at model start date | F28: [$] | H28: 6000000
D29: Annual interest rate | F29: [% p.a.] | H29: 0.07
D30: Amortisation quarters | F30: [#] | H30: 40
D31: Scheduled final payment date | F31: [date] | H31: =EOMONTH(H39,3*H30) -> 47118
B33: Equity
D34: Contribution amount at model start date | F34: [$] | H34: 4000000
D35: Discount rate for Net Present Value calculations | F35: [% p.a.] | H35: 0.095
B38: Other Assumptions
D39: Model start date (Project start date) | F39: [date] | H39: 43465
D40: Initial quarter end date | F40: [date] | H40: =EOMONTH(H39,3) -> 43555
D41: Number of quarters in project | F41: [# qtrs] | H41: 40
D42: Final quarter end date (Project end date) | F42: [date] | H42: =EOMONTH(H39,H41*3) -> 47118
D44: Interest rate earned on cash account balance | F44: [% p.a.] | H44: 0.015
C47: EBITDA Profiles ($)
E49: Profile number --> | G49: 1 | H49: 2 | I49: 3 | J49: 4
E50: Profile name --> | G50: Base Case | H50: Case 2 | I50: Case 3 | J50: Case 4 | M50: {=TRANSPOSE(G50:J50)} -> Base Case
E51: Quarter Ending | G51: [$] | H51: [$] | I51: [$] | J51: [$] | M51: Case 2
E52: =$H$40 -> 43555 | G52: 679388 | H52: 812279 | I52: 629617 | J52: 722459 | M52: Case 3
E53: =EOMONTH(E52,3) -> 43646 | G53: 672030 | H53: 706344 | I53: 803471 | J53: 685565 | M53: Case 4
E54: =EOMONTH(E53,3) -> 43738 | G54: 665707 | H54: 770727 | I54: 676023 | J54: 715368
E55: =EOMONTH(E54,3) -> 43830 | G55: 663538 | H55: 789594 | I55: 727805 | J55: 696176
E56: =EOMONTH(E55,3) -> 43921 | G56: 664533 | H56: 821382 | I56: 728123 | J56: 691312
E57: =EOMONTH(E56,3) -> 44012 | G57: 650141 | H57: 713913 | I57: 691525 | J57: 708600
E58: =EOMONTH(E57,3) -> 44104 | G58: 649560 | H58: 673308 | I58: 595978 | J58: 677140
E59: =EOMONTH(E58,3) -> 44196 | G59: 645058 | H59: 677950 | I59: 616922 | J59: 702624
...

Sheet Case1Solution
A1: Blackrat SPV Pty Ltd
A3: 2 | C3: Solution
C9: Date | F9: =Case1Data!H39 -> 43465 | G9: =EOMONTH(F9,3) -> 43555 | H9: =EOMONTH(G9,3) -> 43646 | I9: =EOMONTH(H9,3) -> 43738 | J9: =EOMONTH(I9,3) -> 43830 | K9: =EOMONTH(J9,3) -> 43921 | L9: =EOMONTH(K9,3) -> 44012 | M9: =EOMONTH(L9,3) -> 44104 | N9: =EOMONTH(M9,3) -> 44196 | ... AT9: =EOMONTH(AS9,3) -> 47118
C10: Quarter | G10: =F10+1 -> 1 | H10: =G10+1 -> 2 | I10: =H10+1 -> 3 | J10: =I10+1 -> 4 | K10: =J10+1 -> 5 | L10: =K10+1 -> 6 | M10: =L10+1 -> 7 | N10: =M10+1 -> 8 | ... AT10: =AS10+1 -> 40
A12: =MAX(A$2:A11)+0.01 -> 2.01 | C12: Answers
C14: a) | D14: Schedules | E14: See below
C15: b) | D15: Scenarios | E15: See below
C16: c) | D16: Neutral / Base Case Sr. Debt Repaid | E16: =P24 -> 46477
C17: d) | D17: Total Jr. Facility Interest | E17: =SUM(G91:AT91) -> 2152500
C18: e) | D18: Aggressive / Case 2, Equity Distribution in Mar 2020 | E18: =$Q$32 -> 94488.176
C19: f) | D19: Situation with Highest IRR | E19: =G23&" / "&F25 -> Passive / Case 2
C20: g) | D20: Situation with Lowest NPV | E20: =I30&" / "&F31 -> Aggressive / Base Case
D22: IRR Sensitivity | G22: Sculpting and interest rate scenarios | K22: Sr. Debt Repayment Date | O22: Sculpting and interest rate scenarios
F23: =E111 -> 0.16166523 | G23: =Case1Data!$G$17 -> Passive | H23: =Case1Data!$H$17 -> Neutral | I23: =Case1Data!$I$17 -> Aggressive | N23: =E56 -> 46022 | O23: =Case1Data!$G$17 -> Passive | P23: =Case1Data!$H$17 -> Neutral | Q23: =Case1Data!$I$17 -> Aggressive
E24: EBITDA | F24: =Case1Data!$G$50 -> Base Case | G24: 0.11439549 | H24: 0.101513 | I24: 0.093689504 | M24: EBITDA | N24: =Case1Data!$G$50 -> Base Case | O24: 46752 | P24: 46477 | Q24: 46295
E25: Profiles | F25: =Case1Data!$H$50 -> Case 2 | G25: 0.18833821 | H25: 0.17128327 | I25: 0.16166523 | M25: Profiles | N25: =Case1Data!$H$50 -> Case 2 | O25: 46387 | P25: 46112 | Q25: 46022
F26: =Case1Data!$I$50 -> Case 3 | G26: 0.12684518 | H26: 0.11314749 | I26: 0.10482313 | N26: =Case1Data!$I$50 -> Case 3 | O26: 46660 | P26: 46387 | Q26: 46295
F27: =Case1Data!$J$50 -> Case 4 | G27: 0.14833984 | H27: 0.13353439 | I27: 0.12480724 | N27: =Case1Data!$J$50 -> Case 4 | O27: 46568 | P27: 46295 | Q27: 46203
D29: NPV Sensitivity | G29: Sculpting and interest rate scenarios | K29: Mar 2020 Equity Distribution | O29: Sculpting and interest rate scenarios
F30: =$E$112 -> 1979546.5 | G30: =Case1Data!$G$17 -> Passive | H30: =Case1Data!$H$17 -> Neutral | I30: =Case1Data!$I$17 -> Aggressive | N30: =K104 -> 94488.176 | O30: =Case1Data!$G$17 -> Passive | P30: =Case1Data!$H$17 -> Neutral | Q30: =Case1Data!$I$17 -> Aggressive
E31: EBITDA | F31: =Case1Data!$G$50 -> Base Case | G31: 456463.88 | H31: 169615.06 | I31: -35704.706 | M31: EBITDA | N31: =Case1Data!$G$50 -> Base Case | O31: 88704 | P31: 51681.333 | Q31: 29903.294
E32: Profiles | F32: =Case1Data!$H$50 -> Case 2 | G32: 2430210.2 | H32: 2169637.1 | I32: 1979546.5 | M32: Profiles | N32: =Case1Data!$H$50 -> Case 2 | O32: 167128.5 | P32: 121392 | Q32: 94488.176
F33: =Case1Data!$I$50 -> Case 3 | G33: 756919.36 | H33: 476045 | I33: 269899.44 | N33: =Case1Data!$I$50 -> Case 3 | O33: 120499 | P33: 79943.556 | Q33: 56087.412
F34: =Case1Data!$J$50 -> Case 4 | G34: 1325222.5 | H34: 1050944.8 | I34: 849944.61 | N34: =Case1Data!$J$50 -> Case 4 | O34: 102093.5 | P34: 63583.111 | Q34: 40929.941
A36: =MAX(A$2:A35)+0.01 -> 2.02 | C36: Scenarios
C38: Sculpting and interest rate scenarios
D39: Selected Case | E39: Aggressive
D40: Sculpted senior DSCR | E40: =INDEX(Case1Data!$G$18:$I$18,MATCH(E$39,Case1Data!$G$17:$I$17,0)) -> 1.7
D41: Annual interest rate | E41: =INDEX(Case1Data!$G$19:$I$19,MATCH(E$39,Case1Data!$G$17:$I$17,0)) -> 0.055
C43: EBITDA Profiles ($)
D44: Selected Case | E44: Case 2
D45: EBITDA | G45: =INDEX(Case1Data!$G$52:$J$91,MATCH(G$9,Case1Data!$E$52:$E$91,0),MATCH($E44,Case1Data!$G$50:$J$50,0)) -> 812279 | H45: =INDEX(Case1Data!$G$52:$J$91,MATCH(H$9,Case1Data!$E$52:$E$91,0),MATCH($E44,Case1Data!$G$50:$J$50,0)) -> 706344 | I45: =INDEX(Case1Data!$G$52:$J$91,MATCH(I$9,Case1Data!$E$52:$E$91,0),MATCH($E44,Case1Data!$G$50:$J$50,0)) -> 770727 | J45: =INDEX(Case1Data!$G$52:$J$91,MATCH(J$9,Case1Data!$E$52:$E$91,0),MATCH($E44,Case1Data!$G$50:$J$50,0)) -> 789594 | K45: =INDEX(Case1Data!$G$52:$J$91,MATCH(K$9,Case1Data!$E$52:$E$91,0),MATCH($E44,Case1Data!$G$50:$J$50,0)) -> 821382 | L45: =INDEX(Case1Data!$G$52:$J$91,MATCH(L$9,Case1Data!$E$52:$E$91,0),MATCH($E44,Case1Data!$G$50:$J$50,0)) -> 713913 | M45: =INDEX(Case1Data!$G$52:$J$91,MATCH(M$9,Case1Data!$E$52:$E$91,0),MATCH($E44,Case1Data!$G$50:$J$50,0)) -> 673308 | N45: =INDEX(Case1Data!$G$52:$J$91,MATCH(N$9,Case1Data!$E$52:$E$91,0),MATCH($E44,Case1Data!$G$50:$J$50,0)) -> 677950 | ... AT45: =INDEX(Case1Data!$G$52:$J$91,MATCH(AT$9,Case1Data!$E$52:$E$91,0),MATCH($E44,Case1Data!$G$50:$J$50,0)) -> 800839
A47: =MAX(A$2:A46)+0.01 -> 2.03 | C47: Senior Facility
C49: Opening Balance | G49: =F51 -> 10000000 | H49: =G51 -> 9658585.9 | I49: =H51 -> 9374792 | J49: =I51 -> 9049223.7 | K49: =J51 -> 8708080.5 | L49: =K51 -> 8343547.8 | M49: =L51 -> 8037219.8 | N49: =M51 -> 7750565.1 | ... AT49: =AS51 -> 0
C50: Issuance / (Repayment) | G50: =-MIN(G49,G68) -> -341414.12 | H50: =-MIN(H49,H68) -> -283793.86 | I50: =-MIN(I49,I68) -> -325568.37 | J50: =-MIN(J49,J68) -> -341143.17 | K50: =-MIN(K49,K68) -> -364532.72 | L50: =-MIN(L49,L68) -> -306327.98 | M50: =-MIN(M49,M68) -> -286654.7 | N50: =-MIN(N49,N68) -> -293326.79 | ... AT50: =-MIN(AT49,AT68) -> 0
C51: Closing Balance | F51: =Case1Data!H13 -> 10000000 | G51: =SUM(G49:G50) -> 9658585.9 | H51: =SUM(H49:H50) -> 9374792 | I51: =SUM(I49:I50) -> 9049223.7 | J51: =SUM(J49:J50) -> 8708080.5 | K51: =SUM(K49:K50) -> 8343547.8 | L51: =SUM(L49:L50) -> 8037219.8 | M51: =SUM(M49:M50) -> 7750565.1 | N51: =SUM(N49:N50) -> 7457238.3 | ... AT51: =SUM(AT49:AT50) -> 0
C53: Interest Rate | E53: =E41 -> 0.055 | G53: =$E53 -> 0.055 | H53: =$E53 -> 0.055 | I53: =$E53 -> 0.055 | J53: =$E53 -> 0.055 | K53: =$E53 -> 0.055 | L53: =$E53 -> 0.055 | M53: =$E53 -> 0.055 | N53: =$E53 -> 0.055 | ... AT53: =$E53 -> 0.055
C54: Interest Expense | G54: =G49*G53/4 -> 137500 | H54: =H49*H53/4 -> 132805.56 | I54: =I49*I53/4 -> 128903.39 | J54: =J49*J53/4 -> 124426.83 | K54: =K49*K53/4 -> 119736.11 | L54: =L49*L53/4 -> 114723.78 | M54: =M49*M53/4 -> 110511.77 | N54: =N49*N53/4 -> 106570.27 | ... AT54: =AT49*AT53/4 -> 0
C56: Repayment Period | E56: =INDEX(F9:AT9,MATCH(0,F51:AT51,0)) -> 46022
A58: =MAX(A$2:A57)+0.01 -> 2.04 | C58: DSCR
...
