Workbook
Name company: CaseData!$D$133
Name ebidta_profiles: _xlfn.ANCHORARRAY(CaseData!$D$137)
Name ebidta_selector: Debt!$H$3
Name periods: CaseData!$G$32
Name start_date: CaseData!$G$30
Name topic: "CFM Topic: " & CaseData!$D$134

Sheet Debt
A1: {=company} -> Black Rat SPV 2
A2: {=topic} -> CFM Topic: Debt | H2: EBIDTA Profile | J2: {=_xlfn.ANCHORARRAY($J$137)} -> 43466 | K2: 43556 | L2: 43647 | M2: 43739 | N2: 43831 | O2: 43922 | P2: 44013 | Q2: 44105 | R2: 44197 | S2: 44287 | T2: 44378 | U2: 44470 | V2: 44562 | W2: 44652 | X2: 44743 | Y2: 44835 | Z2: 44927 | AA2: 45017 | AB2: 45108 | AC2: 45200 | AD2: 45292 | AE2: 45383 | AF2: 45474 | AG2: 45566 | AH2: 45658 | AI2: 45748 | AJ2: 45839 | AK2: 45931 | AL2: 46023 | AM2: 46113 | AN2: 46204 | AO2: 46296 | AP2: 46388 | AQ2: 46478 | AR2: 46569 | AS2: 46661 | AT2: 46753 | AU2: 46844 | AV2: 46935 | AW2: 47027
A3: DEBT SCHEDULE | F3: Constant | G3: Unit | H3: 6 | J3: {=_xlfn.ANCHORARRAY( $J$138)} -> 43555 | K3: 43646 | L3: 43738 | M3: 43830 | N3: 43921 | O3: 44012 | P3: 44104 | Q3: 44196 | R3: 44286 | S3: 44377 | T3: 44469 | U3: 44561 | V3: 44651 | W3: 44742 | X3: 44834 | Y3: 44926 | Z3: 45016 | AA3: 45107 | AB3: 45199 | AC3: 45291 | AD3: 45382 | AE3: 45473 | AF3: 45565 | AG3: 45657 | AH3: 45747 | AI3: 45838 | AJ3: 45930 | AK3: 46022 | AL3: 46112 | AM3: 46203 | AN3: 46295 | AO3: 46387 | AP3: 46477 | AQ3: 46568 | AR3: 46660 | AS3: 46752 | AT3: 46843 | AU3: 46934 | AV3: 47026 | AW3: 47118
A5: Cash flow
E8: EBIDTA | G8: USD | J8: {=INDEX( CaseData!$F$89:$K$128, MATCH(_xlfn.ANCHORARRAY( Debt!J3), CaseData!$D$89:$D$128, 0 ), MATCH( ebidta_selector, CaseData!$F$86:$K$86, 0 ) )} -> 602417 | K8: 595476 | L8: 593198 | M8: 606599 | N8: 631767 | O8: 610527 | P8: 585598 | Q8: 637572 | R8: 646990 | S8: 675583 | T8: 584611 | U8: 218154 | V8: 227447 | W8: 265153 | X8: 259078 | Y8: 604305 | Z8: 574768 | AA8: 641271 | AB8: 640757 | AC8: 633725 | AD8: 576167 | AE8: 581131 | AF8: 709982 | AG8: 602019 | AH8: 675479 | AI8: 669801 | AJ8: 709031 | AK8: 693006 | AL8: 717913 | AM8: 628697 | AN8: 657781 | AO8: 700979 | AP8: 638273 | AQ8: 652849 | AR8: 724981 | AS8: 637701 | AT8: 745903 | AU8: 750208 | AV8: 740965 | AW8: 750009
E9: =E$65 -> Debt Service Reserve Account interest income | G9: =G$65 -> USD | I9: =I$65 -> 0 | J9: =J$65 -> 1875 | K9: =K$65 -> 2721.7971 | L9: =L$65 -> 3561.0701 | M9: =M$65 -> 4408.1208 | N9: =N$65 -> 5313.1204 | O9: =O$65 -> 6313.8208 | P9: =P$65 -> 1875 | ... AW9: =AW$65 -> 1875
E10: Funds available for Debt repayment | G10: USD | J10: =SUM(J8:J9) -> 604292 | K10: =SUM(K8:K9) -> 598197.8 | L10: =SUM(L8:L9) -> 596759.07 | M10: =SUM(M8:M9) -> 611007.12 | N10: =SUM(N8:N9) -> 637080.12 | O10: =SUM(O8:O9) -> 616840.82 | P10: =SUM(P8:P9) -> 587473 | Q10: =SUM(Q8:Q9) -> 639447 | ... AW10: =SUM(AW8:AW9) -> 751884
E12: =E$80 -> Senior Debt interest expenses | G12: =G$80 -> USD | I12: =I$80 -> 0 | J12: =J$80 * - 1 -> -125000 | K12: =K$80 * - 1 -> -121831.51 | L12: =L$80 * - 1 -> -118674.5 | M12: =M$80 * - 1 -> -115521.95 | N12: =N$80 * - 1 -> -112345.05 | O12: =O$80 * - 1 -> -109121.53 | P12: =P$80 * - 1 -> -105957.66 | Q12: =Q$80 * - 1 -> -102758.28 | ... AW12: =AW$80 * - 1 -> 0
E13: =E$73 -> Senior Debt principal addition / (repayment) | G13: =G$73 -> USD | I13: =I$73 -> 0 | J13: =J$73 -> -253479.44 | K13: =K$73 -> -252560.16 | L13: =L$73 -> -252204.38 | M13: =M$73 -> -254151.94 | N13: =N$73 -> -257881.62 | O13: =O$73 -> -253109.58 | P13: =P$73 -> -255950.67 | ... AW13: =AW$73 -> 0
E14: Funds available after Senior Debt service | G14: USD | J14: =SUM(J10:J13) -> 225812.56 | K14: =SUM(K10:K13) -> 223806.13 | L14: =SUM(L10:L13) -> 225880.18 | M14: =SUM(M10:M13) -> 241333.23 | N14: =SUM(N10:N13) -> 266853.45 | O14: =SUM(O10:O13) -> 254609.71 | P14: =SUM(P10:P13) -> 225564.67 | Q14: =SUM(Q10:Q13) -> 280039.78 | ... AW14: =SUM(AW10:AW13) -> 751884
E16: Withdrawal from DSRA to cover for Senior Debt repayment shortfall | G16: USD | J16: =- MIN( J14, 0 ) -> 0 | K16: =- MIN( K14, 0 ) -> 0 | L16: =- MIN( L14, 0 ) -> 0 | M16: =- MIN( M14, 0 ) -> 0 | N16: =- MIN( N14, 0 ) -> 0 | O16: =- MIN( O14, 0 ) -> 0 | P16: =- MIN( P14, 0 ) -> 0 | Q16: =- MIN( Q14, 0 ) -> 0 | ... AW16: =- MIN( AW14, 0 ) -> 0
E17: Top Up of DSRA to keep required minimum balance | G17: USD | J17: =- MAX( MIN( J14, $F$51 - SUM( J54:J55 ) ), 0 ) -> 0 | K17: =- MAX( MIN( K14, $F$51 - SUM( K54:K55 ) ), 0 ) -> 0 | L17: =- MAX( MIN( L14, $F$51 - SUM( L54:L55 ) ), 0 ) -> 0 | M17: =- MAX( MIN( M14, $F$51 - SUM( M54:M55 ) ), 0 ) -> 0 | N17: =- MAX( MIN( N14, $F$51 - SUM( N54:N55 ) ), 0 ) -> 0 | O17: =- MAX( MIN( O14, $F$51 - SUM( O54:O55 ) ), 0 ) -> 0 | P17: =- MAX( MIN( P14, $F$51 - SUM( P54:P55 ) ), 0 ) -> 0 | Q17: =- MAX( MIN( Q14, $F$51 - SUM( Q54:Q55 ) ), 0 ) -> 0 | ... AW17: =- MAX( MIN( AW14, $F$51 - SUM( AW54:AW55 ) ), 0 ) -> 0
E18: DSRA Additions in Lockup | G18: USD | J18: =IF( J$45 = 1, -SUM( J14:J17 ), 0 ) -> -225812.56 | K18: =IF( K$45 = 1, -SUM( K14:K17 ), 0 ) -> -223806.13 | L18: =IF( L$45 = 1, -SUM( L14:L17 ), 0 ) -> -225880.18 | M18: =IF( M$45 = 1, -SUM( M14:M17 ), 0 ) -> -241333.23 | N18: =IF( N$45 = 1, -SUM( N14:N17 ), 0 ) -> -266853.45 | O18: =IF( O$45 = 1, -SUM( O14:O17 ), 0 ) -> 0 | P18: =IF( P$45 = 1, -SUM( P14:P17 ), 0 ) -> 0 | Q18: =IF( Q$45 = 1, -SUM( Q14:Q17 ), 0 ) -> 0 | ... AW18: =IF( AW$45 = 1, -SUM( AW14:AW17 ), 0 ) -> 0
E19: =E$58 -> Release from DSRA | G19: =G$58 -> USD | J19: =J$58 * - 1 -> 0 | K19: =K$58 * - 1 -> 0 | L19: =L$58 * - 1 -> 0 | M19: =M$58 * - 1 -> 0 | N19: =N$58 * - 1 -> 0 | O19: =O$58 * - 1 -> 1183685.6 | P19: =P$58 * - 1 -> 0 | Q19: =Q$58 * - 1 -> 0 | ... AW19: =AW$58 * - 1 -> 0
E20: Funds available for Junior Debt service | G20: USD | J20: =SUM(J14:J19) -> 0 | K20: =SUM(K14:K19) -> 0 | L20: =SUM(L14:L19) -> 0 | M20: =SUM(M14:M19) -> 0 | N20: =SUM(N14:N19) -> 0 | O20: =SUM(O14:O19) -> 1438295.3 | P20: =SUM(P14:P19) -> 225564.67 | Q20: =SUM(Q14:Q19) -> 280039.78 | ... AW20: =SUM(AW14:AW19) -> 751884
E22: =E$101 -> Junior Debt interest paid | G22: USD | J22: =J$101 * - 1 -> 0 | K22: =K$101 * - 1 -> 0 | L22: =L$101 * - 1 -> 0 | M22: =M$101 * - 1 -> 0 | N22: =N$101 * - 1 -> 0 | O22: =O$101 * - 1 -> -114514.74 | P22: =P$101 * - 1 -> -91348.58 | Q22: =Q$101 * - 1 -> -88999.799 | ... AW22: =AW$101 * - 1 -> -2625
E23: Funds Available for Junior Debt Scheduled Repayments | G23: USD | J23: =SUM(J20:J22) -> 0 | K23: =SUM(K20:K22) -> 0 | L23: =SUM(L20:L22) -> 0 | M23: =SUM(M20:M22) -> 0 | N23: =SUM(N20:N22) -> 0 | O23: =SUM(O20:O22) -> 1323780.5 | P23: =SUM(P20:P22) -> 134216.09 | Q23: =SUM(Q20:Q22) -> 191039.98 | ... AW23: =SUM(AW20:AW22) -> 749259
E25: =E$106 -> Junior Debt Scheduled Repayment Paid | G25: =G$106 -> USD | I25: =I$106 -> 0 | J25: =J$106 * - 1 -> 0 | K25: =K$106 * - 1 -> 0 | L25: =L$106 * - 1 -> 0 | M25: =M$106 * - 1 -> 0 | N25: =N$106 * - 1 -> 0 | O25: =O$106 * - 1 -> -150000 | P25: =P$106 * - 1 -> -134216.09 | Q25: =Q$106 * - 1 -> -150000 | ... AW25: =AW$106 * - 1 -> -150000
E26: Funds Available for Junior Debt Arrears Amount Owed | G26: =G$106 -> USD | J26: =SUM(J23:J25) -> 0 | K26: =SUM(K23:K25) -> 0 | L26: =SUM(L23:L25) -> 0 | M26: =SUM(M23:M25) -> 0 | N26: =SUM(N23:N25) -> 0 | O26: =SUM(O23:O25) -> 1173780.5 | P26: =SUM(P23:P25) -> 0 | Q26: =SUM(Q23:Q25) -> 41039.979 | ... AW26: =SUM(AW23:AW25) -> 599259
E28: =E$116 -> Repayment of arrears owed | G28: =G$116 -> USD | I28: =I$116 -> 0 | J28: =J$116 -> 0 | K28: =K$116 -> 0 | L28: =L$116 -> 0 | M28: =M$116 -> 0 | N28: =N$116 -> 0 | O28: =O$116 -> -1173780.5 | P28: =P$116 -> 0 | ... AW28: =AW$116 -> 0
E29: Funds distributed to Equity | G29: USD | J29: =SUM(J26:J28) -> 0 | K29: =SUM(K26:K28) -> 0 | L29: =SUM(L26:L28) -> 0 | M29: =SUM(M26:M28) -> 0 | N29: =SUM(N26:N28) -> 0 | O29: =SUM(O26:O28) -> 0 | P29: =SUM(P26:P28) -> 0 | Q29: =SUM(Q26:Q28) -> 0 | ... AW29: =SUM(AW26:AW28) -> 599259
A34: DSCR (Last Twelve Months)
E36: Senior DSCR Lock up trigger | F36: =CaseData!$G$7 -> 1.62 | G36: factor
E38: EBIDTA | G38: USD | J38: =J8 -> 602417 | K38: =SUM(J8:K8) -> 1197893 | L38: =SUM( J8:L8) -> 1791091 | M38: =SUM( J8:M8) -> 2397690 | N38: =SUM( K8:N8) -> 2427040 | O38: =SUM( L8:O8) -> 2442091 | P38: =SUM( M8:P8) -> 2434491 | Q38: =SUM( N8:Q8) -> 2465464 | R38: =SUM( O8:R8) -> 2480687 | S38: =SUM( P8:S8) -> 2545743 | T38: =SUM( Q8:T8) -> 2544756 | ... AW38: =SUM( AT8:AW8) -> 2987085
E39: =E$65 -> Debt Service Reserve Account interest income | G39: =G$65 -> USD | I39: =I$65 -> 0 | J39: =J65 -> 1875 | K39: =SUM( J65:K65) -> 4596.7971 | L39: =SUM( J65:L65) -> 8157.8672 | M39: =SUM( J65:M65) -> 12565.988 | N39: =SUM( K65:N65) -> 16004.108 | O39: =SUM( L65:O65) -> 19596.132 | P39: =SUM( M65:P65) -> 17910.062 | Q39: =SUM( N65:Q65) -> 15376.941 | R39: =SUM( O65:R65) -> 11938.821 | S39: =SUM( P65:S65) -> 7500 | T39: =SUM( Q65:T65) -> 7500 | ... AW39: =SUM( AT65:AW65) -> 7500
E40: =E$80 -> Senior Debt interest expenses | G40: =G$80 -> USD | I40: =I$80 -> 0 | J40: =J80 * - 1 -> -125000 | K40: =SUM( J80:K80 ) * - 1 -> -246831.51 | L40: =SUM( J80:L80 ) * - 1 -> -365506.01 | M40: =SUM( J80:M80 ) * - 1 -> -481027.96 | N40: =SUM( K80:N80 ) * - 1 -> -468373.01 | O40: =SUM( L80:O80 ) * - 1 -> -455663.04 | P40: =SUM( M80:P80 ) * - 1 -> -442946.19 | Q40: =SUM( N80:Q80 ) * - 1 -> -430182.52 | R40: =SUM( O80:R80 ) * - 1 -> -417387.63 | S40: =SUM( P80:S80 ) * - 1 -> -404346.95 | T40: =SUM( Q80:T80 ) * - 1 -> -391197.77 | ... AW40: =SUM( AT80:AW80 ) * - 1 -> 0
E41: =E$73 -> Senior Debt principal addition / (repayment) | G41: =G$73 -> USD | I41: =I$73 -> 0 | J41: =J$73 -> -253479.44 | K41: =SUM( J73:K73) -> -506039.6 | L41: =SUM( J73:L73) -> -758243.99 | M41: =SUM( J73:M73) -> -1012395.9 | N41: =SUM( K73:N73) -> -1016798.1 | O41: =SUM( L73:O73) -> -1017347.5 | P41: =SUM( M73:P73) -> -1021093.8 | Q41: =SUM( N73:Q73) -> -1023590.8 | R41: =SUM( O73:R73) -> -1043255.1 | S41: =SUM( P73:S73) -> -1051934.2 | T41: =SUM( Q73:T73) -> -1066850.6 | ... AW41: =SUM( AT73:AW73) -> 0
E43: DSCR LTM | G43: factor | J43: =IFERROR(SUM(J38,J39)/-SUM(J40,J41),"n/a") -> 1.596631 | K43: =IFERROR(SUM(K38,K39)/-SUM(K40,K41),"n/a") -> 1.5972054 | L43: =IFERROR(SUM(L38,L39)/-SUM(L40,L41),"n/a") -> 1.6011113 | M43: =IFERROR(SUM(M38,M39)/-SUM(M40,M41),"n/a") -> 1.6139128 | N43: =IFERROR(SUM(N38,N39)/-SUM(N40,N41),"n/a") -> 1.644958 | O43: =IFERROR(SUM(O38,O39)/-SUM(O40,O41),"n/a") -> 1.6711945 | P43: =IFERROR(SUM(P38,P39)/-SUM(P40,P41),"n/a") -> 1.6750916 | Q43: =IFERROR(SUM(Q38,Q39)/-SUM(Q40,Q41),"n/a") -> 1.706484 | ... AW43: =IFERROR(SUM(AW38,AW39)/-SUM(AW40,AW41),"n/a") -> n/a
E44: Lock up trigger flag | G44: flag | J44: =IF( J$43 < $F$36, 1, 0 ) -> 1 | K44: =IF( K$43 < $F$36, 1, 0 ) -> 1 | L44: =IF( L$43 < $F$36, 1, 0 ) -> 1 | M44: =IF( M$43 < $F$36, 1, 0 ) -> 1 | N44: =IF( N$43 < $F$36, 1, 0 ) -> 0 | O44: =IF( O$43 < $F$36, 1, 0 ) -> 0 | P44: =IF( P$43 < $F$36, 1, 0 ) -> 0 | Q44: =IF( Q$43 < $F$36, 1, 0 ) -> 0 | ... AW44: =IF( AW$43 < $F$36, 1, 0 ) -> 0
E45: Release trigger | G45: flag | J45: =MAX(I44:J44) -> 1 | K45: =MAX(J44:K44) -> 1 | L45: =MAX(K44:L44) -> 1 | M45: =MAX(L44:M44) -> 1 | N45: =MAX(M44:N44) -> 1 | O45: =MAX(N44:O44) -> 0 | P45: =MAX(O44:P44) -> 0 | Q45: =MAX(P44:Q44) -> 0 | ... AW45: =MAX(AV44:AW44) -> 0
A48: Debt Service Reserve Account
E50: Debt Service Reserve Account Debt balance at model start | F50: =CaseData!G$14 -> 500000 | G50: USD
E51: Required minimum balance during term of Senior Facility | F51: =CaseData!$G$15 -> 500000 | G51: USD
E54: Debt Service Reserve Account Debt opening balance | G54: USD | J54: =I$59 -> 500000 | K54: =J$59 -> 725812.56 | L54: =K$59 -> 949618.69 | M54: =L$59 -> 1175498.9 | N54: =M$59 -> 1416832.1 | O54: =N$59 -> 1683685.6 | P54: =O$59 -> 500000 | Q54: =P$59 -> 500000 | ... AW54: =AV$59 -> 500000
E55: =E$16 -> Withdrawal from DSRA to cover for Senior Debt repayment shortfall | G55: =G$16 -> USD | I55: =I$16 -> 0 | J55: =J$16 * - 1 -> 0 | K55: =K$16 * - 1 -> 0 | L55: =L$16 * - 1 -> 0 | M55: =M$16 * - 1 -> 0 | N55: =N$16 * - 1 -> 0 | O55: =O$16 * - 1 -> 0 | P55: =P$16 * - 1 -> 0 | Q55: =Q$16 * - 1 -> 0 | ... AW55: =AW$16 * - 1 -> 0
E56: Top Up of DSRA to keep required minimum balance | G56: USD | J56: =-J17 -> 0 | K56: =-K17 -> 0 | L56: =-L17 -> 0 | M56: =-M17 -> 0 | N56: =-N17 -> 0 | O56: =-O17 -> 0 | P56: =-P17 -> 0 | Q56: =-Q17 -> 0 | ... AW56: =-AW17 -> 0
E57: =E$18 -> DSRA Additions in Lockup | G57: =G$18 -> USD | I57: =I$18 -> 0 | J57: =J$18 * - 1 -> 225812.56 | K57: =K$18 * - 1 -> 223806.13 | L57: =L$18 * - 1 -> 225880.18 | M57: =M$18 * - 1 -> 241333.23 | N57: =N$18 * - 1 -> 266853.45 | O57: =O$18 * - 1 -> 0 | P57: =P$18 * - 1 -> 0 | Q57: =Q$18 * - 1 -> 0 | ... AW57: =AW$18 * - 1 -> 0
E58: Release from DSRA | G58: USD | J58: =IF( J$45 = 0, $F$51 - SUM( J54:J57 ), 0 ) -> 0 | K58: =IF( K$45 = 0, $F$51 - SUM( K54:K57 ), 0 ) -> 0 | L58: =IF( L$45 = 0, $F$51 - SUM( L54:L57 ), 0 ) -> 0 | M58: =IF( M$45 = 0, $F$51 - SUM( M54:M57 ), 0 ) -> 0 | N58: =IF( N$45 = 0, $F$51 - SUM( N54:N57 ), 0 ) -> 0 | O58: =IF( O$45 = 0, $F$51 - SUM( O54:O57 ), 0 ) -> -1183685.6 | P58: =IF( P$45 = 0, $F$51 - SUM( P54:P57 ), 0 ) -> 0 | Q58: =IF( Q$45 = 0, $F$51 - SUM( Q54:Q57 ), 0 ) -> 0 | ... AW58: =IF( AW$45 = 0, $F$51 - SUM( AW54:AW57 ), 0 ) -> 0
E59: Debt Service Reserve Account Debt | G59: USD | I59: =$F$50 -> 500000 | J59: =SUM(J54:J58) -> 725812.56 | K59: =SUM(K54:K58) -> 949618.69 | L59: =SUM(L54:L58) -> 1175498.9 | M59: =SUM(M54:M58) -> 1416832.1 | N59: =SUM(N54:N58) -> 1683685.6 | O59: =SUM(O54:O58) -> 500000 | P59: =SUM(P54:P58) -> 500000 | Q59: =SUM(Q54:Q58) -> 500000 | ... AW59: =SUM(AW54:AW58) -> 500000
D62: Debt Service Reserve Account interest income
...

Sheet CaseData
A1: Assumptions
B3: Senior Facility
C4: Facility Balance at model start date | E4: [$] | G4: 10000000
C5: Annual cash interest rate | E5: [% p.a.] | G5: 0.05 | K5: Scenario
K6: Toggle for EBITDA values
C7: Senior DSCR Lock up trigger | E7: [x] | G7: 1.62
C8: Look-back quarters for DSCR incl. current quarter (Last Twelve Months) | E8: [#] | G8: 4 | H8: Do not change | K8: DSCR
C10: To get out of lock-up: | J10: LTM | K10: EBITDA + Interest Income / Senior Debt Costs
C11: Number of quarters required for Sr DSCR to be greater than lock-up trigger: | E11: [# qtrs] | G11: 2 | H11: Do not change
B13: Debt Service Reserve Account
C14: Initial balance at project start (already funded) | G14: 500000
C15: Required minimum balance during term of Senior Facility | G15: 500000
C16: Cash interest rate earned on account balance | E16: [% p.a.] | G16: 0.015
J17: =PMT((G5/4),33,G4,0,0) -> -371678.65
B18: Junior Facility
C19: Facility Balance at model start date | E19: [$] | G19: 6000000
C20: Annual cash interest rate | E20: [% p.a.] | G20: 0.07 | H20: =G19/G21 -> 150000
C21: Amortisation Quarters | E21: [#] | G21: 40
C22: Scheduled final payment date | E22: [date] | G22: =EOMONTH(G30,3*G21) -> 47118
B24: Equity
C25: Contribution amount at model start date | E25: [$] | G25: 4000000
C26: Discount rate for Net Present Value Calculations | E26: [% p.a.] | G26: 0.095
B29: Other Assumptions
C30: Model start date (Project start date) | E30: [date] | G30: 43465
C31: Initial quarter end date | E31: [date] | G31: =EOMONTH(G30,3) -> 43555
C32: Number of quarters in project | E32: [# qtrs] | G32: 40
C33: Final quarter end date (Project end date) | E33: [date] | G33: =EOMONTH(G30,G32*3) -> 47118
C35: Cash interest rate earned on cash account balance | E35: [% p.a.] | G35: 0.015
B38: Schedule Debt Repayments | G38: Senior Debt | J38: Junior Debt
G39: Scheduled Snr | H39: Scheduled Snr | J39: Scheduled Jnr | K39: Scheduled Jnr
G40: Principal | H40: Closing Balance | J40: Principal | K40: Closing Balance
D41: Quarter Ending | G41: [$] | H41: [$] | J41: [$] | K41: [$]
D42: =$G$31 -> 43555 | G42: -253479.44 | H42: =G4+G42 -> 9746520.6 | J42: -150000 | K42: =G19+J42 -> 5850000
D43: =EOMONTH(D42,3) -> 43646 | G43: -252560.16 | H43: =H42+G43 -> 9493960.4 | J43: -150000 | K43: =K42+J43 -> 5700000
D44: =EOMONTH(D43,3) -> 43738 | G44: -252204.38 | H44: =H43+G44 -> 9241756 | J44: -150000 | K44: =K43+J44 -> 5550000
D45: =EOMONTH(D44,3) -> 43830 | G45: -254151.94 | H45: =H44+G45 -> 8987604.1 | J45: -150000 | K45: =K44+J45 -> 5400000
D46: =EOMONTH(D45,3) -> 43921 | G46: -257881.62 | H46: =H45+G46 -> 8729722.5 | J46: -150000 | K46: =K45+J46 -> 5250000
D47: =EOMONTH(D46,3) -> 44012 | G47: -253109.58 | H47: =H46+G47 -> 8476612.9 | J47: -150000 | K47: =K46+J47 -> 5100000
D48: =EOMONTH(D47,3) -> 44104 | G48: -255950.67 | H48: =H47+G48 -> 8220662.2 | J48: -150000 | K48: =K47+J48 -> 4950000
D49: =EOMONTH(D48,3) -> 44196 | G49: -256648.94 | H49: =H48+G49 -> 7964013.3 | J49: -150000 | K49: =K48+J49 -> 4800000
...

Sheet CaseSolution
B2: Period Start | J2: =I3+1 -> 43466 | K2: =J3+1 -> 43556 | L2: =K3+1 -> 43647 | M2: =L3+1 -> 43739 | N2: =M3+1 -> 43831 | O2: =N3+1 -> 43922 | P2: =O3+1 -> 44013 | Q2: =P3+1 -> 44105 | ... AW2: =AV3+1 -> 47027
B3: Period End | I3: =CaseData!G30 -> 43465 | J3: =EOMONTH(I3,3) -> 43555 | K3: =EOMONTH(J3,3) -> 43646 | L3: =EOMONTH(K3,3) -> 43738 | M3: =EOMONTH(L3,3) -> 43830 | N3: =EOMONTH(M3,3) -> 43921 | O3: =EOMONTH(N3,3) -> 44012 | P3: =EOMONTH(O3,3) -> 44104 | Q3: =EOMONTH(P3,3) -> 44196 | ... AW3: =EOMONTH(AV3,3) -> 47118
B4: Model Quarter | I4: 0 | J4: =I4+1 -> 1 | K4: =J4+1 -> 2 | L4: =K4+1 -> 3 | M4: =L4+1 -> 4 | N4: =M4+1 -> 5 | O4: =N4+1 -> 6 | P4: =O4+1 -> 7 | Q4: =P4+1 -> 8 | ... AW4: =AV4+1 -> 40
B7: Cash Flow Waterfall
C9: EBITDA | H9: Case 6 | J9: =INDEX(CaseData!$F$89:$K$128,MATCH(J$3,CaseData!$D$89:$D$128,0),MATCH($H9,CaseData!$F$87:$K$87,0)) -> 602417 | K9: =INDEX(CaseData!$F$89:$K$128,MATCH(K$3,CaseData!$D$89:$D$128,0),MATCH($H9,CaseData!$F$87:$K$87,0)) -> 595476 | L9: =INDEX(CaseData!$F$89:$K$128,MATCH(L$3,CaseData!$D$89:$D$128,0),MATCH($H9,CaseData!$F$87:$K$87,0)) -> 593198 | M9: =INDEX(CaseData!$F$89:$K$128,MATCH(M$3,CaseData!$D$89:$D$128,0),MATCH($H9,CaseData!$F$87:$K$87,0)) -> 606599 | N9: =INDEX(CaseData!$F$89:$K$128,MATCH(N$3,CaseData!$D$89:$D$128,0),MATCH($H9,CaseData!$F$87:$K$87,0)) -> 631767 | O9: =INDEX(CaseData!$F$89:$K$128,MATCH(O$3,CaseData!$D$89:$D$128,0),MATCH($H9,CaseData!$F$87:$K$87,0)) -> 610527 | P9: =INDEX(CaseData!$F$89:$K$128,MATCH(P$3,CaseData!$D$89:$D$128,0),MATCH($H9,CaseData!$F$87:$K$87,0)) -> 585598 | Q9: =INDEX(CaseData!$F$89:$K$128,MATCH(Q$3,CaseData!$D$89:$D$128,0),MATCH($H9,CaseData!$F$87:$K$87,0)) -> 637572 | ... AW9: =INDEX(CaseData!$F$89:$K$128,MATCH(AW$3,CaseData!$D$89:$D$128,0),MATCH($H9,CaseData!$F$87:$K$87,0)) -> 750009
C10: Interest Income | J10: =J66 -> 1875 | K10: =K66 -> 2721.7971 | L10: =L66 -> 3561.0701 | M10: =M66 -> 4408.1208 | N10: =N66 -> 5313.1204 | O10: =O66 -> 6313.8208 | P10: =P66 -> 1875 | Q10: =Q66 -> 1875 | ... AW10: =AW66 -> 0
C11: Funds Available for Debt Service | J11: =SUM(J9:J10) -> 604292 | K11: =SUM(K9:K10) -> 598197.8 | L11: =SUM(L9:L10) -> 596759.07 | M11: =SUM(M9:M10) -> 611007.12 | N11: =SUM(N9:N10) -> 637080.12 | O11: =SUM(O9:O10) -> 616840.82 | P11: =SUM(P9:P10) -> 587473 | Q11: =SUM(Q9:Q10) -> 639447 | ... AW11: =SUM(AW9:AW10) -> 750009
C13: Sr. Debt Repayment | J13: =INDEX(CaseData!$G$42:$G$81,MATCH(J$3,CaseData!$D$42:$D$81,0)) -> -253479.44 | K13: =INDEX(CaseData!$G$42:$G$81,MATCH(K$3,CaseData!$D$42:$D$81,0)) -> -252560.16 | L13: =INDEX(CaseData!$G$42:$G$81,MATCH(L$3,CaseData!$D$42:$D$81,0)) -> -252204.38 | M13: =INDEX(CaseData!$G$42:$G$81,MATCH(M$3,CaseData!$D$42:$D$81,0)) -> -254151.94 | N13: =INDEX(CaseData!$G$42:$G$81,MATCH(N$3,CaseData!$D$42:$D$81,0)) -> -257881.62 | O13: =INDEX(CaseData!$G$42:$G$81,MATCH(O$3,CaseData!$D$42:$D$81,0)) -> -253109.58 | P13: =INDEX(CaseData!$G$42:$G$81,MATCH(P$3,CaseData!$D$42:$D$81,0)) -> -255950.67 | Q13: =INDEX(CaseData!$G$42:$G$81,MATCH(Q$3,CaseData!$D$42:$D$81,0)) -> -256648.94 | ... AW13: =INDEX(CaseData!$G$42:$G$81,MATCH(AW$3,CaseData!$D$42:$D$81,0)) -> 0
C14: Sr. Debt Interest | J14: =-J41 -> -125000 | K14: =-K41 -> -121831.51 | L14: =-L41 -> -118674.5 | M14: =-M41 -> -115521.95 | N14: =-N41 -> -112345.05 | O14: =-O41 -> -109121.53 | P14: =-P41 -> -105957.66 | Q14: =-Q41 -> -102758.28 | ... AW14: =-AW41 -> 0
C15: Sr. Debt Service | J15: =SUM(J13:J14) -> -378479.44 | K15: =SUM(K13:K14) -> -374391.67 | L15: =SUM(L13:L14) -> -370878.89 | M15: =SUM(M13:M14) -> -369673.89 | N15: =SUM(N13:N14) -> -370226.67 | O15: =SUM(O13:O14) -> -362231.11 | P15: =SUM(P13:P14) -> -361908.33 | Q15: =SUM(Q13:Q14) -> -359407.22 | ... AW15: =SUM(AW13:AW14) -> 0
C17: Funds Available / (Required) post Sr. Debt Service | J17: =SUM(J11,J15) -> 225812.56 | K17: =SUM(K11,K15) -> 223806.13 | L17: =SUM(L11,L15) -> 225880.18 | M17: =SUM(M11,M15) -> 241333.23 | N17: =SUM(N11,N15) -> 266853.45 | O17: =SUM(O11,O15) -> 254609.71 | P17: =SUM(P11,P15) -> 225564.67 | Q17: =SUM(Q11,Q15) -> 280039.78 | ... AW17: =SUM(AW11,AW15) -> 750009
C19: Withdrawl from DSRA | J19: =-MIN(J17,0) -> 0 | K19: =-MIN(K17,0) -> 0 | L19: =-MIN(L17,0) -> 0 | M19: =-MIN(M17,0) -> 0 | N19: =-MIN(N17,0) -> 0 | O19: =-MIN(O17,0) -> 0 | P19: =-MIN(P17,0) -> 0 | Q19: =-MIN(Q17,0) -> 0 | ... AW19: =-MIN(AW17,0) -> 0
C20: Top Up of DSRA | J20: =-MAX(MIN(J17,J68-SUM(J58:J59)),0) -> 0 | K20: =-MAX(MIN(K17,K68-SUM(K58:K59)),0) -> 0 | L20: =-MAX(MIN(L17,L68-SUM(L58:L59)),0) -> 0 | M20: =-MAX(MIN(M17,M68-SUM(M58:M59)),0) -> 0 | N20: =-MAX(MIN(N17,N68-SUM(N58:N59)),0) -> 0 | O20: =-MAX(MIN(O17,O68-SUM(O58:O59)),0) -> 0 | P20: =-MAX(MIN(P17,P68-SUM(P58:P59)),0) -> 0 | Q20: =-MAX(MIN(Q17,Q68-SUM(Q58:Q59)),0) -> 0 | ... AW20: =-MAX(MIN(AW17,AW68-SUM(AW58:AW59)),0) -> 0
C21: Sweep while in Lock-up | J21: =IF(J54=1,-SUM(J17:J20),0) -> -225812.56 | K21: =IF(K54=1,-SUM(K17:K20),0) -> -223806.13 | L21: =IF(L54=1,-SUM(L17:L20),0) -> -225880.18 | M21: =IF(M54=1,-SUM(M17:M20),0) -> -241333.23 | N21: =IF(N54=1,-SUM(N17:N20),0) -> -266853.45 | O21: =IF(O54=1,-SUM(O17:O20),0) -> 0 | P21: =IF(P54=1,-SUM(P17:P20),0) -> 0 | Q21: =IF(Q54=1,-SUM(Q17:Q20),0) -> 0 | ... AW21: =IF(AW54=1,-SUM(AW17:AW20),0) -> 0
C22: Release | J22: =-J62 -> 0 | K22: =-K62 -> 0 | L22: =-L62 -> 0 | M22: =-M62 -> 0 | N22: =-N62 -> 0 | O22: =-O62 -> 1183685.6 | P22: =-P62 -> 0 | Q22: =-Q62 -> 0 | ... AW22: =-AW62 -> 0
C23: Funds Available for Jr. Debt Service | J23: =SUM(J17:J22) -> 0 | K23: =SUM(K17:K22) -> 0 | L23: =SUM(L17:L22) -> 0 | M23: =SUM(M17:M22) -> 0 | N23: =SUM(N17:N22) -> 0 | O23: =SUM(O17:O22) -> 1438295.3 | P23: =SUM(P17:P22) -> 225564.67 | Q23: =SUM(Q17:Q22) -> 280039.78 | ... AW23: =SUM(AW17:AW22) -> 750009
C25: Jr. Debt Interest Paid | J25: =-J82 -> 0 | K25: =-K82 -> 0 | L25: =-L82 -> 0 | M25: =-M82 -> 0 | N25: =-N82 -> 0 | O25: =-O82 -> -114514.74 | P25: =-P82 -> -91348.58 | Q25: =-Q82 -> -88999.799 | ... AW25: =-AW82 -> -2625
C26: Funds Available for Jr. Debt - Scheduled Repayments | J26: =J23+J25 -> 0 | K26: =K23+K25 -> 0 | L26: =L23+L25 -> 0 | M26: =M23+M25 -> 0 | N26: =N23+N25 -> 0 | O26: =O23+O25 -> 1323780.5 | P26: =P23+P25 -> 134216.09 | Q26: =Q23+Q25 -> 191039.98 | ... AW26: =AW23+AW25 -> 747384
C28: Jr. Debt Repayment | J28: =-J88 -> 0 | K28: =-K88 -> 0 | L28: =-L88 -> 0 | M28: =-M88 -> 0 | N28: =-N88 -> 0 | O28: =-O88 -> -150000 | P28: =-P88 -> -134216.09 | Q28: =-Q88 -> -150000 | ... AW28: =-AW88 -> -150000
C29: Funds Available for Jr. Debt - Arrears Amount Owed | J29: =J26+J28 -> 0 | K29: =K26+K28 -> 0 | L29: =L26+L28 -> 0 | M29: =M26+M28 -> 0 | N29: =N26+N28 -> 0 | O29: =O26+O28 -> 1173780.5 | P29: =P26+P28 -> 0 | Q29: =Q26+Q28 -> 41039.979 | ... AW29: =AW26+AW28 -> 597384
C31: Arrears Amount Owed Repayment | J31: =J97 -> 0 | K31: =K97 -> 0 | L31: =L97 -> 0 | M31: =M97 -> 0 | N31: =N97 -> 0 | O31: =O97 -> -1173780.5 | P31: =P97 -> 0 | Q31: =Q97 -> -41039.979 | ... AW31: =AW97 -> 0
C32: Funds Distributed to Equity | J32: =SUM(J29,J31) -> 0 | K32: =SUM(K29,K31) -> 0 | L32: =SUM(L29,L31) -> 0 | M32: =SUM(M29,M31) -> 0 | N32: =SUM(N29,N31) -> 0 | O32: =SUM(O29,O31) -> 0 | P32: =SUM(P29,P31) -> 0 | Q32: =SUM(Q29,Q31) -> 0 | ... AW32: =SUM(AW29,AW31) -> 597384
B35: Sr Facility
C36: Opening Balance | J36: =I38 -> 10000000 | K36: =J38 -> 9746520.6 | L36: =K38 -> 9493960.4 | M36: =L38 -> 9241756 | N36: =M38 -> 8987604.1 | O36: =N38 -> 8729722.5 | P36: =O38 -> 8476612.9 | Q36: =P38 -> 8220662.2 | ... AW36: =AV38 -> 0
C37: Repayment | J37: =J13 -> -253479.44 | K37: =K13 -> -252560.16 | L37: =L13 -> -252204.38 | M37: =M13 -> -254151.94 | N37: =N13 -> -257881.62 | O37: =O13 -> -253109.58 | P37: =P13 -> -255950.67 | Q37: =Q13 -> -256648.94 | ... AW37: =AW13 -> 0
C38: Closing Balance | I38: =CaseData!G4 -> 10000000 | J38: =SUM(J36:J37) -> 9746520.6 | K38: =SUM(K36:K37) -> 9493960.4 | L38: =SUM(L36:L37) -> 9241756 | M38: =SUM(M36:M37) -> 8987604.1 | N38: =SUM(N36:N37) -> 8729722.5 | O38: =SUM(O36:O37) -> 8476612.9 | P38: =SUM(P36:P37) -> 8220662.2 | Q38: =SUM(Q36:Q37) -> 7964013.3 | ... AW38: =SUM(AW36:AW37) -> 0
C40: Interest Rate | H40: =CaseData!G5 -> 0.05 | J40: =$H40 -> 0.05 | K40: =$H40 -> 0.05 | L40: =$H40 -> 0.05 | M40: =$H40 -> 0.05 | N40: =$H40 -> 0.05 | O40: =$H40 -> 0.05 | P40: =$H40 -> 0.05 | Q40: =$H40 -> 0.05 | ... AW40: =$H40 -> 0.05
C41: Interest Expense | J41: =J36*J40/4 -> 125000 | K41: =K36*K40/4 -> 121831.51 | L41: =L36*L40/4 -> 118674.5 | M41: =M36*M40/4 -> 115521.95 | N41: =N36*N40/4 -> 112345.05 | O41: =O36*O40/4 -> 109121.53 | P41: =P36*P40/4 -> 105957.66 | Q41: =Q36*Q40/4 -> 102758.28 | ... AW41: =AW36*AW40/4 -> 0
B44: DSCR (LTM) | J44: =J37-J41 -> -378479.44 | K44: =K37-K41 -> -374391.67 | L44: =L37-L41 -> -370878.89 | M44: =M37-M41 -> -369673.89 | N44: =N37-N41 -> -370226.67 | O44: =O37-O41 -> -362231.11 | P44: =P37-P41 -> -361908.33 | Q44: =Q37-Q41 -> -359407.22 | R44: =R37-R41 -> -377096.11
C45: EBITDA | J45: =SUM(J9:J9) -> 602417 | K45: =SUM(J9:K9) -> 1197893 | L45: =SUM(J9:L9) -> 1791091 | M45: =SUM(J9:M9) -> 2397690 | N45: =SUM(K9:N9) -> 2427040 | O45: =SUM(L9:O9) -> 2442091 | P45: =SUM(M9:P9) -> 2434491 | Q45: =SUM(N9:Q9) -> 2465464 | R45: =SUM(O9:R9) -> 2480687 | S45: =SUM(P9:S9) -> 2545743 | T45: =SUM(Q9:T9) -> 2544756 | ... AW45: =SUM(AT9:AW9) -> 2987085
C46: Interest Income | J46: =SUM(J10:J10) -> 1875 | K46: =SUM(J10:K10) -> 4596.7971 | L46: =SUM(J10:L10) -> 8157.8672 | M46: =SUM(J10:M10) -> 12565.988 | N46: =SUM(K10:N10) -> 16004.108 | O46: =SUM(L10:O10) -> 19596.132 | P46: =SUM(M10:P10) -> 17910.062 | Q46: =SUM(N10:Q10) -> 15376.941 | R46: =SUM(O10:R10) -> 11938.821 | S46: =SUM(P10:S10) -> 7500 | T46: =SUM(Q10:T10) -> 7500 | ... AW46: =SUM(AT10:AW10) -> 0
C47: Sr. Interest Expense | J47: =SUM(J41:J41) -> 125000 | K47: =SUM(J41:K41) -> 246831.51 | L47: =SUM(J41:L41) -> 365506.01 | M47: =SUM(J41:M41) -> 481027.96 | N47: =SUM(K41:N41) -> 468373.01 | O47: =SUM(L41:O41) -> 455663.04 | P47: =SUM(M41:P41) -> 442946.19 | Q47: =SUM(N41:Q41) -> 430182.52 | R47: =SUM(O41:R41) -> 417387.63 | S47: =SUM(P41:S41) -> 404346.95 | T47: =SUM(Q41:T41) -> 391197.77 | ... AW47: =SUM(AT41:AW41) -> 0
C48: Sr. Principal Repayments | J48: =-SUM(J37:J37) -> 253479.44 | K48: =-SUM(J37:K37) -> 506039.6 | L48: =-SUM(J37:L37) -> 758243.99 | M48: =-SUM(J37:M37) -> 1012395.9 | N48: =-SUM(K37:N37) -> 1016798.1 | O48: =-SUM(L37:O37) -> 1017347.5 | P48: =-SUM(M37:P37) -> 1021093.8 | Q48: =-SUM(N37:Q37) -> 1023590.8 | R48: =-SUM(O37:R37) -> 1043255.1 | S48: =-SUM(P37:S37) -> 1051934.2 | T48: =-SUM(Q37:T37) -> 1066850.6 | ... AW48: =-SUM(AT37:AW37) -> 0
C50: DSCR | J50: =IFERROR(SUM(J45:J46)/SUM(J47:J48),"n.a.") -> 1.596631 | K50: =IFERROR(SUM(K45:K46)/SUM(K47:K48),"n.a.") -> 1.5972054 | L50: =IFERROR(SUM(L45:L46)/SUM(L47:L48),"n.a.") -> 1.6011113 | M50: =IFERROR(SUM(M45:M46)/SUM(M47:M48),"n.a.") -> 1.6139128 | N50: =IFERROR(SUM(N45:N46)/SUM(N47:N48),"n.a.") -> 1.644958 | O50: =IFERROR(SUM(O45:O46)/SUM(O47:O48),"n.a.") -> 1.6711945 | P50: =IFERROR(SUM(P45:P46)/SUM(P47:P48),"n.a.") -> 1.6750916 | Q50: =IFERROR(SUM(Q45:Q46)/SUM(Q47:Q48),"n.a.") -> 1.706484 | ... AW50: =IFERROR(SUM(AW45:AW46)/SUM(AW47:AW48),"n.a.") -> n.a.
C52: Lock-up Trigger | H52: =CaseData!G7 -> 1.62 | J52: =$H52 -> 1.62 | K52: =$H52 -> 1.62 | L52: =$H52 -> 1.62 | M52: =$H52 -> 1.62 | N52: =$H52 -> 1.62 | O52: =$H52 -> 1.62 | P52: =$H52 -> 1.62 | Q52: =$H52 -> 1.62 | ... AW52: =$H52 -> 1.62
C53: Lock Up Flag | J53: =IF(J50<J52,1,0) -> 1 | K53: =IF(K50<K52,1,0) -> 1 | L53: =IF(L50<L52,1,0) -> 1 | M53: =IF(M50<M52,1,0) -> 1 | N53: =IF(N50<N52,1,0) -> 0 | O53: =IF(O50<O52,1,0) -> 0 | P53: =IF(P50<P52,1,0) -> 0 | Q53: =IF(Q50<Q52,1,0) -> 0 | ... AW53: =IF(AW50<AW52,1,0) -> 0
C54: Release Test | H54: =MAX(J54:AW54) -> 1 | J54: =MAX(I53:J53) -> 1 | K54: =MAX(J53:K53) -> 1 | L54: =MAX(K53:L53) -> 1 | M54: =MAX(L53:M53) -> 1 | N54: =MAX(M53:N53) -> 1 | O54: =MAX(N53:O53) -> 0 | P54: =MAX(O53:P53) -> 0 | Q54: =MAX(P53:Q53) -> 0 | ... AW54: =MAX(AV53:AW53) -> 0
B57: DSRA
C58: Opening Balance | J58: =I63 -> 500000 | K58: =J63 -> 725812.56 | L58: =K63 -> 949618.69 | M58: =L63 -> 1175498.9 | N58: =M63 -> 1416832.1 | O58: =N63 -> 1683685.6 | P58: =O63 -> 500000 | Q58: =P63 -> 500000 | ... AW58: =AV63 -> 0
C59: Fund Sr. Debt Repayment Shortfall | J59: =-J19 -> 0 | K59: =-K19 -> 0 | L59: =-L19 -> 0 | M59: =-M19 -> 0 | N59: =-N19 -> 0 | O59: =-O19 -> 0 | P59: =-P19 -> 0 | Q59: =-Q19 -> 0 | ... AW59: =-AW19 -> 0
...
