Workbook
Name company: CaseData!$B$1
Name periods: CaseData!$L$8
Name start_date: CaseData!$L$7
Name topic: "CFM Topic: " & CaseData!$L$10

Sheet Debt
A1: =company -> YHF Ltd.
A2: {=topic} -> CFM Topic: Debt
A3: DEBT SCHEDULE | F3: Constant | G3: Unit | H3: Total | J3: =J$9 -> 43982 | K3: =K$9 -> 44012 | L3: =L$9 -> 44043 | M3: =M$9 -> 44074 | N3: =N$9 -> 44104 | O3: =O$9 -> 44135
A6: Model timeline
E8: Model start date | F8: =start_date -> 43952 | G8: date
E9: Model timeline | G9: date | J9: {=EOMONTH( start_date, _xlfn.SEQUENCE( 1, periods, 0, 1 ) )} -> 43982 | K9: 44012 | L9: 44043 | M9: 44074 | N9: 44104 | O9: 44135
E10: Model counter | G10: counter | J10: {=_xlfn.SEQUENCE( 1, periods, 1, 1 )} -> 1 | K10: 2 | L10: 3 | M10: 4 | N10: 5 | O10: 6
E11: Model first period flag | G11: flag | J11: =IF( J10 = 1, 1, 0 ) -> 1 | K11: =IF( K10 = 1, 1, 0 ) -> 0 | L11: =IF( L10 = 1, 1, 0 ) -> 0 | M11: =IF( M10 = 1, 1, 0 ) -> 0 | N11: =IF( N10 = 1, 1, 0 ) -> 0 | O11: =IF( O10 = 1, 1, 0 ) -> 0
A13: Total Debt / EBIDTA
F15: 43951
E16: Total Debt | F16: =CaseData!$S$43 -> 686848 | G16: USD | J16: =J$172 -> 681851.48 | K16: =K$172 -> 678153.14 | L16: =L$172 -> 676192.03 | M16: =M$172 -> 680818.37 | N16: =N$172 -> 678745.64 | O16: =O$172 -> 677079.93
E17: EBIDTA | F17: =CaseData!$S$44 -> 191177 | G17: USD | J17: =CaseData!E$54 -> 193220 | K17: =CaseData!F$54 -> 189600 | L17: =CaseData!G$54 -> 186312 | M17: =CaseData!H$54 -> 185545 | N17: =CaseData!I$54 -> 185313 | O17: =CaseData!J$54 -> 183795
E18: Total Debt / EBIDTA | F18: =CaseData!$S$45 -> 3.5927334 | G18: multiple | J18: =IFERROR( J16 / J17, "to be calc" ) -> 3.5288866 | K18: =IFERROR( K16 / K17, "to be calc" ) -> 3.5767571 | L18: =IFERROR( L16 / L17, "to be calc" ) -> 3.6293531 | M18: =IFERROR( M16 / M17, "to be calc" ) -> 3.6692898 | N18: =IFERROR( N16 / N17, "to be calc" ) -> 3.6626985 | O18: =IFERROR( O16 / O17, "to be calc" ) -> 3.6838865
A20: Taxes
E22: Free Cash Flow Before Debt Service & Taxes | G22: USD | H22: =SUM( J22:O22) -> 51072.897 | J22: =CaseData!E$56 -> 10393.67 | K22: =CaseData!F$56 -> 8667.573 | L22: =CaseData!G$56 -> 6355.84 | M22: =CaseData!H$56 -> 8884.205 | N22: =CaseData!I$56 -> 11026.2 | O22: =CaseData!J$56 -> 5745.409
D23: less | E23: =E$154 -> Interest expenses accrued | G23: =G$154 -> USD | H23: =SUM( J23:O23) -> -24452.594 | I23: =I$154 -> 0 | J23: =J$154 * - 1 -> -3731.6406 | K23: =K$154 * - 1 -> -3736.4541 | L23: =L$154 * - 1 -> -3741.028 | M23: =M$154 * - 1 -> -6298.9093 | N23: =N$154 * - 1 -> -3420.1032 | O23: =O$154 * - 1 -> -3524.4585
E24: Taxable income | G24: USD | H24: =SUM( J24:O24) -> 26620.303 | J24: =SUM(J22:J23) -> 6662.0294 | K24: =SUM(K22:K23) -> 4931.1189 | L24: =SUM(L22:L23) -> 2614.812 | M24: =SUM(M22:M23) -> 2585.2957 | N24: =SUM(N22:N23) -> 7606.0968 | O24: =SUM(O22:O23) -> 2220.9505
E26: Applicable tax rate | F26: =CaseData!$L$11 -> 0.25 | G26: %
E27: Taxes paid | G27: USD | H27: =SUM( J27:O27) -> 6655.0758 | J27: =J$24 * $F$26 -> 1665.5073 | K27: =K$24 * $F$26 -> 1232.7797 | L27: =L$24 * $F$26 -> 653.70299 | M27: =M$24 * $F$26 -> 646.32391 | N27: =N$24 * $F$26 -> 1901.5242 | O27: =O$24 * $F$26 -> 555.23764
A29: Revolver
C32: Free cash flow after repayment of debt service and taxes
E33: Free Cash Flow Before Debt Service & Taxes | G33: USD | J33: =CaseData!E$56 -> 10393.67 | K33: =CaseData!F$56 -> 8667.573 | L33: =CaseData!G$56 -> 6355.84 | M33: =CaseData!H$56 -> 8884.205 | N33: =CaseData!I$56 -> 11026.2 | O33: =CaseData!J$56 -> 5745.409
E34: =E$142 -> Principal addition / (repayment) | G34: =G$142 -> USD | J34: =J$142 -> -2179.6875 | K34: =K$142 -> -2152.4414 | L34: =L$142 -> -2125.5359 | M34: =M$142 -> 12901.033 | N34: =N$142 -> -2072.7296 | O34: =O$142 -> -2046.8205
D35: less | E35: =E$154 -> Interest expenses accrued | G35: =G$154 -> USD | J35: =J$154 * - 1 -> -3731.6406 | K35: =K$154 * - 1 -> -3736.4541 | L35: =L$154 * - 1 -> -3741.028 | M35: =M$154 * - 1 -> -6298.9093 | N35: =N$154 * - 1 -> -3420.1032 | O35: =O$154 * - 1 -> -3524.4585
D36: less | E36: =E$27 -> Taxes paid | G36: =G$27 -> USD | J36: =J$27 * - 1 -> -1665.5073 | K36: =K$27 * - 1 -> -1232.7797 | L36: =L$27 * - 1 -> -653.70299 | M36: =M$27 * - 1 -> -646.32391 | N36: =N$27 * - 1 -> -1901.5242 | O36: =O$27 * - 1 -> -555.23764
E37: Free cash flow after repayment of debt service and taxes | J37: =SUM(J33:J36) -> 2816.8345 | K37: =SUM(K33:K36) -> 1545.8978 | L37: =SUM(L33:L36) -> -164.42692 | M37: =SUM(M33:M36) -> 14840.005 | N37: =SUM(N33:N36) -> 3631.843 | O37: =SUM(O33:O36) -> -381.10757
E39: Revolver balance as of 30/04/2020 | F39: =CaseData!$E$8 -> 12473 | G39: USD
E41: Revolver beginning balance | G41: USD | J41: =IF( J$11 = 1, $F$39, I43) -> 12473 | K41: =IF( K$11 = 1, $F$39, J43) -> 9656.1655 | L41: =IF( L$11 = 1, $F$39, K43) -> 8110.2677 | M41: =IF( M$11 = 1, $F$39, L43) -> 8274.6946 | N41: =IF( N$11 = 1, $F$39, M43) -> 0 | O41: =IF( O$11 = 1, $F$39, N43) -> 0
E42: Revolver drawdown / (repayment) | G42: USD | J42: =- MIN( J$37, J$41 ) -> -2816.8345 | K42: =- MIN( K$37, K$41 ) -> -1545.8978 | L42: =- MIN( L$37, L$41 ) -> 164.42692 | M42: =- MIN( M$37, M$41 ) -> -8274.6946 | N42: =- MIN( N$37, N$41 ) -> 0 | O42: =- MIN( O$37, O$41 ) -> 381.10757
E43: Revolver | G43: USD | J43: =SUM(J41:J42) -> 9656.1655 | K43: =SUM(K41:K42) -> 8110.2677 | L43: =SUM(L41:L42) -> 8274.6946 | M43: =SUM(M41:M42) -> 0 | N43: =SUM(N41:N42) -> 0 | O43: =SUM(O41:O42) -> 381.10757
C46: Revolver interest expenses
E47: LIBOR | G47: % | J47: =CaseData!E$57 -> 0.0225 | K47: =CaseData!F$57 -> 0.0235 | L47: =CaseData!G$57 -> 0.0245 | M47: =CaseData!H$57 -> 0.0255 | N47: =CaseData!I$57 -> 0.0265 | O47: =CaseData!J$57 -> 0.027
E48: Spread to LIBOR on drawn funds based on Total Debt / EBIDTA | G48: % | J48: {=_xlfn.XLOOKUP( IF( J$11 = 1, $F$18, I$18 ), CaseData!$G$11:$G$14, CaseData!$I$11:$I$14 / 10000,,-1 )} -> 0.03 | K48: {=_xlfn.XLOOKUP( IF( K$11 = 1, $F$18, J$18 ), CaseData!$G$11:$G$14, CaseData!$I$11:$I$14 / 10000,,-1 )} -> 0.03 | L48: {=_xlfn.XLOOKUP( IF( L$11 = 1, $F$18, K$18 ), CaseData!$G$11:$G$14, CaseData!$I$11:$I$14 / 10000,,-1 )} -> 0.03 | M48: {=_xlfn.XLOOKUP( IF( M$11 = 1, $F$18, L$18 ), CaseData!$G$11:$G$14, CaseData!$I$11:$I$14 / 10000,,-1 )} -> 0.03 | N48: {=_xlfn.XLOOKUP( IF( N$11 = 1, $F$18, M$18 ), CaseData!$G$11:$G$14, CaseData!$I$11:$I$14 / 10000,,-1 )} -> 0.03 | O48: {=_xlfn.XLOOKUP( IF( O$11 = 1, $F$18, N$18 ), CaseData!$G$11:$G$14, CaseData!$I$11:$I$14 / 10000,,-1 )} -> 0.03
E49: Effective interest rate on revolver | G49: % | J49: =SUM(J47:J48) -> 0.0525 | K49: =SUM(K47:K48) -> 0.0535 | L49: =SUM(L47:L48) -> 0.0545 | M49: =SUM(M47:M48) -> 0.0555 | N49: =SUM(N47:N48) -> 0.0565 | O49: =SUM(O47:O48) -> 0.057
E52: Annual Commitment Fee (on Undrawn Portion) | F52: =CaseData!E$10 -> 80 | G52: bps
E53: Maximum facility size | F53: =CaseData!$E$7 -> 50000 | G53: USD
E55: Commitment fee on undrawn amount | G55: USD | H55: =SUM( J55:O55) -> 182.38518 | J55: =( $F$53 - J$43 ) * $F$52 / 10000 / 12 -> 26.89589 | K55: =( $F$53 - K$43 ) * $F$52 / 10000 / 12 -> 27.926488 | L55: =( $F$53 - L$43 ) * $F$52 / 10000 / 12 -> 27.81687 | M55: =( $F$53 - M$43 ) * $F$52 / 10000 / 12 -> 33.333333 | N55: =( $F$53 - N$43 ) * $F$52 / 10000 / 12 -> 33.333333 | O55: =( $F$53 - O$43 ) * $F$52 / 10000 / 12 -> 33.079262
E56: Drawn interest expenses | G56: USD | H56: =SUM( J56:O56) -> 172.72437 | J56: =IF( J$11 = 1, $F$39 * J$49 / 12, I$43 * J$49 / 12 ) -> 54.569375 | K56: =IF( K$11 = 1, $F$39 * K$49 / 12, J$43 * K$49 / 12 ) -> 43.050404 | L56: =IF( L$11 = 1, $F$39 * L$49 / 12, K$43 * L$49 / 12 ) -> 36.834132 | M56: =IF( M$11 = 1, $F$39 * M$49 / 12, L$43 * M$49 / 12 ) -> 38.270463 | N56: =IF( N$11 = 1, $F$39 * N$49 / 12, M$43 * N$49 / 12 ) -> 0 | O56: =IF( O$11 = 1, $F$39 * O$49 / 12, N$43 * O$49 / 12 ) -> 0
E57: Revolver interest expenses | G57: USD | H57: =SUM( J57:O57) -> 355.10955 | J57: =SUM(J55:J56) -> 81.465265 | K57: =SUM(K55:K56) -> 70.976893 | L57: =SUM(L55:L56) -> 64.651003 | M57: =SUM(M55:M56) -> 71.603796 | N57: =SUM(N55:N56) -> 33.333333 | O57: =SUM(O55:O56) -> 33.079262
A60: Senior Secured Term Loan
...

Sheet CaseData
B1: YHF Ltd.
B2: (in thousands of $)
B4: Existing Debt as at April 30, 2020
B6: Revolving Credit Facility:
B7: Max. Amount | E7: 50000 | G7: Annual Rates on Drawn Funds (Paid Monthly) | K7: Model start | L7: 43952 | M7: date
B8: Balance Outstanding | E8: 12473 | G8: (spread based on previous month's ratio) | K8: Periods | L8: 6 | M8: months
G9: Total Debt / | I9: Spread to | K9: Model end | L9: =EOMONTH( start_date, periods ) -> 44165 | M9: date
B10: Annual Commitment Fee (on Undrawn Portion) | E10: 80 | G10: EBITDA >= | I10: LIBOR | K10: Topic | L10: Debt
B11: (payable monthly) | G11: 0 | I11: 100 | K11: Tax rate | L11: 0.25 | M11: %
G12: 2 | I12: 175
B13: Interest Coverage Ratio | E13: 2.5 | G13: 3 | I13: 225
G14: 3.5 | I14: 300
B16: Senior Secured Term Loan: | G16: Subordinated Notes: | K16: New Subordinated Note
B17: Balance Outstanding | E17: 174375 | G17: Face Amount | I17: 500000 | K17: 43982 | L17: 0.0505
B18: Original Amount | E18: 225000 | G18: Amortization | I18: 0 | K18: 44012 | L18: 0.0525
G19: Annual Coupon | I19: 0.07125 | K19: 44043 | L19: 0.057
B20: Monthy Amortization | E20: 0.0125 | G20: Payable semi-annually on: | I20: 43951 | K20: 44074 | L20: 0.0595
I21: 44135 | K21: 44104 | L21: 0.0615
B22: Annual Interest Rate | E22: Same | G22: Final Maturity | I22: Oct. 31, 2020 | K22: 44135 | L22: 0.064
B23: (payable monthly) | E23: as revolver | G23: Early Call Prices:
G24: Before 7/31/20 | I24: 1.03
B25: Final Maturity | E25: Jun. 30, 2025 | G25: Before 10/31/20 | I25: 1.02
B27: Historical Debt Details
B29: Revolving Credit Facility: | E29: 43524 | F29: 43555 | G29: 43585 | H29: 43616 | I29: 43646 | J29: 43677 | K29: 43708 | L29: 43738 | M29: 43769 | N29: 43799 | O29: 43830 | P29: 43861 | Q29: 43890 | R29: 43921 | S29: 43951
B30: Ending Balance | D30: 10029 | E30: 5395 | F30: 11094 | G30: 12111 | H30: 12263 | I30: 21116 | J30: 26477 | K30: 31004 | L30: 18530 | M30: 8274 | N30: 31247 | O30: 33481 | P30: 15891 | Q30: 36380 | R30: 13877 | S30: 12473
B31: Drawn Interest | E31: 44.337 | F31: 24.929 | G31: 49.137 | H31: 53.884 | I31: 51.709 | J31: 97.239 | K31: 112.814 | L31: 131.534 | M31: 82.721 | N31: 36.771 | O31: 130.274 | P31: 141.792 | Q31: 68.583 | R31: 165.832 | S31: 60.272
B32: Undrawn Interest | E32: 26.647 | F32: 29.737 | G32: 25.937 | H32: 25.259 | I32: 25.158 | J32: 19.256 | K32: 15.682 | L32: 12.664 | M32: 20.98 | N32: 27.817 | O32: 12.502 | P32: 11.013 | Q32: 22.739 | R32: 9.08 | S32: 24.082
B34: Senior Secured Term Loan:
B35: Ending Balance | D35: 216562.5 | E35: 213750 | F35: 210937.5 | G35: 208125 | H35: 205312.5 | I35: 202500 | J35: 199687.5 | K35: 196875 | L35: 194062.5 | M35: 191250 | N35: 188437.5 | O35: 185625 | P35: 182812.5 | Q35: 180000 | R35: 177187.5 | S35: 174375
B36: Interest | E36: 957.387 | F36: 987.703 | G36: 934.277 | H36: 925.983 | I36: 865.734 | J36: 932.513 | K36: 850.835 | L36: 835.242 | M36: 866.327 | N36: 849.947 | O36: 785.627 | P36: 786.122 | Q36: 788.988 | R36: 820.5 | S36: 769.584
B38: Subordinated Notes:
B39: Ending Balance | D39: 500000 | E39: 500000 | F39: 500000 | G39: 500000 | H39: 500000 | I39: 500000 | J39: 500000 | K39: 500000 | L39: 500000 | M39: 500000 | N39: 500000 | O39: 500000 | P39: 500000 | Q39: 500000 | R39: 500000 | S39: 500000
B40: Interest | E40: 2968.75 | F40: 2968.75 | G40: 2968.75 | H40: 2968.75 | I40: 2968.75 | J40: 2968.75 | K40: 2968.75 | L40: 2968.75 | M40: 2968.75 | N40: 2968.75 | O40: 2968.75 | P40: 2968.75 | Q40: 2968.75 | R40: 2968.75 | S40: 2968.75
B43: Total Debt | D43: 726591.5 | E43: 719145 | F43: 722031.5 | G43: 720236 | H43: 717575.5 | I43: 723616 | J43: 726164.5 | K43: 727879 | L43: 712592.5 | M43: 699524 | N43: 719684.5 | O43: 719106 | P43: 698703.5 | Q43: 716380 | R43: 691064.5 | S43: 686848
B44: TTM EBITDA | D44: 183244 | E44: 191930 | F44: 199032 | G44: 175519 | H44: 170868 | I44: 156913 | J44: 179890 | K44: 174023 | L44: 198141 | M44: 191052 | N44: 189901 | O44: 165475 | P44: 198550 | Q44: 187963 | R44: 180401 | S44: 191177
B45: Total Debt / EBITDA | D45: 3.9651585 | E45: 3.7469129 | F45: 3.6277156 | G45: 4.1034646 | H45: 4.1995897 | I45: 4.6115746 | J45: 4.0367141 | K45: 4.1826598 | L45: 3.596391 | M45: 3.6614325 | N45: 3.7897878 | O45: 4.3457078 | P45: 3.5190305 | Q45: 3.811282 | R45: 3.8307132 | S45: 3.5927334
B46: LIBOR | D46: 0.02317 | E46: 0.02305 | F46: 0.02545 | G46: 0.02315 | H46: 0.02339 | I46: 0.0206 | J46: 0.02526 | K46: 0.02113 | L46: 0.02091 | M46: 0.02357 | N46: 0.02333 | O46: 0.02003 | P46: 0.02082 | Q46: 0.02179 | R46: 0.0247 | S46: 0.02212
B47: Spread | E47: 0.03 | F47: 0.03 | G47: 0.03 | H47: 0.03 | I47: 0.03 | J47: 0.03 | K47: 0.03 | L47: 0.03 | M47: 0.03 | N47: 0.03 | O47: 0.03 | P47: 0.03 | Q47: 0.03 | R47: 0.03 | S47: 0.03
B48: Rate | E48: 0.05305 | F48: 0.05545 | G48: 0.05315 | H48: 0.05339 | I48: 0.0506 | J48: 0.05526 | K48: 0.05113 | L48: 0.05091 | M48: 0.05357 | N48: 0.05333 | O48: 0.05003 | P48: 0.05082 | Q48: 0.05179 | R48: 0.0547 | S48: 0.05212
B51: Forecasted Data
...

Sheet CaseSolution
B1: YHF Ltd.
B2: (in thousands of $)
B4: =CaseData!$B$4 -> Existing Debt as at April 30, 2020
B6: Revolving Credit Facility:
B7: Max. Amount | D7: =CaseData!E7 -> 50000 | F7: Annual Rates on Drawn Funds (Paid Monthly) | J7: Taxes
B8: Balance Outstanding | D8: =CaseData!E8 -> 12473 | F8: (spread based on previous month's ratio)
F9: Total Debt / | H9: Spread to | J9: Applicable Rate: | L9: 0.25
B10: Annual Commitment Fee (on Undrawn Portion) | D10: =CaseData!E10 -> 80 | F10: EBITDA >= | H10: LIBOR
B11: (payable monthly) | F11: =CaseData!G11 -> 0 | H11: =CaseData!I11 -> 100
F12: =CaseData!G12 -> 2 | H12: =CaseData!I12 -> 175
B13: Interest Coverage Ratio | D13: =CaseData!E13 -> 2.5 | F13: =CaseData!G13 -> 3 | H13: =CaseData!I13 -> 225
F14: =CaseData!G14 -> 3.5 | H14: =CaseData!I14 -> 300
B16: Senior Secured Term Loan: | F16: Subordinated Notes: | J16: New Senior Notes:
B17: Balance Outstanding | D17: =CaseData!E17 -> 174375 | F17: Face Amount | H17: =CaseData!I17 -> 500000 | J17: Date Issued | L17: 44043
B18: Original Amount | D18: =CaseData!E18 -> 225000 | F18: Amortization | H18: =CaseData!I18 -> 0 | J18: Annual Coupons:
F19: Annual Coupon | H19: =CaseData!I19 -> 0.07125 | J19: {=TRANSPOSE(D65:I65)} -> 43982 | L19: 0.0505
B20: Monthy Amortization | D20: =CaseData!E20 -> 0.0125 | F20: Payable semi-annually on: | H20: 43951 | J20: 44012 | L20: 0.0525
H21: 44135 | J21: 44043 | L21: 0.057
B22: Annual Interest Rate | D22: =CaseData!E22 -> Same | F22: Final Maturity | H22: =CaseData!I22 -> Oct. 31, 2020 | J22: 44074 | L22: 0.0595
B23: (payable monthly) | D23: =CaseData!E23 -> as revolver | F23: Call Prices: | J23: 44104 | L23: 0.0615
F24: =R31 -> 43951 | H24: 1.03 | J24: 44135 | L24: 0.064
B25: Final Maturity | D25: =CaseData!E25 -> Jun. 30, 2025 | F25: 44043 | H25: 1.02
J26: Payable semi-annually on: | L26: =EOMONTH(L17,6) -> 44227
L27: =EOMONTH(L26,6) -> 44408
B29: Historical Debt Details
B31: =B6 -> Revolving Credit Facility: | D31: =CaseData!E29 -> 43524 | E31: =CaseData!F29 -> 43555 | F31: =CaseData!G29 -> 43585 | G31: =CaseData!H29 -> 43616 | H31: =CaseData!I29 -> 43646 | I31: =CaseData!J29 -> 43677 | J31: =CaseData!K29 -> 43708 | K31: =CaseData!L29 -> 43738 | ... R31: =CaseData!S29 -> 43951
B32: Ending Balance | C32: =CaseData!D30 -> 10029 | D32: =CaseData!E30 -> 5395 | E32: =CaseData!F30 -> 11094 | F32: =CaseData!G30 -> 12111 | G32: =CaseData!H30 -> 12263 | H32: =CaseData!I30 -> 21116 | I32: =CaseData!J30 -> 26477 | J32: =CaseData!K30 -> 31004 | ... R32: =CaseData!S30 -> 12473
B33: Drawn Interest | D33: =CaseData!E31 -> 44.337 | E33: =CaseData!F31 -> 24.929 | F33: =CaseData!G31 -> 49.137 | G33: =CaseData!H31 -> 53.884 | H33: =CaseData!I31 -> 51.709 | I33: =CaseData!J31 -> 97.239 | J33: =CaseData!K31 -> 112.814 | K33: =CaseData!L31 -> 131.534 | ... R33: =CaseData!S31 -> 60.272
B34: Undrawn Interest | D34: =CaseData!E32 -> 26.647 | E34: =CaseData!F32 -> 29.737 | F34: =CaseData!G32 -> 25.937 | G34: =CaseData!H32 -> 25.259 | H34: =CaseData!I32 -> 25.158 | I34: =CaseData!J32 -> 19.256 | J34: =CaseData!K32 -> 15.682 | K34: =CaseData!L32 -> 12.664 | ... R34: =CaseData!S32 -> 24.082
B35: Total Reveolver Interest | D35: =D33+D34 -> 70.984 | E35: =E33+E34 -> 54.666 | F35: =F33+F34 -> 75.074 | G35: =G33+G34 -> 79.143 | H35: =H33+H34 -> 76.867 | I35: =I33+I34 -> 116.495 | J35: =J33+J34 -> 128.496 | K35: =K33+K34 -> 144.198 | ... R35: =R33+R34 -> 84.354
B37: Senior Secured Term Loan:
B38: Ending Balance | C38: =CaseData!D35 -> 216562.5 | D38: =CaseData!E35 -> 213750 | E38: =CaseData!F35 -> 210937.5 | F38: =CaseData!G35 -> 208125 | G38: =CaseData!H35 -> 205312.5 | H38: =CaseData!I35 -> 202500 | I38: =CaseData!J35 -> 199687.5 | J38: =CaseData!K35 -> 196875 | ... R38: =CaseData!S35 -> 174375
B39: Interest | D39: =CaseData!E36 -> 957.387 | E39: =CaseData!F36 -> 987.703 | F39: =CaseData!G36 -> 934.277 | G39: =CaseData!H36 -> 925.983 | H39: =CaseData!I36 -> 865.734 | I39: =CaseData!J36 -> 932.513 | J39: =CaseData!K36 -> 850.835 | K39: =CaseData!L36 -> 835.242 | ... R39: =CaseData!S36 -> 769.584
B41: =F16 -> Subordinated Notes:
B42: Ending Balance | C42: =CaseData!D39 -> 500000 | D42: =CaseData!E39 -> 500000 | E42: =CaseData!F39 -> 500000 | F42: =CaseData!G39 -> 500000 | G42: =CaseData!H39 -> 500000 | H42: =CaseData!I39 -> 500000 | I42: =CaseData!J39 -> 500000 | J42: =CaseData!K39 -> 500000 | ... R42: =CaseData!S39 -> 500000
B43: Interest | D43: =CaseData!E40 -> 2968.75 | E43: =CaseData!F40 -> 2968.75 | F43: =CaseData!G40 -> 2968.75 | G43: =CaseData!H40 -> 2968.75 | H43: =CaseData!I40 -> 2968.75 | I43: =CaseData!J40 -> 2968.75 | J43: =CaseData!K40 -> 2968.75 | K43: =CaseData!L40 -> 2968.75 | ... R43: =CaseData!S40 -> 2968.75
B46: Total Debt | C46: =C32+C38+C42 -> 726591.5 | D46: =D32+D38+D42 -> 719145 | E46: =E32+E38+E42 -> 722031.5 | F46: =F32+F38+F42 -> 720236 | G46: =G32+G38+G42 -> 717575.5 | H46: =H32+H38+H42 -> 723616 | I46: =I32+I38+I42 -> 726164.5 | J46: =J32+J38+J42 -> 727879 | ... R46: =R32+R38+R42 -> 686848
B47: TTM EBITDA | C47: =CaseData!D44 -> 183244 | D47: =CaseData!E44 -> 191930 | E47: =CaseData!F44 -> 199032 | F47: =CaseData!G44 -> 175519 | G47: =CaseData!H44 -> 170868 | H47: =CaseData!I44 -> 156913 | I47: =CaseData!J44 -> 179890 | J47: =CaseData!K44 -> 174023 | ... R47: =CaseData!S44 -> 191177
B48: Total Debt / EBITDA | C48: =C46/C47 -> 3.9651585 | D48: =D46/D47 -> 3.7469129 | E48: =E46/E47 -> 3.6277156 | F48: =F46/F47 -> 4.1034646 | G48: =G46/G47 -> 4.1995897 | H48: =H46/H47 -> 4.6115746 | I48: =I46/I47 -> 4.0367141 | J48: =J46/J47 -> 4.1826598 | ... R48: =R46/R47 -> 3.5927334
B49: LIBOR | C49: =CaseData!D46 -> 0.02317 | D49: =CaseData!E46 -> 0.02305 | E49: =CaseData!F46 -> 0.02545 | F49: =CaseData!G46 -> 0.02315 | G49: =CaseData!H46 -> 0.02339 | H49: =CaseData!I46 -> 0.0206 | I49: =CaseData!J46 -> 0.02526 | J49: =CaseData!K46 -> 0.02113 | ... R49: =CaseData!S46 -> 0.02212
...
