Workbook
Name company: CaseData!$G$53
Name end_date: CaseData!$G$7
Name periods: CaseData!$G$6 * 4
Name quarters: Time!$F$9
Name start_date: CaseData!$G$4
Name topic: "CFM Topic: " & CaseData!$F$54

Sheet Cashflow
A1: {=company} -> Investment Fund Asset
A2: {=topic} -> CFM Topic: | J2: {=EDATE( start_date + 1, _xlfn.SEQUENCE( 1, quarters, 0, 3 ) )} -> 44197 | K2: 44287 | L2: 44378 | M2: 44470 | N2: 44562 | O2: 44652 | P2: 44743 | Q2: 44835 | R2: 44927 | S2: 45017 | T2: 45108 | U2: 45200 | V2: 45292 | W2: 45383 | X2: 45474 | Y2: 45566 | Z2: 45658 | AA2: 45748 | AB2: 45839 | AC2: 45931 | AD2: 46023 | AE2: 46113 | AF2: 46204 | AG2: 46296 | AH2: 46388 | AI2: 46478 | AJ2: 46569 | AK2: 46661 | AL2: 46753 | AM2: 46844 | AN2: 46935 | AO2: 47027 | AP2: 47119 | AQ2: 47209 | AR2: 47300 | AS2: 47392 | AT2: 47484 | AU2: 47574 | AV2: 47665 | AW2: 47757 | AX2: 47849 | AY2: 47939 | AZ2: 48030 | BA2: 48122 | BB2: 48214 | BC2: 48305 | BD2: 48396 | BE2: 48488 | BF2: 48580 | BG2: 48670 | BH2: 48761 | BI2: 48853 | BJ2: 48945 | BK2: 49035 | BL2: 49126 | BM2: 49218 | BN2: 49310 | BO2: 49400 | BP2: 49491 | BQ2: 49583 | BR2: 49675 | BS2: 49766 | BT2: 49857 | BU2: 49949 | BV2: 50041 | BW2: 50131 | BX2: 50222 | BY2: 50314 | BZ2: 50406 | CA2: 50496 | CB2: 50587 | CC2: 50679 | CD2: 50771 | CE2: 50861 | CF2: 50952 | CG2: 51044 | CH2: 51136 | CI2: 51227 | CJ2: 51318 | CK2: 51410 | CL2: 51502 | CM2: 51592 | CN2: 51683 | CO2: 51775 | CP2: 51867 | CQ2: 51957 | CR2: 52048 | CS2: 52140 | CT2: 52232 | CU2: 52322 | CV2: 52413 | CW2: 52505 | CX2: 52597 | CY2: 52688 | CZ2: 52779 | DA2: 52871 | DB2: 52963 | DC2: 53053 | DD2: 53144 | DE2: 53236 | DF2: 53328 | DG2: 53418 | DH2: 53509 | DI2: 53601 | DJ2: 53693 | DK2: 53783 | DL2: 53874 | DM2: 53966 | DN2: 54058 | DO2: 54149 | DP2: 54240 | DQ2: 54332 | DR2: 54424 | DS2: 54514 | DT2: 54605 | DU2: 54697 | DV2: 54789 | DW2: 54879 | DX2: 54970 | DY2: 55062
A3: CASHFLOW SCHEDULE | F3: Constant | G3: Unit | H3: Total | J3: {=EOMONTH( start_date, _xlfn.SEQUENCE( 1, quarters, 3, 3 ) )} -> 44286 | K3: 44377 | L3: 44469 | M3: 44561 | N3: 44651 | O3: 44742 | P3: 44834 | Q3: 44926 | R3: 45016 | S3: 45107 | T3: 45199 | U3: 45291 | V3: 45382 | W3: 45473 | X3: 45565 | Y3: 45657 | Z3: 45747 | AA3: 45838 | AB3: 45930 | AC3: 46022 | AD3: 46112 | AE3: 46203 | AF3: 46295 | AG3: 46387 | AH3: 46477 | AI3: 46568 | AJ3: 46660 | AK3: 46752 | AL3: 46843 | AM3: 46934 | AN3: 47026 | AO3: 47118 | AP3: 47208 | AQ3: 47299 | AR3: 47391 | AS3: 47483 | AT3: 47573 | AU3: 47664 | AV3: 47756 | AW3: 47848 | AX3: 47938 | AY3: 48029 | AZ3: 48121 | BA3: 48213 | BB3: 48304 | BC3: 48395 | BD3: 48487 | BE3: 48579 | BF3: 48669 | BG3: 48760 | BH3: 48852 | BI3: 48944 | BJ3: 49034 | BK3: 49125 | BL3: 49217 | BM3: 49309 | BN3: 49399 | BO3: 49490 | BP3: 49582 | BQ3: 49674 | BR3: 49765 | BS3: 49856 | BT3: 49948 | BU3: 50040 | BV3: 50130 | BW3: 50221 | BX3: 50313 | BY3: 50405 | BZ3: 50495 | CA3: 50586 | CB3: 50678 | CC3: 50770 | CD3: 50860 | CE3: 50951 | CF3: 51043 | CG3: 51135 | CH3: 51226 | CI3: 51317 | CJ3: 51409 | CK3: 51501 | CL3: 51591 | CM3: 51682 | CN3: 51774 | CO3: 51866 | CP3: 51956 | CQ3: 52047 | CR3: 52139 | CS3: 52231 | CT3: 52321 | CU3: 52412 | CV3: 52504 | CW3: 52596 | CX3: 52687 | CY3: 52778 | CZ3: 52870 | DA3: 52962 | DB3: 53052 | DC3: 53143 | DD3: 53235 | DE3: 53327 | DF3: 53417 | DG3: 53508 | DH3: 53600 | DI3: 53692 | DJ3: 53782 | DK3: 53873 | DL3: 53965 | DM3: 54057 | DN3: 54148 | DO3: 54239 | DP3: 54331 | DQ3: 54423 | DR3: 54513 | DS3: 54604 | DT3: 54696 | DU3: 54788 | DV3: 54878 | DW3: 54969 | DX3: 55061 | DY3: 55153
A5: Cashflow Waterfall
F6: =start_date -> 44196
E7: CFADS | F7: 0 | G7: USD | H7: {=_xlfn.BYROW(_xlfn.ANCHORARRAY( $J7), _xleta.SUM )} -> 51600000 | J7: {=_xlfn.LET( _xlpm.cfads_data, CaseData!$G$14:$K$14, _xlpm.cfads_columns, CaseData!$G$13:$K$13, _xlpm.current_date,_xlfn.ANCHORARRAY( $J$3), _xlfn.XLOOKUP( _xlpm.current_date, _xlpm.cfads_columns, _xlpm.cfads_data,, 1 ) )} -> 350000 | K7: 350000 | L7: 350000 | M7: 350000 | N7: 350000 | O7: 350000 | P7: 350000 | Q7: 350000 | R7: 350000 | S7: 350000 | T7: 350000 | U7: 350000 | V7: 350000 | W7: 350000 | X7: 350000 | Y7: 350000 | Z7: 350000 | AA7: 350000 | AB7: 350000 | AC7: 350000 | AD7: 380000 | AE7: 380000 | AF7: 380000 | AG7: 380000 | AH7: 380000 | AI7: 380000 | AJ7: 380000 | AK7: 380000 | AL7: 380000 | AM7: 380000 | AN7: 380000 | AO7: 380000 | AP7: 380000 | AQ7: 380000 | AR7: 380000 | AS7: 380000 | AT7: 380000 | AU7: 380000 | AV7: 380000 | AW7: 380000 | AX7: 400000 | AY7: 400000 | AZ7: 400000 | BA7: 400000 | BB7: 400000 | BC7: 400000 | BD7: 400000 | BE7: 400000 | BF7: 400000 | BG7: 400000 | BH7: 400000 | BI7: 400000 | BJ7: 400000 | BK7: 400000 | BL7: 400000 | BM7: 400000 | BN7: 400000 | BO7: 400000 | BP7: 400000 | BQ7: 400000 | BR7: 450000 | BS7: 450000 | BT7: 450000 | BU7: 450000 | BV7: 450000 | BW7: 450000 | BX7: 450000 | BY7: 450000 | BZ7: 450000 | CA7: 450000 | CB7: 450000 | CC7: 450000 | CD7: 450000 | CE7: 450000 | CF7: 450000 | CG7: 450000 | CH7: 450000 | CI7: 450000 | CJ7: 450000 | CK7: 450000 | CL7: 500000 | CM7: 500000 | CN7: 500000 | CO7: 500000 | CP7: 500000 | CQ7: 500000 | CR7: 500000 | CS7: 500000 | CT7: 500000 | CU7: 500000 | CV7: 500000 | CW7: 500000 | CX7: 500000 | CY7: 500000 | CZ7: 500000 | DA7: 500000 | DB7: 500000 | DC7: 500000 | DD7: 500000 | DE7: 500000 | DF7: 500000 | DG7: 500000 | DH7: 500000 | DI7: 500000 | DJ7: 500000 | DK7: 500000 | DL7: 500000 | DM7: 500000 | DN7: 500000 | DO7: 500000 | DP7: 500000 | DQ7: 500000 | DR7: 500000 | DS7: 500000 | DT7: 500000 | DU7: 500000 | DV7: 500000 | DW7: 500000 | DX7: 500000 | DY7: 500000
E8: Equity Contribution | F8: =CaseData!$G$49 -> 5000000 | G8: USD | J8: =$F8 * ( J$3 = start_date ) -> 0 | K8: =$F8 * ( K$3 = start_date ) -> 0 | L8: =$F8 * ( L$3 = start_date ) -> 0 | M8: =$F8 * ( M$3 = start_date ) -> 0 | N8: =$F8 * ( N$3 = start_date ) -> 0 | O8: =$F8 * ( O$3 = start_date ) -> 0 | P8: =$F8 * ( P$3 = start_date ) -> 0 | Q8: =$F8 * ( Q$3 = start_date ) -> 0 | ... DY8: =$F8 * ( DY$3 = start_date ) -> 0
E9: Senior Facility Initial Drawdown | F9: 10000000 | G9: USD | J9: =$F9 * ( J$3 = start_date ) -> 0 | K9: =$F9 * ( K$3 = start_date ) -> 0 | L9: =$F9 * ( L$3 = start_date ) -> 0 | M9: =$F9 * ( M$3 = start_date ) -> 0 | N9: =$F9 * ( N$3 = start_date ) -> 0 | O9: =$F9 * ( O$3 = start_date ) -> 0 | P9: =$F9 * ( P$3 = start_date ) -> 0 | Q9: =$F9 * ( Q$3 = start_date ) -> 0 | ... DY9: =$F9 * ( DY$3 = start_date ) -> 0
E10: Junior Facility Drawdown | F10: =CaseData!$G$36 -> 3000000 | G10: USD | J10: =$F10 * ( J$3 = start_date ) -> 0 | K10: =$F10 * ( K$3 = start_date ) -> 0 | L10: =$F10 * ( L$3 = start_date ) -> 0 | M10: =$F10 * ( M$3 = start_date ) -> 0 | N10: =$F10 * ( N$3 = start_date ) -> 0 | O10: =$F10 * ( O$3 = start_date ) -> 0 | P10: =$F10 * ( P$3 = start_date ) -> 0 | Q10: =$F10 * ( Q$3 = start_date ) -> 0 | ... DY10: =$F10 * ( DY$3 = start_date ) -> 0
E11: Acquisition of Asset | F11: =CaseData!$G$8 * - 1 -> -18000000 | G11: USD | J11: =$F11 * ( J$3 = start_date ) -> 0 | K11: =$F11 * ( K$3 = start_date ) -> 0 | L11: =$F11 * ( L$3 = start_date ) -> 0 | M11: =$F11 * ( M$3 = start_date ) -> 0 | N11: =$F11 * ( N$3 = start_date ) -> 0 | O11: =$F11 * ( O$3 = start_date ) -> 0 | P11: =$F11 * ( P$3 = start_date ) -> 0 | Q11: =$F11 * ( Q$3 = start_date ) -> 0 | ... DY11: =$F11 * ( DY$3 = start_date ) -> 0
E12: Senior Facility interest paid | G12: USD | H12: =H$47 -> -8509627.8 | J12: =J$47 -> -125000 | K12: =K$47 -> -124365.72 | L12: =L$47 -> -123723.5 | M12: =M$47 -> -123073.26 | N12: =N$47 -> -122414.89 | O12: =O$47 -> -121748.29 | P12: =P$47 -> -121073.36 | Q12: =Q$47 -> -120389.99 | ... DY12: =DY$47 -> 0
E13: Senior Facility scheduled principal payments | G13: USD | H13: =H$47 -> -8509627.8 | J13: =J48 -> -50742.788 | K13: =K48 -> -51377.072 | L13: =L48 -> -52019.286 | M13: =M48 -> -52669.527 | N13: =N48 -> -53327.896 | O13: =O48 -> -53994.495 | P13: =P48 -> -54669.426 | Q13: =Q48 -> -55352.794 | ... DY13: =DY48 -> 0
E14: Senior Facility bullet repayment on refinance | G14: USD | H14: =H$47 -> -8509627.8 | J14: =J$49 -> 0 | K14: =K$49 -> 0 | L14: =L$49 -> 0 | M14: =M$49 -> 0 | N14: =N$49 -> 0 | O14: =O$49 -> 0 | P14: =P$49 -> 0 | Q14: =Q$49 -> 0 | ... DY14: =DY$49 -> 0
E15: Senior Facility refinance drawdown | G15: USD | H15: =H$47 -> -8509627.8 | J15: =J$50 -> 0 | K15: =K$50 -> 0 | L15: =L$50 -> 0 | M15: =M$50 -> 0 | N15: =N$50 -> 0 | O15: =O$50 -> 0 | P15: =P$50 -> 0 | Q15: =Q$50 -> 0 | ... DY15: =DY$50 -> 0
E16: =E$74 -> Junior Facility interest paid | G16: =G$74 -> USD | H16: =H$74 -> -3285000 | I16: =I$74 -> 0 | J16: =J$74 -> -56250 | K16: =K$74 -> -55747.768 | L16: =L$74 -> -55245.536 | M16: =M$74 -> -54743.304 | N16: =N$74 -> -54241.071 | ... DY16: =DY$74 -> 0
E17: =E75 -> Junior Facility scheduled principal repayment | G17: =G75 -> USD | H17: =H75 -> 3000000 | J17: =J75 -> -26785.714 | K17: =K75 -> -26785.714 | L17: =L75 -> -26785.714 | M17: =M75 -> -26785.714 | N17: =N75 -> -26785.714 | O17: =O75 -> -26785.714 | P17: =P75 -> -26785.714 | Q17: =Q75 -> -26785.714 | ... DY17: =DY75 -> 0
E18: Terminal Value of Asset | F18: =CaseData!$G$9 -> 25000000 | G18: USD | H18: {=_xlfn.BYROW( J18:DY18, _xleta.SUM )} -> 25000000 | J18: =$F$18 * ( J$3 = end_date ) -> 0 | K18: =$F$18 * ( K$3 = end_date ) -> 0 | L18: =$F$18 * ( L$3 = end_date ) -> 0 | M18: =$F$18 * ( M$3 = end_date ) -> 0 | N18: =$F$18 * ( N$3 = end_date ) -> 0 | O18: =$F$18 * ( O$3 = end_date ) -> 0 | P18: =$F$18 * ( P$3 = end_date ) -> 0 | Q18: =$F$18 * ( Q$3 = end_date ) -> 0 | ... DY18: =$F$18 * ( DY$3 = end_date ) -> 25000000
E19: Subtotal: Available for distributions | F19: =SUM(F7:F18) -> 25000000 | G19: USD | J19: {=_xlfn.BYCOL( J7:DY18, _xleta.SUM )} -> 91221.498 | K19: 91723.73 | L19: 92225.962 | M19: 92728.195 | N19: 93230.427 | O19: 93732.659 | P19: 94234.891 | Q19: 94737.123 | R19: 95239.355 | S19: 95741.587 | T19: 96243.82 | U19: 96746.052 | V19: 97248.284 | W19: 97750.516 | X19: 98252.748 | Y19: 98754.98 | Z19: 99257.212 | AA19: 99759.445 | AB19: 100261.68 | AC19: 763630.76 | AD19: 116202.47 | AE19: 116704.71 | AF19: 117206.94 | AG19: 117709.17 | AH19: 118211.4 | AI19: 118713.63 | AJ19: 119215.87 | AK19: 119718.1 | AL19: 117407.83 | AM19: 117943.54 | AN19: 118479.26 | AO19: 119014.97 | AP19: 119550.69 | AQ19: 120086.4 | AR19: 120622.12 | AS19: 121157.83 | AT19: 121693.54 | AU19: 122229.26 | AV19: 122764.97 | AW19: 744365.17 | AX19: 126984.74 | AY19: 127520.45 | AZ19: 128056.17 | BA19: 128591.88 | BB19: 129127.6 | BC19: 129663.31 | BD19: 130199.03 | BE19: 130734.74 | BF19: 131270.45 | BG19: 131806.17 | BH19: 132341.88 | BI19: 132877.6 | BJ19: 133413.31 | BK19: 133949.03 | BL19: 134484.74 | BM19: 135020.45 | BN19: 137431.17 | BO19: 137933.4 | BP19: 138435.63 | BQ19: 480912.57 | BR19: 176315.96 | BS19: 176818.19 | BT19: 177320.42 | BU19: 177822.66 | BV19: 178324.89 | BW19: 178827.12 | BX19: 179329.35 | BY19: 179831.58 | BZ19: 180333.82 | CA19: 180836.05 | CB19: 181338.28 | CC19: 181840.51 | CD19: 182342.74 | CE19: 182844.98 | CF19: 183347.21 | CG19: 183849.44 | CH19: 184351.67 | CI19: 184853.91 | CJ19: 185356.14 | CK19: 674560.73 | CL19: 206081.73 | CM19: 206583.96 | CN19: 207086.2 | CO19: 207588.43 | CP19: 205278.16 | CQ19: 205880.84 | CR19: 206483.52 | CS19: 207086.2 | CT19: 207688.87 | CU19: 208291.55 | CV19: 208894.23 | CW19: 209496.91 | CX19: 210099.59 | CY19: 210702.27 | CZ19: 211304.95 | DA19: 211907.62 | DB19: 212510.3 | DC19: 213112.98 | DD19: 213715.66 | DE19: 214318.34 | DF19: 465982.14 | DG19: 466584.82 | DH19: 467187.5 | DI19: 467790.18 | DJ19: 468392.86 | DK19: 468995.54 | DL19: 469598.21 | DM19: 470200.89 | DN19: 470803.57 | DO19: 471406.25 | DP19: 472008.93 | DQ19: 472611.61 | DR19: 500000 | DS19: 500000 | DT19: 500000 | DU19: 500000 | DV19: 500000 | DW19: 500000 | DX19: 500000 | DY19: 25500000
E20: Distributions paid | G20: USD | J20: =J$19 * - 1 -> -91221.498 | K20: =K$19 * - 1 -> -91723.73 | L20: =L$19 * - 1 -> -92225.962 | M20: =M$19 * - 1 -> -92728.195 | N20: =N$19 * - 1 -> -93230.427 | O20: =O$19 * - 1 -> -93732.659 | P20: =P$19 * - 1 -> -94234.891 | Q20: =Q$19 * - 1 -> -94737.123 | ... DY20: =DY$19 * - 1 -> -25500000
E21: Net cash flow for period (should be zero) | G21: USD | H21: {=_xlfn.BYROW(_xlfn.ANCHORARRAY( J21), _xleta.SUM )} -> 0 | J21: {=_xlfn.BYCOL( J19:DY20, _xleta.SUM )} -> 0 | K21: 0 | L21: 0 | M21: 0 | N21: 0 | O21: 0 | P21: 0 | Q21: 0 | R21: 0 | S21: 0 | T21: 0 | U21: 0 | V21: 0 | W21: 0 | X21: 0 | Y21: 0 | Z21: 0 | AA21: 0 | AB21: 0 | AC21: 0 | AD21: 0 | AE21: 0 | AF21: 0 | AG21: 0 | AH21: 0 | AI21: 0 | AJ21: 0 | AK21: 0 | AL21: 0 | AM21: 0 | AN21: 0 | AO21: 0 | AP21: 0 | AQ21: 0 | AR21: 0 | AS21: 0 | AT21: 0 | AU21: 0 | AV21: 0 | AW21: 0 | AX21: 0 | AY21: 0 | AZ21: 0 | BA21: 0 | BB21: 0 | BC21: 0 | BD21: 0 | BE21: 0 | BF21: 0 | BG21: 0 | BH21: 0 | BI21: 0 | BJ21: 0 | BK21: 0 | BL21: 0 | BM21: 0 | BN21: 0 | BO21: 0 | BP21: 0 | BQ21: 0 | BR21: 0 | BS21: 0 | BT21: 0 | BU21: 0 | BV21: 0 | BW21: 0 | BX21: 0 | BY21: 0 | BZ21: 0 | CA21: 0 | CB21: 0 | CC21: 0 | CD21: 0 | CE21: 0 | CF21: 0 | CG21: 0 | CH21: 0 | CI21: 0 | CJ21: 0 | CK21: 0 | CL21: 0 | CM21: 0 | CN21: 0 | CO21: 0 | CP21: 0 | CQ21: 0 | CR21: 0 | CS21: 0 | CT21: 0 | CU21: 0 | CV21: 0 | CW21: 0 | CX21: 0 | CY21: 0 | CZ21: 0 | DA21: 0 | DB21: 0 | DC21: 0 | DD21: 0 | DE21: 0 | DF21: 0 | DG21: 0 | DH21: 0 | DI21: 0 | DJ21: 0 | DK21: 0 | DL21: 0 | DM21: 0 | DN21: 0 | DO21: 0 | DP21: 0 | DQ21: 0 | DR21: 0 | DS21: 0 | DT21: 0 | DU21: 0 | DV21: 0 | DW21: 0 | DX21: 0 | DY21: 0
E22: Check subtotal available for dist's is not negative
A25: Refinancing calculations
B27: DSCR
E28: Target DSCR after each refinance | F28: =_xlfn.LET( _xlpm.rate, CaseData!$G$19 / 4, _xlpm.nper, CaseData!$G$20 * 4, _xlpm.pv, CaseData!$G$17, _xlpm.cfads, CaseData!$G$14, _xlpm.cfads / PMT( _xlpm.rate, _xlpm.nper, _xlpm.pv ) * - 1 ) -> 1.9915469 | G28: multiple
E29: Actual DSCR | G29: multiple | J29: =_xlfn.LET( _xlpm.cfads, J$7, _xlpm.interest, J$12, _xlpm.principal, J$13, IF( _xlpm.interest + _xlpm.principal = 0, 0, _xlpm.cfads / ( _xlpm.interest + _xlpm.principal ) * - 1 ) ) -> 1.9915469 | K29: =_xlfn.LET( _xlpm.cfads, K$7, _xlpm.interest, K$12, _xlpm.principal, K$13, IF( _xlpm.interest + _xlpm.principal = 0, 0, _xlpm.cfads / ( _xlpm.interest + _xlpm.principal ) * - 1 ) ) -> 1.9915469 | L29: =_xlfn.LET( _xlpm.cfads, L$7, _xlpm.interest, L$12, _xlpm.principal, L$13, IF( _xlpm.interest + _xlpm.principal = 0, 0, _xlpm.cfads / ( _xlpm.interest + _xlpm.principal ) * - 1 ) ) -> 1.9915469 | M29: =_xlfn.LET( _xlpm.cfads, M$7, _xlpm.interest, M$12, _xlpm.principal, M$13, IF( _xlpm.interest + _xlpm.principal = 0, 0, _xlpm.cfads / ( _xlpm.interest + _xlpm.principal ) * - 1 ) ) -> 1.9915469 | N29: =_xlfn.LET( _xlpm.cfads, N$7, _xlpm.interest, N$12, _xlpm.principal, N$13, IF( _xlpm.interest + _xlpm.principal = 0, 0, _xlpm.cfads / ( _xlpm.interest + _xlpm.principal ) * - 1 ) ) -> 1.9915469 | O29: =_xlfn.LET( _xlpm.cfads, O$7, _xlpm.interest, O$12, _xlpm.principal, O$13, IF( _xlpm.interest + _xlpm.principal = 0, 0, _xlpm.cfads / ( _xlpm.interest + _xlpm.principal ) * - 1 ) ) -> 1.9915469 | P29: =_xlfn.LET( _xlpm.cfads, P$7, _xlpm.interest, P$12, _xlpm.principal, P$13, IF( _xlpm.interest + _xlpm.principal = 0, 0, _xlpm.cfads / ( _xlpm.interest + _xlpm.principal ) * - 1 ) ) -> 1.9915469 | Q29: =_xlfn.LET( _xlpm.cfads, Q$7, _xlpm.interest, Q$12, _xlpm.principal, Q$13, IF( _xlpm.interest + _xlpm.principal = 0, 0, _xlpm.cfads / ( _xlpm.interest + _xlpm.principal ) * - 1 ) ) -> 1.9915469 | ... DY29: =_xlfn.LET( _xlpm.cfads, DY$7, _xlpm.interest, DY$12, _xlpm.principal, DY$13, IF( _xlpm.interest + _xlpm.principal = 0, 0, _xlpm.cfads / ( _xlpm.interest + _xlpm.principal ) * - 1 ) ) -> 0
B32: Refinance sizing
E33: =E$7 -> CFADS | G33: =G$7 -> USD | H33: =H$7 -> 51600000 | I33: =I$7 -> 0 | J33: =J$7 -> 350000 | K33: =K$7 -> 350000 | L33: =L$7 -> 350000 | M33: =M$7 -> 350000 | N33: =N$7 -> 350000 | ... DY33: =DY$7 -> 500000
E34: Required Senior Facility Debt Service | G34: USD | J34: =J$33 / $F$28 -> 175742.79 | K34: =K$33 / $F$28 -> 175742.79 | L34: =L$33 / $F$28 -> 175742.79 | M34: =M$33 / $F$28 -> 175742.79 | N34: =N$33 / $F$28 -> 175742.79 | O34: =O$33 / $F$28 -> 175742.79 | P34: =P$33 / $F$28 -> 175742.79 | Q34: =Q$33 / $F$28 -> 175742.79 | ... DY34: =DY$33 / $F$28 -> 251061.13
E35: Senior Facilty interest in force | G35: % | J35: =IF( Time!J$47 = 0, CaseData!$G$19, _xlfn.XLOOKUP( J$3, CaseData!$G$27:$J$27, CaseData!$G$29:$J$29,, -1 ) ) / 4 -> 0.0125 | K35: =IF( Time!K$47 = 0, CaseData!$G$19, _xlfn.XLOOKUP( K$3, CaseData!$G$27:$J$27, CaseData!$G$29:$J$29,, -1 ) ) / 4 -> 0.0125 | L35: =IF( Time!L$47 = 0, CaseData!$G$19, _xlfn.XLOOKUP( L$3, CaseData!$G$27:$J$27, CaseData!$G$29:$J$29,, -1 ) ) / 4 -> 0.0125 | M35: =IF( Time!M$47 = 0, CaseData!$G$19, _xlfn.XLOOKUP( M$3, CaseData!$G$27:$J$27, CaseData!$G$29:$J$29,, -1 ) ) / 4 -> 0.0125 | N35: =IF( Time!N$47 = 0, CaseData!$G$19, _xlfn.XLOOKUP( N$3, CaseData!$G$27:$J$27, CaseData!$G$29:$J$29,, -1 ) ) / 4 -> 0.0125 | O35: =IF( Time!O$47 = 0, CaseData!$G$19, _xlfn.XLOOKUP( O$3, CaseData!$G$27:$J$27, CaseData!$G$29:$J$29,, -1 ) ) / 4 -> 0.0125 | P35: =IF( Time!P$47 = 0, CaseData!$G$19, _xlfn.XLOOKUP( P$3, CaseData!$G$27:$J$27, CaseData!$G$29:$J$29,, -1 ) ) / 4 -> 0.0125 | Q35: =IF( Time!Q$47 = 0, CaseData!$G$19, _xlfn.XLOOKUP( Q$3, CaseData!$G$27:$J$27, CaseData!$G$29:$J$29,, -1 ) ) / 4 -> 0.0125 | ... DY35: =IF( Time!DY$47 = 0, CaseData!$G$19, _xlfn.XLOOKUP( DY$3, CaseData!$G$27:$J$27, CaseData!$G$29:$J$29,, -1 ) ) / 4 -> 0.0125
E36: Senior Facility implied opening balance | G36: USD | J36: =PV( J$35, Time!J$32, Cashflow!J$34 ) * - 1 -> 10000000 | K36: =PV( K$35, Time!K$32, Cashflow!K$34 ) * - 1 -> 9949257.2 | L36: =PV( L$35, Time!L$32, Cashflow!L$34 ) * - 1 -> 9897880.1 | M36: =PV( M$35, Time!M$32, Cashflow!M$34 ) * - 1 -> 9845860.9 | N36: =PV( N$35, Time!N$32, Cashflow!N$34 ) * - 1 -> 9793191.3 | O36: =PV( O$35, Time!O$32, Cashflow!O$34 ) * - 1 -> 9739863.4 | P36: =PV( P$35, Time!P$32, Cashflow!P$34 ) * - 1 -> 9685868.9 | Q36: =PV( Q$35, Time!Q$32, Cashflow!Q$34 ) * - 1 -> 9631199.5 | ... DY36: =PV( DY$35, Time!DY$32, Cashflow!DY$34 ) * - 1 -> 0
E37: Target Senior Facilty closing balance (including fee) | G37: USD | J37: =IF( Time!J$40, Cashflow!K$36, 0 ) -> 0 | K37: =IF( Time!K$40, Cashflow!L$36, 0 ) -> 0 | L37: =IF( Time!L$40, Cashflow!M$36, 0 ) -> 0 | M37: =IF( Time!M$40, Cashflow!N$36, 0 ) -> 0 | N37: =IF( Time!N$40, Cashflow!O$36, 0 ) -> 0 | O37: =IF( Time!O$40, Cashflow!P$36, 0 ) -> 0 | P37: =IF( Time!P$40, Cashflow!Q$36, 0 ) -> 0 | Q37: =IF( Time!Q$40, Cashflow!R$36, 0 ) -> 0 | ... DY37: =IF( Time!DY$40, Cashflow!DZ$36, 0 ) -> 0
E38: Senior Facility refinance free | G38: USD | J38: =J$37 * _xlfn.XLOOKUP( J$3, CaseData!$G$27:$J$27, CaseData!$G$28:$J$28, 0 ) -> 0 | K38: =K$37 * _xlfn.XLOOKUP( K$3, CaseData!$G$27:$J$27, CaseData!$G$28:$J$28, 0 ) -> 0 | L38: =L$37 * _xlfn.XLOOKUP( L$3, CaseData!$G$27:$J$27, CaseData!$G$28:$J$28, 0 ) -> 0 | M38: =M$37 * _xlfn.XLOOKUP( M$3, CaseData!$G$27:$J$27, CaseData!$G$28:$J$28, 0 ) -> 0 | N38: =N$37 * _xlfn.XLOOKUP( N$3, CaseData!$G$27:$J$27, CaseData!$G$28:$J$28, 0 ) -> 0 | O38: =O$37 * _xlfn.XLOOKUP( O$3, CaseData!$G$27:$J$27, CaseData!$G$28:$J$28, 0 ) -> 0 | P38: =P$37 * _xlfn.XLOOKUP( P$3, CaseData!$G$27:$J$27, CaseData!$G$28:$J$28, 0 ) -> 0 | Q38: =Q$37 * _xlfn.XLOOKUP( Q$3, CaseData!$G$27:$J$27, CaseData!$G$28:$J$28, 0 ) -> 0 | ... DY38: =DY$37 * _xlfn.XLOOKUP( DY$3, CaseData!$G$27:$J$27, CaseData!$G$28:$J$28, 0 ) -> 0
E39: Senior Facility closing balance (after fee consideration) | G39: USD | J39: =J$37 - J$38 -> 0 | K39: =K$37 - K$38 -> 0 | L39: =L$37 - L$38 -> 0 | M39: =M$37 - M$38 -> 0 | N39: =N$37 - N$38 -> 0 | O39: =O$37 - O$38 -> 0 | P39: =P$37 - P$38 -> 0 | Q39: =Q$37 - Q$38 -> 0 | ... DY39: =DY$37 - DY$38 -> 0
A41: Senior Facility
B43: Senior Facility | F43: =start_date -> 44196
E44: Senior Facility opening balance | G44: USD | J44: =IF( Time!J$15 = 1, Cashflow!$F$45, Cashflow!I$52 ) -> 10000000 | K44: =IF( Time!K$15 = 1, Cashflow!$F$45, Cashflow!J$52 ) -> 9949257.2 | L44: =IF( Time!L$15 = 1, Cashflow!$F$45, Cashflow!K$52 ) -> 9897880.1 | M44: =IF( Time!M$15 = 1, Cashflow!$F$45, Cashflow!L$52 ) -> 9845860.9 | N44: =IF( Time!N$15 = 1, Cashflow!$F$45, Cashflow!M$52 ) -> 9793191.3 | O44: =IF( Time!O$15 = 1, Cashflow!$F$45, Cashflow!N$52 ) -> 9739863.4 | P44: =IF( Time!P$15 = 1, Cashflow!$F$45, Cashflow!O$52 ) -> 9685868.9 | Q44: =IF( Time!Q$15 = 1, Cashflow!$F$45, Cashflow!P$52 ) -> 9631199.5 | ... DY44: =IF( Time!DY$15 = 1, Cashflow!$F$45, Cashflow!DX$52 ) -> 0
D45: add | E45: Senior Facility initial drawdown | F45: =CaseData!$G$17 -> 10000000 | G45: USD | J45: =$F$45 * ( J$3 = start_date ) -> 0 | K45: =$F$45 * ( K$3 = start_date ) -> 0 | L45: =$F$45 * ( L$3 = start_date ) -> 0 | M45: =$F$45 * ( M$3 = start_date ) -> 0 | N45: =$F$45 * ( N$3 = start_date ) -> 0 | O45: =$F$45 * ( O$3 = start_date ) -> 0 | P45: =$F$45 * ( P$3 = start_date ) -> 0 | Q45: =$F$45 * ( Q$3 = start_date ) -> 0 | ... DY45: =$F$45 * ( DY$3 = start_date ) -> 0
D46: add | E46: Senior Facility scheduled interest payments | G46: USD | J46: =J$57 -> 125000 | K46: =K$57 -> 124365.72 | L46: =L$57 -> 123723.5 | M46: =M$57 -> 123073.26 | N46: =N$57 -> 122414.89 | O46: =O$57 -> 121748.29 | P46: =P$57 -> 121073.36 | Q46: =Q$57 -> 120389.99 | ... DY46: =DY$57 -> 0
D47: less | E47: Senior Facility interest paid | G47: USD | H47: {=_xlfn.BYROW( J47:DY47, _xleta.SUM )} -> -8509627.8 | J47: =J$46 * - 1 -> -125000 | K47: =K$46 * - 1 -> -124365.72 | L47: =L$46 * - 1 -> -123723.5 | M47: =M$46 * - 1 -> -123073.26 | N47: =N$46 * - 1 -> -122414.89 | O47: =O$46 * - 1 -> -121748.29 | P47: =P$46 * - 1 -> -121073.36 | Q47: =Q$46 * - 1 -> -120389.99 | ... DY47: =DY$46 * - 1 -> 0
D48: less | E48: Senior Facility scheduled principal payments | G48: USD | H48: {=_xlfn.BYROW( J48:DY48, _xleta.SUM )} -> -12411387 | J48: =J$60 * - 1 -> -50742.788 | K48: =K$60 * - 1 -> -51377.072 | L48: =L$60 * - 1 -> -52019.286 | M48: =M$60 * - 1 -> -52669.527 | N48: =N$60 * - 1 -> -53327.896 | O48: =O$60 * - 1 -> -53994.495 | P48: =P$60 * - 1 -> -54669.426 | Q48: =Q$60 * - 1 -> -55352.794 | ... DY48: =DY$60 * - 1 -> 0
...

Sheet Time
A1: {=company} -> Investment Fund Asset
A2: {=topic} -> CFM Topic: | J2: {=_xlfn.ANCHORARRAY($J$11)} -> 44197 | K2: 44287 | L2: 44378 | M2: 44470 | N2: 44562 | O2: 44652 | P2: 44743 | Q2: 44835 | R2: 44927 | S2: 45017 | T2: 45108 | U2: 45200 | V2: 45292 | W2: 45383 | X2: 45474 | Y2: 45566 | Z2: 45658 | AA2: 45748 | AB2: 45839 | AC2: 45931 | AD2: 46023 | AE2: 46113 | AF2: 46204 | AG2: 46296 | AH2: 46388 | AI2: 46478 | AJ2: 46569 | AK2: 46661 | AL2: 46753 | AM2: 46844 | AN2: 46935 | AO2: 47027 | AP2: 47119 | AQ2: 47209 | AR2: 47300 | AS2: 47392 | AT2: 47484 | AU2: 47574 | AV2: 47665 | AW2: 47757 | AX2: 47849 | AY2: 47939 | AZ2: 48030 | BA2: 48122 | BB2: 48214 | BC2: 48305 | BD2: 48396 | BE2: 48488 | BF2: 48580 | BG2: 48670 | BH2: 48761 | BI2: 48853 | BJ2: 48945 | BK2: 49035 | BL2: 49126 | BM2: 49218 | BN2: 49310 | BO2: 49400 | BP2: 49491 | BQ2: 49583 | BR2: 49675 | BS2: 49766 | BT2: 49857 | BU2: 49949 | BV2: 50041 | BW2: 50131 | BX2: 50222 | BY2: 50314 | BZ2: 50406 | CA2: 50496 | CB2: 50587 | CC2: 50679 | CD2: 50771 | CE2: 50861 | CF2: 50952 | CG2: 51044 | CH2: 51136 | CI2: 51227 | CJ2: 51318 | CK2: 51410 | CL2: 51502 | CM2: 51592 | CN2: 51683 | CO2: 51775 | CP2: 51867 | CQ2: 51957 | CR2: 52048 | CS2: 52140 | CT2: 52232 | CU2: 52322 | CV2: 52413 | CW2: 52505 | CX2: 52597 | CY2: 52688 | CZ2: 52779 | DA2: 52871 | DB2: 52963 | DC2: 53053 | DD2: 53144 | DE2: 53236 | DF2: 53328 | DG2: 53418 | DH2: 53509 | DI2: 53601 | DJ2: 53693 | DK2: 53783 | DL2: 53874 | DM2: 53966 | DN2: 54058 | DO2: 54149 | DP2: 54240 | DQ2: 54332 | DR2: 54424 | DS2: 54514 | DT2: 54605 | DU2: 54697 | DV2: 54789 | DW2: 54879 | DX2: 54970 | DY2: 55062
A3: TIME SCHEDULE | F3: Constant | G3: Unit | H3: Total | J3: {=_xlfn.ANCHORARRAY($J$12)} -> 44286 | K3: 44377 | L3: 44469 | M3: 44561 | N3: 44651 | O3: 44742 | P3: 44834 | Q3: 44926 | R3: 45016 | S3: 45107 | T3: 45199 | U3: 45291 | V3: 45382 | W3: 45473 | X3: 45565 | Y3: 45657 | Z3: 45747 | AA3: 45838 | AB3: 45930 | AC3: 46022 | AD3: 46112 | AE3: 46203 | AF3: 46295 | AG3: 46387 | AH3: 46477 | AI3: 46568 | AJ3: 46660 | AK3: 46752 | AL3: 46843 | AM3: 46934 | AN3: 47026 | AO3: 47118 | AP3: 47208 | AQ3: 47299 | AR3: 47391 | AS3: 47483 | AT3: 47573 | AU3: 47664 | AV3: 47756 | AW3: 47848 | AX3: 47938 | AY3: 48029 | AZ3: 48121 | BA3: 48213 | BB3: 48304 | BC3: 48395 | BD3: 48487 | BE3: 48579 | BF3: 48669 | BG3: 48760 | BH3: 48852 | BI3: 48944 | BJ3: 49034 | BK3: 49125 | BL3: 49217 | BM3: 49309 | BN3: 49399 | BO3: 49490 | BP3: 49582 | BQ3: 49674 | BR3: 49765 | BS3: 49856 | BT3: 49948 | BU3: 50040 | BV3: 50130 | BW3: 50221 | BX3: 50313 | BY3: 50405 | BZ3: 50495 | CA3: 50586 | CB3: 50678 | CC3: 50770 | CD3: 50860 | CE3: 50951 | CF3: 51043 | CG3: 51135 | CH3: 51226 | CI3: 51317 | CJ3: 51409 | CK3: 51501 | CL3: 51591 | CM3: 51682 | CN3: 51774 | CO3: 51866 | CP3: 51956 | CQ3: 52047 | CR3: 52139 | CS3: 52231 | CT3: 52321 | CU3: 52412 | CV3: 52504 | CW3: 52596 | CX3: 52687 | CY3: 52778 | CZ3: 52870 | DA3: 52962 | DB3: 53052 | DC3: 53143 | DD3: 53235 | DE3: 53327 | DF3: 53417 | DG3: 53508 | DH3: 53600 | DI3: 53692 | DJ3: 53782 | DK3: 53873 | DL3: 53965 | DM3: 54057 | DN3: 54148 | DO3: 54239 | DP3: 54331 | DQ3: 54423 | DR3: 54513 | DS3: 54604 | DT3: 54696 | DU3: 54788 | DV3: 54878 | DW3: 54969 | DX3: 55061 | DY3: 55153
A5: Model timeline
E7: Model start date | F7: =start_date -> 44196 | G7: date
E8: Number of years in the model | F8: =CaseData!$G$6 -> 30 | G8: years
E9: Number of quarters in the model | F9: =$F$8 * 4 -> 120 | G9: quarters
E11: Model period beginning | G11: date | J11: {=EDATE( start_date + 1, _xlfn.SEQUENCE( 1, quarters, 0, 3 ) )} -> 44197 | K11: 44287 | L11: 44378 | M11: 44470 | N11: 44562 | O11: 44652 | P11: 44743 | Q11: 44835 | R11: 44927 | S11: 45017 | T11: 45108 | U11: 45200 | V11: 45292 | W11: 45383 | X11: 45474 | Y11: 45566 | Z11: 45658 | AA11: 45748 | AB11: 45839 | AC11: 45931 | AD11: 46023 | AE11: 46113 | AF11: 46204 | AG11: 46296 | AH11: 46388 | AI11: 46478 | AJ11: 46569 | AK11: 46661 | AL11: 46753 | AM11: 46844 | AN11: 46935 | AO11: 47027 | AP11: 47119 | AQ11: 47209 | AR11: 47300 | AS11: 47392 | AT11: 47484 | AU11: 47574 | AV11: 47665 | AW11: 47757 | AX11: 47849 | AY11: 47939 | AZ11: 48030 | BA11: 48122 | BB11: 48214 | BC11: 48305 | BD11: 48396 | BE11: 48488 | BF11: 48580 | BG11: 48670 | BH11: 48761 | BI11: 48853 | BJ11: 48945 | BK11: 49035 | BL11: 49126 | BM11: 49218 | BN11: 49310 | BO11: 49400 | BP11: 49491 | BQ11: 49583 | BR11: 49675 | BS11: 49766 | BT11: 49857 | BU11: 49949 | BV11: 50041 | BW11: 50131 | BX11: 50222 | BY11: 50314 | BZ11: 50406 | CA11: 50496 | CB11: 50587 | CC11: 50679 | CD11: 50771 | CE11: 50861 | CF11: 50952 | CG11: 51044 | CH11: 51136 | CI11: 51227 | CJ11: 51318 | CK11: 51410 | CL11: 51502 | CM11: 51592 | CN11: 51683 | CO11: 51775 | CP11: 51867 | CQ11: 51957 | CR11: 52048 | CS11: 52140 | CT11: 52232 | CU11: 52322 | CV11: 52413 | CW11: 52505 | CX11: 52597 | CY11: 52688 | CZ11: 52779 | DA11: 52871 | DB11: 52963 | DC11: 53053 | DD11: 53144 | DE11: 53236 | DF11: 53328 | DG11: 53418 | DH11: 53509 | DI11: 53601 | DJ11: 53693 | DK11: 53783 | DL11: 53874 | DM11: 53966 | DN11: 54058 | DO11: 54149 | DP11: 54240 | DQ11: 54332 | DR11: 54424 | DS11: 54514 | DT11: 54605 | DU11: 54697 | DV11: 54789 | DW11: 54879 | DX11: 54970 | DY11: 55062
E12: Model period ending | G12: date | J12: {=EOMONTH( start_date, _xlfn.SEQUENCE( 1, quarters, 3, 3 ) )} -> 44286 | K12: 44377 | L12: 44469 | M12: 44561 | N12: 44651 | O12: 44742 | P12: 44834 | Q12: 44926 | R12: 45016 | S12: 45107 | T12: 45199 | U12: 45291 | V12: 45382 | W12: 45473 | X12: 45565 | Y12: 45657 | Z12: 45747 | AA12: 45838 | AB12: 45930 | AC12: 46022 | AD12: 46112 | AE12: 46203 | AF12: 46295 | AG12: 46387 | AH12: 46477 | AI12: 46568 | AJ12: 46660 | AK12: 46752 | AL12: 46843 | AM12: 46934 | AN12: 47026 | AO12: 47118 | AP12: 47208 | AQ12: 47299 | AR12: 47391 | AS12: 47483 | AT12: 47573 | AU12: 47664 | AV12: 47756 | AW12: 47848 | AX12: 47938 | AY12: 48029 | AZ12: 48121 | BA12: 48213 | BB12: 48304 | BC12: 48395 | BD12: 48487 | BE12: 48579 | BF12: 48669 | BG12: 48760 | BH12: 48852 | BI12: 48944 | BJ12: 49034 | BK12: 49125 | BL12: 49217 | BM12: 49309 | BN12: 49399 | BO12: 49490 | BP12: 49582 | BQ12: 49674 | BR12: 49765 | BS12: 49856 | BT12: 49948 | BU12: 50040 | BV12: 50130 | BW12: 50221 | BX12: 50313 | BY12: 50405 | BZ12: 50495 | CA12: 50586 | CB12: 50678 | CC12: 50770 | CD12: 50860 | CE12: 50951 | CF12: 51043 | CG12: 51135 | CH12: 51226 | CI12: 51317 | CJ12: 51409 | CK12: 51501 | CL12: 51591 | CM12: 51682 | CN12: 51774 | CO12: 51866 | CP12: 51956 | CQ12: 52047 | CR12: 52139 | CS12: 52231 | CT12: 52321 | CU12: 52412 | CV12: 52504 | CW12: 52596 | CX12: 52687 | CY12: 52778 | CZ12: 52870 | DA12: 52962 | DB12: 53052 | DC12: 53143 | DD12: 53235 | DE12: 53327 | DF12: 53417 | DG12: 53508 | DH12: 53600 | DI12: 53692 | DJ12: 53782 | DK12: 53873 | DL12: 53965 | DM12: 54057 | DN12: 54148 | DO12: 54239 | DP12: 54331 | DQ12: 54423 | DR12: 54513 | DS12: 54604 | DT12: 54696 | DU12: 54788 | DV12: 54878 | DW12: 54969 | DX12: 55061 | DY12: 55153
E14: Model period counter | G14: counter | H14: {=_xlfn.BYROW(_xlfn.ANCHORARRAY( J14), _xleta.MAX )} -> 120 | J14: {=_xlfn.SEQUENCE( 1, quarters, 1, 1 )} -> 1 | K14: 2 | L14: 3 | M14: 4 | N14: 5 | O14: 6 | P14: 7 | Q14: 8 | R14: 9 | S14: 10 | T14: 11 | U14: 12 | V14: 13 | W14: 14 | X14: 15 | Y14: 16 | Z14: 17 | AA14: 18 | AB14: 19 | AC14: 20 | AD14: 21 | AE14: 22 | AF14: 23 | AG14: 24 | AH14: 25 | AI14: 26 | AJ14: 27 | AK14: 28 | AL14: 29 | AM14: 30 | AN14: 31 | AO14: 32 | AP14: 33 | AQ14: 34 | AR14: 35 | AS14: 36 | AT14: 37 | AU14: 38 | AV14: 39 | AW14: 40 | AX14: 41 | AY14: 42 | AZ14: 43 | BA14: 44 | BB14: 45 | BC14: 46 | BD14: 47 | BE14: 48 | BF14: 49 | BG14: 50 | BH14: 51 | BI14: 52 | BJ14: 53 | BK14: 54 | BL14: 55 | BM14: 56 | BN14: 57 | BO14: 58 | BP14: 59 | BQ14: 60 | BR14: 61 | BS14: 62 | BT14: 63 | BU14: 64 | BV14: 65 | BW14: 66 | BX14: 67 | BY14: 68 | BZ14: 69 | CA14: 70 | CB14: 71 | CC14: 72 | CD14: 73 | CE14: 74 | CF14: 75 | CG14: 76 | CH14: 77 | CI14: 78 | CJ14: 79 | CK14: 80 | CL14: 81 | CM14: 82 | CN14: 83 | CO14: 84 | CP14: 85 | CQ14: 86 | CR14: 87 | CS14: 88 | CT14: 89 | CU14: 90 | CV14: 91 | CW14: 92 | CX14: 93 | CY14: 94 | CZ14: 95 | DA14: 96 | DB14: 97 | DC14: 98 | DD14: 99 | DE14: 100 | DF14: 101 | DG14: 102 | DH14: 103 | DI14: 104 | DJ14: 105 | DK14: 106 | DL14: 107 | DM14: 108 | DN14: 109 | DO14: 110 | DP14: 111 | DQ14: 112 | DR14: 113 | DS14: 114 | DT14: 115 | DU14: 116 | DV14: 117 | DW14: 118 | DX14: 119 | DY14: 120
E15: Model first period flag | G15: flag | H15: {=_xlfn.BYROW(_xlfn.ANCHORARRAY( J15), _xleta.MAX )} -> 1 | J15: {=IF(_xlfn.ANCHORARRAY( J14) = 1, 1, 0 )} -> 1 | K15: 0 | L15: 0 | M15: 0 | N15: 0 | O15: 0 | P15: 0 | Q15: 0 | R15: 0 | S15: 0 | T15: 0 | U15: 0 | V15: 0 | W15: 0 | X15: 0 | Y15: 0 | Z15: 0 | AA15: 0 | AB15: 0 | AC15: 0 | AD15: 0 | AE15: 0 | AF15: 0 | AG15: 0 | AH15: 0 | AI15: 0 | AJ15: 0 | AK15: 0 | AL15: 0 | AM15: 0 | AN15: 0 | AO15: 0 | AP15: 0 | AQ15: 0 | AR15: 0 | AS15: 0 | AT15: 0 | AU15: 0 | AV15: 0 | AW15: 0 | AX15: 0 | AY15: 0 | AZ15: 0 | BA15: 0 | BB15: 0 | BC15: 0 | BD15: 0 | BE15: 0 | BF15: 0 | BG15: 0 | BH15: 0 | BI15: 0 | BJ15: 0 | BK15: 0 | BL15: 0 | BM15: 0 | BN15: 0 | BO15: 0 | BP15: 0 | BQ15: 0 | BR15: 0 | BS15: 0 | BT15: 0 | BU15: 0 | BV15: 0 | BW15: 0 | BX15: 0 | BY15: 0 | BZ15: 0 | CA15: 0 | CB15: 0 | CC15: 0 | CD15: 0 | CE15: 0 | CF15: 0 | CG15: 0 | CH15: 0 | CI15: 0 | CJ15: 0 | CK15: 0 | CL15: 0 | CM15: 0 | CN15: 0 | CO15: 0 | CP15: 0 | CQ15: 0 | CR15: 0 | CS15: 0 | CT15: 0 | CU15: 0 | CV15: 0 | CW15: 0 | CX15: 0 | CY15: 0 | CZ15: 0 | DA15: 0 | DB15: 0 | DC15: 0 | DD15: 0 | DE15: 0 | DF15: 0 | DG15: 0 | DH15: 0 | DI15: 0 | DJ15: 0 | DK15: 0 | DL15: 0 | DM15: 0 | DN15: 0 | DO15: 0 | DP15: 0 | DQ15: 0 | DR15: 0 | DS15: 0 | DT15: 0 | DU15: 0 | DV15: 0 | DW15: 0 | DX15: 0 | DY15: 0
A17: CFADS
E19: =CaseData!C$5 -> Initial quarter end date | F19: =CaseData!G$5 -> 44286 | G19: date
E20: =CaseData!C$7 -> Final quarter end date (Project End Date) | F20: =end_date -> 55153 | G20: date
E22: CFADS period flag | G22: flag | H22: {=_xlfn.BYROW(_xlfn.ANCHORARRAY( J22), _xleta.SUM )} -> 120 | J22: {=_xlfn.LET( _xlpm.timeline_end,_xlfn.ANCHORARRAY( $J$3), _xlpm.initial, $F19, _xlpm.final, $F20, IF( (_xlpm.timeline_end >= _xlpm.initial) * (_xlpm.timeline_end <= _xlpm.final), 1, 0 ) )} -> 1 | K22: 1 | L22: 1 | M22: 1 | N22: 1 | O22: 1 | P22: 1 | Q22: 1 | R22: 1 | S22: 1 | T22: 1 | U22: 1 | V22: 1 | W22: 1 | X22: 1 | Y22: 1 | Z22: 1 | AA22: 1 | AB22: 1 | AC22: 1 | AD22: 1 | AE22: 1 | AF22: 1 | AG22: 1 | AH22: 1 | AI22: 1 | AJ22: 1 | AK22: 1 | AL22: 1 | AM22: 1 | AN22: 1 | AO22: 1 | AP22: 1 | AQ22: 1 | AR22: 1 | AS22: 1 | AT22: 1 | AU22: 1 | AV22: 1 | AW22: 1 | AX22: 1 | AY22: 1 | AZ22: 1 | BA22: 1 | BB22: 1 | BC22: 1 | BD22: 1 | BE22: 1 | BF22: 1 | BG22: 1 | BH22: 1 | BI22: 1 | BJ22: 1 | BK22: 1 | BL22: 1 | BM22: 1 | BN22: 1 | BO22: 1 | BP22: 1 | BQ22: 1 | BR22: 1 | BS22: 1 | BT22: 1 | BU22: 1 | BV22: 1 | BW22: 1 | BX22: 1 | BY22: 1 | BZ22: 1 | CA22: 1 | CB22: 1 | CC22: 1 | CD22: 1 | CE22: 1 | CF22: 1 | CG22: 1 | CH22: 1 | CI22: 1 | CJ22: 1 | CK22: 1 | CL22: 1 | CM22: 1 | CN22: 1 | CO22: 1 | CP22: 1 | CQ22: 1 | CR22: 1 | CS22: 1 | CT22: 1 | CU22: 1 | CV22: 1 | CW22: 1 | CX22: 1 | CY22: 1 | CZ22: 1 | DA22: 1 | DB22: 1 | DC22: 1 | DD22: 1 | DE22: 1 | DF22: 1 | DG22: 1 | DH22: 1 | DI22: 1 | DJ22: 1 | DK22: 1 | DL22: 1 | DM22: 1 | DN22: 1 | DO22: 1 | DP22: 1 | DQ22: 1 | DR22: 1 | DS22: 1 | DT22: 1 | DU22: 1 | DV22: 1 | DW22: 1 | DX22: 1 | DY22: 1
E23: CFADS table column counter | G23: counter | J23: {=_xlfn.LET( _xlpm.flag,_xlfn.ANCHORARRAY( J22), _xlpm.timeline, CaseData!$G$13:$K$13, IF( _xlpm.flag, _xlfn.XMATCH(_xlfn.ANCHORARRAY( J3), _xlpm.timeline, 1 ), 0 ) )} -> 1 | K23: 1 | L23: 1 | M23: 1 | N23: 1 | O23: 1 | P23: 1 | Q23: 1 | R23: 1 | S23: 1 | T23: 1 | U23: 1 | V23: 1 | W23: 1 | X23: 1 | Y23: 1 | Z23: 1 | AA23: 1 | AB23: 1 | AC23: 1 | AD23: 2 | AE23: 2 | AF23: 2 | AG23: 2 | AH23: 2 | AI23: 2 | AJ23: 2 | AK23: 2 | AL23: 2 | AM23: 2 | AN23: 2 | AO23: 2 | AP23: 2 | AQ23: 2 | AR23: 2 | AS23: 2 | AT23: 2 | AU23: 2 | AV23: 2 | AW23: 2 | AX23: 3 | AY23: 3 | AZ23: 3 | BA23: 3 | BB23: 3 | BC23: 3 | BD23: 3 | BE23: 3 | BF23: 3 | BG23: 3 | BH23: 3 | BI23: 3 | BJ23: 3 | BK23: 3 | BL23: 3 | BM23: 3 | BN23: 3 | BO23: 3 | BP23: 3 | BQ23: 3 | BR23: 4 | BS23: 4 | BT23: 4 | BU23: 4 | BV23: 4 | BW23: 4 | BX23: 4 | BY23: 4 | BZ23: 4 | CA23: 4 | CB23: 4 | CC23: 4 | CD23: 4 | CE23: 4 | CF23: 4 | CG23: 4 | CH23: 4 | CI23: 4 | CJ23: 4 | CK23: 4 | CL23: 5 | CM23: 5 | CN23: 5 | CO23: 5 | CP23: 5 | CQ23: 5 | CR23: 5 | CS23: 5 | CT23: 5 | CU23: 5 | CV23: 5 | CW23: 5 | CX23: 5 | CY23: 5 | CZ23: 5 | DA23: 5 | DB23: 5 | DC23: 5 | DD23: 5 | DE23: 5 | DF23: 5 | DG23: 5 | DH23: 5 | DI23: 5 | DJ23: 5 | DK23: 5 | DL23: 5 | DM23: 5 | DN23: 5 | DO23: 5 | DP23: 5 | DQ23: 5 | DR23: 5 | DS23: 5 | DT23: 5 | DU23: 5 | DV23: 5 | DW23: 5 | DX23: 5 | DY23: 5
A25: Senior Facility
C27: Term
E28: Senior Facility drawdown date | F28: =CaseData!$G$18 -> 44196 | G28: date
E29: Senior Facility maturity date | F29: =CaseData!$G$21 -> 53327 | G29: date
E30: Senior Facility period flag | G30: flag | H30: {=_xlfn.BYROW(_xlfn.ANCHORARRAY( J30), _xleta.SUM )} -> 100 | J30: {=_xlfn.LET( _xlpm.timeline_end,_xlfn.ANCHORARRAY( $J$3), _xlpm.initial, $F28, _xlpm.final, $F29, IF( (_xlpm.timeline_end >= _xlpm.initial) * (_xlpm.timeline_end <= _xlpm.final), 1, 0 ) )} -> 1 | K30: 1 | L30: 1 | M30: 1 | N30: 1 | O30: 1 | P30: 1 | Q30: 1 | R30: 1 | S30: 1 | T30: 1 | U30: 1 | V30: 1 | W30: 1 | X30: 1 | Y30: 1 | Z30: 1 | AA30: 1 | AB30: 1 | AC30: 1 | AD30: 1 | AE30: 1 | AF30: 1 | AG30: 1 | AH30: 1 | AI30: 1 | AJ30: 1 | AK30: 1 | AL30: 1 | AM30: 1 | AN30: 1 | AO30: 1 | AP30: 1 | AQ30: 1 | AR30: 1 | AS30: 1 | AT30: 1 | AU30: 1 | AV30: 1 | AW30: 1 | AX30: 1 | AY30: 1 | AZ30: 1 | BA30: 1 | BB30: 1 | BC30: 1 | BD30: 1 | BE30: 1 | BF30: 1 | BG30: 1 | BH30: 1 | BI30: 1 | BJ30: 1 | BK30: 1 | BL30: 1 | BM30: 1 | BN30: 1 | BO30: 1 | BP30: 1 | BQ30: 1 | BR30: 1 | BS30: 1 | BT30: 1 | BU30: 1 | BV30: 1 | BW30: 1 | BX30: 1 | BY30: 1 | BZ30: 1 | CA30: 1 | CB30: 1 | CC30: 1 | CD30: 1 | CE30: 1 | CF30: 1 | CG30: 1 | CH30: 1 | CI30: 1 | CJ30: 1 | CK30: 1 | CL30: 1 | CM30: 1 | CN30: 1 | CO30: 1 | CP30: 1 | CQ30: 1 | CR30: 1 | CS30: 1 | CT30: 1 | CU30: 1 | CV30: 1 | CW30: 1 | CX30: 1 | CY30: 1 | CZ30: 1 | DA30: 1 | DB30: 1 | DC30: 1 | DD30: 1 | DE30: 1 | DF30: 0 | DG30: 0 | DH30: 0 | DI30: 0 | DJ30: 0 | DK30: 0 | DL30: 0 | DM30: 0 | DN30: 0 | DO30: 0 | DP30: 0 | DQ30: 0 | DR30: 0 | DS30: 0 | DT30: 0 | DU30: 0 | DV30: 0 | DW30: 0 | DX30: 0 | DY30: 0
E32: Senior Facility Principal repayment counter | G32: counter | J32: =IF( J$15 = 1, $H$30, IF( J$30 = 1, I$32 - J$30, 0 ) ) -> 100 | K32: =IF( K$15 = 1, $H$30, IF( K$30 = 1, J$32 - K$30, 0 ) ) -> 99 | L32: =IF( L$15 = 1, $H$30, IF( L$30 = 1, K$32 - L$30, 0 ) ) -> 98 | M32: =IF( M$15 = 1, $H$30, IF( M$30 = 1, L$32 - M$30, 0 ) ) -> 97 | N32: =IF( N$15 = 1, $H$30, IF( N$30 = 1, M$32 - N$30, 0 ) ) -> 96 | O32: =IF( O$15 = 1, $H$30, IF( O$30 = 1, N$32 - O$30, 0 ) ) -> 95 | P32: =IF( P$15 = 1, $H$30, IF( P$30 = 1, O$32 - P$30, 0 ) ) -> 94 | Q32: =IF( Q$15 = 1, $H$30, IF( Q$30 = 1, P$32 - Q$30, 0 ) ) -> 93 | ... DZ32: =IF( DZ$15 = 1, $H$30, IF( DZ$30 = 1, DY$32 - DZ$30, 0 ) ) -> 0
C35: Refinancing
E36: First refinancing date | F36: =MIN( CaseData!$G$27:$J$27 ) -> 46022 | G36: date
E37: Last refinancing date | F37: =MAX( CaseData!$G$27:$J$27 ) -> 51501 | G37: date
E38: Refinancing term | F38: 5 | G38: years
E39: Senior Facility refinancing period flag | G39: flag | J39: {=IF( (_xlfn.ANCHORARRAY( J3) > $F$36 ) * (_xlfn.ANCHORARRAY(J3) <= EDATE( $F$37, $F$38 * 12 ) ), 1, 0 )} -> 0 | K39: 0 | L39: 0 | M39: 0 | N39: 0 | O39: 0 | P39: 0 | Q39: 0 | R39: 0 | S39: 0 | T39: 0 | U39: 0 | V39: 0 | W39: 0 | X39: 0 | Y39: 0 | Z39: 0 | AA39: 0 | AB39: 0 | AC39: 0 | AD39: 1 | AE39: 1 | AF39: 1 | AG39: 1 | AH39: 1 | AI39: 1 | AJ39: 1 | AK39: 1 | AL39: 1 | AM39: 1 | AN39: 1 | AO39: 1 | AP39: 1 | AQ39: 1 | AR39: 1 | AS39: 1 | AT39: 1 | AU39: 1 | AV39: 1 | AW39: 1 | AX39: 1 | AY39: 1 | AZ39: 1 | BA39: 1 | BB39: 1 | BC39: 1 | BD39: 1 | BE39: 1 | BF39: 1 | BG39: 1 | BH39: 1 | BI39: 1 | BJ39: 1 | BK39: 1 | BL39: 1 | BM39: 1 | BN39: 1 | BO39: 1 | BP39: 1 | BQ39: 1 | BR39: 1 | BS39: 1 | BT39: 1 | BU39: 1 | BV39: 1 | BW39: 1 | BX39: 1 | BY39: 1 | BZ39: 1 | CA39: 1 | CB39: 1 | CC39: 1 | CD39: 1 | CE39: 1 | CF39: 1 | CG39: 1 | CH39: 1 | CI39: 1 | CJ39: 1 | CK39: 1 | CL39: 1 | CM39: 1 | CN39: 1 | CO39: 1 | CP39: 1 | CQ39: 1 | CR39: 1 | CS39: 1 | CT39: 1 | CU39: 1 | CV39: 1 | CW39: 1 | CX39: 1 | CY39: 1 | CZ39: 1 | DA39: 1 | DB39: 1 | DC39: 1 | DD39: 1 | DE39: 1 | DF39: 0 | DG39: 0 | DH39: 0 | DI39: 0 | DJ39: 0 | DK39: 0 | DL39: 0 | DM39: 0 | DN39: 0 | DO39: 0 | DP39: 0 | DQ39: 0 | DR39: 0 | DS39: 0 | DT39: 0 | DU39: 0 | DV39: 0 | DW39: 0 | DX39: 0 | DY39: 0
E40: Senior Facility refinancing date flag | G40: flag | J40: =_xlfn.XLOOKUP( J$3, CaseData!$G$27:$J$27, CaseData!$G$26:$J$26, 0 ) -> 0 | K40: =_xlfn.XLOOKUP( K$3, CaseData!$G$27:$J$27, CaseData!$G$26:$J$26, 0 ) -> 0 | L40: =_xlfn.XLOOKUP( L$3, CaseData!$G$27:$J$27, CaseData!$G$26:$J$26, 0 ) -> 0 | M40: =_xlfn.XLOOKUP( M$3, CaseData!$G$27:$J$27, CaseData!$G$26:$J$26, 0 ) -> 0 | N40: =_xlfn.XLOOKUP( N$3, CaseData!$G$27:$J$27, CaseData!$G$26:$J$26, 0 ) -> 0 | O40: =_xlfn.XLOOKUP( O$3, CaseData!$G$27:$J$27, CaseData!$G$26:$J$26, 0 ) -> 0 | P40: =_xlfn.XLOOKUP( P$3, CaseData!$G$27:$J$27, CaseData!$G$26:$J$26, 0 ) -> 0 | Q40: =_xlfn.XLOOKUP( Q$3, CaseData!$G$27:$J$27, CaseData!$G$26:$J$26, 0 ) -> 0 | ... DZ40: =_xlfn.XLOOKUP( DZ$3, CaseData!$G$27:$J$27, CaseData!$G$26:$J$26, 0 ) -> 0
E42: Refinancing periods
E43: {=TRANSPOSE( CaseData!$G$26:$J$26 )} -> 1 | F43: {=TRANSPOSE( CaseData!$G$27:$J$27 )} -> 46022 | G43: date
E44: 2 | F44: 47848 | G44: date
E45: 3 | F45: 49674 | G45: date
E46: 4 | F46: 51501 | G46: date
E47: Senior Facility refinancing counter | G47: counter | J47: {=IFERROR( _xlfn.XLOOKUP(_xlfn.ANCHORARRAY( $J$3),_xlfn.ANCHORARRAY( $F43), $E43:$E46,, - 1 ) *_xlfn.ANCHORARRAY( J39), 0 )} -> 0 | K47: 0 | L47: 0 | M47: 0 | N47: 0 | O47: 0 | P47: 0 | Q47: 0 | R47: 0 | S47: 0 | T47: 0 | U47: 0 | V47: 0 | W47: 0 | X47: 0 | Y47: 0 | Z47: 0 | AA47: 0 | AB47: 0 | AC47: 0 | AD47: 1 | AE47: 1 | AF47: 1 | AG47: 1 | AH47: 1 | AI47: 1 | AJ47: 1 | AK47: 1 | AL47: 1 | AM47: 1 | AN47: 1 | AO47: 1 | AP47: 1 | AQ47: 1 | AR47: 1 | AS47: 1 | AT47: 1 | AU47: 1 | AV47: 1 | AW47: 2 | AX47: 2 | AY47: 2 | AZ47: 2 | BA47: 2 | BB47: 2 | BC47: 2 | BD47: 2 | BE47: 2 | BF47: 2 | BG47: 2 | BH47: 2 | BI47: 2 | BJ47: 2 | BK47: 2 | BL47: 2 | BM47: 2 | BN47: 2 | BO47: 2 | BP47: 2 | BQ47: 3 | BR47: 3 | BS47: 3 | BT47: 3 | BU47: 3 | BV47: 3 | BW47: 3 | BX47: 3 | BY47: 3 | BZ47: 3 | CA47: 3 | CB47: 3 | CC47: 3 | CD47: 3 | CE47: 3 | CF47: 3 | CG47: 3 | CH47: 3 | CI47: 3 | CJ47: 3 | CK47: 4 | CL47: 4 | CM47: 4 | CN47: 4 | CO47: 4 | CP47: 4 | CQ47: 4 | CR47: 4 | CS47: 4 | CT47: 4 | CU47: 4 | CV47: 4 | CW47: 4 | CX47: 4 | CY47: 4 | CZ47: 4 | DA47: 4 | DB47: 4 | DC47: 4 | DD47: 4 | DE47: 4 | DF47: 0 | DG47: 0 | DH47: 0 | DI47: 0 | DJ47: 0 | DK47: 0 | DL47: 0 | DM47: 0 | DN47: 0 | DO47: 0 | DP47: 0 | DQ47: 0 | DR47: 0 | DS47: 0 | DT47: 0 | DU47: 0 | DV47: 0 | DW47: 0 | DX47: 0 | DY47: 0
A49: Junior Facility
C51: Term
E52: Junior Facility drawdown date | F52: =CaseData!$G$37 -> 44196 | G52: date
E53: Junior Facility maturity date | F53: =CaseData!$G$40 -> 54423 | G53: date
E54: Junior Facility period flag | G54: flag | H54: {=_xlfn.BYROW(_xlfn.ANCHORARRAY( J54), _xleta.SUM )} -> 112 | J54: {=_xlfn.LET( _xlpm.timeline_end,_xlfn.ANCHORARRAY( $J$3), _xlpm.initial, $F52, _xlpm.final, $F53, IF( (_xlpm.timeline_end >= _xlpm.initial) * (_xlpm.timeline_end <= _xlpm.final), 1, 0 ) )} -> 1 | K54: 1 | L54: 1 | M54: 1 | N54: 1 | O54: 1 | P54: 1 | Q54: 1 | R54: 1 | S54: 1 | T54: 1 | U54: 1 | V54: 1 | W54: 1 | X54: 1 | Y54: 1 | Z54: 1 | AA54: 1 | AB54: 1 | AC54: 1 | AD54: 1 | AE54: 1 | AF54: 1 | AG54: 1 | AH54: 1 | AI54: 1 | AJ54: 1 | AK54: 1 | AL54: 1 | AM54: 1 | AN54: 1 | AO54: 1 | AP54: 1 | AQ54: 1 | AR54: 1 | AS54: 1 | AT54: 1 | AU54: 1 | AV54: 1 | AW54: 1 | AX54: 1 | AY54: 1 | AZ54: 1 | BA54: 1 | BB54: 1 | BC54: 1 | BD54: 1 | BE54: 1 | BF54: 1 | BG54: 1 | BH54: 1 | BI54: 1 | BJ54: 1 | BK54: 1 | BL54: 1 | BM54: 1 | BN54: 1 | BO54: 1 | BP54: 1 | BQ54: 1 | BR54: 1 | BS54: 1 | BT54: 1 | BU54: 1 | BV54: 1 | BW54: 1 | BX54: 1 | BY54: 1 | BZ54: 1 | CA54: 1 | CB54: 1 | CC54: 1 | CD54: 1 | CE54: 1 | CF54: 1 | CG54: 1 | CH54: 1 | CI54: 1 | CJ54: 1 | CK54: 1 | CL54: 1 | CM54: 1 | CN54: 1 | CO54: 1 | CP54: 1 | CQ54: 1 | CR54: 1 | CS54: 1 | CT54: 1 | CU54: 1 | CV54: 1 | CW54: 1 | CX54: 1 | CY54: 1 | CZ54: 1 | DA54: 1 | DB54: 1 | DC54: 1 | DD54: 1 | DE54: 1 | DF54: 1 | DG54: 1 | DH54: 1 | DI54: 1 | DJ54: 1 | DK54: 1 | DL54: 1 | DM54: 1 | DN54: 1 | DO54: 1 | DP54: 1 | DQ54: 1 | DR54: 0 | DS54: 0 | DT54: 0 | DU54: 0 | DV54: 0 | DW54: 0 | DX54: 0 | DY54: 0
E56: Junior Facility Principal repayment counter | J56: =IF( J$15 = 1, $H$54, IF( J$54 = 1, I$56 - J$54, 0 ) ) -> 112 | K56: =IF( K$15 = 1, $H$54, IF( K$54 = 1, J$56 - K$54, 0 ) ) -> 111 | L56: =IF( L$15 = 1, $H$54, IF( L$54 = 1, K$56 - L$54, 0 ) ) -> 110 | M56: =IF( M$15 = 1, $H$54, IF( M$54 = 1, L$56 - M$54, 0 ) ) -> 109 | N56: =IF( N$15 = 1, $H$54, IF( N$54 = 1, M$56 - N$54, 0 ) ) -> 108 | O56: =IF( O$15 = 1, $H$54, IF( O$54 = 1, N$56 - O$54, 0 ) ) -> 107 | P56: =IF( P$15 = 1, $H$54, IF( P$54 = 1, O$56 - P$54, 0 ) ) -> 106 | Q56: =IF( Q$15 = 1, $H$54, IF( Q$54 = 1, P$56 - Q$54, 0 ) ) -> 105 | ... DZ56: =IF( DZ$15 = 1, $H$54, IF( DZ$54 = 1, DY$56 - DZ$54, 0 ) ) -> 0
...

Sheet CaseData
A1: Assumptions
B3: General Assumptions
C4: Project Start Date (must be quarter end date) | E4: [date] | G4: 44196
C5: Initial quarter end date | E5: [date] | G5: =EOMONTH(G4,3) -> 44286
C6: Number of years in project | E6: [# yrs] | G6: 30
C7: Final quarter end date (Project End Date) | E7: [date] | G7: =EOMONTH(G4,G6*12) -> 55153
C8: Acquisition Price of Asset at Project Start Date | E8: [$] | G8: =G17+G36+G49 -> 18000000
C9: Terminal Value at End Date | E9: [$] | G9: 25000000
B11: CFADS
C12: From Date | E12: [start of qtr date] | G12: =$G$4+1 -> 44197 | H12: =G13+1 -> 46023 | I12: =H13+1 -> 47849 | J12: =I13+1 -> 49675 | K12: =J13+1 -> 51502
C13: Until Date (aligns with Senior Refinance Dates) | E13: [end of qtr date] | G13: =G27 -> 46022 | H13: =H27 -> 47848 | I13: =I27 -> 49674 | J13: =J27 -> 51501 | K13: =$G$7 -> 55153
C14: CFADS per quarter | E14: [$ / qtr] | G14: 350000 | H14: 380000 | I14: 400000 | J14: 450000 | K14: 500000
B16: Senior Facility
C17: Initial Drawdown Amount | E17: [$] | G17: 10000000
C18: Initial Drawdown Date | E18: [date] | G18: =$G$4 -> 44196
C19: Initial Interest Rate | E19: [% p.a.] | G19: 0.05
C20: Facility Term (years) | E20: [years] | G20: 25
C21: Maturity Date | E21: [date] | G21: =EOMONTH(G18,12*G20) -> 53327
C23: Senior Interest and Principal to be paid quarterly, in a mortgage / annuity / credit foncier style (level Principal + Interest each quarter)
C25: Senior Refinancing Details
D26: Refinance Number | E26: [#] | G26: 1 | H26: 2 | I26: 3 | J26: 4
D27: Refinance Date (must be quarter end dates) | E27: [date] | G27: =EOMONTH(G18,12*5) -> 46022 | H27: =EOMONTH(G27,12*5) -> 47848 | I27: =EOMONTH(H27,12*5) -> 49674 | J27: =EOMONTH(I27,12*5) -> 51501
D28: Refinance Fee | E28: [% of refi amount] | G28: 0.01 | H28: 0.01 | I28: 0.01 | J28: 0.01
D29: New Interest Rate to apply | E29: [% p.a.] | G29: 0.05 | H29: 0.045 | I29: 0.055 | J29: 0.05
D31: Refinance Amounts should be sized such that the new quarterly debt service gives the same forecast DSCR each quarter as the initial drawdown.
D32: You should take into account the updated interest rate and CFADS amount each refinance date to determine the required debt balance immediately after refinance.
D33: Remember to capitalize the refinance fee. More specifically, the total refinance amount will be the funds drawn down plus the refinance fee.
B35: Junior Facility
C36: Initial Drawdown Amount | E36: [$] | G36: 3000000
C37: Initial Drawdown Date | E37: [date] | G37: =$G$4 -> 44196
C39: Facility Term (years) | E39: [years] | G39: 28
C40: Maturity Date | E40: [date] | G40: =EOMONTH(G37,12*G39) -> 54423
C42: From Date | E42: [start of qtr date] | G42: =$G$37+1 -> 44197 | H42: =G43+1 -> 46753 | I42: =H43+1 -> 49310 | J42: =I43+1 -> 51867
C43: Until Date | E43: [end of qtr date] | G43: 46752 | H43: 49309 | I43: 51866 | J43: =$G$40 -> 54423
C44: Junior Interest Rate | E44: [% p.a.] | G44: 0.075 | H44: 0.08 | I44: 0.075 | J44: 0.09
C46: Junior Interest and Principal to be paid quarterly, with equal Principal each quarter.
B48: Equity
C49: Contribution amount at project start date | E49: [$] | G49: 5000000
C50: Discount rate for Net Present Value Calculations | E50: [% p.a.] | G50: 0.1
B52: Model technical inputs
...

Sheet CaseSolution
A1: Calculations
B2: Period Start | J2: =I3+1 -> 44197 | K2: =J3+1 -> 44287 | L2: =K3+1 -> 44378 | M2: =L3+1 -> 44470 | N2: =M3+1 -> 44562 | O2: =N3+1 -> 44652 | P2: =O3+1 -> 44743 | Q2: =P3+1 -> 44835 | ... DY2: =DX3+1 -> 55062
B3: Period End | I3: =CaseData!G4 -> 44196 | J3: =EOMONTH(I3,3) -> 44286 | K3: =EOMONTH(J3,3) -> 44377 | L3: =EOMONTH(K3,3) -> 44469 | M3: =EOMONTH(L3,3) -> 44561 | N3: =EOMONTH(M3,3) -> 44651 | O3: =EOMONTH(N3,3) -> 44742 | P3: =EOMONTH(O3,3) -> 44834 | Q3: =EOMONTH(P3,3) -> 44926 | ... DY3: =EOMONTH(DX3,3) -> 55153
B4: Period Number | I4: 0 | J4: =I4+1 -> 1 | K4: =J4+1 -> 2 | L4: =K4+1 -> 3 | M4: =L4+1 -> 4 | N4: =M4+1 -> 5 | O4: =N4+1 -> 6 | P4: =O4+1 -> 7 | Q4: =P4+1 -> 8 | ... DY4: =DX4+1 -> 120
F5: Overall integrity | G5: =SUM(G48,G55,G82) -> 0
A8: Calculations
A10: Counters / Flags / Timing
B11: Senior Facility
C12: Refinance Period? | D12: [flag] | G12: =SUM(I12:DY12) -> 4 | I12: =1*NOT(ISNA(MATCH(I3,CaseData!$G$27:$J$27,0))) -> 0 | J12: =1*NOT(ISNA(MATCH(J3,CaseData!$G$27:$J$27,0))) -> 0 | K12: =1*NOT(ISNA(MATCH(K3,CaseData!$G$27:$J$27,0))) -> 0 | L12: =1*NOT(ISNA(MATCH(L3,CaseData!$G$27:$J$27,0))) -> 0 | M12: =1*NOT(ISNA(MATCH(M3,CaseData!$G$27:$J$27,0))) -> 0 | N12: =1*NOT(ISNA(MATCH(N3,CaseData!$G$27:$J$27,0))) -> 0 | O12: =1*NOT(ISNA(MATCH(O3,CaseData!$G$27:$J$27,0))) -> 0 | P12: =1*NOT(ISNA(MATCH(P3,CaseData!$G$27:$J$27,0))) -> 0 | ... DY12: =1*NOT(ISNA(MATCH(DY3,CaseData!$G$27:$J$27,0))) -> 0
C13: # of Refinancings already occurred | D13: [#] | G13: =SUM(I13:DY13) -> 280 | I13: =H13+H12 -> 0 | J13: =I13+I12 -> 0 | K13: =J13+J12 -> 0 | L13: =K13+K12 -> 0 | M13: =L13+L12 -> 0 | N13: =M13+M12 -> 0 | O13: =N13+N12 -> 0 | P13: =O13+O12 -> 0 | ... DY13: =DX13+DX12 -> 4
C14: Refinancing Number | D14: [#] | I14: =I12*(I12+I13) -> 0 | J14: =J12*(J12+J13) -> 0 | K14: =K12*(K12+K13) -> 0 | L14: =L12*(L12+L13) -> 0 | M14: =M12*(M12+M13) -> 0 | N14: =N12*(N12+N13) -> 0 | O14: =O12*(O12+O13) -> 0 | P14: =P12*(P12+P13) -> 0 | ... DY14: =DY12*(DY12+DY13) -> 0
C15: Refinancing Fee % | D15: [% of refi amount] | I15: =IF(I$14,INDEX(CaseData!$G$28:$J$28,I$14),0) -> 0 | J15: =IF(J$14,INDEX(CaseData!$G$28:$J$28,J$14),0) -> 0 | K15: =IF(K$14,INDEX(CaseData!$G$28:$J$28,K$14),0) -> 0 | L15: =IF(L$14,INDEX(CaseData!$G$28:$J$28,L$14),0) -> 0 | M15: =IF(M$14,INDEX(CaseData!$G$28:$J$28,M$14),0) -> 0 | N15: =IF(N$14,INDEX(CaseData!$G$28:$J$28,N$14),0) -> 0 | O15: =IF(O$14,INDEX(CaseData!$G$28:$J$28,O$14),0) -> 0 | P15: =IF(P$14,INDEX(CaseData!$G$28:$J$28,P$14),0) -> 0 | ... DY15: =IF(DY$14,INDEX(CaseData!$G$28:$J$28,DY$14),0) -> 0
C16: Interest Rate in force | D16: [% p.a.] | I16: =IF(I$13=0,CaseData!$G$19,INDEX(CaseData!$G$29:$J$29,I$13)) -> 0.05 | J16: =IF(J$13=0,CaseData!$G$19,INDEX(CaseData!$G$29:$J$29,J$13)) -> 0.05 | K16: =IF(K$13=0,CaseData!$G$19,INDEX(CaseData!$G$29:$J$29,K$13)) -> 0.05 | L16: =IF(L$13=0,CaseData!$G$19,INDEX(CaseData!$G$29:$J$29,L$13)) -> 0.05 | M16: =IF(M$13=0,CaseData!$G$19,INDEX(CaseData!$G$29:$J$29,M$13)) -> 0.05 | N16: =IF(N$13=0,CaseData!$G$19,INDEX(CaseData!$G$29:$J$29,N$13)) -> 0.05 | O16: =IF(O$13=0,CaseData!$G$19,INDEX(CaseData!$G$29:$J$29,O$13)) -> 0.05 | P16: =IF(P$13=0,CaseData!$G$19,INDEX(CaseData!$G$29:$J$29,P$13)) -> 0.05 | ... DY16: =IF(DY$13=0,CaseData!$G$19,INDEX(CaseData!$G$29:$J$29,DY$13)) -> 0.05
C17: Facility Active? | D17: [flag] | E17: =CaseData!G18 -> 44196 | F17: =CaseData!G21 -> 53327 | G17: =SUM(I17:DY17) -> 101 | I17: =(I$3>=$E17)*(I$3<=$F17) -> 1 | J17: =(J$3>=$E17)*(J$3<=$F17) -> 1 | K17: =(K$3>=$E17)*(K$3<=$F17) -> 1 | L17: =(L$3>=$E17)*(L$3<=$F17) -> 1 | M17: =(M$3>=$E17)*(M$3<=$F17) -> 1 | N17: =(N$3>=$E17)*(N$3<=$F17) -> 1 | O17: =(O$3>=$E17)*(O$3<=$F17) -> 1 | P17: =(P$3>=$E17)*(P$3<=$F17) -> 1 | ... DY17: =(DY$3>=$E17)*(DY$3<=$F17) -> 0
C18: Interest / Principal Repayment Period? | D18: [flag] | E18: =EOMONTH(E17,3) -> 44286 | F18: =F17 -> 53327 | G18: =SUM(I18:DY18) -> 100 | I18: =(I$3>=$E18)*(I$3<=$F18) -> 0 | J18: =(J$3>=$E18)*(J$3<=$F18) -> 1 | K18: =(K$3>=$E18)*(K$3<=$F18) -> 1 | L18: =(L$3>=$E18)*(L$3<=$F18) -> 1 | M18: =(M$3>=$E18)*(M$3<=$F18) -> 1 | N18: =(N$3>=$E18)*(N$3<=$F18) -> 1 | O18: =(O$3>=$E18)*(O$3<=$F18) -> 1 | P18: =(P$3>=$E18)*(P$3<=$F18) -> 1 | ... DY18: =(DY$3>=$E18)*(DY$3<=$F18) -> 0
C19: # of repayment periods remaining | D19: [#] | I19: =I18*SUM(I18:$DY18) -> 0 | J19: =J18*SUM(J18:$DY18) -> 100 | K19: =K18*SUM(K18:$DY18) -> 99 | L19: =L18*SUM(L18:$DY18) -> 98 | M19: =M18*SUM(M18:$DY18) -> 97 | N19: =N18*SUM(N18:$DY18) -> 96 | O19: =O18*SUM(O18:$DY18) -> 95 | P19: =P18*SUM(P18:$DY18) -> 94 | ... DY19: =DY18*SUM(DY18:$DY18) -> 0
B21: Junior Facility
C22: Facility Active? | D22: [flag] | E22: =CaseData!G37 -> 44196 | F22: =CaseData!G40 -> 54423 | G22: =SUM(I22:DY22) -> 113 | I22: =(I$3>=$E22)*(I$3<=$F22) -> 1 | J22: =(J$3>=$E22)*(J$3<=$F22) -> 1 | K22: =(K$3>=$E22)*(K$3<=$F22) -> 1 | L22: =(L$3>=$E22)*(L$3<=$F22) -> 1 | M22: =(M$3>=$E22)*(M$3<=$F22) -> 1 | N22: =(N$3>=$E22)*(N$3<=$F22) -> 1 | O22: =(O$3>=$E22)*(O$3<=$F22) -> 1 | P22: =(P$3>=$E22)*(P$3<=$F22) -> 1 | ... DY22: =(DY$3>=$E22)*(DY$3<=$F22) -> 0
C23: Interest / Principal Repayment Period? | D23: [flag] | E23: =EOMONTH(E22,3) -> 44286 | F23: =F22 -> 54423 | G23: =SUM(I23:DY23) -> 112 | I23: =(I$3>=$E23)*(I$3<=$F23) -> 0 | J23: =(J$3>=$E23)*(J$3<=$F23) -> 1 | K23: =(K$3>=$E23)*(K$3<=$F23) -> 1 | L23: =(L$3>=$E23)*(L$3<=$F23) -> 1 | M23: =(M$3>=$E23)*(M$3<=$F23) -> 1 | N23: =(N$3>=$E23)*(N$3<=$F23) -> 1 | O23: =(O$3>=$E23)*(O$3<=$F23) -> 1 | P23: =(P$3>=$E23)*(P$3<=$F23) -> 1 | ... DY23: =(DY$3>=$E23)*(DY$3<=$F23) -> 0
B25: CFADS
C26: Project Active? | D26: [flag] | E26: =CaseData!G5 -> 44286 | F26: =CaseData!G7 -> 55153 | I26: =(I$3>=$E26)*(I$3<=$F26) -> 0 | J26: =(J$3>=$E26)*(J$3<=$F26) -> 1 | K26: =(K$3>=$E26)*(K$3<=$F26) -> 1 | L26: =(L$3>=$E26)*(L$3<=$F26) -> 1 | M26: =(M$3>=$E26)*(M$3<=$F26) -> 1 | N26: =(N$3>=$E26)*(N$3<=$F26) -> 1 | O26: =(O$3>=$E26)*(O$3<=$F26) -> 1 | P26: =(P$3>=$E26)*(P$3<=$F26) -> 1 | ... DY26: =(DY$3>=$E26)*(DY$3<=$F26) -> 1
C27: CFADS column number (MATCH) | D27: [#] | I27: =IF(I26,MATCH(I$3,CaseData!$G$12:$K$12,1),0) -> 0 | J27: =IF(J26,MATCH(J$3,CaseData!$G$12:$K$12,1),0) -> 1 | K27: =IF(K26,MATCH(K$3,CaseData!$G$12:$K$12,1),0) -> 1 | L27: =IF(L26,MATCH(L$3,CaseData!$G$12:$K$12,1),0) -> 1 | M27: =IF(M26,MATCH(M$3,CaseData!$G$12:$K$12,1),0) -> 1 | N27: =IF(N26,MATCH(N$3,CaseData!$G$12:$K$12,1),0) -> 1 | O27: =IF(O26,MATCH(O$3,CaseData!$G$12:$K$12,1),0) -> 1 | P27: =IF(P26,MATCH(P$3,CaseData!$G$12:$K$12,1),0) -> 1 | ... DY27: =IF(DY26,MATCH(DY$3,CaseData!$G$12:$K$12,1),0) -> 5
C28: CFADS (INDEX) | D28: [$] | G28: =SUM(I28:DY28) -> 51600000 | I28: =INDEX(CaseData!$G$14:$K$14,CaseSolution!I27)*I26 -> 0 | J28: =INDEX(CaseData!$G$14:$K$14,CaseSolution!J27)*J26 -> 350000 | K28: =INDEX(CaseData!$G$14:$K$14,CaseSolution!K27)*K26 -> 350000 | L28: =INDEX(CaseData!$G$14:$K$14,CaseSolution!L27)*L26 -> 350000 | M28: =INDEX(CaseData!$G$14:$K$14,CaseSolution!M27)*M26 -> 350000 | N28: =INDEX(CaseData!$G$14:$K$14,CaseSolution!N27)*N26 -> 350000 | O28: =INDEX(CaseData!$G$14:$K$14,CaseSolution!O27)*O26 -> 350000 | P28: =INDEX(CaseData!$G$14:$K$14,CaseSolution!P27)*P26 -> 350000 | ... DY28: =INDEX(CaseData!$G$14:$K$14,CaseSolution!DY27)*DY26 -> 500000
A31: Cash Flow Waterfall
B32: Cash Flow
C33: CFADS | D33: [$] | G33: =SUM(I33:DY33) -> 51600000 | I33: =I28 -> 0 | J33: =J28 -> 350000 | K33: =K28 -> 350000 | L33: =L28 -> 350000 | M33: =M28 -> 350000 | N33: =N28 -> 350000 | O33: =O28 -> 350000 | P33: =P28 -> 350000 | ... DY33: =DY28 -> 500000
C34: Equity Contribution | D34: [$] | G34: =SUM(I34:DY34) -> 5000000 | I34: =0-I102 -> 5000000 | J34: =0-J102 -> 0 | K34: =0-K102 -> 0 | L34: =0-L102 -> 0 | M34: =0-M102 -> 0 | N34: =0-N102 -> 0 | O34: =0-O102 -> 0 | P34: =0-P102 -> 0 | ... DY34: =0-DY102 -> 0
C35: Senior Initial Drawdown | D35: [$] | G35: =SUM(I35:DY35) -> 10000000 | I35: =I70 -> 10000000 | J35: =J70 -> 0 | K35: =K70 -> 0 | L35: =L70 -> 0 | M35: =M70 -> 0 | N35: =N70 -> 0 | O35: =O70 -> 0 | P35: =P70 -> 0 | ... DY35: =DY70 -> 0
C36: Junior Drawdown | D36: [$] | G36: =SUM(I36:DY36) -> 3000000 | I36: =I89 -> 3000000 | J36: =J89 -> 0 | K36: =K89 -> 0 | L36: =L89 -> 0 | M36: =M89 -> 0 | N36: =N89 -> 0 | O36: =O89 -> 0 | P36: =P89 -> 0 | ... DY36: =DY89 -> 0
C37: Acquisition of Asset | D37: [$] | E37: =CaseData!$G$4 -> 44196 | F37: =0-CaseData!G8 -> -18000000 | G37: =SUM(I37:DY37) -> -18000000 | I37: =$F37*(I$3=$E37) -> -18000000 | J37: =$F37*(J$3=$E37) -> 0 | K37: =$F37*(K$3=$E37) -> 0 | L37: =$F37*(L$3=$E37) -> 0 | M37: =$F37*(M$3=$E37) -> 0 | N37: =$F37*(N$3=$E37) -> 0 | O37: =$F37*(O$3=$E37) -> 0 | P37: =$F37*(P$3=$E37) -> 0 | ... DY37: =$F37*(DY$3=$E37) -> 0
C38: Senior Interest Paid | D38: [$] | G38: =SUM(I38:DY38) -> -8454429.8 | I38: =I72 -> 0 | J38: =J72 -> -125000 | K38: =K72 -> -124365.72 | L38: =L72 -> -123723.5 | M38: =M72 -> -123073.26 | N38: =N72 -> -122414.89 | O38: =O72 -> -121748.29 | P38: =P72 -> -121073.36 | ... DY38: =DY72 -> 0
C39: Senior Principal Paid | D39: [$] | G39: =SUM(I39:DY39) -> -12433856 | I39: =I73 -> 0 | J39: =J73 -> -50742.788 | K39: =K73 -> -51377.072 | L39: =L73 -> -52019.286 | M39: =M73 -> -52669.527 | N39: =N73 -> -53327.896 | O39: =O73 -> -53994.495 | P39: =P73 -> -54669.426 | ... DY39: =DY73 -> 0
C40: Senior Bullet Repayment on Refinance | D40: [$] | G40: =SUM(I40:DY40) -> -27244003 | I40: =I74 -> 0 | J40: =J74 -> 0 | K40: =K74 -> 0 | L40: =L74 -> 0 | M40: =M74 -> 0 | N40: =N74 -> 0 | O40: =O74 -> 0 | P40: =P74 -> 0 | ... DY40: =DY74 -> 0
C41: Senior Refinance Drawdown | D41: [$] | G41: =SUM(I41:DY41) -> 29381080 | I41: =I75 -> 0 | J41: =J75 -> 0 | K41: =K75 -> 0 | L41: =L75 -> 0 | M41: =M75 -> 0 | N41: =N75 -> 0 | O41: =O75 -> 0 | P41: =P75 -> 0 | ... DY41: =DY75 -> 0
C42: Junior Interest Paid | D42: [$] | G42: =SUM(I42:DY42) -> -3285000 | I42: =I91 -> 0 | J42: =J91 -> -56250 | K42: =K91 -> -55747.768 | L42: =L91 -> -55245.536 | M42: =M91 -> -54743.304 | N42: =N91 -> -54241.071 | O42: =O91 -> -53738.839 | P42: =P91 -> -53236.607 | ... DY42: =DY91 -> 0
C43: Junior Principal Paid | D43: [$] | G43: =SUM(I43:DY43) -> -3000000 | I43: =I92 -> 0 | J43: =J92 -> -26785.714 | K43: =K92 -> -26785.714 | L43: =L92 -> -26785.714 | M43: =M92 -> -26785.714 | N43: =N92 -> -26785.714 | O43: =O92 -> -26785.714 | P43: =P92 -> -26785.714 | ... DY43: =DY92 -> 0
C44: Terminal Value of Asset | D44: [$] | E44: =CaseData!G7 -> 55153 | F44: =CaseData!G9 -> 25000000 | G44: =SUM(I44:DY44) -> 25000000 | I44: =$F44*(I$3=$E44) -> 0 | J44: =$F44*(J$3=$E44) -> 0 | K44: =$F44*(K$3=$E44) -> 0 | L44: =$F44*(L$3=$E44) -> 0 | M44: =$F44*(M$3=$E44) -> 0 | N44: =$F44*(N$3=$E44) -> 0 | O44: =$F44*(O$3=$E44) -> 0 | P44: =$F44*(P$3=$E44) -> 0 | ... DY44: =$F44*(DY$3=$E44) -> 25000000
C45: Subtotal: Available for distributions | D45: [$] | G45: =SUM(I45:DY45) -> 51563792 | I45: =SUM(I33:I44) -> 0 | J45: =SUM(J33:J44) -> 91221.498 | K45: =SUM(K33:K44) -> 91723.73 | L45: =SUM(L33:L44) -> 92225.962 | M45: =SUM(M33:M44) -> 92728.195 | N45: =SUM(N33:N44) -> 93230.427 | O45: =SUM(O33:O44) -> 93732.659 | P45: =SUM(P33:P44) -> 94234.891 | ... DY45: =SUM(DY33:DY44) -> 25500000
C46: Distributions paid | D46: [$] | G46: =SUM(I46:DY46) -> -51563792 | I46: =-I45 -> 0 | J46: =-J45 -> -91221.498 | K46: =-K45 -> -91723.73 | L46: =-L45 -> -92225.962 | M46: =-M45 -> -92728.195 | N46: =-N45 -> -93230.427 | O46: =-O45 -> -93732.659 | P46: =-P45 -> -94234.891 | ... DY46: =-DY45 -> -25500000
C47: Net cash flow for period (should be zero) | D47: [$] | G47: =SUM(I47:DY47) -> 0 | I47: =SUM(I45:I46) -> 0 | J47: =SUM(J45:J46) -> 0 | K47: =SUM(K45:K46) -> 0 | L47: =SUM(L45:L46) -> 0 | M47: =SUM(M45:M46) -> 0 | N47: =SUM(N45:N46) -> 0 | O47: =SUM(O45:O46) -> 0 | P47: =SUM(P45:P46) -> 0 | ... DY47: =SUM(DY45:DY46) -> 0
...

Sheet Tmp
A1: {=company} -> Investment Fund Asset
A2: {=topic} -> CFM Topic:
A3: TMP SCHEDULE | F3: Constant | G3: Unit | H3: Total
A9: Corkscrew
E11: ="[xxx] initial balance from model on " & TEXT( start_date, "dd/mm/yyyy" ) -> [xxx] initial balance from model on 31/12/2020 | G11: USD
E13: [xxx] opening balance | G13: USD
E14: [xxx] addition / (repayment) | G14: USD
E15: [xxx] | G15: USD
