Workbook
Name company: CaseData!$H$42
Name end_date: CaseData!$H$38
Name periods: CaseData!$H$37
Name scenarios: CaseData!$E$45:$E$50
Name selector: CaseData!$H$45
Name start_date: CaseData!$H$35
Name topic: "CFM Topic: " & CaseData!$H$43

Sheet Debt
A1: {=company} -> Unicord Construction
A2: {=topic} -> CFM Topic: Debt | J2: {=_xlfn.ANCHORARRAY( J11)} -> 44927 | K2: 45017 | L2: 45108 | M2: 45200 | N2: 45292 | O2: 45383 | P2: 45474 | Q2: 45566 | R2: 45658 | S2: 45748 | T2: 45839 | U2: 45931 | V2: 46023 | W2: 46113 | X2: 46204 | Y2: 46296 | Z2: 46388 | AA2: 46478 | AB2: 46569 | AC2: 46661 | AD2: 46753 | AE2: 46844 | AF2: 46935 | AG2: 47027 | AH2: 47119 | AI2: 47209 | AJ2: 47300 | AK2: 47392 | AL2: 47484 | AM2: 47574 | AN2: 47665 | AO2: 47757 | AP2: 47849 | AQ2: 47939 | AR2: 48030 | AS2: 48122 | AT2: 48214 | AU2: 48305 | AV2: 48396 | AW2: 48488
A3: LIVE SCENARIO | F3: 1 | G3: Unit | H3: Total | J3: {=_xlfn.ANCHORARRAY( J12)} -> 45016 | K3: 45107 | L3: 45199 | M3: 45291 | N3: 45382 | O3: 45473 | P3: 45565 | Q3: 45657 | R3: 45747 | S3: 45838 | T3: 45930 | U3: 46022 | V3: 46112 | W3: 46203 | X3: 46295 | Y3: 46387 | Z3: 46477 | AA3: 46568 | AB3: 46660 | AC3: 46752 | AD3: 46843 | AE3: 46934 | AF3: 47026 | AG3: 47118 | AH3: 47208 | AI3: 47299 | AJ3: 47391 | AK3: 47483 | AL3: 47573 | AM3: 47664 | AN3: 47756 | AO3: 47848 | AP3: 47938 | AQ3: 48029 | AR3: 48121 | AS3: 48213 | AT3: 48304 | AU3: 48395 | AV3: 48487 | AW3: 48579
A5: Model timeline
E7: Model start date | F7: =start_date -> 44926
E8: Model end date | F8: =end_date -> 48579
E9: Number of quarters | F9: =periods -> 40
E11: Model period beginning | G11: date | J11: {=EDATE( start_date + 1, _xlfn.SEQUENCE( 1, periods, 0, 3 ) )} -> 44927 | K11: 45017 | L11: 45108 | M11: 45200 | N11: 45292 | O11: 45383 | P11: 45474 | Q11: 45566 | R11: 45658 | S11: 45748 | T11: 45839 | U11: 45931 | V11: 46023 | W11: 46113 | X11: 46204 | Y11: 46296 | Z11: 46388 | AA11: 46478 | AB11: 46569 | AC11: 46661 | AD11: 46753 | AE11: 46844 | AF11: 46935 | AG11: 47027 | AH11: 47119 | AI11: 47209 | AJ11: 47300 | AK11: 47392 | AL11: 47484 | AM11: 47574 | AN11: 47665 | AO11: 47757 | AP11: 47849 | AQ11: 47939 | AR11: 48030 | AS11: 48122 | AT11: 48214 | AU11: 48305 | AV11: 48396 | AW11: 48488
E12: Model period ending | G12: date | J12: {=EOMONTH( start_date, _xlfn.SEQUENCE( 1, periods, 3, 3 ) )} -> 45016 | K12: 45107 | L12: 45199 | M12: 45291 | N12: 45382 | O12: 45473 | P12: 45565 | Q12: 45657 | R12: 45747 | S12: 45838 | T12: 45930 | U12: 46022 | V12: 46112 | W12: 46203 | X12: 46295 | Y12: 46387 | Z12: 46477 | AA12: 46568 | AB12: 46660 | AC12: 46752 | AD12: 46843 | AE12: 46934 | AF12: 47026 | AG12: 47118 | AH12: 47208 | AI12: 47299 | AJ12: 47391 | AK12: 47483 | AL12: 47573 | AM12: 47664 | AN12: 47756 | AO12: 47848 | AP12: 47938 | AQ12: 48029 | AR12: 48121 | AS12: 48213 | AT12: 48304 | AU12: 48395 | AV12: 48487 | AW12: 48579
E14: Model period counter | G14: counter | H14: {=_xlfn.BYROW(_xlfn.ANCHORARRAY( J14), _xleta.SUM )} -> 40 | J14: {=IF(_xlfn.ANCHORARRAY( J12), I14 + 1, 0 )} -> 1 | K14: 1 | L14: 1 | M14: 1 | N14: 1 | O14: 1 | P14: 1 | Q14: 1 | R14: 1 | S14: 1 | T14: 1 | U14: 1 | V14: 1 | W14: 1 | X14: 1 | Y14: 1 | Z14: 1 | AA14: 1 | AB14: 1 | AC14: 1 | AD14: 1 | AE14: 1 | AF14: 1 | AG14: 1 | AH14: 1 | AI14: 1 | AJ14: 1 | AK14: 1 | AL14: 1 | AM14: 1 | AN14: 1 | AO14: 1 | AP14: 1 | AQ14: 1 | AR14: 1 | AS14: 1 | AT14: 1 | AU14: 1 | AV14: 1 | AW14: 1
E15: Model first period flag | G15: flag | H15: {=_xlfn.BYROW(_xlfn.ANCHORARRAY( J15), _xleta.SUM )} -> 1 | J15: {=IF(_xlfn.ANCHORARRAY( J2) - 1 = start_date, 1, 0 )} -> 1 | K15: 0 | L15: 0 | M15: 0 | N15: 0 | O15: 0 | P15: 0 | Q15: 0 | R15: 0 | S15: 0 | T15: 0 | U15: 0 | V15: 0 | W15: 0 | X15: 0 | Y15: 0 | Z15: 0 | AA15: 0 | AB15: 0 | AC15: 0 | AD15: 0 | AE15: 0 | AF15: 0 | AG15: 0 | AH15: 0 | AI15: 0 | AJ15: 0 | AK15: 0 | AL15: 0 | AM15: 0 | AN15: 0 | AO15: 0 | AP15: 0 | AQ15: 0 | AR15: 0 | AS15: 0 | AT15: 0 | AU15: 0 | AV15: 0 | AW15: 0
E16: Model last period flag | G16: flag | H16: {=_xlfn.BYROW(_xlfn.ANCHORARRAY( J16), _xleta.SUM )} -> 1 | J16: {=IF(_xlfn.ANCHORARRAY( J12) = end_date, 1, 0 )} -> 0 | K16: 0 | L16: 0 | M16: 0 | N16: 0 | O16: 0 | P16: 0 | Q16: 0 | R16: 0 | S16: 0 | T16: 0 | U16: 0 | V16: 0 | W16: 0 | X16: 0 | Y16: 0 | Z16: 0 | AA16: 0 | AB16: 0 | AC16: 0 | AD16: 0 | AE16: 0 | AF16: 0 | AG16: 0 | AH16: 0 | AI16: 0 | AJ16: 0 | AK16: 0 | AL16: 0 | AM16: 0 | AN16: 0 | AO16: 0 | AP16: 0 | AQ16: 0 | AR16: 0 | AS16: 0 | AT16: 0 | AU16: 0 | AV16: 0 | AW16: 1
E18: Mortgage amortization quarters flag | G18: flag | H18: =SUM( J18:AW18) -> 32 | J18: =IF( SUM( $J14:J14 ) <= $F$97, 1, 0 ) -> 1 | K18: =IF( SUM( $J14:K14 ) <= $F$97, 1, 0 ) -> 1 | L18: =IF( SUM( $J14:L14 ) <= $F$97, 1, 0 ) -> 1 | M18: =IF( SUM( $J14:M14 ) <= $F$97, 1, 0 ) -> 1 | N18: =IF( SUM( $J14:N14 ) <= $F$97, 1, 0 ) -> 1 | O18: =IF( SUM( $J14:O14 ) <= $F$97, 1, 0 ) -> 1 | P18: =IF( SUM( $J14:P14 ) <= $F$97, 1, 0 ) -> 1 | Q18: =IF( SUM( $J14:Q14 ) <= $F$97, 1, 0 ) -> 1 | ... AW18: =IF( SUM( $J14:AW14 ) <= $F$97, 1, 0 ) -> 0
E19: Junior Debt amortization quarters flag | G19: flag | H19: =SUM( J19:AW19) -> 40 | J19: =IF( SUM( $J15:J15 ) <= $F$120, 1, 0 ) -> 1 | K19: =IF( SUM( $J15:K15 ) <= $F$120, 1, 0 ) -> 1 | L19: =IF( SUM( $J15:L15 ) <= $F$120, 1, 0 ) -> 1 | M19: =IF( SUM( $J15:M15 ) <= $F$120, 1, 0 ) -> 1 | N19: =IF( SUM( $J15:N15 ) <= $F$120, 1, 0 ) -> 1 | O19: =IF( SUM( $J15:O15 ) <= $F$120, 1, 0 ) -> 1 | P19: =IF( SUM( $J15:P15 ) <= $F$120, 1, 0 ) -> 1 | Q19: =IF( SUM( $J15:Q15 ) <= $F$120, 1, 0 ) -> 1 | ... AW19: =IF( SUM( $J15:AW15 ) <= $F$120, 1, 0 ) -> 1
A21: Cashflow waterfall
E23: EBIDTA | G23: USD | H23: =SUM(_xlfn.ANCHORARRAY( J23)) -> 41939007 | J23: {=INDEX( CaseData!$M$8:$R$47, MATCH(_xlfn.ANCHORARRAY( Debt!J3), CaseData!$K$8:$K$47, 0 ), MATCH( selector, CaseData!$M$5:$R$5, 0 ) )} -> 1019082 | K23: 1008045 | L23: 998560.5 | M23: 995307 | N23: 996799.5 | O23: 975211.5 | P23: 974340 | Q23: 967587 | R23: 1015347 | S23: 963435 | T23: 979111.5 | U23: 965946 | V23: 963438 | W23: 1007662.5 | X23: 1011898.5 | Y23: 1027911 | Z23: 990430.5 | AA23: 1015789.5 | AB23: 1030960.5 | AC23: 1048911 | AD23: 1078854 | AE23: 1039989 | AF23: 1069714.5 | AG23: 1047547.5 | AH23: 1049193 | AI23: 1059516 | AJ23: 1107811.5 | AK23: 1059664.5 | AL23: 1045116 | AM23: 1071954 | AN23: 1133484 | AO23: 1125522 | AP23: 1110844.5 | AQ23: 1096879.5 | AR23: 1133016 | AS23: 1153189.5 | AT23: 1146522 | AU23: 1138092 | AV23: 1157863.5 | AW23: 1158460.5
E24: =E$79 -> Debt Service Reserve Account interest income | G24: =G$79 -> USD | H24: =H$79 -> 60000 | I24: =I$79 -> 0 | J24: =J$79 -> 1875 | K24: =K$79 -> 1875 | L24: =L$79 -> 1875 | M24: =M$79 -> 1875 | N24: =N$79 -> 1875 | ... AW24: =AW$79 -> 0
E25: Funds available for Mortgage repayment | G25: USD | J25: =SUM(J23:J24) -> 1020957 | K25: =SUM(K23:K24) -> 1009920 | L25: =SUM(L23:L24) -> 1000435.5 | M25: =SUM(M23:M24) -> 997182 | N25: =SUM(N23:N24) -> 998674.5 | O25: =SUM(O23:O24) -> 977086.5 | P25: =SUM(P23:P24) -> 976215 | Q25: =SUM(Q23:Q24) -> 969462 | ... AW25: =SUM(AW23:AW24) -> 1158460.5
E27: Mortgage interest expenses | G27: USD | J27: =J$93 * - 1 -> -93750 | K27: =K$93 * - 1 -> -91094.407 | L27: =L$93 * - 1 -> -88422.216 | M27: =M$93 * - 1 -> -85733.324 | N27: =N$93 * - 1 -> -83027.626 | O27: =O$93 * - 1 -> -80305.018 | P27: =P$93 * - 1 -> -77565.394 | Q27: =Q$93 * - 1 -> -74808.647 | ... AW27: =AW$93 * - 1 -> 0
E28: =E$99 -> Mortage principal payment | G28: =G$99 -> USD | I28: =I$99 -> 0 | J28: =J$99 * - 1 -> -424894.93 | K28: =K$99 * - 1 -> -427550.52 | L28: =L$99 * - 1 -> -430222.71 | M28: =M$99 * - 1 -> -432911.61 | N28: =N$99 * - 1 -> -435617.3 | O28: =O$99 * - 1 -> -438339.91 | P28: =P$99 * - 1 -> -441079.54 | Q28: =Q$99 * - 1 -> -443836.28 | ... AW28: =AW$99 * - 1 -> 0
E29: Funds available after Mortgage service | G29: USD | J29: =SUM(J25:J28) -> 502312.07 | K29: =SUM(K25:K28) -> 491275.07 | L29: =SUM(L25:L28) -> 481790.57 | M29: =SUM(M25:M28) -> 478537.07 | N29: =SUM(N25:N28) -> 480029.57 | O29: =SUM(O25:O28) -> 458441.57 | P29: =SUM(P25:P28) -> 457570.07 | Q29: =SUM(Q25:Q28) -> 450817.07 | ... AW29: =SUM(AW25:AW28) -> 1158460.5
E31: Withdrawal from DSRA to cover for Senior Debt repayment shortfall | G31: USD | J31: =J$68 * - 1 -> 0 | K31: =K$68 * - 1 -> 0 | L31: =L$68 * - 1 -> 0 | M31: =M$68 * - 1 -> 0 | N31: =N$68 * - 1 -> 0 | O31: =O$68 * - 1 -> 0 | P31: =P$68 * - 1 -> 0 | Q31: =Q$68 * - 1 -> 0 | ... AW31: =AW$68 * - 1 -> 0
E32: =E$69 -> Top Up of DSRA to keep required minimum balance | G32: =G$69 -> USD | I32: =I$69 -> 0 | J32: =J$69 * - 1 -> 0 | K32: =K$69 * - 1 -> 0 | L32: =L$69 * - 1 -> 0 | M32: =M$69 * - 1 -> 0 | N32: =N$69 * - 1 -> 0 | O32: =O$69 * - 1 -> 0 | P32: =P$69 * - 1 -> 0 | Q32: =Q$69 * - 1 -> 0 | ... AW32: =AW$69 * - 1 -> 0
E33: =E$70 -> DSRA Additions in Lockup | G33: =G$70 -> USD | I33: =I$70 -> 0 | J33: =J$70 * - 1 -> 0 | K33: =K$70 * - 1 -> 0 | L33: =L$70 * - 1 -> 0 | M33: =M$70 * - 1 -> 0 | N33: =N$70 * - 1 -> 0 | O33: =O$70 * - 1 -> 0 | P33: =P$70 * - 1 -> 0 | Q33: =Q$70 * - 1 -> 0 | ... AW33: =AW$70 * - 1 -> 0
E34: Release from DSRA | G34: =G$70 -> USD | J34: =J71 * - 1 -> 0 | K34: =K71 * - 1 -> 0 | L34: =L71 * - 1 -> 0 | M34: =M71 * - 1 -> 0 | N34: =N71 * - 1 -> 0 | O34: =O71 * - 1 -> 0 | P34: =P71 * - 1 -> 0 | Q34: =Q71 * - 1 -> 0 | ... AW34: =AW71 * - 1 -> 0
E35: =E$72 -> Liquidation of DSRA | G35: =G$72 -> USD | I35: =I$72 -> 0 | J35: =J$72 * - 1 -> 0 | K35: =K$72 * - 1 -> 0 | L35: =L$72 * - 1 -> 0 | M35: =M$72 * - 1 -> 0 | N35: =N$72 * - 1 -> 0 | O35: =O$72 * - 1 -> 0 | P35: =P$72 * - 1 -> 0 | Q35: =Q$72 * - 1 -> 0 | ... AW35: =AW$72 * - 1 -> 0
E36: Funds available for Junior Debt service | G36: USD | J36: =SUM( J29:J35) -> 502312.07 | K36: =SUM( K29:K35) -> 491275.07 | L36: =SUM( L29:L35) -> 481790.57 | M36: =SUM( M29:M35) -> 478537.07 | N36: =SUM( N29:N35) -> 480029.57 | O36: =SUM( O29:O35) -> 458441.57 | P36: =SUM( P29:P35) -> 457570.07 | Q36: =SUM( Q29:Q35) -> 450817.07 | ... AW36: =SUM( AW29:AW35) -> 1158460.5
E38: Junior Debt interest paid | G38: USD | J38: =J$116 -> 0 | K38: =K$116 -> 0 | L38: =L$116 -> 0 | M38: =M$116 -> 0 | N38: =N$116 -> 0 | O38: =O$116 -> 0 | P38: =P$116 -> 0 | Q38: =Q$116 -> 0 | ... AW38: =AW$116 -> 0
E39: Funds Available for Junior Debt Scheduled Repayments | G39: USD | J39: =SUM(J36:J38) -> 502312.07 | K39: =SUM(K36:K38) -> 491275.07 | L39: =SUM(L36:L38) -> 481790.57 | M39: =SUM(M36:M38) -> 478537.07 | N39: =SUM(N36:N38) -> 480029.57 | O39: =SUM(O36:O38) -> 458441.57 | P39: =SUM(P36:P38) -> 457570.07 | Q39: =SUM(Q36:Q38) -> 450817.07 | ... AW39: =SUM(AW36:AW38) -> 1158460.5
E41: =E$126 -> Junior Debt amortization paid | G41: =G$126 -> USD | I41: =I$126 -> 0 | J41: =J$126 * - 1 -> -225000 | K41: =K$126 * - 1 -> -225000 | L41: =L$126 * - 1 -> -225000 | M41: =M$126 * - 1 -> -225000 | N41: =N$126 * - 1 -> -225000 | O41: =O$126 * - 1 -> -225000 | P41: =P$126 * - 1 -> -225000 | Q41: =Q$126 * - 1 -> -225000 | ... AW41: =AW$126 * - 1 -> -225000
E42: Funds Available for Junior Debt Arrears Amount Owed | G42: USD | J42: =SUM(J39:J41) -> 277312.07 | K42: =SUM(K39:K41) -> 266275.07 | L42: =SUM(L39:L41) -> 256790.57 | M42: =SUM(M39:M41) -> 253537.07 | N42: =SUM(N39:N41) -> 255029.57 | O42: =SUM(O39:O41) -> 233441.57 | P42: =SUM(P39:P41) -> 232570.07 | Q42: =SUM(Q39:Q41) -> 225817.07 | ... AW42: =SUM(AW39:AW41) -> 933460.5
E44: =E$135 -> Repayment of arrears owed | G44: =G$135 -> USD | I44: =I$135 -> 0 | J44: =J$135 -> 0 | K44: =K$135 -> 0 | L44: =L$135 -> 0 | M44: =M$135 -> 0 | N44: =N$135 -> 0 | O44: =O$135 -> 0 | P44: =P$135 -> 0 | ... AW44: =AW$135 -> 0
E45: Funds distributed to Equity | G45: USD | J45: =SUM(J42:J44) -> 277312.07 | K45: =SUM(K42:K44) -> 266275.07 | L45: =SUM(L42:L44) -> 256790.57 | M45: =SUM(M42:M44) -> 253537.07 | N45: =SUM(N42:N44) -> 255029.57 | O45: =SUM(O42:O44) -> 233441.57 | P45: =SUM(P42:P44) -> 232570.07 | Q45: =SUM(Q42:Q44) -> 225817.07 | ... AW45: =SUM(AW42:AW44) -> 933460.5
A48: DSCR (Last Twelve Months)
E50: =CaseData!C$9 -> Mortgage DSCR Lock up trigger | F50: =CaseData!H$9 -> 1.7 | G50: multiple
E52: EBIDTA | G52: USD | J52: =SUM($J23:J23) -> 1019082 | K52: =SUM($J23:K23) -> 2027127 | L52: =SUM($J23:L23) -> 3025687.5 | M52: =SUM($J23:M23) -> 4020994.5 | N52: =SUM( K23:N23) -> 3998712 | O52: =SUM( L23:O23) -> 3965878.5 | P52: =SUM( M23:P23) -> 3941658 | Q52: =SUM( N23:Q23) -> 3913938 | R52: =SUM( O23:R23) -> 3932485.5 | S52: =SUM( P23:S23) -> 3920709 | T52: =SUM( Q23:T23) -> 3925480.5 | U52: =SUM( R23:U23) -> 3923839.5 | ... AW52: =SUM( AT23:AW23) -> 4600938
E53: =E$79 -> Debt Service Reserve Account interest income | G53: =G$79 -> USD | H53: =H$79 -> 60000 | I53: =I$79 -> 0 | J53: =SUM( $J79:J79 ) -> 1875 | K53: =SUM( $J79:K79 ) -> 3750 | L53: =SUM( $J79:L79 ) -> 5625 | M53: =SUM( $J79:M79 ) -> 7500 | N53: =SUM( K79:N79) -> 7500 | O53: =SUM( L79:O79) -> 7500 | P53: =SUM( M79:P79) -> 7500 | Q53: =SUM( N79:Q79) -> 7500 | R53: =SUM( O79:R79) -> 7500 | S53: =SUM( P79:S79) -> 7500 | T53: =SUM( Q79:T79) -> 7500 | U53: =SUM( R79:U79) -> 7500 | ... AW53: =SUM( AT79:AW79) -> 0
E54: =E$93 -> Mortagage interest expenses | F54: =F$93 -> 0 | G54: =G$93 -> USD | H54: =H$93 -> 1596637.7 | I54: =I$93 -> 0 | J54: =SUM( $J93:J93 ) -> 93750 | K54: =SUM( $J93:K93 ) -> 184844.41 | L54: =SUM( $J93:L93 ) -> 273266.62 | M54: =SUM( $J93:M93 ) -> 358999.95 | N54: =SUM( K93:N93) -> 348277.57 | O54: =SUM( L93:O93) -> 337488.18 | P54: =SUM( M93:P93) -> 326631.36 | Q54: =SUM( N93:Q93) -> 315706.69 | R54: =SUM( O93:R93) -> 304713.73 | S54: =SUM( P93:S93) -> 293652.07 | T54: =SUM( Q93:T93) -> 282521.27 | U54: =SUM( R93:U93) -> 271320.9 | ... AW54: =SUM( AT93:AW93) -> 0
E55: =E$99 -> Mortage principal payment | F55: =F$99 -> 0 | G55: =G$99 -> USD | H55: =H$99 -> 15000000 | I55: =I$99 -> 0 | J55: =SUM( $J99:J99) -> 424894.93 | K55: =SUM( $J99:K99) -> 852445.45 | L55: =SUM( $J99:L99) -> 1282668.2 | M55: =SUM( $J99:M99) -> 1715579.8 | N55: =SUM( K99:N99) -> 1726302.1 | O55: =SUM( L99:O99) -> 1737091.5 | P55: =SUM( M99:P99) -> 1747948.4 | Q55: =SUM( N99:Q99) -> 1758873 | R55: =SUM( O99:R99) -> 1769866 | S55: =SUM( P99:S99) -> 1780927.6 | T55: =SUM( Q99:T99) -> 1792058.4 | U55: =SUM( R99:U99) -> 1803258.8 | ... AW55: =SUM( AT99:AW99) -> 0
E57: DSCR LTM | G57: factor | J57: =IFERROR( SUM( J52, J53 ) / SUM( J54, J55 ), "n/a" ) -> 1.9685086 | K57: =IFERROR( SUM( K52, K53 ) / SUM( K54, K55 ), "n/a" ) -> 1.9578684 | L57: =IFERROR( SUM( L52, L53 ) / SUM( L54, L55 ), "n/a" ) -> 1.9482259 | M57: =IFERROR( SUM( M52, M53 ) / SUM( M54, M55 ), "n/a" ) -> 1.9418364 | N57: =IFERROR( SUM( N52, N53 ) / SUM( N54, N55 ), "n/a" ) -> 1.9310957 | O57: =IFERROR( SUM( O52, O53 ) / SUM( O54, O55 ), "n/a" ) -> 1.9152691 | P57: =IFERROR( SUM( P52, P53 ) / SUM( P54, P55 ), "n/a" ) -> 1.9035942 | Q57: =IFERROR( SUM( Q52, Q53 ) / SUM( Q54, Q55 ), "n/a" ) -> 1.8902325 | ... AW57: =IFERROR( SUM( AW52, AW53 ) / SUM( AW54, AW55 ), "n/a" ) -> n/a
...

Sheet CaseData
A1: Assumptions | T1: =MATCH(selector,$M$5:$R$5,0) -> 1
T2: =selector -> 1
B3: Mortgage Facility | T3: =H45 -> 1
C4: Facility Balance at model start date | F4: [$] | H4: 15000000 | J4: EBITDA Profiles
C5: Annual cash interest rate | F5: [% p.a.] | H5: 0.025 | K5: Profile Number --> | M5: 1 | N5: 2 | O5: 3 | P5: 4 | Q5: 5 | R5: 6
C6: Amortisation Months | F6: [#] | H6: 96 | K6: Profile Name --> | M6: Base Case | N6: Case 2 | O6: Case 3 | P6: Case 4 | Q6: Case 5 | R6: Case 6
C7: Scheduled final payment date | F7: [date] | H7: =EOMONTH(H35,H6) -> 47848 | K7: Quarter Ending | M7: [$] | N7: [$] | O7: [$] | P7: [$] | Q7: [$] | R7: [$]
K8: =$H$36 -> 45016 | M8: 1019082 | N8: 1105141.5 | O8: 856621.5 | P8: 982938 | Q8: 1019082 | R8: 903625.5
C9: Mortgage DSCR Lock up trigger | F9: [x] | H9: 1.7 | K9: =EOMONTH(K8,3) -> 45107 | M9: 1008045 | N9: 961012.5 | O9: 957103.5 | P9: 932742 | Q9: 1008045 | R9: 893214
C10: Look-back quarters for DSCR incl. current quarter (Last Twelve Months) | F10: [#] | H10: 4 | I10: Do not change | K10: =EOMONTH(K9,3) -> 45199 | M10: 998560.5 | N10: 1048608 | O10: 919759.5 | P10: 973290 | Q10: 998560.5 | R10: 889797
K11: =EOMONTH(K10,3) -> 45291 | M11: 995307 | N11: 1074277.5 | O11: 990211.5 | P11: 947178 | Q11: 995307 | R11: 909898.5
C12: To get out of lock-up: | K12: =EOMONTH(K11,3) -> 45382 | M12: 996799.5 | N12: 1117527 | O12: 990643.5 | P12: 940560 | Q12: 996799.5 | R12: 947650.5
C13: Number of quarters required for Sr DSCR to be greater than lock-up trigger: | F13: [# qtrs] | H13: 2 | I13: Do not change | K13: =EOMONTH(K12,3) -> 45473 | M13: 975211.5 | N13: 971310 | O13: 940851 | P13: 964081.5 | Q13: 975211.5 | R13: 915790.5
K14: =EOMONTH(K13,3) -> 45565 | M14: 974340 | N14: 916065 | O14: 810855 | P14: 921279 | Q14: 974340 | R14: 878397
K15: =EOMONTH(K14,3) -> 45657 | M15: 967587 | N15: 786327 | O15: 839349 | P15: 955951.5 | Q15: 483793.5 | R15: 956358
B16: Debt Service Reserve Account | K16: =EOMONTH(K15,3) -> 45747 | M16: 1015347 | N16: 882622.5 | O16: 962665.5 | P16: 921717 | Q16: 507673.5 | R16: 970485
C17: Initial balance at project start (already funded) | H17: 750000 | K17: =EOMONTH(K16,3) -> 45838 | M17: 963435 | N17: 1101510 | O17: 803719.5 | P17: 963336 | Q17: 481717.5 | R17: 1013374.5
C18: Required minimum balance during term of Mortgage Facility | H18: 750000 | K18: =EOMONTH(K17,3) -> 45930 | M18: 979111.5 | N18: 1052203.5 | O18: 903232.5 | P18: 914505 | Q18: 489555.75 | R18: 876916.5
C19: Cash interest rate earned on account balance | F19: [% p.a.] | H19: 0.01 | K19: =EOMONTH(K18,3) -> 46022 | M19: 965946 | N19: 1095760.5 | O19: 988131 | P19: 869358 | Q19: 482973 | R19: 327231
K20: =EOMONTH(K19,3) -> 46112 | M20: 963438 | N20: 970521 | O20: 881398.5 | P20: 945835.5 | Q20: 963438 | R20: 341170.5
K21: =EOMONTH(K20,3) -> 46203 | M21: 1007662.5 | N21: 1003909.5 | O21: 963904.5 | P21: 985399.5 | Q21: 1007662.5 | R21: 397729.5
B22: Junior Facility | K22: =EOMONTH(K21,3) -> 46295 | M22: 1011898.5 | N22: 987990 | O22: 890178 | P22: 1010407.5 | Q22: 1011898.5 | R22: 388617
C23: Facility Balance at model start date | F23: [$] | H23: 9000000 | K23: =EOMONTH(K22,3) -> 46387 | M23: 1027911 | N23: 1227384 | O23: 876990 | P23: 593412 | Q23: 1027911 | R23: 906457.5
C24: Annual cash interest rate | F24: [% p.a.] | H24: 0 | K24: =EOMONTH(K23,3) -> 46477 | M24: 990430.5 | N24: 1096188 | O24: 805438.5 | P24: 558492 | Q24: 990430.5 | R24: 862152
C25: Amortisation Quarters | F25: [#] | H25: 40 | K25: =EOMONTH(K24,3) -> 46568 | M25: 1015789.5 | N25: 994783.5 | O25: 928035 | P25: 608830.5 | Q25: 1015789.5 | R25: 961906.5
C26: Scheduled final payment date | F26: [date] | H26: =EOMONTH(H35,3*H25) -> 48579 | K26: =EOMONTH(K25,3) -> 46660 | M26: 1030960.5 | N26: 900456 | O26: 954414 | P26: 607663.5 | Q26: 1030960.5 | R26: 961135.5
K27: =EOMONTH(K26,3) -> 46752 | M27: 1048911 | N27: 941046 | O27: 972483 | P27: 956788.5 | Q27: 1048911 | R27: 950587.5
K28: =EOMONTH(K27,3) -> 46843 | M28: 1078854 | N28: 1093561.5 | O28: 975916.5 | P28: 1020253.5 | Q28: 1078854 | R28: 864250.5
B29: Equity | K29: =EOMONTH(K28,3) -> 46934 | M29: 1039989 | N29: 960078 | O29: 1014169.5 | P29: 1003492.5 | Q29: 1039989 | R29: 871696.5
C30: Contribution amount at model start date | F30: [$] | H30: 6000000 | K30: =EOMONTH(K29,3) -> 47026 | M30: 1069714.5 | N30: 1257165 | O30: 1113783 | P30: 1000381.5 | Q30: 1069714.5 | R30: 1064973
C31: Discount rate for Net Present Value Calculations | F31: [% p.a.] | H31: 0.1 | K31: =EOMONTH(K30,3) -> 47118 | M31: 1047547.5 | N31: 1095327 | O31: 986683.5 | P31: 1030954.5 | Q31: 1047547.5 | R31: 903028.5
K32: =EOMONTH(K31,3) -> 47208 | M32: 1049193 | N32: 885561 | O32: 907974 | P32: 960159 | Q32: 1049193 | R32: 1013218.5
K33: =EOMONTH(K32,3) -> 47299 | M33: 1059516 | N33: 1127121 | O33: 953113.5 | P33: 954321 | Q33: 1059516 | R33: 1004701.5
B34: Other Assumptions | K34: =EOMONTH(K33,3) -> 47391 | M34: 1107811.5 | N34: 992164.5 | O34: 891501 | P34: 1055305.5 | Q34: 1107811.5 | R34: 1063546.5
C35: Model start date (Project start date) | F35: [date] | H35: 44926 | K35: =EOMONTH(K34,3) -> 47483 | M35: 1059664.5 | N35: 1179703.5 | O35: 957454.5 | P35: 1026214.5 | Q35: 1059664.5 | R35: 1039509
C36: Initial quarter end date | F36: [date] | H36: =EOMONTH(H35,3) -> 45016 | K36: =EOMONTH(K35,3) -> 47573 | M36: 1045116 | N36: 976075.5 | O36: 997194 | P36: 1003003.5 | Q36: 1045116 | R36: 1076869.5
C37: Number of quarters in project | F37: [# qtrs] | H37: 40 | K37: =EOMONTH(K36,3) -> 47664 | M37: 1071954 | N37: 958510.5 | O37: 1120617 | P37: 1058319 | Q37: 1071954 | R37: 943045.5
C38: Final quarter end date (Project end date) | F38: [date] | H38: =EOMONTH(H35,H37*3) -> 48579 | K38: =EOMONTH(K37,3) -> 47756 | M38: 1133484 | N38: 1176114 | O38: 1176696 | P38: 1077916.5 | Q38: 1133484 | R38: 986671.5
K39: =EOMONTH(K38,3) -> 47848 | M39: 1125522 | N39: 1138582.5 | O39: 1116520.5 | P39: 1069879.5 | Q39: 1125522 | R39: 1051468.5
C40: Cash interest rate earned on cash account balance | F40: [% p.a.] | H40: 0.01 | K40: =EOMONTH(K39,3) -> 47938 | M40: 1110844.5 | N40: 1221447 | O40: 939954 | P40: 1043466 | Q40: 1110844.5 | R40: 957409.5
...

Sheet CaseSolution
B2: Unicorn Construction Ltd
B3: Debt Model
H6: Total | J6: =CaseData!H35 -> 44926 | K6: =EOMONTH(J6,3) -> 45016 | L6: =EOMONTH(K6,3) -> 45107 | M6: =EOMONTH(L6,3) -> 45199 | N6: =EOMONTH(M6,3) -> 45291 | O6: =EOMONTH(N6,3) -> 45382 | P6: =EOMONTH(O6,3) -> 45473 | Q6: =EOMONTH(P6,3) -> 45565 | R6: =EOMONTH(Q6,3) -> 45657 | ... AX6: =EOMONTH(AW6,3) -> 48579
B8: Answers
K10: Jr Facility Bal | L10: First Lock up | M10: Max DSRA Bal | N10: Mortgage | O10: Mortgage Bal
C11: a) | E11: See below | K11: 45838 | N11: Total Int | O11: 48579
C12: b) | E12: See below | K12: =INDEX($J$97:$AX$97,MATCH(K11,$J$6:$AX$6,0)) -> 6750000 | L12: =IFERROR(INDEX($K$6:$AX$6,MATCH(1,$K$89:$AX$89,0)),"None") -> None | M12: =MAX(K67:AX67) -> 750000 | N12: =H53 -> 1596637.7 | O12: =INDEX($J$50:$AX$50,MATCH(O11,$J$6:$AX$6,0)) -> 0
C13: c) | E13: =K16 -> 6750000 | J13: Base Case | K13: 6750000 | L13: None | M13: 750000 | N13: 1596637.7 | O13: 0
C14: d) | E14: =L14 -> None | J14: Case 2 | K14: 6750000 | L14: None | M14: 750000 | N14: 1596637.7 | O14: 0
C15: e) | E15: =M15 -> 1897175.9 | J15: Case 3 | K15: 6975000 | L15: 45016 | M15: 1897175.9 | N15: 1596637.7 | O15: 0
C16: f) | E16: =N17 -> 1596637.7 | J16: Case 4 | K16: 6750000 | L16: 46477 | M16: 2410494.1 | N16: 1596637.7 | O16: 0
C17: g) | E17: =$O$18 -> 0 | J17: Case 5 | K17: 7425000 | L17: 45657 | M17: 2560711.7 | N17: 1596637.7 | O17: 0
J18: Case 6 | K18: 6750000 | L18: 46022 | M18: 1759237.7 | N18: 1596637.7 | O18: 0
B21: Cash Flow
C23: EBITDA | G23: Case 2 | H23: =SUM(K23:AX23) -> 42470140 | K23: =INDEX(CaseData!$M$8:$R$47,MATCH(K$6,CaseData!$K$8:$K$47,0),MATCH($G$23,CaseData!$M$6:$R$6,0)) -> 1105141.5 | L23: =INDEX(CaseData!$M$8:$R$47,MATCH(L$6,CaseData!$K$8:$K$47,0),MATCH($G$23,CaseData!$M$6:$R$6,0)) -> 961012.5 | M23: =INDEX(CaseData!$M$8:$R$47,MATCH(M$6,CaseData!$K$8:$K$47,0),MATCH($G$23,CaseData!$M$6:$R$6,0)) -> 1048608 | N23: =INDEX(CaseData!$M$8:$R$47,MATCH(N$6,CaseData!$K$8:$K$47,0),MATCH($G$23,CaseData!$M$6:$R$6,0)) -> 1074277.5 | O23: =INDEX(CaseData!$M$8:$R$47,MATCH(O$6,CaseData!$K$8:$K$47,0),MATCH($G$23,CaseData!$M$6:$R$6,0)) -> 1117527 | P23: =INDEX(CaseData!$M$8:$R$47,MATCH(P$6,CaseData!$K$8:$K$47,0),MATCH($G$23,CaseData!$M$6:$R$6,0)) -> 971310 | Q23: =INDEX(CaseData!$M$8:$R$47,MATCH(Q$6,CaseData!$K$8:$K$47,0),MATCH($G$23,CaseData!$M$6:$R$6,0)) -> 916065 | R23: =INDEX(CaseData!$M$8:$R$47,MATCH(R$6,CaseData!$K$8:$K$47,0),MATCH($G$23,CaseData!$M$6:$R$6,0)) -> 786327 | ... AX23: =INDEX(CaseData!$M$8:$R$47,MATCH(AX$6,CaseData!$K$8:$K$47,0),MATCH($G$23,CaseData!$M$6:$R$6,0)) -> 1089577.5
C24: Interest Income | H24: =SUM(K24:AX24) -> 60000 | K24: =K70 -> 1875 | L24: =L70 -> 1875 | M24: =M70 -> 1875 | N24: =N70 -> 1875 | O24: =O70 -> 1875 | P24: =P70 -> 1875 | Q24: =Q70 -> 1875 | R24: =R70 -> 1875 | ... AX24: =AX70 -> 0
C25: Cash flow | H25: =SUM(K25:AX25) -> 42530140 | K25: =SUM(K23:K24) -> 1107016.5 | L25: =SUM(L23:L24) -> 962887.5 | M25: =SUM(M23:M24) -> 1050483 | N25: =SUM(N23:N24) -> 1076152.5 | O25: =SUM(O23:O24) -> 1119402 | P25: =SUM(P23:P24) -> 973185 | Q25: =SUM(Q23:Q24) -> 917940 | R25: =SUM(R23:R24) -> 788202 | ... AX25: =SUM(AX23:AX24) -> 1089577.5
C27: Mortgage Interest | H27: =SUM(K27:AX27) -> -1596637.7 | K27: =-K53 -> -93750 | L27: =-L53 -> -91094.407 | M27: =-M53 -> -88422.216 | N27: =-N53 -> -85733.324 | O27: =-O53 -> -83027.626 | P27: =-P53 -> -80305.018 | Q27: =-Q53 -> -77565.394 | R27: =-R53 -> -74808.647 | ... AX27: =-AX53 -> 0
C28: Mortgage Principal | H28: =SUM(K28:AX28) -> -15000000 | K28: =K49 -> -424894.93 | L28: =L49 -> -427550.52 | M28: =M49 -> -430222.71 | N28: =N49 -> -432911.61 | O28: =O49 -> -435617.3 | P28: =P49 -> -438339.91 | Q28: =Q49 -> -441079.54 | R28: =R49 -> -443836.28 | ... AX28: =AX49 -> 0
C29: Remaining cash flow | K29: =SUM(K25,K27:K28) -> 588371.57 | L29: =SUM(L25,L27:L28) -> 444242.57 | M29: =SUM(M25,M27:M28) -> 531838.07 | N29: =SUM(N25,N27:N28) -> 557507.57 | O29: =SUM(O25,O27:O28) -> 600757.07 | P29: =SUM(P25,P27:P28) -> 454540.07 | Q29: =SUM(Q25,Q27:Q28) -> 399295.07 | R29: =SUM(R25,R27:R28) -> 269557.07 | ... AX29: =SUM(AX25,AX27:AX28) -> 1089577.5
C31: DSRA Withdrawl | H31: =SUM(K31:AX31) -> 0 | K31: =-MIN(K29,0) -> 0 | L31: =-MIN(L29,0) -> 0 | M31: =-MIN(M29,0) -> 0 | N31: =-MIN(N29,0) -> 0 | O31: =-MIN(O29,0) -> 0 | P31: =-MIN(P29,0) -> 0 | Q31: =-MIN(Q29,0) -> 0 | R31: =-MIN(R29,0) -> 0 | ... AX31: =-MIN(AX29,0) -> 0
C32: DSRA Top Up | H32: =SUM(K32:AX32) -> 0 | K32: =-K63 -> 0 | L32: =-L63 -> 0 | M32: =-M63 -> 0 | N32: =-N63 -> 0 | O32: =-O63 -> 0 | P32: =-P63 -> 0 | Q32: =-Q63 -> 0 | R32: =-R63 -> 0 | ... AX32: =-AX63 -> 0
C33: DSRA Liquidation | H33: =SUM(K33:AX33) -> 750000 | K33: =-K66 -> 0 | L33: =-L66 -> 0 | M33: =-M66 -> 0 | N33: =-N66 -> 0 | O33: =-O66 -> 0 | P33: =-P66 -> 0 | Q33: =-Q66 -> 0 | R33: =-R66 -> 0 | ... AX33: =-AX66 -> 0
C34: Remaining cash flow | K34: =SUM(K29,K31:K33) -> 588371.57 | L34: =SUM(L29,L31:L33) -> 444242.57 | M34: =SUM(M29,M31:M33) -> 531838.07 | N34: =SUM(N29,N31:N33) -> 557507.57 | O34: =SUM(O29,O31:O33) -> 600757.07 | P34: =SUM(P29,P31:P33) -> 454540.07 | Q34: =SUM(Q29,Q31:Q33) -> 399295.07 | R34: =SUM(R29,R31:R33) -> 269557.07 | ... AX34: =SUM(AX29,AX31:AX33) -> 1089577.5
C36: Lock-Up Sweep | H36: =SUM(K36:AX36) -> 0 | K36: =-K64 -> 0 | L36: =-L64 -> 0 | M36: =-M64 -> 0 | N36: =-N64 -> 0 | O36: =-O64 -> 0 | P36: =-P64 -> 0 | Q36: =-Q64 -> 0 | R36: =-R64 -> 0 | ... AX36: =-AX64 -> 0
C37: Lock-up Exit Release | H37: =SUM(K37:AX37) -> 0 | K37: =-K65 -> 0 | L37: =-L65 -> 0 | M37: =-M65 -> 0 | N37: =-N65 -> 0 | O37: =-O65 -> 0 | P37: =-P65 -> 0 | Q37: =-Q65 -> 0 | R37: =-R65 -> 0 | ... AX37: =-AX65 -> 0
C38: Remaining cash flow for Jr. Debt | K38: =SUM(K34,K36:K37) -> 588371.57 | L38: =SUM(L34,L36:L37) -> 444242.57 | M38: =SUM(M34,M36:M37) -> 531838.07 | N38: =SUM(N34,N36:N37) -> 557507.57 | O38: =SUM(O34,O36:O37) -> 600757.07 | P38: =SUM(P34,P36:P37) -> 454540.07 | Q38: =SUM(Q34,Q36:Q37) -> 399295.07 | R38: =SUM(R34,R36:R37) -> 269557.07 | ... AX38: =SUM(AX34,AX36:AX37) -> 1089577.5
C40: Jr. Debt Amortization | H40: =SUM(K40:AX40) -> -9000000 | K40: =K95 -> -225000 | L40: =L95 -> -225000 | M40: =M95 -> -225000 | N40: =N95 -> -225000 | O40: =O95 -> -225000 | P40: =P95 -> -225000 | Q40: =Q95 -> -225000 | R40: =R95 -> -225000 | ... AX40: =AX95 -> -225000
C41: Remaining cash flow for Arrears | K41: =SUM(K38,K40) -> 363371.57 | L41: =SUM(L38,L40) -> 219242.57 | M41: =SUM(M38,M40) -> 306838.07 | N41: =SUM(N38,N40) -> 332507.57 | O41: =SUM(O38,O40) -> 375757.07 | P41: =SUM(P38,P40) -> 229540.07 | Q41: =SUM(Q38,Q40) -> 174295.07 | R41: =SUM(R38,R40) -> 44557.071 | ... AX41: =SUM(AX38,AX40) -> 864577.5
C43: Repayment of Arrears Jr. Debt | H43: =SUM(K43:AX43) -> 0 | K43: =K96 -> 0 | L43: =L96 -> 0 | M43: =M96 -> 0 | N43: =N96 -> 0 | O43: =O96 -> 0 | P43: =P96 -> 0 | Q43: =Q96 -> 0 | R43: =R96 -> 0 | ... AX43: =AX96 -> 0
C44: Cash Flow to Equity | K44: =SUM(K41,K43) -> 363371.57 | L44: =SUM(L41,L43) -> 219242.57 | M44: =SUM(M41,M43) -> 306838.07 | N44: =SUM(N41,N43) -> 332507.57 | O44: =SUM(O41,O43) -> 375757.07 | P44: =SUM(P41,P43) -> 229540.07 | Q44: =SUM(Q41,Q43) -> 174295.07 | R44: =SUM(R41,R43) -> 44557.071 | ... AX44: =SUM(AX41,AX43) -> 864577.5
B46: Mortgage Facility
C48: Opening Balance | K48: =J50 -> 15000000 | L48: =K50 -> 14575105 | M48: =L50 -> 14147555 | N48: =M50 -> 13717332 | O48: =N50 -> 13284420 | P48: =O50 -> 12848803 | Q48: =P50 -> 12410463 | R48: =Q50 -> 11969383 | ... AX48: =AW50 -> 0
C49: Amortization | H49: =SUM(K49:AX49) -> -15000000 | K49: =-K57 -> -424894.93 | L49: =-L57 -> -427550.52 | M49: =-M57 -> -430222.71 | N49: =-N57 -> -432911.61 | O49: =-O57 -> -435617.3 | P49: =-P57 -> -438339.91 | Q49: =-Q57 -> -441079.54 | R49: =-R57 -> -443836.28 | ... AX49: =-AX57 -> 0
C50: Closing Balance | J50: =CaseData!$H$4 -> 15000000 | K50: =SUM(K48:K49) -> 14575105 | L50: =SUM(L48:L49) -> 14147555 | M50: =SUM(M48:M49) -> 13717332 | N50: =SUM(N48:N49) -> 13284420 | O50: =SUM(O48:O49) -> 12848803 | P50: =SUM(P48:P49) -> 12410463 | Q50: =SUM(Q48:Q49) -> 11969383 | R50: =SUM(R48:R49) -> 11525547 | ... AX50: =SUM(AX48:AX49) -> 0
C52: Interest Rate | G52: =CaseData!H5 -> 0.025 | K52: =$G52 -> 0.025 | L52: =$G52 -> 0.025 | M52: =$G52 -> 0.025 | N52: =$G52 -> 0.025 | O52: =$G52 -> 0.025 | P52: =$G52 -> 0.025 | Q52: =$G52 -> 0.025 | R52: =$G52 -> 0.025 | ... AX52: =$G52 -> 0.025
C53: Interest Expense | H53: =SUM(K53:AX53) -> 1596637.7 | K53: =K48*K52/4 -> 93750 | L53: =L48*L52/4 -> 91094.407 | M53: =M48*M52/4 -> 88422.216 | N53: =N48*N52/4 -> 85733.324 | O53: =O48*O52/4 -> 83027.626 | P53: =P48*P52/4 -> 80305.018 | Q53: =Q48*Q52/4 -> 77565.394 | R53: =R48*R52/4 -> 74808.647 | ... AX53: =AX48*AX52/4 -> 0
C55: Term (months) | G55: =CaseData!H6 -> 96
C56: Quarterly Payment | G56: =PMT(G52/4,G55/3,-J50) -> 518644.93 | K56: =IF(K48>0,$G56,0) -> 518644.93 | L56: =IF(L48>0,$G56,0) -> 518644.93 | M56: =IF(M48>0,$G56,0) -> 518644.93 | N56: =IF(N48>0,$G56,0) -> 518644.93 | O56: =IF(O48>0,$G56,0) -> 518644.93 | P56: =IF(P48>0,$G56,0) -> 518644.93 | Q56: =IF(Q48>0,$G56,0) -> 518644.93 | R56: =IF(R48>0,$G56,0) -> 518644.93 | ... AX56: =IF(AX48>0,$G56,0) -> 0
C57: Amortization | K57: =MIN(K56-K53,K48) -> 424894.93 | L57: =MIN(L56-L53,L48) -> 427550.52 | M57: =MIN(M56-M53,M48) -> 430222.71 | N57: =MIN(N56-N53,N48) -> 432911.61 | O57: =MIN(O56-O53,O48) -> 435617.3 | P57: =MIN(P56-P53,P48) -> 438339.91 | Q57: =MIN(Q56-Q53,Q48) -> 441079.54 | R57: =MIN(R56-R53,R48) -> 443836.28 | ... AX57: =MIN(AX56-AX53,AX48) -> 0
...
