Workbook
Name company: LEFT(CaseData!$B$2, 28 )
Name topic: "CFM Topic: " & PROPER( MID(CaseData!$B$2, 32,5) )

Sheet Debt
A1: {=company} -> GRANITE BAY REAL ESTATE INC.
A2: {=topic} -> CFM Topic: Debt
A3: DEBT SCHEDULE | F3: Constant | G3: Unit | H3: Total | J3: =J$259 -> 2024 | K3: =K$259 -> 2025 | L3: =L$259 -> 2026 | M3: =M$259 -> 2027 | N3: =N$259 -> 2028 | O3: =O$259 -> 2029 | P3: =P$259 -> 2030 | Q3: =Q$259 -> 2031 | ... S3: =S$259 -> 2033
A5: Cash Flow Waterfall
C7: Free Cash Flow before Debt Service
E8: =E$110 -> Construction Loan I drawdown | G8: =G$110 -> USD | J8: =J$110 * -1 -> -3500000 | K8: =K$110 * -1 -> 0 | L8: =L$110 * -1 -> 0 | M8: =M$110 * -1 -> 0 | N8: =N$110 * -1 -> 0 | O8: =O$110 * -1 -> 0 | P8: =P$110 * -1 -> 0 | Q8: =Q$110 * -1 -> 0 | ... S8: =S$110 * -1 -> 0
E9: =E$98 -> Free Cash Flow before Debt Service - Property I | G9: =G$98 -> USD | I9: =I$98 -> 0 | J9: =J$98 -> 0 | K9: =K$98 -> 625000 | L9: =L$98 -> 1312500 | M9: =M$98 -> 1378125 | N9: =N$98 -> 1447031.3 | O9: =O$98 -> 1483207 | P9: =P$98 -> 1520287.2 | ... S9: =S$98 -> 1637183
E10: FCF before Debt Service - Property I | G10: USD | J10: =SUM(J8:J9) -> -3500000 | K10: =SUM(K8:K9) -> 625000 | L10: =SUM(L8:L9) -> 1312500 | M10: =SUM(M8:M9) -> 1378125 | N10: =SUM(N8:N9) -> 1447031.3 | O10: =SUM(O8:O9) -> 1483207 | P10: =SUM(P8:P9) -> 1520287.2 | Q10: =SUM(Q8:Q9) -> 1558294.4 | ... S10: =SUM(S8:S9) -> 1637183
E12: =E$153 -> Construction Loan II drawdown | G12: =G$153 -> USD | I12: =I$153 -> 0 | J12: =J$153 * - 1 -> 0 | K12: =K$153 * - 1 -> -4166666.7 | L12: =L$153 * - 1 -> -4166666.7 | M12: =M$153 * - 1 -> -4166666.7 | N12: =N$153 * - 1 -> 0 | O12: =O$153 * - 1 -> 0 | P12: =P$153 * - 1 -> 0 | Q12: =Q$153 * - 1 -> 0 | ... S12: =S$153 * - 1 -> 0
E13: Proceeds from sale of Property II | G13: USD | J13: =IF( J3 = CaseData!$G$36, CaseData!$G$37, 0 ) -> 0 | K13: =IF( K3 = CaseData!$G$36, CaseData!$G$37, 0 ) -> 0 | L13: =IF( L3 = CaseData!$G$36, CaseData!$G$37, 0 ) -> 0 | M13: =IF( M3 = CaseData!$G$36, CaseData!$G$37, 0 ) -> 18750000 | N13: =IF( N3 = CaseData!$G$36, CaseData!$G$37, 0 ) -> 0 | O13: =IF( O3 = CaseData!$G$36, CaseData!$G$37, 0 ) -> 0 | P13: =IF( P3 = CaseData!$G$36, CaseData!$G$37, 0 ) -> 0 | Q13: =IF( Q3 = CaseData!$G$36, CaseData!$G$37, 0 ) -> 0 | ... S13: =IF( S3 = CaseData!$G$36, CaseData!$G$37, 0 ) -> 0
E14: FCF before Debt Service - Property II | G14: USD | J14: =SUM(J12:J13) -> 0 | K14: =SUM(K12:K13) -> -4166666.7 | L14: =SUM(L12:L13) -> -4166666.7 | M14: =SUM(M12:M13) -> 14583333 | N14: =SUM(N12:N13) -> 0 | O14: =SUM(O12:O13) -> 0 | P14: =SUM(P12:P13) -> 0 | Q14: =SUM(Q12:Q13) -> 0 | ... S14: =SUM(S12:S13) -> 0
E16: FCF before Debt Service | G16: USD | J16: =SUM( J10, J14) -> -3500000 | K16: =SUM( K10, K14) -> -3541666.7 | L16: =SUM( L10, L14) -> -2854166.7 | M16: =SUM( M10, M14) -> 15961458 | N16: =SUM( N10, N14) -> 1447031.3 | O16: =SUM( O10, O14) -> 1483207 | P16: =SUM( P10, P14) -> 1520287.2 | Q16: =SUM( Q10, Q14) -> 1558294.4 | ... S16: =SUM( S10, S14) -> 1637183
C18: Free Cash Flow before the Use of Cash and Revolver
E19: =E$16 -> FCF before Debt Service | G19: =G$16 -> USD | I19: =I$16 -> 0 | J19: =J$16 -> -3500000 | K19: =K$16 -> -3541666.7 | L19: =L$16 -> -2854166.7 | M19: =M$16 -> 15961458 | N19: =N$16 -> 1447031.3 | O19: =O$16 -> 1483207 | P19: =P$16 -> 1520287.2 | ... S19: =S$16 -> 1637183
E20: Interest paid | G20: USD | J20: =J$239 * - 1 -> -188873.24 | K20: =K$239 * - 1 -> -378321.39 | L20: =L$239 * - 1 -> -368400.36 | M20: =M$239 * - 1 -> -327594.15 | N20: =N$239 * - 1 -> -252253.51 | O20: =O$239 * - 1 -> -185014.07 | P20: =P$239 * - 1 -> -147362.02 | Q20: =Q$239 * - 1 -> -123893.39 | ... S20: =S$239 * - 1 -> -73933.725
E21: =CaseSolution!C147 -> Construction Debt Issuance (excl . Interest) | G21: USD | J21: =SUM( J$110, J$153 ) -> 3500000 | K21: =SUM( K$110, K$153 ) -> 4166666.7 | L21: =SUM( L$110, L$153 ) -> 4166666.7 | M21: =SUM( M$110, M$153 ) -> 4166666.7 | N21: =SUM( N$110, N$153 ) -> 0 | O21: =SUM( O$110, O$153 ) -> 0 | P21: =SUM( P$110, P$153 ) -> 0 | Q21: =SUM( Q$110, Q$153 ) -> 0 | ... S21: =SUM( S$110, S$153 ) -> 0
E22: =CaseSolution!C148 -> Construction Debt Retirement | G22: USD | J22: =SUM( J$119, J$162 ) -> -7426300 | K22: =SUM( K$119, K$162 ) -> 0 | L22: =SUM( L$119, L$162 ) -> 0 | M22: =SUM( M$119, M$162 ) -> -13563107 | N22: =SUM( N$119, N$162 ) -> 0 | O22: =SUM( O$119, O$162 ) -> 0 | P22: =SUM( P$119, P$162 ) -> 0 | Q22: =SUM( Q$119, Q$162 ) -> 0 | ... S22: =SUM( S$119, S$162 ) -> 0
E23: =CaseSolution!C149 -> Mortgage Issuance | G23: USD | J23: =IF( J3 = $F$124, $F$125, 0 ) -> 7426300 | K23: =IF( K3 = $F$124, $F$125, 0 ) -> 0 | L23: =IF( L3 = $F$124, $F$125, 0 ) -> 0 | M23: =IF( M3 = $F$124, $F$125, 0 ) -> 0 | N23: =IF( N3 = $F$124, $F$125, 0 ) -> 0 | O23: =IF( O3 = $F$124, $F$125, 0 ) -> 0 | P23: =IF( P3 = $F$124, $F$125, 0 ) -> 0 | Q23: =IF( Q3 = $F$124, $F$125, 0 ) -> 0 | ... S23: =IF( S3 = $F$124, $F$125, 0 ) -> 0
E24: =CaseSolution!C150 -> Mortgage Principal Payment | G24: USD | J24: =J$132 * - 1 -> 0 | K24: =K$132 * - 1 -> -217411.77 | L24: =L$132 * - 1 -> -222847.07 | M24: =M$132 * - 1 -> -228418.24 | N24: =N$132 * - 1 -> -234128.7 | O24: =O$132 * - 1 -> -239981.92 | P24: =P$132 * - 1 -> -245981.46 | Q24: =Q$132 * - 1 -> -252131 | ... S24: =S$132 * - 1 -> -264895.13
E26: Free Cash Flow before the Use of Cash and Revolver | G26: USD | J26: =SUM(J19:J24) -> -188873.24 | K26: =SUM(K19:K24) -> 29266.836 | L26: =SUM(L19:L24) -> 721252.58 | M26: =SUM(M19:M24) -> 6009005.6 | N26: =SUM(N19:N24) -> 960649.04 | O26: =SUM(O19:O24) -> 1058211 | P26: =SUM(P19:P24) -> 1126943.7 | Q26: =SUM(Q19:Q24) -> 1182270 | ... S26: =SUM(S19:S24) -> 1298354.2
E28: =E$57 -> Revolver addition / (repayment) | G28: =G$57 -> USD | I28: =I$57 -> 0 | J28: =J$57 -> 188873.24 | K28: =K$57 -> -29266.836 | L28: =L$57 -> -159606.4 | M28: =M$57 -> 0 | N28: =N$57 -> 0 | O28: =O$57 -> 0 | P28: =P$57 -> 0 | ... S28: =S$57 -> 0
C30: Existing Debt Repayment
E32: Cash Available to Pay Existing Debt | G32: =G$57 -> USD | J32: =J26 + J28 -> 0 | K32: =K26 + K28 -> 0 | L32: =L26 + L28 -> 561646.17 | M32: =M26 + M28 -> 6009005.6 | N32: =N26 + N28 -> 960649.04 | O32: =O26 + O28 -> 1058211 | P32: =P26 + P28 -> 1126943.7 | Q32: =Q26 + Q28 -> 1182270 | ... S32: =S26 + S28 -> 1298354.2
E33: =E$248 -> Existing Debt Repayment | F33: =F$248 -> 0 | G33: =G$248 -> USD | H33: =H$248 -> 0 | I33: =I$248 -> 0 | J33: =J$248 -> 0 | K33: =K$248 -> 0 | L33: =L$248 -> -561646.17 | ... S33: =S$248 -> 0
E34: Net change in cash | G34: USD | J34: =SUM(J32:J33) -> 0 | K34: =SUM(K32:K33) -> 0 | L34: =SUM(L32:L33) -> 0 | M34: =SUM(M32:M33) -> 0 | N34: =SUM(N32:N33) -> 0 | O34: =SUM(O32:O33) -> 584913.67 | P34: =SUM(P32:P33) -> 1126943.7 | Q34: =SUM(Q32:Q33) -> 1182270 | ... S34: =SUM(S32:S33) -> 1298354.2
A37: Cash and Revolver
C39: Cash and Cash equivalents
E41: Cash and Cash equivalents initial balance from assumptions | F41: =CaseData!$O$19 -> 0 | G41: USD
E43: Cash and Cash equivalents opening balance | G43: USD | J43: =I45 -> 0 | K43: =J45 -> 0 | L43: =K45 -> 0 | M43: =L45 -> 0 | N43: =M45 -> 0 | O43: =N45 -> 0 | P43: =O45 -> 584913.67 | Q43: =P45 -> 1711857.4 | ... S43: =R45 -> 4133517.2
E44: Net Change in Cash | G44: USD | J44: =J$34 -> 0 | K44: =K$34 -> 0 | L44: =L$34 -> 0 | M44: =M$34 -> 0 | N44: =N$34 -> 0 | O44: =O$34 -> 584913.67 | P44: =P$34 -> 1126943.7 | Q44: =Q$34 -> 1182270 | ... S44: =S$34 -> 1298354.2
E45: Cash and Cash equivalents closing balance | G45: USD | I45: =F41 -> 0 | J45: =SUM(J43:J44) -> 0 | K45: =SUM(K43:K44) -> 0 | L45: =SUM(L43:L44) -> 0 | M45: =SUM(M43:M44) -> 0 | N45: =SUM(N43:N44) -> 0 | O45: =SUM(O43:O44) -> 584913.67 | P45: =SUM(P43:P44) -> 1711857.4 | Q45: =SUM(Q43:Q44) -> 2894127.4 | ... S45: =SUM(S43:S44) -> 5431871.4
D47: Interest earned on cash balance
E48: =CaseData!J$21 -> Interest Rate | F48: =CaseData!O$21 -> 0.015 | G48: %
E49: Interest earned on cash balance | G49: USD | J49: =AVERAGE( J$43, J$45 ) * $F$48 -> 0 | K49: =AVERAGE( K$43, K$45 ) * $F$48 -> 0 | L49: =AVERAGE( L$43, L$45 ) * $F$48 -> 0 | M49: =AVERAGE( M$43, M$45 ) * $F$48 -> 0 | N49: =AVERAGE( N$43, N$45 ) * $F$48 -> 0 | O49: =AVERAGE( O$43, O$45 ) * $F$48 -> 4386.8525 | P49: =AVERAGE( P$43, P$45 ) * $F$48 -> 17225.783 | Q49: =AVERAGE( Q$43, Q$45 ) * $F$48 -> 34544.886 | ... S49: =AVERAGE( S$43, S$45 ) * $F$48 -> 71740.414
C52: Revolver
E54: Revolver initial balance from assumptions | F54: =CaseData!$Q$19 -> 0 | G54: USD
E56: Revolver opening balance | G56: USD | J56: =I$58 -> 0 | K56: =J$58 -> 188873.24 | L56: =K$58 -> 159606.4 | M56: =L$58 -> 0 | N56: =M$58 -> 0 | O56: =N$58 -> 0 | P56: =O$58 -> 0 | Q56: =P$58 -> 0 | ... S56: =R$58 -> 0
E57: Revolver addition / (repayment) | G57: USD | J57: =MAX( - MIN( SUM( J26, J43 ), J56 ), - J$67 ) -> 188873.24 | K57: =MAX( - MIN( SUM( K26, K43 ), K56 ), - K$67 ) -> -29266.836 | L57: =MAX( - MIN( SUM( L26, L43 ), L56 ), - L$67 ) -> -159606.4 | M57: =MAX( - MIN( SUM( M26, M43 ), M56 ), - M$67 ) -> 0 | N57: =MAX( - MIN( SUM( N26, N43 ), N56 ), - N$67 ) -> 0 | O57: =MAX( - MIN( SUM( O26, O43 ), O56 ), - O$67 ) -> 0 | P57: =MAX( - MIN( SUM( P26, P43 ), P56 ), - P$67 ) -> 0 | Q57: =MAX( - MIN( SUM( Q26, Q43 ), Q56 ), - Q$67 ) -> 0 | ... S57: =MAX( - MIN( SUM( S26, S43 ), S56 ), - S$67 ) -> 0
E58: Revolver closing balance | G58: USD | I58: =F54 -> 0 | J58: =SUM(J56:J57) -> 188873.24 | K58: =SUM(K56:K57) -> 159606.4 | L58: =SUM(L56:L57) -> 0 | M58: =SUM(M56:M57) -> 0 | N58: =SUM(N56:N57) -> 0 | O58: =SUM(O56:O57) -> 0 | P58: =SUM(P56:P57) -> 0 | Q58: =SUM(Q56:Q57) -> 0 | ... S58: =SUM(S56:S57) -> 0
D60: Interest expenses on revolver
...

Sheet CaseData
B2: GRANITE BAY REAL ESTATE INC. - DEBT QUESTION
B3: =MID( B2, 31, 5) -> DEBT
B5: ASSUMPTIONS
B7: TIMING | J7: EXISTING DEBT
G8: Information | O8: Existing Debt I | Q8: Existing Debt II | S8: Existing Debt III
C9: Start Year | G9: 2024 | J9: ="Outstanding Balance as at: "&TEXT((DATE(G9-1,12,31)),"[$-F800]dddd, mmmm dd, yyyy") -> Outstanding Balance as at: December 31, 2023 | O9: 2750000 | Q9: 1500000 | S9: 2225000
C10: Periodicity | G10: Annual | J10: Interest Rate | O10: 0.0925 | Q10: 0.0875 | S10: 0.0795
J11: Annual Payment | O11: Interest Only | Q11: Interest Only | S11: Interest Only
J12: Interest Payment Type | O12: Non-Cash / Accrued | Q12: Non-Cash / Accrued | S12: Cash
J13: Principal Repayment Priority (After Revolver) | O13: Pay Down First | Q13: Pay Down Second | S13: Pay Down Third
B17: FREE CASH FLOW BEFORE DEBT SERVICE | J17: CASH BALANCE AND REVOLVER
G18: Information | O18: Cash Account | Q18: Revolver
C19: Start Year | G19: =O32+1 -> 2025 | J19: ="Outstanding Balance as at: "&TEXT((DATE(G9-1,12,31)),"[$-F800]dddd, mmmm dd, yyyy") -> Outstanding Balance as at: December 31, 2023 | O19: 0 | Q19: 0
C20: Free Cash Flow Before Debt Service | G20: 1250000 | H20: ok | J20: Maximum Amount | O20: N/A | Q20: 1000000
C21: ="Occupancy Rate ("&G19&" - "&G19+F21-1&")" -> Occupancy Rate (2025 - 2025) | F21: 1 | G21: 0.5 | H21: ok | J21: Interest Rate | O21: 0.015 | Q21: 0.055
C22: ="Occupancy Rate in "&G19+F21&" and Beyond" -> Occupancy Rate in 2026 and Beyond | G22: 1 | H22: ok | J22: Standby Fee Rate | O22: N/A | Q22: 0.0075
C23: ="Growth Rate ("&G19+1&" - "&G19+F23&")" -> Growth Rate (2026 - 2028) | F23: 3 | G23: 0.05 | H23: ok | J23: Annual Payment | O23: Interest Only | Q23: Principal + Interest
C24: ="Growth Rate "&G19+F23+1&" and Beyond" -> Growth Rate 2029 and Beyond | G24: 0.025 | H24: ok | J24: Interest Payment Type | O24: Cash | Q24: Cash
J25: Repayment Priority | O25: N/A | Q25: Cash Sweep
B29: PROPERTY DETAILS | J29: NEW DEBT
C30: Property I | G30: Information | O30: Construction Loan I | Q30: Construction Loan II | S30: Mortgage Loan
C31: Start Renting | G31: =G19 -> 2025 | J31: Issuance | O31: 2023 | Q31: 2025 | S31: =O32 -> 2024
C32: Free Cash Flow Before Debt Service Information | G32: See box above | H32: ok | J32: Payment / Term | O32: 2024 | Q32: 2027 | S32: 25
J33: Amount | O33: 7000000 | Q33: 12500000 | S33: End Value of Constr. Loan I
C34: Property II | G34: Information | J34: ="Amount Spent as at: "&TEXT((DATE(G9-1,12,31)),"[$-F800]dddd, mmmm dd, yyyy") -> Amount Spent as at: December 31, 2023 | O34: 3500000 | Q34: N/A | S34: N/A
C35: Construction Start | G35: =Q31 -> 2025 | J35: Interest Rate | O35: 0.06 | Q35: 0.055 | S35: 0.025
C36: Year Sold | G36: =Q32 -> 2027 | J36: Annual Payment | O36: Interest Only | Q36: Interest Only | S36: Principal + Interest
C37: Amount | G37: 18750000 | J37: Interest Payment Type | O37: Non-Cash / Accrued | Q37: Non-Cash / Accrued | S37: Cash
J38: Final Payment | O38: Competion of Construction | Q38: Competion of Construction | S38: N/A (Annual Amortization)

Sheet CaseSolution
B2: GRANITE BAY REAL ESTATE INC. - DEBT ANSWER KEY
B5: (i) BUILD AN ANNUAL MODEL OF THE COMPANY FOR THE TWO PROPERTIES OVER THE NEXT TEN YEARS (I.E., 2024 – 2033).
C6: ="See the Model Build below, beginning in Row "&ROW(A58) -> See the Model Build below, beginning in Row 58
B10: (ii) CREATE A SUMMARY TABLE OUTLINING THE ENDING BALANCE FOR EACH OF THE THREE EXISTING PIECES OF DEBT. WHEN DOES EACH PIECE OF DEBT GET PAID OFF?
C11: =IFERROR(C17&" is Paid off in: "&TEXT(INDEX($I$15:$S$15,MATCH(0,I17:S17,0)),"0;[Red]0")&" (see below for details):",C17&" does NOT get Paid off (see below for details):") -> Existing Debt I is Paid off in: 2027 (see below for details):
C12: =IFERROR(C18&" is Paid off in: "&TEXT(INDEX($I$15:$S$15,MATCH(0,I18:S18,0)),"0;[Red]0")&" (see below for details):",C18&" does NOT get Paid off (see below for details):") -> Existing Debt II is Paid off in: 2027 (see below for details):
C13: =IFERROR(C19&" is Paid off in: "&TEXT(INDEX($I$15:$S$15,MATCH(0,I19:S19,0)),"0;[Red]0")&" (see below for details):",C19&" does NOT get Paid off (see below for details):") -> Existing Debt III is Paid off in: 2029 (see below for details):
C14: =IFERROR("All Existing Debt is Paid off in: "&TEXT(INDEX($I$15:$S$15,MATCH(0,I20:S20,0)),"0;[Red]0")&" (see below for details):","All Existing Debt does not get Paid off (see below for details):") -> All Existing Debt is Paid off in: 2029 (see below for details): | J14: =J$103 -> Forecast
I15: =I$104 -> 2023 | J15: =J$104 -> 2024 | K15: =K$104 -> 2025 | L15: =L$104 -> 2026 | M15: =M$104 -> 2027 | N15: =N$104 -> 2028 | O15: =O$104 -> 2029 | P15: =P$104 -> 2030 | ... S15: =S$104 -> 2033
C16: Existing Debt Summary
C17: =C264 -> Existing Debt I | J17: =J270 -> 3016710.4 | K17: =K270 -> 3309287.8 | L17: =L270 -> 3041359 | M17: =M270 -> 0 | N17: =N270 -> 0 | O17: =O270 -> 0 | P17: =P270 -> 0 | Q17: =Q270 -> 0 | ... S17: =S270 -> 0
C18: =C277 -> Existing Debt II | J18: =J283 -> 1637254.9 | K18: =K283 -> 1787069.1 | L18: =L283 -> 1950591.7 | M18: =M283 -> 0 | N18: =N283 -> 0 | O18: =O283 -> 0 | P18: =P283 -> 0 | Q18: =Q283 -> 0 | ... S18: =S283 -> 0
C19: =C290 -> Existing Debt III | J19: =J296 -> 2225000 | K19: =K296 -> 2225000 | L19: =L296 -> 2225000 | M19: =M296 -> 1433946.4 | N19: =N296 -> 473297.37 | O19: =O296 -> 0 | P19: =P296 -> 0 | Q19: =Q296 -> 0 | ... S19: =S296 -> 0
C20: Total | J20: =SUM(J17:J19) -> 6878965.3 | K20: =SUM(K17:K19) -> 7321356.8 | L20: =SUM(L17:L19) -> 7216950.7 | M20: =SUM(M17:M19) -> 1433946.4 | N20: =SUM(N17:N19) -> 473297.37 | O20: =SUM(O17:O19) -> 0 | P20: =SUM(P17:P19) -> 0 | Q20: =SUM(Q17:Q19) -> 0 | ... S20: =SUM(S17:S19) -> 0
B24: (iii) CREATE A SUMMARY TABLE CONTAINING THE TOTAL AMOUNT OF INTEREST EACH YEAR, BROKEN DOWN INTO CASH INTEREST AND NON-CASH INTEREST.
C25: =C31&" Paid is: "&TEXT(SUM(J31:S31),"$#,##0;[Red]$#,##0") -> Total Interest Paid is: $5059,079
C26: ="This consists of "&C29&" of: "&TEXT(SUM(J29:S29),"$#,##0;[Red]$#,##0")& ", and "&C30&" of: "&TEXT(SUM(J30:S30),"$#,##0;[Red]$#,##0") -> This consists of Non-Cash Interest of: $2914,005, and Cash Interest of: $2145,074 | J26: =J$103 -> Forecast
I27: =I$104 -> 2023 | J27: =J$104 -> 2024 | K27: =K$104 -> 2025 | L27: =L$104 -> 2026 | M27: =M$104 -> 2027 | N27: =N$104 -> 2028 | O27: =O$104 -> 2029 | P27: =P$104 -> 2030 | ... S27: =S$104 -> 2033
C28: Interest Summary
C29: =C317 -> Non-Cash Interest | J29: =J317 -> 725265.26 | K29: =K317 -> 556974.92 | L29: =L317 -> 807292.16 | M29: =M317 -> 824472.86 | N29: =N317 -> 0 | O29: =O317 -> 0 | P29: =P317 -> 0 | Q29: =Q317 -> 0 | ... S29: =S317 -> 0
C30: =C318 -> Cash Interest | J30: =J318 -> 188873.24 | K30: =K318 -> 378321.39 | L30: =L318 -> 368400.36 | M30: =M318 -> 327594.15 | N30: =N318 -> 252253.51 | O30: =O318 -> 185014.07 | P30: =P318 -> 147362.02 | Q30: =Q318 -> 123893.39 | ... S30: =S318 -> 73933.725
C31: =C319 -> Total Interest | J31: =J319 -> 914138.5 | K31: =K319 -> 935296.31 | L31: =L319 -> 1175692.5 | M31: =M319 -> 1152067 | N31: =N319 -> 252253.51 | O31: =O319 -> 185014.07 | P31: =P319 -> 147362.02 | Q31: =Q319 -> 123893.39 | ... S31: =S319 -> 73933.725
B35: (iv) WHAT IS THE AMOUNT OF THE MORTGAGE TAKE-OUT FINANCING FOR PROPERTY I?
C36: ="The Amount of Mortgage Take-Out Financing for Property II is: "&TEXT(-SUM(I184:S184),"$#,##0;[Red]$#,##0") -> The Amount of Mortgage Take-Out Financing for Property II is: $7,426,300
B40: (v) WHAT IS THE PROFIT FROM SELLING PROPERTY II?
C41: ="The Property Sold for: "&TEXT(SUM(J131:S131),"$#,##0;[Red]$#,##0") -> The Property Sold for: $18,750,000
C42: ="Total Loan and Interest Paid was: "&TEXT(SUM(J210:S210),"$#,##0;[Red]$#,##0") -> Total Loan and Interest Paid was: $13,563,107
C43: ="Thus, the Profit from Selling Property II is: "&TEXT(SUM(J131:S131,J210:S210),"$#,##0;[Red]$#,##0") -> Thus, the Profit from Selling Property II is: $5,186,893
B47: (vi) DOES THE REVOLVER EVER GET TRIPPED (I.E., THE BALANCE EXCEEDS THE MAXIMUM AMOUNT)? IF SO, IN WHICH YEAR(S) AND BY HOW MUCH?
C48: ="The Maximum Amount allowed to be Borrowed under the Revolver is: "&TEXT(Q76,"$#,##0;[Red]$#,##0") -> The Maximum Amount allowed to be Borrowed under the Revolver is: $1,000,000
C49: =IF(SUM(J53:S53)<>0,"Yes, the Revolver Trips (see below for details):","No, the Revolver does NOT Trip (see below for details):") -> No, the Revolver does NOT Trip (see below for details): | J49: =J$103 -> Forecast
I50: =I$104 -> 2023 | J50: =J$104 -> 2024 | K50: =K$104 -> 2025 | L50: =L$104 -> 2026 | M50: =M$104 -> 2027 | N50: =N$104 -> 2028 | O50: =O$104 -> 2029 | P50: =P$104 -> 2030 | ... S50: =S$104 -> 2033
C51: Revolver (Drawn Amount)
C52: Amount Outstanding - Ending | J52: =J235 -> 188873.24 | K52: =K235 -> 159606.4 | L52: =L235 -> 0 | M52: =M235 -> 0 | N52: =N235 -> 0 | O52: =O235 -> 0 | P52: =P235 -> 0 | Q52: =Q235 -> 0 | ... S52: =S235 -> 0
C53: Tripped? | J53: =IF(J52>$Q$76,1,0) -> 0 | K53: =IF(K52>$Q$76,1,0) -> 0 | L53: =IF(L52>$Q$76,1,0) -> 0 | M53: =IF(M52>$Q$76,1,0) -> 0 | N53: =IF(N52>$Q$76,1,0) -> 0 | O53: =IF(O52>$Q$76,1,0) -> 0 | P53: =IF(P52>$Q$76,1,0) -> 0 | Q53: =IF(Q52>$Q$76,1,0) -> 0 | ... S53: =IF(S52>$Q$76,1,0) -> 0
C54: Overdrawn by: | J54: =-MIN(J242,J52)*J53 -> 0 | K54: =-MIN(K242,K52)*K53 -> 0 | L54: =-MIN(L242,L52)*L53 -> 0 | M54: =-MIN(M242,M52)*M53 -> 0 | N54: =-MIN(N242,N52)*N53 -> 0 | O54: =-MIN(O242,O52)*O53 -> 0 | P54: =-MIN(P242,P52)*P53 -> 0 | Q54: =-MIN(Q242,Q52)*Q53 -> 0 | ... S54: =-MIN(S242,S52)*S53 -> 0
B58: GRANITE BAY REAL ESTATE INC. - DEBT ANSWER
B61: =CaseData!B5 -> ASSUMPTIONS
B63: =CaseData!B7 -> TIMING | J63: =CaseData!J7 -> EXISTING DEBT
G64: =CaseData!G8 -> Information | O64: =CaseData!O8 -> Existing Debt I | Q64: =CaseData!Q8 -> Existing Debt II | S64: =CaseData!S8 -> Existing Debt III
...
