Workbook
Name company: CaseData!$M$2
Name method_selector: Acquisition!$F$9
Name methods: Acquisition!$S$9:$S$10
Name topic: "CFM Topic: " & CaseData!$M$3

Sheet Acquisition
A1: =company -> Alpha
A2: {=topic} -> CFM Topic: Acquisitions
A3: ACQUISITION SCHEDULE | F3: Constant | G3: Unit | H3: Total | J3: {=_xlfn.SEQUENCE( 1, 5, 2022, 1 )} -> 2022 | K3: 2023 | L3: 2024 | M3: 2025 | N3: 2026
A5: Acquisition assumptions
E7: =CaseData!B$3 -> Value of 100% of Bravo's Equity | F7: =CaseData!E$3 -> 4500 | G7: USD m
E8: =CaseData!B$4 -> Percentage of Bravo's Equity Acquired by Alpha | F8: =CaseData!E$4 -> 1 | G8: =CaseData!D$4 -> %
E9: Consolidation Method | F9: 2 | G9: method selection | S9: Equity
S10: Consolidation
B11: Income Statement
E13: Revenue | J13: {=_xlfn.LET( _xlpm.consolidation_method, $F$9, _xlpm.current_account, $E13, _xlpm.alpha_rows,_xlfn.ANCHORARRAY( $E$95), _xlpm.alpha_data,_xlfn.ANCHORARRAY( $J$95), _xlpm.alpha_account, INDEX( _xlpm.alpha_data, MATCH( _xlpm.current_account, _xlpm.alpha_rows, 0 ), 0 ), _xlpm.beta_rows,_xlfn.ANCHORARRAY( $E$175), _xlpm.beta_data,_xlfn.ANCHORARRAY( $J$175), _xlpm.beta_account, INDEX( _xlpm.beta_data, MATCH( _xlpm.current_account, _xlpm.beta_rows, 0 ), 0 ), IF( _xlpm.consolidation_method = 1, _xlpm.alpha_account, _xlpm.alpha_account + _xlpm.beta_account ) )} -> 5189.2857 | K13: 5463.8929 | L13: 5753.1389 | M13: 6057.8104 | N13: 6378.7363
E14: Less: COGS | J14: {=_xlfn.LET( _xlpm.consolidation_method, $F$9, _xlpm.current_account, $E14, _xlpm.alpha_rows,_xlfn.ANCHORARRAY( $E$95), _xlpm.alpha_data,_xlfn.ANCHORARRAY( $J$95), _xlpm.alpha_account, INDEX( _xlpm.alpha_data, MATCH( _xlpm.current_account, _xlpm.alpha_rows, 0 ), 0 ), _xlpm.beta_rows,_xlfn.ANCHORARRAY( $E$175), _xlpm.beta_data,_xlfn.ANCHORARRAY( $J$175), _xlpm.beta_account, INDEX( _xlpm.beta_data, MATCH( _xlpm.current_account, _xlpm.beta_rows, 0 ), 0 ), IF( _xlpm.consolidation_method = 1, _xlpm.alpha_account, _xlpm.alpha_account + _xlpm.beta_account ) )} -> -3031.3929 | K14: -3136.955 | L14: -3245.2602 | M14: -3356.303 | N14: -3470.0699
E15: Gross Profit | J15: =SUM(J13:J14) -> 2157.8929 | K15: =SUM(K13:K14) -> 2326.9379 | L15: =SUM(L13:L14) -> 2507.8788 | M15: =SUM(M13:M14) -> 2701.5073 | N15: =SUM(N13:N14) -> 2908.6663
E16: Less: SG&A | J16: {=_xlfn.LET( _xlpm.consolidation_method, $F$9, _xlpm.current_account, $E16, _xlpm.alpha_rows,_xlfn.ANCHORARRAY( $E$95), _xlpm.alpha_data,_xlfn.ANCHORARRAY( $J$95), _xlpm.alpha_account, INDEX( _xlpm.alpha_data, MATCH( _xlpm.current_account, _xlpm.alpha_rows, 0 ), 0 ), _xlpm.beta_rows,_xlfn.ANCHORARRAY( $E$175), _xlpm.beta_data,_xlfn.ANCHORARRAY( $J$175), _xlpm.beta_account, INDEX( _xlpm.beta_data, MATCH( _xlpm.current_account, _xlpm.beta_rows, 0 ), 0 ), IF( _xlpm.consolidation_method = 1, _xlpm.alpha_account, _xlpm.alpha_account + _xlpm.beta_account ) )} -> -244.32143 | K16: -257.14321 | L16: -270.64243 | M16: -284.85513 | N16: -299.81931
E17: EBITDA | J17: =SUM(J15:J16) -> 1913.5714 | K17: =SUM(K15:K16) -> 2069.7946 | L17: =SUM(L15:L16) -> 2237.2363 | M17: =SUM(M15:M16) -> 2416.6522 | N17: =SUM(N15:N16) -> 2608.847
E18: Less: Depreciation | J18: {=_xlfn.LET( _xlpm.consolidation_method, $F$9, _xlpm.current_account, $E18, _xlpm.alpha_rows,_xlfn.ANCHORARRAY( $E$95), _xlpm.alpha_data,_xlfn.ANCHORARRAY( $J$95), _xlpm.alpha_account, INDEX( _xlpm.alpha_data, MATCH( _xlpm.current_account, _xlpm.alpha_rows, 0 ), 0 ), _xlpm.beta_rows,_xlfn.ANCHORARRAY( $E$175), _xlpm.beta_data,_xlfn.ANCHORARRAY( $J$175), _xlpm.beta_account, INDEX( _xlpm.beta_data, MATCH( _xlpm.current_account, _xlpm.beta_rows, 0 ), 0 ), IF( _xlpm.consolidation_method = 1, _xlpm.alpha_account, _xlpm.alpha_account + _xlpm.beta_account ) )} -> -770.82143 | K18: -811.55821 | L18: -854.46358 | M18: -899.65387 | N18: -947.25169
E19: EBIT | J19: =SUM(J17:J18) -> 1142.75 | K19: =SUM(K17:K18) -> 1258.2364 | L19: =SUM(L17:L18) -> 1382.7728 | M19: =SUM(M17:M18) -> 1516.9983 | N19: =SUM(N17:N18) -> 1661.5954
E20: Add/(Less): Net Interest Income/(Expense) | J20: {=_xlfn.LET( _xlpm.consolidation_method, $F$9, _xlpm.current_account, $E20, _xlpm.alpha_rows,_xlfn.ANCHORARRAY( $E$95), _xlpm.alpha_data,_xlfn.ANCHORARRAY( $J$95), _xlpm.alpha_account, INDEX( _xlpm.alpha_data, MATCH( _xlpm.current_account, _xlpm.alpha_rows, 0 ), 0 ), _xlpm.beta_rows,_xlfn.ANCHORARRAY( $E$175), _xlpm.beta_data,_xlfn.ANCHORARRAY( $J$175), _xlpm.beta_account, INDEX( _xlpm.beta_data, MATCH( _xlpm.current_account, _xlpm.beta_rows, 0 ), 0 ), IF( _xlpm.consolidation_method = 1, _xlpm.alpha_account, _xlpm.alpha_account + _xlpm.beta_account ) )} -> -328.92383 | K20: -282.89596 | L20: -236.41517 | M20: -189.45455 | N20: -141.98528
E21: Earnings before Share of Earnings from Bravo and Tax | J21: =SUM(J19:J20) -> 813.82617 | K21: =SUM(K19:K20) -> 975.34047 | L21: =SUM(L19:L20) -> 1146.3576 | M21: =SUM(M19:M20) -> 1327.5438 | N21: =SUM(N19:N20) -> 1519.6101
E22: Add: Share of Earnings from Bravo | J22: {=_xlfn.LET( _xlpm.method, $F$9, _xlpm.percent, $F$8, _xlpm.bravo_net_income, INDEX( $J$185:$N$185, 1, 0 ), IF( _xlpm.method = 1, _xlpm.bravo_net_income * _xlpm.percent, 0 ) )} -> 0
E23: EBT | J23: =SUM(J21:J22) -> 813.82617 | K23: =SUM(K21:K22) -> 975.34047 | L23: =SUM(L21:L22) -> 1146.3576 | M23: =SUM(M21:M22) -> 1327.5438 | N23: =SUM(N21:N22) -> 1519.6101
E24: Less: Taxes | J24: {=_xlfn.LET( _xlpm.consolidation_method, $F$9, _xlpm.current_account, $E24, _xlpm.alpha_rows,_xlfn.ANCHORARRAY( $E$95), _xlpm.alpha_data,_xlfn.ANCHORARRAY( $J$95), _xlpm.alpha_account, INDEX( _xlpm.alpha_data, MATCH( _xlpm.current_account, _xlpm.alpha_rows, 0 ), 0 ), _xlpm.beta_rows,_xlfn.ANCHORARRAY( $E$175), _xlpm.beta_data,_xlfn.ANCHORARRAY( $J$175), _xlpm.beta_account, INDEX( _xlpm.beta_data, MATCH( _xlpm.current_account, _xlpm.beta_rows, 0 ), 0 ), IF( _xlpm.consolidation_method = 1, _xlpm.alpha_account, _xlpm.alpha_account + _xlpm.beta_account ) )} -> -198.18253 | K24: -237.50263 | L24: -279.13046 | M24: -323.22734 | N24: -369.96536
E25: Net Earnings before Non controlling Interest | J25: =SUM(J23:J24) -> 615.64364 | K25: =SUM(K23:K24) -> 737.83784 | L25: =SUM(L23:L24) -> 867.22712 | M25: =SUM(M23:M24) -> 1004.3165 | N25: =SUM(N23:N24) -> 1149.6447
E26: Less: Non-Controlling Interest | J26: {=_xlfn.LET( _xlpm.method, $F$9, _xlpm.percent, $F$8, _xlpm.bravo_net_income, INDEX( $J$185:$N$185, 1, 0 ), IF( _xlpm.method = 1, _xlfn.SEQUENCE( 1, 5, 0, 0 ), - _xlpm.bravo_net_income * ( 1 - _xlpm.percent ) ) )} -> 0 | K26: 0 | L26: 0 | M26: 0 | N26: 0
E27: Net Income | J27: =SUM(J25:J26) -> 615.64364 | K27: =SUM(K25:K26) -> 737.83784 | L27: =SUM(L25:L26) -> 867.22712 | M27: =SUM(M25:M26) -> 1004.3165 | N27: =SUM(N25:N26) -> 1149.6447
B29: Cash Flow Statement
D31: Cash Flow from Operations
E32: Net Income | J32: {=J27:N27} -> 615.64364 | K32: 737.83784 | L32: 867.22712 | M32: 1004.3165 | N32: 1149.6447
E33: Add: Depreciation | J33: {=_xlfn.LET( _xlpm.consolidation_method, $F$9, _xlpm.current_account, $E33, _xlpm.alpha_rows,_xlfn.ANCHORARRAY( $E$95), _xlpm.alpha_data,_xlfn.ANCHORARRAY( $J$95), _xlpm.alpha_account, INDEX( _xlpm.alpha_data, MATCH( _xlpm.current_account, _xlpm.alpha_rows, 0 ), 0 ), _xlpm.beta_rows,_xlfn.ANCHORARRAY( $E$175), _xlpm.beta_data,_xlfn.ANCHORARRAY( $J$175), _xlpm.beta_account, INDEX( _xlpm.beta_data, MATCH( _xlpm.current_account, _xlpm.beta_rows, 0 ), 0 ), IF( _xlpm.consolidation_method = 1, _xlpm.alpha_account, _xlpm.alpha_account + _xlpm.beta_account ) )} -> 770.82143 | K33: 811.55821 | L33: 854.46358 | M33: 899.65387 | N33: 947.25169
E34: Add: Non-Controlling Interest | J34: {=_xlfn.LET( _xlpm.method, $F$9, _xlpm.non_controlling_interest, INDEX(_xlfn.ANCHORARRAY( J26), 1, 0 ), IF( _xlpm.method = 1, _xlpm.non_controlling_interest, - _xlpm.non_controlling_interest ) )} -> 0 | K34: 0 | L34: 0 | M34: 0 | N34: 0
E35: Add: Share of Dividends from Bravo | J35: {=_xlfn.LET( _xlpm.method, $F$9, _xlpm.percent, $F$8, _xlpm.bravo_dividends, INDEX( $J$207:$N$207, 1, 0 ), IF( _xlpm.method = 1, - _xlpm.bravo_dividends * _xlpm.percent, _xlfn.SEQUENCE( 1, 5, 0, 0 ) ) )} -> 0 | K35: 0 | L35: 0 | M35: 0 | N35: 0
E36: Add/(Less): Change in W/C | J36: {=_xlfn.LET( _xlpm.consolidation_method, $F$9, _xlpm.current_account, $E36, _xlpm.alpha_rows,_xlfn.ANCHORARRAY( $E$95), _xlpm.alpha_data,_xlfn.ANCHORARRAY( $J$95), _xlpm.alpha_account, INDEX( _xlpm.alpha_data, MATCH( _xlpm.current_account, _xlpm.alpha_rows, 0 ), 0 ), _xlpm.beta_rows,_xlfn.ANCHORARRAY( $E$175), _xlpm.beta_data,_xlfn.ANCHORARRAY( $J$175), _xlpm.beta_account, INDEX( _xlpm.beta_data, MATCH( _xlpm.current_account, _xlpm.beta_rows, 0 ), 0 ), IF( _xlpm.consolidation_method = 1, _xlpm.alpha_account, _xlpm.alpha_account + _xlpm.beta_account ) )} -> -33.544286 | K36: -35.167479 | L36: -36.869147 | M36: -38.653077 | N36: -40.523234
E37: Less: Share of Earnings from Bravo | J37: {=-_xlfn.ANCHORARRAY( J22)} -> 0
E38: Cash Flow from Operations | J38: =SUM(J32:J37) -> 1352.9208 | K38: =SUM(K32:K37) -> 1514.2286 | L38: =SUM(L32:L37) -> 1684.8216 | M38: =SUM(M32:M37) -> 1865.3172 | N38: =SUM(N32:N37) -> 2056.3732
D40: Cash Flow from Investing Activities
E41: Less: Capex | J41: {=_xlfn.LET( _xlpm.consolidation_method, $F$9, _xlpm.current_account, $E41, _xlpm.alpha_rows,_xlfn.ANCHORARRAY( $E$95), _xlpm.alpha_data,_xlfn.ANCHORARRAY( $J$95), _xlpm.alpha_account, INDEX( _xlpm.alpha_data, MATCH( _xlpm.current_account, _xlpm.alpha_rows, 0 ), 0 ), _xlpm.beta_rows,_xlfn.ANCHORARRAY( $E$175), _xlpm.beta_data,_xlfn.ANCHORARRAY( $J$175), _xlpm.beta_account, INDEX( _xlpm.beta_data, MATCH( _xlpm.current_account, _xlpm.beta_rows, 0 ), 0 ), IF( _xlpm.consolidation_method = 1, _xlpm.alpha_account, _xlpm.alpha_account + _xlpm.beta_account ) )} -> -847.90357 | K41: -892.71404 | L41: -939.90994 | M41: -989.61925 | N41: -1041.9769
E42: Cash Flow from Investing Activities | J42: =SUM(J41) -> -847.90357 | K42: =SUM(K41) -> -892.71404 | L42: =SUM(L41) -> -939.90994 | M42: =SUM(M41) -> -989.61925 | N42: =SUM(N41) -> -1041.9769
D44: Cash Flow from Financing Activities
E45: Add/(Less): Issuance/(Repayment) of Debt | J45: {=_xlfn.LET( _xlpm.consolidation_method, $F$9, _xlpm.current_account, $E45, _xlpm.alpha_rows,_xlfn.ANCHORARRAY( $E$95), _xlpm.alpha_data,_xlfn.ANCHORARRAY( $J$95), _xlpm.alpha_account, INDEX( _xlpm.alpha_data, MATCH( _xlpm.current_account, _xlpm.alpha_rows, 0 ), 0 ), _xlpm.beta_rows,_xlfn.ANCHORARRAY( $E$175), _xlpm.beta_data,_xlfn.ANCHORARRAY( $J$175), _xlpm.beta_account, INDEX( _xlpm.beta_data, MATCH( _xlpm.current_account, _xlpm.beta_rows, 0 ), 0 ), IF( _xlpm.consolidation_method = 1, _xlpm.alpha_account, _xlpm.alpha_account + _xlpm.beta_account ) )} -> -700 | K45: -700 | L45: -700 | M45: -700 | N45: -700
E46: Add/(Less): Issuance/(Repayment) of Common Shares | J46: {=_xlfn.LET( _xlpm.consolidation_method, $F$9, _xlpm.current_account, $E46, _xlpm.alpha_rows,_xlfn.ANCHORARRAY( $E$95), _xlpm.alpha_data,_xlfn.ANCHORARRAY( $J$95), _xlpm.alpha_account, INDEX( _xlpm.alpha_data, MATCH( _xlpm.current_account, _xlpm.alpha_rows, 0 ), 0 ), _xlpm.beta_rows,_xlfn.ANCHORARRAY( $E$175), _xlpm.beta_data,_xlfn.ANCHORARRAY( $J$175), _xlpm.beta_account, INDEX( _xlpm.beta_data, MATCH( _xlpm.current_account, _xlpm.beta_rows, 0 ), 0 ), IF( _xlpm.consolidation_method = 1, IF( _xlpm.alpha_account = "", 0, _xlpm.alpha_account ), IFERROR( _xlpm.alpha_account + _xlpm.beta_account, 0 ) ) )} -> 0 | K46: 0 | L46: 0 | M46: 0 | N46: 0
E47: Less: Dividends Paid to Non-Controlling Interests | J47: {=_xlfn.LET( _xlpm.method, $F$9, _xlpm.percent, $F$8, _xlpm.bravo_dividends, INDEX( $J$207:$N$207, 1, 0 ), IF( _xlpm.method = 1, _xlfn.SEQUENCE( 1, 5, 0, 0 ), _xlpm.bravo_dividends * (1 - _xlpm.percent ) ) )} -> 0 | K47: 0 | L47: 0 | M47: 0 | N47: 0
...

Sheet CaseData
A1: Acquisition Assumptions
K2: Company name | M2: Alpha
B3: Value of 100% of Bravo's Equity | D3: USD$ millions | E3: 4500 | K3: Topic | M3: Acquisitions
B4: Percentage of Bravo's Equity Acquired by Alpha | D4: % | E4: 1
A7: Alpha Financial Statements (Prior to the Acquisition)
B10: Income statement
B11: (in USD$ millions, fiscal years ended December 31st)
C13: 2021 | D13: =C13+1 -> 2022 | E13: =D13+1 -> 2023 | F13: =E13+1 -> 2024 | G13: =F13+1 -> 2025 | H13: =G13+1 -> 2026
B15: Revenue | C15: 3500 | D15: 3675 | E15: 3858.75 | F15: 4051.6875 | G15: 4254.2719 | H15: 4466.9855
B16: Less: COGS | C16: -2100 | D16: -2168.25 | E16: -2238.075 | F16: -2309.4619 | G16: -2382.3922 | H16: -2456.842
B17: Gross Profit | C17: =SUM(C15:C16) -> 1400 | D17: =SUM(D15:D16) -> 1506.75 | E17: =SUM(E15:E16) -> 1620.675 | F17: =SUM(F15:F16) -> 1742.2256 | G17: =SUM(G15:G16) -> 1871.8796 | H17: =SUM(H15:H16) -> 2010.1435
B18: Less: SG&A | C18: -175 | D18: -183.75 | E18: -192.9375 | F18: -202.58438 | G18: -212.71359 | H18: -223.34927
B19: EBITDA | C19: =SUM(C17:C18) -> 1225 | D19: =SUM(D17:D18) -> 1323 | E19: =SUM(E17:E18) -> 1427.7375 | F19: =SUM(F17:F18) -> 1539.6413 | G19: =SUM(G17:G18) -> 1659.166 | H19: =SUM(H17:H18) -> 1786.7942
B20: Less: Depreciation | C20: -525 | D20: -551.25 | E20: -578.8125 | F20: -607.75312 | G20: -638.14078 | H20: -670.04782
B21: EBIT | C21: =SUM(C19:C20) -> 700 | D21: =SUM(D19:D20) -> 771.75 | E21: =SUM(E19:E20) -> 848.925 | F21: =SUM(F19:F20) -> 931.88813 | G21: =SUM(G19:G20) -> 1021.0253 | H21: =SUM(H19:H20) -> 1116.7464
B22: Add/(Less): Net Interest Income/(Expense) | C22: -252.75288 | D22: -221.62456 | E22: -190.20869 | F22: -158.47721 | G22: -126.41212 | H22: -93.994238
B23: EBT | C23: =SUM(C21:C22) -> 447.24712 | D23: =SUM(D21:D22) -> 550.12544 | E23: =SUM(E21:E22) -> 658.71631 | F23: =SUM(F21:F22) -> 773.41092 | G23: =SUM(G21:G22) -> 894.61313 | H23: =SUM(H21:H22) -> 1022.7521
B24: Less: Taxes | C24: -111.81178 | D24: -137.53136 | E24: -164.67908 | F24: -193.35273 | G24: -223.65328 | H24: -255.68803
B25: Net Income | C25: =SUM(C23:C24) -> 335.43534 | D25: =SUM(D23:D24) -> 412.59408 | E25: =SUM(E23:E24) -> 494.03723 | F25: =SUM(F23:F24) -> 580.05819 | G25: =SUM(G23:G24) -> 670.95985 | H25: =SUM(H23:H24) -> 767.0641
B29: Cash Flow Statement
B30: (in USD$ millions, fiscal years ended December 31st)
C32: =C13 -> 2021 | D32: =D13 -> 2022 | E32: =E13 -> 2023 | F32: =F13 -> 2024 | G32: =G13 -> 2025 | H32: =H13 -> 2026
B34: Cash Flow from Operations
B35: Net Income | C35: =C25 -> 335.43534 | D35: =D25 -> 412.59408 | E35: =E25 -> 494.03723 | F35: =F25 -> 580.05819 | G35: =G25 -> 670.95985 | H35: =H25 -> 767.0641
B36: Add: Depreciation | C36: =-C20 -> 525 | D36: =-D20 -> 551.25 | E36: =-E20 -> 578.8125 | F36: =-F20 -> 607.75312 | G36: =-G20 -> 638.14078 | H36: =-H20 -> 670.04782
B37: Add/(Less): Change in W/C | C37: -17 | D37: -22.47 | E37: -23.48325 | F37: -24.54165 | G37: -25.647182 | H37: -26.801913
B38: Cash Flow from Operations | C38: =SUM(C35:C37) -> 843.43534 | D38: =SUM(D35:D37) -> 941.37408 | E38: =SUM(E35:E37) -> 1049.3665 | F38: =SUM(F35:F37) -> 1163.2697 | G38: =SUM(G35:G37) -> 1283.4534 | H38: =SUM(H35:H37) -> 1410.31
B40: Cash Flow from Investing Activities
B41: Less: Capex | C41: -577.5 | D41: -606.375 | E41: -636.69375 | F41: -668.52844 | G41: -701.95486 | H41: -737.0526
B42: Cash Flow from Investing Activities | C42: =SUM(C41:C41) -> -577.5 | D42: =SUM(D41:D41) -> -606.375 | E42: =SUM(E41:E41) -> -636.69375 | F42: =SUM(F41:F41) -> -668.52844 | G42: =SUM(G41:G41) -> -701.95486 | H42: =SUM(H41:H41) -> -737.0526
B44: Cash Flow from Financing Activities
B45: Add/(Less): Issuance/(Repayment) of Debt | C45: -500 | D45: -500 | E45: -500 | F45: -500 | G45: -500 | H45: -500
B46: Add/(Less): Issuance/(Repayment) of Common Shares | C46: 0 | D46: 0 | E46: 0 | F46: 0 | G46: 0 | H46: 0
B47: Less: Dividends | C47: -67.087068 | D47: -82.518816 | E47: -98.807446 | F47: -116.01164 | G47: -134.19197 | H47: -153.41282
B48: Cash Flow from Financing Activities | C48: =SUM(C45:C47) -> -567.08707 | D48: =SUM(D45:D47) -> -582.51882 | E48: =SUM(E45:E47) -> -598.80745 | F48: =SUM(F45:F47) -> -616.01164 | G48: =SUM(G45:G47) -> -634.19197 | H48: =SUM(H45:H47) -> -653.41282
B50: Beginning Cash & Equivalents | C50: 4850 | D50: =C52 -> 4548.8483 | E50: =D52 -> 4301.3285 | F50: =E52 -> 4115.1938 | G50: =F52 -> 3993.9234 | H50: =G52 -> 3941.23
B51: Change in Cash & Equivalents | C51: =C38+C42+C48 -> -301.15173 | D51: =D38+D42+D48 -> -247.51973 | E51: =E38+E42+E48 -> -186.13472 | F51: =F38+F42+F48 -> -121.27041 | G51: =G38+G42+G48 -> -52.69338 | H51: =H38+H42+H48 -> 19.844582
B52: Ending Cash & Equivalents | C52: =SUM(C50:C51) -> 4548.8483 | D52: =SUM(D50:D51) -> 4301.3285 | E52: =SUM(E50:E51) -> 4115.1938 | F52: =SUM(F50:F51) -> 3993.9234 | G52: =SUM(G50:G51) -> 3941.23 | H52: =SUM(H50:H51) -> 3961.0746
B56: Balance Sheet
B57: (in USD$ millions, fiscal years ended December 31st)
...

Sheet CaseSolution
B2: Pro Forma Financial Statements
C4: Pro Forma Financial Statements | D4: Click Here
B7: Summary Table of Answers
E9: % of Bravo's Equity Acquired by Alpha
E10: 0.25 | F10: 0.75 | G10: 1
C11: 2025 Retained Earnings | D11: =$H$120 -> 10638.443 | E11: 9837.9117 | F11: 10371.6 | G11: 10638.443
C12: 2023 Investment in Bravo | D12: =$F$98 -> 0 | E12: 1203.1988 | F12: 0 | G12: 0
C13: 2024 Non-Controlling Interests | D13: =$G$121 -> 0 | E13: 0 | F13: 1253.4533 | G13: 0
C14: 2026 EBITDA | D14: =$I$41 -> 2608.847 | E14: 1786.7942 | F14: 2608.847 | G14: 2608.847
B18: ="LIVE: CURRENTLY RUNNING: "&UPPER(I27) -> LIVE: CURRENTLY RUNNING: CONSOLIDATION METHOD | K18: EQUITY METHODOLOGY | V18: CONSOLIDATION METHODOLOGY
C20: If Alpha acquires >=20% but <=50% of Bravo's equity, the Equity Method is applied. | F20: 0.2 | G20: 0.5 | H20: Equity Method | L20: =C20 -> If Alpha acquires >=20% but <=50% of Bravo's equity, the Equity Method is applied. | W20: =C21 -> If Alpha acquires >50% of Bravo's equity, the Consolidation Method is applied.
C21: If Alpha acquires >50% of Bravo's equity, the Consolidation Method is applied. | F21: 0.5 | H21: Consolidation Method
B23: Acquisition Assumptions | K23: Acquisition Assumptions | V23: Acquisition Assumptions
C25: Value of 100% of Bravo's Equity | D25: USD$ millions | E25: =CaseData!E3 -> 4500 | G25: BS Check: | I25: =IF(AND(MAX(D125:I125)=0, MIN(D125:I125)=0), "Balanced", "Error") -> Balanced | L25: Value of 100% of Bravo's Equity | M25: USD$ millions | N25: =$E25 -> 4500 | Q25: BS Check: | S25: =IF(AND(MAX(O125:T125)=0, MIN(O125:T125)=0), "Balanced", "Error") -> Balanced | W25: Value of 100% of Bravo's Equity | X25: USD$ millions | Y25: =$E25 -> 4500 | AB25: BS Check: | AD25: =IF(AND(MAX(Z125:AE125)=0, MIN(Z125:AE125)=0), "Balanced", "Error") -> Balanced
C26: Percentage of Bravo's Equity Acquired by Alpha | D26: % | E26: =CaseData!E4 -> 1 | L26: Percentage of Bravo's Equity Acquired by Alpha | M26: % | N26: =$E26 -> 1 | W26: Percentage of Bravo's Equity Acquired by Alpha | X26: % | Y26: =$E26 -> 1
G27: Running: | I27: =VLOOKUP($E$26,$F$20:$H$21,COLUMNS($F$20:$H$20),TRUE) -> Consolidation Method | Q27: Running: | S27: =H20 -> Equity Method | AB27: Running: | AD27: =H21 -> Consolidation Method
B29: ="Alpha Financial Statements (Pro-Forma under "&I27&")" -> Alpha Financial Statements (Pro-Forma under Consolidation Method) | K29: ="Alpha Financial Statements (Pro-Forma under "&S27&")" -> Alpha Financial Statements (Pro-Forma under Equity Method) | V29: ="Alpha Financial Statements (Pro-Forma under "&AD27&")" -> Alpha Financial Statements (Pro-Forma under Consolidation Method)
C32: ="Alpha Income Statement (Pro-Forma under "&I27&")" -> Alpha Income Statement (Pro-Forma under Consolidation Method) | L32: ="Alpha Income Statement (Pro-Forma under "&S27&")" -> Alpha Income Statement (Pro-Forma under Equity Method) | W32: ="Alpha Income Statement (Pro-Forma under "&AD27&")" -> Alpha Income Statement (Pro-Forma under Consolidation Method)
C33: (in USD$ millions, fiscal years ended December 31st) | L33: (in USD$ millions, fiscal years ended December 31st) | W33: (in USD$ millions, fiscal years ended December 31st)
D35: =O35 -> 44561 | E35: =P35 -> 44926 | F35: =Q35 -> 45291 | G35: =R35 -> 45657 | H35: =S35 -> 46022 | I35: =T35 -> 46387 | O35: =O135 -> 44561 | P35: =P135 -> 44926 | Q35: =Q135 -> 45291 | R35: =R135 -> 45657 | S35: =S135 -> 46022 | T35: =T135 -> 46387 | Z35: =Z135 -> 44561 | AA35: =AA135 -> 44926 | AB35: =AB135 -> 45291 | AC35: =AC135 -> 45657 | AD35: =AD135 -> 46022 | AE35: =AE135 -> 46387
C37: Revenue | E37: =IF($I$27=$H$20,P37,AA37) -> 5189.2857 | F37: =IF($I$27=$H$20,Q37,AB37) -> 5463.8929 | G37: =IF($I$27=$H$20,R37,AC37) -> 5753.1389 | H37: =IF($I$27=$H$20,S37,AD37) -> 6057.8104 | I37: =IF($I$27=$H$20,T37,AE37) -> 6378.7363 | L37: Revenue | P37: =P137 -> 3675 | Q37: =Q137 -> 3858.75 | R37: =R137 -> 4051.6875 | S37: =S137 -> 4254.2719 | T37: =T137 -> 4466.9855 | W37: Revenue | AA37: =SUM(AA137,AA226) -> 5189.2857 | AB37: =SUM(AB137,AB226) -> 5463.8929 | AC37: =SUM(AC137,AC226) -> 5753.1389 | AD37: =SUM(AD137,AD226) -> 6057.8104 | AE37: =SUM(AE137,AE226) -> 6378.7363
C38: Less: COGS | E38: =IF($I$27=$H$20,P38,AA38) -> -3031.3929 | F38: =IF($I$27=$H$20,Q38,AB38) -> -3136.955 | G38: =IF($I$27=$H$20,R38,AC38) -> -3245.2602 | H38: =IF($I$27=$H$20,S38,AD38) -> -3356.303 | I38: =IF($I$27=$H$20,T38,AE38) -> -3470.0699 | L38: Less: COGS | P38: =P138 -> -2168.25 | Q38: =Q138 -> -2238.075 | R38: =R138 -> -2309.4619 | S38: =S138 -> -2382.3922 | T38: =T138 -> -2456.842 | W38: Less: COGS | AA38: =SUM(AA138,AA227) -> -3031.3929 | AB38: =SUM(AB138,AB227) -> -3136.955 | AC38: =SUM(AC138,AC227) -> -3245.2602 | AD38: =SUM(AD138,AD227) -> -3356.303 | AE38: =SUM(AE138,AE227) -> -3470.0699
C39: Gross Profit | E39: =SUM(E37:E38) -> 2157.8929 | F39: =SUM(F37:F38) -> 2326.9379 | G39: =SUM(G37:G38) -> 2507.8788 | H39: =SUM(H37:H38) -> 2701.5073 | I39: =SUM(I37:I38) -> 2908.6663 | L39: Gross Profit | P39: =SUM(P37:P38) -> 1506.75 | Q39: =SUM(Q37:Q38) -> 1620.675 | R39: =SUM(R37:R38) -> 1742.2256 | S39: =SUM(S37:S38) -> 1871.8796 | T39: =SUM(T37:T38) -> 2010.1435 | W39: Gross Profit | AA39: =SUM(AA37:AA38) -> 2157.8929 | AB39: =SUM(AB37:AB38) -> 2326.9379 | AC39: =SUM(AC37:AC38) -> 2507.8788 | AD39: =SUM(AD37:AD38) -> 2701.5073 | AE39: =SUM(AE37:AE38) -> 2908.6663
C40: Less: SG&A | E40: =IF($I$27=$H$20,P40,AA40) -> -244.32143 | F40: =IF($I$27=$H$20,Q40,AB40) -> -257.14321 | G40: =IF($I$27=$H$20,R40,AC40) -> -270.64243 | H40: =IF($I$27=$H$20,S40,AD40) -> -284.85513 | I40: =IF($I$27=$H$20,T40,AE40) -> -299.81931 | L40: Less: SG&A | P40: =P140 -> -183.75 | Q40: =Q140 -> -192.9375 | R40: =R140 -> -202.58438 | S40: =S140 -> -212.71359 | T40: =T140 -> -223.34927 | W40: Less: SG&A | AA40: =SUM(AA140,AA229) -> -244.32143 | AB40: =SUM(AB140,AB229) -> -257.14321 | AC40: =SUM(AC140,AC229) -> -270.64243 | AD40: =SUM(AD140,AD229) -> -284.85513 | AE40: =SUM(AE140,AE229) -> -299.81931
C41: EBITDA | E41: =SUM(E39:E40) -> 1913.5714 | F41: =SUM(F39:F40) -> 2069.7946 | G41: =SUM(G39:G40) -> 2237.2363 | H41: =SUM(H39:H40) -> 2416.6522 | I41: =SUM(I39:I40) -> 2608.847 | L41: EBITDA | P41: =SUM(P39:P40) -> 1323 | Q41: =SUM(Q39:Q40) -> 1427.7375 | R41: =SUM(R39:R40) -> 1539.6413 | S41: =SUM(S39:S40) -> 1659.166 | T41: =SUM(T39:T40) -> 1786.7942 | W41: EBITDA | AA41: =SUM(AA39:AA40) -> 1913.5714 | AB41: =SUM(AB39:AB40) -> 2069.7946 | AC41: =SUM(AC39:AC40) -> 2237.2363 | AD41: =SUM(AD39:AD40) -> 2416.6522 | AE41: =SUM(AE39:AE40) -> 2608.847
C42: Less: Depreciation | E42: =IF($I$27=$H$20,P42,AA42) -> -770.82143 | F42: =IF($I$27=$H$20,Q42,AB42) -> -811.55821 | G42: =IF($I$27=$H$20,R42,AC42) -> -854.46358 | H42: =IF($I$27=$H$20,S42,AD42) -> -899.65387 | I42: =IF($I$27=$H$20,T42,AE42) -> -947.25169 | L42: Less: Depreciation | P42: =P142 -> -551.25 | Q42: =Q142 -> -578.8125 | R42: =R142 -> -607.75312 | S42: =S142 -> -638.14078 | T42: =T142 -> -670.04782 | W42: Less: Depreciation | AA42: =SUM(AA142,AA231) -> -770.82143 | AB42: =SUM(AB142,AB231) -> -811.55821 | AC42: =SUM(AC142,AC231) -> -854.46358 | AD42: =SUM(AD142,AD231) -> -899.65387 | AE42: =SUM(AE142,AE231) -> -947.25169
C43: EBIT | E43: =SUM(E41:E42) -> 1142.75 | F43: =SUM(F41:F42) -> 1258.2364 | G43: =SUM(G41:G42) -> 1382.7728 | H43: =SUM(H41:H42) -> 1516.9983 | I43: =SUM(I41:I42) -> 1661.5954 | L43: EBIT | P43: =SUM(P41:P42) -> 771.75 | Q43: =SUM(Q41:Q42) -> 848.925 | R43: =SUM(R41:R42) -> 931.88813 | S43: =SUM(S41:S42) -> 1021.0253 | T43: =SUM(T41:T42) -> 1116.7464 | W43: EBIT | AA43: =SUM(AA41:AA42) -> 1142.75 | AB43: =SUM(AB41:AB42) -> 1258.2364 | AC43: =SUM(AC41:AC42) -> 1382.7728 | AD43: =SUM(AD41:AD42) -> 1516.9983 | AE43: =SUM(AE41:AE42) -> 1661.5954
C44: Add/(Less): Net Interest Income/(Expense) | E44: =IF($I$27=$H$20,P44,AA44) -> -328.92383 | F44: =IF($I$27=$H$20,Q44,AB44) -> -282.89596 | G44: =IF($I$27=$H$20,R44,AC44) -> -236.41517 | H44: =IF($I$27=$H$20,S44,AD44) -> -189.45455 | I44: =IF($I$27=$H$20,T44,AE44) -> -141.98528 | L44: Add/(Less): Net Interest Income/(Expense) | P44: =P144 -> -221.62456 | Q44: =Q144 -> -190.20869 | R44: =R144 -> -158.47721 | S44: =S144 -> -126.41212 | T44: =T144 -> -93.994238 | W44: Add/(Less): Net Interest Income/(Expense) | AA44: =SUM(AA144,AA233) -> -328.92383 | AB44: =SUM(AB144,AB233) -> -282.89596 | AC44: =SUM(AC144,AC233) -> -236.41517 | AD44: =SUM(AD144,AD233) -> -189.45455 | AE44: =SUM(AE144,AE233) -> -141.98528
C45: Earnings before Share of Earnings from Bravo and Tax | E45: =SUM(E43:E44) -> 813.82617 | F45: =SUM(F43:F44) -> 975.34047 | G45: =SUM(G43:G44) -> 1146.3576 | H45: =SUM(H43:H44) -> 1327.5438 | I45: =SUM(I43:I44) -> 1519.6101 | L45: Earnings before Share of Earnings from Bravo and Tax | P45: =SUM(P43:P44) -> 550.12544 | Q45: =SUM(Q43:Q44) -> 658.71631 | R45: =SUM(R43:R44) -> 773.41092 | S45: =SUM(S43:S44) -> 894.61313 | T45: =SUM(T43:T44) -> 1022.7521 | W45: Earnings before Share of Earnings from Bravo and Tax | AA45: =SUM(AA43:AA44) -> 813.82617 | AB45: =SUM(AB43:AB44) -> 975.34047 | AC45: =SUM(AC43:AC44) -> 1146.3576 | AD45: =SUM(AD43:AD44) -> 1327.5438 | AE45: =SUM(AE43:AE44) -> 1519.6101
C46: Add: Share of Earnings from Bravo | E46: =IF($I$27=$H$20,P46,AA46) -> 0 | F46: =IF($I$27=$H$20,Q46,AB46) -> 0 | G46: =IF($I$27=$H$20,R46,AC46) -> 0 | H46: =IF($I$27=$H$20,S46,AD46) -> 0 | I46: =IF($I$27=$H$20,T46,AE46) -> 0 | L46: Add: Share of Earnings from Bravo | P46: =P236*$N$26 -> 203.04956 | Q46: =Q236*$N$26 -> 243.80061 | R46: =R236*$N$26 -> 287.16893 | S46: =S236*$N$26 -> 333.35661 | T46: =T236*$N$26 -> 382.58062 | W46: Add: Share of Earnings from Bravo | AA46: 0 | AB46: 0 | AC46: 0 | AD46: 0 | AE46: 0
C47: EBT | E47: =SUM(E45:E46) -> 813.82617 | F47: =SUM(F45:F46) -> 975.34047 | G47: =SUM(G45:G46) -> 1146.3576 | H47: =SUM(H45:H46) -> 1327.5438 | I47: =SUM(I45:I46) -> 1519.6101 | L47: EBT | P47: =SUM(P45:P46) -> 753.175 | Q47: =SUM(Q45:Q46) -> 902.51691 | R47: =SUM(R45:R46) -> 1060.5799 | S47: =SUM(S45:S46) -> 1227.9697 | T47: =SUM(T45:T46) -> 1405.3327 | W47: EBT | AA47: =SUM(AA45:AA46) -> 813.82617 | AB47: =SUM(AB45:AB46) -> 975.34047 | AC47: =SUM(AC45:AC46) -> 1146.3576 | AD47: =SUM(AD45:AD46) -> 1327.5438 | AE47: =SUM(AE45:AE46) -> 1519.6101
C48: Less: Taxes | E48: =IF($I$27=$H$20,P48,AA48) -> -198.18253 | F48: =IF($I$27=$H$20,Q48,AB48) -> -237.50263 | G48: =IF($I$27=$H$20,R48,AC48) -> -279.13046 | H48: =IF($I$27=$H$20,S48,AD48) -> -323.22734 | I48: =IF($I$27=$H$20,T48,AE48) -> -369.96536 | L48: Less: Taxes | P48: =P146 -> -137.53136 | Q48: =Q146 -> -164.67908 | R48: =R146 -> -193.35273 | S48: =S146 -> -223.65328 | T48: =T146 -> -255.68803 | W48: Less: Taxes | AA48: =SUM(AA146,AA235) -> -198.18253 | AB48: =SUM(AB146,AB235) -> -237.50263 | AC48: =SUM(AC146,AC235) -> -279.13046 | AD48: =SUM(AD146,AD235) -> -323.22734 | AE48: =SUM(AE146,AE235) -> -369.96536
C49: Net Earnings before Noncontrolling Interest | E49: =SUM(E47:E48) -> 615.64364 | F49: =SUM(F47:F48) -> 737.83784 | G49: =SUM(G47:G48) -> 867.22712 | H49: =SUM(H47:H48) -> 1004.3165 | I49: =SUM(I47:I48) -> 1149.6447 | L49: Net Earnings before Noncontrolling Interest | P49: =SUM(P47:P48) -> 615.64364 | Q49: =SUM(Q47:Q48) -> 737.83784 | R49: =SUM(R47:R48) -> 867.22712 | S49: =SUM(S47:S48) -> 1004.3165 | T49: =SUM(T47:T48) -> 1149.6447 | W49: Net Earnings before Noncontrolling Interest | AA49: =SUM(AA47:AA48) -> 615.64364 | AB49: =SUM(AB47:AB48) -> 737.83784 | AC49: =SUM(AC47:AC48) -> 867.22712 | AD49: =SUM(AD47:AD48) -> 1004.3165 | AE49: =SUM(AE47:AE48) -> 1149.6447
C50: Less: Non-Controlling Interest | E50: =IF($I$27=$H$20,P50,AA50) -> 0 | F50: =IF($I$27=$H$20,Q50,AB50) -> 0 | G50: =IF($I$27=$H$20,R50,AC50) -> 0 | H50: =IF($I$27=$H$20,S50,AD50) -> 0 | I50: =IF($I$27=$H$20,T50,AE50) -> 0 | L50: Less: Non-Controlling Interest | P50: 0 | Q50: 0 | R50: 0 | S50: 0 | T50: 0 | W50: Less: Non-Controlling Interest | AA50: =-AA236*(1-$Y$26) -> 0 | AB50: =-AB236*(1-$Y$26) -> 0 | AC50: =-AC236*(1-$Y$26) -> 0 | AD50: =-AD236*(1-$Y$26) -> 0 | AE50: =-AE236*(1-$Y$26) -> 0
C51: Net Income | E51: =SUM(E49:E50) -> 615.64364 | F51: =SUM(F49:F50) -> 737.83784 | G51: =SUM(G49:G50) -> 867.22712 | H51: =SUM(H49:H50) -> 1004.3165 | I51: =SUM(I49:I50) -> 1149.6447 | L51: Net Income | P51: =SUM(P49:P50) -> 615.64364 | Q51: =SUM(Q49:Q50) -> 737.83784 | R51: =SUM(R49:R50) -> 867.22712 | S51: =SUM(S49:S50) -> 1004.3165 | T51: =SUM(T49:T50) -> 1149.6447 | W51: Net Income | AA51: =SUM(AA49:AA50) -> 615.64364 | AB51: =SUM(AB49:AB50) -> 737.83784 | AC51: =SUM(AC49:AC50) -> 867.22712 | AD51: =SUM(AD49:AD50) -> 1004.3165 | AE51: =SUM(AE49:AE50) -> 1149.6447
C55: ="Alpha Cash Flow Statement (Pro-Forma under "&I27&")" -> Alpha Cash Flow Statement (Pro-Forma under Consolidation Method) | L55: ="Alpha Cash Flow Statement (Pro-Forma under "&S27&")" -> Alpha Cash Flow Statement (Pro-Forma under Equity Method) | W55: ="Alpha Cash Flow Statement (Pro-Forma under "&AD27&")" -> Alpha Cash Flow Statement (Pro-Forma under Consolidation Method)
C56: (in USD$ millions, fiscal years ended December 31st) | L56: (in USD$ millions, fiscal years ended December 31st) | W56: (in USD$ millions, fiscal years ended December 31st)
D58: =D35 -> 44561 | E58: =E35 -> 44926 | F58: =F35 -> 45291 | G58: =G35 -> 45657 | H58: =H35 -> 46022 | I58: =I35 -> 46387 | O58: =O35 -> 44561 | P58: =P35 -> 44926 | Q58: =Q35 -> 45291 | R58: =R35 -> 45657 | S58: =S35 -> 46022 | T58: =T35 -> 46387 | Z58: =Z35 -> 44561 | AA58: =AA35 -> 44926 | AB58: =AB35 -> 45291 | AC58: =AC35 -> 45657 | AD58: =AD35 -> 46022 | AE58: =AE35 -> 46387
C60: Cash Flow from Operations | L60: Cash Flow from Operations | W60: Cash Flow from Operations
C61: Net Income | E61: =E51 -> 615.64364 | F61: =F51 -> 737.83784 | G61: =G51 -> 867.22712 | H61: =H51 -> 1004.3165 | I61: =I51 -> 1149.6447 | L61: Net Income | P61: =P51 -> 615.64364 | Q61: =Q51 -> 737.83784 | R61: =R51 -> 867.22712 | S61: =S51 -> 1004.3165 | T61: =T51 -> 1149.6447 | W61: Net Income | AA61: =AA51 -> 615.64364 | AB61: =AB51 -> 737.83784 | AC61: =AC51 -> 867.22712 | AD61: =AD51 -> 1004.3165 | AE61: =AE51 -> 1149.6447
...
