Workbook
Name company: Acquisition!$F$270
Name methods: Acquisition!$F$278:$F$279
Name percentage: Acquisition!$F$8
Name Pro_Forma_FS: CaseSolution!$B$29:$I$123
Name selector: Acquisition!$F$9
Name topic: "CFM Topic: " & Acquisition!$F$271
Name value: Acquisition!$F$7

Sheet Acquisition
A1: {=company} -> WV Cars
A2: {=topic} -> CFM Topic: Subsidiaries
A3: ACQUSITION SCHEDULE | J3: =J$277 -> 45291 | K3: =K$277 -> 45657 | L3: =L$277 -> 46022 | M3: =M$277 -> 46387 | N3: =N$277 -> 46752
A5: Acquisition asssumptions
E7: =CaseData!B$3 -> Value of 100% of JP Motors Equity | F7: =CaseData!E$3 -> 6750 | G7: USD m
E8: =CaseData!B$4 -> Percentage of JP Motors' Equity Acquired by WW | F8: =CaseData!E$4 -> 0.6 | G8: =CaseData!D$4 -> %
E9: Method selector | F9: 2 | G9: <= select
A11: Acquisition schedule
B13: Income Statement
E15: Revenue | J15: {=_xlfn.LET( _xlpm.vw_data,_xlfn.ANCHORARRAY( $J$97), _xlpm.vw_rows,_xlfn.ANCHORARRAY( $E$97), _xlpm.vw, INDEX( _xlpm.vw_data, MATCH( $E15, _xlpm.vw_rows, 0 ), 0 ), _xlpm.jp_data,_xlfn.ANCHORARRAY( $J$183), _xlpm.jp_rows,_xlfn.ANCHORARRAY( $E$183), _xlpm.jp, INDEX( _xlpm.jp_data, MATCH( $E15, _xlpm.jp_rows, 0 ), 0 ), IF( selector = 1, _xlpm.vw, _xlpm.vw + _xlpm.jp ) )} -> 7783.9286 | K15: 8195.8393 | L15: 8629.7084 | M15: 9086.7156 | N15: 9568.1044
E16: Less: COGS | J16: {=_xlfn.LET( _xlpm.vw_data,_xlfn.ANCHORARRAY( $J$97), _xlpm.vw_rows,_xlfn.ANCHORARRAY( $E$97), _xlpm.vw, INDEX( _xlpm.vw_data, MATCH( $E16, _xlpm.vw_rows, 0 ), 0 ), _xlpm.jp_data,_xlfn.ANCHORARRAY( $J$183), _xlpm.jp_rows,_xlfn.ANCHORARRAY( $E$183), _xlpm.jp, INDEX( _xlpm.jp_data, MATCH( $E16, _xlpm.jp_rows, 0 ), 0 ), IF( selector = 1, _xlpm.vw, _xlpm.vw + _xlpm.jp ) )} -> -4547.0893 | K16: -4705.4325 | L16: -4867.8902 | M16: -5034.4546 | N16: -5205.1049
E17: Gross Profit | J17: =SUM(J15:J16) -> 3236.8393 | K17: =SUM(K15:K16) -> 3490.4068 | L17: =SUM(L15:L16) -> 3761.8182 | M17: =SUM(M15:M16) -> 4052.261 | N17: =SUM(N15:N16) -> 4362.9995
E18: Less: SG&A | J18: {=_xlfn.LET( _xlpm.vw_data,_xlfn.ANCHORARRAY( $J$97), _xlpm.vw_rows,_xlfn.ANCHORARRAY( $E$97), _xlpm.vw, INDEX( _xlpm.vw_data, MATCH( $E18, _xlpm.vw_rows, 0 ), 0 ), _xlpm.jp_data,_xlfn.ANCHORARRAY( $J$183), _xlpm.jp_rows,_xlfn.ANCHORARRAY( $E$183), _xlpm.jp, INDEX( _xlpm.jp_data, MATCH( $E18, _xlpm.jp_rows, 0 ), 0 ), IF( selector = 1, _xlpm.vw, _xlpm.vw + _xlpm.jp ) )} -> -366.48214 | K18: -385.71482 | L18: -405.96365 | M18: -427.2827 | N18: -449.72896
E19: EBITDA | J19: =SUM(J17:J18) -> 2870.3571 | K19: =SUM(K17:K18) -> 3104.692 | L19: =SUM(L17:L18) -> 3355.8545 | M19: =SUM(M17:M18) -> 3624.9783 | N19: =SUM(N17:N18) -> 3913.2706
E20: Less: Depreciation | J20: {=_xlfn.LET( _xlpm.vw_data,_xlfn.ANCHORARRAY( $J$97), _xlpm.vw_rows,_xlfn.ANCHORARRAY( $E$97), _xlpm.vw, INDEX( _xlpm.vw_data, MATCH( $E20, _xlpm.vw_rows, 0 ), 0 ), _xlpm.jp_data,_xlfn.ANCHORARRAY( $J$183), _xlpm.jp_rows,_xlfn.ANCHORARRAY( $E$183), _xlpm.jp, INDEX( _xlpm.jp_data, MATCH( $E20, _xlpm.jp_rows, 0 ), 0 ), IF( selector = 1, _xlpm.vw, _xlpm.vw + _xlpm.jp ) )} -> -1156.2321 | K20: -1217.3373 | L20: -1281.6954 | M20: -1349.4808 | N20: -1420.8775
E21: EBIT | J21: =SUM(J19:J20) -> 1714.125 | K21: =SUM(K19:K20) -> 1887.3546 | L21: =SUM(L19:L20) -> 2074.1591 | M21: =SUM(M19:M20) -> 2275.4975 | N21: =SUM(N19:N20) -> 2492.393
E22: Add/(Less): Net Interest Income/(Expense) | J22: {=_xlfn.LET( _xlpm.vw_data,_xlfn.ANCHORARRAY( $J$97), _xlpm.vw_rows,_xlfn.ANCHORARRAY( $E$97), _xlpm.vw, INDEX( _xlpm.vw_data, MATCH( $E22, _xlpm.vw_rows, 0 ), 0 ), _xlpm.jp_data,_xlfn.ANCHORARRAY( $J$183), _xlpm.jp_rows,_xlfn.ANCHORARRAY( $E$183), _xlpm.jp, INDEX( _xlpm.jp_data, MATCH( $E22, _xlpm.jp_rows, 0 ), 0 ), IF( selector = 1, _xlpm.vw, _xlpm.vw + _xlpm.jp ) )} -> -493.38575 | K22: -424.34394 | L22: -354.62275 | M22: -284.18182 | N22: -212.97791
E23: EBT | J23: =SUM(J21:J22) -> 1220.7392 | K23: =SUM(K21:K22) -> 1463.0107 | L23: =SUM(L21:L22) -> 1719.5364 | M23: =SUM(M21:M22) -> 1991.3157 | N23: =SUM(N21:N22) -> 2279.4151
E24: Less: Taxes | J24: {=_xlfn.LET( _xlpm.vw_data,_xlfn.ANCHORARRAY( $J$97), _xlpm.vw_rows,_xlfn.ANCHORARRAY( $E$97), _xlpm.vw, INDEX( _xlpm.vw_data, MATCH( $E24, _xlpm.vw_rows, 0 ), 0 ), _xlpm.jp_data,_xlfn.ANCHORARRAY( $J$183), _xlpm.jp_rows,_xlfn.ANCHORARRAY( $E$183), _xlpm.jp, INDEX( _xlpm.jp_data, MATCH( $E24, _xlpm.jp_rows, 0 ), 0 ), IF( selector = 1, _xlpm.vw, _xlpm.vw + _xlpm.jp ) )} -> -297.27379 | K24: -356.25395 | L24: -418.69569 | M24: -484.841 | N24: -554.94804
E25: Net Earnings before Non controlling Interest | J25: =SUM(J23:J24) -> 923.46546 | K25: =SUM(K23:K24) -> 1106.7568 | L25: =SUM(L23:L24) -> 1300.8407 | M25: =SUM(M23:M24) -> 1506.4747 | N25: =SUM(N23:N24) -> 1724.4671
E26: Less: Non-Controlling Interest | J26: {=_xlfn.LET( _xlpm.jp_net_income, INDEX( $J$198:$N$198, 1, 0 ), IF( selector = 1, _xlfn.SEQUENCE( 1, 5, 0, 0 ), - _xlpm.jp_net_income * ( 1 - percentage ) ) )} -> -121.82973 | K26: -146.28036 | L26: -172.30136 | M26: -200.01397 | N26: -229.54837
E27: Add: Investment Income | J27: {=_xlfn.LET( _xlpm.jp_net_income, INDEX( $J$220:$N$220, 1, 0 ), IF( selector = 1, - _xlpm.jp_net_income * percentage, _xlfn.SEQUENCE( 1, 5, 0, 0 ) ) )} -> 0 | K27: 0 | L27: 0 | M27: 0 | N27: 0
E28: Net Income | J28: =SUM(J25:J27) -> 801.63572 | K28: =SUM(K25:K27) -> 960.47639 | L28: =SUM(L25:L27) -> 1128.5393 | M28: =SUM(M25:M27) -> 1306.4607 | N28: =SUM(N25:N27) -> 1494.9187
B31: Cash Flow Statement
D33: Cash Flow from Operations
E34: Net Income | J34: {=INDEX( J28:N28, 1, 0 )} -> 801.63572 | K34: 960.47639 | L34: 1128.5393 | M34: 1306.4607 | N34: 1494.9187
E35: Add: Depreciation | J35: {=_xlfn.LET( _xlpm.vw_data,_xlfn.ANCHORARRAY( $J$97), _xlpm.vw_rows,_xlfn.ANCHORARRAY( $E$97), _xlpm.vw, INDEX( _xlpm.vw_data, MATCH( $E35, _xlpm.vw_rows, 0 ), 0 ), _xlpm.jp_data,_xlfn.ANCHORARRAY( $J$183), _xlpm.jp_rows,_xlfn.ANCHORARRAY( $E$183), _xlpm.jp, INDEX( _xlpm.jp_data, MATCH( $E35, _xlpm.jp_rows, 0 ), 0 ), IF( selector = 1, _xlpm.vw, _xlpm.vw + _xlpm.jp ) )} -> 1156.2321 | K35: 1217.3373 | L35: 1281.6954 | M35: 1349.4808 | N35: 1420.8775
E36: Add: Non-Controlling Interest | J36: {=-_xlfn.ANCHORARRAY( J26)} -> 121.82973 | K36: 146.28036 | L36: 172.30136 | M36: 200.01397 | N36: 229.54837
E37: Add/(Less): Change in W/C | J37: {=_xlfn.LET( _xlpm.vw_data,_xlfn.ANCHORARRAY( $J$97), _xlpm.vw_rows,_xlfn.ANCHORARRAY( $E$97), _xlpm.vw, INDEX( _xlpm.vw_data, MATCH( $E37, _xlpm.vw_rows, 0 ), 0 ), _xlpm.jp_data,_xlfn.ANCHORARRAY( $J$183), _xlpm.jp_rows,_xlfn.ANCHORARRAY( $E$183), _xlpm.jp, INDEX( _xlpm.jp_data, MATCH( $E37, _xlpm.jp_rows, 0 ), 0 ), IF( selector = 1, _xlpm.vw, _xlpm.vw + _xlpm.jp ) )} -> -50.316429 | K37: -52.751218 | L37: -55.303721 | M37: -57.979615 | N37: -60.784851
E38: Cash Flow from Operations | J38: =SUM(J34:J37) -> 2029.3812 | K38: =SUM(K34:K37) -> 2271.3429 | L38: =SUM(L34:L37) -> 2527.2323 | M38: =SUM(M34:M37) -> 2797.9759 | N38: =SUM(N34:N37) -> 3084.5598
D40: Cash Flow from Investing Activities
E41: Less: Capex | J41: {=_xlfn.LET( _xlpm.vw_data,_xlfn.ANCHORARRAY( $J$97), _xlpm.vw_rows,_xlfn.ANCHORARRAY( $E$97), _xlpm.vw, INDEX( _xlpm.vw_data, MATCH( $E41, _xlpm.vw_rows, 0 ), 0 ), _xlpm.jp_data,_xlfn.ANCHORARRAY( $J$183), _xlpm.jp_rows,_xlfn.ANCHORARRAY( $E$183), _xlpm.jp, INDEX( _xlpm.jp_data, MATCH( $E41, _xlpm.jp_rows, 0 ), 0 ), IF( selector = 1, _xlpm.vw, _xlpm.vw + _xlpm.jp ) )} -> -1271.8554 | K41: -1339.0711 | L41: -1409.8649 | M41: -1484.4289 | N41: -1562.9653
E42: Cash Flow from Investing Activities | J42: =SUM( J41) -> -1271.8554 | K42: =SUM( K41) -> -1339.0711 | L42: =SUM( L41) -> -1409.8649 | M42: =SUM( M41) -> -1484.4289 | N42: =SUM( N41) -> -1562.9653
D44: Cash Flow from Financing Activities
E45: Add/(Less): Issuance/(Repayment) of Debt | J45: {=_xlfn.LET( _xlpm.vw_data,_xlfn.ANCHORARRAY( $J$97), _xlpm.vw_rows,_xlfn.ANCHORARRAY( $E$97), _xlpm.vw, INDEX( _xlpm.vw_data, MATCH( $E45, _xlpm.vw_rows, 0 ), 0 ), _xlpm.jp_data,_xlfn.ANCHORARRAY( $J$183), _xlpm.jp_rows,_xlfn.ANCHORARRAY( $E$183), _xlpm.jp, INDEX( _xlpm.jp_data, MATCH( $E45, _xlpm.jp_rows, 0 ), 0 ), IF( selector = 1, _xlpm.vw, _xlpm.vw + _xlpm.jp ) )} -> -1050 | K45: -1050 | L45: -1050 | M45: -1050 | N45: -1050
E46: Add/(Less): Issuance/(Repayment) of Common Shares | J46: {=_xlfn.LET( _xlpm.vw_data,_xlfn.ANCHORARRAY( $J$97), _xlpm.vw_rows,_xlfn.ANCHORARRAY( $E$97), _xlpm.vw, INDEX( _xlpm.vw_data, MATCH( $E46, _xlpm.vw_rows, 0 ), 0 ), _xlpm.jp_data,_xlfn.ANCHORARRAY( $J$183), _xlpm.jp_rows,_xlfn.ANCHORARRAY( $E$183), _xlpm.jp, INDEX( _xlpm.jp_data, MATCH( $E46, _xlpm.jp_rows, 0 ), 0 ), IF( selector = 1, _xlpm.vw, _xlpm.vw + _xlpm.jp ) )} -> 0 | K46: 0 | L46: 0 | M46: 0 | N46: 0
E47: Less: Dividends Paid to Non-Controlling Interests | J47: {=_xlfn.LET( _xlpm.jp_net_income, INDEX( $J$220:$N$220, 1, 0 ), IF( selector = 1, _xlfn.SEQUENCE( 1, 5, 0, 0 ), _xlpm.jp_net_income * (1 - percentage ) ) )} -> -36.54892 | K47: -43.884109 | L47: -51.690408 | M47: -60.00419 | N47: -68.864512
E48: Less: Dividends | J48: {=_xlfn.LET( _xlpm.vw_data,_xlfn.ANCHORARRAY( $J$97), _xlpm.vw_rows,_xlfn.ANCHORARRAY( $E$97), _xlpm.vw, INDEX( _xlpm.vw_data, MATCH( $E48, _xlpm.vw_rows, 0 ), 0 ), _xlpm.jp_data,_xlfn.ANCHORARRAY( $J$183), _xlpm.jp_rows,_xlfn.ANCHORARRAY( $E$183), _xlpm.jp, INDEX( _xlpm.jp_data, MATCH( $E48, _xlpm.jp_rows, 0 ), 0 ), IF( selector = 1, _xlpm.vw, _xlpm.vw ) )} -> -123.77822 | K48: -148.21117 | L48: -174.01746 | M48: -201.28796 | N48: -230.11923
E49: Cash Flow from Financing Activities | J49: =SUM(J45:J48) -> -1210.3271 | K49: =SUM(K45:K48) -> -1242.0953 | L49: =SUM(L45:L48) -> -1275.7079 | M49: =SUM(M45:M48) -> -1311.2921 | N49: =SUM(N45:N48) -> -1348.9837
E51: Beginning Cash & Equivalents | J51: =I$53 -> 4401.662 | K51: =J$53 -> 3948.8607 | L51: =K$53 -> 3639.0372 | M51: =L$53 -> 3480.6967 | N51: =M$53 -> 3482.9516
...

Sheet CaseData
A1: Acquisition Assumptions
B3: Value of 100% of JP Motors Equity | D3: USD$ millions | E3: 6750
B4: Percentage of JP Motors' Equity Acquired by WW | D4: % | E4: 0.6
A7: WW Financial Statements (Prior to the Acquisition)
B10: Income statement
B11: (in USD$ millions, fiscal years ended December 31st)
C13: 44926 | D13: =EOMONTH( C$13, 12 ) -> 45291 | E13: =EOMONTH( D$13, 12 ) -> 45657 | F13: =EOMONTH( E$13, 12 ) -> 46022 | G13: =EOMONTH( F$13, 12 ) -> 46387 | H13: =EOMONTH( G$13, 12 ) -> 46752
B15: Revenue | C15: 5250 | D15: 5512.5 | E15: 5788.125 | F15: 6077.5312 | G15: 6381.4078 | H15: 6700.4782
B16: Less: COGS | C16: -3150 | D16: -3252.375 | E16: -3357.1125 | F16: -3464.1928 | G16: -3573.5884 | H16: -3685.263
B17: Gross Profit | C17: =SUM(C15:C16) -> 2100 | D17: =SUM(D15:D16) -> 2260.125 | E17: =SUM(E15:E16) -> 2431.0125 | F17: =SUM(F15:F16) -> 2613.3384 | G17: =SUM(G15:G16) -> 2807.8194 | H17: =SUM(H15:H16) -> 3015.2152
B18: Less: SG&A | C18: -262.5 | D18: -275.625 | E18: -289.40625 | F18: -303.87656 | G18: -319.07039 | H18: -335.02391
B19: EBITDA | C19: =SUM(C17:C18) -> 1837.5 | D19: =SUM(D17:D18) -> 1984.5 | E19: =SUM(E17:E18) -> 2141.6063 | F19: =SUM(F17:F18) -> 2309.4619 | G19: =SUM(G17:G18) -> 2488.749 | H19: =SUM(H17:H18) -> 2680.1913
B20: Less: Depreciation | C20: -787.5 | D20: -826.875 | E20: -868.21875 | F20: -911.62969 | G20: -957.21117 | H20: -1005.0717
B21: EBIT | C21: =SUM(C19:C20) -> 1050 | D21: =SUM(D19:D20) -> 1157.625 | E21: =SUM(E19:E20) -> 1273.3875 | F21: =SUM(F19:F20) -> 1397.8322 | G21: =SUM(G19:G20) -> 1531.5379 | H21: =SUM(H19:H20) -> 1675.1196
B22: Add/(Less): Net Interest Income/(Expense) | C22: -379.12932 | D22: -332.43684 | E22: -285.31304 | F22: -237.71581 | G22: -189.61817 | H22: -140.99136
B23: EBT | C23: =SUM(C21:C22) -> 670.87068 | D23: =SUM(D21:D22) -> 825.18816 | E23: =SUM(E21:E22) -> 988.07446 | F23: =SUM(F21:F22) -> 1160.1164 | G23: =SUM(G21:G22) -> 1341.9197 | H23: =SUM(H21:H22) -> 1534.1282
B24: Less: Taxes | C24: -167.71767 | D24: -206.29704 | E24: -247.01861 | F24: -290.02909 | G24: -335.47993 | H24: -383.53205
B25: Net Income | C25: =SUM(C23:C24) -> 503.15301 | D25: =SUM(D23:D24) -> 618.89112 | E25: =SUM(E23:E24) -> 741.05584 | F25: =SUM(F23:F24) -> 870.08728 | G25: =SUM(G23:G24) -> 1006.4398 | H25: =SUM(H23:H24) -> 1150.5961
B29: Cash Flow Statement
B30: (in USD$ millions, fiscal years ended December 31st)
C32: =C13 -> 44926 | D32: =D13 -> 45291 | E32: =E13 -> 45657 | F32: =F13 -> 46022 | G32: =G13 -> 46387 | H32: =H13 -> 46752
B34: Cash Flow from Operations
B35: Net Income | C35: =C25 -> 503.15301 | D35: =D25 -> 618.89112 | E35: =E25 -> 741.05584 | F35: =F25 -> 870.08728 | G35: =G25 -> 1006.4398 | H35: =H25 -> 1150.5961
B36: Add: Depreciation | C36: =-C20 -> 787.5 | D36: =-D20 -> 826.875 | E36: =-E20 -> 868.21875 | F36: =-F20 -> 911.62969 | G36: =-G20 -> 957.21117 | H36: =-H20 -> 1005.0717
B37: Add/(Less): Change in W/C | C37: -25.5 | D37: -33.705 | E37: -35.224875 | F37: -36.812475 | G37: -38.470773 | H37: -40.202869
B38: Cash Flow from Operations | C38: =SUM(C35:C37) -> 1265.153 | D38: =SUM(D35:D37) -> 1412.0611 | E38: =SUM(E35:E37) -> 1574.0497 | F38: =SUM(F35:F37) -> 1744.9045 | G38: =SUM(G35:G37) -> 1925.1802 | H38: =SUM(H35:H37) -> 2115.465
B40: Cash Flow from Investing Activities
B41: Less: Capex | C41: -866.25 | D41: -909.5625 | E41: -955.04063 | F41: -1002.7927 | G41: -1052.9323 | H41: -1105.5789
B42: Cash Flow from Investing Activities | C42: =SUM(C41:C41) -> -866.25 | D42: =SUM(D41:D41) -> -909.5625 | E42: =SUM(E41:E41) -> -955.04063 | F42: =SUM(F41:F41) -> -1002.7927 | G42: =SUM(G41:G41) -> -1052.9323 | H42: =SUM(H41:H41) -> -1105.5789
B44: Cash Flow from Financing Activities
B45: Add/(Less): Issuance/(Repayment) of Debt | C45: -750 | D45: -750 | E45: -750 | F45: -750 | G45: -750 | H45: -750
B46: Add/(Less): Issuance/(Repayment) of Common Shares | C46: 0 | D46: 0 | E46: 0 | F46: 0 | G46: 0 | H46: 0
B47: Less: Dividends | C47: -100.6306 | D47: -123.77822 | E47: -148.21117 | F47: -174.01746 | G47: -201.28796 | H47: -230.11923
B48: Cash Flow from Financing Activities | C48: =SUM(C45:C47) -> -850.6306 | D48: =SUM(D45:D47) -> -873.77822 | E48: =SUM(E45:E47) -> -898.21117 | F48: =SUM(F45:F47) -> -924.01746 | G48: =SUM(G45:G47) -> -951.28796 | H48: =SUM(H45:H47) -> -980.11923
B50: Beginning Cash & Equivalents | C50: 7275 | D50: =C52 -> 6823.2724 | E50: =D52 -> 6451.9928 | F50: =E52 -> 6172.7907 | G50: =F52 -> 5990.8851 | H50: =G52 -> 5911.845
B51: Change in Cash & Equivalents | C51: =C38+C42+C48 -> -451.72759 | D51: =D38+D42+D48 -> -371.2796 | E51: =E38+E42+E48 -> -279.20207 | F51: =F38+F42+F48 -> -181.90562 | G51: =G38+G42+G48 -> -79.04007 | H51: =H38+H42+H48 -> 29.766874
B52: Ending Cash & Equivalents | C52: =SUM(C50:C51) -> 6823.2724 | D52: =SUM(D50:D51) -> 6451.9928 | E52: =SUM(E50:E51) -> 6172.7907 | F52: =SUM(F50:F51) -> 5990.8851 | G52: =SUM(G50:G51) -> 5911.845 | H52: =SUM(H50:H51) -> 5941.6119
B56: Balance Sheet
B57: (in USD$ millions, fiscal years ended December 31st)
C59: =C32 -> 44926 | D59: =D32 -> 45291 | E59: =E32 -> 45657 | F59: =F32 -> 46022 | G59: =G32 -> 46387 | H59: =H32 -> 46752
...

Sheet CaseSolution
B2: Pro Forma Financial Statements
C4: Pro Forma Financial Statements | D4: Click Here
B7: Summary Table of Answers
E9: % of JP Motors' Equity Acquired by WW
E10: 0.15 | F10: 0.6 | G10: 1
C11: 2026 Retained Earnings | D11: =$H$117 -> 15317.24 | E11: 14428.649 | F11: 15317.24 | G11: 15957.665
C12: 2024 Investment in JP Motors | D12: =$F$95 -> 0 | E12: 1012.5 | F12: 0 | G12: 0
C13: 2025 Non-Controlling Interests | D13: =$G$118 -> 3008.288 | E13: 0 | F13: 3008.288 | G13: 0
C14: 2027 EBITDA | D14: =$I$41 -> 3913.2706 | E14: 2680.1913 | F14: 3913.2706 | G14: 3913.2706
B18: ="LIVE: CURRENTLY RUNNING: "&UPPER(I27) -> LIVE: CURRENTLY RUNNING: CONSOLIDATION METHOD | K18: COST METHODOLOGY | V18: CONSOLIDATION METHODOLOGY
C20: If WW acquires <20% JP Motors' equity, the Cost Method is applied. | F20: 0.2 | H20: Cost Method | L20: =C20 -> If WW acquires <20% JP Motors' equity, the Cost Method is applied. | W20: =C21 -> If WW acquires >50% of JP Motors' equity, the Consolidation Method is applied.
C21: If WW acquires >50% of JP Motors' equity, the Consolidation Method is applied. | F21: 0.5 | H21: Consolidation Method
B23: Acquisition Assumptions | K23: Acquisition Assumptions | V23: Acquisition Assumptions
C25: Value of 100% of JP Motors' Equity | D25: USD$ millions | E25: =CaseData!E3 -> 6750 | G25: BS Check: | I25: =IF(AND(MAX(D122:I122)=0, MIN(D122:I122)=0), "Balanced", "Error") -> Balanced | L25: =$C$25 -> Value of 100% of JP Motors' Equity | M25: =$D$25 -> USD$ millions | N25: =$E25 -> 6750 | Q25: BS Check: | S25: =IF(AND(MAX(O122:T122)=0, MIN(O122:T122)=0), "Balanced", "Error") -> Balanced | W25: =$C$25 -> Value of 100% of JP Motors' Equity | X25: =$D$25 -> USD$ millions | Y25: =$E25 -> 6750 | AB25: BS Check: | AD25: =IF(AND(MAX(Z122:AE122)=0, MIN(Z122:AE122)=0), "Balanced", "Error") -> Balanced
C26: Percentage of JP Motors' Equity Acquired by WW | D26: % | E26: =CaseData!E4 -> 0.6 | L26: =$C$26 -> Percentage of JP Motors' Equity Acquired by WW | M26: =$D$26 -> % | N26: =$E26 -> 0.6 | W26: =$C$26 -> Percentage of JP Motors' Equity Acquired by WW | X26: =$D$26 -> % | Y26: =$E26 -> 0.6
G27: Running: | I27: =IF(E26<F20,H20,H21) -> Consolidation Method | Q27: Running: | S27: =H20 -> Cost Method | AB27: Running: | AD27: =H21 -> Consolidation Method
B29: ="WW Financial Statements (Pro-Forma under "&I27&")" -> WW Financial Statements (Pro-Forma under Consolidation Method) | K29: ="WW Financial Statements (Pro-Forma under "&S27&")" -> WW Financial Statements (Pro-Forma under Cost Method) | V29: ="WW Financial Statements (Pro-Forma under "&AD27&")" -> WW Financial Statements (Pro-Forma under Consolidation Method)
C32: ="WW Income Statement (Pro-Forma under "&I27&")" -> WW Income Statement (Pro-Forma under Consolidation Method) | L32: ="WW Income Statement (Pro-Forma under "&S27&")" -> WW Income Statement (Pro-Forma under Cost Method) | W32: ="WW Income Statement (Pro-Forma under "&AD27&")" -> WW Income Statement (Pro-Forma under Consolidation Method)
C33: (in USD$ millions, fiscal years ended December 31st) | L33: (in USD$ millions, fiscal years ended December 31st) | W33: (in USD$ millions, fiscal years ended December 31st)
D35: =O35 -> 44926 | E35: =P35 -> 45291 | F35: =Q35 -> 45657 | G35: =R35 -> 46022 | H35: =S35 -> 46387 | I35: =T35 -> 46752 | O35: =O132 -> 44926 | P35: =P132 -> 45291 | Q35: =Q132 -> 45657 | R35: =R132 -> 46022 | S35: =S132 -> 46387 | T35: =T132 -> 46752 | Z35: =Z132 -> 44926 | AA35: =AA132 -> 45291 | AB35: =AB132 -> 45657 | AC35: =AC132 -> 46022 | AD35: =AD132 -> 46387 | AE35: =AE132 -> 46752
C37: Revenue | E37: =IF($I$27=$H$20,P37,AA37) -> 7783.9286 | F37: =IF($I$27=$H$20,Q37,AB37) -> 8195.8393 | G37: =IF($I$27=$H$20,R37,AC37) -> 8629.7084 | H37: =IF($I$27=$H$20,S37,AD37) -> 9086.7156 | I37: =IF($I$27=$H$20,T37,AE37) -> 9568.1044 | L37: Revenue | P37: =P134 -> 5512.5 | Q37: =Q134 -> 5788.125 | R37: =R134 -> 6077.5312 | S37: =S134 -> 6381.4078 | T37: =T134 -> 6700.4782 | W37: Revenue | AA37: =SUM(AA134,AA223) -> 7783.9286 | AB37: =SUM(AB134,AB223) -> 8195.8393 | AC37: =SUM(AC134,AC223) -> 8629.7084 | AD37: =SUM(AD134,AD223) -> 9086.7156 | AE37: =SUM(AE134,AE223) -> 9568.1044
C38: Less: COGS | E38: =IF($I$27=$H$20,P38,AA38) -> -4547.0893 | F38: =IF($I$27=$H$20,Q38,AB38) -> -4705.4325 | G38: =IF($I$27=$H$20,R38,AC38) -> -4867.8902 | H38: =IF($I$27=$H$20,S38,AD38) -> -5034.4546 | I38: =IF($I$27=$H$20,T38,AE38) -> -5205.1049 | L38: Less: COGS | P38: =P135 -> -3252.375 | Q38: =Q135 -> -3357.1125 | R38: =R135 -> -3464.1928 | S38: =S135 -> -3573.5884 | T38: =T135 -> -3685.263 | W38: Less: COGS | AA38: =SUM(AA135,AA224) -> -4547.0893 | AB38: =SUM(AB135,AB224) -> -4705.4325 | AC38: =SUM(AC135,AC224) -> -4867.8902 | AD38: =SUM(AD135,AD224) -> -5034.4546 | AE38: =SUM(AE135,AE224) -> -5205.1049
C39: Gross Profit | E39: =SUM(E37:E38) -> 3236.8393 | F39: =SUM(F37:F38) -> 3490.4068 | G39: =SUM(G37:G38) -> 3761.8182 | H39: =SUM(H37:H38) -> 4052.261 | I39: =SUM(I37:I38) -> 4362.9995 | L39: Gross Profit | P39: =SUM(P37:P38) -> 2260.125 | Q39: =SUM(Q37:Q38) -> 2431.0125 | R39: =SUM(R37:R38) -> 2613.3384 | S39: =SUM(S37:S38) -> 2807.8194 | T39: =SUM(T37:T38) -> 3015.2152 | W39: Gross Profit | AA39: =SUM(AA37:AA38) -> 3236.8393 | AB39: =SUM(AB37:AB38) -> 3490.4068 | AC39: =SUM(AC37:AC38) -> 3761.8182 | AD39: =SUM(AD37:AD38) -> 4052.261 | AE39: =SUM(AE37:AE38) -> 4362.9995
C40: Less: SG&A | E40: =IF($I$27=$H$20,P40,AA40) -> -366.48214 | F40: =IF($I$27=$H$20,Q40,AB40) -> -385.71482 | G40: =IF($I$27=$H$20,R40,AC40) -> -405.96365 | H40: =IF($I$27=$H$20,S40,AD40) -> -427.2827 | I40: =IF($I$27=$H$20,T40,AE40) -> -449.72896 | L40: Less: SG&A | P40: =P137 -> -275.625 | Q40: =Q137 -> -289.40625 | R40: =R137 -> -303.87656 | S40: =S137 -> -319.07039 | T40: =T137 -> -335.02391 | W40: Less: SG&A | AA40: =SUM(AA137,AA226) -> -366.48214 | AB40: =SUM(AB137,AB226) -> -385.71482 | AC40: =SUM(AC137,AC226) -> -405.96365 | AD40: =SUM(AD137,AD226) -> -427.2827 | AE40: =SUM(AE137,AE226) -> -449.72896
C41: EBITDA | E41: =SUM(E39:E40) -> 2870.3571 | F41: =SUM(F39:F40) -> 3104.692 | G41: =SUM(G39:G40) -> 3355.8545 | H41: =SUM(H39:H40) -> 3624.9783 | I41: =SUM(I39:I40) -> 3913.2706 | L41: EBITDA | P41: =SUM(P39:P40) -> 1984.5 | Q41: =SUM(Q39:Q40) -> 2141.6063 | R41: =SUM(R39:R40) -> 2309.4619 | S41: =SUM(S39:S40) -> 2488.749 | T41: =SUM(T39:T40) -> 2680.1913 | W41: EBITDA | AA41: =SUM(AA39:AA40) -> 2870.3571 | AB41: =SUM(AB39:AB40) -> 3104.692 | AC41: =SUM(AC39:AC40) -> 3355.8545 | AD41: =SUM(AD39:AD40) -> 3624.9783 | AE41: =SUM(AE39:AE40) -> 3913.2706
C42: Less: Depreciation | E42: =IF($I$27=$H$20,P42,AA42) -> -1156.2321 | F42: =IF($I$27=$H$20,Q42,AB42) -> -1217.3373 | G42: =IF($I$27=$H$20,R42,AC42) -> -1281.6954 | H42: =IF($I$27=$H$20,S42,AD42) -> -1349.4808 | I42: =IF($I$27=$H$20,T42,AE42) -> -1420.8775 | L42: Less: Depreciation | P42: =P139 -> -826.875 | Q42: =Q139 -> -868.21875 | R42: =R139 -> -911.62969 | S42: =S139 -> -957.21117 | T42: =T139 -> -1005.0717 | W42: Less: Depreciation | AA42: =SUM(AA139,AA228) -> -1156.2321 | AB42: =SUM(AB139,AB228) -> -1217.3373 | AC42: =SUM(AC139,AC228) -> -1281.6954 | AD42: =SUM(AD139,AD228) -> -1349.4808 | AE42: =SUM(AE139,AE228) -> -1420.8775
C43: EBIT | E43: =SUM(E41:E42) -> 1714.125 | F43: =SUM(F41:F42) -> 1887.3546 | G43: =SUM(G41:G42) -> 2074.1591 | H43: =SUM(H41:H42) -> 2275.4975 | I43: =SUM(I41:I42) -> 2492.393 | L43: EBIT | P43: =SUM(P41:P42) -> 1157.625 | Q43: =SUM(Q41:Q42) -> 1273.3875 | R43: =SUM(R41:R42) -> 1397.8322 | S43: =SUM(S41:S42) -> 1531.5379 | T43: =SUM(T41:T42) -> 1675.1196 | W43: EBIT | AA43: =SUM(AA41:AA42) -> 1714.125 | AB43: =SUM(AB41:AB42) -> 1887.3546 | AC43: =SUM(AC41:AC42) -> 2074.1591 | AD43: =SUM(AD41:AD42) -> 2275.4975 | AE43: =SUM(AE41:AE42) -> 2492.393
C44: Add/(Less): Net Interest Income/(Expense) | E44: =IF($I$27=$H$20,P44,AA44) -> -493.38575 | F44: =IF($I$27=$H$20,Q44,AB44) -> -424.34394 | G44: =IF($I$27=$H$20,R44,AC44) -> -354.62275 | H44: =IF($I$27=$H$20,S44,AD44) -> -284.18182 | I44: =IF($I$27=$H$20,T44,AE44) -> -212.97791 | L44: Add/(Less): Net Interest Income/(Expense) | P44: =P141 -> -332.43684 | Q44: =Q141 -> -285.31304 | R44: =R141 -> -237.71581 | S44: =S141 -> -189.61817 | T44: =T141 -> -140.99136 | W44: Add/(Less): Net Interest Income/(Expense) | AA44: =SUM(AA141,AA230) -> -493.38575 | AB44: =SUM(AB141,AB230) -> -424.34394 | AC44: =SUM(AC141,AC230) -> -354.62275 | AD44: =SUM(AD141,AD230) -> -284.18182 | AE44: =SUM(AE141,AE230) -> -212.97791
C45: EBT | E45: =SUM(E43:E44) -> 1220.7392 | F45: =SUM(F43:F44) -> 1463.0107 | G45: =SUM(G43:G44) -> 1719.5364 | H45: =SUM(H43:H44) -> 1991.3157 | I45: =SUM(I43:I44) -> 2279.4151 | L45: EBT | P45: =SUM(P43:P44) -> 825.18816 | Q45: =SUM(Q43:Q44) -> 988.07446 | R45: =SUM(R43:R44) -> 1160.1164 | S45: =SUM(S43:S44) -> 1341.9197 | T45: =SUM(T43:T44) -> 1534.1282 | W45: EBT | AA45: =SUM(AA43:AA44) -> 1220.7392 | AB45: =SUM(AB43:AB44) -> 1463.0107 | AC45: =SUM(AC43:AC44) -> 1719.5364 | AD45: =SUM(AD43:AD44) -> 1991.3157 | AE45: =SUM(AE43:AE44) -> 2279.4151
C46: Less: Taxes | E46: =IF($I$27=$H$20,P46,AA46) -> -297.27379 | F46: =IF($I$27=$H$20,Q46,AB46) -> -356.25395 | G46: =IF($I$27=$H$20,R46,AC46) -> -418.69569 | H46: =IF($I$27=$H$20,S46,AD46) -> -484.841 | I46: =IF($I$27=$H$20,T46,AE46) -> -554.94804 | L46: Less: Taxes | P46: =P143 -> -206.29704 | Q46: =Q143 -> -247.01861 | R46: =R143 -> -290.02909 | S46: =S143 -> -335.47993 | T46: =T143 -> -383.53205 | W46: Less: Taxes | AA46: =SUM(AA143,AA232) -> -297.27379 | AB46: =SUM(AB143,AB232) -> -356.25395 | AC46: =SUM(AC143,AC232) -> -418.69569 | AD46: =SUM(AD143,AD232) -> -484.841 | AE46: =SUM(AE143,AE232) -> -554.94804
C47: Net Earnings before Noncontrolling Interest | E47: =SUM(E45:E46) -> 923.46546 | F47: =SUM(F45:F46) -> 1106.7568 | G47: =SUM(G45:G46) -> 1300.8407 | H47: =SUM(H45:H46) -> 1506.4747 | I47: =SUM(I45:I46) -> 1724.4671 | L47: Net Earnings before Noncontrolling Interest | P47: =SUM(P45:P46) -> 618.89112 | Q47: =SUM(Q45:Q46) -> 741.05584 | R47: =SUM(R45:R46) -> 870.08728 | S47: =SUM(S45:S46) -> 1006.4398 | T47: =SUM(T45:T46) -> 1150.5961 | W47: Net Earnings before Noncontrolling Interest | AA47: =SUM(AA45:AA46) -> 923.46546 | AB47: =SUM(AB45:AB46) -> 1106.7568 | AC47: =SUM(AC45:AC46) -> 1300.8407 | AD47: =SUM(AD45:AD46) -> 1506.4747 | AE47: =SUM(AE45:AE46) -> 1724.4671
C48: Less: Non-Controlling Interest | E48: =IF($I$27=$H$20,P48,AA48) -> -121.82973 | F48: =IF($I$27=$H$20,Q48,AB48) -> -146.28036 | G48: =IF($I$27=$H$20,R48,AC48) -> -172.30136 | H48: =IF($I$27=$H$20,S48,AD48) -> -200.01397 | I48: =IF($I$27=$H$20,T48,AE48) -> -229.54837 | L48: Less: Non-Controlling Interest | P48: 0 | Q48: 0 | R48: 0 | S48: 0 | T48: 0 | W48: Less: Non-Controlling Interest | AA48: =-AA233*(1-$Y$26) -> -121.82973 | AB48: =-AB233*(1-$Y$26) -> -146.28036 | AC48: =-AC233*(1-$Y$26) -> -172.30136 | AD48: =-AD233*(1-$Y$26) -> -200.01397 | AE48: =-AE233*(1-$Y$26) -> -229.54837
C49: Add: Investment Income | E49: =IF($I$27=$H$20,P49,AA49) -> 0 | F49: =IF($I$27=$H$20,Q49,AB49) -> 0 | G49: =IF($I$27=$H$20,R49,AC49) -> 0 | H49: =IF($I$27=$H$20,S49,AD49) -> 0 | I49: =IF($I$27=$H$20,T49,AE49) -> 0 | L49: Add: Investment Income | P49: =-P255*$N$26 -> 54.82338 | Q49: =-Q255*$N$26 -> 65.826164 | R49: =-R255*$N$26 -> 77.535612 | S49: =-S255*$N$26 -> 90.006284 | T49: =-T255*$N$26 -> 103.29677 | W49: Add: Investment Income | AA49: 0 | AB49: 0 | AC49: 0 | AD49: 0 | AE49: 0
C50: Net Income | E50: =SUM(E47:E49) -> 801.63572 | F50: =SUM(F47:F49) -> 960.47639 | G50: =SUM(G47:G49) -> 1128.5393 | H50: =SUM(H47:H49) -> 1306.4607 | I50: =SUM(I47:I49) -> 1494.9187 | L50: Net Income | P50: =SUM(P47:P49) -> 673.7145 | Q50: =SUM(Q47:Q49) -> 806.88201 | R50: =SUM(R47:R49) -> 947.6229 | S50: =SUM(S47:S49) -> 1096.4461 | T50: =SUM(T47:T49) -> 1253.8929 | W50: Net Income | AA50: =SUM(AA47:AA49) -> 801.63572 | AB50: =SUM(AB47:AB49) -> 960.47639 | AC50: =SUM(AC47:AC49) -> 1128.5393 | AD50: =SUM(AD47:AD49) -> 1306.4607 | AE50: =SUM(AE47:AE49) -> 1494.9187
C54: ="WW Cash Flow Statement (Pro-Forma under "&I27&")" -> WW Cash Flow Statement (Pro-Forma under Consolidation Method) | L54: ="WW Cash Flow Statement (Pro-Forma under "&S27&")" -> WW Cash Flow Statement (Pro-Forma under Cost Method) | W54: ="WW Cash Flow Statement (Pro-Forma under "&AD27&")" -> WW Cash Flow Statement (Pro-Forma under Consolidation Method)
C55: (in USD$ millions, fiscal years ended December 31st) | L55: (in USD$ millions, fiscal years ended December 31st) | W55: (in USD$ millions, fiscal years ended December 31st)
D57: =D35 -> 44926 | E57: =E35 -> 45291 | F57: =F35 -> 45657 | G57: =G35 -> 46022 | H57: =H35 -> 46387 | I57: =I35 -> 46752 | O57: =O35 -> 44926 | P57: =P35 -> 45291 | Q57: =Q35 -> 45657 | R57: =R35 -> 46022 | S57: =S35 -> 46387 | T57: =T35 -> 46752 | Z57: =Z35 -> 44926 | AA57: =AA35 -> 45291 | AB57: =AB35 -> 45657 | AC57: =AC35 -> 46022 | AD57: =AD35 -> 46387 | AE57: =AE35 -> 46752
C59: Cash Flow from Operations | L59: Cash Flow from Operations | W59: Cash Flow from Operations
C60: Net Income | E60: =IF($I$27=$H$20,P60,AA60) -> 801.63572 | F60: =IF($I$27=$H$20,Q60,AB60) -> 960.47639 | G60: =IF($I$27=$H$20,R60,AC60) -> 1128.5393 | H60: =IF($I$27=$H$20,S60,AD60) -> 1306.4607 | I60: =IF($I$27=$H$20,T60,AE60) -> 1494.9187 | L60: Net Income | P60: =P50 -> 673.7145 | Q60: =Q50 -> 806.88201 | R60: =R50 -> 947.6229 | S60: =S50 -> 1096.4461 | T60: =T50 -> 1253.8929 | W60: Net Income | AA60: =AA50 -> 801.63572 | AB60: =AB50 -> 960.47639 | AC60: =AC50 -> 1128.5393 | AD60: =AD50 -> 1306.4607 | AE60: =AE50 -> 1494.9187
C61: Add: Depreciation | E61: =IF($I$27=$H$20,P61,AA61) -> 1156.2321 | F61: =IF($I$27=$H$20,Q61,AB61) -> 1217.3373 | G61: =IF($I$27=$H$20,R61,AC61) -> 1281.6954 | H61: =IF($I$27=$H$20,S61,AD61) -> 1349.4808 | I61: =IF($I$27=$H$20,T61,AE61) -> 1420.8775 | L61: Add: Depreciation | P61: =-P42 -> 826.875 | Q61: =-Q42 -> 868.21875 | R61: =-R42 -> 911.62969 | S61: =-S42 -> 957.21117 | T61: =-T42 -> 1005.0717 | W61: Add: Depreciation | AA61: =-AA42 -> 1156.2321 | AB61: =-AB42 -> 1217.3373 | AC61: =-AC42 -> 1281.6954 | AD61: =-AD42 -> 1349.4808 | AE61: =-AE42 -> 1420.8775
...
