Workbook
Name Acquirer: CaseData!$E$8
Name debt: Merger!$F$11
Name premium: Merger!$F$14
Name Target: Merger!$F$17
Name topic: "CFM Topic: " & CaseData!$B$34

Sheet Cover
B3: CFM LEARNING MATERIALS
B8: FINANCIAL MODELING INSTITUTE
B9: LEVEL 2: CHARTERED FINANCIAL MODELER (CFM)
B13: Case Name: | C13: BoTrainers
B14: Topic 8: | C14: M&A and Subsidiaries

Sheet CaseData
B2: Sample CFM M&A Question
A3: x | B3: Case Data
B4: (in US$ millions, except per share amounts)
A6: x | B6: ACQUIRER
B8: Company Name: | E8: BoTrainers
B9: Current Share Price: | E9: 55.4
B10: Fully Diluted Shares Outstanding (mm): | E10: 119.4
B12: Deal Assumptions | G12: Income Statement | M12: Balance Sheet
I13: Last Fiscal | J13: Forecast | O13: =$I$13 -> Last Fiscal
B14: Purchase Price: | I14: Year | J14: 1 | K14: =J14+1 -> 2 | O14: =$I$14 -> Year
B15: Equity Premium | E15: 0.3 | G15: Revenues | I15: 3451.8 | J15: 3586.4 | K15: 3708.3 | M15: Cash & Equivalents | O15: 265.9
B16: % of Gross Assets Written Up | E16: 0.75 | G16: Cost of Goods Sold (ex. D&A) | I16: 1933 | J16: 2001.2 | K16: 2047 | M16: Accounts Receivable | O16: 302.6
B17: Life of Written Up Assets | E17: 12 | G17: Gross Profit | I17: =I15-I16 -> 1518.8 | J17: =J15-J16 -> 1585.2 | K17: =K15-K16 -> 1661.3 | M17: Inventories | O17: 688.5
M18: Other Current Assets | O18: 86.3
B19: Financing: | G19: SG&A Expenses (ex. D&A) | I19: 414.2 | J19: 408.8 | K19: 463.5 | M19: Total Current Assets | O19: =SUM(O15:O18) -> 1343.3
B20: % of Required Funding with New Debt | E20: 0.4 | G20: Other Expenses | I20: 172.6 | J20: 168.6 | K20: 181.7
B21: Cost of New Debt | E21: 0.06 | G21: EBITDA | I21: =I17-SUM(I19:I20) -> 932 | J21: =J17-SUM(J19:J20) -> 1007.8 | K21: =K17-SUM(K19:K20) -> 1016.1 | M21: Fixed Assets (Net) | O21: 1003.8
B22: Interest Income on Cash | E22: 0.01 | M22: Goodwill | O22: 134.5
B23: Minimum Cash on Hand at Closing | E23: 70 | G23: Depreciation & Amortization | I23: 65.2 | J23: 71.7 | K23: 77.9 | M23: Other Long-term Assets | O23: 121.7
G24: Operating Income | I24: =I21-I23 -> 866.8 | J24: =J21-J23 -> 936.1 | K24: =K21-K23 -> 938.2 | M24: Total Assets | O24: =SUM(O19:O23) -> 2603.3
B25: Fees:
B26: Debt Financing Fees (% of Amount Issued) | E26: 0.025 | G26: Interest Expense (Net) | I26: 41.9 | J26: 23.9 | K26: 11.2 | M26: Short-term Debt | O26: 55.3
B27: Other Fees (% of Target Enterprise Value) | E27: 0.005 | G27: Earnings Before Tax | I27: =I24-I26 -> 824.9 | J27: =J24-J26 -> 912.2 | K27: =K24-K26 -> 927 | M27: Accounts Payable | O27: 323
M28: Other Current Liabilities | O28: 538
B29: Other: | G29: Income Tax Expense | I29: 226.8 | J29: 232.6 | K29: 231.8 | M29: Total Current Liabilities | O29: =SUM(O26:O28) -> 916.3
B30: Combined Effective Tax Rate | E30: 0.275 | G30: Net Earnings | I30: =I27-I29 -> 598.1 | J30: =J27-J29 -> 679.6 | K30: =K27-K29 -> 695.2
M31: Long-term Debt | O31: 698.3
G32: Weighted Avg Shares OS | I32: 120.3 | J32: 119.6 | K32: 119.4 | M32: Other Liabilities | O32: 331.8
M33: Total Liabilities | O33: =SUM(O29:O32) -> 1946.4
B34: M&A | G34: Earnings Per Share | I34: =I30/I32 -> 4.9717373 | J34: =J30/J32 -> 5.6822742 | K34: =K30/K32 -> 5.8224456
M35: Shareholders' Equity | O35: 656.9
G36: Revenue Growth | I36: N/A | J36: =J15/I15-1 -> 0.038994148 | K36: =K15/J15-1 -> 0.033989516 | M36: Total Liabilities and Equity | O36: =O33+O35 -> 2603.3
G37: Gross Margin | I37: =I17/I15 -> 0.44000232 | J37: =J17/J15 -> 0.44200312 | K37: =K17/K15 -> 0.44799504
G38: SG&A % of Revenues | I38: =I19/I15 -> 0.11999536 | J38: =J19/J15 -> 0.11398617 | K38: =K19/K15 -> 0.12498989 | M38: CHECK | O38: =ROUND(O24-O36,2) -> 0
G39: Other Expenses % of Revenues | I39: =I20/I15 -> 0.050002897 | J39: =J20/J15 -> 0.04701093 | K39: =K20/K15 -> 0.048998193
G40: EBITDA Margin | I40: =I21/I15 -> 0.27000406 | J40: =J21/J15 -> 0.28100602 | K40: =K21/K15 -> 0.27400696
G41: D&A % of Revenues | I41: =I23/I15 -> 0.018888696 | J41: =J23/J15 -> 0.019992193 | K41: =K23/K15 -> 0.02100693
G42: Operating Income Margin | I42: =I24/I15 -> 0.25111536 | J42: =J24/J15 -> 0.26101383 | K42: =K24/K15 -> 0.25300003
G43: Tax Rate | I43: =I29/I27 -> 0.27494242 | J43: =J29/J27 -> 0.25498794 | K43: =K29/K27 -> 0.25005394
G44: Net Margin | I44: =I30/I15 -> 0.17327192 | J44: =J30/J15 -> 0.18949364 | K44: =K30/K15 -> 0.18747135
...

Sheet Merger
A1: =Acquirer -> BoTrainers
A2: {=topic} -> CFM Topic: M&A
A3: MERGER MODEL | F3: Constant | G3: Unit
A5: Assumptions
C7: Acquirer
E8: Acquirer | F8: =Acquirer -> BoTrainers | G8: label
E9: =CaseData!B$9 -> Current Share Price: | F9: =CaseData!E$9 -> 55.4 | G9: USD
E10: =CaseData!B$16 -> % of Gross Assets Written Up | F10: =CaseData!E$16 -> 0.75 | G10: %
E11: =CaseData!B$20 -> % of Required Funding with New Debt | F11: =CaseData!E$20 -> 0.4 | G11: %
E12: =CaseData!B$23 -> Minimum Cash on Hand at Closing | F12: =CaseData!E$23 -> 70 | G12: USD m
E13: =CaseData!B$17 -> Life of Written Up Assets | F13: =CaseData!E$17 -> 12 | G13: years
E14: =CaseData!B$15 -> Equity Premium | F14: =CaseData!E$15 -> 0.3 | G14: %
C16: Target
E17: Target | F17: Highpeak | G17: label
E18: =CaseData!B$21 -> Cost of New Debt | F18: =CaseData!E$21 -> 0.06 | G18: %
E19: =CaseData!B$22 -> Interest Income on Cash | F19: =CaseData!E$22 -> 0.01 | G19: %
E20: =CaseData!B$26 -> Debt Financing Fees (% of Amount Issued) | F20: =CaseData!E$26 -> 0.025 | G20: %
E21: =CaseData!B$27 -> Other Fees (% of Target Enterprise Value) | F21: =CaseData!E$27 -> 0.005 | G21: %
E22: =CaseData!B$30 -> Combined Effective Tax Rate | F22: =CaseData!E$30 -> 0.275 | G22: %
A25: Purchase Price Allocation
C27: Goodwill
D29: Purchase price of Equity
E30: Pre-acquisition Equity Value | F30: =INDEX( TargetData!$E$9:$E$55, MATCH( RIGHT( Merger!$E30, 12 ), TargetData!$B$9:$B$55, 0 ), 1 ) -> 2435.744 | G30: USD m
E31: =E$14 -> Equity Premium | F31: =F$14 -> 0.3 | G31: %
E32: Purchase Price of Equity | F32: =F30 * ( 1 + F31 ) -> 3166.4672 | G32: USD m
D34: Enterprise Value
D35: plus | E35: Short-term Debt | F35: =IF( INDEX( TargetData!$E$9:$E$55, MATCH( $E35, TargetData!$B$9:$B$55, 0 ), 1 ) = "", 0, INDEX( TargetData!$E$9:$E$55, MATCH( $E35, TargetData!$B$9:$B$55, 0 ), 1 ) ) -> 0 | G35: USD m
D36: plus | E36: Long-term Debt | F36: =IF( INDEX( TargetData!$E$9:$E$55, MATCH( $E36, TargetData!$B$9:$B$55, 0 ), 1 ) = "", 0, INDEX( TargetData!$E$9:$E$55, MATCH( $E36, TargetData!$B$9:$B$55, 0 ), 1 ) ) -> 546 | G36: USD m
D37: less | E37: Cash & Equivalents | F37: =IF( INDEX( TargetData!$E$9:$E$55, MATCH( $E37, TargetData!$B$9:$B$55, 0 ), 1 ) = "", 0, - INDEX( TargetData!$E$9:$E$55, MATCH( $E37, TargetData!$B$9:$B$55, 0 ), 1 ) ) -> -55.2 | G37: USD m
E38: Enterprise Value | F38: =SUM(F32:F37) -> 3657.2672 | G38: USD m
D40: Fair Market Value of Net Assets
E41: Total assets | F41: =IF( INDEX( TargetData!$E$9:$E$55, MATCH( $E41, TargetData!$B$9:$B$55, 0 ), 1 ) = "", 0, INDEX( TargetData!$E$9:$E$55, MATCH( $E41, TargetData!$B$9:$B$55, 0 ), 1 ) ) -> 1388 | G41: USD m
D42: plus | E42: Assets Write-Ups | F42: =F41 * F10 -> 1041 | G42: USD m
D43: less | E43: Goodwill | F43: =IF( INDEX( TargetData!$E$9:$E$55, MATCH( $E43, TargetData!$B$9:$B$55, 0 ), 1 ) = "", 0, - INDEX( TargetData!$E$9:$E$55, MATCH( $E43, TargetData!$B$9:$B$55, 0 ), 1 ) ) -> -21.4 | G43: USD m
D44: less | E44: Total liabilities | F44: =IF( INDEX( TargetData!$E$9:$E$55, MATCH( $E44, TargetData!$B$9:$B$55, 0 ), 1 ) = "", 0, - INDEX( TargetData!$E$9:$E$55, MATCH( $E44, TargetData!$B$9:$B$55, 0 ), 1 ) ) -> -937.6 | G44: USD m
D45: less | E45: Deferred tax liabilities | F45: =- $F$42 * $F$22 -> -286.275 | G45: USD m
E46: Fair Market Value of Net Assets | F46: =SUM(F41:F45) -> 1183.725 | G46: USD m
D48: Goodwill
E49: =E$32 -> Purchase Price of Equity | F49: =F$32 -> 3166.4672 | G49: =G$32 -> USD m
D50: less | E50: =E$46 -> Fair Market Value of Net Assets | F50: =F$46 -> 1183.725 | G50: =G$46 -> USD m
...

Sheet TargetData
B2: Sample CFM M&A Question
B3: Target Data Selector
B4: (in US$ millions, except per share amounts)
E6: LIVE TARGET | G6: =CaseData!B51 -> TARGET 1 | H6: =CaseData!B96 -> TARGET 2
B7: COMPANY NAME | E7: =Target -> Highpeak | G7: =CaseData!E$53 -> Highpeak | H7: =CaseData!$E$98 -> NoLace
B9: SHARE CAPITAL
B10: Current Share Price | E10: {=IF( _xlfn.XLOOKUP( $E$7, $G$7:$H$7,G10:H55) > 0, _xlfn.XLOOKUP( $E$7, $G$7:$H$7,G10:H55), "" )} -> 59.12 | G10: =CaseData!E$54 -> 59.12 | H10: NA
B11: Fully Diluted Shares Outstanding (mm) | E11: 41.2 | G11: =CaseData!E$55 -> 41.2 | H11: NA
B12: Equity Value | E12: 2435.744 | G12: =G10 * G11 -> 2435.744 | H12: =CaseData!$E$99 -> 2900
B14: INCOME STATEMENT
B15: ="Forecast Year "&CaseData!J14 -> Forecast Year 1
B16: Revenues | E16: 1796.4 | G16: =CaseData!J60 -> 1796.4 | H16: =CaseData!J104 -> 2320
B17: Cost of Goods Sold (ex. D&A) | E17: 1131.7 | G17: =CaseData!J61 -> 1131.7 | H17: =CaseData!J105 -> 967.4
B18: SG&A Expenses (ex. D&A) | E18: 273.1 | G18: =CaseData!J64 -> 273.1 | H18: =CaseData!J108 -> 241.3
B19: Other Expenses | E19: 71.9 | G19: =CaseData!J65 -> 71.9 | H19: =CaseData!J109 -> 23.2
B20: Depreciation & Amortization | E20: 52.1 | G20: =CaseData!$J$68 -> 52.1 | H20: =CaseData!$J$112 -> 88.2
B21: Revenue Synergies | E21: 105 | G21: =CaseData!$D$60 -> 105 | H21: =CaseData!D104 -> 20
B22: Cost of Goods Sold Synergies | E22: 30 | G22: =CaseData!$D$61 -> 30 | H22: =CaseData!D105 -> 40
B23: SG&A Synergies | E23: 60 | G23: =CaseData!$D$62 -> 60 | H23: =CaseData!D106 -> 15
B25: ="Forecast Year "&CaseData!K14 -> Forecast Year 2
B26: Revenues | E26: 1877.2 | G26: =CaseData!K60 -> 1877.2 | H26: =CaseData!K104 -> 2440.6
B27: Cost of Goods Sold (ex. D&A) | E27: 1147 | G27: =CaseData!K61 -> 1147 | H27: =CaseData!K105 -> 1000.6
B28: SG&A Expenses (ex. D&A) | E28: 275.9 | G28: =CaseData!K64 -> 275.9 | H28: =CaseData!K108 -> 248.9
B29: Other Expenses | E29: 71.3 | G29: =CaseData!K65 -> 71.3 | H29: =CaseData!K109 -> 24.4
B30: Depreciation & Amortization | E30: 52.6 | G30: =CaseData!$K$68 -> 52.6 | H30: =CaseData!$K$112 -> 97.6
B31: Revenue Synergies | E31: 125 | G31: =CaseData!E60 -> 125 | H31: =CaseData!E104 -> 25
B32: Cost of Goods Sold Synergies | E32: 40 | G32: =CaseData!E61 -> 40 | H32: =CaseData!E105 -> 55
B33: SG&A Synergies | E33: 70 | G33: =CaseData!E62 -> 70 | H33: =CaseData!E106 -> 25
B35: HISTORICAL BALANCE SHEET
B36: Assets
B37: Cash & Equivalents | E37: 55.2 | G37: =CaseData!O60 -> 55.2 | H37: =CaseData!O104 -> 334.2
B38: Accounts Receivable | E38: 213.2 | G38: =CaseData!O61 -> 213.2 | H38: =CaseData!O105 -> 317.2
B39: Inventories | E39: 360.8 | G39: =CaseData!O62 -> 360.8 | H39: =CaseData!O106 -> 206.9
B40: Other Current Assets | E40: 21.7 | G40: =CaseData!O63 -> 21.7 | H40: =CaseData!O107 -> 44.4
B41: Fixed Assets (Net) | E41: 625.2 | G41: =CaseData!O66 -> 625.2 | H41: =CaseData!O110 -> 1196.8
B42: Goodwill | E42: 21.4 | G42: =CaseData!O67 -> 21.4 | H42: =CaseData!O111 -> 100.3
B43: Other Long-term Assets | E43: 90.5 | G43: =CaseData!O68 -> 90.5 | H43: =CaseData!O112 -> 452.1
B44: Total Assets | E44: 1388 | G44: =SUM(G37:G43) -> 1388 | H44: =SUM(H37:H43) -> 2651.9
B46: Liabilities and Equity
B47: Short-term Debt | G47: =CaseData!O71 -> 0 | H47: =CaseData!O115 -> 55.9
...
