Workbook
Name company: Input!$F$151
Name scenarios: Input!$F$154:$F$183
Name selector: Output!$I$6
Name topic: "CFM Topic: " &Input!$F$152

Sheet Output
A1: =company -> Rock Climbing Inc
A2: {=topic} -> CFM Topic: Sensitivity Analysis
A3: OUTPUT SCHEDULE
F6: Selector | I6: 18
F7: =Input!E$8 -> Comparison scenario | I7: =Input!F$8 -> Base
A10: Key Outputs
G12: Key Outputs per scenario and sensitivity | L12: In comparison to Base Case | Q12: IRR accretion scenarios or sensitivity | V12: IRR decrease scenarios or sensitivity
G13: IRR | H13: Net Sales Proceeds | I13: EBIDTA | J13: Revenue | L13: IRR | M13: Net Sales Proceeds | N13: EBIDTA | O13: Revenue | Q13: Top 5 | R13: Scenario or Sensitivity | S13: Delta to base | T13: IRR | V13: Bottom 5 | W13: Scenario or Sensitivity | X13: Delta to base | Y13: IRR
G14: =CaseCalcs!$E$119 -> 0.27882521 | H14: =CaseCalcs!$E$102 -> 5467208.7 | I14: =CaseCalcs!$E$52 -> 3612751.3 | J14: =CaseCalcs!$E$40 -> 12801811
E15: {=scenarios} -> Base | F15: {=_xlfn.SEQUENCE( ROWS( scenarios ) )} -> 1 | G15: 0.27663035 | H15: 5399940.8 | I15: 3585322.2 | J15: 12761011
E16: Scenario 1 | F16: 2 | G16: 0.26156512 | H16: 4916167.5 | I16: 3421517.7 | J16: 12717534 | L16: =( G16 - $G$15 ) / $G$15 -> -0.054459784 | M16: =( H16 - $H$15 ) / $H$15 -> -0.08958862 | N16: =( I16 - $I$15 ) / $I$15 -> -0.045687543 | O16: =( J16 - $J$15 ) / $J$15 -> -0.0034070888 | Q16: 1 | R16: {=_xlfn.XLOOKUP($S16,$L$15:$L$44,_xlfn.ANCHORARRAY($E$15))} -> Sensitivity 24 | S16: =LARGE($L$15:$L$44, $Q16 ) -> 0.28567803 | T16: =_xlfn.XLOOKUP($S16,$L$15:$L$44,$G$15:$G$44) -> 0.35565756 | V16: 5 | W16: {=_xlfn.XLOOKUP($X16,$L$15:$L$44,_xlfn.ANCHORARRAY($E$15))} -> Scenario 4 | X16: =SMALL( $L$15:$L$44, $V16 ) -> -0.067147242 | Y16: =_xlfn.XLOOKUP($X16,$L$15:$L$44,$G$15:$G$44) -> 0.25805538
E17: Scenario 2 | F17: 3 | G17: 0.27630394 | H17: 5390160.8 | I17: 3581202.1 | J17: 12695911 | L17: =( G17 - $G$15 ) / $G$15 -> -0.0011799391 | M17: =( H17 - $H$15 ) / $H$15 -> -0.0018111224 | N17: =( I17 - $I$15 ) / $I$15 -> -0.0011491738 | O17: =( J17 - $J$15 ) / $J$15 -> -0.0051015302 | Q17: 2 | R17: {=_xlfn.XLOOKUP($S17,$L$15:$L$44,_xlfn.ANCHORARRAY($E$15))} -> Sensitivity 19 | S17: =LARGE($L$15:$L$44, $Q17 ) -> 0.2540419 | T17: =_xlfn.XLOOKUP($S17,$L$15:$L$44,$G$15:$G$44) -> 0.34690605 | V17: 4 | W17: {=_xlfn.XLOOKUP($X17,$L$15:$L$44,_xlfn.ANCHORARRAY($E$15))} -> Sensitivity 1 | X17: =SMALL( $L$15:$L$44, $V17 ) -> -0.080924747 | Y17: =_xlfn.XLOOKUP($X17,$L$15:$L$44,$G$15:$G$44) -> 0.25424411
E18: Scenario 3 | F18: 4 | G18: 0.27319233 | H18: 5428419.8 | I18: 3529612.3 | J18: 13316613 | L18: =( G18 - $G$15 ) / $G$15 -> -0.012428209 | M18: =( H18 - $H$15 ) / $H$15 -> 0.0052739528 | N18: =( I18 - $I$15 ) / $I$15 -> -0.015538318 | O18: =( J18 - $J$15 ) / $J$15 -> 0.043538993 | Q18: 3 | R18: {=_xlfn.XLOOKUP($S18,$L$15:$L$44,_xlfn.ANCHORARRAY($E$15))} -> Sensitivity 3 | S18: =LARGE($L$15:$L$44, $Q18 ) -> 0.19106541 | T18: =_xlfn.XLOOKUP($S18,$L$15:$L$44,$G$15:$G$44) -> 0.32948484 | V18: 3 | W18: {=_xlfn.XLOOKUP($X18,$L$15:$L$44,_xlfn.ANCHORARRAY($E$15))} -> Sensitivity 20 | X18: =SMALL( $L$15:$L$44, $V18 ) -> -0.14546053 | Y18: =_xlfn.XLOOKUP($X18,$L$15:$L$44,$G$15:$G$44) -> 0.23639155
E19: Scenario 4 | F19: 5 | G19: 0.25805538 | H19: 5431155.7 | I19: 3597586 | J19: 12779176 | L19: =( G19 - $G$15 ) / $G$15 -> -0.067147242 | M19: =( H19 - $H$15 ) / $H$15 -> 0.0057806063 | N19: =( I19 - $I$15 ) / $I$15 -> 0.0034205569 | O19: =( J19 - $J$15 ) / $J$15 -> 0.0014234194 | Q19: 4 | R19: {=_xlfn.XLOOKUP($S19,$L$15:$L$44,_xlfn.ANCHORARRAY($E$15))} -> Sensitivity 7 | S19: =LARGE($L$15:$L$44, $Q19 ) -> 0.14397411 | T19: =_xlfn.XLOOKUP($S19,$L$15:$L$44,$G$15:$G$44) -> 0.31645796 | V19: 2 | W19: {=_xlfn.XLOOKUP($X19,$L$15:$L$44,_xlfn.ANCHORARRAY($E$15))} -> Sensitivity 8 | X19: =SMALL( $L$15:$L$44, $V19 ) -> -0.1558596 | Y19: =_xlfn.XLOOKUP($X19,$L$15:$L$44,$G$15:$G$44) -> 0.23351485
E20: Scenario 5 | F20: 6 | G20: 0.3102164 | H20: 6342386.9 | I20: 4082520.8 | J20: 13276683 | L20: =( G20 - $G$15 ) / $G$15 -> 0.1214113 | M20: =( H20 - $H$15 ) / $H$15 -> 0.17452896 | N20: =( I20 - $I$15 ) / $I$15 -> 0.13867613 | O20: =( J20 - $J$15 ) / $J$15 -> 0.04040992 | Q20: 5 | R20: {=_xlfn.XLOOKUP($S20,$L$15:$L$44,_xlfn.ANCHORARRAY($E$15))} -> Scenario 5 | S20: =LARGE($L$15:$L$44, $Q20 ) -> 0.1214113 | T20: =_xlfn.XLOOKUP($S20,$L$15:$L$44,$G$15:$G$44) -> 0.3102164 | V20: 1 | W20: {=_xlfn.XLOOKUP($X20,$L$15:$L$44,_xlfn.ANCHORARRAY($E$15))} -> Sensitivity 4 | X20: =SMALL( $L$15:$L$44, $V20 ) -> -0.21144654 | Y20: =_xlfn.XLOOKUP($X20,$L$15:$L$44,$G$15:$G$44) -> 0.21813782
E21: Sensitivity 1 | F21: 7 | G21: 0.25424411 | H21: 5399940.8 | I21: 3585322.2 | J21: 12761011 | L21: =( G21 - $G$15 ) / $G$15 -> -0.080924747 | M21: =( H21 - $H$15 ) / $H$15 -> 0 | N21: =( I21 - $I$15 ) / $I$15 -> 0 | O21: =( J21 - $J$15 ) / $J$15 -> 0
E22: Sensitivity 2 | F22: 8 | G22: 0.30231774 | H22: 5399940.8 | I22: 3585322.2 | J22: 12761011 | L22: =( G22 - $G$15 ) / $G$15 -> 0.092858201 | M22: =( H22 - $H$15 ) / $H$15 -> 0 | N22: =( I22 - $I$15 ) / $I$15 -> 0 | O22: =( J22 - $J$15 ) / $J$15 -> 0
E23: Sensitivity 3 | F23: 9 | G23: 0.32948484 | H23: 6421703.4 | I23: 4360119.9 | J23: 13535809 | L23: =( G23 - $G$15 ) / $G$15 -> 0.19106541 | M23: =( H23 - $H$15 ) / $H$15 -> 0.18921737 | N23: =( I23 - $I$15 ) / $I$15 -> 0.21610267 | O23: =( J23 - $J$15 ) / $J$15 -> 0.060716012
E24: Sensitivity 4 | F24: 10 | G24: 0.21813782 | H24: 4378178.2 | I24: 2810524.5 | J24: 11986214 | L24: =( G24 - $G$15 ) / $G$15 -> -0.21144654 | M24: =( H24 - $H$15 ) / $H$15 -> -0.18921737 | N24: =( I24 - $I$15 ) / $I$15 -> -0.21610267 | O24: =( J24 - $J$15 ) / $J$15 -> -0.060716012
E25: Sensitivity 5 | F25: 11 | G25: 0.29081978 | H25: 5833265.5 | I25: 3774280.9 | J25: 12949970 | L25: =( G25 - $G$15 ) / $G$15 -> 0.051293844 | M25: =( H25 - $H$15 ) / $H$15 -> 0.08024619 | N25: =( I25 - $I$15 ) / $I$15 -> 0.052703394 | O25: =( J25 - $J$15 ) / $J$15 -> 0.014807498
E26: Sensitivity 6 | F26: 12 | G26: 0.26316245 | H26: 5013504.7 | I26: 3417955.3 | J26: 12593644 | L26: =( G26 - $G$15 ) / $G$15 -> -0.048685533 | M26: =( H26 - $H$15 ) / $H$15 -> -0.071563022 | N26: =( I26 - $I$15 ) / $I$15 -> -0.04668115 | O26: =( J26 - $J$15 ) / $J$15 -> -0.013115494
E27: Sensitivity 7 | F27: 13 | G27: 0.31645796 | H27: 6178492.1 | I27: 4162733.2 | J27: 13730087 | L27: =( G27 - $G$15 ) / $G$15 -> 0.14397411 | M27: =( H27 - $H$15 ) / $H$15 -> 0.14417775 | N27: =( I27 - $I$15 ) / $I$15 -> 0.16104857 | O27: =( J27 - $J$15 ) / $J$15 -> 0.075940366
E28: Sensitivity 8 | F28: 14 | G28: 0.23351485 | H28: 4621389.5 | I28: 3007911.2 | J28: 11791936 | L28: =( G28 - $G$15 ) / $G$15 -> -0.1558596 | M28: =( H28 - $H$15 ) / $H$15 -> -0.14417775 | N28: =( I28 - $I$15 ) / $I$15 -> -0.16104857 | O28: =( J28 - $J$15 ) / $J$15 -> -0.075940366
E29: Sensitivity 9 | F29: 15 | G29: 0.283671 | H29: 5615189.5 | I29: 3675846.8 | J29: 12851536 | L29: =( G29 - $G$15 ) / $G$15 -> 0.025451494 | M29: =( H29 - $H$15 ) / $H$15 -> 0.039861318 | N29: =( I29 - $I$15 ) / $I$15 -> 0.025248651 | O29: =( J29 - $J$15 ) / $J$15 -> 0.0070938383
E30: Sensitivity 10 | F30: 16 | G30: 0.2695457 | H30: 5191748.7 | I30: 3496918.8 | J30: 12672608 | L30: =( G30 - $G$15 ) / $G$15 -> -0.025610508 | M30: =( H30 - $H$15 ) / $H$15 -> -0.038554521 | N30: =( I30 - $I$15 ) / $I$15 -> -0.024657038 | O30: =( J30 - $J$15 ) / $J$15 -> -0.0069276192
E31: Sensitivity 11 | F31: 17 | G31: 0.28886271 | H31: 5783915.3 | I31: 3743955 | J31: 13025464 | L31: =( G31 - $G$15 ) / $G$15 -> 0.044219166 | M31: =( H31 - $H$15 ) / $H$15 -> 0.071107175 | N31: =( I31 - $I$15 ) / $I$15 -> 0.044245063 | O31: =( J31 - $J$15 ) / $J$15 -> 0.020723479
E32: Sensitivity 12 | F32: 18 | G32: 0.27882521 | H32: 5467208.7 | I32: 3612751.3 | J32: 12801811 | L32: =( G32 - $G$15 ) / $G$15 -> 0.0079342618 | M32: =( H32 - $H$15 ) / $H$15 -> 0.012457152 | N32: =( I32 - $I$15 ) / $I$15 -> 0.0076503824 | O32: =( J32 - $J$15 ) / $J$15 -> 0.003197195
... E44: Sensitivity 24 | F44: 30 | G44: 0.35565756 | H44: 1841827.1 | I44: 752497.61 | J44: 3335581.4 | L44: =( G44 - $G$15 ) / $G$15 -> 0.28567803 | M44: =( H44 - $H$15 ) / $H$15 -> -0.65891717 | N44: =( I44 - $I$15 ) / $I$15 -> -0.79011716 | O44: =( J44 - $J$15 ) / $J$15 -> -0.73861152

Sheet Input
A1: {=company} -> Rock Climbing Inc
A2: {=topic} -> CFM Topic: Sensitivity Analysis
A3: ASSUMPTIONS SCHEDULE
K5: =IF( K$6 = $F$186, "q","" ) | L5: =IF( L$6 = $F$186, "q","" ) | M5: =IF( M$6 = $F$186, "q","" ) | N5: =IF( N$6 = $F$186, "q","" ) | O5: =IF( O$6 = $F$186, "q","" ) | P5: =IF( P$6 = $F$186, "q","" ) | Q5: =IF( Q$6 = $F$186, "q","" ) | R5: =IF( R$6 = $F$186, "q","" ) | ... AN5: =IF( AN$6 = $F$186, "q","" )
E6: Live Case | K6: {=TRANSPOSE( scenarios )} -> Base | L6: Scenario 1 | M6: Scenario 2 | N6: Scenario 3 | O6: Scenario 4 | P6: Scenario 5 | Q6: Sensitivity 1 | R6: Sensitivity 2 | S6: Sensitivity 3 | T6: Sensitivity 4 | U6: Sensitivity 5 | V6: Sensitivity 6 | W6: Sensitivity 7 | X6: Sensitivity 8 | Y6: Sensitivity 9 | Z6: Sensitivity 10 | AA6: Sensitivity 11 | AB6: Sensitivity 12 | AC6: Sensitivity 13 | AD6: Sensitivity 14 | AE6: Sensitivity 15 | AF6: Sensitivity 16 | AG6: Sensitivity 17 | AH6: Sensitivity 18 | AI6: Sensitivity 19 | AJ6: Sensitivity 20 | AK6: Sensitivity 21 | AL6: Sensitivity 22 | AM6: Sensitivity 23 | AN6: Sensitivity 24
E7: {=REPT( CHAR( 10 ), 2 ) & "Case description" & REPT( CHAR( 10 ), 2 ) & INDEX( $K$7:$AN$7, selector )} -> Case description Input: Year on Year change to Ordinary Casual Visits Requested change: plus 50 basis points to all years (excluding 2022) | K7: Base case scenario | L7: =CaseAnalysis!$B35 -> Change the escalation rate of regular membership fees from 4.00% to 3.00%, and add 1.00% to the Regular members YoY growth for each of 2023, 2024, 2025 and 2026. | M7: =CaseAnalysis!$B36 -> Increase the Casual Visit Ordinary 2022 price to $30.00, and decrease the number of 2022 Ordinary Casual visits from 5,000 to 4,500. | N7: =CaseAnalysis!$B37 -> Increase Fixed Expenses in 2022 to $420,000, and increase the number of 2022 Ordinary Casual visits from 5,000 to 6,000. Increase the # of Friends of Members Casuals visits to 13 per member per year. | O7: =CaseAnalysis!$B38 -> Perform a larger refurbishment that costs 800,000, still with 400,000 debt funded and the remainder equity funded. Change the 2027 YoY regular member growth to 22%, and the 2027 YoY Casual Visit growth to 12%. | P7: =CaseAnalysis!$B39 -> At the start of 2023, convert all Foundation Members to Regular Members. Assume that 20% will quit the gym in protest, and 80% will convert. (This may require some logic changes to the model.) | Q7: {=TRANSPOSE( CaseAnalysis!$E$4:$E$27 )} -> Input: Initial Purchase Cost Requested change: plus 10% of base value | R7: Input: Initial Purchase Cost Requested change: minus 10% of base value | S7: Input: 2022 Membership fee (Regular member) Requested change: plus 10% of base value | T7: Input: 2022 Membership fee (Regular member) Requested change: minus 10% of base value | U7: Input: Escalation rate of membership fees Requested change: plus 50 basis points (e.g. from 4.00% up to 4.50%) | V7: Input: Escalation rate of membership fees Requested change: minus 50 basis points | W7: Input: Number of Regular members at start of 2022 Requested change: plus 50 people from base value | X7: Input: Number of Regular members at start of 2022 Requested change: minus 50 people from base value | Y7: Input: Increase in Casual Visit Prices each year Requested change: plus 50 basis points | Z7: Input: Increase in Casual Visit Prices each year Requested change: minus 50 basis points | AA7: Input: Year on Year change to Regular Members Requested change: plus 50 basis points to all years (excluding 2022) | AB7: Input: Year on Year change to Ordinary Casual Visits Requested change: plus 50 basis points to all years (excluding 2022) | AC7: Input: Escalation rate of fixed expenses Requested change: plus 50 basis points | AD7: Input: Escalation rate of fixed expenses Requested change: minus 50 basis points | AE7: Input: Escalation rate of variable expenses Requested change: plus 50 basis points | AF7: Input: Escalation rate of variable expenses Requested change: minus 50 basis points | AG7: Input: Initial Purchase Debt Facility Interest Rate Requested change: plus 50 basis points | AH7: Input: Refurbishment Debt Facility Interest Rate Requested change: plus 50 basis points | AI7: Input: Initial Purchase % funded by Debt Requested change: change % funded to 80% | AJ7: Input: Initial Purchase % funded by Debt Requested change: change % funded to 40% | AK7: Input: Refurbishment % funded by Debt Requested change: change % funded to 90% | AL7: Input: Refurbishment % funded by Debt Requested change: change % funded to 70% | AM7: Input: Time of Sale of Business Requested change: bring forward to end of 2028 | AN7: Input: Time of Sale of Business Requested change: bring forward to end of 2024
E8: Comparison scenario | F8: =INDEX( scenarios, 1, 1 ) -> Base
E9: Input differences | F9: =COUNTIF( $I$12:$I$144, "tu" ) -> 9
F11: Constant | G11: Unit
B13: Initial Purchase
E15: Initial Purchase Date (Day 0) - DO NOT CHANGE | F15: 44561 | G15: [date]
E16: Initial Purchase Costs on day 0 | F16: {=IF( INDEX( $K16:$AN16, selector ) = "", INDEX( $K16:$AN16, , 1 ), INDEX( $K16:$AN16, 1, selector ))} -> 2000000 | G16: [$] | I16: =IF( $F16 = $K16, "vw", "tu" ) -> vw | K16: 2000000 | Q16: 2200000 | R16: 1800000
B18: Revenues
D20: Membership Fees
E21: Membership fees per Foundation member in 2022 | F21: {=IF( INDEX( $K21:$AN21, selector ) = "", INDEX( $K21:$AN21, , 1 ), INDEX( $K21:$AN21, 1, selector ))} -> 900 | G21: [$ / member] | I21: =IF( $F21 = $K21, "vw", "tu" ) -> vw | K21: 900
E22: Membership fees per Regular member in 2022 | F22: {=IF( INDEX( $K22:$AN22, selector ) = "", INDEX( $K22:$AN22, , 1 ), INDEX( $K22:$AN22, 1, selector ))} -> 1200 | G22: [$ / member] | I22: =IF( $F22 = $K22, "vw", "tu" ) -> vw | K22: 1200 | S22: 1320 | T22: 1080
E23: Escalation rate of Foundation membership fees | F23: {=IF( INDEX( $K23:$AN23, selector ) = "", INDEX( $K23:$AN23, , 1 ), INDEX( $K23:$AN23, 1, selector ))} -> 0 | G23: [%] | I23: =IF( $F23 = $K23, "vw", "tu" ) -> vw | K23: 0 | U23: 0.005 | V23: 0
E24: Escalation rate of Regular membership fees | F24: {=IF( INDEX( $K24:$AN24, selector ) = "", INDEX( $K24:$AN24, , 1 ), INDEX( $K24:$AN24, 1, selector ))} -> 0.04 | G24: [%] | I24: =IF( $F24 = $K24, "vw", "tu" ) -> vw | K24: 0.04 | L24: 0.03 | U24: 0.045 | V24: 0.035
D26: Initial Membership Numbers | P26: changed in the model
E27: Number of Foundation members at start of 2022 | F27: {=IF( INDEX( $K27:$AN27, selector ) = "", INDEX( $K27:$AN27, , 1 ), INDEX( $K27:$AN27, 1, selector ))} -> 120 | G27: [#] | I27: =IF( $F27 = $K27, "vw", "tu" ) -> vw | K27: 120
E28: Number of Regular members at start of 2022 | F28: {=IF( INDEX( $K28:$AN28, selector ) = "", INDEX( $K28:$AN28, , 1 ), INDEX( $K28:$AN28, 1, selector ))} -> 500 | G28: [#] | I28: =IF( $F28 = $K28, "vw", "tu" ) -> vw | K28: 500 | W28: 550 | X28: 450
D30: Year on Year (YoY %) change in membership numbers
E31: Assume the change happens on Day 1 of each year
F32: Foundation Members
E33: Calendar Year | F33: Change
E34: =YEAR($F$15)+1 -> 2022 | F34: {=IF( INDEX( $K34:$AN34, selector ) = "", INDEX( $K34:$AN34, , 1 ), INDEX( $K34:$AN34, 1, selector ))} -> 0 | G34: [%] | I34: =IF( $F34 = $K34, "vw", "tu" ) -> vw | K34: 0
E35: =E34+1 -> 2023 | F35: {=IF( INDEX( $K35:$AN35, selector ) = "", INDEX( $K35:$AN35, , 1 ), INDEX( $K35:$AN35, 1, selector ))} -> -0.02 | G35: [%] | I35: =IF( $F35 = $K35, "vw", "tu" ) -> vw | K35: -0.02
E36: =E35+1 -> 2024 | F36: {=IF( INDEX( $K36:$AN36, selector ) = "", INDEX( $K36:$AN36, , 1 ), INDEX( $K36:$AN36, 1, selector ))} -> -0.02 | G36: [%] | I36: =IF( $F36 = $K36, "vw", "tu" ) -> vw | K36: -0.02
E37: =E36+1 -> 2025 | F37: {=IF( INDEX( $K37:$AN37, selector ) = "", INDEX( $K37:$AN37, , 1 ), INDEX( $K37:$AN37, 1, selector ))} -> -0.02 | G37: [%] | I37: =IF( $F37 = $K37, "vw", "tu" ) -> vw | K37: -0.02
E38: =E37+1 -> 2026 | F38: {=IF( INDEX( $K38:$AN38, selector ) = "", INDEX( $K38:$AN38, , 1 ), INDEX( $K38:$AN38, 1, selector ))} -> -0.02 | G38: [%] | I38: =IF( $F38 = $K38, "vw", "tu" ) -> vw | K38: -0.02
E39: =E38+1 -> 2027 | F39: {=IF( INDEX( $K39:$AN39, selector ) = "", INDEX( $K39:$AN39, , 1 ), INDEX( $K39:$AN39, 1, selector ))} -> -0.02 | G39: [%] | I39: =IF( $F39 = $K39, "vw", "tu" ) -> vw | K39: -0.02
E40: =E39+1 -> 2028 | F40: {=IF( INDEX( $K40:$AN40, selector ) = "", INDEX( $K40:$AN40, , 1 ), INDEX( $K40:$AN40, 1, selector ))} -> -0.02 | G40: [%] | I40: =IF( $F40 = $K40, "vw", "tu" ) -> vw | K40: -0.02
E41: =E40+1 -> 2029 | F41: {=IF( INDEX( $K41:$AN41, selector ) = "", INDEX( $K41:$AN41, , 1 ), INDEX( $K41:$AN41, 1, selector ))} -> -0.02 | G41: [%] | I41: =IF( $F41 = $K41, "vw", "tu" ) -> vw | K41: -0.02
E42: =E41+1 -> 2030 | F42: {=IF( INDEX( $K42:$AN42, selector ) = "", INDEX( $K42:$AN42, , 1 ), INDEX( $K42:$AN42, 1, selector ))} -> -0.02 | G42: [%] | I42: =IF( $F42 = $K42, "vw", "tu" ) -> vw | K42: -0.02
E43: =E42+1 -> 2031 | F43: {=IF( INDEX( $K43:$AN43, selector ) = "", INDEX( $K43:$AN43, , 1 ), INDEX( $K43:$AN43, 1, selector ))} -> -0.02 | G43: [%] | I43: =IF( $F43 = $K43, "vw", "tu" ) -> vw | K43: -0.02
F45: Regular Members
E46: Calendar Year | F46: Change
E47: =YEAR($F$15)+1 -> 2022 | F47: {=IF( INDEX( $K47:$AN47, selector ) = "", INDEX( $K47:$AN47, , 1 ), INDEX( $K47:$AN47, 1, selector ))} -> 0 | G47: [%] | I47: =IF( $F47 = $K47, "vw", "tu" ) -> vw | K47: 0 | AA47: 0.005
E48: =E47+1 -> 2023 | F48: {=IF( INDEX( $K48:$AN48, selector ) = "", INDEX( $K48:$AN48, , 1 ), INDEX( $K48:$AN48, 1, selector ))} -> 0.06 | G48: [%] | I48: =IF( $F48 = $K48, "vw", "tu" ) -> vw | K48: 0.06 | L48: 0.07 | AA48: 0.065
E49: =E48+1 -> 2024 | F49: {=IF( INDEX( $K49:$AN49, selector ) = "", INDEX( $K49:$AN49, , 1 ), INDEX( $K49:$AN49, 1, selector ))} -> 0.04 | G49: [%] | I49: =IF( $F49 = $K49, "vw", "tu" ) -> vw | K49: 0.04 | L49: 0.05 | AA49: 0.045
...

Sheet CaseCalcs
A1: CALCULATION SCHEDULE
A3: 2 | C3: Calculations
D5: Period Start | E5: Select Live Case | K5: =J6+1 -> 44562 | L5: =K6+1 -> 44927 | M5: =L6+1 -> 45292 | N5: =M6+1 -> 45658 | O5: =N6+1 -> 46023 | P5: =O6+1 -> 46388 | Q5: =P6+1 -> 46753 | R5: =Q6+1 -> 47119 | ... T5: =S6+1 -> 47849
D6: Period End | J6: =Input!$F$15 -> 44561 | K6: =EOMONTH(J6,12) -> 44926 | L6: =EOMONTH(K6,12) -> 45291 | M6: =EOMONTH(L6,12) -> 45657 | N6: =EOMONTH(M6,12) -> 46022 | O6: =EOMONTH(N6,12) -> 46387 | P6: =EOMONTH(O6,12) -> 46752 | Q6: =EOMONTH(P6,12) -> 47118 | R6: =EOMONTH(Q6,12) -> 47483 | ... T6: =EOMONTH(S6,12) -> 48213
D7: Calendar Year | J7: =YEAR(J6) -> 2021 | K7: =YEAR(K6) -> 2022 | L7: =YEAR(L6) -> 2023 | M7: =YEAR(M6) -> 2024 | N7: =YEAR(N6) -> 2025 | O7: =YEAR(O6) -> 2026 | P7: =YEAR(P6) -> 2027 | Q7: =YEAR(Q6) -> 2028 | ... T7: =YEAR(T6) -> 2031
A10: =MAX(A$3:A9)+0.01 -> 2.01 | C10: Operations
D12: Operating Period Number | F12: [#] | J12: 0 | K12: =J12+1 -> 1 | L12: =K12+1 -> 2 | M12: =L12+1 -> 3 | N12: =M12+1 -> 4 | O12: =N12+1 -> 5 | P12: =O12+1 -> 6 | Q12: =P12+1 -> 7 | R12: =Q12+1 -> 8 | ... T12: =S12+1 -> 10
D13: Operating Period? (i.e. before Sale of Business) | F13: [flag] | G13: =Input!$F$144 -> 2030 | J13: =1*(J$7<=$G13) -> 1 | K13: =1*(K$7<=$G13) -> 1 | L13: =1*(L$7<=$G13) -> 1 | M13: =1*(M$7<=$G13) -> 1 | N13: =1*(N$7<=$G13) -> 1 | O13: =1*(O$7<=$G13) -> 1 | P13: =1*(P$7<=$G13) -> 1 | Q13: =1*(Q$7<=$G13) -> 1 | ... T13: =1*(T$7<=$G13) -> 0
B15: Operations
D16: Membership Prices
D17: Price per Foundation membership | F17: [$] | G17: =Input!F21 -> 900 | H17: =Input!F23 -> 0 | K17: =$G17 -> 900 | L17: =K17*(1+$H17) -> 900 | M17: =L17*(1+$H17) -> 900 | N17: =M17*(1+$H17) -> 900 | O17: =N17*(1+$H17) -> 900 | P17: =O17*(1+$H17) -> 900 | Q17: =P17*(1+$H17) -> 900 | R17: =Q17*(1+$H17) -> 900 | S17: =R17*(1+$H17) -> 900 | T17: =S17*(1+$H17) -> 900
D18: Price per Regular membership | G18: =Input!F22 -> 1200 | H18: =Input!F24 -> 0.04 | K18: =$G18 -> 1200 | L18: =K18*(1+$H18) -> 1248 | M18: =L18*(1+$H18) -> 1297.92 | N18: =M18*(1+$H18) -> 1349.8368 | O18: =N18*(1+$H18) -> 1403.8303 | P18: =O18*(1+$H18) -> 1459.9835 | Q18: =P18*(1+$H18) -> 1518.3828 | R18: =Q18*(1+$H18) -> 1579.1181 | S18: =R18*(1+$H18) -> 1642.2829 | T18: =S18*(1+$H18) -> 1707.9742
D20: Membership Numbers
D21: Foundation Members - Year of Year Growth | F21: [%] | K21: =INDEX(Input!$F$34:$F$43,MATCH(K$7,Input!$E$34:$E$43,0)) -> 0 | L21: =INDEX(Input!$F$34:$F$43,MATCH(L$7,Input!$E$34:$E$43,0)) -> -0.02 | M21: =INDEX(Input!$F$34:$F$43,MATCH(M$7,Input!$E$34:$E$43,0)) -> -0.02 | N21: =INDEX(Input!$F$34:$F$43,MATCH(N$7,Input!$E$34:$E$43,0)) -> -0.02 | O21: =INDEX(Input!$F$34:$F$43,MATCH(O$7,Input!$E$34:$E$43,0)) -> -0.02 | P21: =INDEX(Input!$F$34:$F$43,MATCH(P$7,Input!$E$34:$E$43,0)) -> -0.02 | Q21: =INDEX(Input!$F$34:$F$43,MATCH(Q$7,Input!$E$34:$E$43,0)) -> -0.02 | R21: =INDEX(Input!$F$34:$F$43,MATCH(R$7,Input!$E$34:$E$43,0)) -> -0.02 | ... T21: =INDEX(Input!$F$34:$F$43,MATCH(T$7,Input!$E$34:$E$43,0)) -> -0.02
D22: Regular Members - Year on Year Growth | F22: [%] | K22: =INDEX(Input!$F$47:$F$56,MATCH(K$7,Input!$E$47:$E$56,0)) -> 0 | L22: =INDEX(Input!$F$47:$F$56,MATCH(L$7,Input!$E$47:$E$56,0)) -> 0.06 | M22: =INDEX(Input!$F$47:$F$56,MATCH(M$7,Input!$E$47:$E$56,0)) -> 0.04 | N22: =INDEX(Input!$F$47:$F$56,MATCH(N$7,Input!$E$47:$E$56,0)) -> 0.02 | O22: =INDEX(Input!$F$47:$F$56,MATCH(O$7,Input!$E$47:$E$56,0)) -> 0.01 | P22: =INDEX(Input!$F$47:$F$56,MATCH(P$7,Input!$E$47:$E$56,0)) -> 0.17 | Q22: =INDEX(Input!$F$47:$F$56,MATCH(Q$7,Input!$E$47:$E$56,0)) -> 0.02 | R22: =INDEX(Input!$F$47:$F$56,MATCH(R$7,Input!$E$47:$E$56,0)) -> 0.01 | ... T22: =INDEX(Input!$F$47:$F$56,MATCH(T$7,Input!$E$47:$E$56,0)) -> 0.01
D23: Foundation Members during year | E23: =SUM(J23:T23) -> 1097.5632 | F23: [#] | G23: =Input!F27 -> 120 | K23: =G23 -> 120 | L23: =IF( selector = 6, 0, K23*(1+L21) ) -> 117.6 | M23: =IF( selector = 6, 0, L23*(1+M21) ) -> 115.248 | N23: =IF( selector = 6, 0, M23*(1+N21) ) -> 112.94304 | O23: =IF( selector = 6, 0, N23*(1+O21) ) -> 110.68418 | P23: =IF( selector = 6, 0, O23*(1+P21) ) -> 108.4705 | Q23: =IF( selector = 6, 0, P23*(1+Q21) ) -> 106.30109 | R23: =IF( selector = 6, 0, Q23*(1+R21) ) -> 104.17506 | S23: =IF( selector = 6, 0, R23*(1+S21) ) -> 102.09156 | T23: =IF( selector = 6, 0, S23*(1+T21) ) -> 100.04973
D24: Regular Members during year | E24: =SUM(J24:T24) -> 6127.253 | F24: [#] | G24: =Input!F28 -> 500 | K24: =G24 -> 500 | L24: =IF( selector = 6, ( K23 * 0.8 ) + K24*(1+L22), K24*(1+L22) ) -> 530 | M24: =L24*(1+M22) -> 551.2 | N24: =M24*(1+N22) -> 562.224 | O24: =N24*(1+O22) -> 567.84624 | P24: =O24*(1+P22) -> 664.3801 | Q24: =P24*(1+Q22) -> 677.6677 | R24: =Q24*(1+R22) -> 684.44438 | S24: =R24*(1+S22) -> 691.28882 | T24: =S24*(1+T22) -> 698.20171
D26: Casual Prices
D27: Price per casual visit - Ordinary | F27: [$] | G27: =Input!F60 -> 28 | H27: =Input!$F$62 -> 0.05 | K27: =G27 -> 28 | L27: =K27*(1+$H27) -> 29.4 | M27: =L27*(1+$H27) -> 30.87 | N27: =M27*(1+$H27) -> 32.4135 | O27: =N27*(1+$H27) -> 34.034175 | P27: =O27*(1+$H27) -> 35.735884 | Q27: =P27*(1+$H27) -> 37.522678 | R27: =Q27*(1+$H27) -> 39.398812 | S27: =R27*(1+$H27) -> 41.368752 | T27: =S27*(1+$H27) -> 43.43719
D28: Price per casual visit - Friends of Members | F28: [$] | G28: =Input!F61 -> 24 | H28: =Input!$F$62 -> 0.05 | K28: =G28 -> 24 | L28: =K28*(1+$H28) -> 25.2 | M28: =L28*(1+$H28) -> 26.46 | N28: =M28*(1+$H28) -> 27.783 | O28: =N28*(1+$H28) -> 29.17215 | P28: =O28*(1+$H28) -> 30.630758 | Q28: =P28*(1+$H28) -> 32.162295 | R28: =Q28*(1+$H28) -> 33.77041 | S28: =R28*(1+$H28) -> 35.458931 | T28: =S28*(1+$H28) -> 37.231877
D30: Casual Visit Numbers
D31: Casual visits - Year on Year Growth | F31: [%] | K31: =INDEX(Input!$F$71:$F$80,MATCH(K$7,Input!$E$71:$E$80,0)) -> 0 | L31: =INDEX(Input!$F$71:$F$80,MATCH(L$7,Input!$E$71:$E$80,0)) -> 0.035 | M31: =INDEX(Input!$F$71:$F$80,MATCH(M$7,Input!$E$71:$E$80,0)) -> 0.035 | N31: =INDEX(Input!$F$71:$F$80,MATCH(N$7,Input!$E$71:$E$80,0)) -> 0.035 | O31: =INDEX(Input!$F$71:$F$80,MATCH(O$7,Input!$E$71:$E$80,0)) -> 0.035 | P31: =INDEX(Input!$F$71:$F$80,MATCH(P$7,Input!$E$71:$E$80,0)) -> 0.105 | Q31: =INDEX(Input!$F$71:$F$80,MATCH(Q$7,Input!$E$71:$E$80,0)) -> 0.035 | R31: =INDEX(Input!$F$71:$F$80,MATCH(R$7,Input!$E$71:$E$80,0)) -> 0.035 | ... T31: =INDEX(Input!$F$71:$F$80,MATCH(T$7,Input!$E$71:$E$80,0)) -> 0.035
D32: Casual visits - Ordinary | E32: =SUM(J32:T32) -> 60810.709 | F32: [#] | G32: =Input!F65 -> 5000 | K32: =G32 -> 5000 | L32: =K32*(1+L31) -> 5175 | M32: =L32*(1+M31) -> 5356.125 | N32: =M32*(1+N31) -> 5543.5894 | O32: =N32*(1+O31) -> 5737.615 | P32: =O32*(1+P31) -> 6340.0646 | Q32: =P32*(1+Q31) -> 6561.9668 | R32: =Q32*(1+R31) -> 6791.6357 | S32: =R32*(1+S31) -> 7029.3429 | T32: =S32*(1+T31) -> 7275.3699
D33: Casual visits - Friends of Members | E33: =SUM(J33:T33) -> 86697.793 | F33: [#] | G33: =Input!F82 -> 12 | K33: =$G33*SUM(K23:K24) -> 7440 | L33: =$G33*SUM(L23:L24) -> 7771.2 | M33: =$G33*SUM(M23:M24) -> 7997.376 | N33: =$G33*SUM(N23:N24) -> 8102.0045 | O33: =$G33*SUM(O23:O24) -> 8142.365 | P33: =$G33*SUM(P23:P24) -> 9274.2072 | Q33: =$G33*SUM(Q23:Q24) -> 9407.6255 | R33: =$G33*SUM(R23:R24) -> 9463.4333 | ... T33: =$G33*SUM(T23:T24) -> 9579.0173
C35: Revenues
D36: Membership Fees - Foundation | E36: =SUM(J36:T36) -> 897762.08 | F36: [$] | J36: 0 | K36: =K17*K23*K$13 -> 108000 | L36: =L17*L23*L$13 -> 105840 | M36: =M17*M23*M$13 -> 103723.2 | N36: =N17*N23*N$13 -> 101648.74 | O36: =O17*O23*O$13 -> 99615.761 | P36: =P17*P23*P$13 -> 97623.446 | Q36: =Q17*Q23*Q$13 -> 95670.977 | R36: =R17*R23*R$13 -> 93757.558 | ... T36: =T17*T23*T$13 -> 0
D37: Membership Fees - Regular | E37: =SUM(J37:T37) -> 7747977.2 | F37: [$] | J37: 0 | K37: =K18*K24*K$13 -> 600000 | L37: =L18*L24*L$13 -> 661440 | M37: =M18*M24*M$13 -> 715413.5 | N37: =N18*N24*N$13 -> 758910.65 | O37: =O18*O24*O$13 -> 797159.74 | P37: =P18*P24*P$13 -> 969983.97 | Q37: =Q18*Q24*Q$13 -> 1028959 | R37: =R18*R24*R$13 -> 1080818.5 | ... T37: =T18*T24*T$13 -> 0
D38: Casual Visit Fees - Ordinary | E38: =SUM(J38:T38) -> 1863618.6 | F38: [$] | J38: 0 | K38: =K27*K32*K$13 -> 140000 | L38: =L27*L32*L$13 -> 152145 | M38: =M27*M32*M$13 -> 165343.58 | N38: =N27*N32*N$13 -> 179687.13 | O38: =O27*O32*O$13 -> 195274.99 | P38: =P27*P32*P$13 -> 226567.81 | Q38: =Q27*Q32*Q$13 -> 246222.57 | R38: =R27*R32*R$13 -> 267582.38 | ... T38: =T27*T32*T$13 -> 0
D39: Casual Visit Fees - Friends of Members | E39: =SUM(J39:T39) -> 2292453 | J39: 0 | K39: =K28*K33*K$13 -> 178560 | L39: =L28*L33*L$13 -> 195834.24 | M39: =M28*M33*M$13 -> 211610.57 | N39: =N28*N33*N$13 -> 225097.99 | O39: =O28*O33*O$13 -> 237530.29 | P39: =P28*P33*P$13 -> 284075.99 | Q39: =Q28*Q33*Q$13 -> 302570.83 | R39: =R28*R33*R$13 -> 319584.02 | ... T39: =T28*T33*T$13 -> 0
D40: Total Revenues | E40: =SUM(J40:T40) -> 12801811 | F40: [$] | J40: =SUM(J36:J39) -> 0 | K40: =SUM(K36:K39) -> 1026560 | L40: =SUM(L36:L39) -> 1115259.2 | M40: =SUM(M36:M39) -> 1196090.9 | N40: =SUM(N36:N39) -> 1265344.5 | O40: =SUM(O36:O39) -> 1329580.8 | P40: =SUM(P36:P39) -> 1578251.2 | Q40: =SUM(Q36:Q39) -> 1673423.4 | ... T40: =SUM(T36:T39) -> 0
C42: Expenses
D43: Variable Expenses per member per year | F43: [$] | G43: =Input!F92 -> 500 | H43: =Input!$F$94 -> 0.035 | K43: =G43 -> 500 | L43: =K43*(1+$H43) -> 517.5 | M43: =L43*(1+$H43) -> 535.6125 | N43: =M43*(1+$H43) -> 554.35894 | O43: =N43*(1+$H43) -> 573.7615 | P43: =O43*(1+$H43) -> 593.84315 | Q43: =P43*(1+$H43) -> 614.62766 | R43: =Q43*(1+$H43) -> 636.13963 | S43: =R43*(1+$H43) -> 658.40452 | T43: =S43*(1+$H43) -> 681.44868
D44: Variable Expenses per casual visit | F44: [$] | G44: =Input!F93 -> 10 | H44: =Input!$F$94 -> 0.035 | K44: =G44 -> 10 | L44: =K44*(1+$H44) -> 10.35 | M44: =L44*(1+$H44) -> 10.71225 | N44: =M44*(1+$H44) -> 11.087179 | O44: =N44*(1+$H44) -> 11.47523 | P44: =O44*(1+$H44) -> 11.876863 | Q44: =P44*(1+$H44) -> 12.292553 | R44: =Q44*(1+$H44) -> 12.722793 | S44: =R44*(1+$H44) -> 13.16809 | T44: =S44*(1+$H44) -> 13.628974
D47: Fixed Expenses | E47: =SUM(J47:T47) -> 3940028.4 | F47: [$] | G47: =Input!F88 -> 380000 | H47: =Input!F89 -> 0.035 | J47: 0 | K47: =$G47*K$13 -> 380000 | L47: =K47*(1+$H47)*L$13 -> 393300 | M47: =L47*(1+$H47)*M$13 -> 407065.5 | N47: =M47*(1+$H47)*N$13 -> 421312.79 | O47: =N47*(1+$H47)*O$13 -> 436058.74 | P47: =O47*(1+$H47)*P$13 -> 451320.8 | Q47: =P47*(1+$H47)*Q$13 -> 467117.02 | R47: =Q47*(1+$H47)*R$13 -> 483466.12 | S47: =R47*(1+$H47)*S$13 -> 500387.43 | T47: =S47*(1+$H47)*T$13 -> 0
D48: Variable Expenses - Member visits | E48: =SUM(J48:T48) -> 3730528.6 | F48: [$] | J48: 0 | K48: =K43*SUM(K23:K24)*K$13 -> 310000 | L48: =L43*SUM(L23:L24)*L$13 -> 335133 | M48: =M43*SUM(M23:M24)*M$13 -> 356957.88 | N48: =N43*SUM(N23:N24)*N$13 -> 374284.88 | O48: =O43*SUM(O23:O24)*O$13 -> 389314.63 | P48: =P43*SUM(P23:P24)*P$13 -> 458952.03 | Q48: =Q43*SUM(Q23:Q24)*Q$13 -> 481848.9 | R48: =R43*SUM(R23:R24)*R$13 -> 501672.08 | ... T48: =T43*SUM(T23:T24)*T$13 -> 0
D49: Variable Expenses - Casual visits | E49: =SUM(J49:T49) -> 1518502.5 | F49: [$] | J49: 0 | K49: =K44*SUM(K32:K33)*K$13 -> 124400 | L49: =L44*SUM(L32:L33)*L$13 -> 133993.17 | M49: =M44*SUM(M32:M33)*M$13 -> 143046.04 | N49: =N44*SUM(N32:N33)*N$13 -> 151291.14 | O49: =O44*SUM(O32:O33)*O$13 -> 159275.96 | P49: =P44*SUM(P32:P33)*P$13 -> 185448.57 | Q49: =Q44*SUM(Q32:Q33)*Q$13 -> 196307.06 | R49: =R44*SUM(R32:R33)*R$13 -> 206809.87 | ... T49: =T44*SUM(T32:T33)*T$13 -> 0
D50: Total Expenses | E50: =SUM(J50:T50) -> 9189059.5 | F50: [$] | J50: =SUM(J47:J49) -> 0 | K50: =SUM(K47:K49) -> 814400 | L50: =SUM(L47:L49) -> 862426.17 | M50: =SUM(M47:M49) -> 907069.42 | N50: =SUM(N47:N49) -> 946888.81 | O50: =SUM(O47:O49) -> 984649.33 | P50: =SUM(P47:P49) -> 1095721.4 | Q50: =SUM(Q47:Q49) -> 1145273 | ... T50: =SUM(T47:T49) -> 0
D52: EBITDA | E52: =SUM(J52:T52) -> 3612751.3 | F52: [$] | J52: =J40-J50 -> 0 | K52: =K40-K50 -> 212160 | L52: =L40-L50 -> 252833.07 | M52: =M40-M50 -> 289021.43 | N52: =N40-N50 -> 318455.69 | O52: =O40-O50 -> 344931.46 | P52: =P40-P50 -> 482529.82 | Q52: =Q40-Q50 -> 528150.38 | ... T52: =T40-T50 -> 0
A55: =MAX(A$3:A54)+0.01 -> 2.02 | C55: Debt
B57: Debt
...

Sheet CaseAnalysis
A2: Sensitivity Analysis
B3: Input | C3: Requested change
A4: 1 | B4: Initial Purchase Cost | C4: plus 10% of base value | E4: ="Input: " & CHAR(10) & $B4 & REPT(CHAR(10), 2 ) & "Requested change: " & CHAR(10) & $C4 -> Input: Initial Purchase Cost Requested change: plus 10% of base value
A5: 2 | B5: Initial Purchase Cost | C5: minus 10% of base value | E5: ="Input: " & CHAR(10) & $B5 & REPT(CHAR(10), 2 ) & "Requested change: " & CHAR(10) & $C5 -> Input: Initial Purchase Cost Requested change: minus 10% of base value
A6: 3 | B6: 2022 Membership fee (Regular member) | C6: plus 10% of base value | E6: ="Input: " & CHAR(10) & $B6 & REPT(CHAR(10), 2 ) & "Requested change: " & CHAR(10) & $C6 -> Input: 2022 Membership fee (Regular member) Requested change: plus 10% of base value
A7: 4 | B7: 2022 Membership fee (Regular member) | C7: minus 10% of base value | E7: ="Input: " & CHAR(10) & $B7 & REPT(CHAR(10), 2 ) & "Requested change: " & CHAR(10) & $C7 -> Input: 2022 Membership fee (Regular member) Requested change: minus 10% of base value
A8: 5 | B8: Escalation rate of membership fees | C8: plus 50 basis points (e.g. from 4.00% up to 4.50%) | E8: ="Input: " & CHAR(10) & $B8 & REPT(CHAR(10), 2 ) & "Requested change: " & CHAR(10) & $C8 -> Input: Escalation rate of membership fees Requested change: plus 50 basis points (e.g. from 4.00% up to 4.50%)
A9: 6 | B9: Escalation rate of membership fees | C9: minus 50 basis points | E9: ="Input: " & CHAR(10) & $B9 & REPT(CHAR(10), 2 ) & "Requested change: " & CHAR(10) & $C9 -> Input: Escalation rate of membership fees Requested change: minus 50 basis points
A10: 7 | B10: Number of Regular members at start of 2022 | C10: plus 50 people from base value | E10: ="Input: " & CHAR(10) & $B10 & REPT(CHAR(10), 2 ) & "Requested change: " & CHAR(10) & $C10 -> Input: Number of Regular members at start of 2022 Requested change: plus 50 people from base value
A11: 8 | B11: Number of Regular members at start of 2022 | C11: minus 50 people from base value | E11: ="Input: " & CHAR(10) & $B11 & REPT(CHAR(10), 2 ) & "Requested change: " & CHAR(10) & $C11 -> Input: Number of Regular members at start of 2022 Requested change: minus 50 people from base value
A12: 9 | B12: Increase in Casual Visit Prices each year | C12: plus 50 basis points | E12: ="Input: " & CHAR(10) & $B12 & REPT(CHAR(10), 2 ) & "Requested change: " & CHAR(10) & $C12 -> Input: Increase in Casual Visit Prices each year Requested change: plus 50 basis points
A13: 10 | B13: Increase in Casual Visit Prices each year | C13: minus 50 basis points | E13: ="Input: " & CHAR(10) & $B13 & REPT(CHAR(10), 2 ) & "Requested change: " & CHAR(10) & $C13 -> Input: Increase in Casual Visit Prices each year Requested change: minus 50 basis points
A14: 11 | B14: Year on Year change to Regular Members | C14: plus 50 basis points to all years (excluding 2022) | E14: ="Input: " & CHAR(10) & $B14 & REPT(CHAR(10), 2 ) & "Requested change: " & CHAR(10) & $C14 -> Input: Year on Year change to Regular Members Requested change: plus 50 basis points to all years (excluding 2022)
A15: 12 | B15: Year on Year change to Ordinary Casual Visits | C15: plus 50 basis points to all years (excluding 2022) | E15: ="Input: " & CHAR(10) & $B15 & REPT(CHAR(10), 2 ) & "Requested change: " & CHAR(10) & $C15 -> Input: Year on Year change to Ordinary Casual Visits Requested change: plus 50 basis points to all years (excluding 2022)
... A27: 24 | B27: Time of Sale of Business | C27: bring forward to end of 2024 | E27: ="Input: " & CHAR(10) & $B27 & REPT(CHAR(10), 2 ) & "Requested change: " & CHAR(10) & $C27 -> Input: Time of Sale of Business Requested change: bring forward to end of 2024
B29: Output to examine for each sensitivity
A30: 1 | B30: Equity IRR
A33: Scenarios
B34: Description
A35: 1 | B35: Change the escalation rate of regular membership fees from 4.00% to 3.00%, and add 1.00% to the Regular members YoY growth for each of 2023, 2024, 2025 and 2026.
A36: 2 | B36: Increase the Casual Visit Ordinary 2022 price to $30.00, and decrease the number of 2022 Ordinary Casual visits from 5,000 to 4,500.
A37: 3 | B37: Increase Fixed Expenses in 2022 to $420,000, and increase the number of 2022 Ordinary Casual visits from 5,000 to 6,000. Increase the # of Friends of Members Casuals visits to 13 per member per year.
A38: 4 | B38: Perform a larger refurbishment that costs 800,000, still with 400,000 debt funded and the remainder equity funded. Change the 2027 YoY regular member growth to 22%, and the 2027 YoY Casual Visit growth to 12%.
A39: 5 | B39: At the start of 2023, convert all Foundation Members to Regular Members. Assume that 20% will quit the gym in protest, and 80% will convert. (This may require some logic changes to the model.)
B41: Key Outputs to examine for each scenario
A42: 1 | B42: Equity IRR
A43: 2 | B43: Net Sale Proceeds
A44: 3 | B44: Total EBITDA (sum over all years)
A45: 4 | B45: Total Revenues
