Workbook
Name company: CaseData!$L$9
Name end_date: CaseData!$N$7
Name months: Calculations!$F$10
Name start_date: CaseData!$L$6
Name topic: "CFM Topic: " & CaseData!$L$10

Sheet Calculations
A1: {=company} -> United Landlords Ltd
A2: {=topic} -> CFM Topic: Timing flexibility
A3: CALCULATIONS SCHEDULE | F3: Constant | G3: Unit | H3: Total | J3: {=_xlfn.ANCHORARRAY( J11)} -> 44592 | K3: 44620 | L3: 44651 | M3: 44681 | N3: 44712 | O3: 44742 | P3: 44773 | Q3: 44804 | R3: 44834 | S3: 44865 | T3: 44895 | U3: 44926 | V3: 44957 | W3: 44985 | X3: 45016 | Y3: 45046 | Z3: 45077 | AA3: 45107 | AB3: 45138 | AC3: 45169 | AD3: 45199 | AE3: 45230 | AF3: 45260 | AG3: 45291 | AH3: 45322 | AI3: 45351 | AJ3: 45382 | AK3: 45412 | AL3: 45443 | AM3: 45473 | AN3: 45504 | AO3: 45535 | AP3: 45565 | AQ3: 45596 | AR3: 45626 | AS3: 45657 | AT3: 45688 | AU3: 45716 | AV3: 45747 | AW3: 45777 | AX3: 45808 | AY3: 45838 | AZ3: 45869 | BA3: 45900 | BB3: 45930 | BC3: 45961 | BD3: 45991 | BE3: 46022 | BF3: 46053 | BG3: 46081 | BH3: 46112 | BI3: 46142 | BJ3: 46173 | BK3: 46203 | BL3: 46234 | BM3: 46265 | BN3: 46295 | BO3: 46326 | BP3: 46356 | BQ3: 46387 | BR3: 46418 | BS3: 46446 | BT3: 46477 | BU3: 46507 | BV3: 46538 | BW3: 46568 | BX3: 46599 | BY3: 46630 | BZ3: 46660 | CA3: 46691 | CB3: 46721 | CC3: 46752 | CD3: 46783 | CE3: 46812 | CF3: 46843 | CG3: 46873 | CH3: 46904 | CI3: 46934 | CJ3: 46965 | CK3: 46996 | CL3: 47026 | CM3: 47057 | CN3: 47087 | CO3: 47118 | CP3: 47149 | CQ3: 47177 | CR3: 47208 | CS3: 47238 | CT3: 47269 | CU3: 47299 | CV3: 47330 | CW3: 47361 | CX3: 47391 | CY3: 47422 | CZ3: 47452 | DA3: 47483 | DB3: 47514 | DC3: 47542 | DD3: 47573 | DE3: 47603 | DF3: 47634 | DG3: 47664 | DH3: 47695 | DI3: 47726 | DJ3: 47756 | DK3: 47787 | DL3: 47817 | DM3: 47848 | DN3: 47879 | DO3: 47907 | DP3: 47938 | DQ3: 47968 | DR3: 47999 | DS3: 48029 | DT3: 48060 | DU3: 48091 | DV3: 48121 | DW3: 48152 | DX3: 48182 | DY3: 48213
A5: Model technical inputs
E7: Model start date | F7: =start_date -> 44562 | G7: date
E8: Model end date | F8: =end_date -> 48213 | G8: date
E9: Delay in project start | F9: 0 | G9: years
E10: Periods | F10: =( VALUE(F8)-VALUE(F7) ) / 365 * 12 -> 120.03288 | G10: months
E11: Model timeline | G11: date | J11: {=EOMONTH( start_date, _xlfn.SEQUENCE( 1, months, 0, 1 ) )} -> 44592 | K11: 44620 | L11: 44651 | M11: 44681 | N11: 44712 | O11: 44742 | P11: 44773 | Q11: 44804 | R11: 44834 | S11: 44865 | T11: 44895 | U11: 44926 | V11: 44957 | W11: 44985 | X11: 45016 | Y11: 45046 | Z11: 45077 | AA11: 45107 | AB11: 45138 | AC11: 45169 | AD11: 45199 | AE11: 45230 | AF11: 45260 | AG11: 45291 | AH11: 45322 | AI11: 45351 | AJ11: 45382 | AK11: 45412 | AL11: 45443 | AM11: 45473 | AN11: 45504 | AO11: 45535 | AP11: 45565 | AQ11: 45596 | AR11: 45626 | AS11: 45657 | AT11: 45688 | AU11: 45716 | AV11: 45747 | AW11: 45777 | AX11: 45808 | AY11: 45838 | AZ11: 45869 | BA11: 45900 | BB11: 45930 | BC11: 45961 | BD11: 45991 | BE11: 46022 | BF11: 46053 | BG11: 46081 | BH11: 46112 | BI11: 46142 | BJ11: 46173 | BK11: 46203 | BL11: 46234 | BM11: 46265 | BN11: 46295 | BO11: 46326 | BP11: 46356 | BQ11: 46387 | BR11: 46418 | BS11: 46446 | BT11: 46477 | BU11: 46507 | BV11: 46538 | BW11: 46568 | BX11: 46599 | BY11: 46630 | BZ11: 46660 | CA11: 46691 | CB11: 46721 | CC11: 46752 | CD11: 46783 | CE11: 46812 | CF11: 46843 | CG11: 46873 | CH11: 46904 | CI11: 46934 | CJ11: 46965 | CK11: 46996 | CL11: 47026 | CM11: 47057 | CN11: 47087 | CO11: 47118 | CP11: 47149 | CQ11: 47177 | CR11: 47208 | CS11: 47238 | CT11: 47269 | CU11: 47299 | CV11: 47330 | CW11: 47361 | CX11: 47391 | CY11: 47422 | CZ11: 47452 | DA11: 47483 | DB11: 47514 | DC11: 47542 | DD11: 47573 | DE11: 47603 | DF11: 47634 | DG11: 47664 | DH11: 47695 | DI11: 47726 | DJ11: 47756 | DK11: 47787 | DL11: 47817 | DM11: 47848 | DN11: 47879 | DO11: 47907 | DP11: 47938 | DQ11: 47968 | DR11: 47999 | DS11: 48029 | DT11: 48060 | DU11: 48091 | DV11: 48121 | DW11: 48152 | DX11: 48182 | DY11: 48213
A13: Existing properties
C15: Rent revenues
C16: (adjusted for inflation and vacancy)
E17: {=INDEX( CaseData!$A$6:$B$10,, 1 )} -> Property A | G17: USD | H17: {=_xlfn.BYROW(_xlfn.ANCHORARRAY( J17), _xleta.SUM )} -> 1.1037505e+08 | J17: {=_xlfn.LET( _xlpm.timeline,_xlfn.ANCHORARRAY( $J$3), _xlpm.inflation_flag, IF( MONTH( _xlpm.timeline ) = 1, 1, 0 ), _xlpm.inflation_data, CaseData!$J$15:$M$24, _xlpm.annual_rate, _xlfn.XLOOKUP( YEAR( _xlpm.timeline ), INDEX( _xlpm.inflation_data,, 1 ), INDEX( _xlpm.inflation_data,, 2 ) ), _xlpm.effective_step, _xlpm.inflation_flag * _xlpm.annual_rate, _xlpm.inflation_factor, _xlfn.SCAN( 1, _xlpm.effective_step, _xlfn.LAMBDA(_xlpm.prev,_xlpm.step, IF( _xlpm.step = 0, _xlpm.prev, _xlpm.prev * ( 1 + _xlpm.step ) ) ) ), _xlpm.property_data, CaseData!$A$6:$D$10, _xlpm.property_rows, INDEX( _xlpm.property_data, 0, 1 ), _xlpm.current_property, INDEX(_xlfn.ANCHORARRAY( E17),, 1 ), _xlpm.vacancy_factor, 1 - INDEX( _xlpm.property_data, MATCH( _xlpm.current_property, _xlpm.property_rows, 0 ), 3 ), _xlpm.rent, INDEX( _xlpm.property_data,, 2 ), _xlpm.rent * _xlpm.inflation_factor * _xlpm.vacancy_factor )} -> 789022.5 | K17: 789022.5 | L17: 789022.5 | M17: 789022.5 | N17: 789022.5 | O17: 789022.5 | P17: 789022.5 | Q17: 789022.5 | R17: 789022.5 | S17: 789022.5 | T17: 789022.5 | U17: 789022.5 | V17: 824528.51 | W17: 824528.51 | X17: 824528.51 | Y17: 824528.51 | Z17: 824528.51 | AA17: 824528.51 | AB17: 824528.51 | AC17: 824528.51 | AD17: 824528.51 | AE17: 824528.51 | AF17: 824528.51 | AG17: 824528.51 | AH17: 857509.65 | AI17: 857509.65 | AJ17: 857509.65 | AK17: 857509.65 | AL17: 857509.65 | AM17: 857509.65 | AN17: 857509.65 | AO17: 857509.65 | AP17: 857509.65 | AQ17: 857509.65 | AR17: 857509.65 | AS17: 857509.65 | AT17: 887522.49 | AU17: 887522.49 | AV17: 887522.49 | AW17: 887522.49 | AX17: 887522.49 | AY17: 887522.49 | AZ17: 887522.49 | BA17: 887522.49 | BB17: 887522.49 | BC17: 887522.49 | BD17: 887522.49 | BE17: 887522.49 | BF17: 914148.17 | BG17: 914148.17 | BH17: 914148.17 | BI17: 914148.17 | BJ17: 914148.17 | BK17: 914148.17 | BL17: 914148.17 | BM17: 914148.17 | BN17: 914148.17 | BO17: 914148.17 | BP17: 914148.17 | BQ17: 914148.17 | BR17: 937001.87 | BS17: 937001.87 | BT17: 937001.87 | BU17: 937001.87 | BV17: 937001.87 | BW17: 937001.87 | BX17: 937001.87 | BY17: 937001.87 | BZ17: 937001.87 | CA17: 937001.87 | CB17: 937001.87 | CC17: 937001.87 | CD17: 960426.92 | CE17: 960426.92 | CF17: 960426.92 | CG17: 960426.92 | CH17: 960426.92 | CI17: 960426.92 | CJ17: 960426.92 | CK17: 960426.92 | CL17: 960426.92 | CM17: 960426.92 | CN17: 960426.92 | CO17: 960426.92 | CP17: 984437.59 | CQ17: 984437.59 | CR17: 984437.59 | CS17: 984437.59 | CT17: 984437.59 | CU17: 984437.59 | CV17: 984437.59 | CW17: 984437.59 | CX17: 984437.59 | CY17: 984437.59 | CZ17: 984437.59 | DA17: 984437.59 | DB17: 1009048.5 | DC17: 1009048.5 | DD17: 1009048.5 | DE17: 1009048.5 | DF17: 1009048.5 | DG17: 1009048.5 | DH17: 1009048.5 | DI17: 1009048.5 | DJ17: 1009048.5 | DK17: 1009048.5 | DL17: 1009048.5 | DM17: 1009048.5 | DN17: 1034274.7 | DO17: 1034274.7 | DP17: 1034274.7 | DQ17: 1034274.7 | DR17: 1034274.7 | DS17: 1034274.7 | DT17: 1034274.7 | DU17: 1034274.7 | DV17: 1034274.7 | DW17: 1034274.7 | DX17: 1034274.7 | DY17: 1034274.7
E18: Property B | G18: USD | H18: 61197234 | J18: 437472 | K18: 437472 | L18: 437472 | M18: 437472 | N18: 437472 | O18: 437472 | P18: 437472 | Q18: 437472 | R18: 437472 | S18: 437472 | T18: 437472 | U18: 437472 | V18: 457158.24 | W18: 457158.24 | X18: 457158.24 | Y18: 457158.24 | Z18: 457158.24 | AA18: 457158.24 | AB18: 457158.24 | AC18: 457158.24 | AD18: 457158.24 | AE18: 457158.24 | AF18: 457158.24 | AG18: 457158.24 | AH18: 475444.57 | AI18: 475444.57 | AJ18: 475444.57 | AK18: 475444.57 | AL18: 475444.57 | AM18: 475444.57 | AN18: 475444.57 | AO18: 475444.57 | AP18: 475444.57 | AQ18: 475444.57 | AR18: 475444.57 | AS18: 475444.57 | AT18: 492085.13 | AU18: 492085.13 | AV18: 492085.13 | AW18: 492085.13 | AX18: 492085.13 | AY18: 492085.13 | AZ18: 492085.13 | BA18: 492085.13 | BB18: 492085.13 | BC18: 492085.13 | BD18: 492085.13 | BE18: 492085.13 | BF18: 506847.68 | BG18: 506847.68 | BH18: 506847.68 | BI18: 506847.68 | BJ18: 506847.68 | BK18: 506847.68 | BL18: 506847.68 | BM18: 506847.68 | BN18: 506847.68 | BO18: 506847.68 | BP18: 506847.68 | BQ18: 506847.68 | BR18: 519518.88 | BS18: 519518.88 | BT18: 519518.88 | BU18: 519518.88 | BV18: 519518.88 | BW18: 519518.88 | BX18: 519518.88 | BY18: 519518.88 | BZ18: 519518.88 | CA18: 519518.88 | CB18: 519518.88 | CC18: 519518.88 | CD18: 532506.85 | CE18: 532506.85 | CF18: 532506.85 | CG18: 532506.85 | CH18: 532506.85 | CI18: 532506.85 | CJ18: 532506.85 | CK18: 532506.85 | CL18: 532506.85 | CM18: 532506.85 | CN18: 532506.85 | CO18: 532506.85 | CP18: 545819.52 | CQ18: 545819.52 | CR18: 545819.52 | CS18: 545819.52 | CT18: 545819.52 | CU18: 545819.52 | CV18: 545819.52 | CW18: 545819.52 | CX18: 545819.52 | CY18: 545819.52 | CZ18: 545819.52 | DA18: 545819.52 | DB18: 559465.01 | DC18: 559465.01 | DD18: 559465.01 | DE18: 559465.01 | DF18: 559465.01 | DG18: 559465.01 | DH18: 559465.01 | DI18: 559465.01 | DJ18: 559465.01 | DK18: 559465.01 | DL18: 559465.01 | DM18: 559465.01 | DN18: 573451.63 | DO18: 573451.63 | DP18: 573451.63 | DQ18: 573451.63 | DR18: 573451.63 | DS18: 573451.63 | DT18: 573451.63 | DU18: 573451.63 | DV18: 573451.63 | DW18: 573451.63 | DX18: 573451.63 | DY18: 573451.63
E19: Property C | G19: USD | H19: 94715880 | J19: 677082 | K19: 677082 | L19: 677082 | M19: 677082 | N19: 677082 | O19: 677082 | P19: 677082 | Q19: 677082 | R19: 677082 | S19: 677082 | T19: 677082 | U19: 677082 | V19: 707550.69 | W19: 707550.69 | X19: 707550.69 | Y19: 707550.69 | Z19: 707550.69 | AA19: 707550.69 | AB19: 707550.69 | AC19: 707550.69 | AD19: 707550.69 | AE19: 707550.69 | AF19: 707550.69 | AG19: 707550.69 | AH19: 735852.72 | AI19: 735852.72 | AJ19: 735852.72 | AK19: 735852.72 | AL19: 735852.72 | AM19: 735852.72 | AN19: 735852.72 | AO19: 735852.72 | AP19: 735852.72 | AQ19: 735852.72 | AR19: 735852.72 | AS19: 735852.72 | AT19: 761607.56 | AU19: 761607.56 | AV19: 761607.56 | AW19: 761607.56 | AX19: 761607.56 | AY19: 761607.56 | AZ19: 761607.56 | BA19: 761607.56 | BB19: 761607.56 | BC19: 761607.56 | BD19: 761607.56 | BE19: 761607.56 | BF19: 784455.79 | BG19: 784455.79 | BH19: 784455.79 | BI19: 784455.79 | BJ19: 784455.79 | BK19: 784455.79 | BL19: 784455.79 | BM19: 784455.79 | BN19: 784455.79 | BO19: 784455.79 | BP19: 784455.79 | BQ19: 784455.79 | BR19: 804067.18 | BS19: 804067.18 | BT19: 804067.18 | BU19: 804067.18 | BV19: 804067.18 | BW19: 804067.18 | BX19: 804067.18 | BY19: 804067.18 | BZ19: 804067.18 | CA19: 804067.18 | CB19: 804067.18 | CC19: 804067.18 | CD19: 824168.86 | CE19: 824168.86 | CF19: 824168.86 | CG19: 824168.86 | CH19: 824168.86 | CI19: 824168.86 | CJ19: 824168.86 | CK19: 824168.86 | CL19: 824168.86 | CM19: 824168.86 | CN19: 824168.86 | CO19: 824168.86 | CP19: 844773.09 | CQ19: 844773.09 | CR19: 844773.09 | CS19: 844773.09 | CT19: 844773.09 | CU19: 844773.09 | CV19: 844773.09 | CW19: 844773.09 | CX19: 844773.09 | CY19: 844773.09 | CZ19: 844773.09 | DA19: 844773.09 | DB19: 865892.41 | DC19: 865892.41 | DD19: 865892.41 | DE19: 865892.41 | DF19: 865892.41 | DG19: 865892.41 | DH19: 865892.41 | DI19: 865892.41 | DJ19: 865892.41 | DK19: 865892.41 | DL19: 865892.41 | DM19: 865892.41 | DN19: 887539.72 | DO19: 887539.72 | DP19: 887539.72 | DQ19: 887539.72 | DR19: 887539.72 | DS19: 887539.72 | DT19: 887539.72 | DU19: 887539.72 | DV19: 887539.72 | DW19: 887539.72 | DX19: 887539.72 | DY19: 887539.72
E20: Property D | G20: USD | H20: 1.040635e+08 | J20: 743904 | K20: 743904 | L20: 743904 | M20: 743904 | N20: 743904 | O20: 743904 | P20: 743904 | Q20: 743904 | R20: 743904 | S20: 743904 | T20: 743904 | U20: 743904 | V20: 777379.68 | W20: 777379.68 | X20: 777379.68 | Y20: 777379.68 | Z20: 777379.68 | AA20: 777379.68 | AB20: 777379.68 | AC20: 777379.68 | AD20: 777379.68 | AE20: 777379.68 | AF20: 777379.68 | AG20: 777379.68 | AH20: 808474.87 | AI20: 808474.87 | AJ20: 808474.87 | AK20: 808474.87 | AL20: 808474.87 | AM20: 808474.87 | AN20: 808474.87 | AO20: 808474.87 | AP20: 808474.87 | AQ20: 808474.87 | AR20: 808474.87 | AS20: 808474.87 | AT20: 836771.49 | AU20: 836771.49 | AV20: 836771.49 | AW20: 836771.49 | AX20: 836771.49 | AY20: 836771.49 | AZ20: 836771.49 | BA20: 836771.49 | BB20: 836771.49 | BC20: 836771.49 | BD20: 836771.49 | BE20: 836771.49 | BF20: 861874.63 | BG20: 861874.63 | BH20: 861874.63 | BI20: 861874.63 | BJ20: 861874.63 | BK20: 861874.63 | BL20: 861874.63 | BM20: 861874.63 | BN20: 861874.63 | BO20: 861874.63 | BP20: 861874.63 | BQ20: 861874.63 | BR20: 883421.5 | BS20: 883421.5 | BT20: 883421.5 | BU20: 883421.5 | BV20: 883421.5 | BW20: 883421.5 | BX20: 883421.5 | BY20: 883421.5 | BZ20: 883421.5 | CA20: 883421.5 | CB20: 883421.5 | CC20: 883421.5 | CD20: 905507.04 | CE20: 905507.04 | CF20: 905507.04 | CG20: 905507.04 | CH20: 905507.04 | CI20: 905507.04 | CJ20: 905507.04 | CK20: 905507.04 | CL20: 905507.04 | CM20: 905507.04 | CN20: 905507.04 | CO20: 905507.04 | CP20: 928144.71 | CQ20: 928144.71 | CR20: 928144.71 | CS20: 928144.71 | CT20: 928144.71 | CU20: 928144.71 | CV20: 928144.71 | CW20: 928144.71 | CX20: 928144.71 | CY20: 928144.71 | CZ20: 928144.71 | DA20: 928144.71 | DB20: 951348.33 | DC20: 951348.33 | DD20: 951348.33 | DE20: 951348.33 | DF20: 951348.33 | DG20: 951348.33 | DH20: 951348.33 | DI20: 951348.33 | DJ20: 951348.33 | DK20: 951348.33 | DL20: 951348.33 | DM20: 951348.33 | DN20: 975132.04 | DO20: 975132.04 | DP20: 975132.04 | DQ20: 975132.04 | DR20: 975132.04 | DS20: 975132.04 | DT20: 975132.04 | DU20: 975132.04 | DV20: 975132.04 | DW20: 975132.04 | DX20: 975132.04 | DY20: 975132.04
E21: Property E | G21: USD | H21: 78789382 | J21: 563230.5 | K21: 563230.5 | L21: 563230.5 | M21: 563230.5 | N21: 563230.5 | O21: 563230.5 | P21: 563230.5 | Q21: 563230.5 | R21: 563230.5 | S21: 563230.5 | T21: 563230.5 | U21: 563230.5 | V21: 588575.87 | W21: 588575.87 | X21: 588575.87 | Y21: 588575.87 | Z21: 588575.87 | AA21: 588575.87 | AB21: 588575.87 | AC21: 588575.87 | AD21: 588575.87 | AE21: 588575.87 | AF21: 588575.87 | AG21: 588575.87 | AH21: 612118.91 | AI21: 612118.91 | AJ21: 612118.91 | AK21: 612118.91 | AL21: 612118.91 | AM21: 612118.91 | AN21: 612118.91 | AO21: 612118.91 | AP21: 612118.91 | AQ21: 612118.91 | AR21: 612118.91 | AS21: 612118.91 | AT21: 633543.07 | AU21: 633543.07 | AV21: 633543.07 | AW21: 633543.07 | AX21: 633543.07 | AY21: 633543.07 | AZ21: 633543.07 | BA21: 633543.07 | BB21: 633543.07 | BC21: 633543.07 | BD21: 633543.07 | BE21: 633543.07 | BF21: 652549.36 | BG21: 652549.36 | BH21: 652549.36 | BI21: 652549.36 | BJ21: 652549.36 | BK21: 652549.36 | BL21: 652549.36 | BM21: 652549.36 | BN21: 652549.36 | BO21: 652549.36 | BP21: 652549.36 | BQ21: 652549.36 | BR21: 668863.1 | BS21: 668863.1 | BT21: 668863.1 | BU21: 668863.1 | BV21: 668863.1 | BW21: 668863.1 | BX21: 668863.1 | BY21: 668863.1 | BZ21: 668863.1 | CA21: 668863.1 | CB21: 668863.1 | CC21: 668863.1 | CD21: 685584.67 | CE21: 685584.67 | CF21: 685584.67 | CG21: 685584.67 | CH21: 685584.67 | CI21: 685584.67 | CJ21: 685584.67 | CK21: 685584.67 | CL21: 685584.67 | CM21: 685584.67 | CN21: 685584.67 | CO21: 685584.67 | CP21: 702724.29 | CQ21: 702724.29 | CR21: 702724.29 | CS21: 702724.29 | CT21: 702724.29 | CU21: 702724.29 | CV21: 702724.29 | CW21: 702724.29 | CX21: 702724.29 | CY21: 702724.29 | CZ21: 702724.29 | DA21: 702724.29 | DB21: 720292.4 | DC21: 720292.4 | DD21: 720292.4 | DE21: 720292.4 | DF21: 720292.4 | DG21: 720292.4 | DH21: 720292.4 | DI21: 720292.4 | DJ21: 720292.4 | DK21: 720292.4 | DL21: 720292.4 | DM21: 720292.4 | DN21: 738299.71 | DO21: 738299.71 | DP21: 738299.71 | DQ21: 738299.71 | DR21: 738299.71 | DS21: 738299.71 | DT21: 738299.71 | DU21: 738299.71 | DV21: 738299.71 | DW21: 738299.71 | DX21: 738299.71 | DY21: 738299.71
E22: Rent revenue from existing properties | G22: USD | H22: {=_xlfn.BYROW(_xlfn.ANCHORARRAY( J22), _xleta.SUM )} -> 4.4914105e+08 | J22: {=_xlfn.BYCOL(_xlfn.ANCHORARRAY( J17), _xleta.SUM )} -> 3210711 | K22: 3210711 | L22: 3210711 | M22: 3210711 | N22: 3210711 | O22: 3210711 | P22: 3210711 | Q22: 3210711 | R22: 3210711 | S22: 3210711 | T22: 3210711 | U22: 3210711 | V22: 3355193 | W22: 3355193 | X22: 3355193 | Y22: 3355193 | Z22: 3355193 | AA22: 3355193 | AB22: 3355193 | AC22: 3355193 | AD22: 3355193 | AE22: 3355193 | AF22: 3355193 | AG22: 3355193 | AH22: 3489400.7 | AI22: 3489400.7 | AJ22: 3489400.7 | AK22: 3489400.7 | AL22: 3489400.7 | AM22: 3489400.7 | AN22: 3489400.7 | AO22: 3489400.7 | AP22: 3489400.7 | AQ22: 3489400.7 | AR22: 3489400.7 | AS22: 3489400.7 | AT22: 3611529.7 | AU22: 3611529.7 | AV22: 3611529.7 | AW22: 3611529.7 | AX22: 3611529.7 | AY22: 3611529.7 | AZ22: 3611529.7 | BA22: 3611529.7 | BB22: 3611529.7 | BC22: 3611529.7 | BD22: 3611529.7 | BE22: 3611529.7 | BF22: 3719875.6 | BG22: 3719875.6 | BH22: 3719875.6 | BI22: 3719875.6 | BJ22: 3719875.6 | BK22: 3719875.6 | BL22: 3719875.6 | BM22: 3719875.6 | BN22: 3719875.6 | BO22: 3719875.6 | BP22: 3719875.6 | BQ22: 3719875.6 | BR22: 3812872.5 | BS22: 3812872.5 | BT22: 3812872.5 | BU22: 3812872.5 | BV22: 3812872.5 | BW22: 3812872.5 | BX22: 3812872.5 | BY22: 3812872.5 | BZ22: 3812872.5 | CA22: 3812872.5 | CB22: 3812872.5 | CC22: 3812872.5 | CD22: 3908194.3 | CE22: 3908194.3 | CF22: 3908194.3 | CG22: 3908194.3 | CH22: 3908194.3 | CI22: 3908194.3 | CJ22: 3908194.3 | CK22: 3908194.3 | CL22: 3908194.3 | CM22: 3908194.3 | CN22: 3908194.3 | CO22: 3908194.3 | CP22: 4005899.2 | CQ22: 4005899.2 | CR22: 4005899.2 | CS22: 4005899.2 | CT22: 4005899.2 | CU22: 4005899.2 | CV22: 4005899.2 | CW22: 4005899.2 | CX22: 4005899.2 | CY22: 4005899.2 | CZ22: 4005899.2 | DA22: 4005899.2 | DB22: 4106046.7 | DC22: 4106046.7 | DD22: 4106046.7 | DE22: 4106046.7 | DF22: 4106046.7 | DG22: 4106046.7 | DH22: 4106046.7 | DI22: 4106046.7 | DJ22: 4106046.7 | DK22: 4106046.7 | DL22: 4106046.7 | DM22: 4106046.7 | DN22: 4208697.8 | DO22: 4208697.8 | DP22: 4208697.8 | DQ22: 4208697.8 | DR22: 4208697.8 | DS22: 4208697.8 | DT22: 4208697.8 | DU22: 4208697.8 | DV22: 4208697.8 | DW22: 4208697.8 | DX22: 4208697.8 | DY22: 4208697.8
C25: OPEX
C26: (adjusted for inflation)
E27: {=INDEX( CaseData!$A$6:$D$10,, 1 )} -> Property A | G27: USD | H27: {=_xlfn.BYROW(_xlfn.ANCHORARRAY( J27), _xleta.SUM )} -> 27250266 | J27: {=_xlfn.LET( _xlpm.timeline,_xlfn.ANCHORARRAY( $J$3), _xlpm.inflation_flag, IF( MONTH( _xlpm.timeline ) = 1, 1, 0 ), _xlpm.inflation_data, CaseData!$J$15:$M$24, _xlpm.annual_rate, _xlfn.XLOOKUP( YEAR( _xlpm.timeline ), INDEX( _xlpm.inflation_data,, 1 ), INDEX( _xlpm.inflation_data,, 3 ) ), _xlpm.effective_step, _xlpm.inflation_flag * _xlpm.annual_rate, _xlpm.inflation_factor, _xlfn.SCAN( 1, _xlpm.effective_step, _xlfn.LAMBDA(_xlpm.prev,_xlpm.step, IF( _xlpm.step = 0, _xlpm.prev, _xlpm.prev * ( 1 + _xlpm.step ) ) ) ), _xlpm.property_data, CaseData!$A$6:$D$10, _xlpm.opex, INDEX( _xlpm.property_data,, 4 ), _xlpm.opex * _xlpm.inflation_factor )} -> 202693.75 | K27: 202693.75 | L27: 202693.75 | M27: 202693.75 | N27: 202693.75 | O27: 202693.75 | P27: 202693.75 | Q27: 202693.75 | R27: 202693.75 | S27: 202693.75 | T27: 202693.75 | U27: 202693.75 | V27: 207761.09 | W27: 207761.09 | X27: 207761.09 | Y27: 207761.09 | Z27: 207761.09 | AA27: 207761.09 | AB27: 207761.09 | AC27: 207761.09 | AD27: 207761.09 | AE27: 207761.09 | AF27: 207761.09 | AG27: 207761.09 | AH27: 212955.12 | AI27: 212955.12 | AJ27: 212955.12 | AK27: 212955.12 | AL27: 212955.12 | AM27: 212955.12 | AN27: 212955.12 | AO27: 212955.12 | AP27: 212955.12 | AQ27: 212955.12 | AR27: 212955.12 | AS27: 212955.12 | AT27: 218279 | AU27: 218279 | AV27: 218279 | AW27: 218279 | AX27: 218279 | AY27: 218279 | AZ27: 218279 | BA27: 218279 | BB27: 218279 | BC27: 218279 | BD27: 218279 | BE27: 218279 | BF27: 223735.97 | BG27: 223735.97 | BH27: 223735.97 | BI27: 223735.97 | BJ27: 223735.97 | BK27: 223735.97 | BL27: 223735.97 | BM27: 223735.97 | BN27: 223735.97 | BO27: 223735.97 | BP27: 223735.97 | BQ27: 223735.97 | BR27: 229329.37 | BS27: 229329.37 | BT27: 229329.37 | BU27: 229329.37 | BV27: 229329.37 | BW27: 229329.37 | BX27: 229329.37 | BY27: 229329.37 | BZ27: 229329.37 | CA27: 229329.37 | CB27: 229329.37 | CC27: 229329.37 | CD27: 235062.61 | CE27: 235062.61 | CF27: 235062.61 | CG27: 235062.61 | CH27: 235062.61 | CI27: 235062.61 | CJ27: 235062.61 | CK27: 235062.61 | CL27: 235062.61 | CM27: 235062.61 | CN27: 235062.61 | CO27: 235062.61 | CP27: 240939.17 | CQ27: 240939.17 | CR27: 240939.17 | CS27: 240939.17 | CT27: 240939.17 | CU27: 240939.17 | CV27: 240939.17 | CW27: 240939.17 | CX27: 240939.17 | CY27: 240939.17 | CZ27: 240939.17 | DA27: 240939.17 | DB27: 246962.65 | DC27: 246962.65 | DD27: 246962.65 | DE27: 246962.65 | DF27: 246962.65 | DG27: 246962.65 | DH27: 246962.65 | DI27: 246962.65 | DJ27: 246962.65 | DK27: 246962.65 | DL27: 246962.65 | DM27: 246962.65 | DN27: 253136.72 | DO27: 253136.72 | DP27: 253136.72 | DQ27: 253136.72 | DR27: 253136.72 | DS27: 253136.72 | DT27: 253136.72 | DU27: 253136.72 | DV27: 253136.72 | DW27: 253136.72 | DX27: 253136.72 | DY27: 253136.72
E28: Property B | G28: USD | H28: 21607290 | J28: 160720 | K28: 160720 | L28: 160720 | M28: 160720 | N28: 160720 | O28: 160720 | P28: 160720 | Q28: 160720 | R28: 160720 | S28: 160720 | T28: 160720 | U28: 160720 | V28: 164738 | W28: 164738 | X28: 164738 | Y28: 164738 | Z28: 164738 | AA28: 164738 | AB28: 164738 | AC28: 164738 | AD28: 164738 | AE28: 164738 | AF28: 164738 | AG28: 164738 | AH28: 168856.45 | AI28: 168856.45 | AJ28: 168856.45 | AK28: 168856.45 | AL28: 168856.45 | AM28: 168856.45 | AN28: 168856.45 | AO28: 168856.45 | AP28: 168856.45 | AQ28: 168856.45 | AR28: 168856.45 | AS28: 168856.45 | AT28: 173077.86 | AU28: 173077.86 | AV28: 173077.86 | AW28: 173077.86 | AX28: 173077.86 | AY28: 173077.86 | AZ28: 173077.86 | BA28: 173077.86 | BB28: 173077.86 | BC28: 173077.86 | BD28: 173077.86 | BE28: 173077.86 | BF28: 177404.81 | BG28: 177404.81 | BH28: 177404.81 | BI28: 177404.81 | BJ28: 177404.81 | BK28: 177404.81 | BL28: 177404.81 | BM28: 177404.81 | BN28: 177404.81 | BO28: 177404.81 | BP28: 177404.81 | BQ28: 177404.81 | BR28: 181839.93 | BS28: 181839.93 | BT28: 181839.93 | BU28: 181839.93 | BV28: 181839.93 | BW28: 181839.93 | BX28: 181839.93 | BY28: 181839.93 | BZ28: 181839.93 | CA28: 181839.93 | CB28: 181839.93 | CC28: 181839.93 | CD28: 186385.93 | CE28: 186385.93 | CF28: 186385.93 | CG28: 186385.93 | CH28: 186385.93 | CI28: 186385.93 | CJ28: 186385.93 | CK28: 186385.93 | CL28: 186385.93 | CM28: 186385.93 | CN28: 186385.93 | CO28: 186385.93 | CP28: 191045.57 | CQ28: 191045.57 | CR28: 191045.57 | CS28: 191045.57 | CT28: 191045.57 | CU28: 191045.57 | CV28: 191045.57 | CW28: 191045.57 | CX28: 191045.57 | CY28: 191045.57 | CZ28: 191045.57 | DA28: 191045.57 | DB28: 195821.71 | DC28: 195821.71 | DD28: 195821.71 | DE28: 195821.71 | DF28: 195821.71 | DG28: 195821.71 | DH28: 195821.71 | DI28: 195821.71 | DJ28: 195821.71 | DK28: 195821.71 | DL28: 195821.71 | DM28: 195821.71 | DN28: 200717.26 | DO28: 200717.26 | DP28: 200717.26 | DQ28: 200717.26 | DR28: 200717.26 | DS28: 200717.26 | DT28: 200717.26 | DU28: 200717.26 | DV28: 200717.26 | DW28: 200717.26 | DX28: 200717.26 | DY28: 200717.26
E29: Property C | G29: USD | H29: 23632974 | J29: 175787.5 | K29: 175787.5 | L29: 175787.5 | M29: 175787.5 | N29: 175787.5 | O29: 175787.5 | P29: 175787.5 | Q29: 175787.5 | R29: 175787.5 | S29: 175787.5 | T29: 175787.5 | U29: 175787.5 | V29: 180182.19 | W29: 180182.19 | X29: 180182.19 | Y29: 180182.19 | Z29: 180182.19 | AA29: 180182.19 | AB29: 180182.19 | AC29: 180182.19 | AD29: 180182.19 | AE29: 180182.19 | AF29: 180182.19 | AG29: 180182.19 | AH29: 184686.74 | AI29: 184686.74 | AJ29: 184686.74 | AK29: 184686.74 | AL29: 184686.74 | AM29: 184686.74 | AN29: 184686.74 | AO29: 184686.74 | AP29: 184686.74 | AQ29: 184686.74 | AR29: 184686.74 | AS29: 184686.74 | AT29: 189303.91 | AU29: 189303.91 | AV29: 189303.91 | AW29: 189303.91 | AX29: 189303.91 | AY29: 189303.91 | AZ29: 189303.91 | BA29: 189303.91 | BB29: 189303.91 | BC29: 189303.91 | BD29: 189303.91 | BE29: 189303.91 | BF29: 194036.51 | BG29: 194036.51 | BH29: 194036.51 | BI29: 194036.51 | BJ29: 194036.51 | BK29: 194036.51 | BL29: 194036.51 | BM29: 194036.51 | BN29: 194036.51 | BO29: 194036.51 | BP29: 194036.51 | BQ29: 194036.51 | BR29: 198887.42 | BS29: 198887.42 | BT29: 198887.42 | BU29: 198887.42 | BV29: 198887.42 | BW29: 198887.42 | BX29: 198887.42 | BY29: 198887.42 | BZ29: 198887.42 | CA29: 198887.42 | CB29: 198887.42 | CC29: 198887.42 | CD29: 203859.61 | CE29: 203859.61 | CF29: 203859.61 | CG29: 203859.61 | CH29: 203859.61 | CI29: 203859.61 | CJ29: 203859.61 | CK29: 203859.61 | CL29: 203859.61 | CM29: 203859.61 | CN29: 203859.61 | CO29: 203859.61 | CP29: 208956.1 | CQ29: 208956.1 | CR29: 208956.1 | CS29: 208956.1 | CT29: 208956.1 | CU29: 208956.1 | CV29: 208956.1 | CW29: 208956.1 | CX29: 208956.1 | CY29: 208956.1 | CZ29: 208956.1 | DA29: 208956.1 | DB29: 214180 | DC29: 214180 | DD29: 214180 | DE29: 214180 | DF29: 214180 | DG29: 214180 | DH29: 214180 | DI29: 214180 | DJ29: 214180 | DK29: 214180 | DL29: 214180 | DM29: 214180 | DN29: 219534.5 | DO29: 219534.5 | DP29: 219534.5 | DQ29: 219534.5 | DR29: 219534.5 | DS29: 219534.5 | DT29: 219534.5 | DU29: 219534.5 | DV29: 219534.5 | DW29: 219534.5 | DX29: 219534.5 | DY29: 219534.5
E30: Property D | G30: USD | H30: 28475322 | J30: 211806 | K30: 211806 | L30: 211806 | M30: 211806 | N30: 211806 | O30: 211806 | P30: 211806 | Q30: 211806 | R30: 211806 | S30: 211806 | T30: 211806 | U30: 211806 | V30: 217101.15 | W30: 217101.15 | X30: 217101.15 | Y30: 217101.15 | Z30: 217101.15 | AA30: 217101.15 | AB30: 217101.15 | AC30: 217101.15 | AD30: 217101.15 | AE30: 217101.15 | AF30: 217101.15 | AG30: 217101.15 | AH30: 222528.68 | AI30: 222528.68 | AJ30: 222528.68 | AK30: 222528.68 | AL30: 222528.68 | AM30: 222528.68 | AN30: 222528.68 | AO30: 222528.68 | AP30: 222528.68 | AQ30: 222528.68 | AR30: 222528.68 | AS30: 222528.68 | AT30: 228091.9 | AU30: 228091.9 | AV30: 228091.9 | AW30: 228091.9 | AX30: 228091.9 | AY30: 228091.9 | AZ30: 228091.9 | BA30: 228091.9 | BB30: 228091.9 | BC30: 228091.9 | BD30: 228091.9 | BE30: 228091.9 | BF30: 233794.19 | BG30: 233794.19 | BH30: 233794.19 | BI30: 233794.19 | BJ30: 233794.19 | BK30: 233794.19 | BL30: 233794.19 | BM30: 233794.19 | BN30: 233794.19 | BO30: 233794.19 | BP30: 233794.19 | BQ30: 233794.19 | BR30: 239639.05 | BS30: 239639.05 | BT30: 239639.05 | BU30: 239639.05 | BV30: 239639.05 | BW30: 239639.05 | BX30: 239639.05 | BY30: 239639.05 | BZ30: 239639.05 | CA30: 239639.05 | CB30: 239639.05 | CC30: 239639.05 | CD30: 245630.02 | CE30: 245630.02 | CF30: 245630.02 | CG30: 245630.02 | CH30: 245630.02 | CI30: 245630.02 | CJ30: 245630.02 | CK30: 245630.02 | CL30: 245630.02 | CM30: 245630.02 | CN30: 245630.02 | CO30: 245630.02 | CP30: 251770.77 | CQ30: 251770.77 | CR30: 251770.77 | CS30: 251770.77 | CT30: 251770.77 | CU30: 251770.77 | CV30: 251770.77 | CW30: 251770.77 | CX30: 251770.77 | CY30: 251770.77 | CZ30: 251770.77 | DA30: 251770.77 | DB30: 258065.04 | DC30: 258065.04 | DD30: 258065.04 | DE30: 258065.04 | DF30: 258065.04 | DG30: 258065.04 | DH30: 258065.04 | DI30: 258065.04 | DJ30: 258065.04 | DK30: 258065.04 | DL30: 258065.04 | DM30: 258065.04 | DN30: 264516.67 | DO30: 264516.67 | DP30: 264516.67 | DQ30: 264516.67 | DR30: 264516.67 | DS30: 264516.67 | DT30: 264516.67 | DU30: 264516.67 | DV30: 264516.67 | DW30: 264516.67 | DX30: 264516.67 | DY30: 264516.67
E31: Property E | G31: USD | H31: 24385370 | J31: 181384 | K31: 181384 | L31: 181384 | M31: 181384 | N31: 181384 | O31: 181384 | P31: 181384 | Q31: 181384 | R31: 181384 | S31: 181384 | T31: 181384 | U31: 181384 | V31: 185918.6 | W31: 185918.6 | X31: 185918.6 | Y31: 185918.6 | Z31: 185918.6 | AA31: 185918.6 | AB31: 185918.6 | AC31: 185918.6 | AD31: 185918.6 | AE31: 185918.6 | AF31: 185918.6 | AG31: 185918.6 | AH31: 190566.56 | AI31: 190566.56 | AJ31: 190566.56 | AK31: 190566.56 | AL31: 190566.56 | AM31: 190566.56 | AN31: 190566.56 | AO31: 190566.56 | AP31: 190566.56 | AQ31: 190566.56 | AR31: 190566.56 | AS31: 190566.56 | AT31: 195330.73 | AU31: 195330.73 | AV31: 195330.73 | AW31: 195330.73 | AX31: 195330.73 | AY31: 195330.73 | AZ31: 195330.73 | BA31: 195330.73 | BB31: 195330.73 | BC31: 195330.73 | BD31: 195330.73 | BE31: 195330.73 | BF31: 200214 | BG31: 200214 | BH31: 200214 | BI31: 200214 | BJ31: 200214 | BK31: 200214 | BL31: 200214 | BM31: 200214 | BN31: 200214 | BO31: 200214 | BP31: 200214 | BQ31: 200214 | BR31: 205219.35 | BS31: 205219.35 | BT31: 205219.35 | BU31: 205219.35 | BV31: 205219.35 | BW31: 205219.35 | BX31: 205219.35 | BY31: 205219.35 | BZ31: 205219.35 | CA31: 205219.35 | CB31: 205219.35 | CC31: 205219.35 | CD31: 210349.83 | CE31: 210349.83 | CF31: 210349.83 | CG31: 210349.83 | CH31: 210349.83 | CI31: 210349.83 | CJ31: 210349.83 | CK31: 210349.83 | CL31: 210349.83 | CM31: 210349.83 | CN31: 210349.83 | CO31: 210349.83 | CP31: 215608.58 | CQ31: 215608.58 | CR31: 215608.58 | CS31: 215608.58 | CT31: 215608.58 | CU31: 215608.58 | CV31: 215608.58 | CW31: 215608.58 | CX31: 215608.58 | CY31: 215608.58 | CZ31: 215608.58 | DA31: 215608.58 | DB31: 220998.79 | DC31: 220998.79 | DD31: 220998.79 | DE31: 220998.79 | DF31: 220998.79 | DG31: 220998.79 | DH31: 220998.79 | DI31: 220998.79 | DJ31: 220998.79 | DK31: 220998.79 | DL31: 220998.79 | DM31: 220998.79 | DN31: 226523.76 | DO31: 226523.76 | DP31: 226523.76 | DQ31: 226523.76 | DR31: 226523.76 | DS31: 226523.76 | DT31: 226523.76 | DU31: 226523.76 | DV31: 226523.76 | DW31: 226523.76 | DX31: 226523.76 | DY31: 226523.76
E32: Opex from existing properties | G32: USD | H32: {=_xlfn.BYROW(_xlfn.ANCHORARRAY( J32), _xleta.SUM )} -> 1.2535122e+08 | J32: {=_xlfn.BYCOL(_xlfn.ANCHORARRAY( J27), _xleta.SUM )} -> 932391.25 | K32: 932391.25 | L32: 932391.25 | M32: 932391.25 | N32: 932391.25 | O32: 932391.25 | P32: 932391.25 | Q32: 932391.25 | R32: 932391.25 | S32: 932391.25 | T32: 932391.25 | U32: 932391.25 | V32: 955701.03 | W32: 955701.03 | X32: 955701.03 | Y32: 955701.03 | Z32: 955701.03 | AA32: 955701.03 | AB32: 955701.03 | AC32: 955701.03 | AD32: 955701.03 | AE32: 955701.03 | AF32: 955701.03 | AG32: 955701.03 | AH32: 979593.56 | AI32: 979593.56 | AJ32: 979593.56 | AK32: 979593.56 | AL32: 979593.56 | AM32: 979593.56 | AN32: 979593.56 | AO32: 979593.56 | AP32: 979593.56 | AQ32: 979593.56 | AR32: 979593.56 | AS32: 979593.56 | AT32: 1004083.4 | AU32: 1004083.4 | AV32: 1004083.4 | AW32: 1004083.4 | AX32: 1004083.4 | AY32: 1004083.4 | AZ32: 1004083.4 | BA32: 1004083.4 | BB32: 1004083.4 | BC32: 1004083.4 | BD32: 1004083.4 | BE32: 1004083.4 | BF32: 1029185.5 | BG32: 1029185.5 | BH32: 1029185.5 | BI32: 1029185.5 | BJ32: 1029185.5 | BK32: 1029185.5 | BL32: 1029185.5 | BM32: 1029185.5 | BN32: 1029185.5 | BO32: 1029185.5 | BP32: 1029185.5 | BQ32: 1029185.5 | BR32: 1054915.1 | BS32: 1054915.1 | BT32: 1054915.1 | BU32: 1054915.1 | BV32: 1054915.1 | BW32: 1054915.1 | BX32: 1054915.1 | BY32: 1054915.1 | BZ32: 1054915.1 | CA32: 1054915.1 | CB32: 1054915.1 | CC32: 1054915.1 | CD32: 1081288 | CE32: 1081288 | CF32: 1081288 | CG32: 1081288 | CH32: 1081288 | CI32: 1081288 | CJ32: 1081288 | CK32: 1081288 | CL32: 1081288 | CM32: 1081288 | CN32: 1081288 | CO32: 1081288 | CP32: 1108320.2 | CQ32: 1108320.2 | CR32: 1108320.2 | CS32: 1108320.2 | CT32: 1108320.2 | CU32: 1108320.2 | CV32: 1108320.2 | CW32: 1108320.2 | CX32: 1108320.2 | CY32: 1108320.2 | CZ32: 1108320.2 | DA32: 1108320.2 | DB32: 1136028.2 | DC32: 1136028.2 | DD32: 1136028.2 | DE32: 1136028.2 | DF32: 1136028.2 | DG32: 1136028.2 | DH32: 1136028.2 | DI32: 1136028.2 | DJ32: 1136028.2 | DK32: 1136028.2 | DL32: 1136028.2 | DM32: 1136028.2 | DN32: 1164428.9 | DO32: 1164428.9 | DP32: 1164428.9 | DQ32: 1164428.9 | DR32: 1164428.9 | DS32: 1164428.9 | DT32: 1164428.9 | DU32: 1164428.9 | DV32: 1164428.9 | DW32: 1164428.9 | DX32: 1164428.9 | DY32: 1164428.9
A34: New properties
C37: Land acquisition
C38: (adjusted for inflation)
E39: {=_xlfn.LET( _xlpm.property_data, CaseData!$A$15:$H$24, _xlfn.CHOOSECOLS( _xlpm.property_data, 1 ) )} -> Property F | G39: USD | J39: {=_xlfn.LET( _xlpm.timeline,_xlfn.ANCHORARRAY( $J$3), _xlpm.properties_data, CaseData!$A$15:$H$24, _xlpm.project_start, IF( $F$9 = 0, 0, 12 ), _xlpm.land_acquisition, _xlfn.MAKEARRAY( ROWS( _xlpm.properties_data ), COLUMNS( _xlpm.timeline ), _xlfn.LAMBDA(_xlpm.r,_xlpm.c, IF( INDEX( _xlpm.timeline, _xlpm.c ) = EOMONTH( INDEX( _xlpm.properties_data, _xlpm.r, 6), _xlpm.project_start), INDEX( _xlpm.properties_data, _xlpm.r, 4), 0 ) ) ), _xlpm.inflation_flag, IF( MONTH( _xlpm.timeline ) = 1, 1, 0 ), _xlpm.inflation_data, CaseData!$J$15:$M$24, _xlpm.annual_rate, _xlfn.XLOOKUP( YEAR( _xlpm.timeline ), INDEX( _xlpm.inflation_data,, 1 ), INDEX( _xlpm.inflation_data,, 4 ) ), _xlpm.effective_step, _xlpm.inflation_flag * _xlpm.annual_rate, _xlpm.inflation_factor, _xlfn.SCAN( 1, _xlpm.effective_step, _xlfn.LAMBDA(_xlpm.prev,_xlpm.step, IF( _xlpm.step = 0, _xlpm.prev, _xlpm.prev * ( 1 + _xlpm.step ) ) ) ), _xlpm.land_acquisition * _xlpm.inflation_factor )} -> 4316130 | K39: 0 | L39: 0 | M39: 0 | N39: 0 | O39: 0 | P39: 0 | Q39: 0 | R39: 0 | S39: 0 | T39: 0 | U39: 0 | V39: 0 | W39: 0 | X39: 0 | Y39: 0 | Z39: 0 | AA39: 0 | AB39: 0 | AC39: 0 | AD39: 0 | AE39: 0 | AF39: 0 | AG39: 0 | AH39: 0 | AI39: 0 | AJ39: 0 | AK39: 0 | AL39: 0 | AM39: 0 | AN39: 0 | AO39: 0 | AP39: 0 | AQ39: 0 | AR39: 0 | AS39: 0 | AT39: 0 | AU39: 0 | AV39: 0 | AW39: 0 | AX39: 0 | AY39: 0 | AZ39: 0 | BA39: 0 | BB39: 0 | BC39: 0 | BD39: 0 | BE39: 0 | BF39: 0 | BG39: 0 | BH39: 0 | BI39: 0 | BJ39: 0 | BK39: 0 | BL39: 0 | BM39: 0 | BN39: 0 | BO39: 0 | BP39: 0 | BQ39: 0 | BR39: 0 | BS39: 0 | BT39: 0 | BU39: 0 | BV39: 0 | BW39: 0 | BX39: 0 | BY39: 0 | BZ39: 0 | CA39: 0 | CB39: 0 | CC39: 0 | CD39: 0 | CE39: 0 | CF39: 0 | CG39: 0 | CH39: 0 | CI39: 0 | CJ39: 0 | CK39: 0 | CL39: 0 | CM39: 0 | CN39: 0 | CO39: 0 | CP39: 0 | CQ39: 0 | CR39: 0 | CS39: 0 | CT39: 0 | CU39: 0 | CV39: 0 | CW39: 0 | CX39: 0 | CY39: 0 | CZ39: 0 | DA39: 0 | DB39: 0 | DC39: 0 | DD39: 0 | DE39: 0 | DF39: 0 | DG39: 0 | DH39: 0 | DI39: 0 | DJ39: 0 | DK39: 0 | DL39: 0 | DM39: 0 | DN39: 0 | DO39: 0 | DP39: 0 | DQ39: 0 | DR39: 0 | DS39: 0 | DT39: 0 | DU39: 0 | DV39: 0 | DW39: 0 | DX39: 0 | DY39: 0
E40: Property G | G40: USD | J40: 0 | K40: 0 | L40: 0 | M40: 3908898 | N40: 0 | O40: 0 | P40: 0 | Q40: 0 | R40: 0 | S40: 0 | T40: 0 | U40: 0 | V40: 0 | W40: 0 | X40: 0 | Y40: 0 | Z40: 0 | AA40: 0 | AB40: 0 | AC40: 0 | AD40: 0 | AE40: 0 | AF40: 0 | AG40: 0 | AH40: 0 | AI40: 0 | AJ40: 0 | AK40: 0 | AL40: 0 | AM40: 0 | AN40: 0 | AO40: 0 | AP40: 0 | AQ40: 0 | AR40: 0 | AS40: 0 | AT40: 0 | AU40: 0 | AV40: 0 | AW40: 0 | AX40: 0 | AY40: 0 | AZ40: 0 | BA40: 0 | BB40: 0 | BC40: 0 | BD40: 0 | BE40: 0 | BF40: 0 | BG40: 0 | BH40: 0 | BI40: 0 | BJ40: 0 | BK40: 0 | BL40: 0 | BM40: 0 | BN40: 0 | BO40: 0 | BP40: 0 | BQ40: 0 | BR40: 0 | BS40: 0 | BT40: 0 | BU40: 0 | BV40: 0 | BW40: 0 | BX40: 0 | BY40: 0 | BZ40: 0 | CA40: 0 | CB40: 0 | CC40: 0 | CD40: 0 | CE40: 0 | CF40: 0 | CG40: 0 | CH40: 0 | CI40: 0 | CJ40: 0 | CK40: 0 | CL40: 0 | CM40: 0 | CN40: 0 | CO40: 0 | CP40: 0 | CQ40: 0 | CR40: 0 | CS40: 0 | CT40: 0 | CU40: 0 | CV40: 0 | CW40: 0 | CX40: 0 | CY40: 0 | CZ40: 0 | DA40: 0 | DB40: 0 | DC40: 0 | DD40: 0 | DE40: 0 | DF40: 0 | DG40: 0 | DH40: 0 | DI40: 0 | DJ40: 0 | DK40: 0 | DL40: 0 | DM40: 0 | DN40: 0 | DO40: 0 | DP40: 0 | DQ40: 0 | DR40: 0 | DS40: 0 | DT40: 0 | DU40: 0 | DV40: 0 | DW40: 0 | DX40: 0 | DY40: 0
E41: Property H | G41: USD | J41: 0 | K41: 0 | L41: 0 | M41: 0 | N41: 0 | O41: 0 | P41: 4936701 | Q41: 0 | R41: 0 | S41: 0 | T41: 0 | U41: 0 | V41: 0 | W41: 0 | X41: 0 | Y41: 0 | Z41: 0 | AA41: 0 | AB41: 0 | AC41: 0 | AD41: 0 | AE41: 0 | AF41: 0 | AG41: 0 | AH41: 0 | AI41: 0 | AJ41: 0 | AK41: 0 | AL41: 0 | AM41: 0 | AN41: 0 | AO41: 0 | AP41: 0 | AQ41: 0 | AR41: 0 | AS41: 0 | AT41: 0 | AU41: 0 | AV41: 0 | AW41: 0 | AX41: 0 | AY41: 0 | AZ41: 0 | BA41: 0 | BB41: 0 | BC41: 0 | BD41: 0 | BE41: 0 | BF41: 0 | BG41: 0 | BH41: 0 | BI41: 0 | BJ41: 0 | BK41: 0 | BL41: 0 | BM41: 0 | BN41: 0 | BO41: 0 | BP41: 0 | BQ41: 0 | BR41: 0 | BS41: 0 | BT41: 0 | BU41: 0 | BV41: 0 | BW41: 0 | BX41: 0 | BY41: 0 | BZ41: 0 | CA41: 0 | CB41: 0 | CC41: 0 | CD41: 0 | CE41: 0 | CF41: 0 | CG41: 0 | CH41: 0 | CI41: 0 | CJ41: 0 | CK41: 0 | CL41: 0 | CM41: 0 | CN41: 0 | CO41: 0 | CP41: 0 | CQ41: 0 | CR41: 0 | CS41: 0 | CT41: 0 | CU41: 0 | CV41: 0 | CW41: 0 | CX41: 0 | CY41: 0 | CZ41: 0 | DA41: 0 | DB41: 0 | DC41: 0 | DD41: 0 | DE41: 0 | DF41: 0 | DG41: 0 | DH41: 0 | DI41: 0 | DJ41: 0 | DK41: 0 | DL41: 0 | DM41: 0 | DN41: 0 | DO41: 0 | DP41: 0 | DQ41: 0 | DR41: 0 | DS41: 0 | DT41: 0 | DU41: 0 | DV41: 0 | DW41: 0 | DX41: 0 | DY41: 0
E42: Property I | G42: USD | J42: 0 | K42: 0 | L42: 0 | M42: 0 | N42: 0 | O42: 0 | P42: 0 | Q42: 0 | R42: 0 | S42: 6597360 | T42: 0 | U42: 0 | V42: 0 | W42: 0 | X42: 0 | Y42: 0 | Z42: 0 | AA42: 0 | AB42: 0 | AC42: 0 | AD42: 0 | AE42: 0 | AF42: 0 | AG42: 0 | AH42: 0 | AI42: 0 | AJ42: 0 | AK42: 0 | AL42: 0 | AM42: 0 | AN42: 0 | AO42: 0 | AP42: 0 | AQ42: 0 | AR42: 0 | AS42: 0 | AT42: 0 | AU42: 0 | AV42: 0 | AW42: 0 | AX42: 0 | AY42: 0 | AZ42: 0 | BA42: 0 | BB42: 0 | BC42: 0 | BD42: 0 | BE42: 0 | BF42: 0 | BG42: 0 | BH42: 0 | BI42: 0 | BJ42: 0 | BK42: 0 | BL42: 0 | BM42: 0 | BN42: 0 | BO42: 0 | BP42: 0 | BQ42: 0 | BR42: 0 | BS42: 0 | BT42: 0 | BU42: 0 | BV42: 0 | BW42: 0 | BX42: 0 | BY42: 0 | BZ42: 0 | CA42: 0 | CB42: 0 | CC42: 0 | CD42: 0 | CE42: 0 | CF42: 0 | CG42: 0 | CH42: 0 | CI42: 0 | CJ42: 0 | CK42: 0 | CL42: 0 | CM42: 0 | CN42: 0 | CO42: 0 | CP42: 0 | CQ42: 0 | CR42: 0 | CS42: 0 | CT42: 0 | CU42: 0 | CV42: 0 | CW42: 0 | CX42: 0 | CY42: 0 | CZ42: 0 | DA42: 0 | DB42: 0 | DC42: 0 | DD42: 0 | DE42: 0 | DF42: 0 | DG42: 0 | DH42: 0 | DI42: 0 | DJ42: 0 | DK42: 0 | DL42: 0 | DM42: 0 | DN42: 0 | DO42: 0 | DP42: 0 | DQ42: 0 | DR42: 0 | DS42: 0 | DT42: 0 | DU42: 0 | DV42: 0 | DW42: 0 | DX42: 0 | DY42: 0
E43: Property J | G43: USD | J43: 0 | K43: 0 | L43: 0 | M43: 0 | N43: 0 | O43: 0 | P43: 0 | Q43: 0 | R43: 0 | S43: 0 | T43: 0 | U43: 0 | V43: 4793841.4 | W43: 0 | X43: 0 | Y43: 0 | Z43: 0 | AA43: 0 | AB43: 0 | AC43: 0 | AD43: 0 | AE43: 0 | AF43: 0 | AG43: 0 | AH43: 0 | AI43: 0 | AJ43: 0 | AK43: 0 | AL43: 0 | AM43: 0 | AN43: 0 | AO43: 0 | AP43: 0 | AQ43: 0 | AR43: 0 | AS43: 0 | AT43: 0 | AU43: 0 | AV43: 0 | AW43: 0 | AX43: 0 | AY43: 0 | AZ43: 0 | BA43: 0 | BB43: 0 | BC43: 0 | BD43: 0 | BE43: 0 | BF43: 0 | BG43: 0 | BH43: 0 | BI43: 0 | BJ43: 0 | BK43: 0 | BL43: 0 | BM43: 0 | BN43: 0 | BO43: 0 | BP43: 0 | BQ43: 0 | BR43: 0 | BS43: 0 | BT43: 0 | BU43: 0 | BV43: 0 | BW43: 0 | BX43: 0 | BY43: 0 | BZ43: 0 | CA43: 0 | CB43: 0 | CC43: 0 | CD43: 0 | CE43: 0 | CF43: 0 | CG43: 0 | CH43: 0 | CI43: 0 | CJ43: 0 | CK43: 0 | CL43: 0 | CM43: 0 | CN43: 0 | CO43: 0 | CP43: 0 | CQ43: 0 | CR43: 0 | CS43: 0 | CT43: 0 | CU43: 0 | CV43: 0 | CW43: 0 | CX43: 0 | CY43: 0 | CZ43: 0 | DA43: 0 | DB43: 0 | DC43: 0 | DD43: 0 | DE43: 0 | DF43: 0 | DG43: 0 | DH43: 0 | DI43: 0 | DJ43: 0 | DK43: 0 | DL43: 0 | DM43: 0 | DN43: 0 | DO43: 0 | DP43: 0 | DQ43: 0 | DR43: 0 | DS43: 0 | DT43: 0 | DU43: 0 | DV43: 0 | DW43: 0 | DX43: 0 | DY43: 0
E44: Property K | G44: USD | J44: 0 | K44: 0 | L44: 0 | M44: 0 | N44: 0 | O44: 0 | P44: 0 | Q44: 0 | R44: 0 | S44: 0 | T44: 0 | U44: 0 | V44: 0 | W44: 0 | X44: 0 | Y44: 3262091.3 | Z44: 0 | AA44: 0 | AB44: 0 | AC44: 0 | AD44: 0 | AE44: 0 | AF44: 0 | AG44: 0 | AH44: 0 | AI44: 0 | AJ44: 0 | AK44: 0 | AL44: 0 | AM44: 0 | AN44: 0 | AO44: 0 | AP44: 0 | AQ44: 0 | AR44: 0 | AS44: 0 | AT44: 0 | AU44: 0 | AV44: 0 | AW44: 0 | AX44: 0 | AY44: 0 | AZ44: 0 | BA44: 0 | BB44: 0 | BC44: 0 | BD44: 0 | BE44: 0 | BF44: 0 | BG44: 0 | BH44: 0 | BI44: 0 | BJ44: 0 | BK44: 0 | BL44: 0 | BM44: 0 | BN44: 0 | BO44: 0 | BP44: 0 | BQ44: 0 | BR44: 0 | BS44: 0 | BT44: 0 | BU44: 0 | BV44: 0 | BW44: 0 | BX44: 0 | BY44: 0 | BZ44: 0 | CA44: 0 | CB44: 0 | CC44: 0 | CD44: 0 | CE44: 0 | CF44: 0 | CG44: 0 | CH44: 0 | CI44: 0 | CJ44: 0 | CK44: 0 | CL44: 0 | CM44: 0 | CN44: 0 | CO44: 0 | CP44: 0 | CQ44: 0 | CR44: 0 | CS44: 0 | CT44: 0 | CU44: 0 | CV44: 0 | CW44: 0 | CX44: 0 | CY44: 0 | CZ44: 0 | DA44: 0 | DB44: 0 | DC44: 0 | DD44: 0 | DE44: 0 | DF44: 0 | DG44: 0 | DH44: 0 | DI44: 0 | DJ44: 0 | DK44: 0 | DL44: 0 | DM44: 0 | DN44: 0 | DO44: 0 | DP44: 0 | DQ44: 0 | DR44: 0 | DS44: 0 | DT44: 0 | DU44: 0 | DV44: 0 | DW44: 0 | DX44: 0 | DY44: 0
E45: Property L | G45: USD | J45: 0 | K45: 0 | L45: 0 | M45: 0 | N45: 0 | O45: 0 | P45: 0 | Q45: 0 | R45: 0 | S45: 0 | T45: 0 | U45: 0 | V45: 0 | W45: 0 | X45: 0 | Y45: 0 | Z45: 0 | AA45: 0 | AB45: 0 | AC45: 0 | AD45: 0 | AE45: 0 | AF45: 0 | AG45: 0 | AH45: 7810190.4 | AI45: 0 | AJ45: 0 | AK45: 0 | AL45: 0 | AM45: 0 | AN45: 0 | AO45: 0 | AP45: 0 | AQ45: 0 | AR45: 0 | AS45: 0 | AT45: 0 | AU45: 0 | AV45: 0 | AW45: 0 | AX45: 0 | AY45: 0 | AZ45: 0 | BA45: 0 | BB45: 0 | BC45: 0 | BD45: 0 | BE45: 0 | BF45: 0 | BG45: 0 | BH45: 0 | BI45: 0 | BJ45: 0 | BK45: 0 | BL45: 0 | BM45: 0 | BN45: 0 | BO45: 0 | BP45: 0 | BQ45: 0 | BR45: 0 | BS45: 0 | BT45: 0 | BU45: 0 | BV45: 0 | BW45: 0 | BX45: 0 | BY45: 0 | BZ45: 0 | CA45: 0 | CB45: 0 | CC45: 0 | CD45: 0 | CE45: 0 | CF45: 0 | CG45: 0 | CH45: 0 | CI45: 0 | CJ45: 0 | CK45: 0 | CL45: 0 | CM45: 0 | CN45: 0 | CO45: 0 | CP45: 0 | CQ45: 0 | CR45: 0 | CS45: 0 | CT45: 0 | CU45: 0 | CV45: 0 | CW45: 0 | CX45: 0 | CY45: 0 | CZ45: 0 | DA45: 0 | DB45: 0 | DC45: 0 | DD45: 0 | DE45: 0 | DF45: 0 | DG45: 0 | DH45: 0 | DI45: 0 | DJ45: 0 | DK45: 0 | DL45: 0 | DM45: 0 | DN45: 0 | DO45: 0 | DP45: 0 | DQ45: 0 | DR45: 0 | DS45: 0 | DT45: 0 | DU45: 0 | DV45: 0 | DW45: 0 | DX45: 0 | DY45: 0
E46: Property M | G46: USD | J46: 0 | K46: 0 | L46: 0 | M46: 0 | N46: 0 | O46: 0 | P46: 0 | Q46: 0 | R46: 0 | S46: 0 | T46: 0 | U46: 0 | V46: 0 | W46: 0 | X46: 0 | Y46: 0 | Z46: 0 | AA46: 0 | AB46: 0 | AC46: 0 | AD46: 0 | AE46: 0 | AF46: 0 | AG46: 0 | AH46: 0 | AI46: 0 | AJ46: 0 | AK46: 4223861.2 | AL46: 0 | AM46: 0 | AN46: 0 | AO46: 0 | AP46: 0 | AQ46: 0 | AR46: 0 | AS46: 0 | AT46: 0 | AU46: 0 | AV46: 0 | AW46: 0 | AX46: 0 | AY46: 0 | AZ46: 0 | BA46: 0 | BB46: 0 | BC46: 0 | BD46: 0 | BE46: 0 | BF46: 0 | BG46: 0 | BH46: 0 | BI46: 0 | BJ46: 0 | BK46: 0 | BL46: 0 | BM46: 0 | BN46: 0 | BO46: 0 | BP46: 0 | BQ46: 0 | BR46: 0 | BS46: 0 | BT46: 0 | BU46: 0 | BV46: 0 | BW46: 0 | BX46: 0 | BY46: 0 | BZ46: 0 | CA46: 0 | CB46: 0 | CC46: 0 | CD46: 0 | CE46: 0 | CF46: 0 | CG46: 0 | CH46: 0 | CI46: 0 | CJ46: 0 | CK46: 0 | CL46: 0 | CM46: 0 | CN46: 0 | CO46: 0 | CP46: 0 | CQ46: 0 | CR46: 0 | CS46: 0 | CT46: 0 | CU46: 0 | CV46: 0 | CW46: 0 | CX46: 0 | CY46: 0 | CZ46: 0 | DA46: 0 | DB46: 0 | DC46: 0 | DD46: 0 | DE46: 0 | DF46: 0 | DG46: 0 | DH46: 0 | DI46: 0 | DJ46: 0 | DK46: 0 | DL46: 0 | DM46: 0 | DN46: 0 | DO46: 0 | DP46: 0 | DQ46: 0 | DR46: 0 | DS46: 0 | DT46: 0 | DU46: 0 | DV46: 0 | DW46: 0 | DX46: 0 | DY46: 0
E47: Property N | G47: USD | J47: 0 | K47: 0 | L47: 0 | M47: 0 | N47: 0 | O47: 0 | P47: 0 | Q47: 0 | R47: 0 | S47: 0 | T47: 0 | U47: 0 | V47: 0 | W47: 0 | X47: 0 | Y47: 0 | Z47: 0 | AA47: 0 | AB47: 0 | AC47: 0 | AD47: 0 | AE47: 0 | AF47: 0 | AG47: 0 | AH47: 0 | AI47: 0 | AJ47: 0 | AK47: 0 | AL47: 0 | AM47: 0 | AN47: 0 | AO47: 0 | AP47: 0 | AQ47: 0 | AR47: 0 | AS47: 0 | AT47: 6440334.2 | AU47: 0 | AV47: 0 | AW47: 0 | AX47: 0 | AY47: 0 | AZ47: 0 | BA47: 0 | BB47: 0 | BC47: 0 | BD47: 0 | BE47: 0 | BF47: 0 | BG47: 0 | BH47: 0 | BI47: 0 | BJ47: 0 | BK47: 0 | BL47: 0 | BM47: 0 | BN47: 0 | BO47: 0 | BP47: 0 | BQ47: 0 | BR47: 0 | BS47: 0 | BT47: 0 | BU47: 0 | BV47: 0 | BW47: 0 | BX47: 0 | BY47: 0 | BZ47: 0 | CA47: 0 | CB47: 0 | CC47: 0 | CD47: 0 | CE47: 0 | CF47: 0 | CG47: 0 | CH47: 0 | CI47: 0 | CJ47: 0 | CK47: 0 | CL47: 0 | CM47: 0 | CN47: 0 | CO47: 0 | CP47: 0 | CQ47: 0 | CR47: 0 | CS47: 0 | CT47: 0 | CU47: 0 | CV47: 0 | CW47: 0 | CX47: 0 | CY47: 0 | CZ47: 0 | DA47: 0 | DB47: 0 | DC47: 0 | DD47: 0 | DE47: 0 | DF47: 0 | DG47: 0 | DH47: 0 | DI47: 0 | DJ47: 0 | DK47: 0 | DL47: 0 | DM47: 0 | DN47: 0 | DO47: 0 | DP47: 0 | DQ47: 0 | DR47: 0 | DS47: 0 | DT47: 0 | DU47: 0 | DV47: 0 | DW47: 0 | DX47: 0 | DY47: 0
E48: Property O | G48: USD | J48: 0 | K48: 0 | L48: 0 | M48: 0 | N48: 0 | O48: 0 | P48: 0 | Q48: 0 | R48: 0 | S48: 0 | T48: 0 | U48: 0 | V48: 0 | W48: 0 | X48: 0 | Y48: 0 | Z48: 0 | AA48: 0 | AB48: 0 | AC48: 0 | AD48: 0 | AE48: 0 | AF48: 0 | AG48: 0 | AH48: 0 | AI48: 0 | AJ48: 0 | AK48: 0 | AL48: 0 | AM48: 0 | AN48: 0 | AO48: 0 | AP48: 0 | AQ48: 0 | AR48: 0 | AS48: 0 | AT48: 0 | AU48: 0 | AV48: 0 | AW48: 0 | AX48: 0 | AY48: 0 | AZ48: 6385768.3 | BA48: 0 | BB48: 0 | BC48: 0 | BD48: 0 | BE48: 0 | BF48: 0 | BG48: 0 | BH48: 0 | BI48: 0 | BJ48: 0 | BK48: 0 | BL48: 0 | BM48: 0 | BN48: 0 | BO48: 0 | BP48: 0 | BQ48: 0 | BR48: 0 | BS48: 0 | BT48: 0 | BU48: 0 | BV48: 0 | BW48: 0 | BX48: 0 | BY48: 0 | BZ48: 0 | CA48: 0 | CB48: 0 | CC48: 0 | CD48: 0 | CE48: 0 | CF48: 0 | CG48: 0 | CH48: 0 | CI48: 0 | CJ48: 0 | CK48: 0 | CL48: 0 | CM48: 0 | CN48: 0 | CO48: 0 | CP48: 0 | CQ48: 0 | CR48: 0 | CS48: 0 | CT48: 0 | CU48: 0 | CV48: 0 | CW48: 0 | CX48: 0 | CY48: 0 | CZ48: 0 | DA48: 0 | DB48: 0 | DC48: 0 | DD48: 0 | DE48: 0 | DF48: 0 | DG48: 0 | DH48: 0 | DI48: 0 | DJ48: 0 | DK48: 0 | DL48: 0 | DM48: 0 | DN48: 0 | DO48: 0 | DP48: 0 | DQ48: 0 | DR48: 0 | DS48: 0 | DT48: 0 | DU48: 0 | DV48: 0 | DW48: 0 | DX48: 0 | DY48: 0
E49: Land acquisition | G49: USD | J49: {=_xlfn.BYCOL(_xlfn.ANCHORARRAY( J39), _xleta.SUM )} -> 4316130 | K49: 0 | L49: 0 | M49: 3908898 | N49: 0 | O49: 0 | P49: 4936701 | Q49: 0 | R49: 0 | S49: 6597360 | T49: 0 | U49: 0 | V49: 4793841.4 | W49: 0 | X49: 0 | Y49: 3262091.3 | Z49: 0 | AA49: 0 | AB49: 0 | AC49: 0 | AD49: 0 | AE49: 0 | AF49: 0 | AG49: 0 | AH49: 7810190.4 | AI49: 0 | AJ49: 0 | AK49: 4223861.2 | AL49: 0 | AM49: 0 | AN49: 0 | AO49: 0 | AP49: 0 | AQ49: 0 | AR49: 0 | AS49: 0 | AT49: 6440334.2 | AU49: 0 | AV49: 0 | AW49: 0 | AX49: 0 | AY49: 0 | AZ49: 6385768.3 | BA49: 0 | BB49: 0 | BC49: 0 | BD49: 0 | BE49: 0 | BF49: 0 | BG49: 0 | BH49: 0 | BI49: 0 | BJ49: 0 | BK49: 0 | BL49: 0 | BM49: 0 | BN49: 0 | BO49: 0 | BP49: 0 | BQ49: 0 | BR49: 0 | BS49: 0 | BT49: 0 | BU49: 0 | BV49: 0 | BW49: 0 | BX49: 0 | BY49: 0 | BZ49: 0 | CA49: 0 | CB49: 0 | CC49: 0 | CD49: 0 | CE49: 0 | CF49: 0 | CG49: 0 | CH49: 0 | CI49: 0 | CJ49: 0 | CK49: 0 | CL49: 0 | CM49: 0 | CN49: 0 | CO49: 0 | CP49: 0 | CQ49: 0 | CR49: 0 | CS49: 0 | CT49: 0 | CU49: 0 | CV49: 0 | CW49: 0 | CX49: 0 | CY49: 0 | CZ49: 0 | DA49: 0 | DB49: 0 | DC49: 0 | DD49: 0 | DE49: 0 | DF49: 0 | DG49: 0 | DH49: 0 | DI49: 0 | DJ49: 0 | DK49: 0 | DL49: 0 | DM49: 0 | DN49: 0 | DO49: 0 | DP49: 0 | DQ49: 0 | DR49: 0 | DS49: 0 | DT49: 0 | DU49: 0 | DV49: 0 | DW49: 0 | DX49: 0 | DY49: 0
...

Sheet CaseData
A1: Key Model Assumptions
A3: Existing Property Assumptions | F3: New Property Vacancy Rates | J3: Other Assumptions
A5: Existing Properties | B5: Gross Rent (Monthly) | C5: Vacancy Rate | D5: OPEX (Monthly) | F5: Month of Operations | H5: Vacancy Rate | J5: Other Assumptions
A6: Property A | B6: 791000 | C6: 0.05 | D6: 197750 | F6: 1 | H6: 0.75 | J6: Model Start Date | L6: 44562 | M6: Valuation | N6: 20
A7: Property B | B7: 448000 | C7: 0.07 | D7: 156800 | F7: 6 | H7: 0.25 | J7: Property Mgmt Fee | L7: 0.02 | M7: Sale Date | N7: 48213
A8: Property C | B8: 686000 | C8: 0.06 | D8: 171500 | F8: 12 | H8: 0.1
A9: Property D | B9: 738000 | C9: 0.04 | D9: 206640 | F9: 24 | H9: 0.05 | J9: Company name | L9: United Landlords Ltd | M9: label
A10: Property E | B10: 553000 | C10: 0.03 | D10: 176960 | J10: CFM Topic | L10: Timing flexibility
A12: New Property Assumptions | J12: Inflation Assumptions
A14: New Properties | B14: Gross Rent (Monthly) | C14: OPEX (Monthly) | D14: Land Cost | E14: Construction Costs | F14: Land Acquisition | G14: Prep Work Length | H14: Construction Length | J14: Calendar Year | K14: Rent Increase | L14: Cost Increase | M14: Land Appreciation
A15: Property F | B15: 442000 | C15: 137020 | D15: 4110600 | E15: 41106000 | F15: 44562 | G15: 4 | H15: 15 | J15: =YEAR(L6) -> 2022 | K15: 0.05 | L15: 0.025 | M15: 0.05
A16: Property G | B16: 383000 | C16: 114900 | D16: 3722760 | E16: 31023000 | F16: 44652 | G16: 5 | H16: 12 | J16: =J15+1 -> 2023 | K16: 0.045 | L16: 0.025 | M16: 0.045
A17: Property H | B17: 497000 | C17: 134190 | D17: 4701620 | E17: 42742000 | F17: 44743 | G17: 3 | H17: 16 | J17: =J16+1 -> 2024 | K17: 0.04 | L17: 0.025 | M17: 0.04
A18: Property I | B18: 595000 | C18: 166600 | D18: 6283200 | E18: 52360000 | F18: 44835 | G18: 5 | H18: 19 | J18: =J17+1 -> 2025 | K18: 0.035 | L18: 0.025 | M18: 0.035
A19: Property J | B19: 592000 | C19: 165760 | D19: 4368960 | E19: 48544000 | F19: 44927 | G19: 5 | H19: 18 | J19: =J18+1 -> 2026 | K19: 0.03 | L19: 0.025 | M19: 0.03
A20: Property K | B20: 363000 | C20: 105270 | D20: 2972970 | E20: 33033000 | F20: 45017 | G20: 6 | H20: 12 | J20: =J19+1 -> 2027 | K20: 0.025 | L20: 0.025 | M20: 0.025
A21: Property L | B21: 732000 | C21: 248880 | D21: 6844200 | E21: 62220000 | F21: 45292 | G21: 3 | H21: 23 | J21: =J20+1 -> 2028 | K21: 0.025 | L21: 0.025 | M21: 0.025
A22: Property M | B22: 538000 | C22: 182920 | D22: 3701440 | E22: 46268000 | F22: 45383 | G22: 6 | H22: 17 | J22: =J21+1 -> 2029 | K22: 0.025 | L22: 0.025 | M22: 0.025
A23: Property N | B23: 748000 | C23: 194480 | D23: 5452920 | E23: 60588000 | F23: 45658 | G23: 5 | H23: 22 | J23: =J22+1 -> 2030 | K23: 0.025 | L23: 0.025 | M23: 0.025
A24: Property O | B24: 768000 | C24: 238080 | D24: 5406720 | E24: 67584000 | F24: 45839 | G24: 5 | H24: 24 | J24: =J23+1 -> 2031 | K24: 0.025 | L24: 0.025 | M24: 0.025
A26: Construction Bell Assumptions
A28: Construction Bell | B28: % Completed Each Month for Different Construction Lengths
A29: Month of Construction | B29: 24 | C29: =B29-1 -> 23 | D29: =C29-1 -> 22 | E29: =D29-1 -> 21 | F29: =E29-1 -> 20 | G29: =F29-1 -> 19 | H29: =G29-1 -> 18 | I29: =H29-1 -> 17 | J29: =I29-1 -> 16 | ... N29: =M29-1 -> 12
A30: 1 | B30: 0.01 | C30: 0.01 | D30: 0.01 | E30: 0.0125 | F30: 0.015 | G30: 0.015 | H30: 0.015 | I30: 0.015 | J30: 0.02 | K30: 0.0225 | L30: 0.02 | M30: 0.02 | N30: 0.02
A31: =A30+1 -> 2 | B31: 0.01 | C31: 0.01 | D31: 0.01 | E31: 0.0125 | F31: 0.015 | G31: 0.015 | H31: 0.015 | I31: 0.0175 | J31: 0.02 | K31: 0.025 | L31: 0.03 | M31: 0.03 | N31: 0.03
A32: =A31+1 -> 3 | B32: 0.01 | C32: 0.015 | D32: 0.015 | E32: 0.015 | F32: 0.015 | G32: 0.02 | H32: 0.03 | I32: 0.025 | J32: 0.03 | K32: 0.03 | L32: 0.035 | M32: 0.035 | N32: 0.04
A33: =A32+1 -> 4 | B33: 0.02 | C33: 0.02 | D33: 0.02 | E33: 0.0175 | F33: 0.02 | G33: 0.025 | H33: 0.03 | I33: 0.0275 | J33: 0.03 | K33: 0.035 | L33: 0.04 | M33: 0.045 | N33: 0.05
A34: =A33+1 -> 5 | B34: 0.02 | C34: 0.02 | D34: 0.02 | E34: 0.02 | F34: 0.025 | G34: 0.025 | H34: 0.03 | I34: 0.035 | J34: 0.035 | K34: 0.04 | L34: 0.045 | M34: 0.05 | N34: 0.06
A35: =A34+1 -> 6 | B35: 0.02 | C35: 0.025 | D35: 0.025 | E35: 0.025 | F35: 0.0275 | G35: 0.03 | H35: 0.03 | I35: 0.04 | J35: 0.04 | K35: 0.05 | L35: 0.06 | M35: 0.07 | N35: 0.08
A36: =A35+1 -> 7 | B36: 0.02 | C36: 0.025 | D36: 0.03 | E36: 0.03 | F36: 0.035 | G36: 0.035 | H36: 0.04 | I36: 0.05 | J36: 0.05 | K36: 0.07 | L36: 0.08 | M36: 0.08 | N36: 0.1
A37: =A36+1 -> 8 | B37: 0.03 | C37: 0.03 | D37: 0.03 | E37: 0.03 | F37: 0.035 | G37: 0.04 | H37: 0.05 | I37: 0.06 | J37: 0.07 | K37: 0.1 | L37: 0.1 | M37: 0.1 | N37: 0.12
A38: =A37+1 -> 9 | B38: 0.03 | C38: 0.03 | D38: 0.03 | E38: 0.035 | F38: 0.04 | G38: 0.06 | H38: 0.06 | I38: 0.07 | J38: 0.09 | K38: 0.11 | L38: 0.12 | M38: 0.14 | N38: 0.14
A39: =A38+1 -> 10 | B39: 0.03 | C39: 0.035 | D39: 0.04 | E39: 0.05 | F39: 0.05 | G39: 0.065 | H39: 0.07 | I39: 0.08 | J39: 0.1 | K39: 0.11 | L39: 0.12 | M39: 0.14 | N39: 0.16
A40: =A39+1 -> 11 | B40: 0.04 | C40: 0.04 | D40: 0.045 | E40: 0.06 | F40: 0.06 | G40: 0.075 | H40: 0.08 | I40: 0.09 | J40: 0.1 | K40: 0.11 | L40: 0.12 | M40: 0.14 | N40: 0.14
A41: =A40+1 -> 12 | B41: 0.04 | C41: 0.045 | D41: 0.05 | E41: 0.07 | F41: 0.07 | G41: 0.09 | H41: 0.09 | I41: 0.09 | J41: 0.1 | K41: 0.09 | L41: 0.1 | M41: 0.1 | N41: 0.06
A42: =A41+1 -> 13 | B42: 0.05 | C42: 0.05 | D42: 0.055 | E42: 0.08 | F42: 0.09 | G42: 0.09 | H42: 0.1 | I42: 0.09 | J42: 0.1 | K42: 0.08 | L42: 0.08 | M42: 0.05
A43: =A42+1 -> 14 | B43: 0.05 | C43: 0.055 | D43: 0.06 | E43: 0.09 | F43: 0.09 | G43: 0.09 | H43: 0.1 | I43: 0.09 | J43: 0.09 | K43: 0.07 | L43: 0.05
A44: =A43+1 -> 15 | B44: 0.06 | C44: 0.06 | D44: 0.07 | E44: 0.09 | F44: 0.09 | G44: 0.09 | H44: 0.1 | I44: 0.09 | J44: 0.07 | K44: 0.0575
A45: =A44+1 -> 16 | B45: 0.06 | C45: 0.07 | D45: 0.08 | E45: 0.09 | F45: 0.09 | G45: 0.09 | H45: 0.08 | I45: 0.08 | J45: 0.055
A46: =A45+1 -> 17 | B46: 0.07 | C46: 0.08 | D46: 0.08 | E46: 0.09 | F46: 0.09 | G46: 0.07 | H46: 0.05 | I46: 0.05
...

Sheet CaseSolution
B2: Period Start | G2: =CaseData!$L$6 -> 44562 | H2: =G3+1 -> 44593 | I2: =H3+1 -> 44621 | J2: =I3+1 -> 44652 | K2: =J3+1 -> 44682 | L2: =K3+1 -> 44713 | M2: =L3+1 -> 44743 | N2: =M3+1 -> 44774 | O2: =N3+1 -> 44805 | ... DV2: =DU3+1 -> 48183
B3: Period End | F3: =G2-1 -> 44561 | G3: =EOMONTH(G2,0) -> 44592 | H3: =EOMONTH(H2,0) -> 44620 | I3: =EOMONTH(I2,0) -> 44651 | J3: =EOMONTH(J2,0) -> 44681 | K3: =EOMONTH(K2,0) -> 44712 | L3: =EOMONTH(L2,0) -> 44742 | M3: =EOMONTH(M2,0) -> 44773 | N3: =EOMONTH(N2,0) -> 44804 | ... DV3: =EOMONTH(DV2,0) -> 48213
B4: Period # | F4: 0 | G4: =F4+1 -> 1 | H4: =G4+1 -> 2 | I4: =H4+1 -> 3 | J4: =I4+1 -> 4 | K4: =J4+1 -> 5 | L4: =K4+1 -> 6 | M4: =L4+1 -> 7 | N4: =M4+1 -> 8 | ... DV4: =DU4+1 -> 120
B6: 1. Cashflow Summary
B8: Total Project Cashflow for the Month | E8: [$] | G8: =SUM(G9:G13) -> -2105346.2 | H8: =SUM(H9:H13) -> 2210783.8 | I8: =SUM(I9:I13) -> 2210783.8 | J8: =SUM(J9:J13) -> -1698114.2 | K8: =SUM(K9:K13) -> 1262776.6 | L8: =SUM(L9:L13) -> 1157442.5 | M8: =SUM(M9:M13) -> -3989926.8 | N8: =SUM(N9:N13) -> 736106 | ... DV8: =SUM(DV9:DV13) -> 8037216.9
B9: Net Rent Revenue | E9: [$] | G9: =G22 -> 3210711 | H9: =H22 -> 3210711 | I9: =I22 -> 3210711 | J9: =J22 -> 3210711 | K9: =K22 -> 3210711 | L9: =L22 -> 3210711 | M9: =M22 -> 3210711 | N9: =N22 -> 3210711 | ... DV9: =DV22 -> 11606835
B10: Operating Expenses | E10: [$] | G10: =-G46 -> -932391.25 | H10: =-H46 -> -932391.25 | I10: =-I46 -> -932391.25 | J10: =-J46 -> -932391.25 | K10: =-K46 -> -932391.25 | L10: =-L46 -> -932391.25 | M10: =-M46 -> -932391.25 | N10: =-N46 -> -932391.25 | ... DV10: =-DV46 -> -3325339.6
B11: Property Management Fee | E11: [$] | G11: =-G70 -> -67536 | H11: =-H70 -> -67536 | I11: =-I70 -> -67536 | J11: =-J70 -> -67536 | K11: =-K70 -> -67536 | L11: =-L70 -> -67536 | M11: =-M70 -> -67536 | N11: =-N70 -> -67536 | ... DV11: =-DV70 -> -244278.5
B12: Land Acquisition Cost | E12: [$] | G12: =-G95 -> -4316130 | H12: =-H95 -> 0 | I12: =-I95 -> 0 | J12: =-J95 -> -3908898 | K12: =-K95 -> 0 | L12: =-L95 -> 0 | M12: =-M95 -> -4936701 | N12: =-N95 -> 0 | ... DV12: =-DV95 -> 0
B13: Construction Cost | E13: [$] | G13: =-G110 -> 0 | H13: =-H110 -> 0 | I13: =-I110 -> 0 | J13: =-J110 -> 0 | K13: =-K110 -> -948007.12 | L13: =-L110 -> -1053341.2 | M13: =-M110 -> -1264009.5 | N13: =-N110 -> -1474677.8 | ... DV13: =-DV110 -> 0
B15: Opening Cash | E15: [$] | G15: 0 | H15: =G16 -> -2105346.2 | I15: =H16 -> 105437.5 | J15: =I16 -> 2316221.2 | K15: =J16 -> 618107 | L15: =K16 -> 1880883.6 | M15: =L16 -> 3038326.1 | N15: =M16 -> -951600.62 | O15: =N16 -> -215494.63 | ... DV15: =DU16 -> 74806390
B16: Closing Cash | E16: [$] | G16: =G8+G15 -> -2105346.2 | H16: =H8+H15 -> 105437.5 | I16: =I8+I15 -> 2316221.2 | J16: =J8+J15 -> 618107 | K16: =K8+K15 -> 1880883.6 | L16: =L8+L15 -> 3038326.1 | M16: =M8+M15 -> -951600.62 | N16: =N8+N15 -> -215494.63 | ... DV16: =DV8+DV15 -> 82843607
B17: NOI | E17: [$] | G17: =SUM(G9:G11) -> 2210783.8 | H17: =SUM(H9:H11) -> 2210783.8 | I17: =SUM(I9:I11) -> 2210783.8 | J17: =SUM(J9:J11) -> 2210783.8 | K17: =SUM(K9:K11) -> 2210783.8 | L17: =SUM(L9:L11) -> 2210783.8 | M17: =SUM(M9:M11) -> 2210783.8 | N17: =SUM(N9:N11) -> 2210783.8 | ... DV17: =SUM(DV9:DV11) -> 8037216.9
B19: 2. Rent Revenue Forecast
B22: Rent Revenue, Net | E22: [$] | G22: =SUBTOTAL(9,G24:G41) -> 3210711 | H22: =SUBTOTAL(9,H24:H41) -> 3210711 | I22: =SUBTOTAL(9,I24:I41) -> 3210711 | J22: =SUBTOTAL(9,J24:J41) -> 3210711 | K22: =SUBTOTAL(9,K24:K41) -> 3210711 | L22: =SUBTOTAL(9,L24:L41) -> 3210711 | M22: =SUBTOTAL(9,M24:M41) -> 3210711 | N22: =SUBTOTAL(9,N24:N41) -> 3210711 | ... DV22: =SUBTOTAL(9,DV24:DV41) -> 11606835
B24: Existing Properties | C24: Gross Revenue | D24: Vacancy Rate | E24: [$] | G24: =SUBTOTAL(9,G25:G29) -> 3210711 | H24: =SUBTOTAL(9,H25:H29) -> 3210711 | I24: =SUBTOTAL(9,I25:I29) -> 3210711 | J24: =SUBTOTAL(9,J25:J29) -> 3210711 | K24: =SUBTOTAL(9,K25:K29) -> 3210711 | L24: =SUBTOTAL(9,L25:L29) -> 3210711 | M24: =SUBTOTAL(9,M25:M29) -> 3210711 | N24: =SUBTOTAL(9,N25:N29) -> 3210711 | ... DV24: =SUBTOTAL(9,DV25:DV29) -> 4208697.8
B25: =CaseData!A6 -> Property A | C25: =CaseData!B6 -> 791000 | D25: =CaseData!C6 -> 0.05 | E25: [$] | G25: =$C25*(1-$D25)*G$210 -> 789022.5 | H25: =$C25*(1-$D25)*H$210 -> 789022.5 | I25: =$C25*(1-$D25)*I$210 -> 789022.5 | J25: =$C25*(1-$D25)*J$210 -> 789022.5 | K25: =$C25*(1-$D25)*K$210 -> 789022.5 | L25: =$C25*(1-$D25)*L$210 -> 789022.5 | M25: =$C25*(1-$D25)*M$210 -> 789022.5 | N25: =$C25*(1-$D25)*N$210 -> 789022.5 | ... DV25: =$C25*(1-$D25)*DV$210 -> 1034274.7
B26: =CaseData!A7 -> Property B | C26: =CaseData!B7 -> 448000 | D26: =CaseData!C7 -> 0.07 | E26: [$] | G26: =$C26*(1-$D26)*G$210 -> 437472 | H26: =$C26*(1-$D26)*H$210 -> 437472 | I26: =$C26*(1-$D26)*I$210 -> 437472 | J26: =$C26*(1-$D26)*J$210 -> 437472 | K26: =$C26*(1-$D26)*K$210 -> 437472 | L26: =$C26*(1-$D26)*L$210 -> 437472 | M26: =$C26*(1-$D26)*M$210 -> 437472 | N26: =$C26*(1-$D26)*N$210 -> 437472 | ... DV26: =$C26*(1-$D26)*DV$210 -> 573451.63
B27: =CaseData!A8 -> Property C | C27: =CaseData!B8 -> 686000 | D27: =CaseData!C8 -> 0.06 | E27: [$] | G27: =$C27*(1-$D27)*G$210 -> 677082 | H27: =$C27*(1-$D27)*H$210 -> 677082 | I27: =$C27*(1-$D27)*I$210 -> 677082 | J27: =$C27*(1-$D27)*J$210 -> 677082 | K27: =$C27*(1-$D27)*K$210 -> 677082 | L27: =$C27*(1-$D27)*L$210 -> 677082 | M27: =$C27*(1-$D27)*M$210 -> 677082 | N27: =$C27*(1-$D27)*N$210 -> 677082 | ... DV27: =$C27*(1-$D27)*DV$210 -> 887539.72
B28: =CaseData!A9 -> Property D | C28: =CaseData!B9 -> 738000 | D28: =CaseData!C9 -> 0.04 | E28: [$] | G28: =$C28*(1-$D28)*G$210 -> 743904 | H28: =$C28*(1-$D28)*H$210 -> 743904 | I28: =$C28*(1-$D28)*I$210 -> 743904 | J28: =$C28*(1-$D28)*J$210 -> 743904 | K28: =$C28*(1-$D28)*K$210 -> 743904 | L28: =$C28*(1-$D28)*L$210 -> 743904 | M28: =$C28*(1-$D28)*M$210 -> 743904 | N28: =$C28*(1-$D28)*N$210 -> 743904 | ... DV28: =$C28*(1-$D28)*DV$210 -> 975132.04
B29: =CaseData!A10 -> Property E | C29: =CaseData!B10 -> 553000 | D29: =CaseData!C10 -> 0.03 | E29: [$] | G29: =$C29*(1-$D29)*G$210 -> 563230.5 | H29: =$C29*(1-$D29)*H$210 -> 563230.5 | I29: =$C29*(1-$D29)*I$210 -> 563230.5 | J29: =$C29*(1-$D29)*J$210 -> 563230.5 | K29: =$C29*(1-$D29)*K$210 -> 563230.5 | L29: =$C29*(1-$D29)*L$210 -> 563230.5 | M29: =$C29*(1-$D29)*M$210 -> 563230.5 | N29: =$C29*(1-$D29)*N$210 -> 563230.5 | ... DV29: =$C29*(1-$D29)*DV$210 -> 738299.71
B31: New Properties | C31: Gross Revenue | E31: [$] | G31: =SUBTOTAL(9,G32:G41) -> 0 | H31: =SUBTOTAL(9,H32:H41) -> 0 | I31: =SUBTOTAL(9,I32:I41) -> 0 | J31: =SUBTOTAL(9,J32:J41) -> 0 | K31: =SUBTOTAL(9,K32:K41) -> 0 | L31: =SUBTOTAL(9,L32:L41) -> 0 | M31: =SUBTOTAL(9,M32:M41) -> 0 | N31: =SUBTOTAL(9,N32:N41) -> 0 | ... DV31: =SUBTOTAL(9,DV32:DV41) -> 7398137.2
B32: =CaseData!A15 -> Property F | C32: =CaseData!B15 -> 442000 | E32: [$] | G32: =IF(G179=0,0,$C32*(1-G192)*G$210) -> 0 | H32: =IF(H179=0,0,$C32*(1-H192)*H$210) -> 0 | I32: =IF(I179=0,0,$C32*(1-I192)*I$210) -> 0 | J32: =IF(J179=0,0,$C32*(1-J192)*J$210) -> 0 | K32: =IF(K179=0,0,$C32*(1-K192)*K$210) -> 0 | L32: =IF(L179=0,0,$C32*(1-L192)*L$210) -> 0 | M32: =IF(M179=0,0,$C32*(1-M192)*M$210) -> 0 | N32: =IF(N179=0,0,$C32*(1-N192)*N$210) -> 0 | ... DV32: =IF(DV179=0,0,$C32*(1-DV192)*DV$210) -> 577938.6
