Workbook
Name cities: CaseData!$B$7:$B$16
Name company: Calculations!$F$51
Name months: Calculations!$F$55
Name start_date: Calculations!$F$54
Name states: CaseData!$C$7:$C$16
Name topic: "CFM Topic: " & Calculations!$F$52

Sheet Calculations
A1: {=company} -> Eagle Security Corp.
A2: {=topic} -> CFM Topic: Data Management
A3: CALCULATION SCHEDULE | J3: {=EDATE( start_date, _xlfn.SEQUENCE( 1, months, 0, 1 ) )} -> 43466 | K3: 43497 | L3: 43525 | M3: 43556 | N3: 43586 | O3: 43617 | P3: 43647 | Q3: 43678 | R3: 43709 | S3: 43739 | T3: 43770 | U3: 43800
A5: Summary tables
C7: Revenues
E9: City | F9: Start Date | J9: {=_xlfn.ANCHORARRAY( J3)} -> 43466 | K9: 43497 | L9: 43525 | M9: 43556 | N9: 43586 | O9: 43617 | P9: 43647 | Q9: 43678 | R9: 43709 | S9: 43739 | T9: 43770 | U9: 43800
D10: {=_xlfn.LET( _xlpm.city_position, CaseData!$A$7:$A$16, _xlpm.current_city, Calculations!$E$10:$E$14, _xlfn.XLOOKUP( _xlpm.current_city, cities, _xlpm.city_position,, 0 ) )} -> 2 | E10: Denver | F10: 43466 | G10: USD | H10: {=_xlfn.BYROW(_xlfn.ANCHORARRAY( J10), _xleta.SUM )} -> 50452233 | J10: {=_xlfn.LET( _xlpm.data, CaseData!$B$7:$L$16, _xlpm.cities, INDEX( _xlpm.data,, 1 ), _xlpm.hours, INDEX( _xlpm.data,, 3 ), _xlpm.hours_growth, ((1 + INDEX( _xlpm.data,, 4 ) / 100 ) ^ ( 1 / months )) - 1, _xlpm.share, INDEX( _xlpm.data,, 5 ) / 100, _xlpm.revenue, INDEX( _xlpm.data,, 6 ), _xlpm.revenue_growth, ((1 + INDEX( _xlpm.data,, 7 ) / 100 ) ^ ( 1 / months )) - 1, _xlpm.timeline,_xlfn.ANCHORARRAY( $J$3), _xlpm.current_selection, MATCH( $E$10:$E$14, _xlpm.cities, 0 ), _xlpm.current_city, INDEX( _xlpm.cities, _xlpm.current_selection, 1 ), _xlpm.current_hours, INDEX( _xlpm.hours, _xlpm.current_selection, 1 ), _xlpm.current_hours_growth, INDEX( _xlpm.hours_growth, _xlpm.current_selection, 1 ), _xlpm.current_share, INDEX( _xlpm.share, _xlpm.current_selection, 1 ), _xlpm.current_revenue, INDEX( _xlpm.revenue, _xlpm.current_selection, 1 ), _xlpm.current_rev_growth, INDEX( _xlpm.revenue_growth, _xlpm.current_selection, 1 ), _xlpm.operation_start, $F$10:$F$14, _xlpm.model_period_flag, _xlfn.MAKEARRAY( ROWS( _xlpm.current_city ), COLUMNS( _xlpm.timeline ), _xlfn.LAMBDA(_xlpm.r,_xlpm.c, IF( INDEX( _xlpm.timeline, 1, _xlpm.c ) >= start_date, 1, 0 ) ) ), _xlpm.operation_flag, _xlfn.MAKEARRAY( ROWS( _xlpm.current_city ), COLUMNS( _xlpm.timeline ), _xlfn.LAMBDA(_xlpm.r,_xlpm.c, IF( INDEX( _xlpm.timeline, 1, _xlpm.c ) >= INDEX( _xlpm.operation_start, _xlpm.r, 1 ), 1, 0 ) ) ), _xlpm.period_count, _xlfn.MAKEARRAY( ROWS( _xlpm.current_city ), COLUMNS( _xlpm.timeline ), _xlfn.LAMBDA(_xlpm.r,_xlpm.c, SUM( INDEX( _xlpm.model_period_flag, _xlpm.r, _xlfn.SEQUENCE( 1, _xlpm.c ) ) ) ) ), _xlpm.hours_monthly_fact, IF( _xlpm.model_period_flag, ( 1 + _xlpm.current_hours_growth ) ^ ( _xlpm.period_count ), 0 ), _xlpm.hours_available, _xlfn.MAKEARRAY( ROWS( _xlpm.current_city ), COLUMNS( _xlpm.timeline ), _xlfn.LAMBDA(_xlpm.r,_xlpm.c, INDEX( _xlpm.current_hours, _xlpm.r, 1 ) ) ) * _xlpm.hours_monthly_fact * _xlpm.current_share, _xlpm.revenue_fact, IF( _xlpm.model_period_flag, ( 1 + _xlpm.current_rev_growth ) ^ ( _xlpm.period_count ), 0 ), _xlpm.revenue_realised, _xlfn.MAKEARRAY( ROWS( _xlpm.current_city ), COLUMNS( _xlpm.timeline ), _xlfn.LAMBDA(_xlpm.r,_xlpm.c, INDEX( _xlpm.current_revenue, _xlpm.r, 1 ) ) ) * _xlpm.revenue_fact, _xlpm.operation_flag * _xlpm.hours_available * _xlpm.revenue_realised )} -> 4076702.8 | K10: 4099482.2 | L10: 4122388.9 | M10: 4145423.6 | N10: 4168587 | O10: 4191879.9 | P10: 4215302.8 | Q10: 4238856.7 | R10: 4262542.2 | S10: 4286360 | T10: 4310310.9 | U10: 4334395.7
D11: 6 | E11: Nashville | F11: 43466 | G11: USD | H11: 52975581 | J11: 4358587.8 | K11: 4368699 | L11: 4378833.7 | M11: 4388991.9 | N11: 4399173.6 | O11: 4409379 | P11: 4419608 | Q11: 4429860.8 | R11: 4440137.4 | S11: 4450437.8 | T11: 4460762.1 | U11: 4471110.3
D12: 10 | E12: Rochester | F12: 43466 | G12: USD | H12: 22816800 | J12: 1850305.4 | K12: 1859443.2 | L12: 1868626.2 | M12: 1877854.5 | N12: 1887128.3 | O12: 1896448 | P12: 1905813.7 | Q12: 1915225.6 | R12: 1924684 | S12: 1934189.2 | T12: 1943741.3 | U12: 1953340.5
D13: 4 | E13: San Antonio | F13: 43466 | G13: USD | H13: 57056058 | J13: 4602046.7 | K13: 4629253.3 | L13: 4656620.8 | M13: 4684150.1 | N13: 4711842.1 | O13: 4739697.8 | P13: 4767718.2 | Q13: 4795904.2 | R13: 4824256.9 | S13: 4852777.2 | T13: 4881466.1 | U13: 4910324.6
D14: 9 | E14: Hartford | F14: 43466 | G14: USD | H14: 16928143 | J14: 1383960.3 | K14: 1388762.2 | L14: 1393580.8 | M14: 1398416 | N14: 1403268.1 | O14: 1408137 | P14: 1413022.8 | Q14: 1417925.5 | R14: 1422845.3 | S14: 1427782.1 | T14: 1432736 | U14: 1437707.2
E15: Total Revenue | G15: USD | H15: {=_xlfn.BYROW(_xlfn.ANCHORARRAY(J15), _xleta.SUM )} -> 2.0022882e+08 | J15: {=_xlfn.BYCOL(_xlfn.ANCHORARRAY( J10), _xleta.SUM )} -> 16271603 | K15: 16345640 | L15: 16420050 | M15: 16494836 | N15: 16569999 | O15: 16645542 | P15: 16721466 | Q15: 16797773 | R15: 16874466 | S15: 16951546 | T15: 17029016 | U15: 17106878
C17: Salaries
E19: City | F19: Start Date | J19: {=_xlfn.ANCHORARRAY( $J$3)} -> 43466 | K19: 43497 | L19: 43525 | M19: 43556 | N19: 43586 | O19: 43617 | P19: 43647 | Q19: 43678 | R19: 43709 | S19: 43739 | T19: 43770 | U19: 43800
D20: {=_xlfn.LET( _xlpm.city_position, CaseData!$A$7:$A$16, _xlpm.current_city, Calculations!$E$10:$E$14, _xlfn.XLOOKUP( _xlpm.current_city, cities, _xlpm.city_position,, 0 ) )} -> 2 | E20: =$E10 -> Denver | F20: =$F10 -> 43466 | G20: USD | H20: {=_xlfn.BYROW(_xlfn.ANCHORARRAY( J20), _xleta.SUM )} -> 20705822 | J20: {=_xlfn.LET( _xlpm.data, CaseData!$B$7:$L$16, _xlpm.cities, INDEX( _xlpm.data,, 1 ), _xlpm.hours, INDEX( _xlpm.data,, 3 ), _xlpm.hours_growth, ((1 + INDEX( _xlpm.data,, 4 ) / 100 ) ^ ( 1 / months )) - 1, _xlpm.share, INDEX( _xlpm.data,, 5 ) / 100, _xlpm.salary, INDEX( _xlpm.data,, 8 ), _xlpm.salary_growth, ((1 + INDEX( _xlpm.data,, 9 ) / 100 ) ^ ( 1 / months )) - 1, _xlpm.timeline,_xlfn.ANCHORARRAY( $J$3), _xlpm.current_selection, MATCH( $E$20:$E$24, _xlpm.cities, 0 ), _xlpm.current_city, INDEX( _xlpm.cities, _xlpm.current_selection, 1 ), _xlpm.current_hours, INDEX( _xlpm.hours, _xlpm.current_selection, 1 ), _xlpm.current_hours_growth, INDEX( _xlpm.hours_growth, _xlpm.current_selection, 1 ), _xlpm.current_share, INDEX( _xlpm.share, _xlpm.current_selection, 1 ), _xlpm.current_salary, INDEX( _xlpm.salary, _xlpm.current_selection, 1 ), _xlpm.current_sal_growth, INDEX( _xlpm.salary_growth, _xlpm.current_selection, 1 ), _xlpm.operation_start, $F$20:$F$24, _xlpm.model_period_flag, _xlfn.MAKEARRAY( ROWS( _xlpm.current_city ), COLUMNS( _xlpm.timeline ), _xlfn.LAMBDA(_xlpm.r,_xlpm.c, IF( INDEX( _xlpm.timeline, 1, _xlpm.c ) >= start_date, 1, 0 ) ) ), _xlpm.operation_flag, _xlfn.MAKEARRAY( ROWS( _xlpm.current_city ), COLUMNS( _xlpm.timeline ), _xlfn.LAMBDA(_xlpm.r,_xlpm.c, IF( INDEX( _xlpm.timeline, 1, _xlpm.c ) >= INDEX( _xlpm.operation_start, _xlpm.r, 1 ), 1, 0 ) ) ), _xlpm.period_count, _xlfn.MAKEARRAY( ROWS( _xlpm.current_city ), COLUMNS( _xlpm.timeline ), _xlfn.LAMBDA(_xlpm.r,_xlpm.c, SUM( INDEX( _xlpm.model_period_flag, _xlpm.r, _xlfn.SEQUENCE( 1, _xlpm.c ) ) ) ) ), _xlpm.hours_monthly_fact, IF( _xlpm.model_period_flag, ( 1 + _xlpm.current_hours_growth ) ^ ( _xlpm.period_count ), 0 ), _xlpm.hours_available, _xlfn.MAKEARRAY( ROWS( _xlpm.current_city ), COLUMNS( _xlpm.timeline ), _xlfn.LAMBDA(_xlpm.r,_xlpm.c, INDEX( _xlpm.current_hours, _xlpm.r, 1 ) ) ) * _xlpm.hours_monthly_fact * _xlpm.current_share, _xlpm.salary_fact, IF( _xlpm.model_period_flag, ( 1 + _xlpm.current_sal_growth ) ^ ( _xlpm.period_count ), 0 ), _xlpm.salary_paid, _xlfn.MAKEARRAY( ROWS( _xlpm.current_city ), COLUMNS( _xlpm.timeline ), _xlfn.LAMBDA(_xlpm.r,_xlpm.c, INDEX( _xlpm.current_salary, _xlpm.r, 1 ) ) ) * _xlpm.salary_fact, _xlpm.operation_flag * _xlpm.hours_available * _xlpm.salary_paid )} -> 1671600.7 | K20: 1681211.2 | L20: 1690877.1 | M20: 1700598.5 | N20: 1710375.8 | O20: 1720209.3 | P20: 1730099.4 | Q20: 1740046.3 | R20: 1750050.4 | S20: 1760112.1 | T20: 1770231.5 | U20: 1780409.2
D21: 6 | E21: =$E11 -> Nashville | F21: =$F11 -> 43466 | G21: USD | H21: 16943091 | J21: 1394633.4 | K21: 1397753.8 | L21: 1400881.2 | M21: 1404015.6 | N21: 1407156.9 | O21: 1410305.3 | P21: 1413460.8 | Q21: 1416623.3 | R21: 1419792.9 | S21: 1422969.6 | T21: 1426153.4 | U21: 1429344.3
D22: 10 | E22: =$E12 -> Rochester | F22: =$F12 -> 43466 | G22: USD | H22: 9800646.8 | J22: 795488.65 | K22: 799287.86 | L22: 803105.22 | M22: 806940.8 | N22: 810794.71 | O22: 814667.02 | P22: 818557.82 | Q22: 822467.21 | R22: 826395.27 | S22: 830342.09 | T22: 834307.75 | U22: 838292.36
D23: 4 | E23: =$E13 -> San Antonio | F23: =$F13 -> 43466 | G23: USD | H23: 25144413 | J23: 2025388.1 | K23: 2037852.4 | L23: 2050393.4 | M23: 2063011.6 | N23: 2075707.5 | O23: 2088481.4 | P23: 2101334 | Q23: 2114265.7 | R23: 2127277 | S23: 2140368.3 | T23: 2153540.2 | U23: 2166793.2
D24: 9 | E24: =$E14 -> Hartford | F24: =$F14 -> 43466 | G24: USD | H24: 6255935.7 | J24: 511916.76 | K24: 513609.11 | L24: 515307.04 | M24: 517010.59 | N24: 518719.77 | O24: 520434.6 | P24: 522155.1 | Q24: 523881.29 | R24: 525613.18 | S24: 527350.8 | T24: 529094.16 | U24: 530843.29
E25: Total Salaries | G25: USD | H25: {=_xlfn.BYROW(_xlfn.ANCHORARRAY(J25), _xleta.SUM )} -> 78849908 | J25: {=_xlfn.BYCOL(_xlfn.ANCHORARRAY( J20), _xleta.SUM )} -> 6399027.6 | K25: 6429714.4 | L25: 6460563.9 | M25: 6491577.1 | N25: 6522754.7 | O25: 6554097.8 | P25: 6585607.2 | Q25: 6617283.9 | R25: 6649128.8 | S25: 6681142.9 | T25: 6713327.1 | U25: 6745682.3
C27: Fixed Costs
E29: City | F29: Start Date | J29: {=_xlfn.ANCHORARRAY( $J$3)} -> 43466 | K29: 43497 | L29: 43525 | M29: 43556 | N29: 43586 | O29: 43617 | P29: 43647 | Q29: 43678 | R29: 43709 | S29: 43739 | T29: 43770 | U29: 43800
D30: {=_xlfn.LET( _xlpm.city_position, CaseData!$A$7:$A$16, _xlpm.current_city, Calculations!$E$10:$E$14, _xlfn.XLOOKUP( _xlpm.current_city, cities, _xlpm.city_position,, 0 ) )} -> 2 | E30: =$E10 -> Denver | F30: =$F10 -> 43466 | G30: USD | H30: {=_xlfn.BYROW(_xlfn.ANCHORARRAY( J30), _xleta.SUM )} -> 681958 | J30: {=_xlfn.LET( _xlpm.data, CaseData!$B$7:$L$16, _xlpm.cities, INDEX( _xlpm.data,, 1 ), _xlpm.fixed, INDEX( _xlpm.data,, 10 ), _xlpm.fixed_growth, ((1 + INDEX( _xlpm.data,, 11 ) / 100 ) ^ ( 1 / months )) - 1, _xlpm.timeline,_xlfn.ANCHORARRAY( $J$3), _xlpm.current_selection, MATCH( $E$20:$E$24, _xlpm.cities, 0 ), _xlpm.current_city, INDEX( _xlpm.cities, _xlpm.current_selection, 1 ), _xlpm.current_fixed, INDEX( _xlpm.fixed, _xlpm.current_selection, 1 ), _xlpm.current_fixd_growth, INDEX( _xlpm.fixed_growth, _xlpm.current_selection, 1 ), _xlpm.operation_start, $F$20:$F$24, _xlpm.model_period_flag, _xlfn.MAKEARRAY( ROWS( _xlpm.current_city ), COLUMNS( _xlpm.timeline ), _xlfn.LAMBDA(_xlpm.r,_xlpm.c, IF( INDEX( _xlpm.timeline, 1, _xlpm.c ) >= start_date, 1, 0 ) ) ), _xlpm.operation_flag, _xlfn.MAKEARRAY( ROWS( _xlpm.current_city ), COLUMNS( _xlpm.timeline ), _xlfn.LAMBDA(_xlpm.r,_xlpm.c, IF( INDEX( _xlpm.timeline, 1, _xlpm.c ) >= INDEX( _xlpm.operation_start, _xlpm.r, 1 ), 1, 0 ) ) ), _xlpm.period_count, _xlfn.MAKEARRAY( ROWS( _xlpm.current_city ), COLUMNS( _xlpm.timeline ), _xlfn.LAMBDA(_xlpm.r,_xlpm.c, SUM( INDEX( _xlpm.model_period_flag, _xlpm.r, _xlfn.SEQUENCE( 1, _xlpm.c ) ) ) ) ), _xlpm.fixed_fact, IF( _xlpm.model_period_flag, ( 1 + _xlpm.current_fixd_growth ) ^ ( _xlpm.period_count ), 0 ), _xlpm.fixed_costs, _xlfn.MAKEARRAY( ROWS( _xlpm.current_city ), COLUMNS( _xlpm.timeline ), _xlfn.LAMBDA(_xlpm.r,_xlpm.c, INDEX( _xlpm.current_fixed, _xlpm.r, 1 ) ) ) * _xlpm.fixed_fact, _xlpm.operation_flag * _xlpm.fixed_costs )} -> 56465.846 | K30: 56531.768 | L30: 56597.767 | M30: 56663.844 | N30: 56729.997 | O30: 56796.228 | P30: 56862.536 | Q30: 56928.922 | R30: 56995.385 | S30: 57061.926 | T30: 57128.544 | U30: 57195.24
D31: 6 | E31: =$E11 -> Nashville | F31: =$F11 -> 43466 | G31: USD | H31: 499671.04 | J31: 41351.952 | K31: 41403.97 | L31: 41456.053 | M31: 41508.202 | N31: 41560.416 | O31: 41612.696 | P31: 41665.042 | Q31: 41717.454 | R31: 41769.931 | S31: 41822.475 | T31: 41875.084 | U31: 41927.76
D32: 10 | E32: =$E12 -> Rochester | F32: =$F12 -> 43466 | G32: USD | H32: 602456.06 | J32: 49777.2 | K32: 49854.521 | L32: 49931.961 | M32: 50009.522 | N32: 50087.203 | O32: 50165.005 | P32: 50242.927 | Q32: 50320.971 | R32: 50399.136 | S32: 50477.422 | T32: 50555.83 | U32: 50634.36
D33: 4 | E33: =$E13 -> San Antonio | F33: =$F13 -> 43466 | G33: USD | H33: 563824.23 | J33: 46743.75 | K33: 46787.54 | L33: 46831.372 | M33: 46875.245 | N33: 46919.159 | O33: 46963.114 | P33: 47007.11 | Q33: 47051.147 | R33: 47095.226 | S33: 47139.346 | T33: 47183.507 | U33: 47227.71
D34: 9 | E34: =$E14 -> Hartford | F34: =$F14 -> 43466 | G34: USD | H34: 666902.31 | J34: 55342.219 | K34: 55384.47 | L34: 55426.754 | M34: 55469.069 | N34: 55511.417 | O34: 55553.798 | P34: 55596.21 | Q34: 55638.655 | R34: 55681.133 | S34: 55723.643 | T34: 55766.185 | U34: 55808.76
E35: Total Fixed Costs | G35: USD | H35: {=_xlfn.BYROW(_xlfn.ANCHORARRAY(J35), _xleta.SUM )} -> 3014811.6 | J35: {=_xlfn.BYCOL(_xlfn.ANCHORARRAY( J30), _xleta.SUM )} -> 249680.97 | K35: 249962.27 | L35: 250243.91 | M35: 250525.88 | N35: 250808.19 | O35: 251090.84 | P35: 251373.83 | Q35: 251657.15 | R35: 251940.81 | S35: 252224.81 | T35: 252509.15 | U35: 252793.83
C37: Operating Profit
E39: City | F39: Start Date | J39: {=_xlfn.ANCHORARRAY( $J$3)} -> 43466 | K39: 43497 | L39: 43525 | M39: 43556 | N39: 43586 | O39: 43617 | P39: 43647 | Q39: 43678 | R39: 43709 | S39: 43739 | T39: 43770 | U39: 43800
D40: {=_xlfn.LET( _xlpm.city_position, CaseData!$A$7:$A$16, _xlpm.current_city, Calculations!$E$10:$E$14, _xlfn.XLOOKUP( _xlpm.current_city, cities, _xlpm.city_position,, 0 ) )} -> 2 | E40: =E10 -> Denver | F40: =F10 -> 43466 | G40: USD | H40: {=_xlfn.BYROW(_xlfn.ANCHORARRAY( J40), _xleta.SUM )} -> 29064453 | J40: {=_xlfn.ANCHORARRAY( J10) -_xlfn.ANCHORARRAY( J20) -_xlfn.ANCHORARRAY( J30)} -> 2348636.3 | K40: 2361739.2 | L40: 2374914.1 | M40: 2388161.3 | N40: 2401481.2 | O40: 2414874.3 | P40: 2428340.9 | Q40: 2441881.5 | R40: 2455496.4 | S40: 2469186 | T40: 2482950.8 | U40: 2496791.2
D41: 6 | E41: =E11 -> Nashville | F41: =F11 -> 43466 | G41: USD | H41: 35532820 | J41: 2922602.4 | K41: 2929541.2 | L41: 2936496.5 | M41: 2943468.1 | N41: 2950456.3 | O41: 2957461 | P41: 2964482.2 | Q41: 2971520 | R41: 2978574.5 | S41: 2985645.7 | T41: 2992733.6 | U41: 2999838.2
D42: 10 | E42: =E12 -> Rochester | F42: =F12 -> 43466 | G42: USD | H42: 12413697 | J42: 1005039.6 | K42: 1010300.8 | L42: 1015589 | M42: 1020904.1 | N42: 1026246.4 | O42: 1031616 | P42: 1037012.9 | Q42: 1042437.4 | R42: 1047889.6 | S42: 1053369.7 | T42: 1058877.7 | U42: 1064413.8
D43: 4 | E43: =E13 -> San Antonio | F43: =F13 -> 43466 | G43: USD | H43: 31347821 | J43: 2529914.9 | K43: 2544613.4 | L43: 2559396 | M43: 2574263.2 | N43: 2589215.5 | O43: 2604253.2 | P43: 2619377 | Q43: 2634587.4 | R43: 2649884.7 | S43: 2665269.5 | T43: 2680742.4 | U43: 2696303.7
D44: 9 | E44: =E14 -> Hartford | F44: =F14 -> 43466 | G44: USD | H44: 10005305 | J44: 816701.32 | K44: 819768.63 | L44: 822846.97 | M44: 825936.39 | N44: 829036.92 | O44: 832148.6 | P44: 835271.48 | Q44: 838405.58 | R44: 841550.96 | S44: 844707.65 | T44: 847875.7 | U44: 851055.14
E45: Total Operating Profit | G45: USD | H45: {=_xlfn.BYROW(_xlfn.ANCHORARRAY(J45), _xleta.SUM )} -> 1.183641e+08 | J45: {=_xlfn.BYCOL(_xlfn.ANCHORARRAY( J40), _xleta.SUM )} -> 9622894.5 | K45: 9665963.4 | L45: 9709242.5 | M45: 9752733.1 | N45: 9796436.3 | O45: 9840353 | P45: 9884484.5 | Q45: 9928831.9 | R45: 9973396.2 | S45: 10018179 | T45: 10063180 | U45: 10108402
A49: Model technical inputs
E51: Company | F51: Eagle Security Corp. | G51: label
E52: Topic | F52: Data Management | G52: label
E54: Model start date | F54: 43466 | G54: date
...

Sheet CaseData
D4: Dec 2018 Base Data
D5: Total Hrs Available | E5: Annualized | F5: Market | G5: Revenue / | H5: Annualized | I5: Salary / | J5: Annualized | K5: Montly Fixed | L5: Annualized
B6: City | C6: State | D6: in Market per Month | E6: Growth % | F6: Share | G6: Hour | H6: Growth % | I6: Hour | J6: Growth % | K6: Costs ($) | L6: Growth %
A7: =ROW()-ROW($A$6) -> 1 | B7: Minneapolis | C7: Minnesota | D7: =1000*30*14 -> 420000 | E7: 2.5 | F7: 30 | G7: 65.25 | H7: 2.5 | I7: 28.71 | J7: 2.2 | K7: 50300 | L7: 1.39
A8: =ROW()-ROW($A$6) -> 2 | B8: Denver | C8: Colorado | D8: 385000 | E8: 3.2 | F8: 15 | G8: 70.2 | H8: 3.6 | I8: 28.78 | J8: 3.8 | K8: 56400 | L8: 1.41
A9: =ROW()-ROW($A$6) -> 3 | B9: St. Louis | C9: Missouri | D9: 315000 | E9: 1.6 | F9: 15 | G9: 62.5 | H9: 1.5 | I9: 20.62 | J9: 1.3 | K9: 50200 | L9: 1.07
A10: =ROW()-ROW($A$6) -> 4 | B10: San Antonio | C10: Texas | D10: 305000 | E10: 3.5 | F10: 25 | G10: 60 | H10: 3.7 | I10: 26.4 | J10: 4 | K10: 46700 | L10: 1.13
A11: =ROW()-ROW($A$6) -> 5 | B11: Columbus | C11: Ohio | D11: 285000 | E11: 3.1 | F11: 17 | G11: 53.1 | H11: 3.2 | I11: 25.48 | J11: 3.4 | K11: 43100 | L11: 1.55
A12: =ROW()-ROW($A$6) -> 6 | B12: Nashville | C12: Tennessee | D12: 260000 | E12: 1.4 | F12: 30 | G12: 55.75 | H12: 1.4 | I12: 17.84 | J12: 1.3 | K12: 41300 | L12: 1.52
A13: =ROW()-ROW($A$6) -> 7 | B13: Oklahoma City | C13: Oklahoma | D13: 230000 | E13: 1.2 | F13: 25 | G13: 60 | H13: 1.2 | I13: 25.2 | J13: 1.2 | K13: 46300 | L13: 1.27
A14: =ROW()-ROW($A$6) -> 8 | B14: New Orleans | C14: Louisiana | D14: 190000 | E14: 2.6 | F14: 20 | G14: 64.55 | H14: 2.7 | I14: 23.88 | J14: 2.7 | K14: 51300 | L14: 1.02
A15: =ROW()-ROW($A$6) -> 9 | B15: Hartford | C15: Connecticut | D15: 185000 | E15: 2 | F15: 10 | G15: 74.55 | H15: 2.2 | I15: 27.58 | J15: 2 | K15: 55300 | L15: 0.92
A16: =ROW()-ROW($A$6) -> 10 | B16: Rochester | C16: New York | D16: 185000 | E16: 2.9 | F16: 15 | G16: 66.35 | H16: 3.1 | I16: 28.53 | J16: 2.9 | K16: 49700 | L16: 1.88

Sheet CaseSolution
D1: Dec 2018 Base Data
A3: Launch | D3: Total Hrs Avail. | E3: Annualized | F3: Monthly | G3: Market | H3: Revenue / | I3: Annualized | J3: Monthly | K3: Salary / | L3: Annualized | M3: Monthly | N3: Montly Fixed | O3: Annualized | P3: Monthly
A4: Date | B4: City | C4: State | D4: per Month | E4: Growth % | F4: Growth % | G4: Share | H4: Hour | I4: Growth % | J4: Growth % | K4: Hour | L4: Growth % | M4: Growth % | N4: Costs ($) | O4: Growth % | P4: Growth %
A5: 43466 | B5: Minneapolis | C5: Minnesota | D5: =1000*30*14 -> 420000 | E5: 2.5 | F5: =((1+E5/100)^(1/12))-1 -> 0.0020598363 | G5: 30 | H5: 65.25 | I5: 2.5 | J5: =((1+I5/100)^(1/12))-1 -> 0.0020598363 | K5: 28.71 | L5: 2.2 | M5: =((1+L5/100)^(1/12))-1 -> 0.001815103 | N5: 50300 | O5: 1.39 | P5: =((1+O5/100)^(1/12))-1 -> 0.0011510187
A6: 43617 | B6: Denver | C6: Colorado | D6: 385000 | E6: 3.2 | F6: =((1+E6/100)^(1/12))-1 -> 0.002628337 | G6: 15 | H6: 70.2 | I6: 3.6 | J6: =((1+I6/100)^(1/12))-1 -> 0.0029516094 | K6: 28.78 | L6: 3.8 | M6: =((1+L6/100)^(1/12))-1 -> 0.0031128168 | N6: 56400 | O6: 1.41 | P6: =((1+O6/100)^(1/12))-1 -> 0.0011674743
A7: 43647 | B7: St. Louis | C7: Missouri | D7: 315000 | E7: 1.6 | F7: =((1+E7/100)^(1/12))-1 -> 0.0013236544 | G7: 15 | H7: 62.5 | I7: 1.5 | J7: =((1+I7/100)^(1/12))-1 -> 0.0012414877 | K7: 20.62 | L7: 1.3 | M7: =((1+L7/100)^(1/12))-1 -> 0.0010769316 | N7: 50200 | O7: 1.07 | P7: =((1+O7/100)^(1/12))-1 -> 0.00088732345
A8: 43678 | B8: San Antonio | C8: Texas | D8: 305000 | E8: 3.5 | F8: =((1+E8/100)^(1/12))-1 -> 0.0028708987 | G8: 25 | H8: 60 | I8: 3.7 | J8: =((1+I8/100)^(1/12))-1 -> 0.0030322488 | K8: 26.4 | L8: 4 | M8: =((1+L8/100)^(1/12))-1 -> 0.0032737398 | N8: 46700 | O8: 1.13 | P8: =((1+O8/100)^(1/12))-1 -> 0.00093682454
A9: 43556 | B9: Columbus | C9: Ohio | D9: 285000 | E9: 3.1 | F9: =((1+E9/100)^(1/12))-1 -> 0.0025473394 | G9: 17 | H9: 53.1 | I9: 3.2 | J9: =((1+I9/100)^(1/12))-1 -> 0.002628337 | K9: 25.48 | L9: 3.4 | M9: =((1+L9/100)^(1/12))-1 -> 0.0027901165 | N9: 43100 | O9: 1.55 | P9: =((1+O9/100)^(1/12))-1 -> 0.0012825803
A10: 43586 | B10: Nashville | C10: Tennessee | D10: 260000 | E10: 1.4 | F10: =((1+E10/100)^(1/12))-1 -> 0.0011592468 | G10: 30 | H10: 55.75 | I10: 1.4 | J10: =((1+I10/100)^(1/12))-1 -> 0.0011592468 | K10: 17.84 | L10: 1.3 | M10: =((1+L10/100)^(1/12))-1 -> 0.0010769316 | N10: 41300 | O10: 1.52 | P10: =((1+O10/100)^(1/12))-1 -> 0.001257927
A11: 43617 | B11: Oklahoma City | C11: Oklahoma | D11: 230000 | E11: 1.2 | F11: =((1+E11/100)^(1/12))-1 -> 0.0009945418 | G11: 25 | H11: 60 | I11: 1.2 | J11: =((1+I11/100)^(1/12))-1 -> 0.0009945418 | K11: 25.2 | L11: 1.2 | M11: =((1+L11/100)^(1/12))-1 -> 0.0009945418 | N11: 46300 | O11: 1.27 | P11: =((1+O11/100)^(1/12))-1 -> 0.0010522225
A12: 43617 | B12: New Orleans | C12: Louisiana | D12: 190000 | E12: 2.6 | F12: =((1+E12/100)^(1/12))-1 -> 0.0021412681 | G12: 20 | H12: 64.55 | I12: 2.7 | J12: =((1+I12/100)^(1/12))-1 -> 0.0022226273 | K12: 23.88 | L12: 2.7 | M12: =((1+L12/100)^(1/12))-1 -> 0.0022226273 | N12: 51300 | O12: 1.02 | P12: =((1+O12/100)^(1/12))-1 -> 0.00084605195
A13: 43617 | B13: Hartford | C13: Connecticut | D13: 185000 | E13: 2 | F13: =((1+E13/100)^(1/12))-1 -> 0.0016515813 | G13: 10 | H13: 74.55 | I13: 2.2 | J13: =((1+I13/100)^(1/12))-1 -> 0.001815103 | K13: 27.58 | L13: 2 | M13: =((1+L13/100)^(1/12))-1 -> 0.0016515813 | N13: 55300 | O13: 0.92 | P13: =((1+O13/100)^(1/12))-1 -> 0.00076345276
A14: 43647 | B14: Rochester | C14: New York | D14: 185000 | E14: 2.9 | F14: =((1+E14/100)^(1/12))-1 -> 0.002385128 | G14: 15 | H14: 66.35 | I14: 3.1 | J14: =((1+I14/100)^(1/12))-1 -> 0.0025473394 | K14: 28.53 | L14: 2.9 | M14: =((1+L14/100)^(1/12))-1 -> 0.002385128 | N14: 49700 | O14: 1.88 | P14: =((1+O14/100)^(1/12))-1 -> 0.0015533272
A16: INDEXES | P16: Annual %
B17: Hours Available: | C17: =EDATE(D17,-1) -> 43435 | D17: 43466 | E17: =EDATE(D17,1) -> 43497 | F17: =EDATE(E17,1) -> 43525 | G17: =EDATE(F17,1) -> 43556 | H17: =EDATE(G17,1) -> 43586 | I17: =EDATE(H17,1) -> 43617 | J17: =EDATE(I17,1) -> 43647 | K17: =EDATE(J17,1) -> 43678 | L17: =EDATE(K17,1) -> 43709 | ... O17: =EDATE(N17,1) -> 43800 | P17: Check
B19: =$B$5 -> Minneapolis | C19: =D5 -> 420000 | D19: =C19*(1+$F5) -> 420865.13 | E19: =D19*(1+$F5) -> 421732.04 | F19: =E19*(1+$F5) -> 422600.74 | G19: =F19*(1+$F5) -> 423471.23 | H19: =G19*(1+$F5) -> 424343.51 | I19: =H19*(1+$F5) -> 425217.59 | J19: =I19*(1+$F5) -> 426093.47 | K19: =J19*(1+$F5) -> 426971.15 | ... O19: =N19*(1+$F5) -> 430500 | P19: =(O19/C19-1)*100-E5 -> -1.1990409e-13
B20: =$B$6 -> Denver | C20: =D6 -> 385000 | D20: =C20*(1+$F6) -> 386011.91 | E20: =D20*(1+$F6) -> 387026.48 | F20: =E20*(1+$F6) -> 388043.72 | G20: =F20*(1+$F6) -> 389063.62 | H20: =G20*(1+$F6) -> 390086.22 | I20: =H20*(1+$F6) -> 391111.49 | J20: =I20*(1+$F6) -> 392139.47 | K20: =J20*(1+$F6) -> 393170.14 | ... O20: =N20*(1+$F6) -> 397320 | P20: =(O20/C20-1)*100-E6 -> 4.7073456e-14
B21: =$B$7 -> St. Louis | C21: =D7 -> 315000 | D21: =C21*(1+$F7) -> 315416.95 | E21: =D21*(1+$F7) -> 315834.45 | F21: =E21*(1+$F7) -> 316252.51 | G21: =F21*(1+$F7) -> 316671.12 | H21: =G21*(1+$F7) -> 317090.28 | I21: =H21*(1+$F7) -> 317510 | J21: =I21*(1+$F7) -> 317930.27 | K21: =J21*(1+$F7) -> 318351.1 | ... O21: =N21*(1+$F7) -> 320040 | P21: =(O21/C21-1)*100-E7 -> 1.1235457e-13
B22: =$B$8 -> San Antonio | C22: =D8 -> 305000 | D22: =C22*(1+$F8) -> 305875.62 | E22: =D22*(1+$F8) -> 306753.76 | F22: =E22*(1+$F8) -> 307634.42 | G22: =F22*(1+$F8) -> 308517.61 | H22: =G22*(1+$F8) -> 309403.33 | I22: =H22*(1+$F8) -> 310291.6 | J22: =I22*(1+$F8) -> 311182.41 | K22: =J22*(1+$F8) -> 312075.79 | ... O22: =N22*(1+$F8) -> 315675 | P22: =(O22/C22-1)*100-E8 -> 1.4210855e-14
B23: =$B$9 -> Columbus | C23: =D9 -> 285000 | D23: =C23*(1+$F9) -> 285725.99 | E23: =D23*(1+$F9) -> 286453.83 | F23: =E23*(1+$F9) -> 287183.53 | G23: =F23*(1+$F9) -> 287915.08 | H23: =G23*(1+$F9) -> 288648.5 | I23: =H23*(1+$F9) -> 289383.78 | J23: =I23*(1+$F9) -> 290120.94 | K23: =J23*(1+$F9) -> 290859.98 | ... O23: =N23*(1+$F9) -> 293835 | P23: =(O23/C23-1)*100-E9 -> 1.3766766e-14
B24: =$B$10 -> Nashville | C24: =D10 -> 260000 | D24: =C24*(1+$F10) -> 260301.4 | E24: =D24*(1+$F10) -> 260603.16 | F24: =E24*(1+$F10) -> 260905.26 | G24: =F24*(1+$F10) -> 261207.71 | H24: =G24*(1+$F10) -> 261510.52 | I24: =H24*(1+$F10) -> 261813.67 | J24: =I24*(1+$F10) -> 262117.18 | K24: =J24*(1+$F10) -> 262421.04 | ... O24: =N24*(1+$F10) -> 263640 | P24: =(O24/C24-1)*100-E10 -> 4.5741189e-14
B25: =$B$11 -> Oklahoma City | C25: =D11 -> 230000 | D25: =C25*(1+$F11) -> 230228.74 | E25: =D25*(1+$F11) -> 230457.72 | F25: =E25*(1+$F11) -> 230686.92 | G25: =F25*(1+$F11) -> 230916.34 | H25: =G25*(1+$F11) -> 231146 | I25: =H25*(1+$F11) -> 231375.88 | J25: =I25*(1+$F11) -> 231606 | K25: =J25*(1+$F11) -> 231836.34 | ... O25: =N25*(1+$F11) -> 232760 | P25: =(O25/C25-1)*100-E11 -> -2.1094237e-14
B26: =$B$12 -> New Orleans | C26: =D12 -> 190000 | D26: =C26*(1+$F12) -> 190406.84 | E26: =D26*(1+$F12) -> 190814.55 | F26: =E26*(1+$F12) -> 191223.14 | G26: =F26*(1+$F12) -> 191632.6 | H26: =G26*(1+$F12) -> 192042.93 | I26: =H26*(1+$F12) -> 192454.15 | J26: =I26*(1+$F12) -> 192866.25 | K26: =J26*(1+$F12) -> 193279.22 | ... O26: =N26*(1+$F12) -> 194940 | P26: =(O26/C26-1)*100-E12 -> 1.1324275e-13
B27: =$B$13 -> Hartford | C27: =D13 -> 185000 | D27: =C27*(1+$F13) -> 185305.54 | E27: =D27*(1+$F13) -> 185611.59 | F27: =E27*(1+$F13) -> 185918.14 | G27: =F27*(1+$F13) -> 186225.2 | H27: =G27*(1+$F13) -> 186532.77 | I27: =H27*(1+$F13) -> 186840.84 | J27: =I27*(1+$F13) -> 187149.42 | K27: =J27*(1+$F13) -> 187458.52 | ... O27: =N27*(1+$F13) -> 188700 | P27: =(O27/C27-1)*100-E13 -> 6.8389738e-14
B28: =$B$14 -> Rochester | C28: =D14 -> 185000 | D28: =C28*(1+$F14) -> 185441.25 | E28: =D28*(1+$F14) -> 185883.55 | F28: =E28*(1+$F14) -> 186326.91 | G28: =F28*(1+$F14) -> 186771.32 | H28: =G28*(1+$F14) -> 187216.79 | I28: =H28*(1+$F14) -> 187663.33 | J28: =I28*(1+$F14) -> 188110.93 | K28: =J28*(1+$F14) -> 188559.6 | ... O28: =N28*(1+$F14) -> 190365 | P28: =(O28/C28-1)*100-E14 -> -9.7255537e-14
B30: Eagle Hours: | C30: =$C$17 -> 43435 | D30: =$D$17 -> 43466 | E30: =$E$17 -> 43497 | F30: =$F$17 -> 43525 | G30: =$G$17 -> 43556 | H30: =$H$17 -> 43586 | I30: =$I$17 -> 43617 | J30: =$J$17 -> 43647 | K30: =$K$17 -> 43678 | L30: =$L$17 -> 43709 | M30: =$M$17 -> 43739 | N30: =$N$17 -> 43770 | O30: =$O$17 -> 43800
B32: =$B$5 -> Minneapolis | D32: =D19*$G5/100 -> 126259.54 | E32: =E19*$G5/100 -> 126519.61 | F32: =F19*$G5/100 -> 126780.22 | G32: =G19*$G5/100 -> 127041.37 | H32: =H19*$G5/100 -> 127303.05 | I32: =I19*$G5/100 -> 127565.28 | J32: =J19*$G5/100 -> 127828.04 | K32: =K19*$G5/100 -> 128091.35 | ... O32: =O19*$G5/100 -> 129150
B33: =$B$6 -> Denver | D33: =D20*$G6/100 -> 57901.786 | E33: =E20*$G6/100 -> 58053.972 | F33: =F20*$G6/100 -> 58206.557 | G33: =G20*$G6/100 -> 58359.544 | H33: =H20*$G6/100 -> 58512.932 | I33: =I20*$G6/100 -> 58666.724 | J33: =J20*$G6/100 -> 58820.92 | K33: =K20*$G6/100 -> 58975.521 | ... O33: =O20*$G6/100 -> 59598
B34: =$B$7 -> St. Louis | D34: =D21*$G7/100 -> 47312.543 | E34: =E21*$G7/100 -> 47375.168 | F34: =F21*$G7/100 -> 47437.876 | G34: =G21*$G7/100 -> 47500.668 | H34: =H21*$G7/100 -> 47563.542 | I34: =I21*$G7/100 -> 47626.5 | J34: =J21*$G7/100 -> 47689.541 | K34: =K21*$G7/100 -> 47752.665 | ... O34: =O21*$G7/100 -> 48006
B35: =$B$8 -> San Antonio | D35: =D22*$G8/100 -> 76468.906 | E35: =E22*$G8/100 -> 76688.441 | F35: =F22*$G8/100 -> 76908.605 | G35: =G22*$G8/100 -> 77129.402 | H35: =H22*$G8/100 -> 77350.833 | I35: =I22*$G8/100 -> 77572.899 | J35: =J22*$G8/100 -> 77795.603 | K35: =K22*$G8/100 -> 78018.946 | ... O35: =O22*$G8/100 -> 78918.75
B36: =$B$9 -> Columbus | D36: =D23*$G9/100 -> 48573.419 | E36: =E23*$G9/100 -> 48697.152 | F36: =F23*$G9/100 -> 48821.2 | G36: =G23*$G9/100 -> 48945.564 | H36: =H23*$G9/100 -> 49070.245 | I36: =I23*$G9/100 -> 49195.243 | J36: =J23*$G9/100 -> 49320.56 | K36: =K23*$G9/100 -> 49446.197 | ... O36: =O23*$G9/100 -> 49951.95
B37: =$B$10 -> Nashville | D37: =D24*$G10/100 -> 78090.421 | E37: =E24*$G10/100 -> 78180.947 | F37: =F24*$G10/100 -> 78271.578 | G37: =G24*$G10/100 -> 78362.314 | H37: =H24*$G10/100 -> 78453.156 | I37: =I24*$G10/100 -> 78544.102 | J37: =J24*$G10/100 -> 78635.154 | K37: =K24*$G10/100 -> 78726.312 | ... O37: =O24*$G10/100 -> 79092
B38: =$B$11 -> Oklahoma City | D38: =D25*$G11/100 -> 57557.186 | E38: =E25*$G11/100 -> 57614.429 | F38: =F25*$G11/100 -> 57671.729 | G38: =G25*$G11/100 -> 57729.086 | H38: =H25*$G11/100 -> 57786.5 | I38: =I25*$G11/100 -> 57843.971 | J38: =J25*$G11/100 -> 57901.499 | K38: =K25*$G11/100 -> 57959.085 | ... O38: =O25*$G11/100 -> 58190
B39: =$B$12 -> New Orleans | D39: =D26*$G12/100 -> 38081.368 | E39: =E26*$G12/100 -> 38162.911 | F39: =F26*$G12/100 -> 38244.628 | G39: =G26*$G12/100 -> 38326.52 | H39: =H26*$G12/100 -> 38408.587 | I39: =I26*$G12/100 -> 38490.83 | J39: =J26*$G12/100 -> 38573.249 | K39: =K26*$G12/100 -> 38655.845 | ... O39: =O26*$G12/100 -> 38988
B40: =$B$13 -> Hartford | D40: =D27*$G13/100 -> 18530.554 | E40: =E27*$G13/100 -> 18561.159 | F40: =F27*$G13/100 -> 18591.814 | G40: =G27*$G13/100 -> 18622.52 | H40: =H27*$G13/100 -> 18653.277 | I40: =I27*$G13/100 -> 18684.084 | J40: =J27*$G13/100 -> 18714.942 | K40: =K27*$G13/100 -> 18745.852 | ... O40: =O27*$G13/100 -> 18870
B41: =$B$14 -> Rochester | D41: =D28*$G14/100 -> 27816.187 | E41: =E28*$G14/100 -> 27882.532 | F41: =F28*$G14/100 -> 27949.036 | G41: =G28*$G14/100 -> 28015.698 | H41: =H28*$G14/100 -> 28082.519 | I41: =I28*$G14/100 -> 28149.499 | J41: =J28*$G14/100 -> 28216.639 | K41: =K28*$G14/100 -> 28283.94 | ... O41: =O28*$G14/100 -> 28554.75
P42: Annual %
B43: Revenues / Hour: | C43: =$C$17 -> 43435 | D43: =$D$17 -> 43466 | E43: =$E$17 -> 43497 | F43: =$F$17 -> 43525 | G43: =$G$17 -> 43556 | H43: =$H$17 -> 43586 | I43: =$I$17 -> 43617 | J43: =$J$17 -> 43647 | K43: =$K$17 -> 43678 | L43: =$L$17 -> 43709 | M43: =$M$17 -> 43739 | N43: =$N$17 -> 43770 | O43: =$O$17 -> 43800 | P43: Check
B45: =$B$5 -> Minneapolis | C45: =H5 -> 65.25 | D45: =C45*(1+$J5) -> 65.384404 | E45: =D45*(1+$J5) -> 65.519085 | F45: =E45*(1+$J5) -> 65.654044 | G45: =F45*(1+$J5) -> 65.789281 | H45: =G45*(1+$J5) -> 65.924796 | I45: =H45*(1+$J5) -> 66.06059 | J45: =I45*(1+$J5) -> 66.196664 | K45: =J45*(1+$J5) -> 66.333018 | ... O45: =N45*(1+$J5) -> 66.88125 | P45: =(O45/C45-1)*100-I5 -> -1.4210855e-13
B46: =$B$6 -> Denver | C46: =H6 -> 70.2 | D46: =C46*(1+$J6) -> 70.407203 | E46: =D46*(1+$J6) -> 70.615018 | F46: =E46*(1+$J6) -> 70.823445 | G46: =F46*(1+$J6) -> 71.032489 | H46: =G46*(1+$J6) -> 71.242149 | I46: =H46*(1+$J6) -> 71.452428 | J46: =I46*(1+$J6) -> 71.663327 | K46: =J46*(1+$J6) -> 71.87485 | ... O46: =N46*(1+$J6) -> 72.7272 | P46: =(O46/C46-1)*100-I6 -> 9.1926466e-14
...
